Workbook
Name AdditionalInstructions: IndexInformation!$B$42
Name Address: ImportantDisclosures!$A$2:$A$2
Name ANA: ModPubIndex!$A$7
Name Authors: ImportantDisclosures!$A$7
Name Authors: IndexInformation!$B$18
Name BRO: ModPubIndex!$A$1
Name CopyrightStamp: ImportantDisclosures!$A$27
Name COU: ModPubIndex!$A$5
Name CQEnd: IndexInformation!$B$31
Name Currency: IndexInformation!$B$24
Name CurrentStockPrice: IndexInformation!$B$23
Name CurrQtrEPS: IndexInformation!$B$29
Name CurrYearEPS: IndexInformation!$B$11
Name CurrYearTotalRevenue: IndexInformation!$B$10
Name CurrYearTotalRevenueActual: IndexInformation!$B$32
Name CUSIP: IndexInformation!$B$20
Name CYEnd: IndexInformation!$B$30
Name Date: ImportantDisclosures!$A$8
Name Deleted: IndexInformation!$B$27
Name Description: IndexInformation!$B$7
Name Discipline: IndexInformation!$B$3
Name DISCIPLINE: ModPubIndex!$A$12
Name DisclosuresText: ImportantDisclosures!$A$22
Name Distribution: IndexInformation!$B$26
Name DistTable: ImportantDisclosures!#REF!
Name DistTablePreamble: ImportantDisclosures!#REF!
Name DOCDAT: ModPubIndex!$A$2
Name DOCTIME: ModPubIndex!$A$3
Name DocType: IndexInformation!$B$5
Name EMAIL_ALERT: ModPubIndex!$A$10
Name EmailAlert: IndexInformation!$B$28
Name FiveYearGrowthRate: IndexInformation!$B$16
Name FollowingYearEPS: IndexInformation!$B$15
Name FollowingYearTotalRevenue: IndexInformation!$B$14
Name FollowingYearTotalRevenueActual: IndexInformation!$B$34
Name HL: ModPubIndex!$A$8
Name IND: ModPubIndex!$A$9
Name Industry: ImportantDisclosures!$A$12
Name IndustryId: IndexInformation!$B$40
Name IndustryRating: ImportantDisclosures!$A$13
Name KeepVersions: IndexInformation!$B$8
Name LanguageCode: IndexInformation!$B$38
Name LastCell: ImportantDisclosures!$A$22
Name Linking_1: IS!$A$5:$CM$57
Name Linking_10: [7]BBB!$L$37
Name Linking_11: [7]BBB!$N$37
Name Linking_12: [7]BBB!$P$37
Name Linking_13: [7]BBB!$L$41
Name Linking_14: [7]BBB!$N$41
Name Linking_15: [7]BBB!$P$41
Name Linking_16: [7]Variance!$A$12:$I$41
Name Linking_17: [7]Guidance!$A$5:$I$19
Name Linking_18: '[7]Model Changes'!$A$7:$G$57
Name Linking_19: '[7]EPS Preview'!$A$8:$E$33
Name Linking_2: BDX!$A$5:$CM$74
Name Linking_3: BS!$A$5:$CM$53
Name Linking_4: CFS!$A$5:$CM$59
Name Linking_5: [7]BBB!$L$31
Name Linking_6: [7]BBB!$P$31
Name Linking_7: [7]BBB!$L$34

Sheet ImportantDisclosures
A2: 1585 Broadway
A3: New York, NY 10036-8293
A4: United States
A5: Tel: +1 (1)212 761 4000
A7: Authors: David Lewis, Varun Kuchibhatla
A8: Date: 14 Apr 2018
A10: Ticker: BDX.N
A11: Stock Rating: Equal-Weight
A12: Industry: Medical Technology
A13: Industry View: Attractive
A14: Price as of 14 Apr 2018: 225.45
A15: Target Price: 250
... A123: Equal-weight and Not-Rated to hold and Underweight to sell recommendations, respectively.
B125: Coverage Universe | D125: Investment Banking Clients (IBC) | G125: Other Material Investment Services Clients (MISC)
A126: Stock Rating Category | B126: Count | C126: % of Total | D126: Count | E126: % of Total IBC | F126: % of Rating Category | G126: Count | H126: % of Total Other MISC
A127: Overweight/Buy | B127: 1189 | C127: 0.38 | D127: 315 | E127: 0.41 | F127: 0.26 | G127: 555 | H127: 0.39
A128: Equal-weight/Hold | B128: 1355 | C128: 0.43 | D128: 364 | E128: 0.47 | F128: 0.27 | G128: 644 | H128: 0.45
A129: Not-Rated/Hold | B129: 53 | C129: 0.02 | D129: 4 | E129: 0.01 | F129: 0.08 | G129: 7 | H129: 0
A130: Underweight/Sell | B130: 545 | C130: 0.17 | D130: 84 | E130: 0.11 | F130: 0.15 | G130: 214 | H130: 0.15
A131: Total | B131: 3142 | D131: 767 | G131: 1420
A133: Data include common stock and ADRs currently assigned ratings. Investment Banking Clients are companies
A134: from whom Morgan Stanley received investment banking compensation in the last 12 months. Due to rounding
A135: off of decimals, the percentages provided in the "% of total" column may not add up to exactly 100
A136: percent.
A138: Analyst Stock Ratings
A140: Overweight (O). The stock's total return is expected to exceed the average total return of the analyst's
A141: industry (or industry team's) coverage universe, on a risk-adjusted basis, over the next 12-18 months.
A143: Equal-weight (E). The stock's total return is expected to be in line with the average total return of
A144: the analyst's industry (or industry team's) coverage universe, on a risk-adjusted basis, over the next
A145: 12-18 months.
A147: Not-Rated (NR). Currently the analyst does not have adequate conviction about the stock's total return
A148: relative to the average total return of the analyst's industry (or industry team's) coverage universe,
... A394: © Copyright 2018 Morgan Stanley

Sheet TOC
A4: Becton Dickinson | D4: BDX.N
A6: Click on the following to go to specific sections of our BDX model:
A9: Quarterly Income Statement
A11: Quarterly Sales by Segment
A13: Quarterly Balance Sheet
A15: Quarterly Cash Flow Statement

Sheet IS
A1: Becton Dickinson
A2: Income Statement
A3: Dollars in millions, except per share data
A4: Fiscal year ends Sep 30
C5: 2007 | G5: =C5 -> 2007 | I5: =C5+1 -> 2008 | M5: =I5 -> 2008 | O5: =I5+1 -> 2009 | S5: =O5 -> 2009 | U5: =O5+1 -> 2010 | Y5: =U5 -> 2010 | AA5: =U5+1 -> 2011 | AE5: =AA5 -> 2011 | AG5: =AA5+1 -> 2012 | AK5: =AG5 -> 2012 | AM5: =AG5+1 -> 2013 | AQ5: =AM5 -> 2013 | AS5: =AM5+1 -> 2014 | AW5: =AS5 -> 2014 | AY5: =AS5+1 -> 2015 | BC5: =AY5 -> 2015 | BE5: =AY5+1 -> 2016 | BI5: =BE5 -> 2016 | BK5: =BE5+1 -> 2017 | BO5: =BK5 -> 2017 | BQ5: =BK5+1 -> 2018 | BU5: =BQ5 -> 2018 | BW5: =BQ5+1 -> 2019 | CA5: =BW5 -> 2019 | CC5: =BW5+1 -> 2020 | CG5: =CC5 -> 2020 | CI5: =CC5+1 -> 2021 | CM5: =CI5 -> 2021
C6: 39082 | D6: 39172 | E6: 39263 | F6: 39355 | I6: =F6+FLOOR(365/4,1)+1 -> 39447 | J6: =D6+365+1 -> 39538 | K6: =J6+FLOOR(365/4,1) -> 39629 | L6: =K6+FLOOR(365/4,1)+1 -> 39721 | O6: =L6+FLOOR(365/4,1)+1 -> 39813 | P6: =J6+365 -> 39903 | Q6: =P6+FLOOR(365/4,1) -> 39994 | R6: =Q6+FLOOR(365/4,1)+1 -> 40086 | U6: =R6+FLOOR(365/4,1)+1 -> 40178 | V6: =P6+365 -> 40268 | W6: =V6+FLOOR(365/4,1) -> 40359 | X6: =W6+FLOOR(365/4,1)+1 -> 40451 | AA6: =X6+FLOOR(365/4,1)+1 -> 40543 | AB6: =V6+365 -> 40633 | AC6: =AB6+FLOOR(365/4,1) -> 40724 | AD6: =AC6+FLOOR(365/4,1)+1 -> 40816 | AG6: =AD6+FLOOR(365/4,1)+1 -> 40908 | AH6: =AB6+365+1 -> 40999 | AI6: =AH6+FLOOR(365/4,1) -> 41090 | AJ6: =AI6+FLOOR(365/4,1)+1 -> 41182 | AM6: =AJ6+FLOOR(365/4,1)+1 -> 41274 | AN6: =AH6+365 -> 41364 | AO6: =AN6+FLOOR(365/4,1) -> 41455 | AP6: =AO6+FLOOR(365/4,1)+1 -> 41547 | AS6: =AP6+FLOOR(365/4,1)+1 -> 41639 | AT6: =AN6+365 -> 41729 | AU6: =AT6+FLOOR(365/4,1) -> 41820 | AV6: =AU6+FLOOR(365/4,1)+1 -> 41912 | AY6: =AV6+FLOOR(365/4,1)+1 -> 42004 | AZ6: =AT6+365 -> 42094 | BA6: =AZ6+FLOOR(365/4,1) -> 42185 | BB6: =BA6+FLOOR(365/4,1)+1 -> 42277 | BE6: =BB6+FLOOR(365/4,1)+1 -> 42369 | BF6: =AZ6+365+1 -> 42460 | BG6: =BF6+FLOOR(365/4,1) -> 42551 | BH6: =BG6+FLOOR(365/4,1)+1 -> 42643 | BK6: =BH6+FLOOR(365/4,1)+1 -> 42735 | BL6: =BF6+365 -> 42825 | BM6: =BL6+FLOOR(365/4,1) -> 42916 | BN6: =BM6+FLOOR(365/4,1)+1 -> 43008 | BQ6: =BN6+FLOOR(365/4,1)+1 -> 43100 | BR6: =BL6+365 -> 43190 | BS6: =BR6+FLOOR(365/4,1) -> 43281 | BT6: =BS6+FLOOR(365/4,1)+1 -> 43373 | BW6: =BT6+FLOOR(365/4,1)+1 -> 43465 | BX6: =BR6+365 -> 43555 | BY6: =BX6+FLOOR(365/4,1) -> 43646 | BZ6: =BY6+FLOOR(365/4,1)+1 -> 43738 | CC6: =BZ6+FLOOR(365/4,1)+1 -> 43830 | CD6: =BX6+365+1 -> 43921 | CE6: =CD6+FLOOR(365/4,1) -> 44012 | CF6: =CE6+FLOOR(365/4,1)+1 -> 44104 | CI6: =CF6+FLOOR(365/4,1)+1 -> 44196 | CJ6: =CD6+365 -> 44286 | CK6: =CJ6+FLOOR(365/4,1) -> 44377 | CL6: =CK6+FLOOR(365/4,1)+1 -> 44469
A7: Revenue | C7: 1501.534 | D7: 1575.922 | E7: 1631.159 | F7: 1651.101 | G7: 6359.716 | I7: 1705.767 | J7: 1746.925 | K7: 1867.588 | L7: 1835.631 | M7: 7155.911 | O7: 1673.148 | P7: 1683.142 | Q7: 1776.409 | R7: 1854.023 | S7: =SUM(O7:R7) -> 6986.722 | U7: 1868.818 | V7: 1799.409 | W7: 1830.911 | X7: 1873.195 | Y7: =SUM(U7:X7) -> 7372.333 | AA7: 1783.3537 | AB7: 1860.614 | AC7: 1951.889 | AD7: 1988.181 | AE7: =SUM(AA7:AD7) -> 7584.0377 | AG7: 1831.72 | AH7: 1928.961 | AI7: 1980.53 | AJ7: 1967.171 | AK7: =SUM(AG7:AJ7) -> 7708.382 | AM7: 1900.192 | AN7: 2000.375 | AO7: 2052.664 | AP7: 2100 | AQ7: =SUM(AM7:AP7) -> 8053.231 | AS7: 2014.9 | AT7: 2072 | AU7: 2156.8 | AV7: 2201.99 | AW7: =SUM(AS7:AV7) -> 8445.69 | AY7: 2051.14 | AZ7: 2050.45 | BA7: 3133 | BB7: 3067 | BC7: =SUM(AY7:BB7) -> 10301.59 | BE7: 2992.24 | BF7: 3071 | BG7: 3200 | BH7: 3234 | BI7: =SUM(BE7:BH7) -> 12497.24 | BK7: 2922 | BL7: 2969 | BM7: 3035 | BN7: 3166.49 | BO7: =SUM(BK7:BN7) -> 12092.49 | BQ7: 3080 | BR7: =BDX!BR69 -> 4160.551 | BS7: =BDX!BS69 -> 4300.105 | BT7: =BDX!BT69 -> 4359.769 | BU7: =SUM(BQ7:BT7) -> 15900.425 | BW7: =BDX!BW69 -> 4322.2334 | BX7: =BDX!BX69 -> 4385.98 | BY7: =BDX!BY69 -> 4527.9818 | BZ7: =BDX!BZ69 -> 4590.2554 | CA7: =SUM(BW7:BZ7) -> 17826.451 | CC7: =BDX!CC69 -> 4552.9028 | CD7: =BDX!CD69 -> 4618.0674 | CE7: =BDX!CE69 -> 4769.8669 | CF7: =BDX!CF69 -> 4834.8831 | CG7: =SUM(CC7:CF7) -> 18775.72 | CI7: =BDX!CI69 -> 4797.2495 | CJ7: =BDX!CJ69 -> 4863.7671 | CK7: =BDX!CK69 -> 5026.0855 | CL7: =BDX!CL69 -> 5093.9644 | CM7: =SUM(CI7:CL7) -> 19781.067
A8: COGS | AM8: 894.063 | AN8: 982.256 | AO8: 992.673 | AP8: 1014 | AQ8: =SUM(AM8:AP8) -> 3882.992 | AS8: 980 | AT8: 1019 | AU8: 1046 | AV8: 1079 | AW8: =SUM(AS8:AV8) -> 4124 | AY8: =AY9+AY10 -> 1005.6 | AZ8: =AZ9+AZ10 -> 1005.6 | BA8: =BA9+BA10 -> 1641.2 | BB8: =BB9+BB10 -> 1597.6 | BC8: =SUM(AY8:BB8) -> 5250 | BE8: =BE9+BE10 -> 1562.8 | BF8: =BF9+BF10 -> 1569.95 | BG8: =BG9+BG10 -> 1635.7 | BH8: =BH9+BH10 -> 1661.1 | BI8: =SUM(BE8:BH8) -> 6429.55 | BK8: =BK9+BK10 -> 1458.3 | BL8: =BL9+BL10 -> 1523.9 | BM8: =BM9+BM10 -> 1518.8 | BN8: =BN9+BN10 -> 1600.7 | BO8: =SUM(BK8:BN8) -> 6101.7 | BQ8: =BQ9+BQ10 -> 1512.5 | BR8: =BR9+BR10 -> 2016.9441 | BS8: =BS9+BS10 -> 2043.2493 | BT8: =BT9+BT10 -> 2060.0063 | BU8: =SUM(BQ8:BT8) -> 7632.6997 | BW8: =BW9+BW10 -> 2044.0537 | BX8: =BX9+BX10 -> 2066.76 | BY8: =BY9+BY10 -> 2131.4967 | BZ8: =BZ9+BZ10 -> 2148.7825 | CA8: =SUM(BW8:BZ8) -> 8391.0929 | CC8: =CC9+CC10 -> 2101.112 | CD8: =CD9+CD10 -> 2123.6024 | CE8: =CE9+CE10 -> 2191.3691 | CF8: =CF9+CF10 -> 2208.7461 | CG8: =SUM(CC8:CF8) -> 8624.8296 | CI8: =CI9+CI10 -> 2178.774 | CJ8: =CJ9+CJ10 -> 2235.2953 | CK8: =CK9+CK10 -> 2252.7213 | CL8: =CL9+CL10 -> 2270.16 | CM8: =SUM(CI8:CL8) -> 8936.9507
A9: Amortization of Intangibles | AM9: =CFS!AM13*0.925 -> 17.870075 | AN9: =CFS!AN13*0.925 -> 19.8875 | AO9: =CFS!AO13*0.925 -> 19.94115 | AP9: =CFS!AP13*0.925 -> 19.076275 | AQ9: =SUM(AM9:AP9) -> 76.775 | AS9: =CFS!AS13*0.88 -> 18.48 | AT9: =CFS!AT13*0.88 -> 18.48 | AU9: =CFS!AU13*0.88 -> 18.48 | AV9: =CFS!AV13*0.88 -> 18.92 | AW9: =SUM(AS9:AV9) -> 74.36 | AY9: =CFS!AY13*0.88 -> 17.6 | AZ9: =CFS!AZ13*0.88 -> 17.6 | BA9: =CFS!BA13*0.9 -> 136.8 | BB9: =CFS!BB13*0.9 -> 138.6 | BC9: =SUM(AY9:BB9) -> 310.6 | BE9: =CFS!BE13*0.9 -> 136.8 | BF9: =CFS!BF13*0.9 -> 124.2 | BG9: =CFS!BG13*0.9 -> 119.7 | BH9: =CFS!BH13*0.9 -> 116.1 | BI9: =SUM(BE9:BH9) -> 496.8 | BK9: =CFS!BK13*0.9 -> 123.3 | BL9: =CFS!BL13*0.9 -> 117.9 | BM9: =CFS!BM13*0.9 -> 118.8 | BN9: =CFS!BN13*0.9 -> 119.7 | BO9: =SUM(BK9:BN9) -> 479.7 | BQ9: =CFS!BQ13*0.9 -> 121.5 | BR9: =CFS!BR13*0.9 -> 207.10446 | BS9: =CFS!BS13*0.9 -> 207.10446 | BT9: =CFS!BT13*0.9 -> 207.10446 | BU9: =SUM(BQ9:BT9) -> 742.81339 | BW9: =CFS!BW13*0.9 -> 207.10446 | BX9: =CFS!BX13*0.9 -> 207.10446 | BY9: =CFS!BY13*0.9 -> 207.10446 | BZ9: =CFS!BZ13*0.9 -> 207.10446 | CA9: =SUM(BW9:BZ9) -> 828.41786 | CC9: =CFS!CC13*0.9 -> 207.10446 | CD9: =CFS!CD13*0.9 -> 207.10446 | CE9: =CFS!CE13*0.9 -> 207.10446 | CF9: =CFS!CF13*0.9 -> 207.10446 | CG9: =SUM(CC9:CF9) -> 828.41786 | CI9: =CFS!CI13*0.9 -> 207.10446 | CJ9: =CFS!CJ13*0.9 -> 207.10446 | CK9: =CFS!CK13*0.9 -> 207.10446 | CL9: =CFS!CL13*0.9 -> 207.10446 | CM9: =SUM(CI9:CL9) -> 828.41786
A10: Adj COGS | C10: 708.933 | D10: 764.54 | E10: 791.071 | F10: 807.377 | G10: =SUM(C10:F10) -> 3071.921 | I10: 829.846 | J10: 853.807 | K10: 917.362 | L10: 891.546 | M10: =SUM(I10:L10) -> 3492.561 | O10: 775.542 | P10: 807.382 | Q10: 838.555 | R10: 890.197 | S10: =SUM(O10:R10) -> 3311.676 | U10: 894.324 | V10: 864.492 | W10: 883.434 | X10: 900.933 | Y10: =SUM(U10:X10) -> 3543.183 | AA10: 840.166 | AB10: 891.262 | AC10: 922.652 | AD10: 971.041 | AE10: =AE7-AE11 -> 3625.121 | AG10: 900.465 | AH10: 941.184 | AI10: 947.395 | AJ10: =966.345-10 -> 956.345 | AK10: =AK7-AK11 -> 3745.389 | AM10: =AM8-AM9 -> 876.19292 | AN10: =AN8-AN9 -> 962.3685 | AO10: =AO8-AO9 -> 972.73185 | AP10: =AP8-AP9 -> 994.92372 | AQ10: =AQ8-AQ9 -> 3806.217 | AS10: =AS8-AS9 -> 961.52 | AT10: =AT8-AT9 -> 1000.52 | AU10: =AU8-AU9 -> 1027.52 | AV10: =AV8-AV9 -> 1060.08 | AW10: =AW7-AW11 -> 4049.64 | AY10: 988 | AZ10: =2051-1063 -> 988 | BA10: =1932+13-444+3+0.4 -> 1504.4 | BB10: =1630-178+7 -> 1459 | BC10: =BC7-BC11 -> 4939.4 | BE10: =2992-1566 -> 1426 | BF10: 1445.75 | BG10: =3200-1684 -> 1516 | BH10: =3234-1689 -> 1545 | BI10: =BI7-BI11 -> 5932.75 | BK10: =2922-1587 -> 1335 | BL10: =2969-1563 -> 1406 | BM10: =3035-1635 -> 1400 | BN10: 1481 | BO10: =BO7-BO11 -> 5622 | BQ10: =1530-133-6 -> 1391 | BR10: =BR7-BR11 -> 1809.8397 | BS10: =BS7-BS11 -> 1836.1448 | BT10: =BT7-BT11 -> 1852.9018 | BU10: =BU7-BU11 -> 6889.8863 | BW10: =BW7-BW11 -> 1836.9492 | BX10: =BX7-BX11 -> 1859.6555 | BY10: =BY7-BY11 -> 1924.3923 | BZ10: =BZ7-BZ11 -> 1941.678 | CA10: =CA7-CA11 -> 7562.675 | CC10: =CC7-CC11 -> 1894.0076 | CD10: =CD7-CD11 -> 1916.498 | CE10: =CE7-CE11 -> 1984.2646 | CF10: =CF7-CF11 -> 2001.6416 | CG10: =CG7-CG11 -> 7796.4118 | CI10: =CI7-CI11 -> 1971.6696 | CJ10: =CJ7-CJ11 -> 2028.1909 | CK10: =CK7-CK11 -> 2045.6168 | CL10: =CL7-CL11 -> 2063.0556 | CM10: =CM7-CM11 -> 8108.5328
A11: Gross Profit | C11: =C7-C10 -> 792.601 | D11: =D7-D10 -> 811.382 | E11: =E7-E10 -> 840.088 | F11: =F7-F10 -> 843.724 | G11: =G7-G10 -> 3287.795 | I11: =I7-I10 -> 875.921 | J11: =J7-J10 -> 893.118 | K11: =K7-K10 -> 950.226 | L11: =L7-L10 -> 944.085 | M11: =SUM(I11:L11) -> 3663.35 | O11: =O7-O10 -> 897.606 | P11: =P7-P10 -> 875.76 | Q11: =Q7-Q10 -> 937.854 | R11: =R7-R10 -> 963.826 | S11: =SUM(O11:R11) -> 3675.046 | U11: =U7-U10 -> 974.494 | V11: =V7-V10 -> 934.917 | W11: =W7-W10 -> 947.477 | X11: =X7-X10 -> 972.262 | Y11: =SUM(U11:X11) -> 3829.15 | AA11: =AA7-AA10 -> 943.1877 | AB11: =AB7-AB10 -> 969.352 | AC11: =AC7-AC10 -> 1029.237 | AD11: =AD7-AD10 -> 1017.14 | AE11: =SUM(AA11:AD11) -> 3958.9167 | AG11: =AG7-AG10 -> 931.255 | AH11: =AH7-AH10 -> 987.777 | AI11: =AI7-AI10 -> 1033.135 | AJ11: =AJ7-AJ10 -> 1010.826 | AK11: =SUM(AG11:AJ11) -> 3962.993 | AM11: =AM7-AM10 -> 1023.9991 | AN11: =AN7-AN10 -> 1038.0065 | AO11: =AO7-AO10 -> 1079.9321 | AP11: =AP7-AP10 -> 1105.0763 | AQ11: =SUM(AM11:AP11) -> 4247.014 | AS11: =AS7-AS10 -> 1053.38 | AT11: =AT7-AT10 -> 1071.48 | AU11: =AU7-AU10 -> 1129.28 | AV11: =AV7-AV10 -> 1141.91 | AW11: =SUM(AS11:AV11) -> 4396.05 | AY11: =AY7-AY10 -> 1063.14 | AZ11: =AZ7-AZ10 -> 1062.45 | BA11: =BA7-BA10 -> 1628.6 | BB11: =BB7-BB10 -> 1608 | BC11: =SUM(AY11:BB11) -> 5362.19 | BE11: =BE7-BE10 -> 1566.24 | BF11: =BF7-BF10 -> 1625.25 | BG11: =BG7-BG10 -> 1684 | BH11: =BH7-BH10 -> 1689 | BI11: =SUM(BE11:BH11) -> 6564.49 | BK11: =BK7-BK10 -> 1587 | BL11: =BL7-BL10 -> 1563 | BM11: =BM7-BM10 -> 1635 | BN11: =BN7-BN10 -> 1685.49 | BO11: =SUM(BK11:BN11) -> 6470.49 | BQ11: =BQ7-BQ10 -> 1689 | BR11: =BR7*BR37 -> 2350.7113 | BS11: =BS7*BS37 -> 2463.9602 | BT11: =BT7*BT37 -> 2506.8672 | BU11: =SUM(BQ11:BT11) -> 9010.5387 | BW11: =BW7*BW37 -> 2485.2842 | BX11: =BX7*BX37 -> 2526.3245 | BY11: =BY7*BY37 -> 2603.5896 | BZ11: =BZ7*BZ37 -> 2648.5774 | CA11: =SUM(BW11:BZ11) -> 10263.776 | CC11: =CC7*CC37 -> 2658.8953 | CD11: =CD7*CD37 -> 2701.5694 | CE11: =CE7*CE37 -> 2785.6022 | CF11: =CF7*CF37 -> 2833.2415 | CG11: =SUM(CC11:CF11) -> 10979.308 | CI11: =CI7*CI37 -> 2825.58 | CJ11: =CJ7*CJ37 -> 2835.5762 | CK11: =CK7*CK37 -> 2980.4687 | CL11: =CL7*CL37 -> 3030.9088 | CM11: =SUM(CI11:CL11) -> 11672.534
A12: Adj SG&A | C12: 384.084 | D12: 406.631 | E12: 412.164 | F12: 399.525 | G12: =SUM(C12:F12) -> 1602.404 | I12: =421.718 -> 421.718 | J12: 415.523 | K12: 440.588 | L12: 437.216 | M12: =SUM(I12:L12) -> 1715.045 | O12: 399.668 | P12: 430.608 | Q12: 423.513 | R12: 427.008 | S12: =SUM(O12:R12) -> 1680.797 | U12: 445.673 | V12: 421.076 | W12: 416.468 | X12: 438.139 | Y12: =SUM(U12:X12) -> 1721.356 | AA12: 440.955 | AB12: 435.024 | AC12: 467.968 | AD12: 479.591 | AE12: =SUM(AA12:AD12) -> 1823.538 | AG12: 482.271 | AH12: 487.694 | AI12: 469.13 | AJ12: =484.259-8 -> 476.259 | AK12: =SUM(AG12:AJ12) -> 1915.354 | AM12: 495.878 | AN12: =514.61 -> 514.61 | AO12: =534.32-22 -> 512.32 | AP12: =877-341-6 -> 530 | AQ12: =SUM(AM12:AP12) -> 2052.808 | AS12: =531 -> 531 | AT12: =525-11 -> 514 | AU12: 528 | AV12: 542 | AW12: =SUM(AS12:AV12) -> 2115 | AY12: 532 | AZ12: 511 | BA12: =764-3+0.4 -> 761.4 | BB12: =756-9 -> 747 | BC12: =SUM(AY12:BB12) -> 2551.4 | BE12: 745 | BF12: 750.75 | BG12: 728 | BH12: 789 | BI12: =SUM(BE12:BH12) -> 3012.75 | BK12: 711 | BL12: 721 | BM12: 719 | BN12: 774 | BO12: =SUM(BK12:BN12) -> 2925 | BQ12: =774-1-1 -> 772 | BR12: =BR13+BR14 -> 1027.6561 | BS12: =BS13+BS14 -> 1023.425 | BT12: =BT13+BT14 -> 1068.1434 | BU12: =SUM(BQ12:BT12) -> 3891.2245 | BW12: =BW13+BW14 -> 1037.336 | BX12: =BX13+BX14 -> 1039.4773 | BY12: =BY13+BY14 -> 1064.0757 | BZ12: =BZ13+BZ14 -> 1092.4808 | CA12: =SUM(BW12:BZ12) -> 4233.3698 | CC12: =CC13+CC14 -> 1047.1677 | CD12: =CD13+CD14 -> 1048.3013 | CE12: =CE13+CE14 -> 1073.22 | CF12: =CF13+CF14 -> 1102.3534 | CG12: =SUM(CC12:CF12) -> 4271.0424 | CI12: =CI13+CI14 -> 1074.5839 | CJ12: =CJ13+CJ14 -> 1074.8925 | CK12: =CK13+CK14 -> 1100.7127 | CL12: =CL13+CL14 -> 1130.8601 | CM12: =SUM(CI12:CL12) -> 4381.0492
A13: Core SG&A | C13: =C12-C14 -> 384.084 | D13: =D12-D14 -> 406.631 | E13: =E12-E14 -> 412.164 | F13: =F12-F14 -> 399.525 | G13: =SUM(C13:F13) -> 1602.404 | I13: =I12-I14 -> 421.718 | J13: =J12-J14 -> 415.523 | K13: =K12-K14 -> 440.588 | L13: =L12-L14 -> 437.216 | M13: =SUM(I13:L13) -> 1715.045 | O13: =O12-O14 -> 399.668 | P13: =P12-P14 -> 430.608 | Q13: =Q12-Q14 -> 423.513 | R13: =R12-R14 -> 427.008 | S13: =SUM(O13:R13) -> 1680.797 | U13: =U12-U14 -> 445.673 | V13: =V12-V14 -> 421.076 | W13: =W12-W14 -> 416.468 | X13: =X12-X14 -> 438.139 | Y13: =SUM(U13:X13) -> 1721.356 | AA13: =AA12-AA14 -> 440.955 | AB13: =AB12-AB14 -> 435.024 | AC13: =AC12-AC14 -> 467.968 | AD13: =AD12-AD14 -> 479.591 | AE13: =SUM(AA13:AD13) -> 1823.538 | AG13: =AG12-AG14 -> 482.271 | AH13: =AH12-AH14 -> 487.694 | AI13: =AI12-AI14 -> 469.13 | AJ13: =AJ12-AJ14 -> 476.259 | AK13: =SUM(AG13:AJ13) -> 1915.354 | AM13: =AM12-AM14 -> 495.878 | AN13: =AN12-AN14 -> 500.60737 | AO13: =AO12-AO14 -> 497.95135 | AP13: =AP12-AP14 -> 516.98 | AQ13: =SUM(AM13:AP13) -> 2011.4167 | AS13: =AS12-AS14 -> 518.50762 | AT13: =AT12-AT14 -> 499.496 | AU13: =AU12-AU14 -> 512.9024 | AV13: =AV12-AV14 -> 526.58607 | AW13: =SUM(AS13:AV13) -> 2057.4921 | AY13: =AY12-AY14 -> 519.28293 | AZ13: =AZ12-AZ14 -> 498.6973 | BA13: =BA12-BA14 -> 742.602 | BB13: =BB12-BB14 -> 728.598 | BC13: =SUM(AY13:BB13) -> 2489.1802 | BE13: =BE12-BE14 -> 745 | BF13: =BF12-BF14 -> 750.75 | BG13: =BG12-BG14 -> 728 | BH13: =BH12-BH14 -> 789 | BI13: =SUM(BE13:BH13) -> 3012.75 | BK13: =+BK12-BK14 -> 711 | BL13: =BL12-BL14 -> 721 | BM13: =BM12-BM14 -> 719 | BN13: =BN12-BN14 -> 774 | BO13: =SUM(BK13:BN13) -> 2925 | BQ13: =+BQ12-BQ14 -> 772 | BR13: =BR7*BR39 -> 1027.6561 | BS13: =BS7*BS39 -> 1023.425 | BT13: =BT7*BT39 -> 1068.1434 | BU13: =SUM(BQ13:BT13) -> 3891.2245 | BW13: =BW7*BW39 -> 1037.336 | BX13: =BX7*BX39 -> 1039.4773 | BY13: =BY7*BY39 -> 1064.0757 | BZ13: =BZ7*BZ39 -> 1092.4808 | CA13: =SUM(BW13:BZ13) -> 4233.3698 | CC13: =CC7*CC39 -> 1047.1677 | CD13: =CD7*CD39 -> 1048.3013 | CE13: =CE7*CE39 -> 1073.22 | CF13: =CF7*CF39 -> 1102.3534 | CG13: =SUM(CC13:CF13) -> 4271.0424 | CI13: =CI7*CI39 -> 1074.5839 | CJ13: =CJ7*CJ39 -> 1074.8925 | CK13: =CK7*CK39 -> 1100.7127 | CL13: =CL7*CL39 -> 1130.8601 | CM13: =SUM(CI13:CL13) -> 4381.0492
A14: Medtech Tax | C14: 0 | D14: 0 | E14: 0 | F14: 0 | G14: =SUM(C14:F14) -> 0 | I14: 0 | J14: 0 | K14: 0 | L14: 0 | M14: =SUM(I14:L14) -> 0 | O14: 0 | P14: 0 | Q14: 0 | R14: 0 | S14: =SUM(O14:R14) -> 0 | U14: 0 | V14: 0 | W14: 0 | X14: 0 | Y14: =SUM(U14:X14) -> 0 | AA14: 0 | AB14: 0 | AC14: 0 | AD14: 0 | AE14: =SUM(AA14:AD14) -> 0 | AG14: 0 | AH14: 0 | AI14: 0 | AJ14: 0 | AK14: =SUM(AG14:AJ14) -> 0 | AM14: 0 | AN14: =AN7*AN40 -> 14.002625 | AO14: =AO7*AO40 -> 14.368648 | AP14: =AP7*AP40 -> 13.02 | AQ14: =SUM(AM14:AP14) -> 41.391273 | AS14: =AS7*AS40 -> 12.49238 | AT14: =AT7*AT40 -> 14.504 | AU14: =AU7*AU40 -> 15.0976 | AV14: =AV7*AV40 -> 15.41393 | AW14: =SUM(AS14:AV14) -> 57.50791 | AY14: =AY7*AY40 -> 12.717068 | AZ14: =AZ7*AZ40 -> 12.3027 | BA14: =BA7*BA40 -> 18.798 | BB14: =BB7*BB40 -> 18.402 | BC14: =SUM(AY14:BB14) -> 62.219768 | BE14: =BE7*BE40 -> 0 | BF14: =BF7*BF40 -> 0 | BG14: =BG7*BG40 -> 0 | BH14: =BH7*BH40 -> 0 | BI14: =SUM(BE14:BH14) -> 0 | BK14: =BK7*BK40 -> 0 | BL14: =BL7*BL40 -> 0 | BM14: =BM7*BM40 -> 0 | BN14: =BN7*BN40 -> 0 | BO14: =SUM(BK14:BN14) -> 0 | BQ14: =BQ7*BQ40 -> 0 | BR14: =BR7*BR40 -> 0 | BS14: =BS7*BS40 -> 0 | BT14: =BT7*BT40 -> 0 | BU14: =SUM(BQ14:BT14) -> 0 | BW14: =BW7*BW40 -> 0 | BX14: =BX7*BX40 -> 0 | BY14: =BY7*BY40 -> 0 | BZ14: =BZ7*BZ40 -> 0 | CA14: =SUM(BW14:BZ14) -> 0 | CC14: =CC7*CC40 -> 0 | CD14: =CD7*CD40 -> 0 | CE14: =CE7*CE40 -> 0 | CF14: =CF7*CF40 -> 0 | CG14: =SUM(CC14:CF14) -> 0 | CI14: =CI7*CI40 -> 0 | CJ14: =CJ7*CJ40 -> 0 | CK14: =CK7*CK40 -> 0 | CL14: =CL7*CL40 -> 0 | CM14: =SUM(CI14:CL14) -> 0
A15: R&D | C15: 79.94 | D15: 86.687 | E15: 92.993 | F15: 100.43 | G15: =SUM(C15:F15) -> 360.05 | I15: 91.527 | J15: 96.034 | K15: 100.071 | L15: 108.606 | M15: =SUM(I15:L15) -> 396.238 | O15: 96.356 | P15: 97.7 | Q15: 97.621 | R15: 112.89 | S15: =SUM(O15:R15) -> 404.567 | U15: 99.151 | V15: 100.193 | W15: 108.047 | X15: 123.606 | Y15: =SUM(U15:X15) -> 430.997 | AA15: 113.568 | AB15: 117.343 | AC15: 114.078 | AD15: =124.528-9.27 -> 115.258 | AE15: =SUM(AA15:AD15) -> 460.247 | AG15: 112.227 | AH15: 116.753 | AI15: 114.987 | AJ15: =127.787-2 -> 125.787 | AK15: =SUM(AG15:AJ15) -> 469.754 | AM15: 118.162 | AN15: 122.377 | AO15: 121.116 | AP15: 133 | AQ15: =SUM(AM15:AP15) -> 494.655 | AS15: 126 | AT15: =147-20 -> 127 | AU15: 128 | AV15: 133 | AW15: =SUM(AS15:AV15) -> 514 | AY15: 129 | AZ15: 129 | BA15: =178+2+0.1 -> 180.1 | BB15: 196 | BC15: =SUM(AY15:BB15) -> 634.1 | BE15: 187 | BF15: 181.75 | BG15: 207 | BH15: 253 | BI15: =SUM(BE15:BH15) -> 828.75 | BK15: 182 | BL15: 187 | BM15: =186-1 -> 185 | BN15: 221 | BO15: =SUM(BK15:BN15) -> 775 | BQ15: 192 | BR15: =BR7*BR41 -> 270.43581 | BS15: =BS7*BS41 -> 283.80693 | BT15: =BT7*BT41 -> 296.46429 | BU15: =SUM(BQ15:BT15) -> 1042.707 | BW15: =BW7*BW41 -> 289.58964 | BX15: =BX7*BX41 -> 289.47468 | BY15: =BY7*BY41 -> 298.8468 | BZ15: =BZ7*BZ41 -> 302.95686 | CA15: =SUM(BW15:BZ15) -> 1180.868 | CC15: =CC7*CC41 -> 291.38578 | CD15: =CD7*CD41 -> 290.93825 | CE15: =CE7*CE41 -> 300.50161 | CF15: =CF7*CF41 -> 304.59764 | CG15: =SUM(CC15:CF15) -> 1187.4233 | CI15: =CI7*CI41 -> 299.8281 | CJ15: =CJ7*CJ41 -> 299.12167 | CK15: =CK7*CK41 -> 309.10426 | CL15: =CL7*CL41 -> 313.27881 | CM15: =SUM(CI15:CL15) -> 1221.3328
A16: Total Operating Expenses | C16: =C12+C15 -> 464.024 | D16: =D12+D15 -> 493.318 | E16: =E12+E15 -> 505.157 | F16: =F12+F15 -> 499.955 | G16: =G12+G15 -> 1962.454 | I16: =I12+I15 -> 513.245 | J16: =J12+J15 -> 511.557 | K16: =K12+K15 -> 540.659 | L16: =L12+L15 -> 545.822 | M16: =M12+M15 -> 2111.283 | O16: =O12+O15 -> 496.024 | P16: =P12+P15 -> 528.308 | Q16: =Q12+Q15 -> 521.134 | R16: =R12+R15 -> 539.898 | S16: =S12+S15 -> 2085.364 | U16: =U12+U15 -> 544.824 | V16: =V12+V15 -> 521.269 | W16: =W12+W15 -> 524.515 | X16: =X12+X15 -> 561.745 | Y16: =Y12+Y15 -> 2152.353 | AA16: =AA12+AA15 -> 554.523 | AB16: =AB12+AB15 -> 552.367 | AC16: =AC12+AC15 -> 582.046 | AD16: =AD12+AD15 -> 594.849 | AE16: =AE12+AE15 -> 2283.785 | AG16: =AG12+AG15 -> 594.498 | AH16: =AH12+AH15 -> 604.447 | AI16: =AI12+AI15 -> 584.117 | AJ16: =AJ12+AJ15 -> 602.046 | AK16: =AK12+AK15 -> 2385.108 | AM16: =AM12+AM15 -> 614.04 | AN16: =AN12+AN15 -> 636.987 | AO16: =AO12+AO15 -> 633.436 | AP16: =AP12+AP15 -> 663 | AQ16: =AQ12+AQ15 -> 2547.463 | AS16: =AS12+AS15 -> 657 | AT16: =AT12+AT15 -> 641 | AU16: =AU12+AU15 -> 656 | AV16: =AV12+AV15 -> 675 | AW16: =AW12+AW15 -> 2629 | AY16: =AY12+AY15 -> 661 | AZ16: =AZ12+AZ15 -> 640 | BA16: =BA12+BA15 -> 941.5 | BB16: =BB12+BB15 -> 943 | BC16: =BC12+BC15 -> 3185.5 | BE16: =BE12+BE15 -> 932 | BF16: =BF12+BF15 -> 932.5 | BG16: =BG12+BG15 -> 935 | BH16: =BH12+BH15 -> 1042 | BI16: =BI12+BI15 -> 3841.5 | BK16: =BK12+BK15 -> 893 | BL16: =BL12+BL15 -> 908 | BM16: =BM12+BM15 -> 904 | BN16: =BN12+BN15 -> 995 | BO16: =BO12+BO15 -> 3700 | BQ16: =BQ12+BQ15 -> 964 | BR16: =BR12+BR15 -> 1298.0919 | BS16: =BS12+BS15 -> 1307.2319 | BT16: =BT12+BT15 -> 1364.6077 | BU16: =BU12+BU15 -> 4933.9315 | BW16: =BW12+BW15 -> 1326.9257 | BX16: =BX12+BX15 -> 1328.9519 | BY16: =BY12+BY15 -> 1362.9225 | BZ16: =BZ12+BZ15 -> 1395.4376 | CA16: =CA12+CA15 -> 5414.2378 | CC16: =CC12+CC15 -> 1338.5534 | CD16: =CD12+CD15 -> 1339.2395 | CE16: =CE12+CE15 -> 1373.7217 | CF16: =CF12+CF15 -> 1406.951 | CG16: =CG12+CG15 -> 5458.4656 | CI16: =CI12+CI15 -> 1374.412 | CJ16: =CJ12+CJ15 -> 1374.0142 | CK16: =CK12+CK15 -> 1409.817 | CL16: =CL12+CL15 -> 1444.1389 | CM16: =CM12+CM15 -> 5602.3821
A17: Operating Income | C17: =C11-C12-C15 -> 328.577 | D17: =D11-D12-D15 -> 318.064 | E17: =E11-E12-E15 -> 334.931 | F17: =F11-F12-F15 -> 343.769 | G17: =G11-G12-G15 -> 1325.341 | I17: =I11-I12-I15 -> 362.676 | J17: =J11-J12-J15 -> 381.561 | K17: =K11-K12-K15 -> 409.567 | L17: =L11-L12-L15 -> 398.263 | M17: =M11-M12-M15 -> 1552.067 | O17: =O11-O12-O15 -> 401.582 | P17: =P11-P12-P15 -> 347.452 | Q17: =Q11-Q12-Q15 -> 416.72 | R17: =R11-R12-R15 -> 423.928 | S17: =S11-S12-S15 -> 1589.682 | U17: =U11-U12-U15 -> 429.67 | V17: =V11-V12-V15 -> 413.648 | W17: =W11-W12-W15 -> 422.962 | X17: =X11-X12-X15 -> 410.517 | Y17: =Y11-Y12-Y15 -> 1676.797 | AA17: =AA11-AA12-AA15 -> 388.6647 | AB17: =AB11-AB12-AB15 -> 416.985 | AC17: =AC11-AC12-AC15 -> 447.191 | AD17: =AD11-AD12-AD15 -> 422.291 | AE17: =AE11-AE12-AE15 -> 1675.1317 | AG17: =AG11-AG12-AG15 -> 336.757 | AH17: =AH11-AH12-AH15 -> 383.33 | AI17: =AI11-AI12-AI15 -> 449.018 | AJ17: =AJ11-AJ12-AJ15 -> 408.78 | AK17: =SUM(AG17:AJ17) -> 1577.885 | AM17: =AM11-AM12-AM15 -> 409.95907 | AN17: =AN11-AN12-AN15 -> 401.0195 | AO17: =AO11-AO12-AO15 -> 446.49615 | AP17: =AP11-AP12-AP15 -> 442.07627 | AQ17: =SUM(AM17:AP17) -> 1699.551 | AS17: =AS11-AS12-AS15 -> 396.38 | AT17: =AT11-AT12-AT15 -> 430.48 | AU17: =AU11-AU12-AU15 -> 473.28 | AV17: =AV11-AV12-AV15 -> 466.91 | AW17: =SUM(AS17:AV17) -> 1767.05 | AY17: =AY11-AY12-AY15 -> 402.14 | AZ17: =AZ11-AZ12-AZ15 -> 422.45 | BA17: =BA11-BA12-BA15 -> 687.1 | BB17: =BB11-BB12-BB15 -> 665 | BC17: =SUM(AY17:BB17) -> 2176.69 | BE17: =BE11-BE12-BE15 -> 634.24 | BF17: =BF11-BF12-BF15 -> 692.75 | BG17: =BG11-BG12-BG15 -> 749 | BH17: =BH11-BH12-BH15 -> 647 | BI17: =SUM(BE17:BH17) -> 2722.99 | BK17: =BK11-BK12-BK15 -> 694 | BL17: =BL11-BL12-BL15 -> 655 | BM17: =BM11-BM12-BM15 -> 731 | BN17: =BN11-BN12-BN15 -> 690.49 | BO17: =SUM(BK17:BN17) -> 2770.49 | BQ17: =BQ11-BQ12-BQ15 -> 725 | BR17: =BR11-BR12-BR15 -> 1052.6194 | BS17: =BS11-BS12-BS15 -> 1156.7282 | BT17: =BT11-BT12-BT15 -> 1142.2595 | BU17: =SUM(BQ17:BT17) -> 4076.6071 | BW17: =BW11-BW12-BW15 -> 1158.3585 | BX17: =BX11-BX12-BX15 -> 1197.3725 | BY17: =BY11-BY12-BY15 -> 1240.667 | BZ17: =BZ11-BZ12-BZ15 -> 1253.1397 | CA17: =SUM(BW17:BZ17) -> 4849.5378 | CC17: =CC11-CC12-CC15 -> 1320.3418 | CD17: =CD11-CD12-CD15 -> 1362.3299 | CE17: =CE11-CE12-CE15 -> 1411.8806 | CF17: =CF11-CF12-CF15 -> 1426.2905 | CG17: =SUM(CC17:CF17) -> 5520.8428 | CI17: =CI11-CI12-CI15 -> 1451.168 | CJ17: =CJ11-CJ12-CJ15 -> 1461.562 | CK17: =CK11-CK12-CK15 -> 1570.6517 | CL17: =CL11-CL12-CL15 -> 1586.7699 | CM17: =SUM(CI17:CL17) -> 6070.1516
A18: EBITDA | C18: =CFS!C11+C17 -> 429.658 | D18: =CFS!D11+D17 -> 428.011 | E18: =CFS!E11+E17 -> 447.468 | F18: =CFS!F11+F17 -> 461.545 | G18: =SUM(C18:F18) -> 1766.682 | I18: =CFS!I11+I17 -> 477.888 | J18: =CFS!J11+J17 -> 498.408 | K18: =CFS!K11+K17 -> 530.621 | L18: =CFS!L11+L17 -> 522.572 | M18: =SUM(I18:L18) -> 2029.489 | O18: =CFS!O11+O17 -> 518.1 | P18: =CFS!P11+P17 -> 464.73 | Q18: =CFS!Q11+Q17 -> 535.17 | R18: =CFS!R11+R17 -> 541.875 | S18: =SUM(O18:R18) -> 2059.875 | U18: =CFS!U11+U17 -> 554.891 | V18: =CFS!V11+V17 -> 540.454 | W18: =CFS!W11+W17 -> 553.94 | X18: =CFS!X11+X17 -> 529.625 | Y18: =SUM(U18:X18) -> 2178.91 | AA18: =CFS!AA11+AA17 -> 511.8567 | AB18: =CFS!AB11+AB17 -> 539.19 | AC18: =CFS!AC11+AC17 -> 574.004 | AD18: =CFS!AD11+AD17 -> 554.17 | AE18: =SUM(AA18:AD18) -> 2179.2207 | AG18: =CFS!AG11+AG17 -> 472.375 | AH18: =CFS!AH11+AH17 -> 513.593 | AI18: =CFS!AI11+AI17 -> 566.696 | AJ18: =CFS!AJ11+AJ17 -> 536.159 | AK18: =SUM(AG18:AJ18) -> 2088.823 | AM18: =CFS!AM11+AM17 -> 538.79207 | AN18: =CFS!AN11+AN17 -> 537.6635 | AO18: =CFS!AO11+AO17 -> 584.70015 | AP18: =CFS!AP11+AP17 -> 584.39527 | AQ18: =SUM(AM18:AP18) -> 2245.551 | AS18: =CFS!AS11+AS17 -> 538.38 | AT18: =CFS!AT11+AT17 -> 560.48 | AU18: =CFS!AU11+AU17 -> 614.28 | AV18: =CFS!AV11+AV17 -> 616.41 | AW18: =SUM(AS18:AV18) -> 2329.55 | AY18: =CFS!AY12+AY17 -> 511.14 | AZ18: =CFS!AZ12+AZ17 -> 530.45 | BA18: =CFS!BA12+BA17 -> 811.6 | BB18: =CFS!BB12+BB17 -> 803.5 | BC18: =SUM(AY18:BB18) -> 2656.69 | BE18: =CFS!BE12+BE17 -> 771.24 | BF18: =CFS!BF12+BF17 -> 834.75 | BG18: =CFS!BG12+BG17 -> 888 | BH18: =CFS!BH12+BH17 -> 791 | BI18: =SUM(BE18:BH18) -> 3284.99 | BK18: =CFS!BK12+BK17 -> 819 | BL18: =CFS!BL12+BL17 -> 785 | BM18: =CFS!BM12+BM17 -> 878 | BN18: =CFS!BN12+BN17 -> 843.49 | BO18: =SUM(BK18:BN18) -> 3325.49 | BQ18: =CFS!BQ12+BQ17 -> 880 | BR18: =CFS!BR12+BR17 -> 1226.9125 | BS18: =CFS!BS12+BS17 -> 1334.9007 | BT18: =CFS!BT12+BT17 -> 1324.3112 | BU18: =SUM(BQ18:BT18) -> 4766.1244 | BW18: =CFS!BW12+BW17 -> 1344.2896 | BX18: =CFS!BX12+BX17 -> 1386.9243 | BY18: =CFS!BY12+BY17 -> 1433.8394 | BZ18: =CFS!BZ12+BZ17 -> 1449.9328 | CA18: =SUM(BW18:BZ18) -> 5614.9861 | CC18: =CFS!CC12+CC17 -> 1520.7556 | CD18: =CFS!CD12+CD17 -> 1566.3644 | CE18: =CFS!CE12+CE17 -> 1619.5358 | CF18: =CFS!CF12+CF17 -> 1637.5664 | CG18: =SUM(CC18:CF18) -> 6344.2221 | CI18: =CFS!CI12+CI17 -> 1666.0645 | CJ18: =CFS!CJ12+CJ17 -> 1680.0792 | CK18: =CFS!CK12+CK17 -> 1792.7897 | CL18: =CFS!CL12+CL17 -> 1812.5285 | CM18: =SUM(CI18:CL18) -> 6951.462
A19: Net Interest Income (Expense) | C19: =C21-C20 -> 3.246 | D19: =D21-D20 -> -2.6 | E19: =E21-E20 -> 0.34 | F19: =F21-F20 -> -1.185 | G19: =G21-G20 -> -0.199 | I19: =I21-I20 -> 3.189 | J19: =J21-J20 -> -0.093 | K19: =K21-K20 -> 1.939 | L19: =L21-L20 -> -2.01 | M19: =SUM(I19:L19) -> 3.025 | O19: =O21-O20 -> -6.173 | P19: =P21-P20 -> -3.183 | Q19: =Q21-Q20 -> 1.479 | R19: =R21-R20 -> 0.636 | S19: =SUM(O19:R19) -> -7.241 | U19: =U21-U20 -> -4.198 | V19: =V21-V20 -> -3.261 | W19: =W21-W20 -> -10.991 | X19: =X21-X20 -> 2.316 | Y19: =SUM(U19:X19) -> -16.134 | AA19: =AA21-AA20 -> -0.331 | AB19: =AB21-AB20 -> -9.357 | AC19: =AC21-AC20 -> -10.703 | AD19: =AD21-AD20 -> -20.419 | AE19: =SUM(AA19:AD19) -> -40.81 | AG19: =AG21-AG20 -> -13.93 | AH19: =AH21-AH20 -> -18.462 | AI19: =AI21-AI20 -> -28.596 | AJ19: =AJ21-AJ20 -> -23.338 | AK19: =SUM(AG19:AJ19) -> -84.326 | AM19: =AM21-AM20 -> -27.107 | AN19: =AN21-AN20 -> -22.914 | AO19: =AO21-AO20 -> -28.301 | AP19: =AP21-AP20 -> -20 | AQ19: =SUM(AM19:AP19) -> -98.322 | AS19: =AS21-AS20 -> -20 | AT19: =AT21-AT20 -> -23 | AU19: =AU21-AU20 -> -21 | AV19: =AV21-AV20 -> -26 | AW19: =SUM(AS19:AV19) -> -90 | AY19: =AY21-AY20 -> -22 | AZ19: =AZ21-AZ20 -> -25 | BA19: =BA21-BA20 -> -106 | BB19: =BB21-BB20 -> -112 | BC19: =SUM(AY19:BB19) -> -265 | BE19: =BE21-BE20 -> -99 | BF19: =BF21-BF20 -> -104 | BG19: =BG21-BG20 -> -100 | BH19: =BH21-BH20 -> -96 | BI19: =SUM(BE19:BH19) -> -399 | BK19: =BK21-BK20 -> -96 | BL19: =BL21-BL20 -> -83 | BM19: =BM21-BM20 -> -81 | BN19: =BN21-BN20 -> -68 | BO19: =SUM(BK19:BN19) -> -328 | BQ19: =BQ21-BQ20 -> -65 | BR19: =BR21-BR20 -> -185.25457 | BS19: =BS21-BS20 -> -184.7588 | BT19: =BT21-BT20 -> -180.7981 | BU19: =SUM(BQ19:BT19) -> -615.81146 | BW19: =BW21-BW20 -> -176.72912 | BX19: =BX21-BX20 -> -172.32783 | BY19: =BY21-BY20 -> -169.46154 | BZ19: =BZ21-BZ20 -> -168.02538 | CA19: =SUM(BW19:BZ19) -> -686.54387 | CC19: =CC21-CC20 -> -163.77349 | CD19: =CD21-CD20 -> -158.95453 | CE19: =CE21-CE20 -> -153.12141 | CF19: =CF21-CF20 -> -148.29192 | CG19: =SUM(CC19:CF19) -> -624.14136 | CI19: =CI21-CI20 -> -142.22454 | CJ19: =CJ21-CJ20 -> -138.63762 | CK19: =CK21-CK20 -> -132.35501 | CL19: =CL21-CL20 -> -125.59378 | CM19: =SUM(CI19:CL19) -> -538.81095
A20: Interest Expense | C20: 12.868 | D20: 11.686 | E20: 11.598 | F20: 10.268 | G20: =SUM(C20:F20) -> 46.42 | I20: 10.339 | J20: 8.098 | K20: 9.017 | L20: 8.889 | M20: =SUM(I20:L20) -> 36.343 | O20: 7.824 | P20: 7.495 | Q20: 11.288 | R20: 13.782 | S20: =SUM(O20:R20) -> 40.389 | U20: 12.987 | V20: 12.913 | W20: 13.085 | X20: 12.278 | Y20: =SUM(U20:X20) -> 51.263 | AA20: 15.553 | AB20: 23.921 | AC20: 22.211 | AD20: 22.334 | AE20: =SUM(AA20:AD20) -> 84.019 | AG20: 29.378 | AH20: 35.14 | AI20: 34.849 | AJ20: 35.292 | AK20: =SUM(AG20:AJ20) -> 134.659 | AM20: 35.029 | AN20: 34.732 | AO20: 34.573 | AP20: 34 | AQ20: =SUM(AM20:AP20) -> 138.334 | AS20: 34 | AT20: 33 | AU20: 33 | AV20: 35 | AW20: =SUM(AS20:AV20) -> 135 | AY20: 32 | AZ20: 33 | BA20: =105+8-5 -> 108 | BB20: =99+8 -> 107 | BC20: =SUM(AY20:BB20) -> 280 | BE20: =97+8 -> 105 | BF20: 107 | BG20: 105 | BH20: =95+8 -> 103 | BI20: =SUM(BE20:BH20) -> 420 | BK20: 101 | BL20: =86+4 -> 90 | BM20: =184-87 -> 97 | BN20: =156-44+1 -> 113 | BO20: =SUM(BK20:BN20) -> 401 | BQ20: =158-50+1 -> 109 | BR20: 187.51957 | BS20: 186.58207 | BT20: 183.19457 | BU20: =SUM(BQ20:BT20) -> 666.2962 | BW20: 179.85082 | BX20: 175.78832 | BY20: 173.28832 | BZ20: 171.4362 | CA20: =SUM(BW20:BZ20) -> 700.36365 | CC20: 168.8487 | CD20: 163.73151 | CE20: 156.22701 | CF20: 152.09201 | CG20: =SUM(CC20:CF20) -> 640.89923 | CI20: 145.77951 | CJ20: 144.15451 | CK20: 139.40009 | CL20: 133.15009 | CM20: =SUM(CI20:CL20) -> 562.48422
A21: Interest Income | C21: 16.114 | D21: 9.086 | E21: 11.938 | F21: 9.083 | G21: =SUM(C21:F21) -> 46.221 | I21: 13.528 | J21: 8.005 | K21: 10.956 | L21: 6.879 | M21: =SUM(I21:L21) -> 39.368 | O21: 1.651 | P21: 4.312 | Q21: 12.767 | R21: 14.418 | S21: =SUM(O21:R21) -> 33.148 | U21: 8.789 | V21: 9.652 | W21: 2.094 | X21: 14.594 | Y21: =SUM(U21:X21) -> 35.129 | AA21: 15.222 | AB21: 14.564 | AC21: 11.508 | AD21: 1.915 | AE21: =SUM(AA21:AD21) -> 43.209 | AG21: 15.448 | AH21: 16.678 | AI21: 6.253 | AJ21: 11.954 | AK21: =SUM(AG21:AJ21) -> 50.333 | AM21: 7.922 | AN21: 11.818 | AO21: 6.272 | AP21: 14 | AQ21: =SUM(AM21:AP21) -> 40.012 | AS21: 14 | AT21: 10 | AU21: 12 | AV21: 9 | AW21: =SUM(AS21:AV21) -> 45 | AY21: 10 | AZ21: 8 | BA21: 2 | BB21: -5 | BC21: =SUM(AY21:BB21) -> 15 | BE21: 6 | BF21: 3 | BG21: 5 | BH21: 7 | BI21: =SUM(BE21:BH21) -> 21 | BK21: 5 | BL21: 7 | BM21: =19-3 -> 16 | BN21: 45 | BO21: =SUM(BK21:BN21) -> 73 | BQ21: 44 | BR21: 2.265 | BS21: 1.8232697 | BT21: 2.3964723 | BU21: =SUM(BQ21:BT21) -> 50.484742 | BW21: 3.1217027 | BX21: 3.4604877 | BY21: 3.8267791 | BZ21: 3.4108132 | CA21: =SUM(BW21:BZ21) -> 13.819783 | CC21: 5.0752048 | CD21: 4.7769788 | CE21: 3.1056021 | CF21: 3.8000895 | CG21: =SUM(CC21:CF21) -> 16.757875 | CI21: 3.5549717 | CJ21: 5.5168967 | CK21: 7.0450876 | CL21: 7.5563129 | CM21: =SUM(CI21:CL21) -> 23.673269
A22: Other Income (Expense) | C22: -2.368 | D22: 5.872 | E22: 1.774 | F22: -4.334 | G22: =SUM(C22:F22) -> 0.944 | I22: 0.707 | J22: 0.828 | K22: -1.285 | L22: =-1.734-1.804 -> -3.538 | M22: =SUM(I22:L22) -> -3.288 | O22: 9.411 | P22: -5.701 | Q22: =-4.246 -> -4.246 | R22: =-3.312 -> -3.312 | S22: =SUM(O22:R22) -> -3.848 | U22: -2.354 | V22: 0.164 | W22: 1.402 | X22: 1.285 | Y22: =SUM(U22:X22) -> 0.497 | AA22: -4.596 | AB22: -2.522 | AC22: -1.318 | AD22: 1.272 | AE22: =SUM(AA22:AD22) -> -7.164 | AG22: -0.385 | AH22: 4.657 | AI22: -1.881 | AJ22: -3.543 | AK22: =SUM(AG22:AJ22) -> -1.152 | AM22: 0.714 | AN22: 2.253 | AO22: 2.809 | AP22: 3 | AQ22: =SUM(AM22:AP22) -> 8.776 | AS22: 1 | AT22: =5-8 -> -3 | AU22: -2 | AV22: 1 | AW22: =SUM(AS22:AV22) -> -3 | AY22: 2 | AZ22: 6 | BA22: 5 | BB22: -2 | BC22: =SUM(AY22:BB22) -> 11 | BE22: 6 | BF22: 6 | BG22: -1 | BH22: 1 | BI22: =SUM(BE22:BH22) -> 12 | BK22: 13 | BL22: 1 | BM22: -7 | BN22: -8 | BO22: =SUM(BK22:BN22) -> -1 | BQ22: =-11+1 -> -10 | BR22: 47 | BS22: 47 | BT22: 47 | BU22: =SUM(BQ22:BT22) -> 131 | BW22: 47 | BX22: 47 | BY22: 47 | BZ22: 20 | CA22: =SUM(BW22:BZ22) -> 161 | CC22: 10 | CD22: 10 | CE22: 10 | CF22: 10 | CG22: =SUM(CC22:CF22) -> 40 | CI22: 10 | CJ22: 10 | CK22: 10 | CL22: 10 | CM22: =SUM(CI22:CL22) -> 40
A23: Pretax Income | C23: =C17+C19+C22 -> 329.455 | D23: =D17+D19+D22 -> 321.336 | E23: =E17+E19+E22 -> 337.045 | F23: =F17+F19+F22 -> 338.25 | G23: =G17+G19+G22 -> 1326.086 | I23: =I17+I19+I22 -> 366.572 | J23: =J17+J19+J22 -> 382.296 | K23: =K17+K19+K22 -> 410.221 | L23: =L17+L19+L22 -> 392.715 | M23: =M17+M19+M22 -> 1551.804 | O23: =O17+O19+O22 -> 404.82 | P23: =P17+P19+P22 -> 338.568 | Q23: =Q17+Q19+Q22 -> 413.953 | R23: =R17+R19+R22 -> 421.252 | S23: =S17+S19+S22 -> 1578.593 | U23: =U17+U19+U22 -> 423.118 | V23: =V17+V19+V22 -> 410.551 | W23: =W17+W19+W22 -> 413.373 | X23: =X17+X19+X22 -> 414.118 | Y23: =SUM(U23:X23) -> 1661.16 | AA23: =AA17+AA19+AA22 -> 383.7377 | AB23: =AB17+AB19+AB22 -> 405.106 | AC23: =AC17+AC19+AC22 -> 435.17 | AD23: =AD17+AD19+AD22 -> 403.144 | AE23: =SUM(AA23:AD23) -> 1627.1577 | AG23: =AG17+AG19+AG22 -> 322.442 | AH23: =AH17+AH19+AH22 -> 369.525 | AI23: =AI17+AI19+AI22 -> 418.541 | AJ23: =AJ17+AJ19+AJ22 -> 381.899 | AK23: =SUM(AG23:AJ23) -> 1492.407 | AM23: =AM17+AM19+AM22 -> 383.56607 | AN23: =AN17+AN19+AN22 -> 380.3585 | AO23: =AO17+AO19+AO22 -> 421.00415 | AP23: =AP17+AP19+AP22 -> 425.07627 | AQ23: =SUM(AM23:AP23) -> 1610.005 | AS23: =AS17+AS19+AS22 -> 377.38 | AT23: =AT17+AT19+AT22 -> 404.48 | AU23: =AU17+AU19+AU22 -> 450.28 | AV23: =AV17+AV19+AV22 -> 441.91 | AW23: =SUM(AS23:AV23) -> 1674.05 | AY23: =AY17+AY19+AY22 -> 382.14 | AZ23: =AZ17+AZ19+AZ22 -> 403.45 | BA23: =BA17+BA19+BA22 -> 586.1 | BB23: =BB17+BB19+BB22 -> 551 | BC23: =SUM(AY23:BB23) -> 1922.69 | BE23: =BE17+BE19+BE22 -> 541.24 | BF23: =BF17+BF19+BF22 -> 594.75 | BG23: =BG17+BG19+BG22 -> 648 | BH23: =BH17+BH19+BH22 -> 552 | BI23: =SUM(BE23:BH23) -> 2335.99 | BK23: =BK17+BK19+BK22 -> 611 | BL23: =BL17+BL19+BL22 -> 573 | BM23: =BM17+BM19+BM22 -> 643 | BN23: =BN17+BN19+BN22 -> 614.49 | BO23: =SUM(BK23:BN23) -> 2441.49 | BQ23: =BQ17+BQ19+BQ22 -> 650 | BR23: =BR17+BR19+BR22 -> 914.36484 | BS23: =BS17+BS19+BS22 -> 1018.9694 | BT23: =BT17+BT19+BT22 -> 1008.4614 | BU23: =SUM(BQ23:BT23) -> 3591.7957 | BW23: =BW17+BW19+BW22 -> 1028.6294 | BX23: =BX17+BX19+BX22 -> 1072.0447 | BY23: =BY17+BY19+BY22 -> 1118.2055 | BZ23: =BZ17+BZ19+BZ22 -> 1105.1143 | CA23: =SUM(BW23:BZ23) -> 4323.994 | CC23: =CC17+CC19+CC22 -> 1166.5683 | CD23: =CD17+CD19+CD22 -> 1213.3754 | CE23: =CE17+CE19+CE22 -> 1268.7592 | CF23: =CF17+CF19+CF22 -> 1287.9986 | CG23: =SUM(CC23:CF23) -> 4936.7015 | CI23: =CI17+CI19+CI22 -> 1318.9434 | CJ23: =CJ17+CJ19+CJ22 -> 1332.9244 | CK23: =CK17+CK19+CK22 -> 1448.2967 | CL23: =CL17+CL19+CL22 -> 1471.1761 | CM23: =SUM(CI23:CL23) -> 5571.3407
A24: Income Taxes | C24: 83.657 | D24: 85.796712 | E24: 89.182 | F24: 89.142 | G24: =SUM(C24:F24) -> 347.77771 | I24: 95.676 | J24: 106.661 | K24: 112.811 | L24: 110.541 | M24: =SUM(I24:L24) -> 425.689 | O24: 108.213 | P24: 89.702 | Q24: 86.508 | R24: 126.824 | S24: =SUM(O24:R24) -> 411.247 | U24: 119.025 | V24: 125.517 | W24: 119.213 | X24: 121.065 | Y24: =SUM(U24:X24) -> 484.82 | AA24: 85.291 | AB24: 109.256 | AC24: 113.63 | AD24: =108.827+(9.27-6) -> 112.097 | AE24: =SUM(AA24:AD24) -> 420.274 | AG24: 73.898 | AH24: 94.401 | AI24: 106.96 | AJ24: =87.621+7 -> 94.621 | AK24: =SUM(AG24:AJ24) -> 369.88 | AM24: 100.80802 | AN24: 90.31725 | AO24: 101.16734 | AP24: 106.72288 | AQ24: =SUM(AM24:AP24) -> 399.0155 | AS24: 93.8212 | AT24: 89.8212 | AU24: 105.8212 | AV24: 98.9598 | AW24: =SUM(AS24:AV24) -> 388.4234 | AY24: 80.1 | AZ24: 86 | BA24: =-23+2+3+9+28+128-2+0 -> 145 | BB24: =9+3+15+51+54 -> 132 | BC24: =SUM(AY24:BB24) -> 443.1 | BE24: 116.4 | BF24: 122.4 | BG24: 138 | BH24: 90 | BI24: =SUM(BE24:BH24) -> 466.8 | BK24: 104 | BL24: 72 | BM24: 106 | BN24: 90 | BO24: =SUM(BK24:BN24) -> 372 | BQ24: =241-135 -> 106 | BR24: =BR23*BR25 -> 155.44202 | BS24: =BS23*BS25 -> 173.22481 | BT24: =BT23*BT25 -> 171.43844 | BU24: =SUM(BQ24:BT24) -> 606.10526 | BW24: =BW23*BW25 -> 172.29543 | BX24: =BX23*BX25 -> 179.56749 | BY24: =BY23*BY25 -> 187.29942 | BZ24: =BZ23*BZ25 -> 185.10665 | CA24: =SUM(BW24:BZ24) -> 724.26899 | CC24: =CC23*CC25 -> 192.48378 | CD24: =CD23*CD25 -> 200.20693 | CE24: =CE23*CE25 -> 209.34526 | CF24: =CF23*CF25 -> 212.51977 | CG24: =SUM(CC24:CF24) -> 814.55574 | CI24: =CI23*CI25 -> 217.62567 | CJ24: =CJ23*CJ25 -> 219.93252 | CK24: =CK23*CK25 -> 238.96896 | CL24: =CL23*CL25 -> 242.74406 | CM24: =SUM(CI24:CL24) -> 919.27121
A25: Tax Rate | C25: =C24/C23 -> 0.25392542 | D25: =D24/D23 -> 0.267 | E25: =E24/E23 -> 0.26459968 | F25: =F24/F23 -> 0.2635388 | G25: =G24/G23 -> 0.26225879 | I25: =I24/I23 -> 0.26100193 | J25: =J24/J23 -> 0.27900109 | K25: =K24/K23 -> 0.27500055 | L25: =L24/L23 -> 0.28147894 | M25: =M24/M23 -> 0.27431879 | O25: =O24/O23 -> 0.2673114 | P25: =P24/P23 -> 0.2649453 | Q25: =Q24/Q23 -> 0.20898025 | R25: =R24/R23 -> 0.30106445 | S25: =S24/S23 -> 0.2605149 | U25: =U24/U23 -> 0.28130451 | V25: =V24/V23 -> 0.30572816 | W25: =W24/W23 -> 0.28839087 | X25: =X24/X23 -> 0.29234421 | Y25: =Y24/Y23 -> 0.29185629 | AA25: =AA24/AA23 -> 0.2222638 | AB25: =AB24/AB23 -> 0.26969731 | AC25: =AC24/AC23 -> 0.26111635 | AD25: =AD24/AD23 -> 0.27805697 | AE25: =AE24/AE23 -> 0.2582872 | AG25: =AG24/AG23 -> 0.2291823 | AH25: =AH24/AH23 -> 0.2554658 | AI25: =AI24/AI23 -> 0.25555441 | AJ25: =AJ24/AJ23 -> 0.24776446 | AK25: =AK24/AK23 -> 0.24784124 | AM25: =AM24/AM23 -> 0.26281788 | AN25: =AN24/AN23 -> 0.23745296 | AO25: =AO24/AO23 -> 0.24030011 | AP25: =AP24/AP23 -> 0.25106761 | AQ25: =AQ24/AQ23 -> 0.24783494 | AS25: =AS24/AS23 -> 0.24861201 | AT25: =AT24/AT23 -> 0.22206586 | AU25: =AU24/AU23 -> 0.23501199 | AV25: =AV24/AV23 -> 0.22393655 | AW25: =AW24/AW23 -> 0.23202616 | AY25: =AY24/AY23 -> 0.20960904 | AZ25: =AZ24/AZ23 -> 0.21316148 | BA25: =BA24/BA23 -> 0.24739805 | BB25: =BB24/BB23 -> 0.23956443 | BC25: =BC24/BC23 -> 0.23045837 | BE25: =BE24/BE23 -> 0.21506171 | BF25: =BF24/BF23 -> 0.20580076 | BG25: =BG24/BG23 -> 0.21296296 | BH25: =BH24/BH23 -> 0.16304348 | BI25: =BI24/BI23 -> 0.19982962 | BK25: =+BK24/BK23 -> 0.17021277 | BL25: =BL24/BL23 -> 0.12565445 | BM25: =BM24/BM23 -> 0.16485226 | BN25: =BN24/BN23 -> 0.14646292 | BO25: =BO24/BO23 -> 0.15236597 | BQ25: =+BQ24/BQ23 -> 0.16307692 | BR25: 0.17 | BS25: 0.17 | BT25: 0.17 | BU25: =BU24/BU23 -> 0.16874714 | BW25: 0.1675 | BX25: =BW25 -> 0.1675 | BY25: =BX25 -> 0.1675 | BZ25: =BY25 -> 0.1675 | CA25: =CA24/CA23 -> 0.1675 | CC25: 0.165 | CD25: =CC25 -> 0.165 | CE25: =CD25 -> 0.165 | CF25: =CE25 -> 0.165 | CG25: =CG24/CG23 -> 0.165 | CI25: 0.165 | CJ25: =CI25 -> 0.165 | CK25: =CJ25 -> 0.165 | CL25: =CK25 -> 0.165 | CM25: =CM24/CM23 -> 0.165
A26: Income from cont. ops | C26: =C23-C24 -> 245.798 | D26: =D23-D24 -> 235.53929 | E26: =E23-E24 -> 247.863 | F26: =F23-F24 -> 249.108 | G26: =G23-G24 -> 978.30829 | I26: =I23-I24 -> 270.896 | J26: =J23-J24 -> 275.635 | K26: =K23-K24 -> 297.41 | L26: =L23-L24 -> 282.174 | M26: =M23-M24 -> 1126.115 | O26: =O23-O24 -> 296.607 | P26: =P23-P24 -> 248.866 | Q26: =Q23-Q24 -> 327.445 | R26: =R23-R24 -> 294.428 | S26: =S23-S24 -> 1167.346 | U26: =U23-U24 -> 304.093 | V26: =V23-V24 -> 285.034 | W26: =W23-W24 -> 294.16 | X26: =X23-X24 -> 293.053 | Y26: =Y23-Y24 -> 1176.34 | AA26: =AA23-AA24 -> 298.4467 | AB26: =AB23-AB24 -> 295.85 | AC26: =AC23-AC24 -> 321.54 | AD26: =AD23-AD24 -> 291.047 | AE26: =AE23-AE24 -> 1206.8837 | AG26: =AG23-AG24 -> 248.544 | AH26: =AH23-AH24 -> 275.124 | AI26: =AI23-AI24 -> 311.581 | AJ26: =AJ23-AJ24 -> 287.278 | AK26: =AK23-AK24 -> 1122.527 | AM26: =AM23-AM24 -> 282.75805 | AN26: =AN23-AN24 -> 290.04125 | AO26: =AO23-AO24 -> 319.8368 | AP26: =AP23-AP24 -> 318.35339 | AQ26: =AQ23-AQ24 -> 1210.9895 | AS26: =AS23-AS24 -> 283.5588 | AT26: =AT23-AT24 -> 314.6588 | AU26: =AU23-AU24 -> 344.4588 | AV26: =AV23-AV24 -> 342.9502 | AW26: =AW23-AW24 -> 1285.6266 | AY26: =AY23-AY24 -> 302.04 | AZ26: =AZ23-AZ24 -> 317.45 | BA26: =BA23-BA24 -> 441.1 | BB26: =BB23-BB24 -> 419 | BC26: =BC23-BC24 -> 1479.59 | BE26: =BE23-BE24 -> 424.84 | BF26: =BF23-BF24 -> 472.35 | BG26: =BG23-BG24 -> 510 | BH26: =BH23-BH24 -> 462 | BI26: =BI23-BI24 -> 1869.19 | BK26: =BK23-BK24 -> 507 | BL26: =BL23-BL24 -> 501 | BM26: =BM23-BM24 -> 537 | BN26: =BN23-BN24 -> 524.49 | BO26: =BO23-BO24 -> 2069.49 | BQ26: =BQ23-BQ24 -> 544 | BR26: =BR23-BR24 -> 758.92281 | BS26: =BS23-BS24 -> 845.74464 | BT26: =BT23-BT24 -> 837.02295 | BU26: =BU23-BU24 -> 2985.6904 | BW26: =BW23-BW24 -> 856.334 | BX26: =BX23-BX24 -> 892.47722 | BY26: =BY23-BY24 -> 930.90606 | BZ26: =BZ23-BZ24 -> 920.00769 | CA26: =CA23-CA24 -> 3599.725 | CC26: =CC23-CC24 -> 974.08456 | CD26: =CD23-CD24 -> 1013.1684 | CE26: =CE23-CE24 -> 1059.4139 | CF26: =CF23-CF24 -> 1075.4788 | CG26: =CG23-CG24 -> 4122.1457 | CI26: =CI23-CI24 -> 1101.3178 | CJ26: =CJ23-CJ24 -> 1112.9919 | CK26: =CK23-CK24 -> 1209.3278 | CL26: =CL23-CL24 -> 1228.4321 | CM26: =CM23-CM24 -> 4652.0695
A27: Income from Discont. Ops before Income Tax | C27: 0 | D27: 0 | E27: 0 | F27: 0 | G27: =SUM(C27:F27) -> 0 | I27: 0 | J27: 0 | K27: 0 | L27: 0 | M27: =SUM(I27:L27) -> 0 | O27: 20.234 | P27: 15.944 | Q27: 17.579 | R27: 30.476 | S27: =SUM(O27:R27) -> 84.233 | U27: 16.9 | V27: 16.698 | W27: 17.088 | X27: =103.642+27.645 -> 131.287 | Y27: =SUM(U27:X27) -> 181.973 | AA27: 26.298 | AB27: 24.688 | AC27: 30.53 | AD27: 23.793 | AE27: =SUM(AA27:AD27) -> 105.309 | AG27: 21.768 | AH27: 23.453 | AI27: =15.285+7.288 -> 22.573 | AJ27: =14.765+9.108 -> 23.873 | AK27: =SUM(AG27:AJ27) -> 91.667 | AM27: =355.187+216.336 -> 571.523 | AN27: -1.66 | AO27: =AO28+9.672 -> 16.104 | AP27: 1 | AQ27: =SUM(AM27:AP27) -> 586.967 | AS27: 0 | AT27: 0 | AU27: 0 | AV27: 0 | AW27: =SUM(AS27:AV27) -> 0 | AY27: 0 | AZ27: 0 | BA27: 0 | BB27: 0 | BC27: =SUM(AY27:BB27) -> 0 | BE27: 0 | BF27: 0 | BG27: 0 | BH27: 0 | BI27: =SUM(BE27:BH27) -> 0 | BK27: 0 | BL27: 0 | BM27: 0 | BN27: 0 | BO27: =SUM(BK27:BN27) -> 0 | BQ27: 0 | BR27: 0 | BS27: 0 | BT27: 0 | BU27: =SUM(BQ27:BT27) -> 0 | BW27: 0 | BX27: 0 | BY27: 0 | BZ27: 0 | CA27: =SUM(BW27:BZ27) -> 0 | CC27: 0 | CD27: 0 | CE27: 0 | CF27: 0 | CG27: =SUM(CC27:CF27) -> 0 | CI27: 0 | CJ27: 0 | CK27: 0 | CL27: 0 | CM27: =SUM(CI27:CL27) -> 0
A28: Income Taxes | C28: 0 | D28: 0 | E28: 0 | F28: 0 | G28: =SUM(C28:F28) -> 0 | I28: 0 | J28: 0 | K28: 0 | L28: 0 | M28: =SUM(I28:L28) -> 0 | O28: 4.773 | P28: 3.521 | Q28: 3.997 | R28: 7.684 | S28: =SUM(O28:R28) -> 19.975 | U28: 4.617 | V28: 4.101 | W28: 4.34 | X28: 27.645 | Y28: =SUM(U28:X28) -> 40.703 | AA28: 8.807 | AB28: 8.519 | AC28: 9.012 | AD28: 8.86 | AE28: =SUM(AA28:AD28) -> 35.198 | AG28: 7.327 | AH28: 7.544 | AI28: 7.288 | AJ28: 9.108 | AK28: =SUM(AG28:AJ28) -> 31.267 | AM28: 216.336 | AN28: -1.177 | AO28: 6.432 | AP28: 1 | AQ28: =SUM(AM28:AP28) -> 222.591 | AS28: 0 | AT28: 0 | AU28: 0 | AV28: 0 | AW28: =SUM(AS28:AV28) -> 0 | AY28: 0 | AZ28: 0 | BA28: 0 | BB28: 0 | BC28: =SUM(AY28:BB28) -> 0 | BE28: 0 | BF28: 0 | BG28: 0 | BH28: 0 | BI28: =SUM(BE28:BH28) -> 0 | BK28: 0 | BL28: 0 | BM28: 0 | BN28: 0 | BO28: =SUM(BK28:BN28) -> 0 | BQ28: 0 | BR28: 0 | BS28: 0 | BT28: 0 | BU28: =SUM(BQ28:BT28) -> 0 | BW28: 0 | BX28: 0 | BY28: 0 | BZ28: 0 | CA28: =SUM(BW28:BZ28) -> 0 | CC28: 0 | CD28: 0 | CE28: 0 | CF28: 0 | CG28: =SUM(CC28:CF28) -> 0 | CI28: 0 | CJ28: 0 | CK28: 0 | CL28: 0 | CM28: =SUM(CI28:CL28) -> 0
A29: Income from discont. Ops, net of tax | C29: =C27-C28 -> 0 | D29: =D27-D28 -> 0 | E29: =E27-E28 -> 0 | F29: =F27-F28 -> 0 | G29: =G27-G28 -> 0 | I29: =I27-I28 -> 0 | J29: =J27-J28 -> 0 | K29: =K27-K28 -> 0 | L29: =L27-L28 -> 0 | M29: =M27-M28 -> 0 | O29: =O27-O28 -> 15.461 | P29: =P27-P28 -> 12.423 | Q29: =Q27-Q28 -> 13.582 | R29: =R27-R28 -> 22.792 | S29: =S27-S28 -> 64.258 | U29: =U27-U28 -> 12.283 | V29: =V27-V28 -> 12.597 | W29: =W27-W28 -> 12.748 | X29: =X27-X28 -> 103.642 | Y29: =Y27-Y28 -> 141.27 | AA29: =AA27-AA28 -> 17.491 | AB29: =AB27-AB28 -> 16.169 | AC29: =AC27-AC28 -> 21.518 | AD29: =AD27-AD28 -> 14.933 | AE29: =AE27-AE28 -> 70.111 | AG29: =AG27-AG28 -> 14.441 | AH29: =AH27-AH28 -> 15.909 | AI29: =AI27-AI28 -> 15.285 | AJ29: =AJ27-AJ28 -> 14.765 | AK29: =SUM(AG29:AJ29) -> 60.4 | AM29: =AM27-AM28 -> 355.187 | AN29: =AN27-AN28 -> -0.483 | AO29: =AO27-AO28 -> 9.672 | AP29: =AP27-AP28 -> 0 | AQ29: =AQ27-AQ28 -> 364.376 | AS29: =AS27-AS28 -> 0 | AT29: =AT27-AT28 -> 0 | AU29: =AU27-AU28 -> 0 | AV29: =AV27-AV28 -> 0 | AW29: =SUM(AS29:AV29) -> 0 | AY29: =AY27-AY28 -> 0 | AZ29: =AZ27-AZ28 -> 0 | BA29: =BA27-BA28 -> 0 | BB29: =BB27-BB28 -> 0 | BC29: =SUM(AY29:BB29) -> 0 | BE29: =BE27-BE28 -> 0 | BF29: =BF27-BF28 -> 0 | BG29: =BG27-BG28 -> 0 | BH29: =BH27-BH28 -> 0 | BI29: =SUM(BE29:BH29) -> 0 | BK29: =BK27-BK28 -> 0 | BL29: =BL27-BL28 -> 0 | BM29: =BM27-BM28 -> 0 | BN29: =BN27-BN28 -> 0 | BO29: =SUM(BK29:BN29) -> 0 | BQ29: =BQ27-BQ28 -> 0 | BR29: =BR27-BR28 -> 0 | BS29: =BS27-BS28 -> 0 | BT29: =BT27-BT28 -> 0 | BU29: =SUM(BQ29:BT29) -> 0 | BW29: =BW27-BW28 -> 0 | BX29: =BX27-BX28 -> 0 | BY29: =BY27-BY28 -> 0 | BZ29: =BZ27-BZ28 -> 0 | CA29: =SUM(BW29:BZ29) -> 0 | CC29: =CC27-CC28 -> 0 | CD29: =CD27-CD28 -> 0 | CE29: =CE27-CE28 -> 0 | CF29: =CF27-CF28 -> 0 | CG29: =SUM(CC29:CF29) -> 0 | CI29: =CI27-CI28 -> 0 | CJ29: =CJ27-CJ28 -> 0 | CK29: =CK27-CK28 -> 0 | CL29: =CL27-CL28 -> 0 | CM29: =SUM(CI29:CL29) -> 0
A30: Preferred Stock Dividends | BR30: =IF(CFS!BR110<CFS!BR115,CFS!BR107,0) -> 38.28125 | BS30: =IF(CFS!BS110<CFS!BS115,CFS!BS107,0) -> 38.28125 | BT30: =IF(CFS!BT110<CFS!BT115,CFS!BT107,0) -> 38.28125 | BU30: =SUM(BQ30:BT30) -> 114.84375 | BW30: =IF(CFS!BW110<CFS!BW115,CFS!BW107,0) -> 38.28125 | BX30: =IF(CFS!BX110<CFS!BX115,CFS!BX107,0) -> 38.28125 | BY30: =IF(CFS!BY110<CFS!BY115,CFS!BY107,0) -> 38.28125 | BZ30: =IF(CFS!BZ110<CFS!BZ115,CFS!BZ107,0) -> 38.28125 | CA30: =SUM(BW30:BZ30) -> 153.125 | CC30: =IF(CFS!CC110<CFS!CC115,CFS!CC107,0) -> 0 | CD30: =IF(CFS!CD110<CFS!CD115,CFS!CD107,0) -> 0 | CG30: =SUM(CC30:CF30) -> 0
A31: Net Income | C31: =C26+C29 -> 245.798 | D31: =D26+D29 -> 235.53929 | E31: =E26+E29 -> 247.863 | F31: =F26+F29 -> 249.108 | G31: =G26+G29 -> 978.30829 | I31: =I26+I29 -> 270.896 | J31: =J26+J29 -> 275.635 | K31: =K26+K29 -> 297.41 | L31: =L26+L29 -> 282.174 | M31: =M26+M29 -> 1126.115 | O31: =O26+O29 -> 312.068 | P31: =P26+P29 -> 261.289 | Q31: =Q26+Q29 -> 341.027 | R31: =R26+R29 -> 317.22 | S31: =S26+S29 -> 1231.604 | U31: =U26+U29 -> 316.376 | V31: =V26+V29 -> 297.631 | W31: =W26+W29 -> 306.908 | X31: =X26+X29 -> 396.695 | Y31: =Y26+Y29 -> 1317.61 | AA31: =AA26+AA29 -> 315.9377 | AB31: =AB26+AB29 -> 312.019 | AC31: =AC26+AC29 -> 343.058 | AD31: =AD26+AD29 -> 305.98 | AE31: =AE26+AE29 -> 1276.9947 | AG31: =AG26+AG29 -> 262.985 | AH31: =AH26+AH29 -> 291.033 | AI31: =AI26+AI29 -> 326.866 | AJ31: =AJ26+AJ29 -> 302.043 | AK31: =AK26+AK29 -> 1182.927 | AM31: =AM26+AM29 -> 637.94505 | AN31: =AN26+AN29 -> 289.55825 | AO31: =AO26+AO29 -> 329.5088 | AP31: =AP26+AP29 -> 318.35339 | AQ31: =AQ26+AQ29 -> 1575.3655 | AS31: =AS26+AS29 -> 283.5588 | AT31: =AT26+AT29 -> 314.6588 | AU31: =AU26+AU29 -> 344.4588 | AV31: =AV26+AV29 -> 342.9502 | AW31: =AW26+AW29 -> 1285.6266 | AY31: =AY26+AY29 -> 302.04 | AZ31: =AZ26+AZ29 -> 317.45 | BA31: =BA26+BA29 -> 441.1 | BB31: =BB26+BB29 -> 419 | BC31: =BC26+BC29 -> 1479.59 | BE31: =BE26+BE29 -> 424.84 | BF31: =BF26+BF29 -> 472.35 | BG31: =BG26+BG29 -> 510 | BH31: =BH26+BH29 -> 462 | BI31: =BI26+BI29 -> 1869.19 | BK31: =BK26+BK29 -> 507 | BL31: =BL26+BL29 -> 501 | BM31: =BM26+BM29 -> 537 | BN31: =BN26+BN29 -> 524.49 | BO31: =BO26+BO29 -> 2069.49 | BQ31: =BQ26+BQ29-BQ30 -> 544 | BR31: =BR26+BR29-BR30 -> 720.64156 | BS31: =BS26+BS29-BS30 -> 807.46339 | BT31: =BT26+BT29-BT30 -> 798.7417 | BU31: =BU26+BU29-BU30 -> 2870.8467 | BW31: =BW26+BW29-BW30 -> 818.05275 | BX31: =BX26+BX29-BX30 -> 854.19597 | BY31: =BY26+BY29-BY30 -> 892.62481 | BZ31: =BZ26+BZ29-BZ30 -> 881.72644 | CA31: =CA26+CA29-CA30 -> 3446.6 | CC31: =CC26+CC29-CC30 -> 974.08456 | CD31: =CD26+CD29-CD30 -> 1013.1684 | CE31: =CE26+CE29-CE30 -> 1059.4139 | CF31: =CF26+CF29-CF30 -> 1075.4788 | CG31: =CG26+CG29-CG30 -> 4122.1457 | CI31: =CI26+CI29-CI30 -> 1101.3178 | CJ31: =CJ26+CJ29-CJ30 -> 1112.9919 | CK31: =CK26+CK29-CK30 -> 1209.3278 | CL31: =CL26+CL29-CL30 -> 1228.4321 | CM31: =CM26+CM29-CM30 -> 4652.0695
A32: Net Income to Common | BQ32: 544 | BR32: =BR26-IF(CFS!BR110<CFS!BR115,CFS!BR107) -> 720.64156 | BS32: =BS26-IF(CFS!BS110<CFS!BS115,CFS!BS107) -> 807.46339 | BT32: =BT26-IF(CFS!BT110<CFS!BT115,CFS!BT107) -> 798.7417 | BU32: =SUM(BQ32:BT32) -> 2870.8467 | BW32: =BW26-IF(CFS!BW110<CFS!BW115,CFS!BW107) -> 818.05275 | BX32: =BX26-IF(CFS!BX110<CFS!BX115,CFS!BX107) -> 854.19597 | BY32: =BY26-IF(CFS!BY110<CFS!BY115,CFS!BY107) -> 892.62481 | BZ32: =BZ26-IF(CFS!BZ110<CFS!BZ115,CFS!BZ107) -> 881.72644 | CA32: =SUM(BW32:BZ32) -> 3446.6 | CC32: =CC26-IF(CFS!CC110<CFS!CC115,CFS!CC107) -> 974.08456 | CD32: =CD26-IF(CFS!CD110<CFS!CD115,CFS!CD107) -> 1013.1684 | CE32: =CE26-IF(CFS!CE110<CFS!CE115,CFS!CE107) -> 1059.4139 | CF32: =CF26-IF(CFS!CF110<CFS!CF115,CFS!CF107) -> 1075.4788 | CG32: =SUM(CC32:CF32) -> 4122.1457 | CI32: =CI26-IF(CFS!CI110<CFS!CI115,CFS!CI107) -> 1101.3178 | CJ32: =CJ26-IF(CFS!CJ110<CFS!CJ115,CFS!CJ107) -> 1112.9919 | CK32: =CK26-IF(CFS!CK110<CFS!CK115,CFS!CK107) -> 1209.3278 | CL32: =CL26-IF(CFS!CL110<CFS!CL115,CFS!CL107) -> 1228.4321 | CM32: =SUM(CI32:CL32) -> 4652.0695
A33: Fully Diluted Shares | C33: 254.941 | D33: 254.74 | E33: 254.128 | F33: 253.009 | G33: 254.81 | I33: 253.116 | J33: 252.788 | K33: 251.648 | L33: 251.197 | M33: 252.681 | O33: 248.311 | P33: 245.89 | Q33: 245.696 | R33: 245.056 | S33: 246.798 | U33: 242.965 | V33: 240.863 | W33: 238.319 | X33: 236.316 | Y33: 240.136 | AA33: 232.915 | AB33: 225.467 | AC33: 223.567 | AD33: 220.859 | AE33: =AVERAGE(AA33:AD33) -> 225.702 | AG33: 217.634 | AH33: 209.803 | AI33: 205.29 | AJ33: 202.439 | AK33: =AVERAGE(AG33:AJ33) -> 208.7915 | AM33: 199.57 | AN33: 198.143 | AO33: 198.719 | AP33: 198.628 | AQ33: =AVERAGE(AM33:AP33) -> 198.765 | AS33: 198.11 | AT33: 197.488 | AU33: 197.005 | AV33: 196.46 | AW33: 197.709 | AY33: 197 | AZ33: 197 | BA33: 214.928 | BB33: 215.719 | BC33: 206.833 | BE33: 216.294 | BF33: 216.538 | BG33: 217.372 | BH33: 217.916 | BI33: =AVERAGE(BE33:BH33) -> 217.03 | BK33: 217.739 | BL33: 217.866 | BM33: 218.184 | BN33: 218.632 | BO33: =AVERAGE(BK33:BN33) -> 218.10525 | BQ33: 218.997 | BR33: =CFS!BR81 -> 275.03953 | BS33: =CFS!BS81 -> 275.141 | BT33: =CFS!BT81 -> 275.34395 | BU33: =AVERAGE(BQ33:BT33) -> 261.13037 | BW33: =CFS!BW81 -> 275.15529 | BX33: =CFS!BX81 -> 275.66038 | BY33: =CFS!BY81 -> 276.16745 | BZ33: =CFS!BZ81 -> 276.67453 | CA33: =AVERAGE(BW33:BZ33) -> 275.91441 | CC33: =CFS!CC81 -> 289.49086 | CD33: =CFS!CD81 -> 290.30291 | CE33: =CFS!CE81 -> 290.64568 | CF33: =CFS!CF81 -> 290.70565 | CG33: =AVERAGE(CC33:CF33) -> 290.28627 | CI33: =CFS!CI81 -> 291.52497 | CJ33: =CFS!CJ81 -> 292.53788 | CK33: =CFS!CK81 -> 293.04501 | CL33: =CFS!CL81 -> 293.55215 | CM33: =AVERAGE(CI33:CL33) -> 292.665
A34: Diluted EPS | C34: =C26/C33 -> 0.9641368 | D34: =D26/D33 -> 0.92462624 | E34: =E26/E33 -> 0.97534707 | F34: =F26/F33 -> 0.98458158 | G34: =G26/G33 -> 3.8393638 | I34: =I26/I33 -> 1.0702445 | J34: =J26/J33 -> 1.0903801 | K34: =K26/K33 -> 1.1818492 | L34: =L26/L33 -> 1.1233176 | M34: =M26/M33 -> 4.4566667 | O34: =O26/O33 -> 1.194498 | P34: =P26/P33 -> 1.012103 | Q34: =Q26/Q33 -> 1.3327242 | R34: =R26/R33 -> 1.2014723 | S34: =S26/S33 -> 4.7299654 | U34: =U26/U33 -> 1.2515918 | V34: =V26/V33 -> 1.1833864 | W34: =W26/W33 -> 1.234312 | X34: =X26/X33 -> 1.2400895 | Y34: =Y26/Y33 -> 4.8986408 | AA34: =AA26/AA33 -> 1.2813546 | AB34: =AB26/AB33 -> 1.3121654 | AC34: =AC26/AC33 -> 1.4382266 | AD34: =AD26/AD33 -> 1.3177955 | AE34: =AE26/AE33 -> 5.3472442 | AG34: =AG26/AG33 -> 1.1420274 | AH34: =AH26/AH33 -> 1.3113445 | AI34: =AI26/AI33 -> 1.5177602 | AJ34: =AJ26/AJ33 -> 1.4190843 | AK34: =AK26/AK33 -> 5.376306 | AM34: =AM26/AM33 -> 1.4168365 | AN34: =AN26/AN33 -> 1.4637976 | AO34: =AO26/AO33 -> 1.6094928 | AP34: =AP26/AP33 -> 1.6027619 | AQ34: =AQ26/AQ33 -> 6.0925691 | AS34: =AS26/AS33 -> 1.43132 | AT34: =AT26/AT33 -> 1.5933059 | AU34: =AU26/AU33 -> 1.7484774 | AV34: =AV26/AV33 -> 1.745649 | AW34: =AW26/AW33 -> 6.5026205 | AY34: =AY26/AY33 -> 1.533198 | AZ34: =AZ26/AZ33 -> 1.6114213 | BA34: =BA26/BA33 -> 2.0523152 | BB34: =BB26/BB33 -> 1.9423417 | BC34: =BC26/BC33 -> 7.153549 | BE34: =BE26/BE33 -> 1.9641784 | BF34: =BF26/BF33 -> 2.1813723 | BG34: =BG26/BG33 -> 2.3462083 | BH34: =BH26/BH33 -> 2.120083 | BI34: =BI26/BI33 -> 8.6125881 | BK34: =BK26/BK33 -> 2.3284758 | BL34: =BL26/BL33 -> 2.2995786 | BM34: =BM26/BM33 -> 2.4612254 | BN34: =BN26/BN33 -> 2.3989626 | BO34: =BO26/BO33 -> 9.4884924 | BQ34: =BQ26/BQ33 -> 2.4840523 | BR34: =BR32/BR33 -> 2.6201382 | BS34: =BS32/BS33 -> 2.9347258 | BT34: =BT32/BT33 -> 2.9008871 | BU34: =BU32/BU33 -> 10.993921 | BW34: =BW32/BW33 -> 2.9730584 | BX34: =BX32/BX33 -> 3.098726 | BY34: =BY32/BY33 -> 3.2321869 | BZ34: =BZ32/BZ33 -> 3.1868725 | CA34: =CA32/CA33 -> 12.491555 | CC34: =CC32/CC33 -> 3.3648197 | CD34: =CD32/CD33 -> 3.4900389 | CE34: =CE26/CE33 -> 3.6450359 | CF34: =CF26/CF33 -> 3.6995457 | CG34: =CG32/CG33 -> 14.200278 | CI34: =CI26/CI33 -> 3.777782 | CJ34: =CJ26/CJ33 -> 3.8046077 | CK34: =CK26/CK33 -> 4.1267646 | CL34: =CL26/CL33 -> 4.184715 | CM34: =CM26/CM33 -> 15.895544
A36: Margin Analysis
