Workbook
Name AdditionalInstructions: IndexInformation!$B$42
Name Address: ImportantDisclosures!$A$2:$A$2
Name ANA: ModPubIndex!$A$7
Name Authors: ImportantDisclosures!$A$7
Name Authors: IndexInformation!$B$18
Name BRO: ModPubIndex!$A$1
Name CopyrightStamp: ImportantDisclosures!$A$27
Name COU: ModPubIndex!$A$5
Name CQEnd: IndexInformation!$B$31
Name Currency: IndexInformation!$B$24
Name CurrentStockPrice: IndexInformation!$B$23
Name CurrQtrEPS: IndexInformation!$B$29
Name CurrYearEPS: IndexInformation!$B$11
Name CurrYearTotalRevenue: IndexInformation!$B$10
Name CurrYearTotalRevenueActual: IndexInformation!$B$32
Name CUSIP: IndexInformation!$B$20
Name CYEnd: IndexInformation!$B$30
Name Date: ImportantDisclosures!$A$8
Name Deleted: IndexInformation!$B$27
Name Description: IndexInformation!$B$7
Name Discipline: IndexInformation!$B$3
Name DISCIPLINE: ModPubIndex!$A$12
Name DisclosuresText: ImportantDisclosures!$A$22
Name Distribution: IndexInformation!$B$26
Name DistTable: ImportantDisclosures!#REF!
Name DistTablePreamble: ImportantDisclosures!#REF!
Name DOCDAT: ModPubIndex!$A$2
Name DOCTIME: ModPubIndex!$A$3
Name DocType: IndexInformation!$B$5
Name EMAIL_ALERT: ModPubIndex!$A$10
Name EmailAlert: IndexInformation!$B$28
Name FiveYearGrowthRate: IndexInformation!$B$16
Name FollowingYearEPS: IndexInformation!$B$15
Name FollowingYearTotalRevenue: IndexInformation!$B$14
Name FollowingYearTotalRevenueActual: IndexInformation!$B$34
Name HL: ModPubIndex!$A$8
Name IND: ModPubIndex!$A$9
Name Industry: ImportantDisclosures!$A$12
Name IndustryId: IndexInformation!$B$40
Name IndustryRating: ImportantDisclosures!$A$13
Name KeepVersions: IndexInformation!$B$8
Name LanguageCode: IndexInformation!$B$38
Name LastCell: ImportantDisclosures!$A$22
Name Linking_1: IS!$A$7:$DM$109
Name Linking_10: IS!$A$7:$DR$109
Name Linking_11: CF!$A$7:$DR$78
Name Linking_12: IS!$A$7:$DW$109
Name Linking_2: BS!$A$6:$DM$70
Name Linking_3: CF!$A$7:$DM$95
Name Linking_4: IS!$A$5:$DM$82
Name Linking_5: BS!$A$5:$DM$57
Name Linking_6: CF!$A$5:$DM$95
Name Linking_7: IS!$A$7:$DR$108
Name Linking_8: BS!$A$6:$DR$57
Name Linking_9: CF!$A$9:$DR$78
Name Linking_Range_1: IS!$A$7:$DC$100
Name Linking_Range_12: BS!$A$5:$DC$75
Name Linking_Range_13: CF!$A$5:$DC$90
Name Linking_Range_15: IS!$A$5:$DH$82
Name Linking_Range_16: BS!$A$5:$DH$57

Sheet ImportantDisclosures
A2: 1585 Broadway
A3: New York, NY 10036-8293
A4: United States
A5: Tel: +1 (1)212 761 4000
A7: Authors: John Glass
A8: Date: 16 Apr 2018
A10: Ticker: SBUX.O
A11: Stock Rating: Overweight
A12: Industry: Restaurants
A13: Industry View: In-Line
A14: Price as of 16 Apr 2018: 59.36
A15: Target Price: 72
... A129: Equal-weight and Not-Rated to hold and Underweight to sell recommendations, respectively.
B131: Coverage Universe | D131: Investment Banking Clients (IBC) | G131: Other Material Investment Services Clients (MISC)
A132: Stock Rating Category | B132: Count | C132: % of Total | D132: Count | E132: % of Total IBC | F132: % of Rating Category | G132: Count | H132: % of Total Other MISC
A133: Overweight/Buy | B133: 1189 | C133: 0.38 | D133: 315 | E133: 0.41 | F133: 0.26 | G133: 555 | H133: 0.39
A134: Equal-weight/Hold | B134: 1355 | C134: 0.43 | D134: 364 | E134: 0.47 | F134: 0.27 | G134: 644 | H134: 0.45
A135: Not-Rated/Hold | B135: 53 | C135: 0.02 | D135: 4 | E135: 0.01 | F135: 0.08 | G135: 7 | H135: 0
A136: Underweight/Sell | B136: 545 | C136: 0.17 | D136: 84 | E136: 0.11 | F136: 0.15 | G136: 214 | H136: 0.15
A137: Total | B137: 3142 | D137: 767 | G137: 1420
A139: Data include common stock and ADRs currently assigned ratings. Investment Banking Clients are companies
A140: from whom Morgan Stanley received investment banking compensation in the last 12 months. Due to rounding
A141: off of decimals, the percentages provided in the "% of total" column may not add up to exactly 100
A142: percent.
A144: Analyst Stock Ratings
A146: Overweight (O). The stock's total return is expected to exceed the average total return of the analyst's
A147: industry (or industry team's) coverage universe, on a risk-adjusted basis, over the next 12-18 months.
A149: Equal-weight (E). The stock's total return is expected to be in line with the average total return of
A150: the analyst's industry (or industry team's) coverage universe, on a risk-adjusted basis, over the next
A151: 12-18 months.
A153: Not-Rated (NR). Currently the analyst does not have adequate conviction about the stock's total return
A154: relative to the average total return of the analyst's industry (or industry team's) coverage universe,
... A400: © Copyright 2018 Morgan Stanley

Sheet Intro
C1: Ticker (Nasdaq): SBUX | F1: Price Target/Base Case | I1: 72
C2: Snapshot
C3: (data in $ millions except EPS & Units) | D3: FY03 | E3: FY04 | F3: FY05 | G3: FY06 | H3: FY07 | I3: FY08 | J3: FY09 | K3: FY10 | L3: FY11 | M3: FY12 | N3: FY13 | O3: FY14 | P3: FY15 | Q3: FY16 | R3: FY17 | S3: FY18E | T3: FY19E | V3: 3yr ('17/'14) CAGR
A4: Starbucks Corporation | C4: Revenue | D4: =IS!AU17 -> 4075.521 | E4: =IS!AZ17 -> 5294.247 | F4: =IS!BE17 -> 6369.3 | G4: =IS!BJ17 -> 7786.942 | H4: =IS!BO17 -> 9411.497 | I4: =IS!BT17 -> 10383 | J4: =IS!BY17 -> 9774.6 | K4: =IS!CD17 -> 10707.4 | L4: =IS!CI17 -> 11700.6 | M4: =IS!CN17 -> 13276.9 | N4: =IS!CS17 -> 14866.9 | O4: =IS!CX17 -> 16447.9 | P4: =IS!DC17 -> 19162.7 | Q4: =IS!DH17 -> 21315.9 | R4: =IS!DM17 -> 22386.7 | S4: =IS!DR17 -> 24765.707 | T4: =IS!DW17 -> 27224.617 | V4: =(R4/O4)^(1/3)-1 -> 0.10822142
A5: John S. Glass | C5: Revenue Growth | D5: =IS!AU73 -> 0.23917148 | E5: =IS!AZ73 -> 0.29903563 | F5: =IS!BE73 -> 0.20306061 | G5: =IS!BJ73 -> 0.22257422 | H5: =IS!BO73 -> 0.20862554 | I5: =IS!BT73 -> 0.10322513 | J5: =J4/I4-1 -> -0.058595782 | K5: =K4/J4-1 -> 0.095431015 | L5: =L4/K4-1 -> 0.092758279 | M5: =M4/L4-1 -> 0.13471959 | N5: =N4/M4-1 -> 0.11975687 | O5: =O4/N4-1 -> 0.10634362 | P5: =P4/O4-1 -> 0.16505451 | Q5: =Q4/P4-1 -> 0.11236412 | ... T5: =T4/S4-1 -> 0.099286898
A6: (617) 856-8752 | C6: Operating Income | D6: =IS!AU30 -> 424.712 | E6: =IS!AZ30 -> 606.817 | F6: =IS!BE30 -> 780.615 | G6: =IS!BJ30 -> 893.986 | H6: =IS!BO30 -> 1053.945 | I6: =IS!BT30 -> 805.86 | J6: =IS!BY30 -> 894.4 | K6: =IS!CD30 -> 1472.4 | L6: =IS!CI30 -> 1698.3 | M6: =IS!CN30 -> 1997.6 | N6: =IS!CS30 -> 2458.8 | O6: =IS!CX30 -> 3060.8 | P6: =IS!DC30 -> 3655.6 | Q6: =IS!DH30 -> 4197.8122 | R6: =IS!DM30 -> 4412.5 | S6: =IS!DR30 -> 4685.1725 | T6: =IS!DW30 -> 5280.614 | V6: =(R6/O6)^(1/3)-1 -> 0.12966565
A7: john.glass@morganstanley.com | C7: Operating Income Growth | D7: =IS!AU77 -> 0.34258926 | E7: =IS!AZ77 -> 0.42877291 | F7: =IS!BE77 -> 0.28640925 | G7: =IS!BJ77 -> 0.14523293 | H7: =IS!BO77 -> 0.17892786 | I7: =IS!BT77 -> -0.52192951 | J7: =J6/I6-1 -> 0.1098702 | K7: =K6/J6-1 -> 0.64624329 | L7: =L6/K6-1 -> 0.15342298 | M7: =M6/L6-1 -> 0.17623506 | N7: =N6/M6-1 -> 0.23087705 | O7: =O6/N6-1 -> 0.24483488 | P7: =P6/O6-1 -> 0.19432828 | Q7: =Q6/P6-1 -> 0.14832372 | ... T7: =T6/S6-1 -> 0.12709063
C8: Operating EPS | D8: =IS!AU50 -> 0.16702712 | E8: =IS!AZ50 -> 0.23647394 | F8: =IS!BE50 -> 0.30319885 | G8: =IS!BJ53 -> 0.35601891 | H8: =IS!BO50 -> 0.43688973 | I8: =IS!BT50 -> 0.35543985 | J8: =IS!BY50 -> 0.39916879 | K8: =IS!CD50 -> 0.64447783 | L8: =IS!CI50 -> 0.75935429 | M8: =IS!CN50 -> 0.89527814 | N8: =IS!CS50 -> 1.0966155 | O8: =IS!CX50 -> 1.3161531 | P8: =IS!DC50 -> 1.5831266 | Q8: =IS!DH50 -> 1.906739 | R8: =IS!DM50 -> 2.0698592 | S8: =IS!DR50 -> 2.4812693 | T8: =IS!DW50 -> 2.7963085 | V8: =(R8/O8)^(1/3)-1 -> 0.16290652
A9: Chris Carril | C9: Operating EPS Growth | D9: =IS!AU81 -> 0.2486635 | E9: =IS!AZ81 -> 0.41578171 | F9: =IS!BE81 -> 0.28216603 | G9: =IS!BJ81 -> 0.3325096 | H9: =IS!BO81 -> 0.19082649 | I9: =IS!BT81 -> -0.1864312 | J9: =J8/I8-1 -> 0.12302767 | K9: =K8/J8-1 -> 0.61454966 | L9: =L8/K8-1 -> 0.17824734 | M9: =M8/L8-1 -> 0.17899924 | N9: =N8/M8-1 -> 0.22488807 | O9: =O8/N8-1 -> 0.20019556 | P9: =P8/O8-1 -> 0.20284382 | Q9: =Q8/P8-1 -> 0.20441351 | ... T9: =T8/S8-1 -> 0.12696696
A10: (617) 856-8750 | C10: TOTAL SSS | J10: =IS!BY100 -> -0.06 | K10: =IS!CD100 -> 0.07 | L10: =IS!CI100 -> 0.08 | M10: =IS!CN100 -> 0.07 | N10: =IS!CS100 -> 0.07 | O10: =IS!CX100 -> 0.06 | P10: =IS!DC100 -> 0.07 | Q10: =IS!DH100 -> 0.05 | R10: =IS!DM100 -> 0.03 | S10: =IS!DR100 -> 0.022274723 | T10: =IS!DW100 -> 0.037320364 | V10: =AVERAGE(P10:R10) -> 0.05
A11: christopher.carril@morganstanley.com | C11: Total Units | D11: 7225 | E11: 8569 | F11: 10241 | G11: 12440 | H11: 15011 | I11: 16680 | J11: =IS!BY90 -> 16635 | K11: =IS!CD90 -> 16858 | L11: =IS!CI90 -> 17003 | M11: =IS!CN90 -> 18066 | N11: =IS!CS90 -> 19767 | O11: =IS!CX90 -> 21366 | P11: =IS!DC90 -> 23043 | Q11: =IS!DH90 -> 25085 | R11: =IS!DM90 -> 27339 | S11: =IS!DR90 -> 29357 | T11: =IS!DW90 -> 31711 | V11: =(R11/O11)^(1/3)-1 -> 0.085641576
C12: Total Unit Growth | D12: 0.22748896 | E12: 0.18602076 | F12: 0.19512195 | G12: 0.21472512 | H12: 0.20667203 | I12: 0.089124045 | J12: =J11/I11-1 -> -0.0026978417 | K12: =K11/J11-1 -> 0.01340547 | L12: =L11/K11-1 -> 0.0086012576 | M12: =M11/L11-1 -> 0.062518379 | N12: =N11/M11-1 -> 0.094154766 | O12: =O11/N11-1 -> 0.080892396 | P12: =P11/O11-1 -> 0.078489188 | Q12: =Q11/P11-1 -> 0.088616934 | ... T12: =T11/S11-1 -> 0.080185305
C13: Calendarized Results and Estimates
A14: Go To: | C14: (data in $ millions except EPS & Units) | F14: CY05 | G14: CY06 | H14: CY07 | I14: CY08 | J14: CY09 | K14: CY10 | L14: CY11 | M14: CY12 | N14: CY13 | O14: CY14 | P14: CY15 | Q14: CY16 | R14: CY17E | S14: CY18E | T14: CY19E | V14: CY
A15: Income Statement | C15: Revenue | F15: =IS!EN17 -> 6713.848 | G15: =IS!EO17 -> 8208.573 | H15: =IS!EP17 -> 9823.374 | I15: =IS!EQ17 -> 10230.6 | J15: =IS!ER17 -> 9882.1 | K15: =IS!ES17 -> 10935.5 | L15: =IS!ET17 -> 12179.8 | M15: =IS!EU17 -> 13640.1 | ... T15: =IS!FB17 -> 27861.787 | V15: =(R15/O15)^(1/3)-1 -> 0.10137789
A16: Balance Sheet | C16: Revenue Growth | G16: =G15/F15-1 -> 0.22263313 | H16: =H15/G15-1 -> 0.19672128 | I16: =I15/H15-1 -> 0.0414548 | J16: =J15/I15-1 -> -0.034064473 | K16: =K15/J15-1 -> 0.10659678 | L16: =L15/K15-1 -> 0.11378538 | M16: =M15/L15-1 -> 0.11989524 | N16: =N15/M15-1 -> 0.12266772 | ... T16: =T15/S15-1 -> 0.095707154
A17: Statement of Cash Flows | C17: EBITDA (before charges) | F17: =IS!EN31 -> 1212.863 | G17: =IS!EO31 -> 1364.832 | H17: =IS!EP31 -> 1582.337 | I17: =IS!EQ31+IS!EQ26 -> 1558.76 | J17: =IS!ER31+IS!ER26 -> 1603.1 | K17: =IS!ES32 -> 2111 | L17: =IS!ET31 -> 2282.8 | M17: =IS!EU31 -> 2636.6 | N17: =IS!EV31 -> 3263.7 | O17: =IS!EW31 -> 3928.9 | P17: =IS!EX31 -> 4666.9 | Q17: =IS!EY31 -> 5241.6 | R17: =IS!EZ31 -> 5138.6 | S17: =IS!FA31 -> 5886.6204 | T17: =IS!FB31 -> 6591.5957 | V17: =(R17/O17)^(1/3)-1 -> 0.093598601
A18: Unit Detail | C18: EBITDA Growth | G18: =G17/F17-1 -> 0.12529775 | H18: =H17/G17-1 -> 0.15936394 | I18: =I17/H17-1 -> -0.014900113 | J18: =J17/I17-1 -> 0.028445688 | K18: =K17/J17-1 -> 0.31682365 | L18: =L17/K17-1 -> 0.081383231 | M18: =M17/L17-1 -> 0.15498511 | N18: =N17/M17-1 -> 0.23784419 | ... T18: =T17/S17-1 -> 0.11975892
A19: Revenue Drivers | C19: Operating EPS | F19: =IS!EN50 -> 0.32499222 | G19: =IS!EO50 -> 0.38757124 | H19: =IS!EP50 -> 0.44435823 | I19: =IS!EQ50 -> 0.28940379 | J19: =IS!ER50 -> 0.49203964 | K19: =IS!ES50 -> 0.70209063 | L19: =IS!ET50 -> 0.76232674 | M19: =IS!EU50 -> 0.92981944 | ... T19: =IS!FB50 -> 2.8883687 | V19: =(R19/O19)^(1/3)-1 -> -0.054956808
A20: Segment Details | C20: Operating EPS Growth | G20: =G19/F19-1 -> 0.19255543 | H20: =H19/G19-1 -> 0.14652015 | I20: =I19/H19-1 -> -0.34871513 | J20: =J19/I19-1 -> 0.70018378 | K20: =K19/J19-1 -> 0.42689853 | L20: =L19/K19-1 -> 0.085795349 | M20: =M19/L19-1 -> 0.21971248 | N20: =N19/M19-1 -> 0.24407307 | ... T20: =T19/S19-1 -> 0.15341518
C21: Free Cash Flow (CFO less Capex) | G21: =CF!EE85 -> 306.726 | H21: =CF!EF85 -> 387.011 | I21: =CF!EG85 -> 251.1 | J21: =CF!EH85 -> 1091.5 | K21: =CF!EI85 -> 1139.9 | L21: =CF!EJ85 -> 848.6 | M21: =CF!EK85 -> 1375.5 | N21: =CF!EL85 -> -725.9 | ... T21: =CF!ER85 -> 3183.128 | V21: =(R21/O21)^(1/3)-1 -> 0.1857646
C23: Valuation Information
N24: =N14 -> CY13 | O24: =O14 -> CY14 | P24: =P14 -> CY15 | Q24: =Q14 -> CY16 | R24: =R14 -> CY17E | S24: CY18E | T24: CY19E
C25: Current stock price | D25: 60.61
C26: Current shares outstanding | D26: =IS!DL54 -> 1451.2
C27: Market Cap | D27: =D26*D25 -> 87957.232
C28: Current net debt | D28: =BS!DL45-BS!DL9+BS!DL35 -> 1470.3
C29: Enterprise Value | D29: =D28+D27 -> 89427.532
C30: Rent (fiscal year) | F30: 416.916 | G30: 498.8 | H30: 638.1 | I30: 741.1 | J30: 714.7 | K30: 714.6 | L30: 749.9 | M30: 803.7 | N30: 894.7 | O30: 974.2 | P30: 1137.8 | Q30: 1223.2 | R30: 1239.8738 | S30: 1322.1023 | T30: 1398.9205
C31: Capitalized Rent | N31: =N30*8 -> 7157.6 | O31: =O30*8 -> 7793.6 | P31: =P30*8 -> 9102.4 | Q31: =Q30*8 -> 9785.6 | R31: =R30*8 -> 9918.9905 | S31: =S30*8 -> 10576.818 | T31: =T30*8 -> 11191.364
C32: Debt to EBITDA | N32: =-$D$28/N17 -> -0.45050097 | O32: =-$D$28/O17 -> -0.37422688 | P32: =-$D$28/P17 -> -0.31504853 | Q32: =-$D$28/Q17 -> -0.28050595 | R32: =-$D$28/R17 -> -0.28612852 | S32: =-$D$28/S17 -> -0.2497698 | T32: =-$D$28/T17 -> -0.22305676
C33: Rent Adjusted Debt to EBITDAR | N33: =(N31+$D$28)/(N17+N30) -> 2.0748124 | O33: =(O31+$D$28)/(O17+O30) -> 1.8893965 | P33: =(P31+$D$28)/(P17+P30) -> 1.8214033 | Q33: =(Q31+$D$28)/(Q17+Q30) -> 1.7411057 | R33: =(R31+$D$28)/(R17+R30) -> 1.7855824 | S33: =(S31+$D$28)/(S17+S30) -> 1.6711862 | T33: =(T31+$D$28)/(T17+T30) -> 1.5845864
C34: EV/EBITDA (before charges) | N34: =$D$29/N17 -> 27.400659 | O34: =$D$29/O17 -> 22.761468 | P34: =$D$29/P17 -> 19.162084 | Q34: =$D$29/Q17 -> 17.061113 | R34: =$D$29/R17 -> 17.403093 | S34: =$D$29/S17 -> 15.191659 | T34: =$D$29/T17 -> 13.566902
C35: Rent Adjusted EV/EBITDAR (before charges) | N35: =($D$29+N31)/(N17+N30) -> 23.226513 | O35: =($D$29+O31)/(O17+O30) -> 19.828503 | P35: =($D$29+P31)/(P17+P30) -> 16.974164 | Q35: =($D$29+Q31)/(Q17+Q30) -> 15.346667 | R35: =($D$29+R31)/(R17+R30) -> 15.575281 | S35: =($D$29+S31)/(S17+S30) -> 13.872687 | T35: =($D$29+T31)/(T17+T30) -> 12.59229
C36: FCF Yield | N36: =N21/$D$27 -> -0.0082528745 | O36: =O21/$D$27 -> 0.025447595 | P36: =P21/$D$27 -> 0.029744001 | Q36: =Q21/$D$27 -> 0.034322362 | R36: =R21/$D$27 -> 0.042426986 | S36: =S21/$D$27 -> 0.030351808 | T36: =T21/$D$27 -> 0.036189497
C37: P/S | N37: =$D$27/N15 -> 5.7438457 | O37: =$D$27/O15 -> 5.1704572 | P37: =$D$27/P15 -> 4.4573675 | Q37: =$D$27/Q15 -> 4.0579476 | R37: =$D$27/R15 -> 3.8700795 | S37: =$D$27/S15 -> 3.459052 | T37: =$D$27/T15 -> 3.1569128
C38: P/E | N38: =$D$25/N19 -> 52.396198 | O38: =$D$25/O19 -> 54.362735 | P38: =$D$25/P19 -> 35.946679 | Q38: =$D$25/Q19 -> 30.898884 | R38: =$D$25/R19 -> 64.408965 | S38: =$D$25/S19 -> 24.203452 | T38: =$D$25/T19 -> 20.984163

Sheet MW-Cache
A1: $H$2
A2: SBUX.O,mscalc:targetPrice,,,,USD | B2: 72 | C2: SBUX.O,mscalc:targetPrice | D2: 72 | E2: SBUX.O,mscalc:closePriceCurrencyCalc | F2: USD | G2: SBUX.O,mscalc:sedolCodeCalc | H2: 2842255

Sheet IS
DN1: =DN50 -> 0.64852084 | DO1: =DO50 -> 0.52698176 | DP1: =DP50 -> 0.64379562 | DQ1: =DQ50 -> 0.66246771 | DR1: =DR50 -> 2.4812693 | DS1: =DS50 -> 0.67247901 | DT1: =DT50 -> 0.61722872 | DU1: =DU50 -> 0.74597878 | ... EB1: =EB50 -> 3.1873226
A2: John S. Glass (617) 856-8752 | DN2: 0.64852084 | DO2: 0.52016469 | DP2: 0.65157087 | DQ2: 0.66341236 | DR2: 2.4831099 | DS2: 0.68881118 | DT2: 0.60692769 | DU2: 0.75202038 | DV2: 0.76120858 | DW2: 2.8079115 | DX2: 0.78196693 | DY2: 0.69287111 | DZ2: 0.85548958 | EA2: 0.86543689 | EB2: 3.1945656
A3: Chris Carril (617) 856-8750 | DN3: =+DN1-DN2 -> 0 | DO3: =+DO1-DO2 -> 0.0068170701 | DP3: =+DP1-DP2 -> -0.0077752446 | DQ3: =+DQ1-DQ2 -> -0.00094464993 | DR3: =+DR1-DR2 -> -0.0018406624 | DS3: =+DS1-DS2 -> -0.016332169 | DT3: =+DT1-DT2 -> 0.010301031 | DU3: =+DU1-DU2 -> -0.0060416025 | ... EB3: =+EB1-EB2 -> -0.0072429998
A5: STARBUCKS CORPORATION: INCOME STATEMENT | CB5: =CC5/BX17-1 -> 0.087971974 | CC5: =CC17*13/14 -> 2635.2857 | DO5: =1040*0.07/4 -> 18.2 | FD5: STARBUCKS CORPORATION: INCOME STATEMENT
A7: Fiscal Year Ends: September | B7: FY 1994 | C7: 34669 | D7: 34759 | E7: 34851 | F7: 34943 | G7: FY 1995 | H7: 35034 | I7: 35125 | J7: 35217 | K7: 35309 | L7: FY 1996 | M7: Dec-96R | N7: Mar-97R | O7: Jun-97R | P7: Sep-97R | Q7: FY 1997 R | R7: Dec-97 | S7: Mar-98 | T7: Jun-98 | U7: Sep-98 | V7: FY 1998 | W7: Dec-98 | X7: Mar-99 | Y7: Jun-99 | Z7: Sep-99 | AA7: FY 1999 | AB7: Dec-99 | AC7: Mar-00 | AD7: Jun-00 | AE7: Sep-00 | AF7: FY 2000A | AG7: Dec-00A | AH7: Mar-01A | AI7: Jun-01A | AJ7: Sep-01A | AK7: FY 2001 | AL7: Dec-01A | AM7: Mar-02A | AN7: Jun-02A | AO7: Sep-02A | AP7: FY 2002A | AQ7: Dec-02A | AR7: Mar-03A | AS7: Jun-03A | AT7: Sep-03A | AU7: FY 2003A | AV7: Dec-03A | AW7: Mar-04A | AX7: Jun-04A | AY7: Sep-04A | AZ7: FY 2004A | BA7: Dec-04A | BB7: Mar-05A | BC7: Jun-05A | BD7: Sep-05A | BE7: FY 2005A | BF7: Dec-05A | BG7: Mar-06A | BH7: Jun-06A | BI7: Sep-06A | BJ7: FY 2006A | BK7: Dec-06A | BL7: Mar-07A | BM7: Jun-07A | BN7: Sep-07A | BO7: FY 2007A | BP7: Dec-07A | BQ7: Mar-08A | BR7: Jun-08A | BS7: Sep-08A | BT7: FY 2008A | BU7: Dec-08A | BV7: Mar-09A | BW7: Jun-09A | BX7: Sep-09A | BY7: FY 2009A | BZ7: Dec-09A | CA7: Mar-10A | CB7: Jun-10A | CC7: Sep-10A | CD7: FY 2010A | CE7: Dec-10A | CF7: Mar-11A | CG7: Jun-11A | CH7: Sep-11A | CI7: FY 2011A | CJ7: Dec-11A | CK7: Mar-12A | CL7: Jun-12A | CM7: Sep-12A | CN7: FY 2012A | CO7: Dec-12A | CP7: Mar-13A | CQ7: Jun-13A | CR7: Sep-13A | CS7: FY2013A | CT7: Dec-13A | CU7: Mar-14A | CV7: Jun-14A | CW7: Sep-14A | CX7: FY2014A | CY7: Dec-14A | CZ7: Mar-15A | DA7: Jun-15A | DB7: Sep-15A | DC7: FY2015A | DD7: Dec-15A | DE7: Mar-16A | DF7: Jun-16A | DG7: Sep-16A | DH7: FY2016A | DI7: Dec-16A | DJ7: Mar-17A | DK7: Jun-17A | DL7: Sep-17A | DM7: FY2017A | DN7: Dec-17A | DO7: Mar-18E | DP7: Jun-18E | DQ7: Sep-18E | DR7: FY2018E | DS7: Dec-18E | DT7: Mar-19E | DU7: Jun-19E | DV7: Sep-19E | DW7: FY2019E | DX7: Dec-19E | DY7: Mar-20E | DZ7: Jun-20E | EA7: Sep-20E | EB7: FY2020E | EG7: CY 1998 | EH7: CY 1999 | EI7: CY 2000 | EJ7: CY 2001 | EK7: CY 2002 | EL7: CY 2003 | EM7: CY 2004 | EN7: CY 2005 | EO7: CY 2006 | EP7: CY 2007 | EQ7: CY 2008 | ER7: CY 2009 | ES7: CY 2010 | ET7: CY 2011 | EU7: CY 2012 | EV7: CY 2013 | EW7: CY 2014 | EX7: CY 2015 | EY7: CY 2016 | EZ7: CY 2017 | FA7: CY 2018 | FB7: CY 2019 | FD7: Fiscal Year Ends: September | FE7: =DN7 -> Dec-17A | FF7: Dec-17E | FG7: A vs. E | FH7: =DI7 -> Dec-16A | FI7: Y/Y
A8: $ in millions, quarters 4,4,5 | AA8: 53 weeks | AK8: restated | AP8: restated | AQ8: restated | AR8: restated | AU8: restated | AV8: restated | AW8: restated | AX8: restated | AY8: restated | AZ8: 53 weeks | BA8: restated | BB8: restated | BC8: restated | BD8: restated | BE8: 52 weeks | CD8: 53 weeks | CE8: restated | CF8: restated | CG8: restated | CH8: restated | FD8: dollars in millions, quarters 4,4,5
A9: SYSTEMWIDE SALES | V9: 1190 | W9: 382 | X9: 365 | Y9: 410 | Z9: 476 | AA9: 1633 | AB9: 520 | AC9: 521 | AD9: 584 | AE9: 625 | AF9: 2250 | AG9: 722 | AH9: 679 | AI9: 755 | AJ9: 795 | AK9: =SUM(AG9:AJ9) -> 2951 | AL9: 910 | AM9: 895 | AN9: 972 | AO9: 1019 | AP9: 3796 | AQ9: 1144
A10: Company Store Sales | B10: 248.495 | C10: 98.113 | D10: 86.894 | E10: 103.719 | F10: 113.929 | G10: =SUM(C10:F10) -> 402.655 | H10: 145.732 | I10: =132.301 -> 132.301 | J10: 153.212 | K10: 168.824 | L10: =SUM(H10:K10) -> 600.069 | M10: =205.338+1.012 -> 206.35 | N10: =185.061+1.355 -> 186.416 | O10: =209.993+2.051 -> 212.044 | P10: 231.482 | Q10: =SUM(M10:P10) -> 836.292 | R10: 274.973 | S10: =247.8+5.637 -> 253.437 | T10: 283.47 | U10: 290.922 | V10: 1102.574 | W10: 342.788 | X10: 318.728 | Y10: 355.951 | Z10: 405.9 | AA10: =SUM(W10:Z10) -> 1423.367 | AB10: 440.785 | AC10: 429.031 | AD10: 466.7 | AE10: 487.074 | AF10: =SUM(AB10:AE10) -> 1823.59 | AG10: 562.407 | AH10: 523.277 | AI10: 558.92 | AJ10: 584.99 | AK10: =SUM(AG10:AJ10) -> 2229.594 | AL10: 682.265 | AM10: 664.262 | AN10: 711.834 | AO10: 734.543 | AP10: =SUM(AL10:AO10) -> 2792.904 | AQ10: 849.486 | AR10: 809.317 | AS10: 877.754 | AT10: 913.066 | AU10: =SUM(AQ10:AT10) -> 3449.623 | AV10: 1080.495 | AW10: 1050.481 | AX10: 1108.055 | AY10: 1218.347 | AZ10: =SUM(AV10:AY10) -> 4457.378 | BA10: 1358.661 | BB10: 1283.947 | BC10: 1356.605 | BD10: 1392.714 | BE10: =SUM(BA10:BD10) -> 5391.927 | BF10: 1627.983 | BG10: 1599.844 | BH10: 1660.977 | BI10: 1694.294 | BJ10: =SUM(BF10:BI10) -> 6583.098 | BK10: 2006.811 | BL10: 1922.705 | BM10: 2010.772 | BN10: 2057.977 | BO10: =SUM(BK10:BN10) -> 7998.265 | BP10: 2351.5 | BQ10: 2142.9 | BR10: 2180.2 | BS10: 2097.3 | BT10: =SUM(BP10:BS10) -> 8771.9 | BU10: 2176.2 | BV10: 1961.8 | BW10: 2013.8 | BX10: 2028.4 | BY10: =SUM(BU10:BX10) -> 8180.2 | BZ10: 2292.9 | CA10: 2128.9 | CB10: 2186.7 | CC10: 2355 | CD10: =SUM(BZ10:CC10) -> 8963.5 | CE10: 2451.3 | CF10: 2293.5 | CG10: 2417.3 | CH10: 2470.4 | CI10: =SUM(CE10:CH10) -> 9632.5 | CJ10: 2731.8 | CK10: 2521.2 | CL10: 2615.6 | CM10: 2665.9 | CN10: =SUM(CJ10:CM10) -> 10534.5 | CO10: 2989.6 | CP10: 2807.7 | CQ10: 2986.3 | CR10: 3009.6 | CS10: =SUM(CO10:CR10) -> 11793.2 | CT10: 3343.8 | CU10: 3068 | CV10: 3290.5 | CW10: 3275.7 | CX10: =SUM(CT10:CW10) -> 12978 | CY10: 3772.8 | CZ10: 3622.9 | DA10: 3915 | DB10: 3886.6 | DC10: =SUM(CY10:DB10) -> 15197.3 | DD10: 4210.6 | DE10: 3944.2 | DF10: 4181.6 | DG10: 4507.8 | DH10: =SUM(DD10:DG10) -> 16844.2 | DI10: 4469.3 | DJ10: 4195.4 | DK10: 4509 | DL10: 4477 | DM10: =SUM(DI10:DL10) -> 17650.7 | DN10: 4741.8 | DO10: 4804.0164 | DP10: 5143.8377 | DQ10: 5129.744 | DR10: =SUM(DN10:DQ10) -> 19819.398 | DS10: 5287.1458 | DT10: 5254.1083 | DU10: 5635.8366 | DV10: 5622.9826 | DW10: =SUM(DS10:DV10) -> 21800.073 | DX10: 5778.283 | DY10: 5753.3039 | DZ10: 6164.7196 | EA10: 6142.8339 | EB10: =SUM(DX10:EA10) -> 23839.14 | EL10: =AZ10+BA10+BB10+BD10 -> 8492.7 | EM10: =SUM(BE10:BG10,BI10) -> 10314.048 | EN10: =BB10+BC10+BD10+BF10 -> 5661.249 | EO10: =SUM(BG10:BI10,BK10) -> 6961.926 | EP10: =SUM(BL10:BN10,BP10) -> 8342.954 | EQ10: =SUM(BQ10:BS10,BU10) -> 8596.6 | ER10: =SUM(BV10:BX10,BZ10) -> 8296.9 | ES10: =SUM(CA10:CC10,CE10) -> 9121.9 | ET10: =SUM(CF10:CH10,CJ10) -> 9913 | EU10: =SUM(CK10,CL10,CM10,CO10) -> 10792.3 | EV10: =SUM(CT10,CR10,CQ10,CP10) -> 12147.4 | EW10: =CU10+CV10+CW10+CY10 -> 13407 | EX10: =CZ10+DA10+DB10+DD10 -> 15635.1 | EY10: =DE10+DF10+DG10+DI10 -> 17102.9 | EZ10: =DJ10+DK10+DL10+DN10 -> 17923.2 | FA10: =DO10+DP10+DQ10+DS10 -> 20364.744 | FB10: =DT10+DU10+DV10+DX10 -> 22291.21 | FD10: Company Store Sales | FE10: =DN10 -> 4741.8 | FF10: 4834.8299 | FG10: =FE10-FF10 -> -93.029924 | FH10: =DI10 -> 4469.3 | FI10: =FE10/FH10-1 -> 0.060971517
A11: Licensing | AL11: 72.976 | AM11: 73.823 | AN11: 79.39 | AO11: 85.743 | AP11: =SUM(AL11:AO11) -> 311.932 | AQ11: 98.972 | AR11: 92.269 | AS11: 104.34 | AT11: 113.97 | AU11: =SUM(AQ11:AT11) -> 409.551 | AV11: 133.499 | AW11: 122.517 | AX11: 145.021 | AY11: 164.761 | AZ11: =SUM(AV11:AY11) -> 565.798 | BA11: 157.213 | BB11: 161.292 | BC11: 170.33 | BD11: 184.18 | BE11: =SUM(BA11:BD11) -> 673.015 | BF11: 219.15 | BG11: 202.354 | BH11: 216.267 | BI11: 222.905 | BJ11: =SUM(BF11:BI11) -> 860.676 | BK11: 253.922 | BL11: 234.807 | BM11: 254.904 | BN11: 282.705 | BO11: =SUM(BK11:BN11) -> 1026.338 | BP11: 304.8 | BQ11: 274.4 | BR11: 281.3 | BS11: 311.1 | BT11: =SUM(BP11:BS11) -> 1171.6 | BU11: 334.3 | BV11: 282.8 | BW11: 301 | BX11: 304.2 | BY11: =SUM(BU11:BX11) -> 1222.3 | BZ11: 326.1 | CA11: 310.4 | CB11: 330.6 | CC11: 373.8 | CD11: =SUM(BZ11:CC11) -> 1340.9 | CE11: 378.8 | CF11: =CF13 -> 237.8 | EL11: =AZ11+BA11+BB11+BD11 -> 1068.483 | EM11: =SUM(BE11:BG11,BI11) -> 1317.424 | EN11: =BB11+BC11+BD11+BF11 -> 734.952 | EO11: =SUM(BG11:BI11,BK11) -> 895.448 | EP11: =SUM(BL11:BN11,BP11) -> 1077.216 | EQ11: =SUM(BQ11:BS11,BU11) -> 1201.1 | ER11: =SUM(BV11:BX11,BZ11) -> 1214.1 | ES11: =SUM(CA11:CC11,CE11) -> 1393.6 | ET11: =SUM(CF11:CH11,CJ11) -> 237.8 | EU11: =SUM(CK11,CL11,CM11,CO11) -> 0 | EV11: =SUM(CT11,CR11,CQ11,CP11) -> 0 | EW11: =CU11+CV11+CW11+CY11 -> 0 | EX11: =CZ11+DA11+DB11+DD11 -> 0 | EY11: =DE11+DF11+DG11+DI11 -> 0 | EZ11: =DJ11+DK11+DL11+DN11 -> 0 | FA11: =DO11+DP11+DQ11+DS11 -> 0 | FB11: =DT11+DU11+DV11+DX11 -> 0 | FE11: =DN11 -> 0 | FF11: 0 | FH11: =DI11 -> 0
A12: Food Service and Other | AL12: 50.094 | AM12: 45.132 | AN12: 43.934 | AO12: 44.912 | AP12: =SUM(AL12:AO12) -> 184.072 | AQ12: 55.068 | AR12: 52.62 | AS12: 54.682 | AT12: 53.977 | AU12: =SUM(AQ12:AT12) -> 216.347 | AV12: 67.197 | AW12: 68.07 | AX12: 65.615 | AY12: 70.189 | AZ12: =SUM(AV12:AY12) -> 271.071 | BA12: 73.67 | BB12: 73.477 | BC12: 74.864 | BD12: 82.347 | BE12: =SUM(BA12:BD12) -> 304.358 | BF12: 86.959 | BG12: 83.624 | BH12: 86.429 | BI12: 86.156 | BJ12: =SUM(BF12:BI12) -> 343.168 | BK12: 94.99 | BL12: 98.082 | BM12: 93.569 | BN12: 100.253 | BO12: =SUM(BK12:BN12) -> 386.894 | BP12: 111.3 | BQ12: 108.7 | BR12: 112.5 | BS12: 107 | BT12: =SUM(BP12:BS12) -> 439.5 | BU12: 104.7 | BV12: 88.7 | BW12: 89.1 | BX12: 89.6 | BY12: =SUM(BU12:BX12) -> 372.1 | BZ12: 103.7 | CA12: 95.4 | CB12: 94.7 | CC12: 109.2 | CD12: =SUM(BZ12:CC12) -> 403 | CE12: 120.7 | CF12: =CF14 -> 254.4 | EL12: =AZ12+BA12+BB12+BD12 -> 500.565 | EM12: =SUM(BE12:BG12,BI12) -> 561.097 | EN12: =BB12+BC12+BD12+BF12 -> 317.647 | EO12: =SUM(BG12:BI12,BK12) -> 351.199 | EP12: =SUM(BL12:BN12,BP12) -> 403.204 | EQ12: =SUM(BQ12:BS12,BU12) -> 432.9 | ER12: =SUM(BV12:BX12,BZ12) -> 371.1 | ES12: =SUM(CA12:CC12,CE12) -> 420 | ET12: =SUM(CF12:CH12,CJ12) -> 254.4 | EU12: =SUM(CK12,CL12,CM12,CO12) -> 0 | EV12: =SUM(CT12,CR12,CQ12,CP12) -> 0 | EW12: =CU12+CV12+CW12+CY12 -> 0 | EX12: =CZ12+DA12+DB12+DD12 -> 0 | EY12: =DE12+DF12+DG12+DI12 -> 0 | EZ12: =DJ12+DK12+DL12+DN12 -> 0 | FA12: =DO12+DP12+DQ12+DS12 -> 0 | FB12: =DT12+DU12+DV12+DX12 -> 0 | FE12: =DN12 -> 0 | FF12: 0 | FH12: =DI12 -> 0
A13: Licensed stores | BP13: 204.2 | BQ13: 178.1 | BR13: 190.5 | BS13: 206.2 | BT13: =SUM(BP13:BS13) -> 779 | BU13: 219.9 | BV13: 188 | BW13: 194.7 | BX13: 192.4 | BY13: =SUM(BU13:BX13) -> 795 | BZ13: 216.5 | CA13: 210.9 | CB13: 213.5 | CC13: 234.3 | CD13: =SUM(BZ13:CC13) -> 875.2 | CE13: 254.2 | CF13: 237.8 | CG13: 248.7 | CH13: 266.8 | CI13: =SUM(CE13:CH13) -> 1007.5 | CJ13: 306.6 | CK13: 290.3 | CL13: 308.2 | CM13: 305.3 | CN13: =SUM(CJ13:CM13) -> 1210.4 | CO13: 350.2 | CP13: 322.1 | CQ13: 342 | CR13: 346.3 | CS13: =SUM(CO13:CR13) -> 1360.6 | CT13: 401.8 | CU13: 356.2 | CV13: 408.1 | CW13: 422.6 | CX13: =SUM(CT13:CW13) -> 1588.7 | CY13: 483.9 | CZ13: 421.3 | DA13: 475.2 | DB13: 481.4 | DC13: =SUM(CY13:DB13) -> 1861.8 | DD13: 540.6 | DE13: 493.1 | DF13: 527.2 | DG13: 593.2 | DH13: =SUM(DD13:DG13) -> 2154.1 | DI13: 602.4 | DJ13: 546.7 | DK13: 588.3 | DL13: 617.6 | DM13: =SUM(DI13:DL13) -> 2355 | DN13: 682.4 | DO13: 579.99657 | DP13: 617.85616 | DQ13: 665.97631 | DR13: =SUM(DN13:DQ13) -> 2546.229 | DS13: 753.76952 | DT13: 657.82113 | DU13: 699.79354 | DV13: 753.0606 | DW13: =SUM(DS13:DV13) -> 2864.4448 | DX13: 850.99726 | DY13: 741.36197 | DZ13: 787.61404 | EA13: 846.09414 | EB13: =SUM(DX13:EA13) -> 3226.0674 | ET13: =SUM(CF13:CH13,CJ13) -> 1059.9 | EU13: =SUM(CK13,CL13,CM13,CO13) -> 1254 | EV13: =SUM(CT13,CR13,CQ13,CP13) -> 1412.2 | EW13: =CU13+CV13+CW13+CY13 -> 1670.8 | EX13: =CZ13+DA13+DB13+DD13 -> 1918.5 | EY13: =DE13+DF13+DG13+DI13 -> 2215.9 | EZ13: =DJ13+DK13+DL13+DN13 -> 2435 | FA13: =DO13+DP13+DQ13+DS13 -> 2617.5986 | FB13: =DT13+DU13+DV13+DX13 -> 2961.6725 | FD13: Licensed stores | FE13: =DN13 -> 682.4 | FF13: 680.32312 | FG13: =FE13-FF13 -> 2.0768775 | FH13: =DI13 -> 602.4 | FI13: =FE13/FH13-1 -> 0.13280212
A14: CPG, foodservice and other | BP14: 211.9 | BQ14: 205 | BR14: 203.2 | BS14: 212 | BT14: =SUM(BP14:BS14) -> 832.1 | BU14: 219.1 | BV14: 183.5 | BW14: 195.4 | BX14: 201.4 | BY14: =SUM(BU14:BX14) -> 799.4 | BZ14: 213.3 | CA14: 194.9 | CB14: 211.8 | CC14: 248.7 | CD14: =SUM(BZ14:CC14) -> 868.7 | CE14: 245.3 | CF14: 254.4 | CG14: 266.2 | CH14: 294.7 | CI14: =SUM(CE14:CH14) -> 1060.6 | CJ14: 391.6 | CK14: 378.7 | CL14: 374.4 | CM14: 387.3 | CN14: =SUM(CJ14:CM14) -> 1532 | CO14: 453.4 | CP14: 419.8 | CQ14: 407 | CR14: 432.9 | CS14: =SUM(CO14:CR14) -> 1713.1 | CT14: 494 | CU14: 449.6 | CV14: 455.1 | CW14: 482.5 | CX14: =SUM(CT14:CW14) -> 1881.2 | CY14: 546.5 | CZ14: 519.3 | DA14: 491 | DB14: 546.8 | DC14: =SUM(CY14:DB14) -> 2103.6 | DD14: 622.3 | DE14: 555.9 | DF14: 529.2 | DG14: 610.2 | DH14: =SUM(DD14:DG14) -> 2317.6 | DI14: 661.2 | DJ14: 551.9 | DK14: 564.2 | DL14: 603.7 | DM14: =SUM(DI14:DL14) -> 2381 | DN14: 649.5 | DO14: 566.825 | DP14: 571.988 | DQ14: 611.767 | DR14: =SUM(DN14:DQ14) -> 2400.08 | DS14: 695.21025 | DT14: 603.53343 | DU14: 609.3798 | DV14: 651.97585 | DW14: =SUM(DS14:DV14) -> 2560.0993 | DX14: 744.01481 | DY14: 642.82706 | DZ14: 650.5343 | EA14: 697.0373 | EB14: =SUM(DX14:EA14) -> 2734.4135 | ET14: =SUM(CF14:CH14,CJ14) -> 1206.9 | EU14: =SUM(CK14,CL14,CM14,CO14) -> 1593.8 | EV14: =SUM(CT14,CR14,CQ14,CP14) -> 1753.7 | EW14: =CU14+CV14+CW14+CY14 -> 1933.7 | EX14: =CZ14+DA14+DB14+DD14 -> 2179.4 | EY14: =DE14+DF14+DG14+DI14 -> 2356.5 | EZ14: =DJ14+DK14+DL14+DN14 -> 2369.3 | FA14: =DO14+DP14+DQ14+DS14 -> 2445.7902 | FB14: =DT14+DU14+DV14+DX14 -> 2608.9039 | FD14: CPG, foodservice and other | FE14: =DN14 -> 649.5 | FF14: 705.3975 | FG14: =FE14-FF14 -> -55.8975 | FH14: =DI14 -> 661.2 | FI14: =FE14/FH14-1 -> -0.0176951
A15: Specialty Sales | B15: 26.542 | C15: 11.54 | D15: 11.439 | E15: 12.376 | F15: 12.787 | G15: =SUM(C15:F15) -> 48.142 | H15: 16.616 | I15: 18.024 | J15: 19.855 | K15: 24.159 | L15: =SUM(H15:K15)+17.8 -> 96.454 | M15: 25.022 | N15: 25.498 | O15: 27.9 | P15: 39.441 | Q15: =SUM(M15:P15)+21.2 -> 139.061 | R15: 38.779 | S15: 37.787 | T15: 47 | U15: 66.783 | V15: 206.128 | W15: 62.85 | X15: 57.094 | Y15: 67.841 | Z15: 68.97 | AA15: =SUM(W15:Z15) -> 256.755 | AB15: =86.197+2.35 -> 88.547 | AC15: =75.667+1.97 -> 77.637 | AD15: =88.8+1.97 -> 90.77 | AE15: =94.918+2.106 -> 97.024 | AF15: =SUM(AB15:AE15) -> 353.978 | AG15: 104.98 | AH15: 106.011 | AI15: 103.849 | AJ15: 104.546 | AK15: =SUM(AG15:AJ15) -> 419.386 | AL15: =AL11+AL12 -> 123.07 | AM15: =AM11+AM12 -> 118.955 | AN15: =AN11+AN12 -> 123.324 | AO15: =AO11+AO12 -> 130.655 | AP15: =SUM(AL15:AO15) -> 496.004 | AQ15: =AQ11+AQ12 -> 154.04 | AR15: =AR11+AR12 -> 144.889 | AS15: =AS11+AS12 -> 159.022 | AT15: =AT11+AT12 -> 167.947 | AU15: =SUM(AQ15:AT15) -> 625.898 | AV15: =AV11+AV12 -> 200.696 | AW15: =AW11+AW12 -> 190.587 | AX15: =AX11+AX12 -> 210.636 | AY15: =AY11+AY12 -> 234.95 | AZ15: =AZ11+AZ12 -> 836.869 | BA15: =BA11+BA12 -> 230.883 | BB15: =BB11+BB12 -> 234.769 | BC15: =BC11+BC12 -> 245.194 | ... BO15: =BO11+BO12 -> 1413.232 | BP15: =BP13+BP14 -> 416.1 | BQ15: =BQ13+BQ14 -> 383.1 | BR15: =BR13+BR14 -> 393.7 | BS15: =BS13+BS14 -> 418.2 | BT15: =BT11+BT12 -> 1611.1 | BU15: =BU13+BU14 -> 439 | BV15: =BV13+BV14 -> 371.5 | BW15: =BW13+BW14 -> 390.1 | BX15: =BX13+BX14 -> 393.8 | BY15: =BY13+BY14 -> 1594.4 | BZ15: =BZ13+BZ14 -> 429.8 | CA15: =CA13+CA14 -> 405.8 | CB15: =CB13+CB14 -> 425.3 | ... CD15: =CD13+CD14 -> 1743.9 | CE15: =CE14+CE13 -> 499.5 | CF15: =CF14+CF13 -> 492.2 | CG15: =CG14+CG13 -> 514.9 | CH15: =CH14+CH13 -> 561.5 | CI15: =CI14+CI13 -> 2068.1 | CJ15: =CJ14+CJ13 -> 698.2 | CK15: =CK14+CK13 -> 669 | CL15: =CL14+CL13 -> 682.6 | CM15: =CM14+CM13 -> 692.6 | CN15: =SUM(CJ15:CM15) -> 2742.4 | CO15: =CO14+CO13 -> 803.6 | CP15: =CP14+CP13 -> 741.9 | CQ15: =CQ14+CQ13 -> 749 | CR15: =CR14+CR13 -> 779.2 | CS15: =CS14+CS13 -> 3073.7 | CT15: =CT14+CT13 -> 895.8 | CU15: =CU14+CU13 -> 805.8 | CV15: =CV14+CV13 -> 863.2 | ... EB15: =EB14+EB13 -> 5960.4809 | EL15: =AZ15+BA15+BB15+BD15 -> 1569.048 | EM15: =SUM(BE15:BG15,BI15) -> 1878.521 | EN15: =BB15+BC15+BD15+BF15 -> 1052.599 | EO15: =SUM(BG15:BI15,BK15) -> 1246.647 | EP15: =SUM(BL15:BN15,BP15) -> 1480.42 | EQ15: =SUM(BQ15:BS15,BU15) -> 1634 | ER15: =SUM(BV15:BX15,BZ15) -> 1585.2 | ES15: =SUM(CA15:CC15,CE15) -> 1813.6 | ET15: =SUM(CF15:CH15,CJ15) -> 2266.8 | EU15: =SUM(CK15,CL15,CM15,CO15) -> 2847.8 | EV15: =SUM(CT15,CR15,CQ15,CP15) -> 3165.9 | EW15: =CU15+CV15+CW15+CY15 -> 3604.5 | EX15: =CZ15+DA15+DB15+DD15 -> 4097.9 | EY15: =DE15+DF15+DG15+DI15 -> 4572.4 | EZ15: =DJ15+DK15+DL15+DN15 -> 4804.3 | FA15: =DO15+DP15+DQ15+DS15 -> 5063.3888 | FB15: =DT15+DU15+DV15+DX15 -> 5570.5764 | FD15: Specialty Sales | FE15: =DN15 -> 1331.9 | FF15: 1385.7206 | FG15: =FE15-FF15 -> -53.820623 | FH15: =DI15 -> 1263.6 | FI15: =FE15/FH15-1 -> 0.054051915
A16: Mail Order (2) | B16: 9.886 | C16: 5.892 | D16: 2.78 | E16: 3.079 | F16: 2.664 | G16: =SUM(C16:F16) -> 14.415 | H16: 7.189 | I16: 3.284 | J16: 3.883 | K16: 3.402 | L16: =SUM(H16:K16) -> 17.758 | M16: 8.782 | N16: 4.356 | O16: 4.297 | P16: 3.802 | Q16: =SUM(M16:P16) -> 21.237 | R16: 7.573 | S16: 4.019 | T16: 3.959 | U16: 0 | V16: =SUM(R16:U16) -> 15.551 | FE16: =DN16 -> 0 | FF16: 0 | FH16: =DI16 -> 0
A17: Net Sales | B17: 284.923 | C17: =SUM(C10:C16) -> 115.545 | D17: =SUM(D10:D16) -> 101.113 | E17: =SUM(E10:E16) -> 119.174 | F17: =SUM(F10:F16) -> 129.38 | G17: =SUM(G10:G16) -> 465.212 | H17: =SUM(H10:H16) -> 169.537 | I17: =SUM(I10:I16) -> 153.609 | J17: =SUM(J10:J16) -> 176.95 | K17: =SUM(K10:K16) -> 196.385 | L17: =SUM(L10:L15) -> 696.523 | M17: =SUM(M10:M16) -> 240.154 | N17: =SUM(N10:N16) -> 216.27 | O17: =SUM(O10:O16) -> 244.241 | P17: =SUM(P10:P16) -> 274.725 | Q17: =SUM(Q10:Q15) -> 975.353 | R17: =SUM(R10:R16) -> 321.325 | S17: =SUM(S10:S16) -> 295.243 | T17: =SUM(T10:T16) -> 334.429 | U17: =SUM(U10:U16) -> 357.705 | V17: =SUM(V10:V15) -> 1308.702 | W17: =SUM(W10:W16) -> 405.638 | X17: =SUM(X10:X16) -> 375.822 | Y17: =SUM(Y10:Y16) -> 423.792 | Z17: =SUM(Z10:Z16) -> 474.87 | AA17: =SUM(W17:Z17) -> 1680.122 | AB17: =SUM(AB10:AB16) -> 529.332 | AC17: =SUM(AC10:AC16) -> 506.668 | AD17: =SUM(AD10:AD16) -> 557.47 | AE17: =SUM(AE10:AE16) -> 584.098 | AF17: =SUM(AB17:AE17) -> 2177.568 | AG17: =SUM(AG10:AG16) -> 667.387 | AH17: =SUM(AH10:AH16) -> 629.288 | AI17: =SUM(AI10:AI16) -> 662.769 | AJ17: =SUM(AJ10:AJ16) -> 689.536 | AK17: =SUM(AG17:AJ17) -> 2648.98 | AL17: =AL10+AL15 -> 805.335 | AM17: =AM10+AM15 -> 783.217 | AN17: =AN10+AN15 -> 835.158 | AO17: =AO10+AO15 -> 865.198 | AP17: =SUM(AL17:AO17) -> 3288.908 | AQ17: =AQ10+AQ15 -> 1003.526 | AR17: =AR10+AR15 -> 954.206 | AS17: =AS10+AS15 -> 1036.776 | AT17: =AT10+AT15 -> 1081.013 | AU17: =SUM(AQ17:AT17) -> 4075.521 | AV17: =AV10+AV15 -> 1281.191 | AW17: =AW10+AW15 -> 1241.068 | AX17: =AX10+AX15 -> 1318.691 | AY17: =AY10+AY15 -> 1453.297 | AZ17: =SUM(AV17:AY17) -> 5294.247 | BA17: =BA10+BA15 -> 1589.544 | BB17: =BB10+BB15 -> 1518.716 | BC17: =BC10+BC15 -> 1601.799 | BD17: =BD10+BD15 -> 1659.241 | BE17: =BE10+BE15 -> 6369.3 | BF17: =BF10+BF15 -> 1934.092 | BG17: =BG10+BG15 -> 1885.822 | BH17: =BH10+BH15 -> 1963.673 | ... EB17: =EB10+EB15 -> 29799.621 | EG17: =S17+T17+U17+W17 -> 1393.015 | EH17: =X17+Y17+Z17+AB17 -> 1803.816 | EI17: =AC17+AD17+AE17+AG17 -> 2315.623 | EJ17: =AH17+AI17+AJ17+AL17 -> 2786.928 | EK17: =AM17+AN17+AO17+AQ17 -> 3487.099 | EL17: =AR17+AS17+AT17+AV17 -> 4353.186 | EM17: =AW17+AX17+AY17+BA17 -> 5602.6 | EN17: =BB17+BC17+BD17+BF17 -> 6713.848 | EO17: =SUM(BG17:BI17,BK17) -> 8208.573 | EP17: =SUM(BL17:BN17,BP17) -> 9823.374 | EQ17: =SUM(BQ17:BS17,BU17) -> 10230.6 | ER17: =SUM(BV17:BX17,BZ17) -> 9882.1 | ES17: =SUM(CA17:CC17,CE17) -> 10935.5 | ET17: =SUM(CF17:CH17,CJ17) -> 12179.8 | EU17: =SUM(CK17,CL17,CM17,CO17) -> 13640.1 | EV17: =SUM(CT17,CR17,CQ17,CP17) -> 15313.3 | EW17: =CU17+CV17+CW17+CY17 -> 17011.5 | EX17: =CZ17+DA17+DB17+DD17 -> 19733 | EY17: =DE17+DF17+DG17+DI17 -> 21675.3 | EZ17: =DJ17+DK17+DL17+DN17 -> 22727.5 | FA17: =DO17+DP17+DQ17+DS17 -> 25428.133 | FB17: =DT17+DU17+DV17+DX17 -> 27861.787 | FD17: Net Sales | FE17: =DN17 -> 6073.7 | FF17: 6220.5505 | FG17: =FE17-FF17 -> -146.85055 | FH17: =DI17 -> 5732.9 | FI17: =FE17/FH17-1 -> 0.059446354
A19: Cost of sales | BP19: 910.5 | BQ19: 819.6 | BR19: 860.7 | BS19: 878.3 | BT19: 3469.2 | BU19: 915.3 | BV19: 772.7 | BW19: 766.5 | BX19: 754 | BY19: 3208.5 | BZ19: 859.5 | CA19: 788.4 | CB19: 796.8 | CC19: 881.1 | CD19: 3325.8 | CH19: 169.3 | CI19: 595.5 | EQ19: =SUM(BQ19:BS19,BU19) -> 3473.9 | ER19: =SUM(BV19:BX19,BZ19) -> 3152.7 | ES19: =SUM(CA19:CC19,CE19) -> 2466.3 | ET19: =SUM(CF19:CH19,CJ19) -> 169.3 | EU19: =SUM(CK19,CL19,CM19,CO19) -> 0 | EV19: =SUM(CT19,CR19,CQ19,CP19) -> 0 | EW19: =CU19+CV19+CW19+CY19 -> 0 | EX19: =CZ19+DA19+DB19+DD19 -> 0 | EY19: =DE19+DF19+DG19+DI19 -> 0 | EZ19: =DJ19+DK19+DL19+DN19 -> 0 | FA19: =DO19+DP19+DQ19+DS19 -> 0 | FB19: =DT19+DU19+DN19+DP19 -> 0 | FH19: =CP19 -> 0
A20: Occupancy costs | BP20: 275.5 | BQ20: 287.1 | BR20: 302.4 | BS20: 311 | BT20: 1176.1 | BU20: 281.6 | BV20: 270.7 | BW20: 276.9 | BX20: 287.2 | BY20: 1116.4 | BZ20: 286.1 | CA20: 275.7 | CB20: 279.2 | CC20: 291.5 | CD20: 1132.5 | CH20: 0 | CI20: 0 | FH20: =CP20 -> 0
A21: Cost of Sales and Related Occupancy Costs | B21: 130.324 | C21: 51.983 | D21: 45.639 | E21: 53.723 | F21: 59.935 | G21: =SUM(C21:F21) -> 211.28 | H21: 86.663 | I21: 76.938 | J21: 83.164 | K21: 89.181 | L21: =SUM(H21:K21) -> 335.946 | M21: 116.101 | N21: =216.071-M21 -> 99.97 | O21: =319.906-N21-M21 -> 103.835 | P21: =436.942-O21-N21-M21 -> 117.036 | Q21: =SUM(M21:P21) -> 436.942 | R21: 146.235 | S21: 133.501 | T21: 143.313 | U21: 153.666 | V21: =SUM(R21:U21) -> 576.715 | W21: 186.3 | X21: 169.957 | Y21: 185.02 | Z21: 199.734 | AA21: =SUM(W21:Z21) -> 741.011 | AB21: 240.714 | AC21: 225.24 | AD21: 243.066 | AE21: 252.865 | AF21: =SUM(AB21:AE21) -> 961.885 | AG21: 292.22 | AH21: 271.178 | AI21: 271.35 | AJ21: 278.037 | AK21: =SUM(AG21:AJ21) -> 1112.785 | AL21: 337.029 | AM21: 320.081 | AN21: 337.401 | AO21: 355.5 | AP21: =SUM(AL21:AO21) -> 1350.011 | AQ21: 419.161 | AR21: 392.098 | AS21: 425.709 | AT21: 448.96 | AU21: =SUM(AQ21:AT21) -> 1685.928 | AV21: 528.709 | AW21: 508.268 | AX21: 540.175 | AY21: 614.288 | AZ21: =SUM(AV21:AY21) -> 2191.44 | BA21: 647.755 | BB21: 628.74 | BC21: 649.831 | BD21: 678.886 | BE21: =SUM(BA21:BD21) -> 2605.212 | BF21: 778.038 | BG21: 760.873 | BH21: 804.889 | BI21: 834.991 | BJ21: =SUM(BF21:BI21) -> 3178.791 | BK21: 984.823 | BL21: 944.746 | BM21: 1003.881 | BN21: 1065.674 | BO21: =SUM(BK21:BN21) -> 3999.124 | BP21: 1186 | BQ21: 1106.7 | BR21: 1163.1 | BS21: 1189.5 | BT21: =SUM(BP21:BS21) -> 4645.3 | BU21: 1196.8 | BV21: 1043.5 | BW21: 1043.4 | BX21: 1041.2 | BY21: =SUM(BU21:BX21) -> 4324.9 | BZ21: 1145.7 | CA21: 1064.1 | CB21: 1076.2 | CC21: 1172.6 | CD21: =SUM(BZ21:CC21) -> 4458.6 | CE21: 1192.3 | CF21: 1171.2 | CG21: 1237.5 | CH21: 1314.5 | CI21: =SUM(CE21:CH21) -> 4915.5 | CJ21: 1496.1 | CK21: 1411.9 | CL21: 1446.1 | CM21: 1459.2 | CN21: =SUM(CJ21:CM21) -> 5813.3 | CO21: 1620.7 | CP21: 1530.4 | CQ21: 1597.6 | CR21: 1633.7 | CS21: =SUM(CO21:CR21) -> 6382.4 | CT21: 1795.1 | CU21: 1629.2 | CV21: 1711.5 | CW21: 1723.2 | CX21: =SUM(CT21:CW21) -> 6859 | CY21: 1991.2 | CZ21: 1859.8 | DA21: 1953.9 | DB21: 1982.6 | DC21: =SUM(CY21:DB21) -> 7787.5 | DD21: 2186.2 | DE21: 2010.3 | DF21: 2060.3 | DG21: 2254.2 | DH21: =SUM(DD21:DG21) -> 8511 | DI21: 2295 | DJ21: 2141.2 | DK21: 2249.1 | DL21: 2352.9 | DM21: =SUM(DI21:DL21) -> 9038.2 | DN21: 2502.9 | DO21: 2454.3139 | DP21: 2561.7893 | DQ21: 2607.6475 | DR21: =SUM(DN21:DQ21) -> 10126.651 | DS21: 2747.1685 | DT21: 2649.7999 | DU21: 2771.8859 | DV21: 2826.0405 | DW21: =SUM(DS21:DV21) -> 10994.895 | DX21: 2981.4779 | DY21: 2878.0754 | DZ21: 3008.3822 | EA21: 3064.8763 | EB21: =SUM(DX21:EA21) -> 11932.812 | EG21: =S21+T21+U21+W21 -> 616.78 | EH21: =X21+Y21+Z21+AB21 -> 795.425 | EI21: =AC21+AD21+AE21+AG21 -> 1013.391 | EJ21: =AH21+AI21+AJ21+AL21 -> 1157.594 | EK21: =AM21+AN21+AO21+AQ21 -> 1432.143 | EL21: =AR21+AS21+AT21+AV21 -> 1795.476 | EM21: =AW21+AX21+AY21+BA21 -> 2310.486 | EN21: =BB21+BC21+BD21+BF21 -> 2735.495 | EO21: =SUM(BG21:BI21,BK21) -> 3385.576 | EP21: =SUM(BL21:BN21,BP21) -> 4200.301 | EQ21: =SUM(BQ21:BS21,BU21) -> 4656.1 | ER21: =SUM(BV21:BX21,BZ21) -> 4273.8 | ES21: =SUM(CA21:CC21,CE21) -> 4505.2 | ET21: =SUM(CF21:CH21,CJ21) -> 5219.3 | EU21: =SUM(CK21,CL21,CM21,CO21) -> 5937.9 | EV21: =SUM(CT21,CR21,CQ21,CP21) -> 6556.8 | EW21: =CU21+CV21+CW21+CY21 -> 7055.1 | EX21: =CZ21+DA21+DB21+DD21 -> 7982.5 | EY21: =DE21+DF21+DG21+DI21 -> 8619.8 | EZ21: =DJ21+DK21+DL21+DN21 -> 9246.1 | FA21: =DO21+DP21+DQ21+DS21 -> 10370.919 | FB21: =DT21+DU21+DV21+DX21 -> 11229.204 | FD21: Cost of Sales and Related Occupancy Costs | FE21: =DN21 -> 2502.9 | FF21: 2476.039 | FG21: =FE21-FF21 -> 26.860957 | FH21: =DI21 -> 2295 | FI21: =FE21/FH21-1 -> 0.090588235
A22: Store Operating Expenses | B22: 90.094 | C22: 35.461 | D22: 33.882 | E22: 39.304 | F22: 40.109 | G22: =SUM(C22:F22) -> 148.756 | H22: 47.1 | I22: 47 | J22: 54.8 | K22: 61.7 | L22: =SUM(H22:K22) -> 210.6 | M22: 71.016 | N22: 70.057 | O22: 82.664 | P22: 90.327 | Q22: =SUM(M22:P22) -> 314.064 | R22: 98.101 | S22: 95.026 | T22: 106.869 | U22: 113.617 | V22: =SUM(R22:U22) -> 413.613 | W22: 122.601 | X22: 121.845 | Y22: 137.625 | Z22: 161.498 | AA22: =SUM(W22:Z22) -> 543.569 | AB22: 164.2 | AC22: 169.257 | AD22: 185.515 | AE22: 185.927 | AF22: =SUM(AB22:AE22) -> 704.899 | AG22: 209.69 | AH22: 208.608 | AI22: 226.614 | AJ22: 230.561 | AK22: 867.957 | AL22: 260.49 | AM22: 270.986 | AN22: 291.445 | AO22: 298.187 | AP22: 1109.782 | AQ22: 320.287 | AR22: 329.153 | AS22: 361.835 | AT22: 373.663 | AU22: 1379.574 | AV22: 405.821 | AW22: 425.976 | AX22: 448.029 | AY22: 510.342 | AZ22: =SUM(AV22:AY22) -> 1790.168 | BA22: 521.006 | BB22: 532.944 | BC22: 546.008 | BD22: 565.953 | BE22: =SUM(BA22:BD22) -> 2165.911 | BF22: 622.166 | BG22: 665.273 | BH22: 686.602 | BI22: 713.774 | BJ22: =SUM(BF22:BI22) -> 2687.815 | BK22: 771.967 | BL22: 780.985 | BM22: 819.212 | BN22: 843.725 | BO22: =SUM(BK22:BN22) -> 3215.889 | BP22: 927.3 | BQ22: 927.14 | BR22: 958.3 | BS22: 932.4 | BT22: =SUM(BP22:BS22) -> 3745.14 | BU22: =936.6 -> 936.6 | BV22: 819.6 | BW22: 821.4 | BX22: 847.5 | BY22: =SUM(BU22:BX22) -> 3425.1 | BZ22: 896.1 | CA22: 828 | CB22: 888.9 | CC22: 938.4 | CD22: =SUM(BZ22:CC22) -> 3551.4 | CE22: 888 | CF22: 867.2 | CG22: 917.1 | CH22: 922.9 | CI22: =SUM(CE22:CH22) -> 3595.2 | CJ22: 995.7 | CK22: 956.5 | CL22: 976 | CM22: 989.9 | CN22: =SUM(CJ22:CM22) -> 3918.1 | CO22: 1089.5 | CP22: 1038.4 | CQ22: 1084.1 | CR22: 1073.9 | CS22: =SUM(CO22:CR22) -> 4285.9 | CT22: 1175.1 | CU22: 1134.5 | CV22: 1176.5 | CW22: 1152.1 | CX22: =SUM(CT22:CW22) -> 4638.2 | CY22: 1315.5 | CZ22: 1324.6 | DA22: 1392.4 | DB22: 1378.6 | DC22: =SUM(CY22:DB22) -> 5411.1 | DD22: 1506.2 | DE22: 1466.4 | DF22: 1529.4 | DG22: 1562.3 | DH22: =SUM(DD22:DG22) -> 6064.3 | DI22: 1638.2 | DJ22: 1586.4 | DK22: 1628.9 | DL22: 1639.8 | DM22: =SUM(DI22:DL22) -> 6493.3 | DN22: 1737 | DO22: 1797.7155 | DP22: 1851.537 | DQ22: 1880.2069 | DR22: =SUM(DN22:DQ22) -> 7266.4594 | DS22: 1942.8655 | DT22: 1959.8978 | DU22: 2026.602 | DV22: 2058.1218 | DW22: =SUM(DS22:DV22) -> 7987.4871 | DX22: 2118.931 | DY22: 2137.2304 | DZ22: 2207.0311 | EA22: 2239.1097 | EB22: =SUM(DX22:EA22) -> 8702.3021 | EG22: =S22+T22+U22+W22 -> 438.113 | EH22: =X22+Y22+Z22+AB22 -> 585.168 | EI22: =AC22+AD22+AE22+AG22 -> 750.389 | EJ22: =AH22+AI22+AJ22+AL22 -> 926.273 | EK22: =AM22+AN22+AO22+AQ22 -> 1180.905 | EL22: =AR22+AS22+AT22+AV22 -> 1470.472 | EM22: =AW22+AX22+AY22+BA22 -> 1905.353 | EN22: =BB22+BC22+BD22+BF22 -> 2267.071 | EO22: =SUM(BG22:BI22,BK22) -> 2837.616 | EP22: =SUM(BL22:BN22,BP22) -> 3371.222 | EQ22: =SUM(BQ22:BS22,BU22) -> 3754.44 | ER22: =SUM(BV22:BX22,BZ22) -> 3384.6 | ES22: =SUM(CA22:CC22,CE22) -> 3543.3 | ET22: =SUM(CF22:CH22,CJ22) -> 3702.9 | EU22: =SUM(CK22,CL22,CM22,CO22) -> 4011.9 | EV22: =SUM(CT22,CR22,CQ22,CP22) -> 4371.5 | EW22: =CU22+CV22+CW22+CY22 -> 4778.6 | EX22: =CZ22+DA22+DB22+DD22 -> 5601.8 | EY22: =DE22+DF22+DG22+DI22 -> 6196.3 | EZ22: =DJ22+DK22+DL22+DN22 -> 6592.1 | FA22: =DO22+DP22+DQ22+DS22 -> 7472.3249 | FB22: =DT22+DU22+DV22+DX22 -> 8163.5525 | FD22: Store Operating Expenses | FE22: =DN22 -> 1737 | FF22: 1796.1314 | FG22: =FE22-FF22 -> -59.131385 | FH22: =DI22 -> 1638.2 | FI22: =FE22/FH22-1 -> 0.060310096
A23: Other Op. Expenses | B23: 8.696 | C23: 3.726 | D23: 2.875 | E23: =9.433-E24 -> 3.515 | F23: 3.817 | G23: =SUM(C23:F23) -> 13.933 | H23: 5.8 | I23: 3.8 | J23: 4.9 | K23: 5.3 | L23: =SUM(H23:K23) -> 19.8 | M23: 7.779 | N23: 6.931 | O23: 7.159 | P23: 6.37 | Q23: =SUM(M23:P23) -> 28.239 | R23: 9.674 | S23: 8.634 | T23: 12.221 | U23: 12.952 | V23: =SUM(R23:U23) -> 43.481 | W23: =13.308+W27 -> 13.028 | X23: =11.142+X27 -> 11.087 | Y23: =13.04+Y27 -> 13.4 | Z23: =13.883+Z27 -> 17.049 | AA23: =SUM(W23:Z23) -> 54.564 | AB23: 17.745 | AC23: 20.202 | AD23: 17.659 | AE23: 22.829 | AF23: =SUM(AB23:AE23) -> 78.435 | AG23: 21.786 | AH23: 23.785 | AI23: 22.695 | AJ23: 25.06 | AK23: 72.406 | AL23: 30.325 | AM23: 33.543 | AN23: 29.269 | AO23: 34.041 | AP23: 106.084 | AQ23: 31.516 | AR23: 36.521 | AS23: 41.946 | AT23: 43.658 | AU23: 141.346 | AV23: 43.698 | AW23: 40.802 | AX23: 44.259 | AY23: 42.889 | AZ23: =SUM(AV23:AY23) -> 171.648 | BA23: 44.281 | BB23: 46.347 | BC23: 48.464 | BD23: 57.932 | BE23: =SUM(BA23:BD23) -> 197.024 | BF23: 59.148 | BG23: 63.648 | BH23: 69.478 | BI23: 67.813 | BJ23: =SUM(BF23:BI23) -> 260.087 | BK23: 72.538 | BL23: 75.661 | BM23: 76.507 | BN23: 74.51 | BO23: =SUM(BK23:BN23) -> 299.216 | BP23: 85.7 | BQ23: 82.8 | BR23: 79.6 | BS23: 82 | BT23: =SUM(BP23:BS23) -> 330.1 | BU23: 72.6 | BV23: 64 | BW23: 69.2 | BX23: 58.6 | BY23: =SUM(BU23:BX23) -> 264.4 | BZ23: 71.9 | CA23: 61.8 | CB23: 77.2 | CC23: 82.3 | CD23: =SUM(BZ23:CC23) -> 293.2 | CE23: 90.1 | CF23: 98.9 | CG23: 100 | CH23: 103.7 | CI23: =SUM(CE23:CH23) -> 392.7 | CJ23: 100.8 | CK23: 99.6 | CL23: 100.5 | CM23: 106.2 | CN23: =SUM(CJ23:CM23) -> 407.1 | CO23: 126.1 | CP23: 105.8 | CQ23: 98.9 | CR23: 101.1 | CS23: =SUM(CO23:CR23) -> 431.9 | CT23: 114.9 | CU23: 110.9 | CV23: 120.6 | CW23: 111 | CX23: =SUM(CT23:CW23) -> 457.4 | CY23: 129.4 | CZ23: 133.5 | DA23: 131.6 | DB23: 127.9 | DC23: =SUM(CY23:DB23) -> 522.4 | DD23: 146.2 | DE23: 139.6 | DF23: 137.5 | DG23: 122.1 | DH23: =SUM(DD23:DG23) -> 545.4 | DI23: 145.4 | DJ23: 134.7 | DK23: 142.5 | DL23: 131.1 | DM23: =SUM(DI23:DL23) -> 553.7 | DN23: 141.6 | DO23: 146.19318 | DP23: 148.07814 | DQ23: 136.50251 | DR23: =SUM(DN23:DQ23) -> 572.37383 | DS23: 148.16902 | DT23: 150.34351 | DU23: 155.39241 | DV23: 144.27414 | DW23: =SUM(DS23:DV23) -> 598.17908 | DX23: 161.84502 | DY23: 158.82909 | DZ23: 164.11428 | EA23: 152.43131 | EB23: =SUM(DX23:EA23) -> 637.2197 | EG23: =S23+T23+U23+W23 -> 46.835 | EH23: =X23+Y23+Z23+AB23 -> 59.281 | EI23: =AC23+AD23+AE23+AG23 -> 82.476 | EJ23: =AH23+AI23+AJ23+AL23 -> 101.865 | EK23: =AM23+AN23+AO23+AQ23 -> 128.369 | EL23: =AR23+AS23+AT23+AV23 -> 165.823 | EM23: =AW23+AX23+AY23+BA23 -> 172.231 | EN23: =BB23+BC23+BD23+BF23 -> 211.891 | EO23: =SUM(BG23:BI23,BK23) -> 273.477 | EP23: =SUM(BL23:BN23,BP23) -> 312.378 | EQ23: =SUM(BQ23:BS23,BU23) -> 317 | ER23: =SUM(BV23:BX23,BZ23) -> 263.7 | ES23: =SUM(CA23:CC23,CE23) -> 311.4 | ET23: =SUM(CF23:CH23,CJ23) -> 403.4 | EU23: =SUM(CK23,CL23,CM23,CO23) -> 432.4 | EV23: =SUM(CT23,CR23,CQ23,CP23) -> 420.7 | EW23: =CU23+CV23+CW23+CY23 -> 471.9 | EX23: =CZ23+DA23+DB23+DD23 -> 539.2 | EY23: =DE23+DF23+DG23+DI23 -> 544.6 | EZ23: =DJ23+DK23+DL23+DN23 -> 549.9 | FA23: =DO23+DP23+DQ23+DS23 -> 578.94285 | FB23: =DT23+DU23+DV23+DX23 -> 611.85508 | FD23: Other Op. Expenses | FE23: =DN23 -> 141.6 | FF23: 153.44303 | FG23: =FE23-FF23 -> -11.84303 | FH23: =DI23 -> 145.4 | FI23: =FE23/FH23-1 -> -0.026134801
A24: Depreciation & Amortization | B24: 12.535 | C24: 4.464 | D24: 5.152 | E24: =22.486-D24-C24-F24 -> 5.918 | F24: 6.952 | G24: =SUM(C24:F24) -> 22.486 | H24: 7.6 | I24: 8.6 | J24: 9.5 | K24: 10.3 | L24: 35.9 | M24: 11.576 | N24: 12.494 | O24: 13.829 | P24: 14.902 | Q24: =SUM(M24:P24) -> 52.801 | R24: 16.051 | S24: 17.435 | T24: 18.928 | U24: 20.127 | V24: =SUM(R24:U24) -> 72.541 | W24: 21.893 | X24: 23.74 | Y24: 25.214 | Z24: 26.9 | AA24: =SUM(W24:Z24) -> 97.747 | AB24: 29.29 | AC24: 31.951 | AD24: 33.26 | AE24: 35.731 | AF24: =SUM(AB24:AE24) -> 130.232 | AG24: 37.562 | AH24: 38.597 | AI24: 41.884 | AJ24: 45.458 | AK24: 163.501 | AL24: 50.301 | AM24: 49.972 | AN24: 50.873 | AO24: 54.411 | AP24: 205.557 | AQ24: 57.385 | AR24: 57.961 | AS24: 59.764 | AT24: 62.697 | AU24: 237.807 | AV24: 67.929 | AW24: 74.225 | AX24: 72.886 | AY24: 74.142 | AZ24: =SUM(AV24:AY24) -> 289.182 | BA24: 78.559 | BB24: 87.772 | BC24: 85.363 | BD24: 88.475 | BE24: =SUM(BA24:BD24) -> 340.169 | BF24: 91.288 | BG24: 94.508 | BH24: 98.539 | BI24: 102.876 | BJ24: =SUM(BF24:BI24) -> 387.211 | BK24: 110.196 | BL24: 113.385 | BM24: 119.409 | BN24: 124.17 | BO24: =SUM(BK24:BN24) -> 467.16 | BP24: 133.2 | BQ24: 138.1 | BR24: 139.8 | BS24: 138.2 | BT24: =SUM(BP24:BS24) -> 549.3 | BU24: 134.3 | BV24: 134.1 | BW24: 133.7 | BX24: 132.6 | BY24: =SUM(BU24:BX24) -> 534.7 | BZ24: 130.6 | CA24: 128.5 | CB24: 125.2 | CC24: 126.1 | CD24: =SUM(BZ24:CC24) -> 510.4 | CE24: 127.8 | CF24: 129 | CG24: 129.5 | CH24: 137.1 | CI24: =SUM(CE24:CH24) -> 523.4 | CJ24: 134.8 | CK24: 137.1 | CL24: 136.7 | CM24: 141.7 | CN24: =SUM(CJ24:CM24) -> 550.3 | CO24: 148.9 | CP24: 153.1 | CQ24: 153.3 | CR24: 166.1 | CS24: =SUM(CO24:CR24) -> 621.4 | CT24: 169.7 | CU24: 174.4 | CV24: 180.1 | CW24: 185.4 | CX24: =SUM(CT24:CW24) -> 709.6 | CY24: 206 | CZ24: 217.1 | DA24: 236.5 | DB24: 234.3 | DC24: =SUM(CY24:DB24) -> 893.9 | DD24: 235.5 | DE24: 247.8 | DF24: 247.6 | DG24: 249.9 | DH24: =SUM(DD24:DG24) -> 980.8 | DI24: 249.7 | DJ24: 253.6 | DK24: 252.6 | DL24: 255.4 | DM24: =SUM(DI24:DL24) -> 1011.3 | DN24: 258.8 | DO24: 286.77687 | DP24: 285.37228 | DQ24: 285.95236 | DR24: =SUM(DN24:DQ24) -> 1116.9015 | DS24: 289.85017 | DT24: 301.88127 | DU24: 300.30162 | DV24: 302.28179 | DW24: =SUM(DS24:DV24) -> 1194.3148 | DX24: 310.58494 | DY24: 325.29515 | DZ24: 323.51993 | EA24: 325.71797 | EB24: =SUM(DX24:EA24) -> 1285.118 | EG24: =S24+T24+U24+W24 -> 78.383 | EH24: =X24+Y24+Z24+AB24 -> 105.144 | EI24: =AC24+AD24+AE24+AG24 -> 138.504 | EJ24: =AH24+AI24+AJ24+AL24 -> 176.24 | EK24: =AM24+AN24+AO24+AQ24 -> 212.641 | EL24: =AR24+AS24+AT24+AV24 -> 248.351 | EM24: =AW24+AX24+AY24+BA24 -> 299.812 | EN24: =BB24+BC24+BD24+BF24 -> 352.898 | EO24: =SUM(BG24:BI24,BK24) -> 406.119 | EP24: =SUM(BL24:BN24,BP24) -> 490.164 | EQ24: =SUM(BQ24:BS24,BU24) -> 550.4 | ER24: =SUM(BV24:BX24,BZ24) -> 531 | ES24: =SUM(CA24:CC24,CE24) -> 507.6 | ET24: =SUM(CF24:CH24,CJ24) -> 530.4 | EU24: =SUM(CK24,CL24,CM24,CO24) -> 564.4 | EV24: =SUM(CT24,CR24,CQ24,CP24) -> 642.2 | EW24: =CU24+CV24+CW24+CY24 -> 745.9 | EX24: =CZ24+DA24+DB24+DD24 -> 923.4 | EY24: =DE24+DF24+DG24+DI24 -> 995 | EZ24: =DJ24+DK24+DL24+DN24 -> 1020.4 | FA24: =DO24+DP24+DQ24+DS24 -> 1147.9517 | FB24: =DT24+DU24+DV24+DX24 -> 1215.0496 | FD24: Depreciation & Amortization | FE24: =DN24 -> 258.8 | FF24: 264.28621 | FG24: =FE24-FF24 -> -5.4862067 | FH24: =DI24 -> 249.7 | FI24: =FE24/FH24-1 -> 0.036443732
A25: General & Admin. Expense | B25: 19.973 | C25: 5.747 | D25: 6.489 | E25: 6.407 | F25: 9.999 | G25: =SUM(C25:F25) -> 28.642 | H25: 6.6 | I25: 9.7 | J25: 10 | K25: 10.9 | L25: 37.3 | M25: 12.92 | N25: 13.236 | O25: 14.186 | P25: 16.801 | Q25: =SUM(M25:P25) -> 57.143 | R25: 17.783 | S25: 19.307 | T25: 20.588 | U25: 19.897 | V25: =SUM(R25:U25) -> 77.575 | W25: 20.359 | X25: 22.371 | Y25: 24.679 | Z25: 22.276 | AA25: =SUM(W25:Z25) -> 89.685 | AB25: 26.145 | AC25: 28.622 | AD25: 28.049 | AE25: 27.385 | AF25: =SUM(AB25:AE25) -> 110.201 | AG25: 34.877 | AH25: 42.433 | AI25: 35.651 | AJ25: 38.455 | AK25: 179.852 | AL25: 41.129 | AM25: =67.314-18 -> 49.314 | AN25: 46.997 | AO25: 46.721 | AP25: 234.581 | AQ25: 60.943 | AR25: 59.552 | AS25: 49.325 | AT25: 57.071 | AU25: 244.55 | AV25: 70.417 | AW25: 79.982 | AX25: 73.357 | AY25: 80.537 | AZ25: =SUM(AV25:AY25) -> 304.293 | BA25: 83.599 | BB25: 81.929 | BC25: 90.637 | BD25: 100.949 | BE25: =SUM(BA25:BD25) -> 357.114 | BF25: =123.325 -> 123.325 | BG25: 119.611 | BH25: 115.258 | BI25: 114.829 | BJ25: =SUM(BF25:BI25) -> 473.023 | BK25: =115.228 -> 115.228 | BL25: 126.104 | BM25: 119.525 | BN25: 123.312 | BO25: =SUM(BK25:BN25) -> 484.169 | BP25: 125.9 | BQ25: 117.6 | BR25: 116.1 | BS25: 96.4 | BT25: =SUM(BP25:BS25) -> 456 | BU25: 105.2 | BV25: 104.3 | BW25: 110.3 | BX25: 133.2 | BY25: =SUM(BU25:BX25) -> 453 | BZ25: 136.9 | CA25: 139 | CB25: 132.7 | CC25: 160.9 | CD25: =SUM(BZ25:CC25) -> 569.5 | CE25: 185.2 | CF25: 181.6 | CG25: 190.2 | CH25: 192.3 | CI25: =SUM(CE25:CH25) -> 749.3 | CJ25: 191.5 | CK25: 206.9 | CL25: 199 | CM25: 203.8 | CN25: =SUM(CJ25:CM25) -> 801.2 | CO25: 231.9 | CP25: 230.3 | CQ25: 249.6 | CR25: 226.1 | CS25: =SUM(CO25:CR25) -> 937.9 | CT25: 242.6 | CU25: 240.6 | CV25: 269.4 | CW25: 238.6 | CX25: =SUM(CT25:CW25) -> 991.2 | CY25: 298.4 | CZ25: 305.9 | DA25: 288.5 | DB25: 303.9 | DC25: =SUM(CY25:DB25) -> 1196.7 | DD25: 305.5 | DE25: 330.5 | DF25: 323.4 | DG25: 401.2 | DH25: =SUM(DD25:DG25) -> 1360.6 | DI25: 356.4 | DJ25: 326.8 | DK25: 325 | DL25: 385.2 | DM25: =SUM(DI25:DL25) -> 1393.4 | DN25: 379.1 | DO25: 339.38957 | DP25: 359.16032 | DQ25: 360.9425 | DR25: =SUM(DN25:DQ25) -> 1438.5924 | DS25: 429.27432 | DT25: 380.66902 | DU25: 403.33093 | DV25: 404.83433 | DW25: =SUM(DS25:DV25) -> 1618.1086 | DX25: 477.95394 | DY25: 424.11722 | DZ25: 449.24173 | EA25: 450.15661 | EB25: =SUM(DX25:EA25) -> 1801.4695 | EG25: =S25+T25+U25+W25 -> 80.151 | EH25: =X25+Y25+Z25+AB25 -> 95.471 | EI25: =AC25+AD25+AE25+AG25 -> 118.933 | EJ25: =AH25+AI25+AJ25+AL25 -> 157.668 | EK25: =AM25+AN25+AO25+AQ25 -> 203.975 | EL25: =AR25+AS25+AT25+AV25 -> 236.365 | EM25: =AW25+AX25+AY25+BA25 -> 317.475 | EN25: =BB25+BC25+BD25+BF25 -> 396.84 | EO25: =SUM(BG25:BI25,BK25) -> 464.926 | EP25: =SUM(BL25:BN25,BP25) -> 494.841 | EQ25: =SUM(BQ25:BS25,BU25) -> 435.3 | ER25: =SUM(BV25:BX25,BZ25) -> 484.7 | ES25: =SUM(CA25:CC25,CE25) -> 617.8 | ET25: =SUM(CF25:CH25,CJ25) -> 755.6 | EU25: =SUM(CK25,CL25,CM25,CO25) -> 841.6 | EV25: =SUM(CT25,CR25,CQ25,CP25) -> 948.6 | EW25: =CU25+CV25+CW25+CY25 -> 1047 | EX25: =CZ25+DA25+DB25+DD25 -> 1203.8 | EY25: =DE25+DF25+DG25+DI25 -> 1411.5 | EZ25: =DJ25+DK25+DL25+DN25 -> 1416.1 | FA25: =DO25+DP25+DQ25+DS25 -> 1488.7667 | FB25: =DT25+DU25+DV25+DX25 -> 1666.7882 | FD25: General & Admin. Expense | FE25: =DN25 -> 379.1 | FF25: 414.95759 | FG25: =FE25-FF25 -> -35.857591 | FH25: =DI25 -> 356.4 | FI25: =FE25/FH25-1 -> 0.06369248
A26: Restructuring/Other one-time | BR26: 167.7 | BS26: 99.2 | BT26: =SUM(BP26:BS26) -> 266.9 | BU26: 75.5 | BV26: 152.1 | BW26: 51.6 | BX26: 53.2 | BY26: =SUM(BU26:BX26) -> 332.4 | BZ26: 18.3 | CA26: 7.9 | CB26: 20.4 | CC26: 6.4 | CD26: =SUM(BZ26:CC26) -> 53 | CE26: 0 | CF26: 0 | CG26: 0 | CH26: -30.2 | CI26: =SUM(CE26:CH26) -> -30.2 | CJ26: 0 | CK26: 0 | CL26: 0 | CM26: 0 | CN26: =SUM(CJ26:CM26) -> 0 | CO26: 0 | CP26: 0 | CQ26: 0 | CR26: 2784.1 | CS26: =SUM(CO26:CR26) -> 2784.1 | CT26: -20.2 | CU26: 0 | CV26: 0 | CW26: 0 | CX26: =SUM(CT26:CW26) -> -20.2 | CY26: 0 | CZ26: 0 | DA26: 0 | DB26: 0 | DC26: =SUM(CY26:DB26) -> 0 | DD26: 0 | DE26: 0 | DF26: 0 | DG26: 0 | DH26: =SUM(DD26:DG26) -> 0 | DI26: 0 | DJ26: 0 | DK26: 120.2 | DL26: 33.3 | DM26: =SUM(DI26:DL26) -> 153.5 | DN26: 27.6 | DO26: 0 | DP26: 0 | DQ26: 0 | DR26: =SUM(DN26:DQ26) -> 27.6 | DS26: 0 | DT26: 0 | DU26: 0 | DV26: 0 | DW26: =SUM(DS26:DV26) -> 0 | DX26: 0 | DY26: 0 | DZ26: 0 | EA26: 0 | EB26: =SUM(DX26:EA26) -> 0 | EQ26: =SUM(BQ26:BS26,BU26) -> 342.4 | ER26: =SUM(BV26:BX26,BZ26) -> 275.2 | ES26: =SUM(CA26:CC26,CE26) -> 34.7 | ET26: =SUM(CF26:CH26,CJ26) -> -30.2 | EU26: =SUM(CK26,CL26,CM26,CO26) -> 0 | EV26: =SUM(CT26,CR26,CQ26,CP26) -> 2763.9 | EW26: =CU26+CV26+CW26+CY26 -> 0 | EX26: =CZ26+DA26+DB26+DD26 -> 0 | EY26: =DE26+DF26+DG26+DI26 -> 0 | EZ26: =DJ26+DK26+DL26+DN26 -> 181.1 | FA26: =DO26+DP26+DQ26+DS26 -> 0 | FB26: =DT26+DU26+DV26+DX26 -> 0 | FD26: Restructuring | FE26: =DN26 -> 27.6 | FF26: 0 | FG26: =FE26-FF26 -> 27.6 | FH26: =DI26 -> 0
A27: Income from Equity Investees (loss) | W27: -0.28 | X27: -0.055 | Y27: 0.36 | Z27: 3.166 | AA27: =SUM(W27:Z27) -> 3.191 | AB27: 3.395 | AC27: 3.821 | AD27: 4.339 | AE27: 8.745 | AF27: =SUM(AB27:AE27) -> 20.3 | AG27: 4.805 | AH27: 6.167 | AI27: 6.732 | AJ27: 10.911 | AK27: 27.74 | AL27: =6.585-0.635 -> 5.95 | AM27: =7.459-0.354 -> 7.105 | AN27: =8.536-0.506 -> 8.03 | AO27: =13.252-0.779 -> 12.473 | AP27: 33.445 | AQ27: 6.601 | AR27: 6.573 | AS27: =7.917-0.0959 -> 7.8211 | AT27: 17.401 | AU27: 38.396 | AV27: 10.044 | AW27: 11.944 | AX27: 13.163 | AY27: 24.15 | AZ27: 59.071 | BA27: 12.847 | BB27: 16.294 | BC27: 18.074 | BD27: 29.469 | BE27: 76.745 | BF27: 19.754 | BG27: 19.985 | BH27: 25.666 | BI27: 28.566 | BJ27: =SUM(BF27:BI27) -> 93.971 | BK27: 18.753 | BL27: 26.261 | BM27: 24.503 | BN27: 38.489 | BO27: =SUM(BK27:BN27) -> 108.006 | BP27: 23.6 | BQ27: 24.5 | BR27: 29 | BS27: 36.5 | BT27: =SUM(BP27:BS27) -> 113.6 | BU27: 23.5 | BV27: 25.2 | BW27: 29.7 | BX27: 43.5 | BY27: =SUM(BU27:BX27) -> 121.9 | BZ27: 29.4 | CA27: 34.4 | CB27: 36.3 | CC27: 48 | CD27: =SUM(BZ27:CC27) -> 148.1 | CE27: 34.5 | CF27: 38.3 | CG27: 44.3 | CH27: 56.7 | CI27: =SUM(CE27:CH27) -> 173.8 | CJ27: 44.9 | CK27: 52.2 | CL27: 51.7 | CM27: 61.9 | CN27: =SUM(CJ27:CM27) -> 210.7 | CO27: 54.5 | CP27: 52.5 | CQ27: 63.4 | CR27: 81 | CS27: =SUM(CO27:CR27) -> 251.4 | CT27: 51.1 | CU27: 59.9 | CV27: 72.9 | CW27: 84.4 | CX27: =SUM(CT27:CW27) -> 268.3 | CY27: 52.8 | CZ27: 54.9 | DA27: 60.3 | DB27: 81.9 | DC27: =SUM(CY27:DB27) -> 249.9 | DD27: 64.1 | DE27: 65.6 | DF27: 82.5 | DG27: 106 | DH27: =SUM(DD27:DG27) -> 318.2 | DI27: 84.4 | DJ27: 84.1 | DK27: 101 | DL27: 121.9 | DM27: =SUM(DI27:DL27) -> 391.4 | DN27: 89.4 | DO27: 79.423456 | DP27: 92.356542 | DQ27: 112.53091 | DR27: =SUM(DN27:DQ27) -> 373.71091 | DS27: 85.130545 | DT27: 85.546605 | DU27: 101.91586 | DV27: 120.34192 | DW27: =SUM(DS27:DV27) -> 392.93492 | DX27: 93.404502 | DY27: 93.355598 | DZ27: 111.35828 | EA27: 131.68323 | EB27: =SUM(DX27:EA27) -> 429.80161 | EK27: =AM27+AN27+AO27+AQ27 -> 34.209 | EL27: =AR27+AS27+AT27+AV27 -> 41.8391 | EM27: =AW27+AX27+AY27+BA27 -> 62.104 | EN27: =BB27+BC27+BD27+BF27 -> 83.591 | EO27: =SUM(BG27:BI27,BK27) -> 92.97 | EP27: =SUM(BL27:BN27,BP27) -> 112.853 | EQ27: =SUM(BQ27:BS27,BU27) -> 113.5 | ER27: =SUM(BV27:BX27,BZ27) -> 127.8 | ES27: =SUM(CA27:CC27,CE27) -> 153.2 | ET27: =SUM(CF27:CH27,CJ27) -> 184.2 | EU27: =SUM(CK27,CL27,CM27,CO27) -> 220.3 | EV27: =SUM(CT27,CR27,CQ27,CP27) -> 248 | EW27: =CU27+CV27+CW27+CY27 -> 270 | EX27: =CZ27+DA27+DB27+DD27 -> 261.2 | EY27: =DE27+DF27+DG27+DI27 -> 338.5 | EZ27: =DJ27+DK27+DL27+DN27 -> 396.4 | FA27: =DO27+DP27+DQ27+DS27 -> 369.44145 | FB27: =DT27+DU27+DV27+DX27 -> 401.20888 | FD27: Income from Equity Investees (loss) | FE27: =DN27 -> 89.4 | FF27: 102.51205 | FG27: =FE27-FF27 -> -13.112046 | FH27: =DI27 -> 84.4 | FI27: =FE27/FH27-1 -> 0.059241706
