Workbook
Name AdditionalInstructions: IndexInformation!$B$42
Name Address: ImportantDisclosures!$A$2:$A$2
Name ANA: ModPubIndex!$A$7
Name Authors: ImportantDisclosures!$A$7
Name Authors: IndexInformation!$B$18
Name BRO: ModPubIndex!$A$1
Name BS: [3]BS!$D$44:$GI$44
Name BSMethod: 2
Name Button_1: "TFT_report_data_share_prices_List"
Name cc_ReportCurrency: "NTD"
Name cc_ReportCurrencyUnit: "NT$"
Name cc_ReportCurrencyUnitFactor: 1
Name Conv_mark: 0
Name converting: {"Client Name or Project Name"}
Name CopyrightStamp: ImportantDisclosures!$A$27
Name COU: ModPubIndex!$A$5
Name CQEnd: IndexInformation!$B$31
Name Currency: IndexInformation!$B$24
Name CurrentStockPrice: IndexInformation!$B$23
Name CurrQtrEPS: IndexInformation!$B$29
Name CurrYearEPS: IndexInformation!$B$11
Name CurrYearTotalRevenue: IndexInformation!$B$10
Name CurrYearTotalRevenueActual: IndexInformation!$B$32
Name CUSIP: IndexInformation!$B$20
Name CYEnd: IndexInformation!$B$30
Name dataseries4: OFFSET([4]c1!$G$12,0,0,COUNTA([4]c1!$G$12:$G$31),1)
Name Date: ImportantDisclosures!$A$8
Name Dates: OFFSET('[5]Earnings Exhibits'!$A$3,0,COUNTA('[5]Earnings Exhibits'!$A$3:$IV$3)+2,1,-20)
Name Dates10: OFFSET('[5]Earnings Exhibits'!$A$3,0,COUNTA('[5]Earnings Exhibits'!$A$3:$IV$3)+2,1,-38)
Name DB: "WIREHKPROD"
Name Deleted: IndexInformation!$B$27
Name Description: IndexInformation!$B$7
Name Discipline: IndexInformation!$B$3
Name DISCIPLINE: ModPubIndex!$A$12
Name DisclosuresText: ImportantDisclosures!$A$22
Name Distribution: IndexInformation!$B$26
Name DistTable: ImportantDisclosures!#REF!
Name DistTablePreamble: ImportantDisclosures!#REF!
Name DOCDAT: ModPubIndex!$A$2
Name DOCTIME: ModPubIndex!$A$3
Name DocType: IndexInformation!$B$5
Name DummyEstYears: 3
Name EMAIL_ALERT: ModPubIndex!$A$10
Name EmailAlert: IndexInformation!$B$28
Name EurosFRF: 1
Name EurosITL: 1
Name FINCriteriaType: 1
Name FineUS: {"Client Name or Project Name"}
Name FiveYearGrowthRate: IndexInformation!$B$16
Name FollowingYearEPS: IndexInformation!$B$15
Name FollowingYearTotalRevenue: IndexInformation!$B$14
Name FollowingYearTotalRevenueActual: IndexInformation!$B$34
Name forest: {"Client Name or Project Name"}
Name forest2: {"Client Name or Project Name"}
Name FR_COM_ABBR: "1122.HK"
Name FR_COU_ABBR: "chn"
Name FR_END_DATE: "'31 Dec 2001"
Name FR_START_DATE: "'1 Jan 2001"
Name FR_SYBASE_SERVER: "PTKFBVDF01"
Name FR_TEMPLATE_KEY: "102119|1"

Sheet MW-Cache
A1: $IV$4
A2: STX.N,mstag:incomeLossFromInvestmentsAccountedForUnderTheEquityMethodOperatingIncomeStatement,2008Q4,,FYR,USD | B2: NA | C2: JAVA.O,mscalc:netOperatingAssets,2007Q4,,FYR,USD | D2: 2,984.671 | E2: STX.N,mscalc:operatingExpenses,2008Q1,,FYR,USD | F2: 2,859.87590849649 | G2: STX.N,mscalc:sharePrice,2007Q4,,FYR,USD | H2: 21.77 | I2: STX.N,mstag:tradeReceivables,2007Q1,,FYR,USD | J2: 1,331 | K2: JAVA.O,mscalc:consensusEps,2006Q3,,FYR,USD | L2: (0.0299999993294477) | M2: JAVA.O,mscalc:otheroperatingIncomeExpense,2007Q4,,FYR,USD | N2: NA | O2: STX.N,mscalc:consensusEps,2009Q3,,FYR,USD | P2: 0.685769021511078 | Q2: JAVA.O,mstag:researchAndDevelopment,2008Q2,,FYR,USD | R2: 492.153509172135 | S2: JAVA.O,mscalc:depreciationAndAmortization,2008Q4,,FYR,USD | T2: 212.596639218066 | U2: JAVA.O,mscalc:consensusEps,2008Q4,,FYR,USD | V2: 0.424109995365143 | W2: JAVA.O,mscalc:consensusEps,2006Q4,,FYR,USD | X2: 0.0199999995529652 | Y2: STX.N,mstag:costOfManufacturing,2008Q3,,FYR,USD | Z2: NA | AA2: STX.N,mscalc:taxExpenseFromOperations,2008Q3,,FYR,USD | AB2: 18.0256545986929 | AC2: STX.N,mstag:sellingGeneralAndAdministrativeExpenses,2008Q3,,FYR,USD | AD2: 144.488547365134 | AE2: JAVA.O,mstag:costOfManufacturing,2007Q4 | AF2: NA | AG2: STX.N,mstag:tradeAndOtherPayables,2008Q1,,FYR,USD | AH2: 1,551 | AI2: JAVA.O,mscalc:epsForConsensusForThomsonFeed,2007Q4,,FYR,USD | AJ2: 0.0847642622838515 | AK2: JAVA.O,mscalc:operatingExpenses,2008Q4,,FYR,USD | AL2: 3,677.11700350108 | AM2: JAVA.O,mstag:researchAndDevelopment,2008Q3,,FYR,USD | AN2: 478.661398865851 | AO2: STX.N,mscalc:epsForConsensusForThomsonFeed,2008Q1,,FYR,USD | AP2: 0.677315701983149 | AQ2: JAVA.O,mscalc:otheroperatingIncomeExpense,2008Q2,,FYR,USD | AR2: NA | AS2: JAVA.O,mscalc:netOperatingAssets,2008Q4,,FYR,USD | AT2: 2,154.76695786603 | AU2: JAVA.O,mscalc:netFinancialIncomeExpense,2008Q4,,FYR,USD | AV2: 25.937404376881 | AW2: STX.N,mscalc:consensusEps,2007Q1,,FYR,USD | AX2: 0.159999996423721 | AY2: STX.N,mscalc:otherIncomeExpense,2008Q1,,FYR,USD | AZ2: (4.443306415566) | BA2: JAVA.O,mscalc:sharePrice,2008Q1,,FYR,USD | BB2: 35.05 | BC2: JAVA.O,mscalc:netOperatingAssets,,,FYR,USD | BD2: NA | BE2: JAVA.O,mstag:costOfSalesWithoutDepreciation,2008Q1 | BF2: NA | BG2: STX.N,mstag:costOfSalesWithoutDepreciation,2008Q1 | BH2: NA | BI2: JAVA.O,mstag:costOfManufacturing,2008Q1 | BJ2: NA | BK2: STX.N,mscalc:mwAdjustmentsToEv,2008Q1,,FYR,USD | BL2: NA | BM2: STX.N,mstag:inventories,2008Q4,,FYR,USD | BN2: 861.742561596703 | BO2: JAVA.O,mscalc:consensusEps,2009Q3,,FYR,USD | BP2: 0.287961006164551 | BQ2: WDC.O,mscalc:targetPrice,,,,USD | BR2: 92 | BS2: JAVA.O,mstag:costOfSalesWithoutDepreciation,2008Q1,,FYR,USD | BT2: NA | BU2: STX.N,mscalc:consensusEps,2008Q2,,FYR,USD | BV2: 0.731366991996765 | BW2: STX.N,mstag:inventories,2008Q1,,FYR,USD | BX2: 763 | BY2: STX.N,mstag:employeeExpenses,2008Q1,,FYR,USD | BZ2: NA | CA2: JAVA.O,mstag:incomeLossFromInvestmentsAccountedForUnderTheEquityMethodOperatingIncomeStatement,2008Q4,,FYR,USD | CB2: NA | CC2: STX.N,mscalc:dilutedSharesOutstanding,2008Q2,,FYR | CD2: 562.067222377659 | CE2: JAVA.O,mstag:averageDilutedSharesOutstanding,2008Q4,,FYR | CF2: 3,261.61287817885 | CG2: JAVA.O,mstag:costOfSalesWithDepreciation,2008Q4,,FYR,USD | CH2: 2,184.73281192932 | CI2: JAVA.O,mstag:costOfSalesWithoutDepreciation,2008Q3,,FYR,USD | CJ2: NA | CK2: JAVA.O,mstag:costOfMaterials,2008Q4,,FYR,USD | CL2: NA | CM2: JAVA.O,mstag:inventories,2007Q1,,FYR,USD | CN2: 584 | CO2: STX.N,mscalc:netOperatingAssets,2008Q2,,FYR,USD | CP2: 5,970.77845385973 | CQ2: STX.N,mstag:costOfSalesWithoutDepreciation | CR2: NA | CS2: JAVA.O,mscalc:otheroperatingIncomeExpense,2008Q4,,FYR,USD | CT2: NA | CU2: JAVA.O,mstag:costOfMaterials,2008Q3,,FYR,USD | CV2: NA | CW2: STX.N,mscalc:otherIncomeExpense,2008Q2,,FYR,USD | CX2: 0.000000000000324100 | CY2: JAVA.O,mscalc:operatingRevenue,2008Q1,,FYR,USD | CZ2: 3,218.93093863074 | DA2: JAVA.O,mstag:averageDilutedSharesOutstanding,2008Q1,,FYR | DB2: 3,537 | DC2: JAVA.O,mstag:researchAndDevelopment,2007Q4,,FYR,USD | DD2: 514 | DE2: STX.N,mstag:costOfMaterials,2008Q1 | DF2: NA | DG2: STX.N,mscalc:operatingRevenue,2008Q3,,FYR,USD | DH2: 3,074.22441202413 | DI2: JAVA.O,mstag:costOfServicesSold,2008Q1 | DJ2: NA | DK2: JAVA.O,mscalc:consensusEps,2007Q4,,FYR,USD | DL2: 0.449912011623383 | DM2: STX.N,mscalc:operatingRevenue,2008Q2,,FYR,USD | DN2: 3,421.75749352828 | DO2: STX.N,mscalc:otheroperatingIncomeExpense,2008Q4,,FYR,USD | DP2: NA | DQ2: JAVA.O,mscalc:otherIncomeExpense,2008Q2,,FYR,USD | DR2: 26.9459299001817 | DS2: STX.N,mscalc:taxExpenseFromOperations,2008Q1,,FYR,USD | DT2: 21.2468473434805 | DU2: JAVA.O,mscalc:sharePrice,2007Q4,,FYR,USD | DV2: 5.26 | DW2: STX.N,mstag:inventories,2008Q3,,FYR,USD | DX2: 829.335997496634 | DY2: JAVA.O,mstag:costOfSalesWithoutDepreciation,2008Q3 | DZ2: NA | EA2: JAVA.O,mscalc:consensusEps,2007Q2,,FYR,USD | EB2: 0.159999996423721 | EC2: STX.N,mscalc:consensusEps,2007Q3,,FYR,USD | ED2: 0.469999998807907 | EE2: STX.N,mstag:costOfManufacturing,2008Q2,,FYR,USD | EF2: NA | EG2: JAVA.O,mscalc:epsForConsensusForThomsonFeed,2008Q1,,FYR,USD | EH2: 0.050972548256401 | EI2: JAVA.O,mscalc:netOperatingAssets,2008Q1,,FYR,USD | EJ2: 1,944 | EK2: JAVA.O,mstag:inventories,2008Q1,,FYR,USD | EL2: 571 | EM2: STX.N,mstag:averageDilutedSharesOutstanding,,,FYR | EN2: NA | EO2: JAVA.O,mscalc:taxExpenseFromOperations,2008Q4,,FYR,USD | EP2: 106.666794529249 | EQ2: JAVA.O,mstag:incomeLossFromInvestmentsAccountedForUnderTheEquityMethodOperatingIncomeStatement,2007Q4,,FYR,USD | ER2: NA | ES2: JAVA.O,mscalc:dilutedSharesOutstanding,2007Q4,,FYR | ET2: 3,710.66779184248 | EU2: WDC.N,mscalc:sedolCodeCalc | EV2: 2954699 | EW2: JAVA.O,mscalc:depreciationAndAmortization,2008Q3,,FYR,USD | EX2: 208.875834772559 | EY2: JAVA.O,mscalc:netFinancialIncomeExpense,2008Q2,,FYR,USD | EZ2: 29.0298250428817 | FA2: JAVA.O,mscalc:operatingExpenses,2007Q4,,FYR,USD | FB2: 3,534.06061219646 | FC2: STX.N,mstag:employeeExpenses,,,FYR,USD | FD2: NA | FE2: JAVA.O,mstag:employeeExpenses,,,FYR,USD | FF2: NA | FG2: JAVA.O,mstag:averageDilutedSharesOutstanding,,,FYR | FH2: NA | FI2: STX.N,mscalc:operatingExpenses,2008Q3,,FYR,USD | FJ2: 2,713.71132005027 | FK2: JAVA.O,mstag:costOfSalesWithoutDepreciation,2008Q4 | FL2: NA | FM2: JAVA.O,mstag:costOfManufacturing,2008Q2,,FYR,USD | FN2: NA | FO2: JAVA.O,mstag:researchAndDevelopment,2008Q4,,FYR,USD | FP2: 502.824862389408 | FQ2: STX.N,mstag:costOfManufacturing,2008Q1 | FR2: NA | FS2: STX.N,mscalc:netOperatingAssets,2008Q4,,FYR,USD | FT2: 6,321.46815512331 | FU2: JAVA.O,mstag:costOfSalesWithoutDepreciation,2007Q4 | FV2: NA | FW2: STX.N,mstag:sellingGeneralAndAdministrativeExpenses,2008Q4,,FYR,USD | FX2: 139.367913762653 | FY2: JAVA.O,mstag:costOfMaterials,2008Q1 | FZ2: NA | GA2: STX.N,mscalc:sharePrice,2007Q3,,FYR,USD | GB2: 23.3 | GC2: STX.N,mstag:tradeReceivables,2008Q2,,FYR,USD | GD2: 1,520.78110823479 | GE2: JAVA.O,mstag:tradeReceivables,2007Q1,,FYR,USD | GF2: 2,036 | GG2: JAVA.O,mstag:averageDilutedSharesOutstanding,2007Q4,,FYR | GH2: 3,632 | GI2: JAVA.O,mstag:sellingGeneralAndAdministrativeExpenses,2008Q2,,FYR,USD | GJ2: 927.245741918514 | GK2: STX.N,mstag:averageDilutedSharesOutstanding,2008Q2,,FYR | GL2: 550.722335034556 | GM2: STX.N,mstag:researchAndDevelopment,2008Q4,,FYR,USD | GN2: 226.472859864311 | GO2: JAVA.O,mscalc:operatingRevenue,2008Q3,,FYR,USD | GP2: 3,419.00999189894 | GQ2: STX.N,mstag:tradeAndOtherPayables,2007Q1,,FYR,USD | GR2: 1,448 | GS2: STX.N,mstag:costOfSalesWithoutDepreciation,2008Q4 | GT2: NA | GU2: JAVA.O,mstag:costOfSalesWithDepreciation,2008Q2,,FYR,USD | GV2: 1,916.05042456704 | GW2: JAVA.O,mscalc:operatingRevenue,,,FYR,USD | GX2: NA | GY2: JAVA.O,mstag:costOfManufacturing,2008Q1,,FYR,USD | GZ2: NA | HA2: JAVA.O,mstag:employeeExpenses,2007Q4,,FYR,USD | HB2: NA | HC2: JAVA.O,mscalc:taxExpenseFromOperations,2008Q1,,FYR,USD | HD2: 54.3218088729334 | HE2: STX.N,mscalc:depreciationAndAmortization,2008Q3,,FYR,USD | HF2: 225.17192187029 | HG2: STX.N,mstag:tradeReceivables,2008Q4,,FYR,USD | HH2: 1,516.27128399183 | HI2: STX.N,mscalc:otherIncomeExpense,2008Q3,,FYR,USD | HJ2: (0.000000000000149012) | HK2: JAVA.O,mstag:researchAndDevelopment,2008Q1,,FYR,USD | HL2: 446 | HM2: STX.N,mstag:researchAndDevelopment,2008Q3,,FYR,USD | HN2: 236.715279725858 | HO2: STX.N,mscalc:netFinancialIncomeExpense,2008Q1,,FYR,USD | HP2: (19.95) | HQ2: STX.N,mstag:costOfMaterials,2008Q3,,FYR,USD | HR2: NA | HS2: JAVA.O,mstag:costOfMaterials,2008Q2,,FYR,USD | HT2: NA | HU2: JAVA.O,mstag:employeeExpenses,2008Q2,,FYR,USD | HV2: NA | HW2: JAVA.O,mstag:inventories,2006Q4,,FYR,USD | HX2: 540 | HY2: STX.N,mstag:tradeAndOtherPayables,2008Q2,,FYR,USD | HZ2: 1,567.58235704186 | IA2: STX.N,mscalc:consensusEps,2008Q4,,FYR,USD | IB2: 0.550920009613037 | IC2: STX.N,mstag:costOfMaterials,2008Q2,,FYR,USD | ID2: NA | IE2: STX.N,mscalc:operatingRevenue,2008Q1,,FYR,USD | IF2: 3,284.8128553661 | IG2: JAVA.O,mstag:tradeReceivables,2008Q1,,FYR,USD | IH2: 2,203 | II2: JAVA.O,mscalc:netOperatingAssets,2008Q2,,FYR,USD | IJ2: 2,027.35625225519 | IK2: STX.N,mscalc:consensusEps,2007Q4,,FYR,USD | IL2: 0.4115070104599 | IM2: JAVA.O,mscalc:operatingExpenses,2008Q1,,FYR,USD | IN2: 3,042.98863544785 | IO2: JAVA.O,mstag:tradeAndOtherPayables,2008Q2,,FYR,USD | IP2: 1,368.60744611932 | IQ2: JAVA.O,mscalc:mwAdjustmentsToEv,2007Q4,,FYR,USD | IR2: NA | IS2: JAVA.O,mscalc:depreciationAndAmortization,2007Q4,,FYR,USD | IT2: 203 | IU2: JAVA.O,mscalc:operatingRevenue,2008Q2,,FYR,USD | IV2: 3,566.32977660967
A3: JAVA.O,mscalc:consensusEps,2009Q4,,FYR,USD | B3: 0.48369500041008 | C3: STX.N,mstag:costOfServicesSold,2008Q2,,FYR,USD | D3: NA | E3: STX.N,mstag:averageDilutedSharesOutstanding,2008Q1,,FYR | F3: 560 | G3: STX.N,mscalc:netOperatingAssets,,,FYR,USD | H3: NA | I3: STX.N,mscalc:taxExpenseFromOperations,2008Q4,,FYR,USD | J3: 16.0873992827918 | K3: JAVA.O,mscalc:otherIncomeExpense,2008Q4,,FYR,USD | L3: 47.3959541105269 | M3: JAVA.O,mscalc:operatingRevenue,2007Q4,,FYR,USD | N3: 3,835.14296185225 | O3: JAVA.O,mscalc:mwAdjustmentsToEv,2008Q1,,FYR,USD | P3: NA | Q3: JAVA.O,mscalc:consensusEps,2009Q2,,FYR,USD | R3: 0.369836002588272 | S3: STX.N,mstag:inventories,,,FYR,USD | T3: NA | U3: WDC.O,mscalc:sedolCodeCalc | V3: 2954699 | W3: STX.N,mstag:costOfManufacturing,2008Q4,,FYR,USD | X3: NA | Y3: JAVA.O,mscalc:otheroperatingIncomeExpense,2008Q1,,FYR,USD | Z3: NA | AA3: STX.N,mscalc:netFinancialIncomeExpense,2008Q2,,FYR,USD | AB3: (16.1293323045581) | AC3: STX.N,mscalc:operatingRevenue,,,FYR,USD | AD3: NA | AE3: STX.N,mscalc:consensusEps,2009Q2,,FYR,USD | AF3: 0.774507999420166 | AG3: STX.N,mstag:employeeExpenses,2008Q4,,FYR,USD | AH3: NA | AI3: JAVA.O,mstag:inventories,2008Q3,,FYR,USD | AJ3: 577.674010942396 | AK3: STX.N,mstag:costOfSalesWithDepreciation,2008Q4,,FYR,USD | AL3: 2,215.90944410581 | AM3: STX.N,mscalc:netFinancialIncomeExpense,2008Q3,,FYR,USD | AN3: (14.8950586097725) | AO3: STX.N,mscalc:epsForConsensusForThomsonFeed,2008Q4,,FYR,USD | AP3: 0.541713773410666 | AQ3: JAVA.O,mstag:employeeExpenses,2008Q3,,FYR,USD | AR3: NA | AS3: JAVA.O,mstag:tradeAndOtherPayables,2008Q1,,FYR,USD | AT3: 1,140 | AU3: STX.N,mscalc:sharePrice,2008Q1,,FYR,USD | AV3: 25.58 | AW3: JAVA.O,mscalc:epsForConsensusForThomsonFeed,2008Q3,,FYR,USD | AX3: 0.0532860260859363 | AY3: STX.N,mstag:sellingGeneralAndAdministrativeExpenses,2008Q1,,FYR,USD | AZ3: 153 | BA3: STX.N,mscalc:dilutedSharesOutstanding,2008Q4,,FYR | BB3: 562.067222377659 | BC3: JAVA.O,mscalc:operatingExpenses,2008Q2,,FYR,USD | BD3: 3,335.44967565769 | BE3: STX.N,mscalc:netOperatingAssets,2008Q1,,FYR,USD | BF3: 5,671 | BG3: JAVA.O,mstag:tradeReceivables,2008Q2,,FYR,USD | BH3: 2,468.99753765285 | BI3: JAVA.O,mstag:costOfSalesWithDepreciation,,,FYR,USD | BJ3: NA | BK3: JAVA.O,mstag:tradeReceivables,2007Q4,,FYR,USD | BL3: 2,964 | BM3: JAVA.O,mscalc:consensusEps,2006Q1,,FYR,USD | BN3: (0.0199999995529652) | BO3: STX.N,mscalc:nonMarketCapComponentsOfEv,2008Q1,,FYR,USD | BP3: 791 | BQ3: STX.N,mscalc:sharePrice,2007Q1,,FYR,USD | BR3: 23.09 | BS3: JAVA.O,mscalc:otherIncomeExpense,2007Q4,,FYR,USD | BT3: 71.5292064407504 | BU3: STX.N,mscalc:dilutiveSecurities,2008Q1,,FYR,USD | BV3: NA | BW3: STX.N,mstag:incomeLossFromInvestmentsAccountedForUnderTheEquityMethodOperatingIncomeStatement,2008Q3,,FYR,USD | BX3: NA | BY3: JAVA.O,mstag:costOfSalesWithDepreciation,2007Q4 | BZ3: 2,023.06061219646 | CA3: STX.N,mscalc:operatingExpenses,2008Q2,,FYR,USD | CB3: 2,986.01093777247 | CC3: ,mscalc:closePriceCurrencyCalc | CD3: NA | CE3: JAVA.O,mscalc:sharePrice,2006Q4,,FYR,USD | CF3: 4.15 | CG3: WDC.N,mscalc:targetPrice | CH3: NA | CI3: JAVA.O,mstag:averageDilutedSharesOutstanding,2008Q2,,FYR | CJ3: 3,326.86702900859 | CK3: JAVA.O,mstag:costOfManufacturing,2008Q3,,FYR,USD | CL3: NA | CM3: JAVA.O,mscalc:dilutiveSecurities,2007Q4,,FYR,USD | CN3: NA | CO3: ,mscalc:sedolCodeCalc | CP3: NA | CQ3: JAVA.O,mstag:tradeAndOtherPayables,2008Q4,,FYR,USD | CR3: 1,567.30832160147 | CS3: JAVA.O,mstag:tradeReceivables,2006Q4,,FYR,USD | CT3: 2,702 | CU3: JAVA.O,mscalc:epsForConsensusForThomsonFeed,2008Q2,,FYR,USD | CV3: 0.0647973357132661 | CW3: STX.N,mstag:sellingGeneralAndAdministrativeExpenses,2008Q2,,FYR,USD | CX3: 164.244359689357 | CY3: JAVA.O,mscalc:consensusEps,2008Q3,,FYR,USD | CZ3: 0.172246992588043 | DA3: STX.N,mscalc:otheroperatingIncomeExpense,2008Q1,,FYR,USD | DB3: NA | DC3: STX.N,mstag:tradeReceivables,2008Q1,,FYR,USD | DD3: 1,519 | DE3: JAVA.O,mscalc:nonMarketCapComponentsOfEv,2008Q1,,FYR,USD | DF3: (4,249) | DG3: JAVA.O,mstag:averageDilutedSharesOutstanding,2008Q3,,FYR | DH3: 3,293.88357427538 | DI3: JAVA.O,mstag:incomeLossFromInvestmentsAccountedForUnderTheEquityMethodOperatingIncomeStatement,2008Q1,,FYR,USD | DJ3: NA | DK3: JAVA.O,mstag:inventories,2008Q2,,FYR,USD | DL3: 589.553976789859 | DM3: JAVA.O,mstag:costOfServicesSold,2008Q3,,FYR,USD | DN3: NA | DO3: JAVA.O,mstag:costOfSalesWithDepreciation,2008Q3,,FYR,USD | DP3: 1,852.54079371182 | DQ3: STX.N,mscalc:sharePrice,2007Q2,,FYR,USD | DR3: 26.5 | DS3: STX.N,mscalc:dilutedSharesOutstanding,,,FYR | DT3: NA | DU3: JAVA.O,mscalc:netOperatingAssets,2008Q3,,FYR,USD | DV3: 2,148.23636549668 | DW3: STX.N,mscalc:dilutedSharesOutstanding,2008Q1,,FYR | DX3: 562.067222377659 | DY3: STX.N,mscalc:taxExpenseFromOperations,2008Q2,,FYR,USD | DZ3: 21.7873277877906 | EA3: JAVA.O,mscalc:sharePrice,2006Q2,,FYR,USD | EB3: 4.19 | EC3: WDC.N,mscalc:closePriceCurrencyCalc | ED3: USD | EE3: JAVA.O,mstag:incomeLossFromInvestmentsAccountedForUnderTheEquityMethodOperatingIncomeStatement,2008Q2,,FYR,USD | EF3: NA | EG3: JAVA.O,mscalc:netFinancialIncomeExpense,2007Q4,,FYR,USD | EH3: 38.8245728 | EI3: JAVA.O,mstag:employeeExpenses,2008Q1,,FYR,USD | EJ3: NA | EK3: JAVA.O,mstag:sellingGeneralAndAdministrativeExpenses,2008Q1,,FYR,USD | EL3: 939 | EM3: STX.N,mscalc:epsForConsensusForThomsonFeed,2008Q2,,FYR,USD | EN3: 0.722378357214259 | EO3: STX.N,mscalc:consensusEps,2008Q3,,FYR,USD | EP3: 0.601935982704163 | EQ3: JAVA.O,mscalc:netFinancialIncomeExpense,2008Q3,,FYR,USD | ER3: 26.0099560249537 | ES3: JAVA.O,mscalc:consensusEps,2007Q1,,FYR,USD | ET3: 0 | EU3: JAVA.O,mstag:costOfSalesWithDepreciation | EV3: NA | EW3: JAVA.O,mscalc:operatingExpenses,2008Q3,,FYR,USD | EX3: 3,237.23984043089 | EY3: STX.N,mstag:costOfMaterials,2008Q4,,FYR,USD | EZ3: NA | FA3: STX.N,mscalc:epsForConsensusForThomsonFeed,2008Q3,,FYR,USD | FB3: 0.601951352809964 | FC3: STX.N,mscalc:netOperatingAssets,2008Q3,,FYR,USD | FD3: 6,032.99133899868 | FE3: JAVA.O,mscalc:sharePrice,2007Q2,,FYR,USD | FF3: 5.42 | FG3: STX.N,mstag:costOfSalesWithDepreciation,2008Q2,,FYR,USD | FH3: 2,565.13476606849 | FI3: STX.N,mstag:costOfServicesSold,2008Q4,,FYR,USD | FJ3: NA | FK3: JAVA.O,mstag:tradeAndOtherPayables,2006Q4,,FYR,USD | FL3: 1,446 | FM3: JAVA.O,mscalc:dilutedSharesOutstanding,2008Q3,,FYR | FN3: 3,372.53215958779 | FO3: WDC.O,mscalc:targetPrice | FP3: NA | FQ3: WDC.O,mscalc:closePriceCurrencyCalc | FR3: USD | FS3: STX.N,mstag:researchAndDevelopment,2008Q1,,FYR,USD | FT3: 242 | FU3: STX.N,mscalc:consensusEps,2007Q2,,FYR,USD | FV3: 0.389999985694885 | FW3: ,mscalc:targetPrice,,,,USD | FX3: NA | FY3: JAVA.O,mscalc:netFinancialIncomeExpense,2008Q1,,FYR,USD | FZ3: 40.3329036020583 | GA3: JAVA.O,mscalc:otheroperatingIncomeExpense,2008Q3,,FYR,USD | GB3: NA | GC3: JAVA.O,mscalc:taxExpenseFromOperations,2007Q4,,FYR,USD | GD3: 103.572328281592 | GE3: JAVA.O,mstag:inventories,2007Q4,,FYR,USD | GF3: 524 | GG3: STX.N,mstag:tradeAndOtherPayables,2008Q4,,FYR,USD | GH3: 1,280.30323437225 | GI3: STX.N,mscalc:otherIncomeExpense,2008Q4,,FYR,USD | GJ3: (0.000000000000018626) | GK3: JAVA.O,mscalc:sharePrice,2006Q3,,FYR,USD | GL3: 5.13 | GM3: JAVA.O,mstag:costOfMaterials,2007Q4 | GN3: NA | GO3: JAVA.O,mstag:incomeLossFromInvestmentsAccountedForUnderTheEquityMethodOperatingIncomeStatement,2008Q3,,FYR,USD | GP3: NA | GQ3: STX.N,mscalc:consensusEps,2009Q4,,FYR,USD | GR3: 0.625940978527069 | GS3: JAVA.O,mstag:tradeAndOtherPayables,2007Q1,,FYR,USD | GT3: 1,292 | GU3: JAVA.O,mstag:costOfManufacturing,2008Q4,,FYR,USD | GV3: NA | GW3: JAVA.O,mscalc:otherIncomeExpense,2008Q3,,FYR,USD | GX3: 23.8590031054606 | GY3: JAVA.O,mscalc:dilutiveSecurities,2008Q1,,FYR,USD | GZ3: NA | HA3: JAVA.O,mstag:tradeAndOtherPayables,2008Q3,,FYR,USD | HB3: 1,294.7865762502 | HC3: STX.N,mstag:costOfServicesSold,2008Q1 | HD3: NA | HE3: JAVA.O,mscalc:dilutedSharesOutstanding,2008Q4,,FYR | HF3: 3,372.53215958779 | HG3: JAVA.O,mstag:tradeReceivables,2008Q3,,FYR,USD | HH3: 2,463.15773609923 | HI3: JAVA.O,mscalc:consensusEps,2008Q2,,FYR,USD | HJ3: 0.282489985227585 | HK3: WDC.N,mscalc:targetPrice,,,,USD | HL3: NA | HM3: JAVA.O,mstag:costOfSalesWithoutDepreciation,2008Q2,,FYR,USD | HN3: NA | HO3: STX.N,mscalc:operatingExpenses,2008Q4,,FYR,USD | HP3: 2,581.75021773277 | HQ3: STX.N,mscalc:depreciationAndAmortization,2008Q4,,FYR,USD | HR3: 225.17192187029 | HS3: JAVA.O,mstag:inventories,2008Q4,,FYR,USD | HT3: 546.18320298233 | HU3: JAVA.O,mscalc:consensusEps,2006Q2,,FYR,USD | HV3: (0.0299999993294477) | HW3: STX.N,mstag:employeeExpenses,2008Q3,,FYR,USD | HX3: NA | HY3: STX.N,mstag:costOfSalesWithoutDepreciation,2008Q2,,FYR,USD | HZ3: NA | IA3: JAVA.O,mscalc:consensusEps,2008Q1,,FYR,USD | IB3: 0.239999994635582 | IC3: STX.N,mstag:researchAndDevelopment,2008Q2,,FYR,USD | ID3: 256.631812014621 | IE3: JAVA.O,mscalc:sharePrice,2006Q1,,FYR,USD | IF3: 3.93 | IG3: JAVA.O,mscalc:consensusEps,2007Q3,,FYR,USD | IH3: 0.119999997317791 | II3: JAVA.O,mstag:tradeAndOtherPayables,2007Q4,,FYR,USD | IJ3: 1,428 | IK3: JAVA.O,mscalc:epsForConsensusForThomsonFeed,2008Q4,,FYR,USD | IL3: 0.0957037120072411 | IM3: STX.N,mscalc:consensusEps,2008Q1,,FYR,USD | IN3: 0.689000010490417 | IO3: STX.N,mstag:employeeExpenses,2008Q2,,FYR,USD | IP3: NA | IQ3: JAVA.O,mscalc:sharePrice,2007Q3,,FYR,USD | IR3: 6.01 | IS3: STX.N,mscalc:depreciationAndAmortization,2008Q2,,FYR,USD | IT3: 225.17192187029 | IU3: STX.N,mstag:costOfSalesWithDepreciation,2008Q3,,FYR,USD | IV3: 2,332.50749295928
A4: STX.N,mstag:inventories,2007Q1,,FYR,USD | B4: 939 | C4: JAVA.O,mscalc:sharePrice,,,FYR,USD | D4: NA | E4: JAVA.O,mscalc:dilutedSharesOutstanding,2008Q1,,FYR | F4: 3,372.53215958779 | G4: STX.N,mscalc:otheroperatingIncomeExpense,2008Q3,,FYR,USD | H4: NA | I4: JAVA.O,mstag:employeeExpenses,2008Q4,,FYR,USD | J4: NA | K4: JAVA.O,mstag:costOfMaterials,2008Q1,,FYR,USD | L4: NA | M4: STX.N,mstag:costOfSalesWithoutDepreciation,2008Q3,,FYR,USD | N4: NA | O4: STX.N,mscalc:depreciationAndAmortization,2008Q1,,FYR,USD | P4: 205 | Q4: STX.N,mstag:incomeLossFromInvestmentsAccountedForUnderTheEquityMethodOperatingIncomeStatement,2008Q2,,FYR,USD | R4: NA | S4: JAVA.O,mstag:costOfSalesWithoutDepreciation | T4: NA | U4: JAVA.O,mscalc:otherIncomeExpense,2008Q1,,FYR,USD | V4: 18.3365052708751 | W4: JAVA.O,mscalc:nonMarketCapComponentsOfEv,2007Q4,,FYR,USD | X4: (4,754) | Y4: STX.N,mstag:costOfSalesWithDepreciation | Z4: NA | AA4: STX.N,mscalc:otheroperatingIncomeExpense,2008Q2,,FYR,USD | AB4: NA | AC4: STX.N,mstag:tradeAndOtherPayables,2008Q3,,FYR,USD | AD4: 1,425.42124569734 | AE4: JAVA.O,mscalc:depreciationAndAmortization,2008Q2,,FYR,USD | AF4: 202.408164888305 | AG4: STX.N,mstag:tradeReceivables,2008Q3,,FYR,USD | AH4: 1,468.79610796709 | AI4: STX.N,mscalc:consensusEps,2009Q1,,FYR,USD | AJ4: 0.715201020240784 | AK4: JAVA.O,mscalc:depreciationAndAmortization,2008Q1,,FYR,USD | AL4: 193 | AM4: STX.N,mscalc:netFinancialIncomeExpense,2008Q4,,FYR,USD | AN4: (14.0015300805477) | AO4: JAVA.O,mstag:costOfSalesWithDepreciation,2008Q1,,FYR,USD | AP4: 1,814.135470455 | AQ4: JAVA.O,mstag:inventories,,,FYR,USD | AR4: NA | AS4: JAVA.O,mstag:sellingGeneralAndAdministrativeExpenses,2007Q4,,FYR,USD | AT4: 997 | AU4: JAVA.O,mscalc:dilutedSharesOutstanding,2008Q2,,FYR | AV4: 3,372.53215958779 | AW4: STX.N,mstag:costOfSalesWithDepreciation,,,FYR,USD | AX4: NA | AY4: JAVA.O,mstag:sellingGeneralAndAdministrativeExpenses,2008Q4,,FYR,USD | AZ4: 989.559329182354 | BA4: JAVA.O,mscalc:consensusEps,2009Q1,,FYR,USD | BB4: 0.233264997601509 | BC4: JAVA.O,mstag:costOfSalesWithDepreciation,2008Q1 | BD4: 1,657.98863544785 | BE4: JAVA.O,mscalc:taxExpenseFromOperations,2008Q3,,FYR,USD | BF4: 56.1211445355905 | BG4: JAVA.O,mstag:costOfServicesSold,2007Q4 | BH4: NA | BI4: STX.N,mstag:incomeLossFromInvestmentsAccountedForUnderTheEquityMethodOperatingIncomeStatement,2008Q1,,FYR,USD | BJ4: NA | BK4: STX.N,mstag:averageDilutedSharesOutstanding,2008Q4,,FYR | BL4: 538.400665827991 | BM4: JAVA.O,mstag:tradeReceivables,2008Q4,,FYR,USD | BN4: 3,016.94917433645 | BO4: JAVA.O,mstag:sellingGeneralAndAdministrativeExpenses,2008Q3,,FYR,USD | BP4: 906.037647853218 | BQ4: STX.N,mstag:costOfSalesWithDepreciation,2008Q1 | BR4: 2,464.87590849649 | BS4: JAVA.O,mscalc:dilutedSharesOutstanding,,,FYR | BT4: NA | BU4: STX.N,mscalc:dilutedSharesOutstanding,2008Q3,,FYR | BV4: 562.067222377659 | BW4: JAVA.O,mstag:costOfServicesSold,2008Q2,,FYR,USD | BX4: NA | BY4: JAVA.O,mstag:costOfServicesSold,2008Q1,,FYR,USD | BZ4: NA | CA4: JAVA.O,mstag:costOfServicesSold,2008Q4,,FYR,USD | CB4: NA | CC4: JAVA.O,mscalc:sharePrice,2007Q1,,FYR,USD | CD4: 4.95 | CE4: STX.N,mstag:averageDilutedSharesOutstanding,2008Q3,,FYR | CF4: 544.217364470004 | CG4: STX.N,mstag:costOfServicesSold,2008Q3,,FYR,USD | CH4: NA | CI4: JAVA.O,mscalc:taxExpenseFromOperations,2008Q2,,FYR,USD | CJ4: 71.2837361429788 | CK4: JAVA.O,mscalc:operatingRevenue,2008Q4,,FYR,USD | CL4: 4,022.59889911526 | CM4: STX.N,mscalc:sharePrice,,,FYR,USD | CN4: NA | CO4: STX.N,mscalc:operatingRevenue,2008Q4,,FYR,USD | CP4: 2,903.49820338861 | CQ4: STX.N,mstag:inventories,2008Q2,,FYR,USD | CR4: 912.047916824353

Sheet __FDSCACHE__
B1: This sheet contains Factset binary data for use with this workbook's =FDS codes. Modifying the worksheet's contents may damage the workbook's =FDS functionality.

Sheet ImportantDisclosures
A2: 1585 Broadway
A3: New York, NY 10036-8293
A4: United States
A5: Tel: +1 (1)212 761 4000
A7: Authors: Joseph Moore, Katy Huberty
A8: Date: 25 Jan 2018
A10: Ticker: WDC.O
A11: Stock Rating: Equal-Weight
A12: Industry: Semiconductors
A13: Industry View: In-Line
A14: Price as of 25 Jan 2018: 87.99
A15: Target Price: 92
... A107: Equal-weight and Not-Rated to hold and Underweight to sell recommendations, respectively.
B109: Coverage Universe | D109: Investment Banking Clients (IBC) | G109: Other Material Investment Services Clients (MISC)
A110: Stock Rating Category | B110: Count | C110: % of Total | D110: Count | E110: % of Total IBC | F110: % of Rating Category | G110: Count | H110: % of Total Other MISC
A111: Overweight/Buy | B111: 1142 | C111: 0.36 | D111: 320 | E111: 0.4 | F111: 0.28 | G111: 560 | H111: 0.38
A112: Equal-weight/Hold | B112: 1424 | C112: 0.44 | D112: 371 | E112: 0.47 | F112: 0.26 | G112: 674 | H112: 0.46
A113: Not-Rated/Hold | B113: 55 | C113: 0.02 | D113: 6 | E113: 0.01 | F113: 0.11 | G113: 9 | H113: 0.01
A114: Underweight/Sell | B114: 583 | C114: 0.18 | D114: 95 | E114: 0.12 | F114: 0.16 | G114: 237 | H114: 0.16
A115: Total | B115: 3204 | D115: 792 | G115: 1480
A117: Data include common stock and ADRs currently assigned ratings. Investment Banking Clients are companies
A118: from whom Morgan Stanley received investment banking compensation in the last 12 months. Due to rounding
A119: off of decimals, the percentages provided in the "% of total" column may not add up to exactly 100
A120: percent.
A122: Analyst Stock Ratings
A124: Overweight (O). The stock's total return is expected to exceed the average total return of the analyst's
A125: industry (or industry team's) coverage universe, on a risk-adjusted basis, over the next 12-18 months.
A127: Equal-weight (E). The stock's total return is expected to be in line with the average total return of
A128: the analyst's industry (or industry team's) coverage universe, on a risk-adjusted basis, over the next
A129: 12-18 months.
A131: Not-Rated (NR). Currently the analyst does not have adequate conviction about the stock's total return
A132: relative to the average total return of the analyst's industry (or industry team's) coverage universe,
... A378: © Copyright 2018 Morgan Stanley

Sheet IS
B5: Western Digital
B6: Income Statement
F8: F2001A | J8: F2002A | N8: F2003A | R8: F2004A | V8: F2005A | Z8: F2006A | AD8: F2007A | AH8: F2008A | AL8: F2009A | AP8: F2010A | AT8: F2011A | AX8: F2012A | BB8: F2013A | BF8: F2014A | BJ8: F2015A | BN8: F2016A | BR8: F2017A | BV8: F2018E | BZ8: F2019E | CR8: Fiscal Year | DS8: Calendarized
B9: ($ in millions) | F9: 36776 | G9: 36867 | H9: 36956 | I9: 37048 | J9: 37141 | K9: 37232 | L9: 37321 | M9: 37413 | N9: 37506 | O9: 37597 | P9: 37686 | Q9: 37778 | R9: 37871 | S9: 37962 | T9: 38052 | U9: 38144 | V9: 38237 | W9: 38328 | X9: 38417 | Y9: 38509 | Z9: 38602 | AA9: 38693 | AB9: 38782 | AC9: 38874 | AD9: 38967 | AE9: 39058 | AF9: 39147 | AG9: 39239 | AH9: 39331 | AI9: 39422 | AJ9: 39513 | AK9: 39605 | AL9: 39697 | AM9: 39788 | AN9: 39878 | AO9: 39970 | AP9: 40062 | AQ9: 40153 | AR9: 40243 | AS9: 40335 | AT9: 40451 | AU9: 40542 | AV9: 40632 | AW9: 40724 | AX9: 40816 | AY9: 40907 | AZ9: 40998 | BA9: 41090 | BB9: 41182 | BC9: 41273 | BD9: 41364 | BE9: 41455 | BF9: 41547 | BG9: 41638 | BH9: 41728 | BI9: 41820 | BJ9: 41912 | BK9: 42003 | BL9: 42093 | BM9: 42185 | BN9: 42277 | BO9: 42368 | BP9: 42459 | BQ9: 42551 | BR9: 42643 | BS9: 42735 | BT9: 42825 | BU9: 42916 | BV9: 43008 | BW9: 43100 | BX9: 43190 | BY9: 43281 | BZ9: 43373 | CA9: 43465 | CB9: 43555 | CC9: 43646 | CE9: 2001A | CF9: 2002A | CG9: 2003A | CH9: 2004A | CI9: 2005A | CJ9: 2006A | CK9: 2007A | CL9: 2008A | CM9: 2009A | CN9: 2010A | CO9: 2011A | CP9: 2012A | CQ9: 2013A | CR9: 2014A | CS9: 2015A | CT9: 2016A | CU9: 2017A | CV9: 2018E | CW9: 2019E | CX9: 2020E | CY9: 2021E | CZ9: 2022E | DA9: 2023E | DB9: 2024E | DC9: 2025E | DG9: 2001A | DH9: 2002A | DI9: 2003A | DJ9: 2004A | DK9: 2005A | DL9: 2006A | DM9: 2007A | DN9: 2008A | DO9: 2009A | DP9: 2010A | DQ9: 2011A | DR9: 2012A | DS9: 2013A | DT9: 2014A | DU9: 2015A | DV9: 2016A | DW9: 2017E | DX9: 2018E
BB10: FY13 and fwd restated for new segment reporting in 2H CY16 | BJ10: FY15 and fwd restated for SBC on 10/26/2016
A11: X | B11: Revenues | F11: 424.366 | G11: 561.57 | H11: 511.723 | I11: 455.733 | J11: =J395+J382 -> 440.943 | K11: =K395+K382 -> 574.67 | L11: =L395+L382 -> 594.86671 | M11: =M395+M382 -> 540.672 | N11: =N395+N382 -> 582.90928 | O11: =O395+O382 -> 749.4884 | P11: =P395+P382 -> 705.83853 | Q11: =Q395+Q382 -> 680.26237 | ... AO11: =AO395+AO382 -> 1928.1866 | AP11: =AP28+AP29+AP32+AP35 -> 2208 | AQ11: =AQ28+AQ29+AQ32+AQ35 -> 2619 | AR11: =AR28+AR29+AR32+AR35 -> 2641 | AS11: =AS28+AS29+AS32+AS35 -> 2382 | AT11: =AT28+AT29+AT32+AT35 -> 2447 | AU11: =AU28+AU29+AU32+AU35 -> 2475 | AV11: =AV28+AV29+AV32+AV35 -> 2252 | AW11: =AW28+AW29+AW32+AW35 -> 2403 | ... BA11: =BA28+BA29+BA32+BA35 -> 4754 | BB11: =SUM(BB12, BB13, BB14) -> 4035 | BC11: =SUM(BC12, BC13, BC14) -> 3824 | BD11: =SUM(BD12, BD13, BD14) -> 3764 | BE11: =SUM(BE12, BE13, BE14) -> 3728 | BF11: =SUM(BF12, BF13, BF14) -> 3804 | BG11: =SUM(BG12, BG13, BG14) -> 3972 | BH11: =SUM(BH12, BH13, BH14) -> 3703 | BI11: =SUM(BI12, BI13, BI14) -> 3651 | ... CC11: =SUM(CC12, CC13, CC14) -> 4386.1351 | CE11: =SUM(F11:I11) -> 1953.392 | CF11: =SUM(J11:M11) -> 2151.1517 | CG11: =SUM(N11:Q11) -> 2718.4986 | CH11: =SUM(R11:U11) -> 3046.7261 | CI11: =SUM(V11:Y11) -> 3638.7642 | CJ11: =SUM(Z11:AC11) -> 4341.263 | CK11: =SUM(AD11:AG11) -> 5468.7064 | CL11: =SUM(AH11:AK11) -> 8074.1839 | CM11: =SUM(AL11:AO11) -> 7451.8561 | CN11: =SUM(AP11:AS11) -> 9850 | CO11: =SUM(AT11:AW11) -> 9577 | CP11: =SUM(AX11:BA11) -> 12478 | CQ11: =SUM(CQ12, CQ13, CQ14) -> 15351 | CR11: =SUM(CR12, CR13, CR14) -> 15130 | CS11: =SUM(CS12, CS13, CS14) -> 14572 | CT11: =SUM(CT12, CT13, CT14) -> 12994 | CU11: =SUM(CU12, CU13, CU14) -> 19093 | CV11: =SUM(CV12, CV13, CV14) -> 20340.12 | CW11: =SUM(CW12, CW13, CW14) -> 19080.648 | CX11: =SUM(CX12, CX13, CX14) -> 20472.086 | ... DC11: =SUM(DC12, DC13, DC14) -> 25509.215 | DG11: =SUM(H11:K11) -> 1983.069 | DH11: =SUM(L11:O11) -> 2467.9364 | DI11: =SUM(P11:S11) -> 2935.1426 | DJ11: =SUM(T11:W11) -> 3276.186 | DK11: =SUM(X11:AA11) -> 3987.235 | DL11: =SUM(AB11:AE11) -> 4906.2595 | DM11: =SUM(AF11:AI11) -> 6746.8297 | DN11: =SUM(AJ11:AM11) -> 8035.8692 | DO11: =SUM(AN11:AQ11) -> 8347.0786 | DP11: =SUM(AR11:AU11) -> 9945 | DQ11: =SUM(AV11:AY11) -> 9344 | DR11: =SUM(AZ11:BC11) -> 15648 | DS11: =SUM(BD11:BG11) -> 15268 | DT11: =SUM(BH11:BK11) -> 15185 | DU11: =SUM(BL11:BO11) -> 13418 | DV11: =SUM(BP11:BS11) -> 15919 | DW11: =SUM(BT11:BW11) -> 20008 | DX11: =SUM(BX11:CA11) -> 19883.739 | DZ11: =CU11*(1+DZ28) -> 19665.79
C12: Client Devices | BB12: =BB241 -> 2650 | BC12: =BC241 -> 2259 | BD12: =BD241 -> 2168 | BE12: =BE241 -> 2109 | BF12: =BF241 -> 2198 | BG12: =BG241 -> 2226 | BH12: =BH241 -> 2126 | BI12: =BI241 -> 2170 | ... CC12: =CC241 -> 2114.1098 | CQ12: =CQ241 -> 9186 | CR12: =CR241 -> 8720 | CS12: =CS241 -> 7710 | CT12: =CT241 -> 6205 | CU12: =CU241 -> 9520 | CV12: =CV241 -> 10202.576 | CW12: =CW241 -> 9238.843 | CX12: =CX241 -> 9516.0082 | ... DC12: =DC241 -> 9311.6887 | DS12: =SUM(BD12:BG12) -> 8701 | DT12: =SUM(BH12:BK12) -> 8640 | DU12: =SUM(BL12:BO12) -> 6617 | DV12: =SUM(BP12:BS12) -> 7746 | DW12: =SUM(BT12:BW12) -> 10051 | DX12: =SUM(BX12:CA12) -> 9757.1691
C13: Client Solutions | BB13: =BB291 -> 500 | BC13: =BC291 -> 568 | BD13: =BD291 -> 500 | BE13: =BE291 -> 401 | BF13: =BF291 -> 455 | BG13: =BG291 -> 543 | BH13: =BH291 -> 479 | BI13: =BI291 -> 444 | ... CC13: =CC291 -> 1000.206 | CQ13: =CQ291 -> 1969 | CR13: =CR291 -> 1921 | CS13: =CS291 -> 1850 | CT13: =CT291 -> 1870 | CU13: =CU291 -> 4068 | CV13: =CV291 -> 4516.5835 | CW13: =CW291 -> 4249.3853 | CX13: =CX291 -> 4334.373 | ... DC13: =DC291 -> 4158.5538 | DS13: =SUM(BD13:BG13) -> 1899 | DT13: =SUM(BH13:BK13) -> 1955 | DU13: =SUM(BL13:BO13) -> 1676 | DV13: =SUM(BP13:BS13) -> 3064 | DW13: =SUM(BT13:BW13) -> 4407 | DX13: =SUM(BX13:CA13) -> 4348.7526
C14: Data Center Devices & Solutions | BB14: =BB317 -> 885 | BC14: =BC317 -> 997 | BD14: =BD317 -> 1096 | BE14: =BE317 -> 1218 | BF14: =BF317 -> 1151 | BG14: =BG317 -> 1203 | BH14: =BH317 -> 1098 | BI14: =BI317 -> 1037 | ... CC14: =CC317 -> 1271.8193 | CQ14: =CQ317 -> 4196 | CR14: =CR317 -> 4489 | CS14: =CS317 -> 5012 | CT14: =CT317 -> 4919 | CU14: =CU317 -> 5505 | CV14: =CV317 -> 5620.9601 | CW14: =CW317 -> 5592.4202 | CX14: =CX317 -> 6621.7051 | ... DC14: =DC317 -> 12038.972 | DS14: =SUM(BD14:BG14) -> 4668 | DT14: =SUM(BH14:BK14) -> 4590 | DU14: =SUM(BL14:BO14) -> 5125 | DV14: =SUM(BP14:BS14) -> 5109 | DW14: =SUM(BT14:BW14) -> 5550 | DX14: =SUM(BX14:CA14) -> 5777.817
B16: Cost of revenues | BB16: =SUM(BB17:BB19) -> 2804.1 | BC16: =SUM(BC17:BC19) -> 2726.9445 | BD16: =SUM(BD17:BD19) -> 2665.28 | BE16: =SUM(BE17:BE19) -> 2642.762 | BF16: =SUM(BF17:BF19) -> 2668.9298 | BG16: =SUM(BG17:BG19) -> 2776.176 | BH16: =SUM(BH17:BH19) -> 2587.992 | BI16: =SUM(BI17:BI19) -> 2572.69 | ... CC16: =SUM(CC17:CC19) -> 2832.7765 | CQ16: =SUM(CQ17:CQ19) -> 10839.086 | CR16: =SUM(CR17:CR19) -> 10605.788 | CS16: =SUM(CS17:CS19) -> 10161.024 | CT16: =SUM(CT17:CT19) -> 9183.5725 | CU16: =SUM(CU17:CU19) -> 11878.438 | CV16: =SUM(CV17:CV19) -> 11807.378 | CW16: =SUM(CW17:CW19) -> 12021.718 | CX16: =SUM(CX17:CX19) -> 12971.248 | ... DC16: =SUM(DC17:DC19) -> 16645.919 | DS16: =SUM(BD16:BG16) -> 10753.148 | DT16: =SUM(BH16:BK16) -> 10603.584 | DU16: =SUM(BL16:BO16) -> 9472.684 | DV16: =SUM(BP16:BS16) -> 10640.601 | DW16: =SUM(BT16:BW16) -> 11685.622 | DX16: =SUM(BX16:CA16) -> 12024.318
C17: Client Devices | BB17: =(1-BB516)*BB12 -> 1996.775 | BC17: =(1-BC516)*BC12 -> 1766.538 | BD17: =(1-BD516)*BD12 -> 1691.04 | BE17: =(1-BE516)*BE12 -> 1678.764 | BF17: =(1-BF516)*BF12 -> 1706.9668 | BG17: =(1-BG516)*BG12 -> 1736.28 | BH17: =(1-BH516)*BH12 -> 1643.398 | BI17: =(1-BI516)*BI12 -> 1675.24 | ... CC17: =(1-CC516)*CC12 -> 1522.159 | CQ17: =SUM(BB17:BE17) -> 7133.117 | CR17: =SUM(BF17:BI17) -> 6761.8848 | CS17: =SUM(BJ17:BM17) -> 6019.48 | CT17: =SUM(BN17:BQ17) -> 5015.9675 | CU17: =SUM(BR17:BU17) -> 6652.43 | CV17: =SUM(BV17:BY17) -> 6653.51 | CW17: =SUM(BZ17:CC17) -> 6494.9773 | CX17: =(1-CX516)*CX12 -> 6756.3659 | CY17: =(1-CY516)*CY12 -> 6781.6404 | CZ17: =(1-CZ516)*CZ12 -> 6759.082 | DA17: =(1-DA516)*DA12 -> 6849.5698 | DB17: =(1-DB516)*DB12 -> 6939.9841 | DC17: =(1-DC516)*DC12 -> 7030.325
C18: Client Solutions | BB18: =(1-BB517)*BB13 -> 325 | BC18: =(1-BC517)*BC13 -> 397.6 | BD18: =(1-BD517)*BD13 -> 355 | BE18: =(1-BE517)*BE13 -> 280.7 | BF18: =(1-BF517)*BF13 -> 313.95 | BG18: =(1-BG517)*BG13 -> 363.81 | BH18: =(1-BH517)*BH13 -> 320.93 | BI18: =(1-BI517)*BI13 -> 306.36 | ... CC18: =(1-CC517)*CC13 -> 700.14418 | CQ18: =SUM(BB18:BE18) -> 1358.3 | CR18: =SUM(BF18:BI18) -> 1305.05 | CS18: =SUM(BJ18:BM18) -> 1275.416 | CT18: =SUM(BN18:BQ18) -> 1292.145 | CU18: =SUM(BR18:BU18) -> 2568.908 | CV18: =SUM(BV18:BY18) -> 2771.4734 | CW18: =SUM(BZ18:CC18) -> 2930.1501 | CX18: =(1-CX517)*CX13 -> 2904.0299 | CY18: =(1-CY517)*CY13 -> 2946.1947 | CZ18: =(1-CZ517)*CZ13 -> 2959.0279 | DA18: =(1-DA517)*DA13 -> 2971.2929 | DB18: =(1-DB517)*DB13 -> 2982.9998 | DC18: =(1-DC517)*DC13 -> 2994.1587
C19: Data Center Devices and Solutions | BB19: =(1-BB518)*BB14 -> 482.325 | BC19: =(1-BC518)*BC14 -> 562.8065 | BD19: =(1-BD518)*BD14 -> 619.24 | BE19: =(1-BE518)*BE14 -> 683.298 | BF19: =(1-BF518)*BF14 -> 648.013 | BG19: =(1-BG518)*BG14 -> 676.086 | BH19: =(1-BH518)*BH14 -> 623.664 | BI19: =(1-BI518)*BI14 -> 591.09 | ... CC19: =(1-CC518)*CC14 -> 610.47327 | CQ19: =SUM(BB19:BE19) -> 2347.6695 | CR19: =SUM(BF19:BI19) -> 2538.853 | CS19: =SUM(BJ19:BM19) -> 2866.1275 | CT19: =SUM(BN19:BQ19) -> 2875.46 | CU19: =SUM(BR19:BU19) -> 2657.1 | CV19: =SUM(BV19:BY19) -> 2382.3946 | CW19: =SUM(BZ19:CC19) -> 2596.5902 | CX19: =(1-CX518)*CX14 -> 3310.8526 | CY19: =(1-CY518)*CY14 -> 3805.9575 | CZ19: =(1-CZ518)*CZ14 -> 4373.4183 | DA19: =(1-DA518)*DA14 -> 5023.6278 | DB19: =(1-DB518)*DB14 -> 5768.4517 | DC19: =(1-DC518)*DC14 -> 6621.4348
BV20: =AVERAGE(BR22:BW22) -> 0.3944032
B21: Gross Profit | BB21: =SUM(BB23, BB24, BB25) -> 1230.9 | BC21: =SUM(BC23, BC24, BC25) -> 1097.0555 | BD21: =SUM(BD23, BD24, BD25) -> 1098.72 | BE21: =SUM(BE23, BE24, BE25) -> 1085.238 | BF21: =SUM(BF23, BF24, BF25) -> 1135.0702 | BG21: =SUM(BG23, BG24, BG25) -> 1195.824 | BH21: =SUM(BH23, BH24, BH25) -> 1115.008 | BI21: =SUM(BI23, BI24, BI25) -> 1078.31 | ... CC21: =SUM(CC23, CC24, CC25) -> 1553.3586 | CQ21: =SUM(CQ23, CQ24, CQ25) -> 4511.9135 | CR21: =SUM(CR23, CR24, CR25) -> 4524.2122 | CS21: =SUM(CS23, CS24, CS25) -> 4410.9765 | CT21: =SUM(CT23, CT24, CT25) -> 3810.4275 | CU21: =SUM(CU23, CU24, CU25) -> 7214.562 | CV21: =SUM(CV23, CV24, CV25) -> 8532.7419 | CW21: =SUM(CW23, CW24, CW25) -> 7058.9308 | CX21: =SUM(CX23, CX24, CX25) -> 7500.838 | ... DC21: =SUM(DC23, DC24, DC25) -> 8863.2964 | DS21: =SUM(BD21:BG21) -> 4514.8522 | DT21: =SUM(BH21:BK21) -> 4581.416 | DU21: =SUM(BL21:BO21) -> 3945.316 | DV21: =SUM(BP21:BS21) -> 5278.399 | DW21: =SUM(BT21:BW21) -> 8322.378 | DX21: =SUM(BX21:CA21) -> 7859.4211
B22: Gross Margin | BB22: =BB21/BB11 -> 0.30505576 | BC22: =BC21/BC11 -> 0.2868869 | BD22: =BD21/BD11 -> 0.29190223 | BE22: =BE21/BE11 -> 0.29110461 | BF22: =BF21/BF11 -> 0.29838859 | BG22: =BG21/BG11 -> 0.30106344 | BH22: =BH21/BH11 -> 0.30110937 | BI22: =BI21/BI11 -> 0.29534648 | ... CC22: =CC21/CC11 -> 0.35415202 | CQ22: =CQ21/CQ11 -> 0.29391659 | CR22: =CR21/CR11 -> 0.29902262 | CS22: =CS21/CS11 -> 0.3027022 | CT22: =CT21/CT11 -> 0.29324515 | CU22: =CU21/CU11 -> 0.37786424 | CV22: =CV21/CV11 -> 0.41950303 | CW22: =CW21/CW11 -> 0.36995236 | CX22: =CX21/CX11 -> 0.36639343 | ... DC22: =DC21/DC11 -> 0.34745469 | DS22: =DS21/DS11 -> 0.29570685 | DT22: =DT21/DT11 -> 0.30170668 | DU22: =DU21/DU11 -> 0.2940316 | DV22: =DV21/DV11 -> 0.33157855 | DW22: =DW21/DW11 -> 0.41595252 | DX22: =DX21/DX11 -> 0.39526878
C23: Client Devices | BB23: =BB12-BB17 -> 653.225 | BC23: =BC12-BC17 -> 492.462 | BD23: =BD12-BD17 -> 476.96 | BE23: =BE12-BE17 -> 430.236 | BF23: =BF12-BF17 -> 491.0332 | BG23: =BG12-BG17 -> 489.72 | BH23: =BH12-BH17 -> 482.602 | BI23: =BI12-BI17 -> 494.76 | ... CC23: =CC12-CC17 -> 591.95073 | CQ23: =SUM(BB23:BE23) -> 2052.883 | CR23: =SUM(BF23:BI23) -> 1958.1152 | CS23: =SUM(BJ23:BM23) -> 1690.52 | CT23: =SUM(BN23:BQ23) -> 1189.0325 | CU23: =SUM(BR23:BU23) -> 2867.57 | CV23: =SUM(BV23:BY23) -> 3549.0664 | CW23: =CW12-CW17 -> 2743.8657 | CX23: =CX12-CX17 -> 2759.6424 | CY23: =CY12-CY17 -> 2637.3046 | CZ23: =CZ12-CZ17 -> 2563.7897 | DA23: =DA12-DA17 -> 2469.5728 | DB23: =DB12-DB17 -> 2375.4308 | DC23: =DC12-DC17 -> 2281.3637
C24: Client Solutions | BB24: =BB13-BB18 -> 175 | BC24: =BC13-BC18 -> 170.4 | BD24: =BD13-BD18 -> 145 | BE24: =BE13-BE18 -> 120.3 | BF24: =BF13-BF18 -> 141.05 | BG24: =BG13-BG18 -> 179.19 | BH24: =BH13-BH18 -> 158.07 | BI24: =BI13-BI18 -> 137.64 | ... CC24: =CC13-CC18 -> 300.06179 | CQ24: =SUM(BB24:BE24) -> 610.7 | CR24: =SUM(BF24:BI24) -> 615.95 | CS24: =SUM(BJ24:BM24) -> 574.584 | CT24: =SUM(BN24:BQ24) -> 577.855 | CU24: =SUM(BR24:BU24) -> 1499.092 | CV24: =SUM(BV24:BY24) -> 1745.11 | CW24: =CW13-CW18 -> 1319.2351 | CX24: =CX13-CX18 -> 1430.3431 | CY24: =CY13-CY18 -> 1386.4446 | CZ24: =CZ13-CZ18 -> 1329.4184 | DA24: =DA13-DA18 -> 1273.4112 | DB24: =DB13-DB18 -> 1218.4084 | DC24: =DC13-DC18 -> 1164.3951
C25: Data Center Devices and Solutions | BB25: =BB14-BB19 -> 402.675 | BC25: =BC14-BC19 -> 434.1935 | BD25: =BD14-BD19 -> 476.76 | BE25: =BE14-BE19 -> 534.702 | BF25: =BF14-BF19 -> 502.987 | BG25: =BG14-BG19 -> 526.914 | BH25: =BH14-BH19 -> 474.336 | BI25: =BI14-BI19 -> 445.91 | ... CC25: =CC14-CC19 -> 661.34605 | CQ25: =SUM(BB25:BE25) -> 1848.3305 | CR25: =SUM(BF25:BI25) -> 1950.147 | CS25: =SUM(BJ25:BM25) -> 2145.8725 | CT25: =SUM(BN25:BQ25) -> 2043.54 | CU25: =SUM(BR25:BU25) -> 2847.9 | CV25: =SUM(BV25:BY25) -> 3238.5655 | CW25: =CW14-CW19 -> 2995.83 | CX25: =CX14-CX19 -> 3310.8526 | CY25: =CY14-CY19 -> 3656.7042 | CZ25: =CZ14-CZ19 -> 4037.0015 | DA25: =DA14-DA19 -> 4454.9152 | DB25: =DB14-DB19 -> 4913.8663 | DC25: =DC14-DC19 -> 5417.5376
B27: OLD SEGMENT REPORTING
C28: Other - SSD | AP28: =AP382 -> 48.4382 | AQ28: =AQ382 -> 43.302 | AR28: =AR382 -> 34.241 | AS28: =AS382 -> 47.3835 | AT28: =AT382 -> 115.27873 | AU28: =AU382 -> 19.155 | AV28: =AV382 -> 10.72977 | AW28: =AW382 -> 33.820508 | ... BR28: =BR382 -> 244.59489 | CN28: =SUM(AP28:AS28) -> 173.3647 | CO28: =SUM(AT28:AW28) -> 178.98401 | CP28: =SUM(AX28:BA28) -> 226.44664 | CQ28: =SUM(BB28:BE28) -> 540.19275 | CR28: =SUM(BF28:BI28) -> 675.6603 | CS28: =SUM(BJ28:BM28) -> 905.21042 | CT28: =SUM(BN28:BQ28) -> 1102.2451 | CU28: =SUM(BR28:BU28) -> 244.59489 | DP28: =SUM(AR28:AU28) -> 216.05823 | DQ28: =SUM(AV28:AY28) -> 107.84546 | DR28: =SUM(AZ28:BC28) -> 475.3335 | DS28: =SUM(BD28:BG28) -> 587.38285 | DT28: =SUM(BH28:BK28) -> 729.71867 | DU28: =DU382 -> 1100.7101 | DV28: =DV382 -> 737.9098 | DW28: =DW382 -> 0 | DX28: =DX382 -> 0 | DZ28: 0.03
C29: Enterprise | AP29: =AP406 -> 155.217 | AQ29: =AQ406 -> 206.15 | AR29: =AR406 -> 223.82 | AS29: =AS406 -> 215.832 | AT29: =AT406 -> 211.029 | AU29: =AU406 -> 203.276 | AV29: =AV406 -> 197.01841 | AW29: =AW406 -> 209.34268 | ... BR29: =BR406 -> 770.31642 | CN29: =SUM(AP29:AS29) -> 801.019 | CO29: =SUM(AT29:AW29) -> 820.66609 | CP29: =SUM(AX29:BA29) -> 2046.7133 | CQ29: =SUM(BB29:BE29) -> 3610.479 | CR29: =SUM(BF29:BI29) -> 3663.3585 | CS29: =SUM(BJ29:BM29) -> 3737.5919 | CT29: =SUM(BN29:BQ29) -> 3174.0781 | CU29: =SUM(BR29:BU29) -> 770.31642 | DP29: =SUM(AR29:AU29) -> 853.957 | DQ29: =SUM(AV29:AY29) -> 840.33807 | DR29: =SUM(AZ29:BC29) -> 3302.3557 | DS29: =SUM(BD29:BG29) -> 3870.6433 | DT29: =SUM(BH29:BK29) -> 3633.7667 | DU29: =SUM(BL29:BO29) -> 3533.1208 | DV29: =SUM(BP29:BS29) -> 2228.6738 | DW29: =SUM(BT29:BW29) -> 0 | DX29: =SUM(BX29:CA29) -> 0
D30: Performance | AP30: =AP416 -> 0 | AQ30: =AQ416 -> 0 | AR30: =AR416 -> 0 | AS30: =AS416 -> 0 | AT30: =AT416 -> 0 | AU30: =AU416 -> 0 | AV30: =AV416 -> 0 | AW30: =AW416 -> 0 | ... BR30: =BR416 -> 301.05284 | CN30: =SUM(AP30:AS30) -> 0 | CO30: =SUM(AT30:AW30) -> 0 | CP30: =SUM(AX30:BA30) -> 706.7 | CQ30: =SUM(BB30:BE30) -> 1952.9766 | CR30: =SUM(BF30:BI30) -> 1896.5191 | CS30: =SUM(BJ30:BM30) -> 1891.4707 | CT30: =SUM(BN30:BQ30) -> 1460.9439 | CU30: =SUM(BR30:BU30) -> 301.05284 | DP30: =SUM(AR30:AU30) -> 0 | DQ30: =SUM(AV30:AY30) -> 0 | DR30: =SUM(AZ30:BC30) -> 1666.7949 | DS30: =SUM(BD30:BG30) -> 1999.8273 | DT30: =SUM(BH30:BK30) -> 1836.9771 | DU30: =SUM(BL30:BO30) -> 1780.5283 | DV30: =SUM(BP30:BS30) -> 925.53557 | DW30: =SUM(BT30:BW30) -> 0 | DX30: =SUM(BX30:CA30) -> 0
D31: Capacity | AP31: =AP426 -> 155.217 | AQ31: =AQ426 -> 206.15 | AR31: =AR426 -> 223.82 | AS31: =AS426 -> 215.832 | AT31: =AT426 -> 211.029 | AU31: =AU426 -> 203.276 | AV31: =AV426 -> 197.01841 | AW31: =AW426 -> 209.34268 | ... BR31: =BR426 -> 469.26358 | CN31: =SUM(AP31:AS31) -> 801.019 | CO31: =SUM(AT31:AW31) -> 820.66609 | CP31: =SUM(AX31:BA31) -> 1340.0133 | CQ31: =SUM(BB31:BE31) -> 1657.5024 | CR31: =SUM(BF31:BI31) -> 1766.8394 | CS31: =SUM(BJ31:BM31) -> 1846.1212 | CT31: =SUM(BN31:BQ31) -> 1713.1342 | CU31: =SUM(BR31:BU31) -> 469.26358 | DP31: =SUM(AR31:AU31) -> 853.957 | DQ31: =SUM(AV31:AY31) -> 840.33807 | DR31: =SUM(AZ31:BC31) -> 1635.5608 | DS31: =SUM(BD31:BG31) -> 1870.816 | DT31: =SUM(BH31:BK31) -> 1796.7896 | DU31: =SUM(BL31:BO31) -> 1752.5925 | DV31: =SUM(BP31:BS31) -> 1303.1382 | DW31: =SUM(BT31:BW31) -> 0 | DX31: =SUM(BX31:CA31) -> 0
C32: Compute | AP32: =AP437 -> 1499.7848 | AQ32: =AQ437 -> 1633.145 | AR32: =AR437 -> 1723.2545 | AS32: =AS437 -> 1514.5035 | AT32: =AT437 -> 1499.2298 | AU32: =AU437 -> 1529.9815 | AV32: =AV437 -> 1432.6053 | AW32: =AW437 -> 1545.3673 | ... BR32: =BR437 -> 1142.2333 | CN32: =SUM(AP32:AS32) -> 6370.6878 | CO32: =SUM(AT32:AW32) -> 6007.1838 | CP32: =SUM(AX32:BA32) -> 7881.0759 | CQ32: =SUM(BB32:BE32) -> 8008.2247 | CR32: =SUM(BF32:BI32) -> 7300.841 | CS32: =SUM(BJ32:BM32) -> 6372.9584 | CT32: =SUM(BN32:BQ32) -> 4589.9946 | CU32: =SUM(BR32:BU32) -> 1142.2333 | DP32: =SUM(AR32:AU32) -> 6266.9693 | DQ32: =SUM(AV32:AY32) -> 5957.2833 | DR32: =SUM(AZ32:BC32) -> 9044.4576 | DS32: =SUM(BD32:BG32) -> 7594.2701 | DT32: =SUM(BH32:BK32) -> 7145.2938 | DU32: =SUM(BL32:BO32) -> 5366.4428 | DV32: =SUM(BP32:BS32) -> 3165.5529 | DW32: =SUM(BT32:BW32) -> 0 | DX32: =SUM(BX32:CA32) -> 0
D33: Mobile | AP33: =AP447 -> 717.3152 | AQ33: =AQ447 -> 789.2075 | AR33: =AR447 -> 768.24 | AS33: =AS447 -> 693.0825 | AT33: =AT447 -> 667.4255 | AU33: =AU447 -> 708.43875 | AV33: =AV447 -> 644.71899 | AW33: =AW447 -> 670.14699 | ... BR33: =BR447 -> 710.60516 | CN33: =SUM(AP33:AS33) -> 2967.8452 | CO33: =SUM(AT33:AW33) -> 2690.7302 | CP33: =SUM(AX33:BA33) -> 4259.2349 | CQ33: =SUM(BB33:BE33) -> 4627.7609 | CR33: =SUM(BF33:BI33) -> 4216.9053 | CS33: =SUM(BJ33:BM33) -> 3726.1554 | CT33: =SUM(BN33:BQ33) -> 2622.6447 | CU33: =SUM(BR33:BU33) -> 710.60516 | DP33: =SUM(AR33:AU33) -> 2837.1867 | DQ33: =SUM(AV33:AY33) -> 2730.5716 | DR33: =SUM(AZ33:BC33) -> 5257.1111 | DS33: =SUM(BD33:BG33) -> 4359.0786 | DT33: =SUM(BH33:BK33) -> 4172.3651 | DU33: =SUM(BL33:BO33) -> 3080.04 | DV33: =SUM(BP33:BS33) -> 1879.0059 | DW33: =SUM(BT33:BW33) -> 0 | DX33: =SUM(BX33:CA33) -> 0
D34: Desktop | AP34: =AP457 -> 782.4696 | AQ34: =AQ457 -> 843.9375 | AR34: =AR457 -> 955.0145 | AS34: =AS457 -> 821.421 | AT34: =AT457 -> 831.80427 | AU34: =AU457 -> 821.54275 | AV34: =AV457 -> 787.88626 | AW34: =AW457 -> 875.22031 | ... BR34: =BR457 -> 431.62813 | CN34: =SUM(AP34:AS34) -> 3402.8426 | CO34: =SUM(AT34:AW34) -> 3316.4536 | CP34: =SUM(AX34:BA34) -> 3621.841 | CQ34: =SUM(BB34:BE34) -> 3380.4638 | CR34: =SUM(BF34:BI34) -> 3083.9357 | CS34: =SUM(BJ34:BM34) -> 2646.803 | CT34: =SUM(BN34:BQ34) -> 1967.35 | CU34: =SUM(BR34:BU34) -> 431.62813 | DP34: =SUM(AR34:AU34) -> 3429.7825 | DQ34: =SUM(AV34:AY34) -> 3226.7116 | DR34: =SUM(AZ34:BC34) -> 3787.3464 | DS34: =SUM(BD34:BG34) -> 3235.1915 | DT34: =SUM(BH34:BK34) -> 2972.9287 | DU34: =SUM(BL34:BO34) -> 2286.4029 | DV34: =SUM(BP34:BS34) -> 1286.547 | DW34: =SUM(BT34:BW34) -> 0 | DX34: =SUM(BX34:CA34) -> 0
C35: Non-Compute | AP35: =AP468 -> 504.56 | AQ35: =AQ468 -> 736.403 | AR35: =AR468 -> 659.6845 | AS35: =AS468 -> 604.281 | AT35: =AT468 -> 621.4625 | AU35: =AU468 -> 722.5875 | AV35: =AV468 -> 611.64656 | AW35: =AW468 -> 614.4695 | ... BR35: =BR468 -> 1009.9831 | CN35: =SUM(AP35:AS35) -> 2504.9285 | CO35: =SUM(AT35:AW35) -> 2570.1661 | CP35: =SUM(AX35:BA35) -> 2323.7642 | CQ35: =SUM(BB35:BE35) -> 3192.1036 | CR35: =SUM(BF35:BI35) -> 3490.1401 | CS35: =SUM(BJ35:BM35) -> 3556.2393 | CT35: =SUM(BN35:BQ35) -> 3386.2748 | CU35: =SUM(BR35:BU35) -> 1009.9831 | DP35: =SUM(AR35:AU35) -> 2608.0155 | DQ35: =SUM(AV35:AY35) -> 2438.5332 | DR35: =SUM(AZ35:BC35) -> 2825.8532 | DS35: =SUM(BD35:BG35) -> 3215.7037 | DT35: =SUM(BH35:BK35) -> 3676.2208 | DU35: =SUM(BL35:BO35) -> 3417.7263 | DV35: =SUM(BP35:BS35) -> 2610.5838 | DW35: =SUM(BT35:BW35) -> 0 | DX35: =SUM(BX35:CA35) -> 0
D36: Consumer Electronics | AP36: =AP478 -> 122.56 | AQ36: =AQ478 -> 167.403 | AR36: =AR478 -> 192.6845 | AS36: =AS478 -> 204.281 | AT36: =AT478 -> 196.4625 | AU36: =AU478 -> 176.5875 | AV36: =AV478 -> 170.64656 | AW36: =AW478 -> 232.4695 | ... BR36: =BR478 -> 573.14902 | CN36: =SUM(AP36:AS36) -> 686.9285 | CO36: =SUM(AT36:AW36) -> 776.16606 | CP36: =SUM(AX36:BA36) -> 781.89498 | CQ36: =SUM(BB36:BE36) -> 1190.3894 | CR36: =SUM(BF36:BI36) -> 1525.4404 | CS36: =SUM(BJ36:BM36) -> 1582.7408 | CT36: =SUM(BN36:BQ36) -> 1635.0614 | CU36: =SUM(BR36:BU36) -> 573.14902 | DP36: =SUM(AR36:AU36) -> 770.0155 | DQ36: =SUM(AV36:AY36) -> 798.5332 | DR36: =SUM(AZ36:BC36) -> 1030.256 | DS36: =SUM(BD36:BG36) -> 1264.6914 | DT36: =SUM(BH36:BK36) -> 1641.7578 | DU36: =SUM(BL36:BO36) -> 1593.6396 | DV36: =SUM(BP36:BS36) -> 1362.914 | DW36: =SUM(BT36:BW36) -> 0 | DX36: =SUM(BX36:CA36) -> 0
D37: Branded | AP37: =AP488 -> 382 | AQ37: =AQ488 -> 569 | AR37: =AR488 -> 467 | AS37: =AS488 -> 400 | AT37: =AT488 -> 425 | AU37: =AU488 -> 546 | AV37: =AV488 -> 441 | AW37: =AW488 -> 382 | ... BR37: =BR488 -> 436.83408 | CN37: =SUM(AP37:AS37) -> 1818 | CO37: =SUM(AT37:AW37) -> 1794 | CP37: =SUM(AX37:BA37) -> 1541.8692 | CQ37: =SUM(BB37:BE37) -> 2001.7142 | CR37: =SUM(BF37:BI37) -> 1964.6997 | CS37: =SUM(BJ37:BM37) -> 1973.4985 | CT37: =SUM(BN37:BQ37) -> 1751.2134 | CU37: =SUM(BR37:BU37) -> 436.83408 | DP37: =SUM(AR37:AU37) -> 1838 | DQ37: =SUM(AV37:AY37) -> 1640 | DR37: =SUM(AZ37:BC37) -> 1795.5972 | DS37: =SUM(BD37:BG37) -> 1951.0124 | DT37: =SUM(BH37:BK37) -> 2034.463 | DU37: =SUM(BL37:BO37) -> 1824.0868 | DV37: =SUM(BP37:BS37) -> 1247.6698 | DW37: =SUM(BT37:BW37) -> 0 | DX37: =SUM(BX37:CA37) -> 0
C38: SanDisk | BQ38: =BQ500*BQ499 -> 741.40741 | BR38: =BR500 -> 1546.8723 | CT38: =SUM(BN38:BQ38) -> 741.40741 | CU38: =SUM(BR38:BU38) -> 1546.8723
B40: Cost of revenues | F40: 398.43 | G40: 494.029 | H40: 448.428 | I40: 404.767 | J40: 384.936 | K40: 504.112 | L40: 513.849 | M40: 466.654 | N40: 499.266 | O40: 605.409 | P40: 583.819 | Q40: 568.585 | R40: 618 | S40: 693.0168 | T40: 626.3 | U40: 647.89325 | V40: 710.4765 | W40: 804.7 | X40: 752.9 | Y40: 780.9 | Z40: 831.6 | AA40: 888.8 | AB40: 910.9 | AC40: 894.1 | AD40: 1046 | AE40: 1173 | AF40: 1188 | AG40: 1162 | AH40: 1443 | AI40: 1690.8 | AJ40: 1634.42 | AK40: 1568 | AL40: 1685 | AM40: 1533 | AN40: 1339 | AO40: 1558 | AP40: =AP41+AP42+AP45+AP48 -> 1693.0511 | AQ40: =AQ41+AQ42+AQ45+AQ48 -> 1931.0599 | AR40: =AR41+AR42+AR45+AR48 -> 1975.1607 | AS40: =AS41+AS42+AS45+AS48 -> 1845.4347 | AT40: =AT41+AT42+AT45+AT48 -> 2000.0287 | AU40: =AU41+AU42+AU45+AU48 -> 1999.4178 | AV40: =AV41+AV42+AV45+AV48 -> 1841.9469 | AW40: =AW41+AW42+AW45+AW48 -> 1933.6861 | ... BP40: =BP41+BP42+BP45+BP48 -> 2025.971 | BQ40: =BQ41+BQ42+BQ45+BQ48+BQ51 -> 2403.1182 | BR40: =BR41+BR42+BR45+BR48+BR51 -> 3115.082 | CE40: =SUM(F40:I40) -> 1745.654 | CF40: =SUM(J40:M40) -> 1869.551 | CG40: =SUM(N40:Q40) -> 2257.079 | CH40: =SUM(R40:U40) -> 2585.2101 | CI40: =SUM(V40:Y40) -> 3048.9765 | CJ40: =SUM(Z40:AC40) -> 3525.4 | CK40: =SUM(AD40:AG40) -> 4569 | CL40: =SUM(AH40:AK40) -> 6336.22 | CM40: =SUM(AL40:AO40) -> 6115 | CN40: =SUM(AP40:AS40) -> 7444.7065 | CO40: =SUM(AT40:AW40) -> 7775.0794 | CP40: =SUM(AX40:BA40) -> 8699.9145 | CQ40: =SUM(BB40:BE40) -> 10838.692 | CR40: =SUM(BF40:BI40) -> 10605.997 | CS40: =SUM(BJ40:BM40) -> 10160.306 | CT40: =SUM(BN40:BQ40) -> 9183.9886 | CU40: =SUM(BR40:BU40) -> 3115.082 | DG40: =SUM(H40:K40) -> 1742.243 | DH40: =SUM(L40:O40) -> 2085.178 | DI40: =SUM(P40:S40) -> 2463.4208 | DJ40: =SUM(T40:W40) -> 2789.3697 | DK40: =SUM(X40:AA40) -> 3254.2 | DL40: =SUM(AB40:AE40) -> 4024 | DM40: =SUM(AF40:AI40) -> 5483.8 | DN40: =SUM(AJ40:AM40) -> 6420.42 | DO40: =SUM(AN40:AQ40) -> 6521.1111 | DP40: =SUM(AR40:AU40) -> 7820.0419 | DQ40: =SUM(AV40:AY40) -> 7274.8197 | DR40: =SUM(AZ40:BC40) -> 10731.417 | DS40: =SUM(BD40:BG40) -> 10753 | DT40: =SUM(BH40:BK40) -> 10603.441 | DU40: =SUM(BL40:BO40) -> 9472.7635 | DV40: =SUM(BP40:BS40) -> 7544.1712 | DW40: =SUM(BT40:BW40) -> 0 | DX40: =SUM(BX40:CA40) -> 0
C41: Other - Media | AP41: =AP28*(1-AP523) -> 37.152099 | AQ41: =AQ28*(1-AQ523) -> 31.956876 | AR41: =AR28*(1-AR523) -> 25.612268 | AS41: =AS28*(1-AS523) -> 36.74111 | AT41: =AT28*(1-AT523) -> 94.298001 | AU41: =AU28*(1-AU523) -> 15.47724 | AV41: =AV28*(1-AV523) -> 8.7769521 | AW41: =AW28*(1-AW523) -> 27.225509 | ... BR41: =BR28*(1-BR523) -> 139.41909 | CR41: =SUM(BF41:BI41) -> 408.37803 | CS41: =SUM(BJ41:BM41) -> 515.96994 | CT41: =SUM(BN41:BQ41) -> 627.35096 | CU41: =SUM(BR41:BU41) -> 139.41909 | DP41: =SUM(AR41:AU41) -> 172.12862 | DQ41: =SUM(AV41:AY41) -> 82.801406 | DR41: =SUM(AZ41:BC41) -> 331.25046
C42: Enterprise | AP42: =AP43+AP44 -> 93.1302 | AQ42: =AQ43+AQ44 -> 121.6285 | AR42: =AR43+AR44 -> 134.292 | AS42: =AS43+AS44 -> 131.65752 | AT42: =AT43+AT44 -> 131.89312 | AU42: =AU43+AU44 -> 127.0475 | AV42: =AV43+AV44 -> 126.09178 | AW42: =AW43+AW44 -> 131.88589 | ... BR42: =BR43+BR44 -> 439.08036 | CN42: =SUM(AP42:AS42) -> 480.70822 | CO42: =SUM(AT42:AW42) -> 516.9183 | CP42: =SUM(AX42:BA42) -> 1087.1188 | CQ42: =SUM(BB42:BE42) -> 2012.4703 | CR42: =SUM(BF42:BI42) -> 2071.0797 | CS42: =SUM(BJ42:BM42) -> 2131.9047 | CT42: =SUM(BN42:BQ42) -> 1883.169 | CU42: =SUM(BR42:BU42) -> 439.08036 | DP42: =SUM(AR42:AU42) -> 524.89015 | DQ42: =SUM(AV42:AY42) -> 502.45148 | DR42: =SUM(AZ42:BC42) -> 1779.7584
D43: Performance | AP43: =AP30*(1-AP525) -> 0 | AQ43: =AQ30*(1-AQ525) -> 0 | AR43: =AR30*(1-AR525) -> 0 | AS43: =AS30*(1-AS525) -> 0 | AT43: =AT30*(1-AT525) -> 0 | AU43: =AU30*(1-AU525) -> 0 | AV43: =AV30*(1-AV525) -> 0 | AW43: =AW30*(1-AW525) -> 0 | ... BR43: =BR30*(1-BR525) -> 171.60012 | CN43: =SUM(AP43:AS43) -> 0 | CO43: =SUM(AT43:AW43) -> 0 | CP43: =SUM(AX43:BA43) -> 378.658 | CQ43: =SUM(BB43:BE43) -> 1079.2999 | CR43: =SUM(BF43:BI43) -> 1063.9812 | CS43: =SUM(BJ43:BM43) -> 1068.4706 | CT43: =SUM(BN43:BQ43) -> 863.86593 | CU43: =SUM(BR43:BU43) -> 171.60012 | DP43: =SUM(AR43:AU43) -> 0 | DQ43: =SUM(AV43:AY43) -> 0 | DR43: =SUM(AZ43:BC43) -> 906.90857
D44: Capacity | AP44: =AP31*(1-AP526) -> 93.1302 | AQ44: =AQ31*(1-AQ526) -> 121.6285 | AR44: =AR31*(1-AR526) -> 134.292 | AS44: =AS31*(1-AS526) -> 131.65752 | AT44: =AT31*(1-AT526) -> 131.89312 | AU44: =AU31*(1-AU526) -> 127.0475 | AV44: =AV31*(1-AV526) -> 126.09178 | AW44: =AW31*(1-AW526) -> 131.88589 | ... BR44: =BR31*(1-BR526) -> 267.48024 | CN44: =SUM(AP44:AS44) -> 480.70822 | CO44: =SUM(AT44:AW44) -> 516.9183 | CP44: =SUM(AX44:BA44) -> 708.46076 | CQ44: =SUM(BB44:BE44) -> 933.17037 | CR44: =SUM(BF44:BI44) -> 1007.0985 | CS44: =SUM(BJ44:BM44) -> 1063.4341 | CT44: =SUM(BN44:BQ44) -> 1019.303 | CU44: =SUM(BR44:BU44) -> 267.48024 | DP44: =SUM(AR44:AU44) -> 524.89015 | DQ44: =SUM(AV44:AY44) -> 502.45148 | DR44: =SUM(AZ44:BC44) -> 872.84982
C45: Compute | AP45: =AP46+AP47 -> 1208.0964 | AQ45: =AQ46+AQ47 -> 1266.1733 | AR45: =AR46+AR47 -> 1349.3294 | AS45: =AS46+AS47 -> 1237.6112 | AT45: =AT46+AT47 -> 1305.2548 | AU45: =AU46+AU47 -> 1324.5937 | AV45: =AV46+AV47 -> 1247.2121 | AW45: =AW46+AW47 -> 1309.9903 | ... BR45: =BR46+BR47 -> 902.3643 | CN45: =SUM(AP45:AS45) -> 5061.2104 | CO45: =SUM(AT45:AW45) -> 5187.0509 | CP45: =SUM(AX45:BA45) -> 5859.8725 | CQ45: =SUM(BB45:BE45) -> 6225.6753 | CR45: =SUM(BF45:BI45) -> 5693.79 | CS45: =SUM(BJ45:BM45) -> 5011.2741 | CT45: =SUM(BN45:BQ45) -> 3772.7545 | CU45: =SUM(BR45:BU45) -> 902.3643 | DP45: =SUM(AR45:AU45) -> 5216.7892 | DQ45: =SUM(AV45:AY45) -> 4906.7396 | DR45: =SUM(AZ45:BC45) -> 6701.7231
D46: Mobile | AP46: =AP33*(1-AP528) -> 581.02531 | AQ46: =AQ33*(1-AQ528) -> 615.58185 | AR46: =AR33*(1-AR528) -> 605.37312 | AS46: =AS33*(1-AS528) -> 569.71382 | AT46: =AT33*(1-AT528) -> 583.99731 | AU46: =AU33*(1-AU528) -> 616.34171 | AV46: =AV33*(1-AV528) -> 563.4844 | AW46: =AW33*(1-AW528) -> 570.42912 | ... BR46: =BR33*(1-BR528) -> 561.37808 | CN46: =SUM(AP46:AS46) -> 2371.6941 | CO46: =SUM(AT46:AW46) -> 2334.2525 | CP46: =SUM(AX46:BA46) -> 3180.897 | CQ46: =SUM(BB46:BE46) -> 3637.3236 | CR46: =SUM(BF46:BI46) -> 3342.0797 | CS46: =SUM(BJ46:BM46) -> 2972.1738 | CT46: =SUM(BN46:BQ46) -> 2169.7558 | CU46: =SUM(BR46:BU46) -> 561.37808 | DP46: =SUM(AR46:AU46) -> 2375.426 | DQ46: =SUM(AV46:AY46) -> 2254.243 | DR46: =SUM(AZ46:BC46) -> 3937.6188
D47: Desktop | AP47: =AP34*(1-AP529) -> 627.07114 | AQ47: =AQ34*(1-AQ529) -> 650.59142 | AR47: =AR34*(1-AR529) -> 743.9563 | AS47: =AS34*(1-AS529) -> 667.89742 | AT47: =AT34*(1-AT529) -> 721.25748 | AU47: =AU34*(1-AU529) -> 708.252 | AV47: =AV34*(1-AV529) -> 683.7277 | AW47: =AW34*(1-AW529) -> 739.56116 | ... BR47: =BR34*(1-BR529) -> 340.98622 | CN47: =SUM(AP47:AS47) -> 2689.5163 | CO47: =SUM(AT47:AW47) -> 2852.7983 | CP47: =SUM(AX47:BA47) -> 2678.9755 | CQ47: =SUM(BB47:BE47) -> 2588.3517 | CR47: =SUM(BF47:BI47) -> 2351.7103 | CS47: =SUM(BJ47:BM47) -> 2039.1002 | CT47: =SUM(BN47:BQ47) -> 1602.9986 | CU47: =SUM(BR47:BU47) -> 340.98622 | DP47: =SUM(AR47:AU47) -> 2841.3632 | DQ47: =SUM(AV47:AY47) -> 2652.4965 | DR47: =SUM(AZ47:BC47) -> 2764.1043
C48: Non-Compute | AP48: =AP49+AP50 -> 354.6724 | AQ48: =AQ49+AQ50 -> 511.30128 | AR48: =AR49+AR50 -> 465.92706 | AS48: =AS49+AS50 -> 439.4248 | AT48: =AT49+AT50 -> 468.58275 | AU48: =AU49+AU50 -> 532.29938 | AV48: =AV49+AV50 -> 459.86604 | AW48: =AW49+AW50 -> 464.58438 | ... BR48: =BR49+BR50 -> 726.76949 | CN48: =SUM(AP48:AS48) -> 1771.3255 | CO48: =SUM(AT48:AW48) -> 1925.3326 | CP48: =SUM(AX48:BA48) -> 1593.4012 | CQ48: =SUM(BB48:BE48) -> 2222.4113 | CR48: =SUM(BF48:BI48) -> 2432.7491 | CS48: =SUM(BJ48:BM48) -> 2501.1575 | CT48: =SUM(BN48:BQ48) -> 2454.3882 | CU48: =SUM(BR48:BU48) -> 726.76949 | DP48: =SUM(AR48:AU48) -> 1906.234 | DQ48: =SUM(AV48:AY48) -> 1782.8272 | DR48: =SUM(AZ48:BC48) -> 1918.6856
...

Sheet BS
B4: =IS!$B$5 -> Western Digital
B5: Balance Sheet
B7: ($ in millions) | F7: 2001A | J7: 2002A | N7: 2003A | R7: 2004A | V7: 2005A | Z7: 2006A | AD7: 2007A | AH7: 2008A | AL7: 2009A | AP7: 2010A | AT7: F2011A | AX7: F2012A | BB7: F2013A | BF7: F2014A | BJ7: F2015A | BN7: F2016A | BR7: F2017A | BV7: F2018E | BZ7: F2019E | CR7: Fiscal Year
F8: 36776 | G8: 36867 | H8: 36956 | I8: 37048 | J8: 37141 | K8: 37232 | L8: 37321 | M8: 37413 | N8: 37506 | O8: 37597 | P8: 37686 | Q8: 37778 | R8: 37871 | S8: 37962 | T8: 38052 | U8: 38144 | V8: 38237 | W8: 38328 | X8: 38417 | Y8: 38509 | Z8: 38602 | AA8: 38693 | AB8: 38782 | AC8: 38874 | AD8: 38967 | AE8: 39058 | AF8: 39147 | AG8: 39239 | AH8: 39331 | AI8: 39422 | AJ8: 39513 | AK8: 39605 | AL8: 39697 | AM8: 39788 | AN8: 39878 | AO8: 39970 | AP8: 40062 | AQ8: 40153 | AR8: 40243 | AS8: 40335 | AT8: 40451 | AU8: 40542 | AV8: 40632 | AW8: 40724 | AX8: 40816 | AY8: 40907 | AZ8: 40998 | BA8: 41090 | BB8: 41182 | BC8: 41273 | BD8: 41363 | BE8: 41455 | BF8: 41547 | BG8: 41638 | BH8: 41728 | BI8: 41820 | BJ8: 41912 | BK8: 42003 | BL8: 42093 | BM8: 42185 | BN8: 42277 | BO8: 42368 | BP8: 42459 | BQ8: 42551 | BR8: 42643 | BS8: 42734 | BT8: 42824 | BU8: 42916 | BV8: 43008 | BW8: 43100 | BX8: 43190 | BY8: 43281 | BZ8: 43373 | CA8: 43465 | CB8: 43555 | CC8: 43646 | CE8: 2001A | CF8: 2002A | CG8: 2003A | CH8: 2004A | CI8: 2005A | CJ8: 2006A | CK8: 2007A | CL8: 2008A | CM8: 2009A | CN8: 2010A | CO8: 2011A | CP8: 2012A | CQ8: 2013A | CR8: 2014A | CS8: 2015A | CT8: 2016A | CU8: 2017A | CV8: 2018E | CW8: 2019E | CX8: 2020E | CY8: 2021E | CZ8: 2022E | DA8: 2023E | DB8: 2024E | DC8: 2025E
