Workbook
Name _1H_96: "assumpt"
Name _scenchg_count: 1
Name aaaa: {13}
Name aaaa: {13}
Name aaaaaa: {"BMC"}
Name aaaaaa: {"BMC"}
Name AdditionalInstructions: IndexInformation!$B$42
Name Address: ImportantDisclosures!$A$2:$A$2
Name AllTables: {1}
Name AllTables: {1}
Name AllTables: {9}
Name ANA: ModPubIndex!$A$7
Name asfadsg: {1}
Name asfadsg: {1}
Name asfadsg: {1}
Name Authors: ImportantDisclosures!$A$7
Name Authors: IndexInformation!$B$18
Name AxesFormat: 'debt schedule'!AxesFormat
Name biovailvaluation: {"Client Name or Project Name"}
Name biovailvaluation: {"Client Name or Project Name"}
Name BRO: ModPubIndex!$A$1
Name Cell_Errors: OFFSET('debt schedule'!File_Name,0,5,1,1)
Name CF_OP_GR: "'=BackSheet!$D$239:$AG$239"
Name CF_PR_DV: "'=BackSheet!$D$241:$AG$241"
Name chart_1: "Chart 1"
Name chart_2: "Chart 2"
Name Choices_Wrapper: 'debt schedule'!Choices_Wrapper
Name Company_Name: "Project Knit"
Name converting: {"Client Name or Project Name"}
Name converting: {"Client Name or Project Name"}
Name CopyrightStamp: ImportantDisclosures!$A$27
Name COU: ModPubIndex!$A$5
Name CQEnd: IndexInformation!$B$31
Name Currency: IndexInformation!$B$24
Name Currency_ISOcode: OPEB!$AQ$174
Name Currency_ISOcode: Pension!$AQ$186
Name currentFY: Pension!$AZ$18
Name CurrentStockPrice: IndexInformation!$B$23
Name CurrQtrEPS: IndexInformation!$B$29
Name CurrYearEPS: IndexInformation!$B$11
Name CurrYearTotalRevenue: IndexInformation!$B$10
Name CurrYearTotalRevenueActual: IndexInformation!$B$32
Name CUSIP: IndexInformation!$B$20
Name CYEnd: IndexInformation!$B$30
Name darvon: {"Client Name or Project Name"}
Name darvon: {"Client Name or Project Name"}
Name Date: ImportantDisclosures!$A$8
Name DB: "WIREUK"
Name dd: {"Client Name or Project Name"}
Name dd: {"Client Name or Project Name"}
Name ddd: {13}
Name ddd: {13}
Name ddddd: {"BMC"}
Name ddddd: {"BMC"}
Name Deleted: IndexInformation!$B$27
Name Description: IndexInformation!$B$7
Name DEVELOPMENT: 5
Name dfasd: {"Project PPaids"}
Name dfasd: {"Project PPaids"}
Name Discipline: IndexInformation!$B$3

Sheet ImportantDisclosures
A2: 1585 Broadway
A3: New York, NY 10036-8293
A4: United States
A5: Tel: +1 (1)212 761 4000
A7: Authors: Piyush Sood, Lynn Bernabei, Serena Rocha Calejon
A8: Date: 17 Apr 2018
A10: Ticker: X.N
A11: Stock Rating: Overweight
A12: Industry: Steel
A13: Industry View: In-Line
A14: Price as of 17 Apr 2018: 35.75
A15: Target Price: 44
... A129: Equal-weight and Not-Rated to hold and Underweight to sell recommendations, respectively.
B131: Coverage Universe | D131: Investment Banking Clients (IBC) | G131: Other Material Investment Services Clients (MISC)
A132: Stock Rating Category | B132: Count | C132: % of Total | D132: Count | E132: % of Total IBC | F132: % of Rating Category | G132: Count | H132: % of Total Other MISC
A133: Overweight/Buy | B133: 1189 | C133: 0.38 | D133: 315 | E133: 0.41 | F133: 0.26 | G133: 555 | H133: 0.39
A134: Equal-weight/Hold | B134: 1355 | C134: 0.43 | D134: 364 | E134: 0.47 | F134: 0.27 | G134: 644 | H134: 0.45
A135: Not-Rated/Hold | B135: 53 | C135: 0.02 | D135: 4 | E135: 0.01 | F135: 0.08 | G135: 7 | H135: 0
A136: Underweight/Sell | B136: 545 | C136: 0.17 | D136: 84 | E136: 0.11 | F136: 0.15 | G136: 214 | H136: 0.15
A137: Total | B137: 3142 | D137: 767 | G137: 1420
A139: Data include common stock and ADRs currently assigned ratings. Investment Banking Clients are companies
A140: from whom Morgan Stanley received investment banking compensation in the last 12 months. Due to rounding
A141: off of decimals, the percentages provided in the "% of total" column may not add up to exactly 100
A142: percent.
A144: Analyst Stock Ratings
A146: Overweight (O). The stock's total return is expected to exceed the average total return of the analyst's
A147: industry (or industry team's) coverage universe, on a risk-adjusted basis, over the next 12-18 months.
A149: Equal-weight (E). The stock's total return is expected to be in line with the average total return of
A150: the analyst's industry (or industry team's) coverage universe, on a risk-adjusted basis, over the next
A151: 12-18 months.
A153: Not-Rated (NR). Currently the analyst does not have adequate conviction about the stock's total return
A154: relative to the average total return of the analyst's industry (or industry team's) coverage universe,
... A400: © Copyright 2018 Morgan Stanley

Sheet Summary
B2: US Steel Corp.
B3: Summary Information
B5: Key Assumptions | J5: Income Statement
B6: Year End December | C6: 2014 | D6: 2015 | E6: 2016 | F6: 2017 | G6: 2018e | H6: 2019e | J6: Year End December (US$M) | K6: =C6 -> 2014 | L6: =D6 -> 2015 | M6: =E6 -> 2016 | N6: =F6 -> 2017 | O6: =G6 -> 2018e | P6: =H6 -> 2019e
B7: Realizations, $/t | J7: Sales | K7: =Financials!$BM$14 -> 17507 | L7: =Financials!$BR$14 -> 11574 | M7: =Financials!$BW$14 -> 10261 | N7: =Financials!$CB$14 -> 12250 | O7: =Financials!$CG$14 -> 14096.401 | P7: =Financials!$CL$14 -> 15045.003
B8: Flat Rolled | C8: =Operations!$BM$51 -> 771.57902 | D8: =Operations!$BR$51 -> 694.76614 | E8: =Operations!$BW$51 -> 665.14959 | F8: =Operations!$CB$51 -> 726.63052 | G8: =Operations!$CG$51 -> 791.74194 | H8: =Operations!$CL$51 -> 818.44807 | J8: COGS | K8: =Financials!$BM$18 -> 15461 | L8: =Financials!$BR$18 -> 10916 | M8: =Financials!$BW$18 -> 9398 | N8: =Financials!$CB$18 -> 10744 | O8: =Financials!$CG$18 -> 11894.968 | P8: =Financials!$CL$18 -> 12623.285
B9: Tubular | C9: =Operations!$BM$116 -> 1538.1009 | D9: =Operations!$BR$116 -> 1464.3491 | E9: =Operations!$BW$116 -> 1070.7325 | F9: =Operations!$CB$116 -> 1306.4477 | G9: =Operations!$CG$116 -> 1584.0876 | H9: =Operations!$CL$116 -> 1584.0876 | J9: D&A | K9: =Financials!$BM$25 -> 627 | L9: =Financials!$BR$25 -> 547 | M9: =Financials!$BW$25 -> 507 | N9: =Financials!$CB$25 -> 501 | O9: =Financials!$CG$25 -> 495 | P9: =Financials!$CL$25 -> 495
B10: USSE | C10: =Operations!$BM$155 -> 668 | D10: =Operations!$BR$155 -> 514 | E10: =Operations!$BW$155 -> 482.5 | F10: =Operations!$CB$155 -> 621.75 | G10: =Operations!$CG$155 -> 719.38232 | H10: =Operations!$CL$155 -> 719.38232 | J10: SG&A | K10: =Financials!$BM$23 -> 523 | L10: =Financials!$BR$23 -> 415 | M10: =Financials!$BW$23 -> 255 | N10: =Financials!$CB$23 -> 375 | O10: =Financials!$CG$23 -> 422.89203 | P10: =Financials!$CL$23 -> 451.3501
B11: Blended | C11: =Operations!$BM$196 -> 817.16207 | D11: =Operations!$BR$196 -> 672.34909 | E11: =Operations!$BW$196 -> 621.19891 | F11: =Operations!$CB$196 -> 721.22399 | G11: =Operations!$CG$196 -> 809.66506 | H11: =Operations!$CL$196 -> 827.98195 | J11: EBITDA | K11: =Financials!$BM$101 -> 1678 | L11: =Financials!$BR$101 -> 202 | M11: =Financials!$BW$101 -> 510 | N11: =Financials!$CB$101 -> 1087 | O11: =Financials!$CG$101 -> 1738.5413 | P11: =Financials!$CL$101 -> 1930.3678
J12: EBIT | K12: =Financials!$BM$39 -> 1051 | L12: =Financials!$BR$39 -> -345 | M12: =Financials!$BW$39 -> 3 | N12: =Financials!$CB$39 -> 586 | O12: =Financials!$CG$39 -> 1243.5413 | P12: =Financials!$CL$39 -> 1435.3678
B13: Shipments, kt | J13: Pre-Tax Income | K13: =Financials!$BM$48 -> 808 | L13: =Financials!$BR$48 -> -566 | M13: =Financials!$BW$48 -> -224 | N13: =Financials!$CB$48 -> 336 | O13: =Financials!$CG$48 -> 972.27649 | P13: =Financials!$CL$48 -> 1167.1162
B14: Flat Rolled | C14: =Operations!$BM$34 -> 13908 | D14: =Operations!$BR$34 -> 10596 | E14: =Operations!$BW$34 -> 10094 | F14: =Operations!$CB$34 -> 9887 | G14: =Operations!$CG$34 -> 10483.45 | H14: =Operations!$CL$34 -> 11255.274 | J14: Tax | K14: =Financials!$BM$51 -> 145 | L14: =Financials!$BR$51 -> 183 | M14: =Financials!$BW$51 -> 24 | N14: =Financials!$CB$51 -> -5 | O14: =Financials!$CG$51 -> 77.880788 | P14: =Financials!$CL$51 -> 85.039629
B15: Tubular | C15: =Operations!$BM$100 -> 1744 | D15: =Operations!$BR$100 -> 593 | E15: =Operations!$BW$100 -> 400 | F15: =Operations!$CB$100 -> 688 | G15: =Operations!$CG$100 -> 777.15 | H15: =Operations!$CL$100 -> 800.4645 | J15: Minority Interest and Others | K15: =Financials!$BM$54 -> 0 | L15: =Financials!$BR$54 -> 0 | M15: =Financials!$BW$54 -> 0 | N15: =Financials!$CB$54 -> 0 | O15: =Financials!$CG$54 -> 0 | P15: =Financials!$CL$54 -> 0
B16: USSE | C16: =Operations!$BM$141 -> 4179 | D16: =Operations!$BR$141 -> 4466 | E16: =Operations!$BW$141 -> 4495 | F16: =Operations!$CB$141 -> 4585 | G16: =Operations!$CG$141 -> 4585 | H16: =Operations!$CL$141 -> 4585 | J16: Adj. Net Income | K16: =Financials!$BM$59 -> 663 | L16: =Financials!$BR$59 -> -749 | M16: =Financials!$BW$59 -> -248 | N16: =Financials!$CB$59 -> 341 | O16: =Financials!$CG$59 -> 894.3957 | P16: =Financials!$CL$59 -> 1082.0766
B17: Total | C17: =Operations!$BM$195 -> 19831 | D17: =Operations!$BR$195 -> 15655 | E17: =Operations!$BW$195 -> 14989 | F17: =Operations!$CB$195 -> 15160 | G17: =Operations!$CG$195 -> 15845.6 | H17: =Operations!$CL$195 -> 16640.738 | J17: Adj. EPS | K17: =Financials!$BM$64 -> 4.4608261 | L17: =Financials!$BR$64 -> -5.1268361 | M17: =Financials!$BW$64 -> -1.5834706 | N17: =Financials!$CB$64 -> 1.9292632 | O17: =Financials!$CG$64 -> 5.1109942 | P17: =Financials!$CL$64 -> 6.1834904
B18: NA Capacity Utilization | C18: =Operations!$BM$37 -> 0.79852905 | D18: =Operations!$BR$37 -> 0.60374361 | E18: =Operations!$BW$37 -> 0.62967381 | F18: =Operations!$CB$37 -> 0.63738308 | G18: =Operations!$CG$37 -> 0.67834088 | H18: =Operations!$CL$37 -> 0.72828243 | J18: Reported EPS | K18: =Financials!$BM$94 -> 0.68628094 | L18: =Financials!$BR$94 -> -11.239339 | M18: =Financials!$BW$94 -> -2.8093833 | N18: =Financials!$CB$94 -> 2.1895157 | O18: =Financials!$CG$94 -> 5.1109942 | P18: =Financials!$CL$94 -> 6.1834904
B20: Segment EBIT | J20: Balance Sheet
B21: =+J6 -> Year End December (US$M) | C21: =+C6 -> 2014 | D21: =+D6 -> 2015 | E21: =+E6 -> 2016 | F21: =+F6 -> 2017 | G21: =+G6 -> 2018e | H21: =+H6 -> 2019e | J21: =+$J$6 -> Year End December (US$M) | K21: =+K6 -> 2014 | L21: =+L6 -> 2015 | M21: =+M6 -> 2016 | N21: =+N6 -> 2017 | O21: =+O6 -> 2018e | P21: =+P6 -> 2019e
B22: Flat rolled Segment- Steel | C22: =Financials!$BM$32 -> 709 | D22: =Financials!$BR$32 -> -237 | E22: =Financials!$BW$32 -> -3 | F22: =Financials!$CB$32 -> 380 | G22: =Financials!$CG$32 -> 762.3697 | H22: =Financials!$CL$32 -> 925.0848 | J22: Cash and Equivalents | K22: =Financials!$BM$121 -> 1354 | L22: =Financials!$BR$121 -> 755 | M22: =Financials!$BW$121 -> 1515 | N22: =Financials!$CB$121 -> 1553 | O22: =Financials!$CG$121 -> 1799.9354 | P22: =Financials!$CL$121 -> 2142.9895
B23: Tubular | C23: =Financials!$BM$34 -> 261 | D23: =Financials!$BR$34 -> -179 | E23: =Financials!$BW$34 -> -304 | F23: =Financials!$CB$34 -> -99 | G23: =Financials!$CG$34 -> 64.310698 | H23: =Financials!$CL$34 -> 59.332384 | J23: Receivables | K23: =+Financials!BM122+Financials!BM123 -> 1927 | L23: =+Financials!BR122+Financials!BR123 -> 1063 | M23: =+Financials!BW122+Financials!BW123 -> 1248 | N23: =+Financials!CB122+Financials!CB123 -> 1379 | O23: =+Financials!CG122+Financials!CG123 -> 1697.6643 | P23: =+Financials!CL122+Financials!CL123 -> 1876.2989
B24: USSE | C24: =Financials!$BM$33 -> 116 | D24: =Financials!$BR$33 -> 81 | E24: =Financials!$BW$33 -> 185 | F24: =Financials!$CB$33 -> 327 | G24: =Financials!$CG$33 -> 370.8609 | H24: =Financials!$CL$33 -> 404.95061 | J24: Inventories | K24: =Financials!$BM$124 -> 2496 | L24: =Financials!$BR$124 -> 2074 | M24: =Financials!$BW$124 -> 1573 | N24: =Financials!$CB$124 -> 1738 | O24: =Financials!$CG$124 -> 2132.5494 | P24: =Financials!$CL$124 -> 2118.039
B25: Others | C25: =+Financials!BM35+Financials!BM36+Financials!BM37 -> -35 | D25: =+Financials!BR35+Financials!BR36+Financials!BR37 -> -10 | E25: =+Financials!BW35+Financials!BW36+Financials!BW37 -> 125 | F25: =+Financials!CB35+Financials!CB36+Financials!CB37 -> -22 | G25: =+Financials!CG35+Financials!CG36+Financials!CG37 -> 46 | H25: =+Financials!CL35+Financials!CL36+Financials!CL37 -> 46 | J25: Goodwill and Intangibles | K25: =Financials!BM134+Financials!BM135 -> 204 | L25: =Financials!BR134+Financials!BR135 -> 196 | M25: =Financials!BW134+Financials!BW135 -> 175 | N25: =Financials!CB134+Financials!CB135 -> 167 | O25: =Financials!CG134+Financials!CG135 -> 167 | P25: =Financials!CL134+Financials!CL135 -> 167
J26: Net PP&E | K26: =Financials!$BM$132 -> 4574 | L26: =Financials!$BR$132 -> 4411 | M26: =Financials!$BW$132 -> 3979 | N26: =Financials!$CB$132 -> 4280 | O26: =Financials!$CG$132 -> 4635 | P26: =Financials!$CL$132 -> 5290
B27: Quarterly Data | J27: Deferred Tax Asset | K27: =Financials!BM125+Financials!BM136 -> 648 | L27: =Financials!BR125+Financials!BR136 -> 15 | M27: =Financials!BW125+Financials!BW136 -> 6 | N27: =Financials!CB125+Financials!CB136 -> 0 | O27: =Financials!CG125+Financials!CG136 -> 0 | P27: =Financials!CL125+Financials!CL136 -> 0
B28: =+B6 -> Year End December | C28: =ROUNDUP(MONTH(C60)/3,0)&"Q"&(YEAR(C60)-2000) -> 3Q17 | D28: =ROUNDUP(MONTH(D60)/3,0)&"Q"&(YEAR(D60)-2000) -> 4Q17 | E28: =ROUNDUP(MONTH(E60)/3,0)&"Q"&(YEAR(E60)-2000)&"e" -> 1Q18e | F28: =ROUNDUP(MONTH(F60)/3,0)&"Q"&(YEAR(F60)-2000)&"e" -> 2Q18e | G28: =ROUNDUP(MONTH(G60)/3,0)&"Q"&(YEAR(G60)-2000)&"e" -> 3Q18e | H28: =ROUNDUP(MONTH(H60)/3,0)&"Q"&(YEAR(H60)-2000)&"e" -> 4Q18e | J28: Other Assets | K28: =K29-SUM(K22:K27) -> 1111 | L28: =L29-SUM(L22:L27) -> 676 | M28: =M29-SUM(M22:M27) -> 664 | N28: =N29-SUM(N22:N27) -> 745 | O28: =O29-SUM(O22:O27) -> 745 | P28: =P29-SUM(P22:P27) -> 745
B29: Quarterly Operating Data | J29: Total Assets | K29: =Financials!$BM$139 -> 12314 | L29: =Financials!$BR$139 -> 9190 | M29: =Financials!$BW$139 -> 9160 | N29: =Financials!$CB$139 -> 9862 | O29: =Financials!$CG$139 -> 11177.149 | P29: =Financials!$CL$139 -> 12339.327
B30: Blended Realization | C30: =Operations!BZ196 -> 737.34194 | D30: =Operations!CA196 -> 722.5213 | E30: =Operations!CC196 -> 764.05569 | F30: =Operations!CD196 -> 818.65936 | G30: =Operations!CE196 -> 834.13264 | H30: =Operations!CF196 -> 816.83856
B31: Total Shipments | C31: =Operations!BZ195 -> 3796 | D31: =Operations!CA195 -> 3873 | E31: =Operations!CC195 -> 3688.24 | F31: =Operations!CD195 -> 3894.97 | G31: =Operations!CE195 -> 4087.4 | H31: =Operations!CF195 -> 4174.99 | J31: Short Term debt | K31: =Financials!$BM$149 -> 378 | L31: =Financials!$BR$149 -> 45 | M31: =Financials!$BW$149 -> 50 | N31: =Financials!$CB$149 -> 3 | O31: =Financials!$CG$149 -> 0 | P31: =Financials!$CL$149 -> 0
B32: NA Capacity Utilization | C32: =Operations!BZ37 -> 0.66 | D32: =Operations!CA37 -> 0.6 | E32: =Operations!CC37 -> 0.62843388 | F32: =Operations!CD37 -> 0.65274518 | G32: =Operations!CE37 -> 0.72429176 | H32: =Operations!CF37 -> 0.70789271 | J32: Long Term debt | K32: =Financials!$BM$154 -> 3120 | L32: =Financials!$BR$154 -> 3116 | M32: =Financials!$BW$154 -> 2981 | N32: =Financials!$CB$154 -> 2700 | O32: =Financials!$CG$154 -> 2703 | P32: =Financials!$CL$154 -> 2703
B33: Quarterly Financial Data | J33: Payables | K33: =Financials!BM142+Financials!BM143 -> 2002 | L33: =Financials!BR142+Financials!BR143 -> 1493 | M33: =Financials!BW142+Financials!BW143 -> 1668 | N33: =Financials!CB142+Financials!CB143 -> 2170 | O33: =Financials!CG142+Financials!CG143 -> 2492.5651 | P33: =Financials!CL142+Financials!CL143 -> 2475.0856
B34: Sales | C34: =Financials!BZ14 -> 3248 | D34: =Financials!CA14 -> 3133 | E34: =Financials!CC14 -> 3135.5207 | F34: =Financials!CD14 -> 3506.1536 | G34: =Financials!CE14 -> 3726.9338 | H34: =Financials!CF14 -> 3727.7928 | J34: Deferred Tax Liability | K34: =+Financials!BM147+Financials!BM155 -> 0 | L34: =+Financials!BR147+Financials!BR155 -> 29 | M34: =+Financials!BW147+Financials!BW155 -> 28 | N34: =+Financials!CB147+Financials!CB155 -> 6 | O34: =+Financials!CG147+Financials!CG155 -> 52.691575 | P34: =+Financials!CL147+Financials!CL155 -> 99.70986
B35: EBITDA | C35: =Financials!BZ101 -> 342 | D35: =Financials!CA101 -> 309 | E35: =Financials!CC101 -> 259.78647 | F35: =Financials!CD101 -> 460.24419 | G35: =Financials!CE101 -> 542.18315 | H35: =Financials!CF101 -> 476.32747 | J35: Other Liabilities | K35: =K37-K36-SUM(K31:K34) -> 3015 | L35: =L37-L36-SUM(L31:L34) -> 2071 | M35: =M37-M36-SUM(M31:M34) -> 2159 | N35: =N37-N36-SUM(N31:N34) -> 1663 | O35: =O37-O36-SUM(O31:O34) -> 1589.5955 | P35: =P37-P36-SUM(P31:P34) -> 1515.2575
B36: EBIT | C36: =Financials!BZ98 -> 224 | D36: =Financials!CA98 -> 184 | E36: =Financials!CC98 -> 127.78647 | F36: =Financials!CD98 -> 336.24419 | G36: =Financials!CE98 -> 418.18315 | H36: =Financials!CF98 -> 361.32747 | J36: Shareholders' Equity | K36: =Financials!$BM$172-Financials!$BM$170 -> 3799 | L36: =Financials!$BR$172-Financials!$BR$170 -> 2436 | M36: =Financials!$BW$172-Financials!$BW$170 -> 2274 | N36: =Financials!$CB$172-Financials!$CB$170 -> 3320 | O36: =Financials!$CG$172-Financials!$CG$170 -> 4339.2968 | P36: =Financials!$CL$172-Financials!$CL$170 -> 5546.2745
B37: Adj. EPS | C37: =Financials!BZ64 -> 0.912264 | D37: =Financials!CA64 -> 0.76745105 | E37: =Financials!CC64 -> 0.22229559 | F37: =Financials!CD64 -> 1.4474911 | G37: =Financials!CE64 -> 1.9108477 | H37: =Financials!CF64 -> 1.5303598 | J37: Liabilities & Equity | K37: =K29 -> 12314 | L37: =L29 -> 9190 | M37: =M29 -> 9160 | N37: =N29 -> 9862 | O37: =O29 -> 11177.149 | P37: =P29 -> 12339.327
B38: Reported EPS | C38: =Financials!BZ94 -> 0.8329367 | D38: =Financials!CA94 -> 0.89724056 | E38: =Financials!CC94 -> 0.22229559 | F38: =Financials!CD94 -> 1.4474911 | G38: =Financials!CE94 -> 1.9108477 | H38: =Financials!CF94 -> 1.5303598
J39: Cashflow Statement
B40: Important Ratios | J40: =+$J$6 -> Year End December (US$M) | K40: =+K21 -> 2014 | L40: =+L21 -> 2015 | M40: =+M21 -> 2016 | N40: =+N21 -> 2017 | O40: =+O21 -> 2018e | P40: =+P21 -> 2019e
B41: =+$B$28 -> Year End December | C41: =+C21 -> 2014 | D41: =+D21 -> 2015 | E41: =+E21 -> 2016 | F41: =+F21 -> 2017 | G41: =+G21 -> 2018e | H41: =+H21 -> 2019e | J41: Net Income | K41: =Financials!$BM$217 -> 102 | L41: =Financials!$BR$217 -> -1642 | M41: =Financials!$BW$217 -> -440 | N41: =Financials!$CB$217 -> 387 | O41: =Financials!$CG$217 -> 894.3957 | P41: =Financials!$CL$217 -> 1082.0766
B42: Diluted Shares Out (m) | C42: =Financials!$BM$67 -> 148.62718 | D42: =Financials!$BR$67 -> 146.094 | E42: =Financials!$BW$67 -> 156.618 | F42: =Financials!$CB$67 -> 176.75142 | G42: =Financials!$CG$67 -> 174.99446 | H42: =Financials!$CL$67 -> 174.99446 | J42: D&A | K42: =K9 -> 627 | L42: =L9 -> 547 | M42: =M9 -> 507 | N42: =N9 -> 501 | O42: =O9 -> 495 | P42: =P9 -> 495
B43: Adj. EPS | C43: =K17 -> 4.4608261 | D43: =L17 -> -5.1268361 | E43: =M17 -> -1.5834706 | F43: =N17 -> 1.9292632 | G43: =O17 -> 5.1109942 | H43: =P17 -> 6.1834904 | J43: Others | K43: =K45-K44-K42-K41 -> 397 | L43: =L45-L44-L42-L41 -> 897 | M43: =M45-M44-M42-M41 -> 54 | N43: =N45-N44-N42-N41 -> -106 | O43: =O45-O44-O42-O41 -> 133.18707 | P43: =P45-P44-P42-P41 -> 132.58033
...

Sheet Operations
A1: =Financials!A2 -> US Steel Corporation
A2: Key Model Drivers
A3: (Input Fields in Blue)
D4: =Operations!D25 -> 2001 | E4: =Operations!E25 -> 2002 | F4: =Operations!F25 -> 1Q | G4: =Operations!G25 -> 2Q | H4: =Operations!H25 -> 3Q | I4: =Operations!I25 -> 4Q | J4: 2003 | K4: 1Q | L4: 2Q | M4: 3Q | N4: 4Q | O4: 2004 | P4: 1Q | Q4: 2Q | R4: 3Q | S4: 4Q | T4: 2005 | U4: 1Q | V4: 2Q | W4: 3Q | X4: 4Q | Y4: 2006 | Z4: 1Q | AA4: 2Q | AB4: 3Q | AC4: 4Q | AD4: 2007 | AE4: 1Q | AF4: 2Q | AG4: 3Q | AH4: 4Q | AI4: 2008 | AJ4: 1Q | AK4: 2Q | AL4: 3Q | AM4: 4Q | AN4: 2009 | AO4: 1Q | AP4: 2Q | AQ4: 3Q | AR4: 4Q | AS4: 2010 | AT4: 1Q | AU4: 2Q | AV4: 3Q | AW4: 4Q | AX4: 2011 | AY4: 1Q | AZ4: 2Q | BA4: 3Q | BB4: 4Q | BC4: 2012 | BD4: 1Q | BE4: 2Q | BF4: 3Q | BG4: 4Q | BH4: 2013 | BI4: 1Q | BJ4: 2Q | BK4: 3Q | BL4: 4Q | BM4: 2014 | BN4: 1Q | BO4: 2Q | BP4: 3Q | BQ4: 4Q | BR4: 2015 | BS4: 1Q | BT4: 2Q | BU4: 3Q | BV4: 4Q | BW4: 2016 | BX4: 1Q | BY4: 2Q | BZ4: 3Q | CA4: 4Q | CB4: 2017 | CC4: 1QE | CD4: 2QE | CE4: 3QE | CF4: 4QE | CG4: 2018E | CH4: 1QE | CI4: 2QE | CJ4: 3QE | CK4: 4QE | CL4: 2019E | CM4: 1QE | CN4: 2QE | CO4: 3QE | CP4: 4QE | CQ4: 2020E
AE5: 39538 | AF5: 39629 | AG5: 39721 | AH5: 39813 | AI5: FY8 | AJ5: 39903 | AK5: 39994 | AL5: 40086 | AM5: 40178 | AN5: FY9 | AO5: 40268 | AP5: 40359 | AQ5: 40451 | AR5: 40543 | AS5: FY10 | AT5: 40633 | AU5: 40724 | AV5: 40816 | AW5: 40908 | AX5: FY11 | AY5: 40999 | AZ5: 41090 | BA5: 41182 | BB5: 41274 | BC5: FY12 | BD5: 41364 | BE5: 41455 | BF5: 41547 | BG5: 41639 | BH5: FY13 | BI5: 41729 | BJ5: 41820 | BK5: 41912 | BL5: 42004 | BM5: FY14 | BN5: 42094 | BO5: 42185 | BP5: 42277 | BQ5: 42369 | BR5: FY15 | BS5: 42460 | BT5: 42551 | BU5: 42643 | BV5: 42735 | BW5: FY16 | BX5: 42825 | BY5: 42916 | BZ5: 43008 | CA5: 43100 | CB5: FY17 | CC5: 43190 | CD5: 43281 | CE5: 43373 | CF5: 43465 | CG5: FY18 | CH5: 43555 | CI5: 43646 | CJ5: 43738 | CK5: 43830 | CL5: FY19 | CM5: 43921 | CN5: 44012 | CO5: 44104 | CP5: 44196 | CQ5: FY20
A6: Price Assumptions
B7: Flat-Rolled Segment ($ per ton)
C8: Hot-rolled Sheets | J8: 290.5 | K8: 462.33333 | L8: 610 | M8: 703.33333 | N8: 658.33333 | O8: =AVERAGE(K8:N8) -> 608.5 | P8: 631.66667 | Q8: 532.5 | R8: 461.66667 | S8: 550 | T8: =AVERAGE(P8:S8) -> 543.95833 | U8: 550 | V8: 591.66667 | W8: 621.66667 | X8: 563.33333 | Y8: =AVERAGE(U8:X8) -> 581.66667 | Z8: 518.33333 | AA8: 553.33333 | AB8: 516.66667 | AC8: 535 | AD8: =AVERAGE(Z8:AC8) -> 530.83333 | AE8: 691.66667 | AF8: 976.66667 | AG8: 1051.6667 | AH8: 714 | AI8: =AVERAGE(AE8:AH8) -> 858.5 | AJ8: 508.66667 | AK8: 399 | AL8: 491.33333 | AM8: 528 | AN8: =AVERAGE(AJ8:AM8) -> 481.75 | AO8: 592 | AP8: 682 | AQ8: 582.66667 | AR8: 557 | AS8: =AVERAGE(AO8:AR8) -> 603.41667 | AT8: 795.66667 | AU8: 813 | AV8: 687.66782 | AW8: 657.66667 | AX8: =AVERAGE(AT8:AW8) -> 738.50029 | AY8: 720.66667 | AZ8: 660 | BA8: 625.66667 | BB8: 619.99869 | BC8: =AVERAGE(AY8:BB8) -> 656.58301 | BD8: 616.66667 | BE8: 592.33333 | BF8: 643.66667 | BG8: 658.99708 | BH8: =AVERAGE(BD8:BG8) -> 627.91594 | BI8: 654.66667 | BJ8: 671 | BK8: 667.66667 | BL8: 634.33333 | BM8: =AVERAGE(BI8:BL8) -> 656.91667 | BN8: 536.33333 | BO8: 453.66667 | BP8: 459 | BQ8: 387 | BR8: =AVERAGE(BN8:BQ8) -> 459 | BS8: 398.33333 | BT8: 561.66667 | BU8: 592 | BV8: 521 | BW8: =AVERAGE(BS8:BV8) -> 518.25 | BX8: 622.66667 | BY8: 623.5942 | BZ8: 621.41848 | CA8: 618.09489 | CB8: =AVERAGE(BX8:CA8) -> 621.44356 | CC8: 741.07743 | CD8: 885 | CE8: 830 | CF8: 785 | CG8: =AVERAGE(CC8:CF8) -> 810.26936 | CH8: 800 | CI8: 770 | CJ8: 760 | CK8: 715 | CL8: =AVERAGE(CH8:CK8) -> 761.25 | CM8: 660 | CN8: 675 | CO8: 645 | CP8: 645 | CQ8: =AVERAGE(CM8:CP8) -> 656.25
C9: Cold-rolled Sheets | J9: 386.25 | K9: 538.77778 | L9: 696.66667 | M9: 796.66667 | N9: 750 | O9: =AVERAGE(K9:N9) -> 695.52778 | P9: 710 | Q9: 617.5 | R9: 556.66667 | S9: 640 | T9: =AVERAGE(P9:S9) -> 631.04167 | U9: 640 | V9: 685 | W9: 716.66667 | X9: 658.33333 | Y9: =AVERAGE(U9:X9) -> 675 | Z9: 610 | AA9: 628.33333 | AB9: 606.66667 | AC9: 625 | AD9: =AVERAGE(Z9:AC9) -> 617.5 | AE9: 786.66667 | AF9: 1073.3333 | AG9: 1145 | AH9: 806.66667 | AI9: =AVERAGE(AE9:AH9) -> 952.91667 | AJ9: 596 | AK9: 479.66667 | AL9: 599 | AM9: 638.33333 | AN9: =AVERAGE(AJ9:AM9) -> 578.25 | AO9: 715 | AP9: 792 | AQ9: 701 | AR9: 664.66667 | AS9: =AVERAGE(AO9:AR9) -> 718.16667 | AT9: 904.33333 | AU9: 915.66667 | AV9: 800.66528 | AW9: 768 | AX9: =AVERAGE(AT9:AW9) -> 847.16632 | AY9: 824.33333 | AZ9: 766.66667 | BA9: 735.66667 | BB9: 729.33333 | BC9: =AVERAGE(AY9:BB9) -> 764 | BD9: 725 | BE9: 701.66667 | BF9: 752.33333 | BG9: 770.9966 | BH9: =AVERAGE(BD9:BG9) -> 737.49915 | BI9: 776.66667 | BJ9: 800.33333 | BK9: 794.33333 | BL9: 760.66667 | BM9: =AVERAGE(BI9:BL9) -> 783 | BN9: 674 | BO9: 574.66667 | BP9: 588 | BQ9: 515.33333 | BR9: =AVERAGE(BN9:BQ9) -> 588 | BS9: 551.66667 | BT9: 748.66667 | BU9: 809 | BV9: 743.66667 | BW9: =AVERAGE(BS9:BV9) -> 713.25 | BX9: 827.66667 | BY9: 825.34783 | BZ9: 798.1917 | CA9: 803.08744 | CB9: =AVERAGE(BX9:CA9) -> 813.57341 | CC9: 887.71308 | CD9: 1015 | CE9: 970 | CF9: 935 | CG9: =AVERAGE(CC9:CF9) -> 951.92827 | CH9: 950 | CI9: 920 | CJ9: 910 | CK9: 865 | CL9: =AVERAGE(CH9:CK9) -> 911.25 | CM9: 810 | CN9: 825 | CO9: 795 | CP9: 795 | CQ9: =AVERAGE(CM9:CP9) -> 806.25
C10: Coated Sheets | J10: 396.75 | K10: 548.77778 | L10: 720 | M10: 863.33333 | N10: 805 | O10: =AVERAGE(K10:N10) -> 734.27778 | P10: 756.66667 | Q10: 655 | R10: 603.33333 | S10: 695 | T10: =AVERAGE(P10:S10) -> 677.5 | U10: 703.33333 | V10: 783.33333 | W10: 826.66667 | X10: 765 | Y10: =AVERAGE(U10:X10) -> 769.58333 | Z10: 716.66667 | AA10: 726.66667 | AB10: 703.33333 | AC10: 702 | AD10: =AVERAGE(Z10:AC10) -> 712.16667 | AE10: 857 | AF10: 1153 | AG10: 1207.3333 | AH10: 865 | AI10: =AVERAGE(AE10:AH10) -> 1020.5833 | AJ10: 642.66667 | AK10: 519.66667 | AL10: 662 | AM10: 699 | AN10: =AVERAGE(AJ10:AM10) -> 630.83333 | AO10: 779.66667 | AP10: 848 | AQ10: 756 | AR10: 718 | AS10: =AVERAGE(AO10:AR10) -> 775.41667 | AT10: 956.33333 | AU10: 980 | AV10: 867.00064 | AW10: 837 | AX10: =AVERAGE(AT10:AW10) -> 910.08349 | AY10: 888 | AZ10: 823.66667 | BA10: 796 | BB10: 778.99833 | BC10: =AVERAGE(AY10:BB10) -> 821.66625 | BD10: 781.66667 | BE10: 757.33333 | BF10: 807.66667 | BG10: 827.66301 | BH10: =AVERAGE(BD10:BG10) -> 793.58242 | BI10: 826.33333 | BJ10: 853 | BK10: 851.66667 | BL10: 829 | BM10: =AVERAGE(BI10:BL10) -> 840 | BN10: 740.33333 | BO10: 652.66667 | BP10: 653.66667 | BQ10: 568.66667 | BR10: =AVERAGE(BN10:BQ10) -> 653.83333 | BS10: 610 | BT10: 803 | BU10: 864.66667 | BV10: 799.66667 | BW10: =AVERAGE(BS10:BV10) -> 769.33333 | BX10: 905 | BY10: 910.37681 | BZ10: 885.73946 | CA10: 878.6011 | CB10: =AVERAGE(BX10:CA10) -> 894.92934 | CC10: 929.99058 | CD10: 1120 | CE10: 1080 | CF10: 1040 | CG10: =AVERAGE(CC10:CF10) -> 1042.4976 | CH10: 1050 | CI10: 1015 | CJ10: 1005 | CK10: 960 | CL10: =AVERAGE(CH10:CK10) -> 1007.5 | CM10: 900 | CN10: 915 | CO10: 885 | CP10: 885 | CQ10: =AVERAGE(CM10:CP10) -> 896.25
C11: Tin Mill Products | J11: 474.98704 | K11: 662.47822 | L11: 856.14736 | M11: 957.56237 | N11: 910.10136 | O11: =AVERAGE(K11:N11) -> 846.57233 | P11: 856.0277 | Q11: 760.99291 | R11: 683.96655 | S11: 756.56204 | T11: =AVERAGE(P11:S11) -> 764.3873 | U11: 777.71175 | V11: 841.18516 | W11: 872.63419 | X11: 843.21742 | Y11: =AVERAGE(U11:X11) -> 833.68713 | Z11: 836.27189 | AA11: 882.09743 | AB11: 878.06193 | AC11: 923.48105 | AD11: =AVERAGE(Z11:AC11) -> 879.97808 | AE11: 1110.0963 | AF11: 1479.3705 | AG11: 1557.0173 | AH11: 1214.783 | AI11: =AVERAGE(AE11:AH11) -> 1340.3168 | AJ11: 1003.1487 | AK11: 885.99888 | AL11: 1004.5157 | AM11: 1043.8491 | AN11: =AVERAGE(AJ11:AM11) -> 984.3781 | AO11: 1023.446 | AP11: 1118.5899 | AQ11: =AQ9+AQ$13/1.1023*1000*0.02 -> 1073.7038 | AR11: =AR9+AR$13/1.1023*1000*0.02 -> 1134.7103 | AS11: =AVERAGE(AO11:AR11) -> 1087.6125 | AT11: =AT9+AT$13/1.1023*1000*0.02 -> 1447.139 | AU11: =AU9+AU$13/1.1023*1000*0.02 -> 1434.3107 | AV11: =AV9+AV$13/1.1023*1000*0.02 -> 1247.3338 | AW11: =AW9+AW$13/1.1023*1000*0.02 -> 1146.8285 | AX11: =AVERAGE(AT11:AW11) -> 1318.903 | AY11: =AY9+AY$13/1.1023*1000*0.02 -> 1240.6014 | AZ11: =AZ9+AZ$13/1.1023*1000*0.02 -> 1139.3767 | BA11: =BA9+BA$13/1.1023*1000*0.02 -> 1085.5857 | BB11: =BB9+BB$13/1.1023*1000*0.02 -> 1120.2169 | BC11: =AVERAGE(AY11:BB11) -> 1146.4452 | BD11: =BD9+BD$13/1.1023*1000*0.02 -> 1161.4589 | BE11: =BE9+BE$13/1.1023*1000*0.02 -> 1080.6785 | BF11: =BF9+BF$13/1.1023*1000*0.02 -> 1138.0428 | BG11: =BG9+BG$13/1.1023*1000*0.02 -> 1186.5851 | BH11: =AVERAGE(BD11:BG11) -> 1141.6913 | BI11: =BI9+BI$13/1.1023*1000*0.02 -> 1187.155 | BJ11: =BJ9+BJ$13/1.1023*1000*0.02 -> 1220.1763 | BK11: =BK9+BK$13/1.1023*1000*0.02 -> 1191.9221 | BL11: =BL9+BL$13/1.1023*1000*0.02 -> 1121.1414 | BM11: =AVERAGE(BI11:BL11) -> 1180.0987 | BN11: =BN9+BN$13/1.1023*1000*0.02 -> 1007.371 | BO11: =BO9+BO$13/1.1023*1000*0.02 -> 857.96419 | BP11: =BP9+BP$13/1.1023*1000*0.02 -> 864.08805 | BQ11: =BQ9+BQ$13/1.1023*1000*0.02 -> 791.42139 | BR11: =AVERAGE(BN11:BQ11) -> 880.21116 | BS11: =BS9+BS$13/1.1023*1000*0.02 -> 833.0852 | BT11: =BT9+BT$13/1.1023*1000*0.02 -> 1055.3173 | BU11: =BU9+BU$13/1.1023*1000*0.02 -> 1146.4827 | BV11: =BV9+BV$13/1.1023*1000*0.02 -> 1121.4507 | BW11: =AVERAGE(BS11:BV11) -> 1039.084 | BX11: =BX9+BX$13/1.1023*1000*0.02 -> 1191.0411 | BY11: =BY9+BY$13/1.1023*1000*0.02 -> 1186.7604 | BZ11: =BZ9+BZ$13/1.1023*1000*0.02 -> 1170.388 | CA11: =CA9+CA$13/1.1023*1000*0.02 -> 1175.2837 | CB11: =AVERAGE(BX11:CA11) -> 1180.8683 | CC11: =CC9+CC$13/1.1023*1000*0.02 -> 1259.9094 | CD11: =CD9+CD$13/1.1023*1000*0.02 -> 1399 | CE11: =CE9+CE$13/1.1023*1000*0.02 -> 1350 | CF11: =CF9+CF$13/1.1023*1000*0.02 -> 1315 | CG11: =AVERAGE(CC11:CF11) -> 1330.9773 | CH11: =CH9+CH$13/1.1023*1000*0.02 -> 1330 | CI11: =CI9+CI$13/1.1023*1000*0.02 -> 1300 | CJ11: =CJ9+CJ$13/1.1023*1000*0.02 -> 1290 | CK11: =CK9+CK$13/1.1023*1000*0.02 -> 1245 | CL11: =AVERAGE(CH11:CK11) -> 1291.25 | CM11: =CM9+CM$13/1.1023*1000*0.02 -> 1230 | CN11: =CN9+CN$13/1.1023*1000*0.02 -> 1245 | CO11: =CO9+CO$13/1.1023*1000*0.02 -> 1235 | CP11: =CP9+CP$13/1.1023*1000*0.02 -> 1235 | CQ11: =AVERAGE(CM11:CP11) -> 1236.25
C12: Semi-finished and Plates | J12: 224.07693 | K12: 349.26971 | L12: 465.69295 | M12: 480.81285 | N12: 498.95673 | O12: =AVERAGE(K12:N12) -> 448.68306 | P12: 492.90877 | Q12: 438.47712 | R12: 334.14981 | S12: 362.87762 | T12: =AVERAGE(P12:S12) -> 407.10333 | U12: 359.85364 | V12: 438.47712 | W12: 495.93275 | X12: 456.621 | Y12: =AVERAGE(U12:X12) -> 437.72113 | Z12: 441.5011 | AA12: 501.98071 | AB12: 489.88479 | AC12: 489.88479 | AD12: =AVERAGE(Z12:AC12) -> 480.81285 | AE12: 544.31643 | AF12: 816.47464 | AG12: 946.50579 | AH12: 559.43633 | AI12: =AVERAGE(AE12:AH12) -> 716.6833 | AJ12: 323.68747 | AK12: 118.3 | AL12: 293.44767 | AM12: 387.06946 | AN12: =AVERAGE(AJ12:AM12) -> 280.62615 | AO12: 456.621 | AP12: 547.34041 | AQ12: 492.90877 | AR12: 483.83683 | AS12: =AVERAGE(AO12:AR12) -> 495.17675 | AT12: 613.86797 | AU12: 669.81161 | AV12: 650.15573 | AW12: 666.78763 | AX12: =AVERAGE(AT12:AW12) -> 650.15573 | AY12: 622.93991 | AZ12: 559.50951 | BA12: 530 | BB12: 496.33333 | BC12: =AVERAGE(AY12:BB12) -> 552.19569 | BD12: 524.35816 | BE12: 506.45015 | BF12: 544.92123 | BG12: 549.75959 | BH12: =AVERAGE(BD12:BG12) -> 531.37228 | BI12: 539.17411 | BJ12: 524.6558 | BK12: 511.04801 | BL12: 472.03902 | BM12: =AVERAGE(BI12:BL12) -> 511.72924 | BN12: 399.16538 | BO12: 353.80568 | BP12: 328.10185 | BQ12: 306.93399 | BR12: =AVERAGE(BN12:BQ12) -> 347.00172 | BS12: 297.86205 | BT12: 382.53349 | BU12: 361.36563 | BV12: 390.09344 | BW12: =AVERAGE(BS12:BV12) -> 357.96365 | BX12: 452.08503 | BY12: 453.16667 | BZ12: 460.66667 | CA12: 468.09489 | CB12: =AVERAGE(BX12:CA12) -> 458.50332 | CC12: 591.07743 | CD12: 695 | CE12: 680 | CF12: 635 | CG12: =AVERAGE(CC12:CF12) -> 650.26936 | CH12: 650 | CI12: 620 | CJ12: 610 | CK12: 565 | CL12: =AVERAGE(CH12:CK12) -> 611.25 | CM12: 510 | CN12: 525 | CO12: 495 | CP12: 495 | CQ12: =AVERAGE(CM12:CP12) -> 506.25
C13: LME Tin ($k/t) | AO13: 17.205558 | AP13: 17.804716 | AQ13: 20.541567 | AR13: 25.906452 | AS13: =AVERAGE(AO13:AR13) -> 20.364573 | AT13: 29.916737 | AU13: 28.585066 | AV13: 24.618134 | AW13: 20.879132 | AX13: =AVERAGE(AT13:AW13) -> 25.999767 | AY13: 22.942616 | AZ13: 20.541914 | BA13: 19.285786 | BB13: 21.543547 | BC13: =AVERAGE(AY13:BB13) -> 21.078466 | BD13: 24.055435 | BE13: 20.889238 | BF13: 21.258376 | BG13: 22.905159 | BH13: =AVERAGE(BD13:BG13) -> 22.277052 | BI13: 22.624065 | BJ13: 23.139643 | BK13: 21.913105 | BL13: 19.867562 | BM13: =AVERAGE(BI13:BL13) -> 21.886094 | BN13: 18.373743 | BO13: 15.613943 | BP13: 15.216593 | BQ13: 15.216593 | BR13: =AVERAGE(BN13:BQ13) -> 16.105218 | BS13: 15.510382 | BT13: 16.901051 | BU13: 18.600358 | BV13: 20.821565 | BW13: =AVERAGE(BS13:BV13) -> 17.958339 | BX13: 20.02738 | BY13: 19.919255 | BZ13: 20.513598 | CA13: 20.513598 | CB13: =AVERAGE(BX13:CA13) -> 20.243458 | CC13: 20.513598 | CD13: 21.16416 | CE13: 20.9437 | CF13: 20.9437 | CG13: =AVERAGE(CC13:CF13) -> 20.89129 | CH13: 20.9437 | CI13: 20.9437 | CJ13: 20.9437 | CK13: 20.9437 | CL13: =AVERAGE(CH13:CK13) -> 20.9437 | CM13: 23.1483 | CN13: 23.1483 | CO13: 24.2506 | CP13: 24.2506 | CQ13: =AVERAGE(CM13:CP13) -> 23.69945
B14: Tubular Segment ($ per ton)
C15: Seamless | J15: 882.66667 | K15: 929.33333 | L15: 1297.3333 | M15: 1454.6667 | N15: 1480.3333 | O15: =AVERAGE(K15:N15) -> 1290.4167 | P15: 1527 | Q15: 1569.6667 | R15: 1556 | S15: 1553.6667 | T15: =AVERAGE(P15:S15) -> 1551.5833 | U15: 1569.3333 | V15: 1565 | W15: 1576 | X15: 1536 | Y15: =AVERAGE(U15:X15) -> 1561.5833 | Z15: 1517.3333 | AA15: 1467.6667 | AB15: 1472.3333 | AC15: 1470 | AD15: =AVERAGE(Z15:AC15) -> 1481.8333 | AE15: 1499 | AF15: 2108 | AG15: 3196 | AH15: 3086.6667 | AI15: =AVERAGE(AE15:AH15) -> 2472.4167 | AJ15: 2260 | AK15: 1563 | AL15: 1477 | AM15: 1503.3333 | AN15: =AVERAGE(AJ15:AM15) -> 1700.8333 | AO15: 1616.6667 | AP15: 1779 | AQ15: 1829 | AR15: 1767 | AS15: =AVERAGE(AO15:AR15) -> 1747.9167 | AT15: 1757.6667 | AU15: 1926.3333 | AV15: 1996.6667 | AW15: 2040.6667 | AX15: =AVERAGE(AT15:AW15) -> 1930.3333 | AY15: 2028.3333 | AZ15: 2000.3333 | BA15: 1927 | BB15: 1888.6667 | BC15: =AVERAGE(AY15:BB15) -> 1961.0833 | BD15: 1837.6667 | BE15: 1759.3333 | BF15: 1725.3333 | BG15: 1723 | BH15: =AVERAGE(BD15:BG15) -> 1761.3333 | BI15: 1691.6667 | BJ15: 1705.3333 | BK15: 1792.3333 | BL15: 1929.6667 | BM15: =AVERAGE(BI15:BL15) -> 1779.75 | BN15: 1768 | BO15: 1593.3333 | BP15: 1445 | BQ15: 1304.3333 | BR15: =AVERAGE(BN15:BQ15) -> 1527.6667 | BS15: 1213.3333 | BT15: 1171.6667 | BU15: 1198.3333 | BV15: 1182.3333 | BW15: =AVERAGE(BS15:BV15) -> 1191.4167 | BX15: 1312.3333 | BY15: 1504.6667 | BZ15: 1509.6667 | CA15: 1524 | CB15: =AVERAGE(BX15:CA15) -> 1462.6667 | CC15: 1584.6667 | CD15: 1780 | CE15: 1760 | CF15: 1745 | CG15: =AVERAGE(CC15:CF15) -> 1717.4167 | CH15: 1755 | CI15: 1760 | CJ15: 1755 | CK15: 1735 | CL15: =AVERAGE(CH15:CK15) -> 1751.25 | CM15: 1705 | CN15: 1710 | CO15: 1705 | CP15: 1685 | CQ15: =AVERAGE(CM15:CP15) -> 1701.25
C16: Welded | J16: 789.66667 | K16: 831 | L16: 1259.3333 | M16: 1315.6667 | N16: 1318.3333 | O16: =AVERAGE(K16:N16) -> 1181.0833 | P16: 1358.3333 | Q16: 1330.3333 | R16: 1352 | S16: 1358.3333 | T16: =AVERAGE(P16:S16) -> 1349.75 | U16: 1352.3333 | V16: 1369.6667 | W16: 1385 | X16: 1360.6667 | Y16: =AVERAGE(U16:X16) -> 1366.9167 | Z16: 1332.3333 | AA16: 1305.3333 | AB16: 1276.3333 | AC16: 1289 | AD16: =AVERAGE(Z16:AC16) -> 1300.75 | AE16: 1321.3333 | AF16: 1921 | AG16: 2941.6667 | AH16: 2769 | AI16: =AVERAGE(AE16:AH16) -> 2238.25 | AJ16: 2164 | AK16: 1602 | AL16: 1430 | AM16: 1376.3333 | AN16: =AVERAGE(AJ16:AM16) -> 1643.0833 | AO16: 1540 | AP16: 1683.6667 | AQ16: 1744.3333 | AR16: 1677.3333 | AS16: =AVERAGE(AO16:AR16) -> 1661.3333 | AT16: 1691.3333 | AU16: 1749.6667 | AV16: 1780 | AW16: 1759.3333 | AX16: =AVERAGE(AT16:AW16) -> 1745.0833 | AY16: 1699.3333 | AZ16: 1624 | BA16: 1584 | BB16: 1518.6667 | BC16: =AVERAGE(AY16:BB16) -> 1606.5 | BD16: 1475.6667 | BE16: 1441.3333 | BF16: 1397.3333 | BG16: 1406.3333 | BH16: =AVERAGE(BD16:BG16) -> 1430.1667 | BI16: 1395.6667 | BJ16: 1436.3333 | BK16: 1557.3333 | BL16: 1606.6667 | BM16: =AVERAGE(BI16:BL16) -> 1499 | BN16: 1466.6667 | BO16: 1296 | BP16: 1184.6667 | BQ16: 1088 | BR16: =AVERAGE(BN16:BQ16) -> 1258.8333 | BS16: 1034.3333 | BT16: 995 | BU16: 1011.6667 | BV16: 1000.3333 | BW16: =AVERAGE(BS16:BV16) -> 1010.3333 | BX16: 1117 | BY16: 1316.3333 | BZ16: 1308.6667 | CA16: 1302.6667 | CB16: =AVERAGE(BX16:CA16) -> 1261.1667 | CC16: 1352.6667 | CD16: 1535 | CE16: 1505 | CF16: 1485 | CG16: =AVERAGE(CC16:CF16) -> 1469.4167 | CH16: 1500 | CI16: 1470 | CJ16: 1460 | CK16: 1415 | CL16: =AVERAGE(CH16:CK16) -> 1461.25 | CM16: 1360 | CN16: 1375 | CO16: 1345 | CP16: 1345 | CQ16: =AVERAGE(CM16:CP16) -> 1356.25
B17: USSE Segment ($ per ton)
C18: Hot-rolled Sheets | J18: 238.96704 | K18: 389.6987 | L18: 474.88933 | M18: 531.44784 | N18: 603.82082 | O18: 499.96417 | P18: 617.43983 | Q18: 543.11764 | R18: 438.69405 | S18: 435.04539 | T18: 508.57423 | U18: 451.02379 | V18: 540.27772 | W18: 561.92697 | X18: 561.66809 | Y18: 528.72414 | Z18: 555.71914 | AA18: 602.18398 | AB18: 618.37054 | AC18: 649.6949 | AD18: 606.49214 | AE18: 717.65749 | AF18: 916.51131 | AG18: 1054.3847 | AH18: 673.85413 | AI18: 840.60191 | AJ18: 490.69393 | AK18: 465.05467 | AL18: 547.80209 | AM18: 560.813 | AN18: 516.09092 | AO18: 522.60667 | AP18: 680.03766 | AQ18: 655.595 | AR18: 629.96 | AS18: =AVERAGE(AO18:AR18) -> 622.04983 | AT18: 771.78833 | AU18: 772.87667 | AV18: 689.85667 | AW18: 620.28833 | AX18: =AVERAGE(AT18:AW18) -> 713.7025 | AY18: 651.60667 | AZ18: 633.90667 | BA18: 573.92167 | BB18: 560.94167 | BC18: =AVERAGE(AY18:BB18) -> 605.09417 | BD18: 598.68333 | BE18: 545.82667 | BF18: 528.89667 | BG18: 557.005 | BH18: =AVERAGE(BD18:BG18) -> 557.60292 | BI18: 558.54 | BJ18: 531.265 | BK18: 503.755 | BL18: 467.42667 | BM18: =AVERAGE(BI18:BL18) -> 515.24667 | BN18: 419.26667 | BO18: 402.66333 | BP18: 378.15 | BQ18: 328.42667 | BR18: =AVERAGE(BN18:BQ18) -> 382.12667 | BS18: 329.17333 | BT18: 422.82 | BU18: 431.88333 | BV18: 487.82667 | BW18: =AVERAGE(BS18:BV18) -> 417.92583 | BX18: 549.59833 | BY18: 520.825 | BZ18: 550.50794 | CA18: 574.73968 | CB18: =AVERAGE(BX18:CA18) -> 548.91774 | CC18: 625.47905 | CD18: 625 | CE18: 590 | CF18: 560 | CG18: =AVERAGE(CC18:CF18) -> 600.11976 | CH18: 550 | CI18: 550 | CJ18: 520 | CK18: 520 | CL18: =AVERAGE(CH18:CK18) -> 535 | CM18: 520 | CN18: 530 | CO18: 515 | CP18: 515 | CQ18: =AVERAGE(CM18:CP18) -> 520
C19: Cold-rolled Sheets | J19: 408.24865 | K19: 472.69352 | L19: 562.22536 | M19: 634.01865 | N19: 715.14145 | O19: 596.01975 | P19: 734.66926 | Q19: 668.23738 | R19: 549.33089 | S19: 542.90125 | T19: 623.7847 | U19: 560.15029 | V19: 655.39747 | W19: 676.60595 | X19: 666.19101 | Y19: 639.58618 | Z19: 654.82692 | AA19: 685.89392 | AB19: 699.57071 | AC19: 735.00838 | AD19: 693.82498 | AE19: 799.10473 | AF19: 1001.6109 | AG19: 1108.4557 | AH19: 722.14233 | AI19: 907.82842 | AJ19: 537.79823 | AK19: 509.69773 | AL19: 600.38851 | AM19: 614.6484 | AN19: 565.63322 | AO19: 572.77444 | AP19: 745.31807 | AQ19: =AP19*AQ18/AP18 -> 718.52903 | AR19: =AQ19*AR18/AQ18 -> 690.43319 | AS19: =AVERAGE(AO19:AR19) -> 681.76368 | AT19: =AR19*AT18/AR18 -> 845.87637 | AU19: =AT19*AU18/AT18 -> 847.06918 | AV19: =AU19*AV18/AU18 -> 756.07965 | AW19: =AV19*AW18/AV18 -> 679.83309 | AX19: =AVERAGE(AT19:AW19) -> 782.21457 | AY19: =AW19*AY18/AW18 -> 714.15783 | AZ19: =AY19*AZ18/AY18 -> 694.75872 | BA19: =AZ19*BA18/AZ18 -> 629.01544 | BB19: =BA19*BB18/BA18 -> 614.78942 | BC19: =AVERAGE(AY19:BB19) -> 663.18035 | BD19: =BB19*BD18/BB18 -> 656.15411 | BE19: =BD19*BE18/BD18 -> 598.22345 | BF19: =BE19*BF18/BE18 -> 579.66825 | BG19: =BF19*BG18/BF18 -> 610.47485 | BH19: =AVERAGE(BD19:BG19) -> 611.13017 | BI19: =BG19*BI18/BG18 -> 612.15721 | BJ19: =BI19*BJ18/BI18 -> 582.26393 | BK19: =BJ19*BK18/BJ18 -> 552.1131 | BL19: =BK19*BL18/BK18 -> 512.29742 | BM19: =AVERAGE(BI19:BL19) -> 564.70792 | BN19: =BN18*1.16 -> 486.34933 | BO19: =BN19*BO18/BN18 -> 467.08947 | BP19: =BO19*BP18/BO18 -> 438.654 | BQ19: =BP19*BQ18/BP18 -> 380.97493 | BR19: =AVERAGE(BN19:BQ19) -> 443.26693 | BS19: =BS18*1.16 -> 381.84107 | BT19: =BS19*BT18/BS18 -> 490.4712 | BU19: =BT19*BU18/BT18 -> 500.98467 | BV19: =BU19*BV18/BU18 -> 565.87893 | BW19: =AVERAGE(BS19:BV19) -> 484.79397 | BX19: =BX18*1.16 -> 637.53407 | BY19: =BY18*1.16 -> 604.157 | BZ19: =BZ18*1.16 -> 638.58921 | CA19: =CA18*1.16 -> 666.69803 | CB19: =AVERAGE(BX19:CA19) -> 636.74458 | CC19: =CA19*CC18/CA18 -> 725.5557 | CD19: =CC19*CD18/CC18 -> 725 | CE19: =CD19*CE18/CD18 -> 684.4 | CF19: =CE19*CF18/CE18 -> 649.6 | CG19: =AVERAGE(CC19:CF19) -> 696.13893 | CH19: =CF19*CH18/CF18 -> 638 | CI19: =CH19*CI18/CH18 -> 638 | CJ19: =CI19*CJ18/CI18 -> 603.2 | CK19: =CJ19*CK18/CJ18 -> 603.2 | CL19: =AVERAGE(CH19:CK19) -> 620.6 | CM19: =CK19*CM18/CK18 -> 603.2 | CN19: =CM19*CN18/CM18 -> 614.8 | CO19: =CN19*CO18/CN18 -> 597.4 | CP19: =CO19*CP18/CO18 -> 597.4 | CQ19: =AVERAGE(CM19:CP19) -> 603.2
C20: Coated Sheets | J20: 424.50056 | K20: 483.99985 | L20: 573.14235 | M20: 645.20978 | N20: 726.85941 | O20: 607.30285 | P20: 744.56162 | Q20: 670.06126 | R20: 554.90836 | S20: 560.85045 | T20: 632.59542 | U20: 578.27319 | V20: 756.46867 | W20: 802.75282 | X20: 797.93745 | Y20: 733.85803 | Z20: 797.69825 | AA20: 828.8176 | AB20: 824.39696 | AC20: 813.75927 | AD20: 816.16802 | AE20: 839.43882 | AF20: 1048.9066 | AG20: 1189.5622 | AH20: 794.57464 | AI20: 968.12058 | AJ20: 608.4508 | AK20: 576.65863 | AL20: 679.2638 | AM20: 695.39706 | AN20: 639.94257 | AO20: 648.02197 | AP20: 843.2333 | AQ20: =AP20*AQ19/AP19 -> 812.92488 | AR20: =AQ20*AR19/AQ19 -> 781.13798 | AS20: =AVERAGE(AO20:AR20) -> 771.32953 | AT20: =AR20*AT19/AR19 -> 957.00232 | AU20: =AT20*AU19/AT19 -> 958.35183 | AV20: =AU20*AV19/AU19 -> 855.40867 | AW20: =AV20*AW19/AV19 -> 769.14531 | AX20: =AVERAGE(AT20:AW20) -> 884.97703 | AY20: =AW20*AY19/AW19 -> 807.97942 | AZ20: =AY20*AZ19/AY19 -> 786.03177 | BA20: =AZ20*BA19/AZ19 -> 711.65155 | BB20: =BA20*BB19/BA19 -> 695.55661 | BC20: =AVERAGE(AY20:BB20) -> 750.30484 | BD20: =BB20*BD19/BB19 -> 742.35553 | BE20: =BC20*BE19/BC19 -> 676.81431 | BF20: =BE20*BF19/BE19 -> 655.82144 | BG20: =BF20*BG19/BF19 -> 690.67522 | BH20: =AVERAGE(BD20:BG20) -> 691.41663 | BI20: =BG20*BI19/BG19 -> 692.57859 | BJ20: =BI20*BJ19/BI19 -> 658.75813 | BK20: =BJ20*BK19/BJ19 -> 624.64627 | BL20: =BK20*BL19/BK19 -> 579.59985 | BM20: =AVERAGE(BI20:BL20) -> 638.89571 | BN20: =BN18*1.19 -> 498.92733 | BO20: =BN20*BO19/BN19 -> 479.16937 | BP20: =BO20*BP19/BO19 -> 449.9985 | BQ20: =BP20*BQ19/BP19 -> 390.82773 | BR20: =AVERAGE(BN20:BQ20) -> 454.73073 | BS20: =BS18*1.19 -> 391.71627 | BT20: =BS20*BT19/BS19 -> 503.1558 | BU20: =BT20*BU19/BT19 -> 513.94117 | BV20: =BU20*BV19/BU19 -> 580.51373 | BW20: =AVERAGE(BS20:BV20) -> 497.33174 | BX20: =BX18*1.19 -> 654.02202 | BY20: =BY18*1.19 -> 619.78175 | BZ20: =BZ18*1.19 -> 655.10444 | CA20: =CA18*1.19 -> 683.94022 | CB20: =AVERAGE(BX20:CA20) -> 653.21211 | CC20: =CA20*CC19/CA19 -> 744.32007 | CD20: =CC20*CD19/CC19 -> 743.75 | CE20: =CD20*CE19/CD19 -> 702.1 | CF20: =CE20*CF19/CE19 -> 666.4 | CG20: =AVERAGE(CC20:CF20) -> 714.14252 | CH20: =CF20*CH19/CF19 -> 654.5 | CI20: =CH20*CI19/CH19 -> 654.5 | CJ20: =CI20*CJ19/CI19 -> 618.8 | CK20: =CJ20*CK19/CJ19 -> 618.8 | CL20: =AVERAGE(CH20:CK20) -> 636.65 | CM20: =CK20*CM19/CK19 -> 618.8 | CN20: =CM20*CN19/CM19 -> 630.7 | CO20: =CN20*CO19/CN19 -> 612.85 | CP20: =CO20*CP19/CO19 -> 612.85 | CQ20: =AVERAGE(CM20:CP20) -> 618.8
C21: Tin Mill Products | J21: 496.9857 | K21: 596.39397 | L21: 721.70605 | M21: 794.91436 | N21: 875.24282 | O21: 747.0643 | P21: 880.69696 | Q21: 811.73029 | R21: 676.63078 | S21: 659.46328 | T21: 757.13033 | U21: 697.86205 | V21: 811.58263 | W21: 832.57347 | X21: 851.0751 | Y21: 798.27331 | Z21: 881.09881 | AA21: 939.65802 | AB21: 970.96597 | AC21: 1033.4894 | AD21: 956.30306 | AE21: 1122.5344 | AF21: 1407.648 | AG21: 1520.473 | AH21: 921.72502 | AI21: 1296.2038 | AJ21: 719.23704 | AK21: 691.13654 | AL21: 818.11508 | AM21: 886.80662 | AN21: 972.97847 | AO21: =AO19+AO$13/1.1023*1000*0.02 -> 884.95004 | AP21: =AP19+AP$13/1.1023*1000*0.02 -> 1068.3647 | AQ21: =AQ19+AQ$13/1.1023*1000*0.02 -> 1091.2328 | AR21: =AR19+AR$13/1.1023*1000*0.02 -> 1160.4768 | AS21: =AVERAGE(AO21:AR21) -> 1051.2561 | AT21: =AT19+AT$13/1.1023*1000*0.02 -> 1388.6821 | AU21: =AU19+AU$13/1.1023*1000*0.02 -> 1365.7132 | AV21: =AV19+AV$13/1.1023*1000*0.02 -> 1202.7482 | AW21: =AW19+AW$13/1.1023*1000*0.02 -> 1058.6616 | AX21: =AVERAGE(AT21:AW21) -> 1253.9513 | AY21: =AY19+AY$13/1.1023*1000*0.02 -> 1130.4259 | AZ21: =AZ19+AZ$13/1.1023*1000*0.02 -> 1067.4688 | BA21: =BA19+BA$13/1.1023*1000*0.02 -> 978.93444 | BB21: =BB19+BB$13/1.1023*1000*0.02 -> 1005.673 | BC21: =AVERAGE(AY21:BB21) -> 1045.6255 | BD21: =BD19+BD$13/1.1023*1000*0.02 -> 1092.6131 | BE21: =BE19+BE$13/1.1023*1000*0.02 -> 977.2353 | BF21: =BF19+BF$13/1.1023*1000*0.02 -> 965.3777 | BG21: =BG19+BG$13/1.1023*1000*0.02 -> 1026.0633 | BH21: =AVERAGE(BD21:BG21) -> 1015.3223 | BI21: =BI19+BI$13/1.1023*1000*0.02 -> 1022.6455 | BJ21: =BJ19+BJ$13/1.1023*1000*0.02 -> 1002.1069 | BK21: =BK19+BK$13/1.1023*1000*0.02 -> 949.70187 | BL21: =BL19+BL$13/1.1023*1000*0.02 -> 872.77211 | BM21: =AVERAGE(BI21:BL21) -> 961.80659 | BN21: =BN19+BN$13/1.1023*1000*0.02 -> 819.72035 | BO21: =BO19+BO$13/1.1023*1000*0.02 -> 750.38699 | BP21: =BP19+BP$13/1.1023*1000*0.02 -> 714.74205 | BQ21: =BQ19+BQ$13/1.1023*1000*0.02 -> 657.06299 | BR21: =AVERAGE(BN21:BQ21) -> 735.47809 | BS21: =BS19+BS$13/1.1023*1000*0.02 -> 663.2596 | BT21: =BT19+BT$13/1.1023*1000*0.02 -> 797.12185 | BU21: =BU19+BU$13/1.1023*1000*0.02 -> 838.46734 | BV21: =BV19+BV$13/1.1023*1000*0.02 -> 943.66293 | BW21: =AVERAGE(BS21:BV21) -> 810.62793 | BX21: =BX19+BX$13/1.1023*1000*0.02 -> 1000.9085 | BY21: =BY19+BY$13/1.1023*1000*0.02 -> 965.5696 | BZ21: =BZ19+BZ$13/1.1023*1000*0.02 -> 1010.7855 | CA21: =CA19+CA$13/1.1023*1000*0.02 -> 1038.8943 | CB21: =AVERAGE(BX21:CA21) -> 1004.0395 | CC21: =CC19+CC$13/1.1023*1000*0.02 -> 1097.752 | CD21: =CD19+CD$13/1.1023*1000*0.02 -> 1109 | CE21: =CE19+CE$13/1.1023*1000*0.02 -> 1064.4 | CF21: =CF19+CF$13/1.1023*1000*0.02 -> 1029.6 | CG21: =AVERAGE(CC21:CF21) -> 1075.188 | CH21: =CH19+CH$13/1.1023*1000*0.02 -> 1018 | CI21: =CI19+CI$13/1.1023*1000*0.02 -> 1018 | CJ21: =CJ19+CJ$13/1.1023*1000*0.02 -> 983.2 | CK21: =CK19+CK$13/1.1023*1000*0.02 -> 983.2 | CL21: =AVERAGE(CH21:CK21) -> 1000.6 | CM21: =CM19+CM$13/1.1023*1000*0.02 -> 1023.2 | CN21: =CN19+CN$13/1.1023*1000*0.02 -> 1034.8 | CO21: =CO19+CO$13/1.1023*1000*0.02 -> 1037.4 | CP21: =CP19+CP$13/1.1023*1000*0.02 -> 1037.4 | CQ21: =AVERAGE(CM21:CP21) -> 1033.2
C22: Tubular | J22: 789.66667 | K22: 831 | L22: 1259.3333 | M22: 1315.6667 | N22: 1318.3333 | O22: 1181.0833 | P22: 1358.3333 | Q22: 1330.3333 | R22: 1352 | S22: 1358.3333 | T22: 1349.75 | U22: 1352.3333 | V22: 1369.6667 | W22: 1385 | X22: 1360.6667 | Y22: 1366.9167 | Z22: 1332.3333 | AA22: 1305.3333 | AB22: 1276.3333 | AC22: 1289 | AD22: 1300.75 | AE22: 1321.3333 | AF22: 1921 | AG22: 2941.6667 | AH22: 2769 | AI22: 2238.25 | AJ22: 2164 | AK22: 1602 | AL22: 1430 | AM22: 1376.3333 | AN22: 1643.0833 | AO22: 1540 | AP22: 1683.6667 | AQ22: =AQ16 -> 1744.3333 | AR22: =AR16 -> 1677.3333 | AS22: =AVERAGE(AO22:AR22) -> 1661.3333 | AT22: =AT16 -> 1691.3333 | AU22: =AU16 -> 1749.6667 | AV22: =AV16 -> 1780 | AW22: =AW108 -> 1891.56 | AX22: =AVERAGE(AT22:AW22) -> 1778.14 | AY22: =AY108 -> 1853.9633 | AZ22: =AZ108 -> 1800.8767 | BA22: =BA108 -> 1745.21 | BB22: =BB108 -> 1692.5667 | BC22: =AVERAGE(AY22:BB22) -> 1773.1542 | BD22: =BD108 -> 1645.8067 | BE22: =BE108 -> 1590.7933 | BF22: =BF108 -> 1551.4933 | BG22: =BG108 -> 1555.1667 | BH22: =AVERAGE(BD22:BG22) -> 1585.815 | BI22: =BI108 -> 1534.7867 | BJ22: =BJ108 -> 1562.7633 | BK22: =BK108 -> 1667.7833 | BL22: =BL108 -> 1758.4767 | BM22: =AVERAGE(BI22:BL22) -> 1630.9525 | BN22: =BN108 -> 1608.2933 | BO22: =BO108 -> 1435.7467 | BP22: =BP108 -> 1307.0233 | BQ22: =BQ108 -> 1189.6767 | BR22: =AVERAGE(BN22:BQ22) -> 1385.185 | BS22: =BS108 -> 1118.4633 | BT22: =BT108 -> 1078.0333 | BU22: =BU108 -> 1099.4 | BV22: =BV108 -> 1085.8733 | BW22: =AVERAGE(BS22:BV22) -> 1095.4425 | BX22: =BX108 -> 1208.8067 | BY22: =BY108 -> 1404.85 | BZ22: =BZ108 -> 1403.1367 | CA22: =CA108 -> 1406.6933 | CB22: =AVERAGE(BX22:CA22) -> 1355.8717 | CC22: =CC108 -> 1461.7067 | CD22: =CD108 -> 1650.15 | CE22: =CE108 -> 1624.85 | CF22: =CF108 -> 1607.2 | CG22: =AVERAGE(CC22:CF22) -> 1585.9767 | CH22: =CH108 -> 1619.85 | CI22: =CI108 -> 1606.3 | CJ22: =CJ108 -> 1598.65 | CK22: =CK108 -> 1565.4 | CL22: =AVERAGE(CH22:CK22) -> 1597.55 | CM22: =CM108 -> 1522.15 | CN22: =CN108 -> 1532.45 | CO22: =CO108 -> 1514.2 | CP22: =CP108 -> 1504.8 | CQ22: =AVERAGE(CM22:CP22) -> 1518.4
C23: Semi-finished and Plates | J23: 317.21785 | K23: 389.6987 | L23: 474.88933 | M23: 531.44784 | N23: 603.82082 | O23: 499.96417 | P23: 617.43983 | Q23: 543.11764 | R23: 438.69405 | S23: 435.04539 | T23: 508.57423 | U23: 451.02379 | V23: 540.27772 | W23: 561.92697 | X23: 561.66809 | Y23: 528.72414 | Z23: 555.71914 | AA23: 602.18398 | AB23: 618.37054 | AC23: 649.6949 | AD23: 606.49214 | AE23: 717.65749 | AF23: 916.51131 | AG23: 1054.3847 | AH23: 673.85413 | AI23: 840.60191 | AJ23: 490.69393 | AK23: 465.05467 | AL23: 547.80209 | AM23: 560.813 | AN23: 516.09092 | AO23: 522.60667 | AP23: 680.03766 | AQ23: =AP23*AQ18/AP18 -> 655.595 | AR23: =AQ23*AR18/AQ18 -> 629.96 | AS23: =AVERAGE(AO23:AR23) -> 622.04983 | AT23: =AR23*AT18/AR18 -> 771.78833 | AU23: =AT23*AU18/AT18 -> 772.87667 | AV23: =AU23*AV18/AU18 -> 689.85667 | AW23: =AV23*AW18/AV18 -> 620.28833 | AX23: =AVERAGE(AT23:AW23) -> 713.7025 | AY23: =AW23*AY18/AW18 -> 651.60667 | AZ23: =AY23*AZ18/AY18 -> 633.90667 | BA23: =AZ23*BA18/AZ18 -> 573.92167 | BB23: =BA23*BB18/BA18 -> 560.94167 | BC23: =AVERAGE(AY23:BB23) -> 605.09417 | BD23: =BB23*BD18/BB18 -> 598.68333 | BE23: =BC23*BE18/BC18 -> 545.82667 | BF23: =BE23*BF18/BE18 -> 528.89667 | BG23: =BF23*BG18/BF18 -> 557.005 | BH23: =AVERAGE(BD23:BG23) -> 557.60292 | BI23: =BI18 -> 558.54 | BJ23: =BJ18 -> 531.265 | BK23: =BK18 -> 503.755 | BL23: =BL18 -> 467.42667 | BM23: =AVERAGE(BI23:BL23) -> 515.24667 | BN23: =BN18*1.05 -> 440.23 | BO23: =BN23*BO18/BN18 -> 422.7965 | BP23: =BO23*BP18/BO18 -> 397.0575 | BQ23: =BP23*BQ18/BP18 -> 344.848 | BR23: =AVERAGE(BN23:BQ23) -> 401.233 | BS23: =BS18*1.05 -> 345.632 | BT23: =BS23*BT18/BS18 -> 443.961 | BU23: =BT23*BU18/BT18 -> 453.4775 | BV23: =BU23*BV18/BU18 -> 512.218 | BW23: =AVERAGE(BS23:BV23) -> 438.82213 | BX23: =BX18*1.05 -> 577.07825 | BY23: =BY18*1.05 -> 546.86625 | BZ23: =BZ18*1.05 -> 578.03333 | CA23: =CA18*1.05 -> 603.47667 | CB23: =AVERAGE(BX23:CA23) -> 576.36362 | CC23: =CA23*CC18/CA18 -> 656.75301 | CD23: =CC23*CD18/CC18 -> 656.25 | CE23: =CD23*CE18/CD18 -> 619.5 | CF23: =CE23*CF18/CE18 -> 588 | CG23: =AVERAGE(CC23:CF23) -> 630.12575 | CH23: =CF23*CH18/CF18 -> 577.5 | CI23: =CH23*CI18/CH18 -> 577.5 | CJ23: =CI23*CJ18/CI18 -> 546 | CK23: =CJ23*CK18/CJ18 -> 546 | CL23: =AVERAGE(CH23:CK23) -> 561.75 | CM23: =CK23*CM18/CK18 -> 546 | CN23: =CM23*CN18/CM18 -> 556.5 | CO23: =CN23*CO18/CN18 -> 540.75 | CP23: =CO23*CP18/CO18 -> 540.75 | CQ23: =AVERAGE(CM23:CP23) -> 546
A25: Flat Rolled Steel | D25: 2001 | E25: 2002 | F25: 1Q | G25: 2Q | H25: 3Q | I25: 4Q | J25: =J4 -> 2003 | K25: =Operations!K4 -> 1Q | L25: =Operations!L4 -> 2Q | M25: =Operations!M4 -> 3Q | N25: =Operations!N4 -> 4Q | O25: =Operations!O4 -> 2004 | P25: =Operations!P4 -> 1Q | Q25: =Operations!Q4 -> 2Q | R25: =Operations!R4 -> 3Q | ... CQ25: =Operations!CQ4 -> 2020E
B26: Volume Growth | E26: =Operations!E34/Operations!D34-1 -> 0.12769108 | J26: =Operations!J34/Operations!E34-1 -> 0.36535354 | K26: =Operations!K34/Operations!F34-1 -> 0.70812808 | L26: =Operations!L34/Operations!G34-1 -> 0.24359775 | M26: =Operations!M34/Operations!H34-1 -> -0.041954464 | N26: =Operations!N34/Operations!I34-1 -> -0.056171285 | O26: =Operations!O34/Operations!J34-1 -> 0.15669157 | P26: =Operations!P34/Operations!K34-1 -> -0.1504446 | Q26: =Operations!Q34/Operations!L34-1 -> -0.1903566 | ... CB26: =Operations!CB34/Operations!BW34-1 -> -0.020507232 | CC26: 0.01 | CD26: 0.01 | CE26: 0.1 | CF26: 0.12 | CG26: =Operations!CG34/Operations!CB34-1 -> 0.060326692 | CH26: 0.13 | CI26: 0.137 | CJ26: 0.02 | CK26: 0.02 | CL26: =Operations!CL34/Operations!CG34-1 -> 0.073623081 | CM26: 0 | CN26: 0 | CO26: 0 | CP26: 0 | CQ26: =Operations!CQ34/Operations!CL34-1 -> 0
B28: SHIPMENTS (in '000 tons) | BZ28: =300/BZ34 -> 0.11792453
B29: Hot-rolled Sheets | F29: =$J29/$J$34*F$34 -> 810.07768 | G29: =$J29/$J$34*G$34 -> 1064.8065 | H29: =$J29/$J$34*H$34 -> 1299.9153 | I29: =$J29/$J$34*I$34 -> 1320.2005 | J29: 4495 | K29: =$O29/$O$34*K$34 -> 1374.3143 | L29: =$O29/$O$34*L$34 -> 1315.1933 | M29: =$O29/$O$34*M$34 -> 1236.9159 | N29: =$O29/$O$34*N$34 -> 1237.5765 | O29: 5164 | P29: =$T29/$T$34*P$34 -> 1004.7206 | Q29: =$T29/$T$34*Q$34 -> 916.32792 | R29: =$T29/$T$34*R$34 -> 906.94863 | S29: =$T29/$T$34*S$34 -> 951.00286 | T29: 3779 | U29: =$Y29/$Y$34*U$34 -> 1044.0166 | V29: =$Y29/$Y$34*V$34 -> 1147.2645 | W29: =$Y29/$Y$34*W$34 -> 1093.1259 | X29: =$Y29/$Y$34*X$34 -> 910.59309 | Y29: 4195 | Z29: =$AD29/$AD$34*Z$34 -> 1071.9524 | AA29: =$AD29/$AD$34*AA$34 -> 1210.1495 | AB29: =$AD29/$AD$34*AB$34 -> 1210.822 | AC29: =$AD29/$AD$34*AC$34 -> 1394.0761 | AD29: 4887 | AE29: =$AD29/$AD$34*AE$34 -> 1580.6927 | AF29: =$AD29/$AD$34*AF$34 -> 1630.4571 | AG29: =$AD29/$AD$34*AG$34 -> 1514.7884 | AH29: =$AD29/$AD$34*AH$34 -> 938.12646 | AI29: 6474 | AJ29: =AJ$34*($AN29/$AN$34) -> 683.12331 | AK29: =AK$34*($AN29/$AN$34) -> 584.01734 | AL29: =AL$34*($AN29/$AN$34) -> 875.86513 | AM29: =AM$34*($AN29/$AN$34) -> 1029.9942 | AN29: 3173 | AO29: =AO$34*($AS29/$AS$34) -> 1158.6064 | AP29: =AP$34*($AS29/$AS$34) -> 1317.2174 | AQ29: =AQ$34*($AS29/$AS$34) -> 1236.4523 | AR29: =AR$34*($AS29/$AS$34) -> 1250.724 | AS29: 4963 | AT29: =AT$34*($AX29/$AX$34) -> 1382.0771 | AU29: =AU$34*($AX29/$AX$34) -> 1375.7854 | AV29: =AV$34*($AX29/$AX$34) -> 1340.482 | AW29: =AW$34*($AX29/$AX$34) -> 1322.6555 | AX29: 5421 | AY29: =AY$34*($BC29/$BC$34) -> 1468.6012 | AZ29: =AZ$34*($BC29/$BC$34) -> 1430.5583 | BA29: =BA$34*($BC29/$BC$34) -> 1425.5337 | BB29: =BB$34*($BC29/$BC$34) -> 1408.3067 | BC29: 5733 | BD29: =BD$34*($BH29/$BH$34) -> 1379.5755 | BE29: =BE$34*($BH29/$BH$34) -> 1280.0044 | BF29: =BF$34*($BH29/$BH$34) -> 1176.9997 | BG29: =BG$34*($BH29/$BH$34) -> 1191.4204 | BH29: 5028 | BI29: =BI$34*($BM29/$BM$34) -> 1296.7836 | BJ29: =BJ$34*($BM29/$BM$34) -> 1244.8981 | BK29: =BK$34*($BM29/$BM$34) -> 1303.1369 | BL29: =BL$34*($BM29/$BM$34) -> 1064.1814 | BM29: 4909 | BN29: =BN$34*($BR29/$BR$34) -> 810.83532 | BO29: =BO$34*($BR29/$BR$34) -> 840.26954 | BP29: =BP$34*($BR29/$BR$34) -> 829.11552 | BQ29: =BQ$34*($BR29/$BR$34) -> 802.77963 | BR29: 3283 | BS29: =BS$34*($BW29/$BW$34) -> 688.96691 | BT29: =BT$34*($BW29/$BW$34) -> 742.47355 | BU29: =BU$34*($BW29/$BW$34) -> 699.17179 | BV29: =BV$34*($BW29/$BW$34) -> 653.38776 | BW29: 2784 | BX29: =BX$34*0.25 -> 601 | BY29: =BY$34*0.25 -> 624.25 | BZ29: =BZ$34*0.25 -> 636 | CA29: =CA$34*0.25 -> 610.5 | CB29: =SUM(BX29:CA29) -> 2471.75 | CC29: =CC$34*0.25 -> 607.01 | CD29: =CD$34*0.25 -> 630.4925 | CE29: =CE$34*0.28 -> 783.552 | CF29: =CF$34*0.28 -> 765.8112 | CG29: =SUM(CC29:CF29) -> 2786.8657 | CH29: =CH$34*0.28 -> 768.23186 | CI29: =CI$34*0.28 -> 802.89437 | CJ29: =CJ$34*0.28 -> 799.22304 | CK29: =CK$34*0.28 -> 781.12742 | CL29: =SUM(CH29:CK29) -> 3151.4767 | CM29: =CM$34*0.28 -> 768.23186 | CN29: =CN$34*0.28 -> 802.89437 | CO29: =CO$34*0.28 -> 799.22304 | CP29: =CP$34*0.28 -> 781.12742 | CQ29: =SUM(CM29:CP29) -> 3151.4767 | CS29: 642.36 | CT29: 616.605 | DC29: 619.1502 | DD29: 643.10235 | DE29: =CS29-DF29 -> -1904.0368 | DF29: 2546.3969
B30: Cold-rolled Sheets | F30: =$J30/$J$34*F$34 -> 733.84568 | G30: =$J30/$J$34*G$34 -> 964.60339 | H30: =$J30/$J$34*H$34 -> 1177.5873 | I30: =$J30/$J$34*I$34 -> 1195.9636 | J30: 4072 | K30: =$O30/$O$34*K$34 -> 1220.7552 | L30: =$O30/$O$34*L$34 -> 1168.2401 | M30: =$O30/$O$34*M$34 -> 1098.709 | N30: =$O30/$O$34*N$34 -> 1099.2957 | O30: 4587 | P30: =$T30/$T$34*P$34 -> 1154.671 | Q30: =$T30/$T$34*Q$34 -> 1053.086 | R30: =$T30/$T$34*R$34 -> 1042.3069 | S30: =$T30/$T$34*S$34 -> 1092.9361 | T30: 4343 | U30: =$Y30/$Y$34*U$34 -> 1114.6961 | V30: =$Y30/$Y$34*V$34 -> 1224.9339 | W30: =$Y30/$Y$34*W$34 -> 1167.1301 | X30: =$Y30/$Y$34*X$34 -> 972.23992 | Y30: 4479 | Z30: =$AD30/$AD$34*Z$34 -> 929.59571 | AA30: =$AD30/$AD$34*AA$34 -> 1049.4401 | AB30: =$AD30/$AD$34*AB$34 -> 1050.0233 | AC30: =$AD30/$AD$34*AC$34 -> 1208.941 | AD30: 4238 | AE30: =$AD30/$AD$34*AE$34 -> 1370.7746 | AF30: =$AD30/$AD$34*AF$34 -> 1413.9302 | AG30: =$AD30/$AD$34*AG$34 -> 1313.6225 | AH30: =$AD30/$AD$34*AH$34 -> 813.54204 | AI30: 4489 | AJ30: =AJ$34*($AN30/$AN$34) -> 678.60217 | AK30: =AK$34*($AN30/$AN$34) -> 580.15211 | AL30: =AL$34*($AN30/$AN$34) -> 870.06835 | AM30: =AM$34*($AN30/$AN$34) -> 1023.1774 | AN30: 3152 | AO30: =AO$34*($AS30/$AS$34) -> 1013.1678 | AP30: =AP$34*($AS30/$AS$34) -> 1151.8685 | AQ30: =AQ$34*($AS30/$AS$34) -> 1081.2417 | AR30: =AR$34*($AS30/$AS$34) -> 1093.722 | AS30: 4340 | AT30: =AT$34*($AX30/$AX$34) -> 1099.084 | AU30: =AU$34*($AX30/$AX$34) -> 1094.0806 | AV30: =AV$34*($AX30/$AX$34) -> 1066.0059 | AW30: =AW$34*($AX30/$AX$34) -> 1051.8295 | AX30: 4311 | AY30: =AY$34*($BC30/$BC$34) -> 1146.6002 | AZ30: =AZ$34*($BC30/$BC$34) -> 1116.8985 | BA30: =BA$34*($BC30/$BC$34) -> 1112.9756 | BB30: =BB$34*($BC30/$BC$34) -> 1099.5257 | BC30: 4476 | BD30: =BD$34*($BH30/$BH$34) -> 1192.7237 | BE30: =BE$34*($BH30/$BH$34) -> 1106.6386 | BF30: =BF$34*($BH30/$BH$34) -> 1017.5851 | BG30: =BG$34*($BH30/$BH$34) -> 1030.0526 | BH30: 4347 | BI30: =BI$34*($BM30/$BM$34) -> 1111.3401 | BJ30: =BJ$34*($BM30/$BM$34) -> 1066.8744 | BK30: =BK$34*($BM30/$BM$34) -> 1116.7849 | BL30: =BL$34*($BM30/$BM$34) -> 912.00065 | BM30: 4207 | BN30: =BN$34*($BR30/$BR$34) -> 866.15883 | BO30: =BO$34*($BR30/$BR$34) -> 897.60136 | BP30: =BP$34*($BR30/$BR$34) -> 885.6863 | BQ30: =BQ$34*($BR30/$BR$34) -> 857.55351 | BR30: 3507 | BS30: =BS$34*($BW30/$BW$34) -> 934.21339 | BT30: =BT$34*($BW30/$BW$34) -> 1006.7664 | BU30: =BU$34*($BW30/$BW$34) -> 948.05082 | BV30: =BV$34*($BW30/$BW$34) -> 885.96939 | BW30: 3775 | BX30: =BX$34*0.35 -> 841.4 | BY30: =BY$34*0.35 -> 873.95 | BZ30: =BZ$34*0.35 -> 890.4 | CA30: =CA$34*0.35 -> 854.7 | CB30: =SUM(BX30:CA30) -> 3460.45 | CC30: =CC$34*0.35 -> 849.814 | CD30: =CD$34*0.35 -> 882.6895 | CE30: =CE$34*0.32 -> 895.488 | CF30: =CF$34*0.32 -> 875.2128 | CG30: =SUM(CC30:CF30) -> 3503.2043 | CH30: =CH$34*0.32 -> 877.97926 | CI30: =CI$34*0.32 -> 917.59356 | CJ30: =CJ$34*0.32 -> 913.39776 | CK30: =CK$34*0.32 -> 892.71706 | CL30: =SUM(CH30:CK30) -> 3601.6876 | CM30: =CM$34*0.32 -> 877.97926 | CN30: =CN$34*0.32 -> 917.59356 | CO30: =CO$34*0.32 -> 913.39776 | CP30: =CP$34*0.32 -> 892.71706 | CQ30: =SUM(CM30:CP30) -> 3601.6876 | CS30: 899.304 | CT30: 863.247 | DC30: 866.81028 | DD30: 900.34329 | DE30: =CS30-DF30 -> -2665.6516 | DF30: 3564.9556
