Workbook
Name __FDS_USED_FOR_REUSING_RANGE_IDS_RECYCLE: {2371,2371,2371,2371,2371,2371,2371,2371,2371,2371,2371,2371,2371,2371,2371,2371,2371,2371,2371,2371,2371,2371,2371,2371,2371,2371,2371,2371,2371,2371,2371,2371,2371,2371}
Name _Switch: DCF!$B$5
Name _Toggle: DCF!$A$5
Name actual_start_year: 1992
Name AdditionalInstructions: IndexInformation!$B$42
Name Address: ImportantDisclosures!$A$2:$A$2
Name admin: 1
Name AllTables: {1}
Name ANA: ModPubIndex!$A$7
Name AssetsCurrentDeferredIncomeTaxes: 0
Name AssetsCurrentShortTermInvestments: 0
Name AssetsIntangiblesAccumulatedAmortization: 0
Name AssetsIntangiblesGross: 0
Name AssetsOtherAccumulatedAmortization: 0
Name AssetsOtherGross: 0
Name AssetsOtherNet: 0
Name Authors: ImportantDisclosures!$A$7
Name Authors: IndexInformation!$B$18
Name BRO: ModPubIndex!$A$1
Name case_num: 1
Name CashFlowCapitalExpenditureCellular: 0
Name CashFlowCapitalExpenditureOther: 0
Name CashFlowCapitalExpenditurePaging: 0
Name CashFlowCapitalExpenditureTelephone: 0
Name CashFlowCapitalExpenditureWireless: 0
Name CashFlowDividendPaidPreferredStock: 0
Name chart: "Chart 1"
Name Class_B: 68.45
Name cm: 1
Name CopyrightStamp: ImportantDisclosures!$A$29
Name COU: ModPubIndex!$A$5
Name CQEnd: IndexInformation!$B$31
Name Currency: IndexInformation!$B$24
Name CurrentStockPrice: IndexInformation!$B$23
Name CurrQtrEPS: IndexInformation!$B$29
Name CurrYearEPS: IndexInformation!$B$11
Name CurrYearTotalRevenue: IndexInformation!$B$10
Name CurrYearTotalRevenueActual: IndexInformation!$B$32
Name CUSIP: IndexInformation!$B$20
Name CYEnd: IndexInformation!$B$30
Name Date: ImportantDisclosures!$A$8
Name DB: "WIRENYPROD"
Name dd: {"Jan","Feb","Mar","Apr","May","Jun","Jul","Aug","Sep","Oct","Nov","Dec";"January","February","March","April","May","June","July","August","September","October","November","December"}
Name Deleted: IndexInformation!$B$27
Name Description: IndexInformation!$B$7
Name DEVELOPMENT: 5
Name Discipline: IndexInformation!$B$3
Name DISCIPLINE: ModPubIndex!$A$12
Name DisclosuresText: ImportantDisclosures!$A$24
Name Distribution: IndexInformation!$B$26
Name DistTable: ImportantDisclosures!#REF!
Name DistTablePreamble: ImportantDisclosures!#REF!
Name DOCDAT: ModPubIndex!$A$2
Name DOCTIME: ModPubIndex!$A$3
Name DocType: IndexInformation!$B$5
Name EMAIL_ALERT: ModPubIndex!$A$10
Name EmailAlert: IndexInformation!$B$28
Name EquityAdjustments: 0
Name EquityEmployeeStockOwnershipPlan: 0
Name EquityPaidInCapital: 0

Sheet ImportantDisclosures
A2: 1585 Broadway
A3: New York, NY 10036-8293
A4: United States
A5: Tel: +1 (1)212 761 4000
A7: Authors: James Faucette, Vasundhara Govil, Brian Nowak, Priscilla Russo
A8: Date: 26 Apr 2018
A10: Ticker: PYPL.O
A11: Stock Rating: Overweight
A12: Industry: Payments and Processing
A13: Industry View: In-Line
A14: Price as of 26 Apr 2018: 74.00
A15: Target Price: 89
... A125: Equal-weight and Not-Rated to hold and Underweight to sell recommendations, respectively.
B127: Coverage Universe | D127: Investment Banking Clients (IBC) | G127: Other Material Investment Services Clients (MISC)
A128: Stock Rating Category | B128: Count | C128: % of Total | D128: Count | E128: % of Total IBC | F128: % of Rating Category | G128: Count | H128: % of Total Other MISC
A129: Overweight/Buy | B129: 1189 | C129: 0.38 | D129: 315 | E129: 0.41 | F129: 0.26 | G129: 555 | H129: 0.39
A130: Equal-weight/Hold | B130: 1355 | C130: 0.43 | D130: 364 | E130: 0.47 | F130: 0.27 | G130: 644 | H130: 0.45
A131: Not-Rated/Hold | B131: 53 | C131: 0.02 | D131: 4 | E131: 0.01 | F131: 0.08 | G131: 7 | H131: 0
A132: Underweight/Sell | B132: 545 | C132: 0.17 | D132: 84 | E132: 0.11 | F132: 0.15 | G132: 214 | H132: 0.15
A133: Total | B133: 3142 | D133: 767 | G133: 1420
A135: Data include common stock and ADRs currently assigned ratings. Investment Banking Clients are companies
A136: from whom Morgan Stanley received investment banking compensation in the last 12 months. Due to rounding
A137: off of decimals, the percentages provided in the "% of total" column may not add up to exactly 100
A138: percent.
A140: Analyst Stock Ratings
A142: Overweight (O). The stock's total return is expected to exceed the average total return of the analyst's
A143: industry (or industry team's) coverage universe, on a risk-adjusted basis, over the next 12-18 months.
A145: Equal-weight (E). The stock's total return is expected to be in line with the average total return of
A146: the analyst's industry (or industry team's) coverage universe, on a risk-adjusted basis, over the next
A147: 12-18 months.
A149: Not-Rated (NR). Currently the analyst does not have adequate conviction about the stock's total return
A150: relative to the average total return of the analyst's industry (or industry team's) coverage universe,
... A396: © Copyright 2018 Morgan Stanley

Sheet Portfolio Manager's Snapshot
B2: James Faucette | H2: Vasu Govil | L2: Priscilla Russo
B3: Executive Director | H3: Vice President | L3: Associate
B4: 212-296-5771 | H4: 212-761-3609 | L4: 212-296-4563
B5: james.faucette@morganstanley.com | H5: vasundhara.govil@morganstanley.com | L5: priscilla.russo@morganstanley.com
B7: Scenario:
B9: PayPal Holdings, Inc. (PYPL)
B11: Financials (FY ended December) | H11: MS Estimates vs. Guidance (YoY % change)
C12: 2016A | D12: 2017A | E12: 2018E | F12: 2019E | H12: F18 | I12: MS | J12: Guidance
B13: Revenue
B14: ='Segment Detail'!B45 -> Transaction Revenue | C14: =+'Segment Detail'!BE45 -> 9585 | D14: =+'Segment Detail'!BJ45 -> 11501 | E14: =+'Segment Detail'!BO45 -> 13995.271 | F14: =+'Segment Detail'!BT45 -> 16676.021 | H14: TPV Growth | I14: ='Segment Detail'!BO7 -> 0.28803568
B15: ='Segment Detail'!B49 -> Other Value-Added Services Revenue | C15: =+'Segment Detail'!BE49 -> 1257 | D15: =+'Segment Detail'!BJ49 -> 1593 | E15: =+'Segment Detail'!BO49 -> 1413.9363 | F15: =+'Segment Detail'!BT49 -> 1078.7399
H16: Revenue Growth | I16: ='Quarterly Model'!BO15 -> 0.18032993 | J16: 16-18%
B17: Net Revenue | C17: =+C14+C15 -> 10842 | D17: =+D14+D15 -> 13094 | E17: =+E14+E15 -> 15409.207 | F17: =+F14+F15 -> 17754.761
B18: YoY % change | C18: =+'Segment Detail'!BE58 -> 0.17236159 | D18: =+'Segment Detail'!BJ58 -> 0.20771075 | E18: =+'Segment Detail'!BO58 -> 0.17681436 | F18: =+'Segment Detail'!BT58 -> 0.15221767 | H18: Non-GAAP Operating Margin | I18: ='Quarterly Model'!BO78 -> 0.22288082
B20: EBITDA (MS method) | C20: =+'Quarterly Model'!BE88 -> 2439 | D20: =+'Quarterly Model'!BJ88 -> 2788 | E20: =+'Quarterly Model'!BO88 -> 2989.6504 | F20: =+'Quarterly Model'!BT88 -> 3599.2249 | H20: Adj. Net Income | I20: ='Quarterly Model'!BO104 -> 2835.8217
B21: EBITDA Margin | C21: =+'Quarterly Model'!BE89 -> 0.10212381 | D21: =+'Quarterly Model'!BJ89 -> 0.14309143 | E21: =+'Quarterly Model'!BO89 -> 0.072327963 | F21: =+'Quarterly Model'!BT89 -> 0.20389492
H22: Adj. EPS | I22: ='Quarterly Model'!BO105 -> 2.3370818 | J22: $2.31-2.34
B23: Operating Income | C23: ='Quarterly Model'!BE76 -> 2174 | D23: ='Quarterly Model'!BJ76 -> 2755 | E23: ='Quarterly Model'!BO76 -> 3434.4167 | F23: ='Quarterly Model'!BT76 -> 4085.5105
B24: Operating Margin | C24: ='Quarterly Model'!BE78 -> 0.20051651 | D24: ='Quarterly Model'!BJ78 -> 0.21103026 | E24: ='Quarterly Model'!BO78 -> 0.22288082 | F24: ='Quarterly Model'!BT78 -> 0.23010789
B26: GAAP Net Income | C26: ='Quarterly Model'!BE137 -> 1402 | D26: ='Quarterly Model'!BJ137 -> 1795 | E26: ='Quarterly Model'!BO137 -> 1935.0938 | F26: ='Quarterly Model'!BT137 -> 2338.5776
B27: YoY % change | C27: 0.15581204 | D27: =D26/C26-1 -> 0.28031384 | E27: =E26/D26-1 -> 0.078046677 | F27: =F26/E26-1 -> 0.20850869
B29: Adjusted Net Income (PayPal Method) | C29: ='Quarterly Model'!BE104 -> 1825 | D29: ='Quarterly Model'!BJ104 -> 2318 | E29: ='Quarterly Model'!BO104 -> 2835.8217 | F29: ='Quarterly Model'!BT104 -> 3288.836
B30: YoY % change | C30: 0.16297345 | D30: =D29/C29-1 -> 0.27013699 | E30: =E29/D29-1 -> 0.22339158 | F30: =F29/E29-1 -> 0.1597471
B32: Adjusted EPS (PayPal Method) | C32: ='Quarterly Model'!BE105 -> 1.4989733 | D32: ='Quarterly Model'!BJ105 -> 1.8992216 | E32: ='Quarterly Model'!BO105 -> 2.3370818 | F32: ='Quarterly Model'!BT105 -> 2.7298345
B33: YoY % change | C33: 0.1725256 | D33: =D32/C32-1 -> 0.26701498 | E33: =E32/D32-1 -> 0.23054716 | F33: =F32/E32-1 -> 0.16805261
B35: Capex | C35: =+'Quarterly Model'!BE180 -> -669 | D35: =+'Quarterly Model'!BJ180 -> -667 | E35: =+'Quarterly Model'!BO180 -> -852.14191 | F35: =+'Quarterly Model'!BT180 -> -976.51184
B36: Capex % of sales | C36: =+'Portfolio Manager''s Snapshot'!C35/'Portfolio Manager''s Snapshot'!C17 -> -0.061704483 | D36: =+'Portfolio Manager''s Snapshot'!D35/'Portfolio Manager''s Snapshot'!D17 -> -0.050939362 | E36: =+'Portfolio Manager''s Snapshot'!E35/'Portfolio Manager''s Snapshot'!E17 -> -0.055300828 | F36: =+'Portfolio Manager''s Snapshot'!F35/'Portfolio Manager''s Snapshot'!F17 -> -0.055
B37: FCFF | C37: =+DCF!G72 -> 1577.3339 | D37: =+DCF!H72 -> 811.77489 | E37: =+DCF!I72 -> 853.5269 | F37: =+DCF!J72 -> 1944.5126
B39: Total assets | C39: =+'Quarterly Model'!BE235 -> 33103 | D39: =+'Quarterly Model'!BJ235 -> 40774 | E39: =+'Quarterly Model'!BO235 -> 43675.527 | F39: =+'Quarterly Model'!BT235 -> 45355.89
B40: Total cash | C40: ='Quarterly Model'!BE220 -> 1590 | D40: ='Quarterly Model'!BJ220 -> 2883 | E40: ='Quarterly Model'!BO220 -> 10141.845 | F40: ='Quarterly Model'!BT220 -> 12035.811
B42: Total liabilities | C42: =+'Quarterly Model'!BE247 -> 18391 | D42: =+'Quarterly Model'!BJ247 -> 24780 | E42: =+'Quarterly Model'!BO247 -> 28043.667 | F42: =+'Quarterly Model'!BT247 -> 27920.167
B43: Total debt | C43: =+'Quarterly Model'!BE259 -> 0 | D43: =+'Quarterly Model'!BJ259 -> 1000 | E43: =+'Quarterly Model'!BO259 -> 3000 | F43: =+'Quarterly Model'!BT259 -> 3000
B44: Total shareholder's equity | C44: =+'Quarterly Model'!BE254 -> 14712 | D44: =+'Quarterly Model'!BJ254 -> 15994 | E44: =+'Quarterly Model'!BO254 -> 15631.86 | F44: =+'Quarterly Model'!BT254 -> 17435.723

Sheet Quarterly Model
B2: Scenario:
C3: 1Q06A | D3: 2Q06A | E3: 3Q06A | F3: 4Q06A | G3: 2006A | H3: 1Q07A | I3: 2Q07A | J3: 3Q07A | K3: 4Q07A | L3: 2007A | M3: 1Q08A | N3: 2Q08A | O3: 3Q08A | P3: 4Q08A | Q3: 2008A | R3: 1Q09A | S3: 2Q09A | T3: 3Q09A | U3: 4Q09A | V3: 2009A | W3: 1Q10A | X3: 2Q10A | Y3: 3Q10A | Z3: 4Q10A | AA3: 2010A | AB3: 1Q11A | AC3: 2Q11A | AD3: 3Q11A | AE3: 4Q11A | AF3: 2011A | AG3: 1Q12A | AH3: 2Q12A | AI3: 3Q12A | AJ3: 4Q12A | AK3: 2012A | AL3: 1Q13A | AM3: 2Q13A | AN3: 3Q13A | AO3: 4Q13A | AP3: 2013A | AQ3: 1Q14A | AR3: 2Q14A | AS3: 3Q14A | AT3: 4Q14A | AU3: 2014A | AV3: 1Q15A | AW3: 2Q15A | AX3: 3Q15A | AY3: 4Q15A | AZ3: 2015A | BA3: 1Q16A | BB3: 2Q16A | BC3: 3Q16A | BD3: 4Q16A | BE3: 2016A | BF3: 1Q17A | BG3: 2Q17A | BH3: 3Q17A | BI3: 4Q17A | BJ3: 2017A | BK3: 1Q18A | BL3: 2Q18E | BM3: 3Q18E | BN3: 4Q18E | BO3: 2018E | BP3: 1Q19E | BQ3: 2Q19E | BR3: 3Q19E | BS3: 4Q19E | BT3: 2019E | BU3: 1Q20E | BV3: 2Q20E | BW3: 3Q20E | BX3: 4Q20E | BY3: 2020E | BZ3: 1Q21E | CA3: 2Q21E | CB3: 3Q21E | CC3: 4Q21E | CD3: 2021E
B4: Income Statement
B5: Fiscal Year End: December ($ in millions, except per share data)
B8: Transaction Revenue | AK8: ='Segment Detail'!AK45 -> 5028 | AP8: ='Segment Detail'!AP45 -> 5992 | AQ8: ='Segment Detail'!AQ45 -> 1671 | AR8: ='Segment Detail'!AR45 -> 1710 | AS8: ='Segment Detail'!AS45 -> 1750 | AT8: ='Segment Detail'!AT45 -> 1963 | AU8: ='Segment Detail'!AU45 -> 7094 | AV8: ='Segment Detail'!AV45 -> 1911 | AW8: ='Segment Detail'!AW45 -> 1966 | ... CD8: ='Segment Detail'!CD45 -> 22411.783
B9: YoY % change | AP9: =IF(ISERROR((AP8/AK8-1)),"NM",(AP8/AK8-1)) -> 0.19172633 | AQ9: =IF(ISERROR((AQ8/AL8-1)),"NM",(AQ8/AL8-1)) -> NM | AU9: =IF(ISERROR((AU8/AP8-1)),"NM",(AU8/AP8-1)) -> 0.18391188 | AV9: =IF(ISERROR((AV8/AQ8-1)),"NM",(AV8/AQ8-1)) -> 0.14362657 | AW9: =IF(ISERROR((AW8/AR8-1)),"NM",(AW8/AR8-1)) -> 0.1497076 | AX9: =IF(ISERROR((AX8/AS8-1)),"NM",(AX8/AS8-1)) -> 0.14514286 | AY9: =IF(ISERROR((AY8/AT8-1)),"NM",(AY8/AT8-1)) -> 0.16454407 | AZ9: =IF(ISERROR((AZ8/AU8-1)),"NM",(AZ8/AU8-1)) -> 0.15830279 | BA9: =IF(ISERROR((BA8/AV8-1)),"NM",(BA8/AV8-1)) -> 0.1826269 | BB9: =IF(ISERROR((BB8/AW8-1)),"NM",(BB8/AW8-1)) -> 0.19379451 | ... CD9: =IF(ISERROR((CD8/BY8-1)),"NM",(CD8/BY8-1)) -> 0.1556825
B11: Other Value-added Services | AK11: ='Segment Detail'!AK49 -> 634 | AP11: ='Segment Detail'!AP49 -> 735 | AQ11: ='Segment Detail'!AQ49 -> 200 | AR11: ='Segment Detail'!AR49 -> 271 | AS11: ='Segment Detail'!AS49 -> 221 | AT11: ='Segment Detail'!AT49 -> 226 | AU11: ='Segment Detail'!AU49 -> 918 | AV11: ='Segment Detail'!AV49 -> 223 | AW11: ='Segment Detail'!AW49 -> 327 | ... BH11: ='Segment Detail'!BH49 -> 381 | BI11: ='Segment Detail'!BI49-39 -> 461 | BJ11: ='Segment Detail'!BJ49-39 -> 1554 | BK11: ='Segment Detail'!BK49 -> 488 | BL11: ='Segment Detail'!BL49 -> 452.98511 | BM11: ='Segment Detail'!BM49 -> 173.69852 | BN11: ='Segment Detail'!BN49 -> 299.25267 | BO11: ='Segment Detail'!BO49 -> 1413.9363 | BP11: ='Segment Detail'!BP49 -> 283.4 | BQ11: ='Segment Detail'!BQ49 -> 237.2575 | BR11: ='Segment Detail'!BR49 -> 204.96425 | ... CD11: ='Segment Detail'!CD49 -> 1439.039
B12: YoY % change | AP12: =IF(ISERROR((AP11/AK11-1)),"NM",(AP11/AK11-1)) -> 0.15930599 | AQ12: =IF(ISERROR((AQ11/AL11-1)),"NM",(AQ11/AL11-1)) -> NM | AU12: =IF(ISERROR((AU11/AP11-1)),"NM",(AU11/AP11-1)) -> 0.24897959 | AV12: =IF(ISERROR((AV11/AQ11-1)),"NM",(AV11/AQ11-1)) -> 0.115 | AW12: =IF(ISERROR((AW11/AR11-1)),"NM",(AW11/AR11-1)) -> 0.20664207 | AX12: =IF(ISERROR((AX11/AS11-1)),"NM",(AX11/AS11-1)) -> 0.14932127 | AY12: =IF(ISERROR((AY11/AT11-1)),"NM",(AY11/AT11-1)) -> 0.19469027 | AZ12: =IF(ISERROR((AZ11/AU11-1)),"NM",(AZ11/AU11-1)) -> 0.12309368 | BA12: =IF(ISERROR((BA11/AV11-1)),"NM",(BA11/AV11-1)) -> 0.2735426 | BB12: =IF(ISERROR((BB11/AW11-1)),"NM",(BB11/AW11-1)) -> -0.073394495 | ... CD12: =IF(ISERROR((CD11/BY11-1)),"NM",(CD11/BY11-1)) -> 0.15
B14: Net Revenue | AK14: =IF(ISERROR(AK11+AK8),"NM",AK11+AK8) -> 5662 | AL14: =IF(ISERROR(AL11+AL8),"NM",AL11+AL8) -> 0 | AM14: =IF(ISERROR(AM11+AM8),"NM",AM11+AM8) -> 0 | AN14: =IF(ISERROR(AN11+AN8),"NM",AN11+AN8) -> 0 | AO14: =IF(ISERROR(AO11+AO8),"NM",AO11+AO8) -> 0 | AP14: =IF(ISERROR(AP11+AP8),"NM",AP11+AP8) -> 6727 | AQ14: =IF(ISERROR(AQ11+AQ8),"NM",AQ11+AQ8) -> 1871 | AR14: =IF(ISERROR(AR11+AR8),"NM",AR11+AR8) -> 1981 | ... CD14: =IF(ISERROR(CD11+CD8),"NM",CD11+CD8) -> 23850.822 | CE14: =(BY14/BE14)^0.25-1 -> 0.17468444
B15: YoY % change | AP15: =IF(ISERROR((AP14/AK14-1)),"NM",(AP14/AK14-1)) -> 0.18809608 | AQ15: =IF(ISERROR(AQ14/AL14-1), "NM", (AQ14/AL14-1)) -> NM | AR15: =IF(ISERROR(AR14/AM14-1), "NM", (AR14/AM14-1)) -> NM | AS15: =IF(ISERROR(AS14/AN14-1), "NM", (AS14/AN14-1)) -> NM | AT15: =IF(ISERROR(AT14/AO14-1), "NM", (AT14/AO14-1)) -> NM | AU15: =IF(ISERROR((AU14/AP14-1)),"NM",(AU14/AP14-1)) -> 0.19102126 | AV15: =IF(ISERROR(AV14/AQ14-1), "NM", (AV14/AQ14-1)) -> 0.14056654 | AW15: =IF(ISERROR(AW14/AR14-1), "NM", (AW14/AR14-1)) -> 0.15749621 | AX15: =IF(ISERROR(AX14/AS14-1), "NM", (AX14/AS14-1)) -> 0.14561136 | AY15: =IF(ISERROR(AY14/AT14-1), "NM", (AY14/AT14-1)) -> 0.16765646 | AZ15: =IF(ISERROR(AZ14/AU14-1), "NM", (AZ14/AU14-1)) -> 0.1542686 | BA15: =IF(ISERROR(BA14/AV14-1), "NM", (BA14/AV14-1)) -> 0.19212746 | BB15: =IF(ISERROR(BB14/AW14-1), "NM", (BB14/AW14-1)) -> 0.15569123 | BC15: =IF(ISERROR(BC14/AX14-1), "NM", (BC14/AX14-1)) -> 0.18113375 | ... CD15: =IF(ISERROR(CD14/BY14-1), "NM", (CD14/BY14-1)) -> 0.15533806
B16: YoY % change (FX neutral) | AV16: 0.17 | AW16: 0.19 | AX16: 0.19 | AY16: 0.21 | AZ16: 0.19 | BA16: 0.23 | BB16: 0.19 | BC16: 0.21 | BD16: 0.19 | BF16: 0.19 | BG16: 0.2 | BH16: 0.22 | BK16: 0.22
B18: Transaction Expense | AK18: 1518 | AP18: 1835 | AQ18: 514 | AR18: 525 | AS18: 537 | AT18: 594 | AU18: =SUM(AQ18:AT18) -> 2170 | AV18: 575 | AW18: 634 | AX18: 651 | AY18: 750 | AZ18: =SUM(AV18:AY18) -> 2610 | BA18: 752 | BB18: 810 | BC18: 830 | BD18: 954 | BE18: =SUM(BA18:BD18) -> 3346 | BF18: 987 | BG18: 1064 | BH18: 1102 | BI18: 1266 | BJ18: =SUM(BF18:BI18) -> 4419 | BK18: 1275 | BL18: =BL20*'Segment Detail'!BL6 -> 1363.6012 | BM18: =BM20*'Segment Detail'!BM6 -> 1430.3215 | BN18: =BN20*'Segment Detail'!BN6 -> 1634.1717 | BO18: =SUM(BK18:BN18) -> 5703.0945 | BP18: =BP20*'Segment Detail'!BP6 -> 1588.3017 | BQ18: =BQ20*'Segment Detail'!BQ6 -> 1691.7633 | BR18: =BR20*'Segment Detail'!BR6 -> 1774.4938 | BS18: =BS20*'Segment Detail'!BS6 -> 2027.3427 | BT18: =SUM(BP18:BS18) -> 7081.9015 | BU18: =BU20*'Segment Detail'!BU6 -> 1926.433 | BV18: =BV20*'Segment Detail'!BV6 -> 2052.9003 | BW18: =BW20*'Segment Detail'!BW6 -> 2118.4087 | BX18: =BX20*'Segment Detail'!BX6 -> 2421.4055 | BY18: =SUM(BU18:BX18) -> 8519.1475 | BZ18: =BZ20*'Segment Detail'!BZ6 -> 2281.2991 | CA18: =CA20*'Segment Detail'!CA6 -> 2430.9746 | CB18: =CB20*'Segment Detail'!CB6 -> 2508.4568 | CC18: =CC20*'Segment Detail'!CC6 -> 2867.1394 | CD18: =SUM(BZ18:CC18) -> 10087.87
B19: YoY % change | AP19: =IF(ISERROR((AP18/AK18-1)),"NM",(AP18/AK18-1)) -> 0.2088274 | AQ19: =IF(ISERROR((AQ18/AL18-1)),"NM",(AQ18/AL18-1)) -> NM | AR19: =IF(ISERROR((AR18/AM18-1)),"NM",(AR18/AM18-1)) -> NM | AS19: =IF(ISERROR((AS18/AN18-1)),"NM",(AS18/AN18-1)) -> NM | AT19: =IF(ISERROR((AT18/AO18-1)),"NM",(AT18/AO18-1)) -> NM | AU19: =IF(ISERROR((AU18/AP18-1)),"NM",(AU18/AP18-1)) -> 0.18256131 | AV19: =IF(ISERROR(AV18/AQ18-1), "NM", (AV18/AQ18-1)) -> 0.11867704 | AW19: =IF(ISERROR(AW18/AR18-1), "NM", (AW18/AR18-1)) -> 0.20761905 | AX19: =IF(ISERROR(AX18/AS18-1), "NM", (AX18/AS18-1)) -> 0.2122905 | AY19: =IF(ISERROR(AY18/AT18-1), "NM", (AY18/AT18-1)) -> 0.26262626 | AZ19: =IF(ISERROR(AZ18/AU18-1), "NM", (AZ18/AU18-1)) -> 0.20276498 | BA19: =IF(ISERROR(BA18/AV18-1), "NM", (BA18/AV18-1)) -> 0.30782609 | BB19: =IF(ISERROR(BB18/AW18-1), "NM", (BB18/AW18-1)) -> 0.27760252 | BC19: =IF(ISERROR(BC18/AX18-1), "NM", (BC18/AX18-1)) -> 0.2749616 | ... CD19: =IF(ISERROR(CD18/BY18-1), "NM", (CD18/BY18-1)) -> 0.18414079
B20: As a % of TPV | AK20: =AK18/'Segment Detail'!AK$6 -> 0.010115549 | AP20: =AP18/'Segment Detail'!AP$6 -> 0.0098865338 | AQ20: =AQ18/'Segment Detail'!AQ$6 -> 0.0095759744 | AR20: =AR18/'Segment Detail'!AR$6 -> 0.0092533841 | AS20: =AS18/'Segment Detail'!AS$6 -> 0.0092293414 | AT20: =AT18/'Segment Detail'!AT$6 -> 0.008994685 | AU20: =AU18/'Segment Detail'!AU$6 -> 0.0092484071 | AV20: =AV18/'Segment Detail'!AV$6 -> 0.0091239428 | AW20: =AW18/'Segment Detail'!AW$6 -> 0.009395098 | ... AY20: =AY18/'Segment Detail'!AY$6 -> 0.0090250535 | AZ20: =AZ18/'Segment Detail'!AZ6 -> 0.0090613044 | BA20: =BA18/'Segment Detail'!BA$6 -> 0.0091086375 | BB20: =BB18/'Segment Detail'!BB$6 -> 0.0092294019 | BC20: =BC18/'Segment Detail'!BC$6 -> 0.0093368581 | BD20: =BD18/'Segment Detail'!BD$6 -> 0.0094726495 | BE20: =BE18/'Segment Detail'!BE6 -> 0.0092963037 | BF20: =BF18/'Segment Detail'!BF$6 -> 0.0098073312 | BG20: =BG18/'Segment Detail'!BG$6 -> 0.0098701299 | BH20: =BH18/'Segment Detail'!BH$6 -> 0.0095639797 | BI20: =BI18/'Segment Detail'!BI$6 -> 0.0095536354 | BJ20: =BJ18/'Segment Detail'!BJ6 -> 0.0096870081 | BK20: =BK18/'Segment Detail'!BK$6 -> 0.0096325285 | BL20: =CHOOSE(_Switch,BL21,BL22,BL23) -> 0.0097011117 | BM20: =CHOOSE(_Switch,BM21,BM22,BM23) -> 0.0097261117 | BN20: =CHOOSE(_Switch,BN21,BN22,BN23) -> 0.0097511117 | BO20: =BO18/'Segment Detail'!BO6 -> 0.0097061799 | BP20: =CHOOSE(_Switch,BP21,BP22,BP23) -> 0.0097761117 | BQ20: =CHOOSE(_Switch,BQ21,BQ22,BQ23) -> 0.0098011117 | BR20: =CHOOSE(_Switch,BR21,BR22,BR23) -> 0.0098261117 | BS20: =CHOOSE(_Switch,BS21,BS22,BS23) -> 0.0098511117 | BT20: =BT18/'Segment Detail'!BT6 -> 0.0098160022 | BU20: =CHOOSE(_Switch,BU21,BU22,BU23) -> 0.0098811117 | BV20: =CHOOSE(_Switch,BV21,BV22,BV23) -> 0.0099111117 | BW20: =CHOOSE(_Switch,BW21,BW22,BW23) -> 0.0099411117 | BX20: =CHOOSE(_Switch,BX21,BX22,BX23) -> 0.0099711117 | BY20: =BY18/'Segment Detail'!BY6 -> 0.0099287271 | BZ20: =CHOOSE(_Switch,BZ21,BZ22,BZ23) -> 0.010001112 | CA20: =CHOOSE(_Switch,CA21,CA22,CA23) -> 0.010031112 | CB20: =CHOOSE(_Switch,CB21,CB22,CB23) -> 0.010061112 | CC20: =CHOOSE(_Switch,CC21,CC22,CC23) -> 0.010091112 | CD20: =CD18/'Segment Detail'!CD6 -> 0.010048727
B21: Bull | BL21: =+BL22-0.0001 -> 0.0096011117 | BM21: =+BM22-0.0001 -> 0.0096261117 | BN21: =+BN22-0.0001 -> 0.0096511117 | BP21: =+BP22-0.0001 -> 0.0096761117 | BQ21: =+BQ22-0.0001 -> 0.0097011117 | BR21: =+BR22-0.0001 -> 0.0097261117 | BS21: =+BS22-0.0001 -> 0.0097511117 | BU21: =+BU22-0.0001 -> 0.0097811117 | BV21: =+BV22-0.0001 -> 0.0098111117 | BW21: =+BW22-0.0001 -> 0.0098411117 | BX21: =+BX22-0.0001 -> 0.0098711117 | BZ21: =+BZ22-0.0001 -> 0.0099011117 | CA21: =+CA22-0.0001 -> 0.0099311117 | CB21: =+CB22-0.0001 -> 0.0099611117 | CC21: =+CC22-0.0001 -> 0.0099911117
B22: Base | BL22: 0.0097011117 | BM22: =+BL22+0.000025 -> 0.0097261117 | BN22: =+BM22+0.000025 -> 0.0097511117 | BP22: =+BN22+0.000025 -> 0.0097761117 | BQ22: =+BP22+0.000025 -> 0.0098011117 | BR22: =+BQ22+0.000025 -> 0.0098261117 | BS22: =+BR22+0.000025 -> 0.0098511117 | BU22: =+BS22+0.00003 -> 0.0098811117 | BV22: =+BU22+0.00003 -> 0.0099111117 | BW22: =+BV22+0.00003 -> 0.0099411117 | BX22: =+BW22+0.00003 -> 0.0099711117 | BZ22: =+BX22+0.00003 -> 0.010001112 | CA22: =+BZ22+0.00003 -> 0.010031112 | CB22: =+CA22+0.00003 -> 0.010061112 | CC22: =+CB22+0.00003 -> 0.010091112
B23: Bear | BL23: =BL22+0.01% -> 0.0098011117 | BM23: =BM22+0.01% -> 0.0098261117 | BN23: =BN22+0.01% -> 0.0098511117 | BP23: =BP22+0.01% -> 0.0098761117 | BQ23: =BQ22+0.01% -> 0.0099011117 | BR23: =BR22+0.01% -> 0.0099261117 | BS23: =BS22+0.01% -> 0.0099511117 | BU23: =BU22+0.01% -> 0.0099811117 | BV23: =BV22+0.01% -> 0.010011112 | BW23: =BW22+0.01% -> 0.010041112 | BX23: =BX22+0.01% -> 0.010071112 | BZ23: =BZ22+0.01% -> 0.010101112 | CA23: =CA22+0.01% -> 0.010131112 | CB23: =CB22+0.01% -> 0.010161112 | CC23: =CC22+0.01% -> 0.010191112
B25: Transaction and Loan Losses | AK25: 365 | AP25: 502 | AQ25: =129+12 -> 141 | AR25: =144+10 -> 154 | AS25: =180+10 -> 190 | AT25: =193+11 -> 204 | AU25: =SUM(AQ25:AT25) -> 689 | AV25: =178+10 -> 188 | AW25: =185+12 -> 197 | AX25: 201 | AY25: 245 | AZ25: =SUM(AV25:AY25) -> 831 | BA25: 255 | BB25: 255 | BC25: 271 | BD25: 307 | BE25: =SUM(BA25:BD25) -> 1088 | BF25: 300 | BG25: 308 | BH25: 363 | BI25: 40 | BJ25: =SUM(BF25:BI25) -> 1011 | BK25: 305 | BL25: =BL27*'Segment Detail'!BL$6 -> 323.29108 | BM25: =BM27*'Segment Detail'!BM$6 -> 338.2379 | BN25: =BN27*'Segment Detail'!BN$6 -> 385.45297 | BO25: =SUM(BK25:BN25) -> 1351.9819 | BP25: =BP27*'Segment Detail'!BP$6 -> 369.61386 | BQ25: =BQ27*'Segment Detail'!BQ$6 -> 392.68621 | BR25: =BR27*'Segment Detail'!BR$6 -> 410.84139 | BS25: =BS27*'Segment Detail'!BS$6 -> 468.19129 | BT25: =SUM(BP25:BS25) -> 1641.3328 | BU25: =BU27*'Segment Detail'!BU$6 -> 443.53664 | BV25: =BV27*'Segment Detail'!BV$6 -> 471.22345 | BW25: =BW27*'Segment Detail'!BW$6 -> 484.79285 | BX25: =BX27*'Segment Detail'!BX$6 -> 552.46572 | BY25: =SUM(BU25:BX25) -> 1952.0187 | BZ25: =BZ27*'Segment Detail'!BZ$6 -> 518.93786 | CA25: =CA27*'Segment Detail'!CA$6 -> 551.33144 | CB25: =CB27*'Segment Detail'!CB$6 -> 567.20763 | CC25: =CC27*'Segment Detail'!CC$6 -> 646.38489 | CD25: =SUM(BZ25:CC25) -> 2283.8618
B26: YoY % change | AP26: =IF(ISERROR(AP25/AK25-1), "NM", (AP25/AK25-1)) -> 0.37534247 | AQ26: =IF(ISERROR(AQ25/AL25-1), "NM", (AQ25/AL25-1)) -> NM | AR26: =IF(ISERROR(AR25/AM25-1), "NM", (AR25/AM25-1)) -> NM | AS26: =IF(ISERROR(AS25/AN25-1), "NM", (AS25/AN25-1)) -> NM | AT26: =IF(ISERROR(AT25/AO25-1), "NM", (AT25/AO25-1)) -> NM | AU26: =IF(ISERROR(AU25/AP25-1), "NM", (AU25/AP25-1)) -> 0.37250996 | AV26: =IF(ISERROR(AV25/AQ25-1), "NM", (AV25/AQ25-1)) -> 0.33333333 | AW26: =IF(ISERROR(AW25/AR25-1), "NM", (AW25/AR25-1)) -> 0.27922078 | ... CD26: =IF(ISERROR(CD25/BY25-1), "NM", (CD25/BY25-1)) -> 0.17
B27: As a % of TPV | AK27: =AK25/'Segment Detail'!AK$6 -> 0.0024322631 | AP27: =AP25/'Segment Detail'!AP$6 -> 0.0027046539 | AQ27: =AQ25/'Segment Detail'!AQ$6 -> 0.0026268723 | AR27: =AR25/'Segment Detail'!AR$6 -> 0.002714326 | AS27: =AS25/'Segment Detail'!AS$6 -> 0.0032655025 | AT27: =AT25/'Segment Detail'!AT$6 -> 0.0030890837 | AU27: =AU25/'Segment Detail'!AU$6 -> 0.0029364758 | AV27: =AV25/'Segment Detail'!AV$6 -> 0.0029831326 | AW27: =AW25/'Segment Detail'!AW$6 -> 0.002919297 | ... BK27: =BK25/'Segment Detail'!BK$6 -> 0.0023042519 | BL27: =CHOOSE(_Switch,BL28,BL29,BL30) -> 0.0023 | BM27: =CHOOSE(_Switch,BM28,BM29,BM30) -> 0.0023 | BN27: =CHOOSE(_Switch,BN28,BN29,BN30) -> 0.0023 | BO27: =BO25/'Segment Detail'!BO$6 -> 0.0023009578 | BP27: =CHOOSE(_Switch,BP28,BP29,BP30) -> 0.002275 | BQ27: =CHOOSE(_Switch,BQ28,BQ29,BQ30) -> 0.002275 | BR27: =CHOOSE(_Switch,BR28,BR29,BR30) -> 0.002275 | BS27: =CHOOSE(_Switch,BS28,BS29,BS30) -> 0.002275 | BT27: =BT25/'Segment Detail'!BT$6 -> 0.002275 | BU27: =CHOOSE(_Switch,BU28,BU29,BU30) -> 0.002275 | BV27: =CHOOSE(_Switch,BV28,BV29,BV30) -> 0.002275 | BW27: =CHOOSE(_Switch,BW28,BW29,BW30) -> 0.002275 | BX27: =CHOOSE(_Switch,BX28,BX29,BX30) -> 0.002275 | BY27: =BY25/'Segment Detail'!BY$6 -> 0.002275 | BZ27: =CHOOSE(_Switch,BZ28,BZ29,BZ30) -> 0.002275 | CA27: =CHOOSE(_Switch,CA28,CA29,CA30) -> 0.002275 | CB27: =CHOOSE(_Switch,CB28,CB29,CB30) -> 0.002275 | CC27: =CHOOSE(_Switch,CC28,CC29,CC30) -> 0.002275 | CD27: =CD25/'Segment Detail'!CD$6 -> 0.002275
B28: Bull | BL28: =BL29-0.005% -> 0.00225 | BM28: =BM29-0.005% -> 0.00225 | BN28: =BN29-0.005% -> 0.00225 | BP28: =BP29-0.005% -> 0.002225 | BQ28: =BQ29-0.005% -> 0.002225 | BR28: =BR29-0.005% -> 0.002225 | BS28: =BS29-0.005% -> 0.002225 | BU28: =BU29-0.005% -> 0.002225 | BV28: =BV29-0.005% -> 0.002225 | BW28: =BW29-0.005% -> 0.002225 | BX28: =BX29-0.005% -> 0.002225 | BZ28: =BZ29-0.005% -> 0.002225 | CA28: =CA29-0.005% -> 0.002225 | CB28: =CB29-0.005% -> 0.002225 | CC28: =CC29-0.005% -> 0.002225
B29: Base | BL29: 0.0023 | BM29: =BL29 -> 0.0023 | BN29: =BM29 -> 0.0023 | BP29: =BN29-0.000025 -> 0.002275 | BQ29: =BP29 -> 0.002275 | BR29: =BQ29 -> 0.002275 | BS29: =BR29 -> 0.002275 | BU29: =BS29 -> 0.002275 | BV29: =BU29 -> 0.002275 | BW29: =BV29 -> 0.002275 | BX29: =BW29 -> 0.002275 | BZ29: =BX29 -> 0.002275 | CA29: =BZ29 -> 0.002275 | CB29: =CA29 -> 0.002275 | CC29: =CB29 -> 0.002275 | CE29: =(CD18+CD25+CD37+CD44+CD51+CD58+CD72)/'Take Rate Drivers'!BY6 -> 0.020806383
B30: Bear | BL30: =BL29+0.015% -> 0.00245 | BM30: =BM29+0.015% -> 0.00245 | BN30: =BN29+0.015% -> 0.00245 | BP30: =BP29+0.015% -> 0.002425 | BQ30: =BQ29+0.015% -> 0.002425 | BR30: =BR29+0.015% -> 0.002425 | BS30: =BS29+0.015% -> 0.002425 | BU30: =BU29+0.015% -> 0.002425 | BV30: =BV29+0.015% -> 0.002425 | BW30: =BW29+0.015% -> 0.002425 | BX30: =BX29+0.015% -> 0.002425 | BZ30: =BZ29+0.015% -> 0.002425 | CA30: =CA29+0.015% -> 0.002425 | CB30: =CB29+0.015% -> 0.002425 | CC30: =CC29+0.015% -> 0.002425
B31: Loan Losses (included in above) | AK31: 134 | AP31: 194 | AQ31: 49 | AU31: 239 | AV31: 71
B33: Gross Profit | AK33: =AK14-AK18-AK25 -> 3779 | AL33: =AL14-AL18-AL25 -> 0 | AM33: =AM14-AM18-AM25 -> 0 | AN33: =AN14-AN18-AN25 -> 0 | AO33: =AO14-AO18-AO25 -> 0 | AP33: =AP14-AP18-AP25 -> 4390 | AQ33: =AQ14-AQ18-AQ25 -> 1216 | AR33: =AR14-AR18-AR25 -> 1302 | ... CD33: =CD14-CD18-CD25 -> 11479.09
B34: Gross Profit Margin ("Transaction Margin") | AK34: =AK33/AK14 -> 0.667432 | AP34: =AP33/AP14 -> 0.65259402 | AQ34: =AQ33/AQ14 -> 0.64991983 | AR34: =AR33/AR14 -> 0.65724382 | AS34: =AS33/AS14 -> 0.6311517 | AT34: =AT33/AT14 -> 0.63544998 | AU34: =AU33/AU14 -> 0.64316026 | AV34: =AV33/AV14 -> 0.64245548 | AW34: =AW33/AW14 -> 0.63759267 | ... CD34: =CD33/CD14 -> 0.48128698
B35: As a % of TPV | AU35: =+AU33/'Segment Detail'!AU6 -> 0.02196177 | AV35: =+AV33/'Segment Detail'!AV6 -> 0.021754653 | AW35: =+AW33/'Segment Detail'!AW6 -> 0.021665037 | AX35: =+AX33/'Segment Detail'!AX6 -> 0.019714795 | AY35: =+AY33/'Segment Detail'!AY6 -> 0.018784145 | AZ35: =+AZ33/'Segment Detail'!AZ6 -> 0.020160534 | BA35: =+BA33/'Segment Detail'!BA6 -> 0.018616989 | BB35: =+BB33/'Segment Detail'!BB6 -> 0.018060003 | ... CD35: =+CD33/'Segment Detail'!CD6 -> 0.011434549
B37: Customer Support and Operations | AK37: =814-49 -> 765 | AP37: =950-74 -> 876 | AQ37: =237-15+2 -> 224 | AR37: =246-12+2 -> 236 | AS37: =244-12+4 -> 236 | AT37: =264-13+5 -> 256 | AU37: =SUM(AQ37:AT37) -> 952 | AV37: =249-14+3 -> 238 | AW37: =278+5-17 -> 266 | AX37: =284-16 -> 268 | AY37: =299-18 -> 281 | AZ37: =SUM(AV37:AY37) -> 1053 | BA37: =296-18 -> 278 | BB37: =318-22 -> 296 | BC37: =325-21 -> 304 | BD37: =328-24 -> 304 | BE37: =SUM(BA37:BD37) -> 1182 | BF37: =317-30 -> 287 | BG37: =335-34 -> 301 | BH37: =346-38 -> 308 | BI37: =366-40 -> 326 | BJ37: =SUM(BF37:BI37) -> 1222 | BK37: =351-38 -> 313 | BL37: =BL39*BL$14 -> 328.52405 | BM37: =BM39*BM$14 -> 302.4296 | BN37: =BN39*BN$14 -> 341.40268 | BO37: =SUM(BK37:BN37) -> 1285.3563 | BP37: =BP39*BP$14 -> 341.26929 | BQ37: =BQ39*BQ$14 -> 335.22471 | BR37: =BR39*BR$14 -> 330.08756 | BS37: =BS39*BS$14 -> 371.94023 | BT37: =SUM(BP37:BS37) -> 1378.5218 | BU37: =BU39*BU$14 -> 365.56097 | BV37: =BV39*BV$14 -> 358.44768 | BW37: =BW39*BW$14 -> 345.35737 | BX37: =BX39*BX$14 -> 389.39483 | BY37: =SUM(BU37:BX37) -> 1458.7608 | BZ37: =BZ39*BZ$14 -> 373.49579 | CA37: =CA39*CA$14 -> 363.91453 | CB37: =CB39*CB$14 -> 350.65045 | CC37: =CC39*CC$14 -> 394.20011 | CD37: =SUM(BZ37:CC37) -> 1482.2609
B38: YoY % change | AP38: =IF(ISERROR(AP37/AK37-1), "NM", (AP37/AK37-1)) -> 0.14509804 | AQ38: =IF(ISERROR(AQ37/AL37-1), "NM", (AQ37/AL37-1)) -> NM | AR38: =IF(ISERROR(AR37/AM37-1), "NM", (AR37/AM37-1)) -> NM | AS38: =IF(ISERROR(AS37/AN37-1), "NM", (AS37/AN37-1)) -> NM | AT38: =IF(ISERROR(AT37/AO37-1), "NM", (AT37/AO37-1)) -> NM | AU38: =IF(ISERROR(AU37/AP37-1), "NM", (AU37/AP37-1)) -> 0.086757991 | AV38: =IF(ISERROR(AV37/AQ37-1), "NM", (AV37/AQ37-1)) -> 0.0625 | AW38: =IF(ISERROR(AW37/AR37-1), "NM", (AW37/AR37-1)) -> 0.12711864 | ... CD38: =IF(ISERROR(CD37/BY37-1), "NM", (CD37/BY37-1)) -> 0.016109584
B39: as a % of net revenue | AK39: =AK37/AK$14 -> 0.13511127 | AP39: =AP37/AP$14 -> 0.1302215 | AQ39: =AQ37/AQ$14 -> 0.11972207 | AR39: =AR37/AR$14 -> 0.11913175 | AS39: =AS37/AS$14 -> 0.11973617 | AT39: =AT37/AT$14 -> 0.11694838 | AU39: =AU37/AU$14 -> 0.11882177 | AV39: =AV37/AV$14 -> 0.11152765 | AW39: =AW37/AW$14 -> 0.11600523 | ... BK39: =BK37/BK$14 -> 0.084938942 | BL39: =CHOOSE(_Switch,BL40,BL41,BL42) -> 0.085982143 | BM39: =CHOOSE(_Switch,BM40,BM41,BM42) -> 0.082591077 | BN39: =CHOOSE(_Switch,BN40,BN41,BN42) -> 0.080489204 | BO39: =BO37/BO$14 -> 0.083414825 | BP39: =CHOOSE(_Switch,BP40,BP41,BP42) -> 0.083592334 | BQ39: =CHOOSE(_Switch,BQ40,BQ41,BQ42) -> 0.078982143 | BR39: =CHOOSE(_Switch,BR40,BR41,BR42) -> 0.075591077 | BS39: =CHOOSE(_Switch,BS40,BS41,BS42) -> 0.073489204 | BT39: =BT37/BT$14 -> 0.077642375 | BU39: =CHOOSE(_Switch,BU40,BU41,BU42) -> 0.076592334 | BV39: =CHOOSE(_Switch,BV40,BV41,BV42) -> 0.071982143 | BW39: =CHOOSE(_Switch,BW40,BW41,BW42) -> 0.068591077 | BX39: =CHOOSE(_Switch,BX40,BX41,BX42) -> 0.066489204 | BY39: =BY37/BY$14 -> 0.070662635 | BZ39: =CHOOSE(_Switch,BZ40,BZ41,BZ42) -> 0.068092334 | CA39: =CHOOSE(_Switch,CA40,CA41,CA42) -> 0.063482143 | CB39: =CHOOSE(_Switch,CB40,CB41,CB42) -> 0.060091077 | CC39: =CHOOSE(_Switch,CC40,CC41,CC42) -> 0.057989204 | CD39: =CD37/CD$14 -> 0.062147161
B40: Bull | BL40: =BL41-0.005 -> 0.080982143 | BM40: =BM41-0.005 -> 0.077591077 | BN40: =BN41-0.005 -> 0.075489204 | BP40: =BP41-0.0035 -> 0.080092334 | BQ40: =BQ41-0.0035 -> 0.075482143 | BR40: =BR41-0.0035 -> 0.072091077 | BS40: =BS41-0.0035 -> 0.069989204 | BU40: =BU41-0.0035 -> 0.073092334 | BV40: =BV41-0.0035 -> 0.068482143 | BW40: =BW41-0.0035 -> 0.065091077 | BX40: =BX41-0.0035 -> 0.062989204 | BZ40: =BZ41-0.0035 -> 0.064592334 | CA40: =CA41-0.0035 -> 0.059982143 | CB40: =CB41-0.0035 -> 0.056591077 | CC40: =CC41-0.0035 -> 0.054489204
B41: Base | BL41: =+BG39-0.01 -> 0.085982143 | BM41: =+BH39-0.0125 -> 0.082591077 | BN41: =+BI39-0.0075 -> 0.080489204 | BP41: =+BK38-0.007 -> 0.083592334 | BQ41: =+BL41-0.007 -> 0.078982143 | BR41: =+BM41-0.007 -> 0.075591077 | BS41: =+BN41-0.007 -> 0.073489204 | BU41: =+BP41-0.007 -> 0.076592334 | BV41: =+BQ41-0.007 -> 0.071982143 | BW41: =+BR41-0.007 -> 0.068591077 | BX41: =+BS41-0.007 -> 0.066489204 | BZ41: =+BU41-0.0085 -> 0.068092334 | CA41: =+BV41-0.0085 -> 0.063482143 | CB41: =+BW41-0.0085 -> 0.060091077 | CC41: =+BX41-0.0085 -> 0.057989204
B42: Bear | BL42: =+BL41*0.98 -> 0.0842625 | BM42: =+BM41*0.98 -> 0.080939256 | BN42: =+BN41*0.98 -> 0.07887942 | BP42: =+BP41*0.98 -> 0.081920488 | BQ42: =+BQ41*0.98 -> 0.0774025 | BR42: =+BR41*0.98 -> 0.074079256 | BS42: =+BS41*0.98 -> 0.07201942 | BU42: =+BU41*0.98 -> 0.075060488 | BV42: =+BV41*0.98 -> 0.0705425 | BW42: =+BW41*0.98 -> 0.067219256 | BX42: =+BX41*0.98 -> 0.06515942 | BZ42: =+BZ41*0.98 -> 0.066730488 | CA42: =+CA41*0.98 -> 0.0622125 | CB42: =+CB41*0.98 -> 0.058889256 | CC42: =+CC41*0.98 -> 0.05682942
B44: Sales and Marketing | AK44: =662-43 -> 619 | AP44: =791-46 -> 745 | AQ44: =202-12-17 -> 173 | AR44: =239-14-15 -> 210 | AS44: =255-14-13 -> 228 | AT44: =258-19-15 -> 224 | AU44: =SUM(AQ44:AT44) -> 835 | AV44: =222-13-13 -> 196 | AW44: =234-11-12 -> 211 | AX44: =226-18 -> 208 | AY44: =255-10 -> 245 | AZ44: =SUM(AV44:AY44) -> 860 | BA44: =233-16 -> 217 | BB44: =250-22 -> 228 | BC44: =233-21 -> 212 | BD44: =253-25 -> 228 | BE44: =SUM(BA44:BD44) -> 885 | BF44: =238-28 -> 210 | BG44: =284-33 -> 251 | BH44: =278-36 -> 242 | BI44: =328-43 -> 285 | BJ44: =SUM(BF44:BI44) -> 988 | BK44: =285-44 -> 241 | BL44: =BL46*BL$14 -> 286.70924 | BM44: =BM46*BM$14 -> 255.27823 | BN44: =BN46*BN$14 -> 305.06863 | BO44: =SUM(BK44:BN44) -> 1088.0561 | BP44: =BP46*BP$14 -> 246.5867 | BQ44: =BQ46*BQ$14 -> 297.26412 | BR44: =BR46*BR$14 -> 282.59188 | BS44: =BS46*BS$14 -> 338.70805 | BT44: =SUM(BP44:BS44) -> 1165.1507 | BU44: =BU46*BU$14 -> 264.41519 | BV44: =BV46*BV$14 -> 323.86943 | BW44: =BW46*BW$14 -> 300.66322 | BX44: =BX46*BX$14 -> 362.65325 | BY44: =SUM(BU44:BX44) -> 1251.6011 | BZ44: =BZ46*BZ$14 -> 276.4524 | CA44: =CA46*CA$14 -> 344.17233 | CB44: =CB46*CB$14 -> 319.27594 | CC44: =CC46*CC$14 -> 386.95277 | CD44: =SUM(BZ44:CC44) -> 1326.8534
B45: YoY % change | AP45: =IF(ISERROR(AP44/AK44-1), "NM", (AP44/AK44-1)) -> 0.20355412 | AQ45: =IF(ISERROR(AQ44/AL44-1), "NM", (AQ44/AL44-1)) -> NM | AR45: =IF(ISERROR(AR44/AM44-1), "NM", (AR44/AM44-1)) -> NM | AS45: =IF(ISERROR(AS44/AN44-1), "NM", (AS44/AN44-1)) -> NM | AT45: =IF(ISERROR(AT44/AO44-1), "NM", (AT44/AO44-1)) -> NM | AU45: =IF(ISERROR(AU44/AP44-1), "NM", (AU44/AP44-1)) -> 0.12080537 | AV45: =IF(ISERROR(AV44/AQ44-1), "NM", (AV44/AQ44-1)) -> 0.13294798 | AW45: =IF(ISERROR(AW44/AR44-1), "NM", (AW44/AR44-1)) -> 0.0047619048 | ... CD45: =IF(ISERROR(CD44/BY44-1), "NM", (CD44/BY44-1)) -> 0.060124867
B46: as a % of net revenue | AK46: =AK44/AK$14 -> 0.10932533 | AP46: =AP44/AP$14 -> 0.11074773 | AQ46: =AQ44/AQ$14 -> 0.092463923 | AR46: =AR44/AR$14 -> 0.10600707 | AS46: =AS44/AS$14 -> 0.11567732 | AT46: =AT44/AT$14 -> 0.10232983 | AU46: =AU44/AU$14 -> 0.10421867 | AV46: =AV44/AV$14 -> 0.091846298 | AW46: =AW44/AW$14 -> 0.092019189 | ... BK46: =BK44/BK$14 -> 0.065400271 | BL46: =CHOOSE(_Switch,BL47,BL48,BL49) -> 0.075038265 | BM46: =CHOOSE(_Switch,BM47,BM48,BM49) -> 0.069714418 | BN46: =CHOOSE(_Switch,BN47,BN48,BN49) -> 0.071923077 | BO46: =BO44/BO$14 -> 0.070610777 | BP46: =CHOOSE(_Switch,BP47,BP48,BP49) -> 0.060400271 | BQ46: =CHOOSE(_Switch,BQ47,BQ48,BQ49) -> 0.070038265 | BR46: =CHOOSE(_Switch,BR47,BR48,BR49) -> 0.064714418 | BS46: =CHOOSE(_Switch,BS47,BS48,BS49) -> 0.066923077 | BT46: =BT44/BT$14 -> 0.065624694 | BU46: =CHOOSE(_Switch,BU47,BU48,BU49) -> 0.055400271 | BV46: =CHOOSE(_Switch,BV47,BV48,BV49) -> 0.065038265 | BW46: =CHOOSE(_Switch,BW47,BW48,BW49) -> 0.059714418 | BX46: =CHOOSE(_Switch,BX47,BX48,BX49) -> 0.061923077 | BY46: =BY44/BY$14 -> 0.060627779 | BZ46: =CHOOSE(_Switch,BZ47,BZ48,BZ49) -> 0.050400271 | CA46: =CHOOSE(_Switch,CA47,CA48,CA49) -> 0.060038265 | CB46: =CHOOSE(_Switch,CB47,CB48,CB49) -> 0.054714418 | CC46: =CHOOSE(_Switch,CC47,CC48,CC49) -> 0.056923077 | CD46: =CD44/CD$14 -> 0.055631351
B47: Bull | BL47: =BL48-0.002 -> 0.073038265 | BM47: =BM48-0.002 -> 0.067714418 | BN47: =BN48-0.002 -> 0.069923077 | BP47: =BP48-0.0005 -> 0.059900271 | BQ47: =BQ48-0.0005 -> 0.069538265 | BR47: =BR48-0.0005 -> 0.064214418 | BS47: =BS48-0.0005 -> 0.066423077 | BU47: =BU48-0.0005 -> 0.054900271 | BV47: =BV48-0.0005 -> 0.064538265 | BW47: =BW48-0.0005 -> 0.059214418 | BX47: =BX48-0.0005 -> 0.061423077 | BZ47: =BZ48-0.0005 -> 0.049900271 | CA47: =CA48-0.0005 -> 0.059538265 | CB47: =CB48-0.0005 -> 0.054214418 | CC47: =CC48-0.0005 -> 0.056423077
B48: Base | BL48: =+BG46-0.5% -> 0.075038265 | BM48: =+BH46-0.5% -> 0.069714418 | BN48: =+BI46-0.5% -> 0.071923077 | BP48: =+BK46-0.5% -> 0.060400271 | BQ48: =+BL48-0.5% -> 0.070038265 | BR48: =+BM48-0.5% -> 0.064714418 | BS48: =+BN48-0.5% -> 0.066923077 | BU48: =+BP48-0.5% -> 0.055400271 | BV48: =+BQ48-0.5% -> 0.065038265 | BW48: =+BR48-0.5% -> 0.059714418 | BX48: =+BS48-0.5% -> 0.061923077 | BZ48: =+BU48-0.5% -> 0.050400271 | CA48: =+BV48-0.5% -> 0.060038265 | CB48: =+BW48-0.5% -> 0.054714418 | CC48: =+BX48-0.5% -> 0.056923077
B49: Bear | BL49: =BL48+0.003 -> 0.078038265 | BM49: =BM48+0.003 -> 0.072714418 | BN49: =BN48+0.003 -> 0.074923077 | BP49: =BP48+0.003 -> 0.063400271 | BQ49: =BQ48+0.003 -> 0.073038265 | BR49: =BR48+0.003 -> 0.067714418 | BS49: =BS48+0.003 -> 0.069923077 | BU49: =BU48+0.003 -> 0.058400271 | BV49: =BV48+0.003 -> 0.068038265 | BW49: =BW48+0.003 -> 0.062714418 | BX49: =BX48+0.003 -> 0.064923077 | BZ49: =BZ48+0.003 -> 0.053400271 | CA49: =CA48+0.003 -> 0.063038265 | CB49: =CB48+0.003 -> 0.057714418 | CC49: =CC48+0.003 -> 0.059923077
B51: Product Development | AK51: =677-60 -> 617 | AP51: =727-87 -> 640 | AQ51: =165-24 -> 141 | AR51: =189-28 -> 161 | AS51: =192-28 -> 164 | AT51: =201-28 -> 173 | AU51: =SUM(AQ51:AT51) -> 639 | AV51: =185-29 -> 156 | AW51: =202-35 -> 167 | AX51: =197-33 -> 164 | AY51: =208-35 -> 173 | AZ51: =SUM(AV51:AY51) -> 660 | BA51: =195-33 -> 162 | BB51: =209-35 -> 174 | BC51: =215-34 -> 181 | BD51: =215-37 -> 178 | BE51: =SUM(BA51:BD51) -> 695 | BF51: =214-45 -> 169 | BG51: =232-59 -> 173 | BH51: =240-64 -> 176 | BI51: =267-72 -> 195 | BJ51: =SUM(BF51:BI51) -> 713 | BK51: =258-64 -> 194 | BL51: =BL53*BL$14 -> 195.49642 | BM51: =BM53*BM$14 -> 180.66357 | BN51: =BN53*BN$14 -> 202.03391 | BO51: =SUM(BK51:BN51) -> 772.1939 | BP51: =BP53*BP$14 -> 195.00618 | BQ51: =BQ53*BQ$14 -> 196.45136 | BR51: =BR53*BR$14 -> 194.13605 | BS51: =BS53*BS$14 -> 216.37236 | BT51: =SUM(BP51:BS51) -> 801.96595 | BU51: =BU53*BU$14 -> 208.88632 | BV51: =BV53*BV$14 -> 210.56963 | BW51: =BW53*BW$14 -> 203.70558 | BX51: =BX53*BX$14 -> 226.94909 | BY51: =SUM(BU51:BX51) -> 850.11061 | BZ51: =BZ53*BZ$14 -> 215.37863 | CA51: =CA53*CA$14 -> 216.60907 | CB51: =CB53*CB$14 -> 209.8249 | CC51: =CC53*CC$14 -> 232.83603 | CD51: =SUM(BZ51:CC51) -> 874.64863
...

Sheet Segment Detail
B1: Segment Detail
B2: Fiscal Year End: December ($ in millions, except per share data)
B3: Scenario:
C4: 1Q06A | D4: 2Q06A | E4: 3Q06A | F4: 4Q06A | G4: 2006A | H4: 1Q07A | I4: 2Q07A | J4: 3Q07A | K4: 4Q07A | L4: 2007A | M4: 1Q08A | N4: 2Q08A | O4: 3Q08A | P4: 4Q08A | Q4: 2008A | R4: 1Q09A | S4: 2Q09A | T4: 3Q09A | U4: 4Q09A | V4: 2009A | W4: 1Q10A | X4: 2Q10A | Y4: 3Q10A | Z4: 4Q10A | AA4: 2010A | AB4: 1Q11A | AC4: 2Q11A | AD4: 3Q11A | AE4: 4Q11A | AF4: 2011A | AG4: 1Q12A | AH4: 2Q12A | AI4: 3Q12A | AJ4: 4Q12A | AK4: ='Quarterly Model'!AK3 -> 2012A | AL4: 1Q13A | AM4: 2Q13A | AN4: 3Q13A | AO4: 4Q13A | AP4: ='Quarterly Model'!AP3 -> 2013A | AQ4: ='Quarterly Model'!AQ3 -> 1Q14A | AR4: ='Quarterly Model'!AR3 -> 2Q14A | AS4: ='Quarterly Model'!AS3 -> 3Q14A | AT4: ='Quarterly Model'!AT3 -> 4Q14A | AU4: ='Quarterly Model'!AU3 -> 2014A | AV4: ='Quarterly Model'!AV3 -> 1Q15A | AW4: ='Quarterly Model'!AW3 -> 2Q15A | ... CD4: ='Quarterly Model'!CD3 -> 2021E
B5: Revenue Drivers
B6: TPV | AK6: 150066 | AP6: 185606 | AQ6: 53676 | AR6: 56736 | AS6: 58184 | AT6: 66039 | AU6: 234635 | AV6: 63021 | AW6: 67482 | AX6: 71317 | AY6: 83102 | AZ6: 288038 | BA6: 82559 | BB6: 87763 | BC6: 88895 | BD6: 100711 | BE6: =SUM(BA6:BD6) -> 359928 | BF6: 100639 | BG6: 107800 | BH6: 115224 | BI6: 132515 | BJ6: =SUM(BF6:BI6) -> 456178 | BK6: 132364 | BL6: =+BG6*(1+BL7) -> 140561.34 | BM6: =+BH6*(1+BM7) -> 147059.95 | BN6: =+BI6*(1+BN7) -> 167588.25 | BO6: =SUM(BK6:BN6) -> 587573.54 | BP6: =+BK6*(1+BP7) -> 162467.63 | BQ6: =+BL6*(1+BQ7) -> 172609.32 | BR6: =+BM6*(1+BR7) -> 180589.62 | BS6: =+BN6*(1+BS7) -> 205798.37 | BT6: =SUM(BP6:BS6) -> 721464.95 | BU6: =+BP6*(1+BU7) -> 194961.16 | BV6: =+BQ6*(1+BV7) -> 207131.19 | BW6: =+BR6*(1+BW7) -> 213095.76 | BX6: =+BS6*(1+BX7) -> 242842.07 | BY6: =SUM(BU6:BX6) -> 858030.18 | BZ6: =+BU6*(1+BZ7) -> 228104.56 | CA6: =+BV6*(1+CA7) -> 242343.49 | CB6: =+BW6*(1+CB7) -> 249322.04 | CC6: =+BX6*(1+CC7) -> 284125.23 | CD6: =SUM(BZ6:CC6) -> 1003895.3 | CE6: =+(BO6/AZ6)^(0.33333)-1 -> 0.26824487
B7: YoY % change | AP7: =IF(ISERROR(AP6/AK6-1), "NM", (AP6/AK6-1)) -> 0.23682913 | AU7: =IF(ISERROR(AU6/AP6-1), "NM", (AU6/AP6-1)) -> 0.26415633 | AV7: =IF(ISERROR(AV6/AQ6-1), "NM", (AV6/AQ6-1)) -> 0.17410016 | AW7: =IF(ISERROR(AW6/AR6-1), "NM", (AW6/AR6-1)) -> 0.18940355 | AX7: =IF(ISERROR(AX6/AS6-1), "NM", (AX6/AS6-1)) -> 0.22571497 | AY7: =IF(ISERROR(AY6/AT6-1), "NM", (AY6/AT6-1)) -> 0.25837763 | AZ7: =+AZ6/AU6-1 -> 0.22760032 | BA7: =IF(ISERROR(BA6/AV6-1), "NM", (BA6/AV6-1)) -> 0.31002364 | BB7: =IF(ISERROR(BB6/AW6-1), "NM", (BB6/AW6-1)) -> 0.3005394 | BC7: =IF(ISERROR(BC6/AX6-1), "NM", (BC6/AX6-1)) -> 0.246477 | BD7: =IF(ISERROR(BD6/AY6-1), "NM", (BD6/AY6-1)) -> 0.21189622 | BE7: =IF(ISERROR(BE6/AZ6-1), "NM", (BE6/AZ6-1)) -> 0.24958512 | BF7: =IF(ISERROR(BF6/BA6-1), "NM", (BF6/BA6-1)) -> 0.2189949 | BG7: =IF(ISERROR(BG6/BB6-1), "NM", (BG6/BB6-1)) -> 0.22830806 | BH7: =IF(ISERROR(BH6/BC6-1), "NM", (BH6/BC6-1)) -> 0.29618089 | ... BK7: =IF(ISERROR(BK6/BF6-1), "NM", (BK6/BF6-1)) -> 0.31523564 | BL7: =+BL8+BL12 -> 0.30390851 | BM7: =+BM8+BM12 -> 0.27629621 | BN7: =+BN8+BN12 -> 0.2646738 | BO7: =IF(ISERROR(BO6/BJ6-1), "NM", (BO6/BJ6-1)) -> 0.28803568 | BP7: =+BP8+BP12 -> 0.22743066 | BQ7: =+BQ8+BQ12 -> 0.228 | BR7: =+BR8+BR12 -> 0.228 | BS7: =+BS8+BS12 -> 0.228 | BT7: =IF(ISERROR(BT6/BO6-1), "NM", (BT6/BO6-1)) -> 0.22787174 | BU7: =+BU8+BU12 -> 0.2 | BV7: =+BV8+BV12 -> 0.2 | BW7: =+BW8+BW12 -> 0.18 | BX7: =+BX8+BX12 -> 0.18 | BY7: =IF(ISERROR(BY6/BT6-1), "NM", (BY6/BT6-1)) -> 0.18928879 | BZ7: =+BZ8+BZ12 -> 0.17 | CA7: =+CA8+CA12 -> 0.17 | CB7: =+CB8+CB12 -> 0.17 | CC7: =+CC8+CC12 -> 0.17 | CD7: =IF(ISERROR(CD6/BY6-1), "NM", (CD6/BY6-1)) -> 0.17
B8: YoY % change (ex-FX) | AR8: 0.26 | AS8: 0.27 | AT8: 0.26 | AV8: 0.25 | AW8: 0.27 | AX8: 0.27 | AY8: 0.29 | AZ8: =+AZ7-AZ179 -> 0.28433401 | BA8: 0.31 | BB8: 0.29 | BC8: 0.27 | BD8: 0.25 | BE8: 0.28 | BF8: 0.24 | BG8: 0.25 | BH8: 0.28 | BI8: 0.29 | BJ8: 0.27 | BK8: 0.27 | BL8: =CHOOSE(_Switch,BL9,BL10,BL11) -> 0.2575 | BM8: =CHOOSE(_Switch,BM9,BM10,BM11) -> 0.2475 | BN8: =CHOOSE(_Switch,BN9,BN10,BN11) -> 0.24 | BO8: =+BO7-BO179 -> 0.25099666 | BP8: =CHOOSE(_Switch,BP9,BP10,BP11) -> 0.228 | BQ8: =CHOOSE(_Switch,BQ9,BQ10,BQ11) -> 0.228 | BR8: =CHOOSE(_Switch,BR9,BR10,BR11) -> 0.228 | BS8: =CHOOSE(_Switch,BS9,BS10,BS11) -> 0.228 | BT8: =+BT7-BT179 -> 0.228 | BU8: =CHOOSE(_Switch,BU9,BU10,BU11) -> 0.2 | BV8: =CHOOSE(_Switch,BV9,BV10,BV11) -> 0.2 | BW8: =CHOOSE(_Switch,BW9,BW10,BW11) -> 0.18 | BX8: =CHOOSE(_Switch,BX9,BX10,BX11) -> 0.18 | BY8: =+BY7-BY179 -> 0.18928879 | BZ8: =CHOOSE(_Switch,BZ9,BZ10,BZ11) -> 0.17 | CA8: =CHOOSE(_Switch,CA9,CA10,CA11) -> 0.17 | CB8: =CHOOSE(_Switch,CB9,CB10,CB11) -> 0.17 | CC8: =CHOOSE(_Switch,CC9,CC10,CC11) -> 0.17 | CD8: =+CD7-CD179 -> 0.17 | CE8: =((1+BJ8)*(1+BO8)*(1+BT8))^0.333-1 -> 0.24926909
B9: Bull | BL9: =BL10+3% -> 0.2875 | BM9: =BM10+3% -> 0.2775 | BN9: =BN10+3% -> 0.27 | BP9: =BP10+1% -> 0.238 | BQ9: =BQ10+1% -> 0.238 | BR9: =BR10+1% -> 0.238 | BS9: =BS10+1% -> 0.238 | BU9: =BU10+3% -> 0.23 | BV9: =BV10+3% -> 0.23 | BW9: =BW10+3% -> 0.21 | BX9: =BX10+3% -> 0.21 | BZ9: =BZ10+3% -> 0.2 | CA9: =CA10+3% -> 0.2 | CB9: =CB10+3% -> 0.2 | CC9: =CC10+3% -> 0.2
B10: Base | BL10: 0.2575 | BM10: =+BL10-1% -> 0.2475 | BN10: =+BM10-0.75% -> 0.24 | BP10: =23.5%-0.7% -> 0.228 | BQ10: =+BP10 -> 0.228 | BR10: =+BQ10 -> 0.228 | BS10: =+BR10 -> 0.228 | BU10: 0.2 | BV10: =BU10 -> 0.2 | BW10: =20%-0.02 -> 0.18 | BX10: =BW10 -> 0.18 | BZ10: =19%-0.02 -> 0.17 | CA10: =BZ10 -> 0.17 | CB10: =CA10 -> 0.17 | CC10: =CB10 -> 0.17
B11: Bear | BL11: =BL10-3% -> 0.2275 | BM11: =BM10-3% -> 0.2175 | BN11: =BN10-3% -> 0.21 | BP11: =BP10-4% -> 0.188 | BQ11: =BQ10-4% -> 0.188 | BR11: =BR10-4% -> 0.188 | BS11: =BS10-4% -> 0.188 | BU11: =BU10-4% -> 0.16 | BV11: =BV10-4% -> 0.16 | BW11: =BW10-4% -> 0.14 | BX11: =BX10-4% -> 0.14 | BZ11: =BZ10-4% -> 0.13 | CA11: =CA10-4% -> 0.13 | CB11: =CB10-4% -> 0.13 | CC11: =CC10-4% -> 0.13
B12: Estimated FX Impact on TPV | BL12: =BL179 -> 0.046408515 | BM12: =BM179 -> 0.02879621 | BN12: =BN179 -> 0.024673796 | BP12: =BP179 -> -0.00056933849 | BQ12: =BQ179 -> 0 | BR12: =BR179 -> 0 | BS12: =BS179 -> 0 | BU12: =BU179 -> 0 | BV12: =BV179 -> 0 | BW12: =BW179 -> 0 | BX12: =BX179 -> 0 | BZ12: =BZ179 -> 0 | CA12: =CA179 -> 0 | CB12: =CB179 -> 0 | CC12: =CC179 -> 0
B14: TPV from large merchants | AP14: =+AP16*AP6 -> 72386.34 | AQ14: =+AQ6*AQ16 -> 21470.4 | AR14: =+AR6*AR16 -> 24396.48 | AS14: =+AS6*AS16 -> 25019.12 | AT14: =+AT6*AT16 -> 28396.77 | AU14: =+AU16*AU6 -> 98546.7 | AV14: =+AV6*AV16 -> 26468.82 | AW14: =+AW6*AW16 -> 31041.72 | AX14: =+AX6*AX16 -> 32805.82 | AY14: =AY6*AY16 -> 38226.92 | AZ14: =SUM(AV14:AY14) -> 128543.28 | BA14: =BA6*BA16 -> 37151.55 | BB14: =BB6*BB16 -> 42126.24 | BC14: =BC6*BC16 -> 42669.6 | BD14: =BD6*BD16 -> 48341.28 | BE14: =SUM(BA14:BD14) -> 170288.67 | BF14: =BF6*BF16 -> 48306.72 | BG14: =BG6*BG16 -> 52283 | BH14: =BH6*BH16 -> 56459.76 | BI14: =BI6*BI16 -> 65594.925 | BJ14: =SUM(BF14:BI14) -> 222644.41 | BK14: =BK6*BK16 -> 66049.636 | BL14: =BL6*BL16 -> 70702.353 | BM14: =BM6*BM16 -> 74559.397 | BN14: =BN6*BN16 -> 85637.595 | BO14: =SUM(BK14:BN14) -> 296948.98 | BP14: =BP6*BP16 -> 83345.895 | BQ14: =BQ6*BQ16 -> 88893.801 | BR14: =BR6*BR16 -> 93364.836 | BS14: =BS6*BS16 -> 106809.35 | BT14: =SUM(BP14:BS14) -> 372413.89 | BU14: =BU6*BU16 -> 101574.76 | BV14: =BV6*BV16 -> 108329.61 | BW14: =BW6*BW16 -> 111875.27 | BX14: =BX6*BX16 -> 127977.77 | BY14: =SUM(BU14:BX14) -> 449757.42 | BZ14: =BZ6*BZ16 -> 120667.31 | CA14: =CA6*CA16 -> 128684.39 | CB14: =CB6*CB16 -> 132888.64 | CC14: =CC6*CC16 -> 152007 | CD14: =SUM(BZ14:CC14) -> 534247.34
B15: YoY % change | AU15: =+AU14/AP14-1 -> 0.36139913 | AV15: =+AV14/AQ14-1 -> 0.23280516 | AW15: =+AW14/AR14-1 -> 0.2723852 | AX15: =+AX14/AS14-1 -> 0.31122997 | AY15: =AY14/AT14-1 -> 0.34617141 | AZ15: =+AZ14/AU14-1 -> 0.30438949 | BA15: =BA14/AV14-1 -> 0.40359676 | BB15: =BB14/AW14-1 -> 0.35708459 | BC15: =BC14/AX14-1 -> 0.30067165 | BD15: =BD14/AY14-1 -> 0.26458736 | BE15: =BE14/AZ14-1 -> 0.32475747 | BF15: =BF14/BA14-1 -> 0.30026123 | BG15: =BG14/BB14-1 -> 0.24110293 | BH15: =BH14/BC14-1 -> 0.32318466 | ... CD15: =CD14/BY14-1 -> 0.18785665
B16: % of total TPV | AP16: 0.39 | AQ16: 0.4 | AR16: 0.43 | AS16: 0.43 | AT16: 0.43 | AU16: 0.42 | AV16: 0.42 | AW16: 0.46 | AX16: 0.46 | AY16: 0.46 | AZ16: =AZ14/AZ6 -> 0.44627195 | BA16: 0.45 | BB16: 0.48 | BC16: 0.48 | BD16: =+BC16 -> 0.48 | BE16: =BE14/BE6 -> 0.47311871 | BF16: 0.48 | BG16: 0.485 | BH16: 0.49 | BI16: 0.495 | BJ16: =BJ14/BJ6 -> 0.48806476 | BK16: 0.499 | BL16: =CHOOSE(_Switch,BL17,BL18,BL19) -> 0.503 | BM16: =CHOOSE(_Switch,BM17,BM18,BM19) -> 0.507 | BN16: =CHOOSE(_Switch,BN17,BN18,BN19) -> 0.511 | BO16: =BO14/BO6 -> 0.50538181 | BP16: =CHOOSE(_Switch,BP17,BP18,BP19) -> 0.513 | BQ16: =CHOOSE(_Switch,BQ17,BQ18,BQ19) -> 0.515 | BR16: =CHOOSE(_Switch,BR17,BR18,BR19) -> 0.517 | BS16: =CHOOSE(_Switch,BS17,BS18,BS19) -> 0.519 | BT16: =BT14/BT6 -> 0.51619124 | BU16: =CHOOSE(_Switch,BU17,BU18,BU19) -> 0.521 | BV16: =CHOOSE(_Switch,BV17,BV18,BV19) -> 0.523 | BW16: =CHOOSE(_Switch,BW17,BW18,BW19) -> 0.525 | BX16: =CHOOSE(_Switch,BX17,BX18,BX19) -> 0.527 | BY16: =BY14/BY6 -> 0.52417436 | BZ16: =CHOOSE(_Switch,BZ17,BZ18,BZ19) -> 0.529 | CA16: =CHOOSE(_Switch,CA17,CA18,CA19) -> 0.531 | CB16: =CHOOSE(_Switch,CB17,CB18,CB19) -> 0.533 | CC16: =CHOOSE(_Switch,CC17,CC18,CC19) -> 0.535 | CD16: =CD14/CD6 -> 0.53217436
B17: Bull | BL17: =+BL18+1.5% -> 0.518 | BM17: =+BM18+1.5% -> 0.522 | BN17: =+BN18+1.5% -> 0.526 | BP17: =+BP18+1.5% -> 0.528 | BQ17: =+BQ18+1.5% -> 0.53 | BR17: =+BR18+1.5% -> 0.532 | BS17: =+BS18+1.5% -> 0.534 | BU17: =+BU18+1.5% -> 0.536 | BV17: =+BV18+1.5% -> 0.538 | BW17: =+BW18+1.5% -> 0.54 | BX17: =+BX18+1.5% -> 0.542 | BZ17: =+BZ18+1.5% -> 0.544 | CA17: =+CA18+1.5% -> 0.546 | CB17: =+CB18+1.5% -> 0.548 | CC17: =+CC18+1.5% -> 0.55
B18: Base | BL18: 0.503 | BM18: =BL18+0.004 -> 0.507 | BN18: =BM18+0.004 -> 0.511 | BP18: =BN18+0.002 -> 0.513 | BQ18: =BP18+0.002 -> 0.515 | BR18: =BQ18+0.002 -> 0.517 | BS18: =BR18+0.002 -> 0.519 | BU18: =BS18+0.002 -> 0.521 | BV18: =BU18+0.002 -> 0.523 | BW18: =BV18+0.002 -> 0.525 | BX18: =BW18+0.002 -> 0.527 | BZ18: =BX18+0.002 -> 0.529 | CA18: =BZ18+0.002 -> 0.531 | CB18: =CA18+0.002 -> 0.533 | CC18: =CB18+0.002 -> 0.535
B19: Bear | BL19: =BL18-0.5% -> 0.498 | BM19: =BM18-0.5% -> 0.502 | BN19: =BN18-0.5% -> 0.506 | BP19: =BP18-0.5% -> 0.508 | BQ19: =BQ18-0.5% -> 0.51 | BR19: =BR18-0.5% -> 0.512 | BS19: =BS18-0.5% -> 0.514 | BU19: =BU18-0.5% -> 0.516 | BV19: =BV18-0.5% -> 0.518 | BW19: =BW18-0.5% -> 0.52 | BX19: =BX18-0.5% -> 0.522 | BZ19: =BZ18-0.5% -> 0.524 | CA19: =CA18-0.5% -> 0.526 | CB19: =CB18-0.5% -> 0.528 | CC19: =CC18-0.5% -> 0.53
B21: TPV from small merchants | AP21: =+AP6-AP14 -> 113219.66 | AQ21: =+AQ6-AQ14 -> 32205.6 | AR21: =+AR6-AR14 -> 32339.52 | AS21: =+AS6-AS14 -> 33164.88 | AT21: =+AT6-AT14 -> 37642.23 | AU21: =+AU6-AU14 -> 136088.3 | AV21: =+AV6-AV14 -> 36552.18 | AW21: =+AW6-AW14 -> 36440.28 | ... CD21: =+CD6-CD14 -> 469647.96
B22: YoY % change | AU22: =+AU21/AP21-1 -> 0.20198471 | AV22: =AV21/AQ21-1 -> 0.13496348 | AW22: =AW21/AR21-1 -> 0.12680337 | AX22: =AX21/AS21-1 -> 0.16120366 | AY22: =AY21/AT21-1 -> 0.19214722 | AZ22: =+AZ21/AU21-1 -> 0.17199436 | BA22: =BA21/AV21-1 -> 0.2422638 | BB22: =BB21/AW21-1 -> 0.25237128 | BC22: =BC21/AX21-1 -> 0.20031118 | BD22: =BD21/AY21-1 -> 0.16701118 | BE22: =+BE21/AZ21-1 -> 0.18900068 | BF22: =BF21/BA21-1 -> 0.15250427 | BG22: =BG21/BB21-1 -> 0.2164974 | BH22: =BH21/BC21-1 -> 0.27125433 | BI22: =BI21/BD21-1 -> 0.27783908 | BJ22: =+BJ21/BE21-1 -> 0.23146182 | BK22: =BK21/BF21-1 -> 0.26717896 | BL22: =BL21/BG21-1 -> 0.25833501 | BM22: =BM21/BH21-1 -> 0.233753 | BN22: =BN21/BI21-1 -> 0.22460492 | BO22: =+BO21/BJ21-1 -> 0.24446575 | BP22: =BP21/BK21-1 -> 0.1931312 | BQ22: =BQ21/BL21-1 -> 0.1983501 | BR22: =BR21/BM21-1 -> 0.20309128 | BS22: =BS21/BN21-1 -> 0.20791002 | BT22: =+BT21/BO21-1 -> 0.20103773 | BU22: =BU21/BP21-1 -> 0.18028747 | BV22: =BV21/BQ21-1 -> 0.18020619 | BW22: =BW21/BR21-1 -> 0.16045549 | BX22: =BX21/BS21-1 -> 0.16037422 | BY22: =+BY21/BT21-1 -> 0.16966485 | BZ22: =BZ21/BU21-1 -> 0.15045929 | CA22: =CA21/BV21-1 -> 0.15037736 | CB22: =CB21/BW21-1 -> 0.15029474 | CC22: =CC21/BX21-1 -> 0.15021142 | CD22: =+CD21/BY21-1 -> 0.15032893
B23: % of total TPV | AP23: =+AP21/AP6 -> 0.61 | AQ23: =+AQ21/AQ6 -> 0.6 | AR23: =+AR21/AR6 -> 0.57 | AS23: =+AS21/AS6 -> 0.57 | AT23: =+AT21/AT6 -> 0.57 | AU23: =+AU21/AU6 -> 0.58 | AV23: =+AV21/AV6 -> 0.58 | AW23: =+AW21/AW6 -> 0.54 | ... CD23: =+CD21/CD6 -> 0.46782564
B25: Transaction Revenue Take Rate | AK25: =AK45/AK6 -> 0.033505258 | AP25: =AP45/AP6 -> 0.032283439 | AQ25: =+AQ45/AQ6 -> 0.031131232 | AR25: =+AR45/AR6 -> 0.030139594 | AS25: =+AS45/AS6 -> 0.030076997 | AT25: =+AT45/AT6 -> 0.02972486 | AU25: =AU45/AU6 -> 0.030234194 | AV25: =AV45/AV6 -> 0.030323226 | AW25: =AW45/AW6 -> 0.029133695 | AX25: =AX45/AX6 -> 0.028099892 | AY25: =AY45/AY6 -> 0.027508363 | AZ25: =AZ45/AZ6 -> 0.028527486 | BA25: =BA45/BA6 -> 0.027374363 | BB25: =BB45/BB6 -> 0.026742477 | ... BK25: =BK45/BK6 -> 0.024153093 | BL25: =+BL30*BL23+BL35*BL16+BL43 -> 0.02396004 | BM25: =+BM30*BM23+BM35*BM16+BM43 -> 0.02371871 | BN25: =+BN30*BN23+BN35*BN16+BN43 -> 0.023523984 | BO25: =BO45/BO6 -> 0.023818756 | BP25: =+BP30*BP23+BP35*BP16+BP43 -> 0.023383999 | BQ25: =+BQ30*BQ23+BQ35*BQ16+BQ43 -> 0.023214579 | BR25: =+BR30*BR23+BR35*BR16+BR43 -> 0.023045558 | BS25: =+BS30*BS23+BS35*BS16+BS43 -> 0.022876938 | BT25: =BT45/BT6 -> 0.023114111 | BU25: =+BU30*BU23+BU35*BU16+BU43 -> 0.022794643 | BV25: =+BV30*BV23+BV35*BV16+BV43 -> 0.022712448 | BW25: =+BW30*BW23+BW35*BW16+BW43 -> 0.022512228 | BX25: =+BX30*BX23+BX35*BX16+BX43 -> 0.022429783 | BY25: =BY45/BY6 -> 0.022601398 | BZ25: =+BZ30*BZ23+BZ35*BZ16+BZ43 -> 0.022389213 | CA25: =+CA30*CA23+CA35*CA16+CA43 -> 0.022348643 | CB25: =+CB30*CB23+CB35*CB16+CB43 -> 0.022308073 | CC25: =+CC30*CC23+CC35*CC16+CC43 -> 0.022267503 | CD25: =CD45/CD6 -> 0.022324821
B26: % Change | AU26: =AU25/AP25-1 -> -0.063476681 | AV26: =AV25/AQ25-1 -> -0.025954843 | AW26: =AW25/AR25-1 -> -0.03337467 | AX26: =AX25/AS25-1 -> -0.06573479 | AY26: =AY25/AT25-1 -> -0.074567092 | AZ26: =AZ25/AU25-1 -> -0.056449582 | BA26: =BA25/AV25-1 -> -0.097247669 | BB26: =BB25/AW25-1 -> -0.082077403 | ... CD26: =CD25/BY25-1 -> -0.012237179
B27: Bps Change | AU27: =(AU25-AP25)*10000 -> -20.492456 | AV27: =(AV25-AQ25)*10000 -> -8.0800624 | AW27: =(AW25-AR25)*10000 -> -10.05899 | AX27: =(AX25-AS25)*10000 -> -19.771051 | AY27: =(AY25-AT25)*10000 -> -22.164963 | AZ27: =(AZ25-AU25)*10000 -> -17.067076 | BA27: =(BA25-AV25)*10000 -> -29.48863 | BB27: =(BB25-AW25)*10000 -> -23.91218 | ... CD27: =(CD25-BY25)*10000 -> -2.7657737
AV28: =AV27-AV42*10000 -> -23.733732 | AW28: =AW27-AW42*10000 -> -24.159385 | AX28: =AX27-AX42*10000 -> -29.223821 | AY28: =AY27-AY42*10000 -> -25.950605 | AZ28: =AZ27-AZ42*10000 -> -25.260439 | BA28: =BA27-BA42*10000 -> -27.308371 | BB28: =BB27-BB42*10000 -> -19.126564 | BC28: =BC27-BC42*10000 -> -16.979572 | ... BJ28: =BJ27-BJ42*10000 -> -12.060399 | BO28: =BO27-BO42*10000 -> -11.818562 | BT28: =BT27-BT42*10000 -> -8.4602419 | BY28: =BY27-BY42*10000 -> -5.1271276 | CD28: =CD27-CD42*10000 -> -2.7657737
B29: Take rate derivation (All assumptions)
B30: Small merchant take rate | AQ30: 0.0375 | AR30: 0.037 | AS30: 0.037 | AT30: 0.03506 | AU30: =SUMPRODUCT(AQ30:AT30,AQ6:AT6)/SUM(AQ6:AT6) -> 0.036568361 | AV30: 0.0345 | AW30: 0.0335 | AX30: 0.0333 | AY30: 0.0327 | AZ30: =SUMPRODUCT(AV30:AY30,AV6:AY6)/SUM(AV6:AY6) -> 0.033437794 | BA30: 0.0325 | BB30: 0.0324 | BC30: 0.032 | BD30: 0.0316 | BE30: =SUMPRODUCT(BA30:BD30,BA6:BD6)/SUM(BA6:BD6) -> 0.032100299 | BF30: 0.03125 | BG30: 0.031 | BH30: 0.0307 | BI30: 0.0302 | BJ30: =SUMPRODUCT(BF30:BI30,BF6:BI6)/SUM(BF6:BI6) -> 0.030746986 | BK30: 0.02995 | BL30: =CHOOSE(_Switch,BL31,BL32,BL33) -> 0.0296 | BM30: =CHOOSE(_Switch,BM31,BM32,BM33) -> 0.0292 | BN30: =CHOOSE(_Switch,BN31,BN32,BN33) -> 0.02895 | BO30: =SUMPRODUCT(BK30:BN30,BK6:BN6)/SUM(BK6:BN6) -> 0.029393338 | BP30: =CHOOSE(_Switch,BP31,BP32,BP33) -> 0.02875 | BQ30: =CHOOSE(_Switch,BQ31,BQ32,BQ33) -> 0.02855 | BR30: =CHOOSE(_Switch,BR31,BR32,BR33) -> 0.02835 | BS30: =CHOOSE(_Switch,BS31,BS32,BS33) -> 0.02815 | BT30: =SUMPRODUCT(BP30:BS30,BP6:BS6)/SUM(BP6:BS6) -> 0.028430876 | BU30: =CHOOSE(_Switch,BU31,BU32,BU33) -> 0.028075 | BV30: =CHOOSE(_Switch,BV31,BV32,BV33) -> 0.028 | BW30: =CHOOSE(_Switch,BW31,BW32,BW33) -> 0.027925 | BX30: =CHOOSE(_Switch,BX31,BX32,BX33) -> 0.02785 | BY30: =SUMPRODUCT(BU30:BX30,BU6:BX6)/SUM(BU6:BX6) -> 0.027955961 | BZ30: =CHOOSE(_Switch,BZ31,BZ32,BZ33) -> 0.02783 | CA30: =CHOOSE(_Switch,CA31,CA32,CA33) -> 0.02781 | CB30: =CHOOSE(_Switch,CB31,CB32,CB33) -> 0.02779 | CC30: =CHOOSE(_Switch,CC31,CC32,CC33) -> 0.02777 | CD30: =SUMPRODUCT(BZ30:CC30,BZ6:CC6)/SUM(BZ6:CC6) -> 0.027798256
B31: Bull | BL31: =+BL32+0.06% -> 0.0302 | BM31: =+BM32+0.06% -> 0.0298 | BN31: =+BN32+0.06% -> 0.02955 | BP31: =+BP32+0.06% -> 0.02935 | BQ31: =+BQ32+0.06% -> 0.02915 | BR31: =+BR32+0.06% -> 0.02895 | BS31: =+BS32+0.06% -> 0.02875 | BU31: =+BU32+0.06% -> 0.028675 | BV31: =+BV32+0.06% -> 0.0286 | BW31: =+BW32+0.06% -> 0.028525 | BX31: =+BX32+0.06% -> 0.02845 | BZ31: =+BZ32+0.06% -> 0.02843 | CA31: =+CA32+0.06% -> 0.02841 | CB31: =+CB32+0.06%+CB29/CB23*0.002 -> 0.02839 | CC31: =+CB31-0.005% -> 0.02834
B32: Base | BL32: 0.0296 | BM32: =+BL32-0.04% -> 0.0292 | BN32: =+BM32-0.025% -> 0.02895 | BP32: =+BN32-0.02% -> 0.02875 | BQ32: =+BP32-0.02% -> 0.02855 | BR32: =+BQ32-0.02% -> 0.02835 | BS32: =+BR32-0.02% -> 0.02815 | BU32: =+BS32-0.0075% -> 0.028075 | BV32: =+BU32-0.0075% -> 0.028 | BW32: =+BV32-0.0075% -> 0.027925 | BX32: =+BW32-0.0075% -> 0.02785 | BZ32: =+BX32-0.002% -> 0.02783 | CA32: =+BZ32-0.002% -> 0.02781 | CB32: =+CA32-0.002% -> 0.02779 | CC32: =+CB32-0.002% -> 0.02777
B33: Bear | BL33: =+BL32-0.06% -> 0.029 | BM33: =+BM32-0.06% -> 0.0286 | BN33: =+BN32-0.06% -> 0.02835 | BP33: =+BP32-0.06% -> 0.02815 | BQ33: =+BQ32-0.06% -> 0.02795 | BR33: =+BR32-0.06% -> 0.02775 | BS33: =+BS32-0.06% -> 0.02755 | BU33: =+BU32-0.0625% -> 0.02745 | BV33: =+BV32-0.0625% -> 0.027375 | BW33: =+BW32-0.0625% -> 0.0273 | BX33: =+BX32-0.0625% -> 0.027225 | BZ33: =+BZ32-0.0625% -> 0.027205 | CA33: =+CA32-0.0625% -> 0.027185 | CB33: =+CB32-0.0625%-CB29/CB23*0.002 -> 0.027165 | CC33: =+CB33-0.005% -> 0.027115
B35: Large merchant take rate | AQ35: =+(AQ25-(AQ30*AQ23)-AQ43)/AQ16 -> 0.022369867 | AR35: =+(AR25-(AR30*AR23)-AR43)/AR16 -> 0.021988326 | AS35: =+(AS25-(AS30*AS23)-AS43)/AS16 -> 0.021539504 | AT35: =+(AT25-(AT30*AT23)-AT43)/AT16 -> 0.021948391 | AU35: =SUMPRODUCT(AQ35:AT35,AQ6:AT6)/SUM(AQ6:AT6) -> 0.021953072 | AV35: =+(AV25-(AV30*AV23)-AV43)/AV16 -> 0.022666284 | AW35: =+(AW25-(AW30*AW23)-AW43)/AW16 -> 0.02201072 | AX35: =+(AX25-(AX30*AX23)-AX43)/AX16 -> 0.020837086 | AY35: =+(AY25-(AY30*AY23)-AY43)/AY16 -> 0.020576727 | AZ35: =SUMPRODUCT(AV35:AY35,AV6:AY6)/SUM(AV6:AY6) -> 0.021443711 | BA35: =+(BA25-(BA30*BA23)-BA43)/BA16 -> 0.020248358 | BB35: =+(BB25-(BB30*BB23)-BB43)/BB16 -> 0.02013873 | BC35: =+(BC25-(BC30*BC23)-BC43)/BC16 -> 0.019446801 | BD35: =+(BD25-(BD30*BD23)-BD43)/BD16 -> 0.0195923 | BE35: =SUMPRODUCT(BA35:BD35,BA6:BD6)/SUM(BA6:BD6) -> 0.019840087 | BF35: =+(BF25-(BF30*BF23)-BF43)/BF16 -> 0.019637356 | BG35: =+(BG25-(BG30*BG23)-BG43)/BG16 -> 0.019489566 | BH35: =+(BH25-(BH30*BH23)-BH43)/BH16 -> 0.018897314 | BI35: =+(BI25-(BI30*BI23)-BI43)/BI16 -> 0.019254748 | BJ35: =SUMPRODUCT(BF35:BI35,BF6:BI6)/SUM(BF6:BI6) -> 0.019304364 | BK35: =+(BK25-(BK30*BK23)-BK43)/BK16 -> 0.019089958 | BL35: =CHOOSE(_Switch,BL36,BL37,BL38) -> 0.018839958 | BM35: =CHOOSE(_Switch,BM36,BM37,BM38) -> 0.018589958 | BN35: =CHOOSE(_Switch,BN36,BN37,BN38) -> 0.018389958 | BO35: =SUMPRODUCT(BK35:BN35,BK6:BN6)/SUM(BK6:BN6) -> 0.018705356 | BP35: =CHOOSE(_Switch,BP36,BP37,BP38) -> 0.018289958 | BQ35: =CHOOSE(_Switch,BQ36,BQ37,BQ38) -> 0.018189958 | BR35: =CHOOSE(_Switch,BR36,BR37,BR38) -> 0.018089958 | BS35: =CHOOSE(_Switch,BS36,BS37,BS38) -> 0.017989958 | BT35: =SUMPRODUCT(BP35:BS35,BP6:BS6)/SUM(BP6:BS6) -> 0.018130396 | BU35: =CHOOSE(_Switch,BU36,BU37,BU38) -> 0.017939958 | BV35: =CHOOSE(_Switch,BV36,BV37,BV38) -> 0.017889958 | BW35: =CHOOSE(_Switch,BW36,BW37,BW38) -> 0.017614958 | BX35: =CHOOSE(_Switch,BX36,BX37,BX38) -> 0.017564958 | BY35: =SUMPRODUCT(BU35:BX35,BU6:BX6)/SUM(BU6:BX6) -> 0.017741039 | BZ35: =CHOOSE(_Switch,BZ36,BZ37,BZ38) -> 0.017544958 | CA35: =CHOOSE(_Switch,CA36,CA37,CA38) -> 0.017524958 | CB35: =CHOOSE(_Switch,CB36,CB37,CB38) -> 0.017504958 | CC35: =CHOOSE(_Switch,CC36,CC37,CC38) -> 0.017484958 | CD35: =SUMPRODUCT(BZ35:CC35,BZ6:CC6)/SUM(BZ6:CC6) -> 0.017513215
