Workbook
Name AdditionalInstructions: IndexInformation!$B$42
Name Address: ImportantDisclosures!$A$2:$A$2
Name ANA: ModPubIndex!$A$7
Name Authors: ImportantDisclosures!$A$7
Name Authors: IndexInformation!$B$18
Name BRO: ModPubIndex!$A$1
Name Cap_IQ_Non_Trans: 'Op Metrics'!$239:$239
Name Cap_IQ_Trans: 'Op Metrics'!$235:$235
Name CashFlowCapitalExpenditureCellular: 0
Name CashFlowCapitalExpenditureOther: 0
Name CashFlowCapitalExpenditurePaging: 0
Name CashFlowCapitalExpenditureTelephone: 0
Name CashFlowCapitalExpenditureWireless: 0
Name CashFlowDividendPaidPreferredStock: 0
Name CopyrightStamp: ImportantDisclosures!$A$27
Name Corinthian_Colleges: '[10]Print '!$B$2:$M$71
Name COU: ModPubIndex!$A$5
Name CQEnd: IndexInformation!$B$31
Name Currency: IndexInformation!$B$24
Name CurrentStockPrice: IndexInformation!$B$23
Name CurrQtrEPS: IndexInformation!$B$29
Name CurrYearEPS: IndexInformation!$B$11
Name CurrYearTotalRevenue: IndexInformation!$B$10
Name CurrYearTotalRevenueActual: IndexInformation!$B$32
Name CUSIP: IndexInformation!$B$20
Name CYEnd: IndexInformation!$B$30
Name Date: ImportantDisclosures!$A$8
Name Deleted: IndexInformation!$B$27
Name Description: IndexInformation!$B$7
Name Discipline: IndexInformation!$B$3
Name DISCIPLINE: ModPubIndex!$A$12
Name DisclosuresText: ImportantDisclosures!$A$22
Name Distribution: IndexInformation!$B$26
Name DistTable: ImportantDisclosures!#REF!
Name DistTablePreamble: ImportantDisclosures!#REF!
Name DOCDAT: ModPubIndex!$A$2
Name DOCTIME: ModPubIndex!$A$3
Name DocType: IndexInformation!$B$5
Name EMAIL_ALERT: ModPubIndex!$A$10
Name EmailAlert: IndexInformation!$B$28
Name EquityAdjustments: 0
Name EquityEmployeeStockOwnershipPlan: 0
Name EquityPaidInCapital: 0
Name EquityTreasuryStock: 0
Name FiveYearGrowthRate: IndexInformation!$B$16
Name FollowingYearEPS: IndexInformation!$B$15
Name FollowingYearTotalRevenue: IndexInformation!$B$14
Name FollowingYearTotalRevenueActual: IndexInformation!$B$34
Name HL: ModPubIndex!$A$8
Name IncomeEPSFullyDiluted: 0
Name IncomeEPSPrimary: 0
Name IncomeEPSRegular: 0
Name IND: ModPubIndex!$A$9
Name Industry: ImportantDisclosures!$A$12
Name IndustryId: IndexInformation!$B$40
Name IndustryRating: ImportantDisclosures!$A$13
Name KeepVersions: IndexInformation!$B$8
Name LanguageCode: IndexInformation!$B$38
Name LastCell: ImportantDisclosures!$A$22
Name LiabilitiesCurrentAccruedLiabilities: 0

Sheet ImportantDisclosures
A2: 1585 Broadway
A3: New York, NY 10036-8293
A4: United States
A5: Tel: +1 (1)212 761 4000
A7: Authors: Toni Kaplan, Jeffrey Goldstein
A8: Date: 26 Apr 2018
A10: Ticker: SPGI.N
A11: Stock Rating: Equal-Weight
A12: Industry: Business & Education Services
A13: Industry View: In-Line
A14: Price as of 26 Apr 2018: 190.25
A15: Target Price: 205
... A126: Equal-weight and Not-Rated to hold and Underweight to sell recommendations, respectively.
B128: Coverage Universe | D128: Investment Banking Clients (IBC) | G128: Other Material Investment Services Clients (MISC)
A129: Stock Rating Category | B129: Count | C129: % of Total | D129: Count | E129: % of Total IBC | F129: % of Rating Category | G129: Count | H129: % of Total Other MISC
A130: Overweight/Buy | B130: 1189 | C130: 0.38 | D130: 315 | E130: 0.41 | F130: 0.26 | G130: 555 | H130: 0.39
A131: Equal-weight/Hold | B131: 1355 | C131: 0.43 | D131: 364 | E131: 0.47 | F131: 0.27 | G131: 644 | H131: 0.45
A132: Not-Rated/Hold | B132: 53 | C132: 0.02 | D132: 4 | E132: 0.01 | F132: 0.08 | G132: 7 | H132: 0
A133: Underweight/Sell | B133: 545 | C133: 0.17 | D133: 84 | E133: 0.11 | F133: 0.15 | G133: 214 | H133: 0.15
A134: Total | B134: 3142 | D134: 767 | G134: 1420
A136: Data include common stock and ADRs currently assigned ratings. Investment Banking Clients are companies
A137: from whom Morgan Stanley received investment banking compensation in the last 12 months. Due to rounding
A138: off of decimals, the percentages provided in the "% of total" column may not add up to exactly 100
A139: percent.
A141: Analyst Stock Ratings
A143: Overweight (O). The stock's total return is expected to exceed the average total return of the analyst's
A144: industry (or industry team's) coverage universe, on a risk-adjusted basis, over the next 12-18 months.
A146: Equal-weight (E). The stock's total return is expected to be in line with the average total return of
A147: the analyst's industry (or industry team's) coverage universe, on a risk-adjusted basis, over the next
A148: 12-18 months.
A150: Not-Rated (NR). Currently the analyst does not have adequate conviction about the stock's total return
A151: relative to the average total return of the analyst's industry (or industry team's) coverage universe,
... A401: © Copyright 2018 Morgan Stanley

Sheet MHFI
B1: 2001 | C1: 2002 | D1: 2003 | E1: 2004 | F1: 2005 | G1: 1Q06 | H1: 2Q06 | I1: 3Q06 | J1: 4Q06 | K1: 2006 | L1: 1Q07 | M1: 2Q07 | N1: 3Q07 | O1: 4Q07 | P1: 2007 | Q1: 1Q08 | R1: 2Q08 | S1: 3Q08 | T1: 4Q08 | U1: 2008 | V1: 1Q09 | W1: 2Q09 | X1: 3Q09 | Y1: 4Q09 | Z1: 2009 | AA1: 1Q10 | AB1: 2Q10 | AC1: 3Q10 | AD1: 4Q10 | AE1: 2010 | AF1: 1Q11 | AG1: 2Q11 | AH1: 3Q11 | AI1: 4Q11 | AJ1: 2011 | AK1: 1Q12 | AL1: 2Q12 | AM1: 3Q12 | AN1: 4Q12 | AO1: 2012 | AP1: 1Q13 | AQ1: 2Q13 | AR1: 3Q13 | AS1: 4Q13 | AT1: 2013 | AU1: 1Q14 | AV1: 2Q14 | AW1: 3Q14 | AX1: 4Q14 | AY1: 2014 | AZ1: 1Q15 | BA1: 2Q15 | BB1: 3Q15 | BC1: 4Q15 | BD1: 2015 | BE1: 1Q16 | BF1: 2Q16 | BG1: 3Q16 | BH1: 4Q16 | BI1: 2016 | BJ1: 1Q17 | BK1: 2Q17 | BL1: 3Q17 | BM1: 4Q17 | BN1: 2017 | BO1: 1Q18E | BP1: 2Q18E | BQ1: 3Q18E | BR1: 4Q18E | BS1: 2018E | BT1: 1Q19E | BU1: 2Q19E | BV1: 3Q19E | BW1: 4Q19E | BX1: 2019E | BY1: 2020E | BZ1: 2021E | CA1: 2022E
A3: 2
DK4: Do not Delete
A6: S&P Global, Inc | CD6: The McGraw-Hill Companies, Inc.
A7: Quarterly Income Statement | CD7: Annual Income Statement
A8: (Values in millions, except per-share amounts) | CB8: CAGR | CD8: (Values in millions, except per-share amounts)
B9: =B1 -> 2001 | C9: =C1 -> 2002 | D9: =D1 -> 2003 | E9: =E1 -> 2004 | F9: =F1 -> 2005 | G9: =G1 -> 1Q06 | H9: =H1 -> 2Q06 | I9: =I1 -> 3Q06 | ... CA9: =CA1 -> 2022E | CB9: 17-'22 | CD9: =A9 | CE9: =B9 -> 2001 | CF9: =C9 -> 2002 | CG9: =D9 -> 2003 | CH9: =E9 -> 2004 | CI9: =F9 -> 2005 | CJ9: =K9 -> 2006 | CK9: =P9 -> 2007 | CL9: =U9 -> 2008 | CM9: =Z9 -> 2009 | CN9: =AE9 -> 2010 | CO9: =AJ9 -> 2011 | CP9: =AO9 -> 2012 | CQ9: =AT9 -> 2013 | CR9: =AY9 -> 2014 | CS9: =BD9 -> 2015 | CT9: =BI9 -> 2016 | CU9: =BN9 -> 2017 | CV9: =BS9 -> 2018E | CW9: =BX9 -> 2019E | CX9: =BY9 -> 2020E | CY9: =BZ9 -> 2021E | CZ9: =CA9 -> 2022E | DB9: NTM
A10: Revenues | CD10: =A10 -> Revenues
A11: Product | B11: =B195 -> 2433.402 | C11: =C195 -> 2389.77 | D11: =D195 -> 2477.026 | E11: =E195 -> 2460.274 | F11: =F195 -> 2536.422 | G11: =G195 -> 302.619 | H11: 567.93 | I11: =I195 -> 1069.092 | J11: =J195 -> 503.142 | K11: =SUM(G11:J11) -> 2442.783 | L11: =L195 -> 312.369 | M11: =M195 -> 605.373 | N11: =N195 -> 1167.288 | O11: =O195 -> 519.402 | P11: =SUM(L11:O11) -> 2604.432 | Q11: =Q195 -> 317.643 | R11: =R195 -> 634.112 | S11: =S195 -> 1136.462 | T11: =T195 -> 494.336 | U11: =SUM(Q11:T11) -> 2582.553 | V11: =V195 -> 289.398 | W11: =W195 -> 525.813 | X11: =X195 -> 1013.213 | Y11: =Y195 -> 533.811 | Z11: =SUM(V11:Y11) -> 2362.235 | AA11: =AA195 -> 310.8 | AB11: =AB195 -> 545 | AC11: =AC195 -> 1058.4 | AD11: =AD195 -> 497.093 | AE11: =SUM(AA11:AD11) -> 2411.293 | AF11: =AF195 -> 298 | AG11: =AG195 -> 523 | AH11: =AH195 -> 940.5 | AI11: =AI195 -> 513.5 | AJ11: =SUM(AF11:AI11) -> 2275 | CD11: =A11 -> Product | CE11: =B11 -> 2433.402 | CF11: =C11 -> 2389.77 | CG11: =D11 -> 2477.026 | CH11: =E11 -> 2460.274 | CI11: =F11 -> 2536.422 | CJ11: =K11 -> 2442.783 | CK11: =P11 -> 2604.432 | CL11: =U11 -> 2582.553 | CM11: =Z11 -> 2362.235 | CN11: =AE11 -> 2411.293 | CO11: =AJ11 -> 2275
A12: Service | B12: =B198 -> 2212.133 | C12: =C198 -> 2250.414 | D12: =D198 -> 2413.294 | E12: =E198 -> 2790.264 | F12: =F198 -> 3467.22 | G12: =G198 -> 838.06 | H12: =H198 -> 959.613 | I12: =I198 -> 923.478 | J12: =J198 -> 1091.204 | K12: =SUM(G12:J12) -> 3812.355 | L12: =L198 -> 984.049 | M12: =M198 -> 1112.806 | N12: =N198 -> 1020.708 | O12: =O198 -> 1050.286 | P12: =SUM(L12:O12) -> 4167.849 | Q12: =Q198 -> 900.228 | R12: =R198 -> 1039.113 | S12: =S198 -> 912.079 | T12: =T198 -> 921.082 | U12: =SUM(Q12:T12) -> 3772.502 | V12: =V198 -> 858.809 | W12: =W198 -> 939.367 | X12: =X198 -> 862.69 | Y12: =Y198 -> 928.681 | Z12: =SUM(V12:Y12) -> 3589.547 | AA12: =AA198 -> 879.6 | AB12: =AB198 -> 929.1 | AC12: =AC198 -> 897.8 | AD12: =AD198 -> 1050.538 | AE12: =SUM(AA12:AD12) -> 3757.038 | AF12: =AF198 -> 963 | AG12: =AG198 -> 1034 | AH12: =AH198 -> 967.5 | AI12: =AI198 -> 1006.5 | AJ12: =SUM(AF12:AI12) -> 3971 | CD12: =A12 -> Service | CE12: =B12 -> 2212.133 | CF12: =C12 -> 2250.414 | CG12: =D12 -> 2413.294 | CH12: =E12 -> 2790.264 | CI12: =F12 -> 3467.22 | CJ12: =K12 -> 3812.355 | CK12: =P12 -> 4167.849 | CL12: =U12 -> 3772.502 | CM12: =Z12 -> 3589.547 | CN12: =AE12 -> 3757.038 | CO12: =AJ12 -> 3971
B13: ______ | C13: ______ | D13: ______ | E13: ______ | F13: ______ | G13: ______ | H13: ______ | I13: ______ | J13: ______ | K13: ______ | L13: ______ | M13: ______ | N13: ______ | O13: ______ | P13: ______ | Q13: ______ | R13: ______ | S13: ______ | T13: ______ | U13: ______ | V13: ______ | W13: ______ | X13: ______ | Y13: ______ | Z13: ______ | AA13: ______ | AB13: ______ | AC13: ______ | AD13: ______ | AE13: ______ | AF13: ______ | AG13: ______ | AH13: ______ | AI13: ______ | AJ13: ______ | AK13: ______ | AL13: ______ | AM13: ______ | AN13: ______ | AO13: ______ | AP13: ______ | AQ13: ______ | AR13: ______ | AS13: ______ | AT13: ______ | AU13: ______ | AV13: ______ | AW13: ______ | AX13: ______ | AY13: ______ | AZ13: ______ | BA13: ______ | BB13: ______ | BC13: ______ | BD13: ______ | BE13: ______ | BF13: ______ | BG13: ______ | BH13: ______ | BI13: ______ | BN13: ______ | BS13: ______ | BX13: ______ | BY13: ______ | BZ13: ______ | CA13: ______ | CE13: ______ | CF13: ______ | CG13: ______ | CH13: ______ | CI13: ______ | CJ13: ______ | CK13: ______ | CL13: ______ | CM13: ______ | CN13: ______ | CO13: ______ | CP13: ______ | CQ13: ______ | CR13: ______ | CS13: ______ | CT13: ______ | CU13: ______ | CV13: ______ | CW13: ______ | CX13: ______ | CY13: ______ | CZ13: ______
A14: Total Revenues | B14: =SUM(B11:B12) -> 4645.535 | C14: =SUM(C11:C12) -> 4640.184 | D14: =SUM(D11:D12) -> 4890.32 | E14: =SUM(E11:E12) -> 5250.538 | F14: =SUM(F11:F12) -> 6003.642 | G14: =SUM(G11:G12) -> 1140.679 | H14: =SUM(H11:H12) -> 1527.543 | I14: =SUM(I11:I12) -> 1992.57 | ... X14: =SUM(X11:X12) -> 1875.903 | Y14: 1462.492 | Z14: =SUM(Z11:Z12) -> 5951.782 | AA14: =SUM(AA11:AA12) -> 1190.4 | AB14: =SUM(AB11:AB12) -> 1474.1 | AC14: =SUM(AC11:AC12) -> 1956.2 | AD14: =SUM(AD11:AD12) -> 1547.631 | AE14: =SUM(AE11:AE12) -> 6168.331 | AF14: =AF210 -> 1261 | AG14: =AG210 -> 1557 | AH14: =AH210 -> 1908 | AI14: =AI210 -> 1004 | AJ14: =SUM(AJ11:AJ12) -> 6246 | AK14: =AK210 -> 1035 | AL14: =AL210 -> 1072 | AM14: =AM210 -> 1116 | AN14: =AN210 -> 1227 | AO14: =SUM(AK14:AN14) -> 4450 | AP14: =AP210 -> 1181 | AQ14: =AQ210 -> 1250 | AR14: =AR210 -> 1152 | AS14: =AS210 -> 1206 | AT14: =SUM(AP14:AS14) -> 4789 | AU14: =AU210 -> 1196 | AV14: =AV210 -> 1302 | AW14: =AW210 -> 1263 | AX14: =AX210 -> 1290 | AY14: =SUM(AU14:AX14) -> 5051 | AZ14: =AZ210 -> 1273 | BA14: =BA210 -> 1342 | BB14: =BB210 -> 1324 | BC14: =BC210 -> 1374 | BD14: =SUM(AZ14:BC14) -> 5313 | BE14: =BE210 -> 1341 | BF14: =BF210 -> 1482 | BG14: =BG210 -> 1439 | BH14: =BH210 -> 1399 | BI14: =SUM(BE14:BH14) -> 5661 | BJ14: =BJ210 -> 1453 | BK14: =BK210 -> 1509 | BL14: =BL210 -> 1513 | BM14: =BM210 -> 1589 | BN14: =SUM(BJ14:BM14) -> 6064 | BO14: =BO210 -> 1567 | BP14: ='Op Metrics'!BP30 -> 1640.3822 | BQ14: ='Op Metrics'!BQ30 -> 1623.3294 | BR14: ='Op Metrics'!BR30 -> 1671.1382 | BS14: =SUM(BO14:BR14) -> 6501.8499 | BT14: ='Op Metrics'!BT30 -> 1646.4317 | BU14: ='Op Metrics'!BU30 -> 1737.365 | BV14: ='Op Metrics'!BV30 -> 1721.2878 | BW14: ='Op Metrics'!BW30 -> 1770.9532 | BX14: =SUM(BT14:BW14) -> 6876.0376 | BY14: ='Op Metrics'!BY30 -> 7231.5258 | BZ14: ='Op Metrics'!BZ30 -> 7608.3789 | CA14: ='Op Metrics'!CA30 -> 7964.8548 | CB14: =(CA14/BN14)^(1/5)-1 -> 0.056048183 | CD14: =A14 -> Total Revenues | CE14: =B14 -> 4645.535 | CF14: =C14 -> 4640.184 | CG14: =D14 -> 4890.32 | CH14: =E14 -> 5250.538 | CI14: =F14 -> 6003.642 | CJ14: =K14 -> 6255.138 | CK14: =P14 -> 6772.281 | CL14: =U14 -> 6355.055 | CM14: =Z14 -> 5951.782 | CN14: =AE14 -> 6168.331 | CO14: =AJ14 -> 6246 | CP14: =AO14 -> 4450 | CQ14: =AT14 -> 4789 | CR14: =AY14 -> 5051 | CS14: =BD14 -> 5313 | CT14: =BI14 -> 5661 | CU14: =BN14 -> 6064 | CV14: =BS14 -> 6501.8499 | CW14: =BX14 -> 6876.0376 | CX14: =BY14 -> 7231.5258 | CY14: =BZ14 -> 7608.3789 | CZ14: =CA14 -> 7964.8548 | DB14: =SUM(BO14,BP14,BQ14,BR14) -> 6501.8499
A15: Annual Growth | C15: =C14/B14-1 -> -0.0011518587 | D15: =D14/C14-1 -> 0.053906483 | E15: =E14/D14-1 -> 0.073659392 | F15: =F14/E14-1 -> 0.14343368 | K15: =K14/F14-1 -> 0.041890572 | L15: =L14/G14-1 -> 0.13653184 | M15: =M14/H14-1 -> 0.12479911 | N15: =N14/I14-1 -> 0.098077357 | O15: =O14/J14-1 -> -0.015465903 | P15: =P14/K14-1 -> 0.082674915 | Q15: =Q14/L14-1 -> -0.060587712 | R15: =R14/M14-1 -> -0.026163747 | ... BX15: =BX14/BS14-1 -> 0.057550966 | BY15: =BY14/BX14-1 -> 0.051699566 | BZ15: =BZ14/BY14-1 -> 0.052112529 | CA15: =CA14/BZ14-1 -> 0.046853066 | CD15: =A15 -> Annual Growth | CE15: =B15 -> 0 | CF15: =C15 -> -0.0011518587 | CG15: =D15 -> 0.053906483 | CH15: =E15 -> 0.073659392 | CI15: =F15 -> 0.14343368 | CJ15: =K15 -> 0.041890572 | CK15: =P15 -> 0.082674915 | CL15: =U15 -> -0.061607898 | CM15: =Z15 -> -0.063457043 | CN15: =AE15 -> 0.036383893 | CO15: =AJ15 -> 0.012591575 | CP15: =AO15 -> -0.28754403 | CQ15: =AT15 -> 0.076179775 | CR15: =AY15 -> 0.054708707 | CS15: =BD15 -> 0.051870917 | CT15: =BI15 -> 0.065499718 | CU15: =BN15 -> 0.071188836 | CV15: =BS15 -> 0.072204798 | CW15: =BX15 -> 0.057550966 | CX15: =BY15 -> 0.051699566 | CY15: =BZ15 -> 0.052112529 | CZ15: =CA15 -> 0.046853066
A17: Operating-Related Expenses | CD17: =A17 -> Operating-Related Expenses
A18: Product | B18: =B214 -> 1223.658 | C18: =C214 -> 1166.888 | D18: =D214 -> 1189.573 | E18: =E214 -> 1120.842 | F18: =F214 -> 1092.159 | G18: =G214 -> 172.109 | H18: =H214 -> 261.889 | I18: =I214 -> 407.728 | J18: =J214 -> 250.583 | K18: =SUM(G18:J18) -> 1092.309 | L18: =L214 -> 170.978 | M18: =M214 -> 265.168 | N18: =N214 -> 439.928 | O18: =O214 -> 253.445 | P18: =SUM(L18:O18) -> 1129.519 | Q18: =Q214 -> 182.046 | R18: =R214 -> 278.22 | S18: =S214 -> 453.798 | T18: =T214 -> 267.258 | U18: =SUM(Q18:T18) -> 1181.322 | V18: =V214 -> 174.273 | W18: =W214 -> 268.235 | X18: =X214 -> 438.405 | Y18: =Y214 -> 251.389 | Z18: =SUM(V18:Y18) -> 1132.302 | AA18: =AA214 -> 173 | AB18: =AB214 -> 259.1 | AC18: =AC214 -> 408.4 | AD18: =AD214 -> 239.592 | AE18: =SUM(AA18:AD18) -> 1080.092 | AF18: =AF214 -> 173 | AG18: =AG214 -> 239 | AH18: =AH214 -> 374.5 | AI18: =AI214 -> 221.5 | AJ18: =SUM(AF18:AI18) -> 1008 | CD18: =A18 -> Product | CE18: =B18 -> 1223.658 | CF18: =C18 -> 1166.888 | CG18: =D18 -> 1189.573 | CH18: =E18 -> 1120.842 | CI18: =F18 -> 1092.159 | CJ18: =K18 -> 1092.309 | CK18: =P18 -> 1129.519 | CL18: =U18 -> 1181.322 | CM18: =Z18 -> 1132.302 | CN18: =AE18 -> 1080.092 | CO18: =AJ18 -> 1008
A19: Service | B19: =B217 -> 881.115 | C19: =C217 -> 814.423 | D19: =D217 -> 828.877 | E19: =E217 -> 925.803 | F19: =F217 -> 1224.175 | G19: =G217 -> 309.376 | H19: =H217 -> 324.587 | I19: =I217 -> 304.529 | J19: =J217 -> 356.446 | K19: =SUM(G19:J19) -> 1294.938 | L19: =L217 -> 333.404 | M19: =M217 -> 369.633 | N19: =N217 -> 326.963 | O19: =O217 -> 368.081 | P19: =SUM(L19:O19) -> 1398.081 | Q19: =Q217 -> 326.265 | R19: =R217 -> 368.934 | S19: =S217 -> 301.29 | T19: =T217 -> 340.619 | U19: =SUM(Q19:T19) -> 1337.108 | V19: =V217 -> 314.666 | W19: =W217 -> 314.27 | X19: =X217 -> 297.475 | Y19: =Y217 -> 327.294 | Z19: =SUM(V19:Y19) -> 1253.705 | AA19: =AA217 -> 303.2 | AB19: =AB217 -> 301.8 | AC19: =AC217 -> 299.6 | AD19: =AD217 -> 361.336 | AE19: =SUM(AA19:AD19) -> 1265.936 | AF19: =AF217 -> 330 | AG19: =AG217 -> 354 | AH19: =AH217 -> 336.6 | AI19: =AI217 -> 371.4 | AJ19: =SUM(AF19:AI19) -> 1392 | CD19: =A19 -> Service | CE19: =B19 -> 881.115 | CF19: =C19 -> 814.423 | CG19: =D19 -> 828.877 | CH19: =E19 -> 925.803 | CI19: =F19 -> 1224.175 | CJ19: =K19 -> 1294.938 | CK19: =P19 -> 1398.081 | CL19: =U19 -> 1337.108 | CM19: =Z19 -> 1253.705 | CN19: =AE19 -> 1265.936 | CO19: =AJ19 -> 1392
B20: ______ | C20: ______ | D20: ______ | E20: ______ | F20: ______ | G20: ______ | H20: ______ | I20: ______ | J20: ______ | K20: ______ | L20: ______ | M20: ______ | N20: ______ | O20: ______ | P20: ______ | Q20: ______ | R20: ______ | S20: ______ | T20: ______ | U20: ______ | V20: ______ | W20: ______ | X20: ______ | Y20: ______ | Z20: ______ | AA20: ______ | AB20: ______ | AC20: ______ | AD20: ______ | AE20: ______ | AF20: ______ | AG20: ______ | AH20: ______ | AI20: ______ | AJ20: ______ | AK20: ______ | AL20: ______ | AM20: ______ | AN20: ______ | AO20: ______ | AP20: ______ | AQ20: ______ | AR20: ______ | AS20: ______ | AT20: ______ | AU20: ______ | AV20: ______ | AW20: ______ | AX20: ______ | AY20: ______ | AZ20: ______ | BA20: ______ | BB20: ______ | BC20: ______ | BD20: ______ | BE20: ______ | BF20: ______ | BG20: ______ | BH20: ______ | BI20: ______ | BJ20: ______ | BK20: ______ | BL20: ______ | BM20: ______ | BN20: ______ | BO20: ______ | BP20: ______ | BQ20: ______ | BR20: ______ | BS20: ______ | BT20: ______ | BU20: ______ | BV20: ______ | BW20: ______ | BX20: ______ | BY20: ______ | BZ20: ______ | CA20: ______ | CE20: ______ | CF20: ______ | CG20: ______ | CH20: ______ | CI20: ______ | CJ20: ______ | CK20: ______ | CL20: ______ | CM20: ______ | CN20: ______ | CO20: ______ | CP20: ______ | CQ20: ______ | CR20: ______ | CS20: ______ | CT20: ______ | CU20: ______ | CV20: ______ | CW20: ______ | CX20: ______ | CY20: ______ | CZ20: ______
A21: Total Operating-Related Expenses | B21: =SUM(B18:B19) -> 2104.773 | C21: =SUM(C18:C19) -> 1981.311 | D21: =SUM(D18:D19) -> 2018.45 | E21: =SUM(E18:E19) -> 2046.645 | F21: =SUM(F18:F19) -> 2316.334 | G21: =SUM(G18:G19) -> 481.485 | H21: =SUM(H18:H19) -> 586.476 | I21: =SUM(I18:I19) -> 712.257 | ... AE21: =SUM(AE18:AE19) -> 2346.028 | AF21: =AF220 -> 503 | AG21: =AG220 -> 593 | AH21: =AH220 -> 711 | AI21: =AI220 -> 593 | AJ21: =SUM(AF21:AI21) -> 2400 | AK21: =AK220 -> 361 | AL21: =AL220 -> 351 | AM21: =AM220 -> 367 | AN21: =AN220 -> 407 | AO21: =SUM(AK21:AN21) -> 1486 | AP21: =AP220 -> 374 | AQ21: =AQ220 -> 395 | AR21: =AR220 -> 371 | AS21: =AS220 -> 424 | AT21: =SUM(AP21:AS21) -> 1564 | AU21: =AU220 -> 411 | AV21: =AV220 -> 420 | AW21: =AW220 -> 399 | AX21: =AX220 -> 397 | AY21: =SUM(AU21:AX21) -> 1627 | AZ21: =AZ220 -> 410 | BA21: =BA220 -> 406 | BB21: =BB220 -> 419 | BC21: =BC220 -> 437 | BD21: =SUM(AZ21:BC21) -> 1672 | BE21: =BE220 -> 457 | BF21: =BF220 -> 469 | BG21: =BG220 -> 438 | BH21: =BH220 -> 405 | BI21: =SUM(BE21:BH21) -> 1769 | BJ21: =BJ220 -> 411 | BK21: =BK220 -> 449 | BL21: =BL220 -> 421 | BM21: =BM220 -> 432 | BN21: =SUM(BJ21:BM21) -> 1713 | BO21: =BO220 -> 439 | BP21: =BP220 -> 488.09252 | BQ21: =BQ220 -> 451.69973 | BR21: =BR220 -> 454.33085 | BS21: =SUM(BO21:BR21) -> 1833.1231 | BT21: =BT220 -> 461.25305 | BU21: =BU220 -> 516.94955 | BV21: =BV220 -> 478.95713 | BW21: =BW220 -> 481.46745 | BX21: =SUM(BT21:BW21) -> 1938.6272 | BY21: =BY220 -> 2038.8534 | BZ21: =BZ220 -> 2145.1032 | CA21: =CA220 -> 2245.6078 | CD21: =A21 -> Total Operating-Related Expenses | CE21: =B21 -> 2104.773 | CF21: =C21 -> 1981.311 | CG21: =D21 -> 2018.45 | CH21: =E21 -> 2046.645 | CI21: =F21 -> 2316.334 | CJ21: =K21 -> 2387.247 | CK21: =P21 -> 2527.6 | CL21: =U21 -> 2518.43 | CM21: =Z21 -> 2386.007 | CN21: =AE21 -> 2346.028 | CO21: =AJ21 -> 2400 | CP21: =AO21 -> 1486 | CQ21: =AT21 -> 1564 | CR21: =AY21 -> 1627 | CS21: =BD21 -> 1672 | CT21: =BI21 -> 1769 | CU21: =BN21 -> 1713 | CV21: =BS21 -> 1833.1231 | CW21: =BX21 -> 1938.6272 | CX21: =BY21 -> 2038.8534 | CY21: =BZ21 -> 2145.1032 | CZ21: =CA21 -> 2245.6078 | DB21: =SUM(BO21,BP21,BQ21,BR21) -> 1833.1231
A22: % of Total Revenue | B22: =B21/B14 -> 0.4530744 | C22: =C21/C14 -> 0.42698975 | D22: =D21/D14 -> 0.41274395 | E22: =E21/E14 -> 0.3897972 | F22: =F21/F14 -> 0.38582147 | G22: =G21/G14 -> 0.42210385 | H22: =H21/H14 -> 0.3839342 | I22: =I21/I14 -> 0.35745645 | ... CA22: =CA21/CA14 -> 0.28193958 | CD22: =A22 -> % of Total Revenue | CE22: =B22 -> 0.4530744 | CF22: =C22 -> 0.42698975 | CG22: =D22 -> 0.41274395 | CH22: =E22 -> 0.3897972 | CI22: =F22 -> 0.38582147 | CJ22: =K22 -> 0.38164578 | CK22: =P22 -> 0.37322728 | CL22: =U22 -> 0.39628768 | CM22: =Z22 -> 0.40088952 | CN22: =AE22 -> 0.38033432 | CO22: =AJ22 -> 0.38424592 | CP22: =AO22 -> 0.33393258 | CQ22: =AT22 -> 0.32658175 | CR22: =AY22 -> 0.32211443 | CS22: =BD22 -> 0.31469979 | CT22: =BI22 -> 0.31248896 | CU22: =BN22 -> 0.28248681 | CV22: =BS22 -> 0.2819387 | CW22: =BX22 -> 0.28193958 | CX22: =BY22 -> 0.28193958 | CY22: =BZ22 -> 0.28193958 | CZ22: =CA22 -> 0.28193958 | DB22: =DB21/$DB$14 -> 0.2819387
A23: Selling and general expenses | B23: =B224 -> 1700.533 | C23: =C224 -> 1634.533 | D23: =D224 -> 1766.549 | E23: =E224 -> 1904.556 | F23: =F224 -> 2149.195 | G23: =G224 -> 480.23 | H23: =H224 -> 540.241 | I23: =I224 -> 609.679 | J23: =J224 -> 626.2 | K23: =SUM(G23:J23) -> 2256.35 | L23: =L224 -> 536.643 | M23: =M224 -> 587.687 | N23: =N224 -> 644.545 | O23: =O224 -> 625.309 | P23: =SUM(L23:O23) -> 2394.184 | Q23: =Q224 -> 516.773 | R23: =R224 -> 594.135 | S23: =S224 -> 573.548 | T23: =T224 -> 525.739 | U23: =SUM(Q23:T23) -> 2210.195 | V23: =V224 -> 491.311 | W23: =W224 -> 530.926 | X23: =X224 -> 546.961 | Y23: =Y224 -> 567.053 | Z23: =SUM(V23:Y23) -> 2136.251 | AA23: =AA224 -> 488 | AB23: =AB224 -> 547.7 | AC23: =AC224 -> 597.6 | AD23: =AD224 -> 602.703 | AE23: =SUM(AA23:AD23) -> 2236.003 | AF23: =AF224 -> 503 | AG23: =AG224 -> 580 | AH23: =AH224 -> 552.2 | AI23: =AI224 -> 128.9 | AJ23: =SUM(AF23:AI23) -> 1764.1 | AK23: =AK224 -> 332 | AL23: =AL224 -> 340 | AM23: =AM224 -> 354 | AN23: =AN224 -> 464 | AO23: =SUM(AK23:AN23) -> 1490 | AP23: =AP224 -> 373 | AQ23: =AQ224 -> 374 | AR23: =AR224 -> 388 | AS23: =AS224 -> 364 | AT23: =SUM(AP23:AS23) -> 1499 | AU23: =AU224 -> 331.5 | AV23: =AV224 -> 364.5 | AW23: =AW224 -> 355 | AX23: =AX224 -> 415 | AY23: =SUM(AU23:AX23) -> 1466 | AZ23: =772-'Op Metrics'!AZ140-AZ34-AZ21 -> 335 | BA23: =771-'Op Metrics'!BA140-BA34-BA21 -> 362 | BB23: =914-'Op Metrics'!BB140-BB34-BB21 -> 339 | BC23: =950-'Op Metrics'!BC140-BC34-BC21 -> 406 | BD23: =SUM(AZ23:BC23) -> 1442 | BE23: =829-'Op Metrics'!BE140-BE34-BE21 -> 315 | BF23: =831-'Op Metrics'!BF140-BF34-BF21 -> 339 | BG23: =813-'Op Metrics'!BG140-BG34-BG21-721 -> 340 | BH23: =921-'Op Metrics'!BH140-BH34-BH21-379 -> 383 | BI23: =SUM(BE23:BH23) -> 1377 | BJ23: =805-'Op Metrics'!BJ140-BJ34-BJ21 -> 334 | BK23: =832-'Op Metrics'!BK140-BK34-BK21 -> 325 | BL23: =855-'Op Metrics'!BL140-BL34-BL21 -> 369 | BM23: =961-'Op Metrics'!BM140-BM34-BM21 -> 384 | BN23: =SUM(BJ23:BM23) -> 1412 | BO23: =856-'Op Metrics'!BO140-BO34-BO21 -> 372 | BP23: =BP224 -> 359.36113 | BQ23: =BQ224 -> 397.53765 | BR23: =BR224 -> 413.21026 | BS23: =SUM(BO23:BR23) -> 1542.109 | BT23: =BT224 -> 370.06454 | BU23: =BU224 -> 353.38836 | BV23: =BV224 -> 394.31479 | BW23: =BW224 -> 408.23157 | BX23: =SUM(BT23:BW23) -> 1525.9992 | BY23: =BY224 -> 1563.2314 | BZ23: =BZ224 -> 1594.0943 | CA23: =CA224 -> 1624.7035 | CD23: =A23 -> Selling and general expenses | CE23: =B23 -> 1700.533 | CF23: =C23 -> 1634.533 | CG23: =D23 -> 1766.549 | CH23: =E23 -> 1904.556 | CI23: =F23 -> 2149.195 | CJ23: =K23 -> 2256.35 | CK23: =P23 -> 2394.184 | CL23: =U23 -> 2210.195 | CM23: =Z23 -> 2136.251 | CN23: =AE23 -> 2236.003 | CO23: =AJ23 -> 1764.1 | CP23: =AO23 -> 1490 | CQ23: =AT23 -> 1499 | CR23: =AY23 -> 1466 | CS23: =BD23 -> 1442 | CT23: =BI23 -> 1377 | CU23: =BN23 -> 1412 | CV23: =BS23 -> 1542.109 | CW23: =BX23 -> 1525.9992 | CX23: =BY23 -> 1563.2314 | CY23: =BZ23 -> 1594.0943 | CZ23: =CA23 -> 1624.7035 | DB23: =SUM(BO23,BP23,BQ23,BR23) -> 1542.109
A24: % of Total Revenue | B24: =B23/B14 -> 0.36605752 | C24: =C23/C14 -> 0.35225607 | D24: =D23/D14 -> 0.36123383 | E24: =E23/E14 -> 0.3627354 | F24: =F23/F14 -> 0.35798187 | G24: =G23/G14 -> 0.42100363 | H24: =H23/H14 -> 0.35366664 | I24: =I23/I14 -> 0.3059762 | ... CA24: =CA23/CA14 -> 0.20398408 | CD24: =A24 -> % of Total Revenue | CE24: =B24 -> 0.36605752 | CF24: =C24 -> 0.35225607 | CG24: =D24 -> 0.36123383 | CH24: =E24 -> 0.3627354 | CI24: =F24 -> 0.35798187 | CJ24: =K24 -> 0.36071946 | CK24: =P24 -> 0.35352697 | CL24: =U24 -> 0.34778535 | CM24: =Z24 -> 0.35892628 | CN24: =AE24 -> 0.36249725 | CO24: =AJ24 -> 0.28243676 | CP24: =AO24 -> 0.33483146 | CQ24: =AT24 -> 0.31300898 | CR24: =AY24 -> 0.29023956 | CS24: =BD24 -> 0.27140975 | CT24: =BI24 -> 0.24324324 | CU24: =BN24 -> 0.2328496 | CV24: =BS24 -> 0.23718004 | CW24: =BX24 -> 0.22193003 | CX24: =BY24 -> 0.21616896 | CY24: =BZ24 -> 0.20951826 | CZ24: =CA24 -> 0.20398408 | DB24: =DB23/$DB$14 -> 0.23718004
A26: Other Income/ (Expense) | B26: 10.256 | C26: =18.66+14.5 -> 33.16 | D26: =147.85-131.3 -> 16.55 | E26: 0 | F26: =1.236-1.236 -> 0 | G26: 0 | H26: 0 | I26: 0 | J26: =0-SUM(G26:I26) -> 0 | K26: =SUM(G26:J26) -> 0 | L26: =17.305-17.305 -> 0 | M26: 0 | N26: 0 | O26: =17.305-SUM(L26:N26) -> 17.305 | P26: =SUM(L26:O26) -> 17.305 | Q26: 0 | R26: 0 | S26: 0 | T26: =0-SUM(Q26:S26) -> 0 | U26: =SUM(Q26:T26) -> 0 | V26: 0 | W26: =-13.849+13.849 -> 0 | X26: 0 | Y26: =-3.304+(13.849-0.4)-SUM(V26:X26) -> 10.145 | Z26: =SUM(V26:Y26) -> 10.145 | AA26: 0 | AB26: 0 | AC26: =11.1-7.3-3.8 -> 0 | AD26: =11.058-11.058-SUM(AA26:AC26) -> 0 | AE26: =SUM(AA26:AD26) -> 0 | AF26: 0 | AG26: 13 | AH26: 0 | AI26: =13-SUM(AF26:AH26) -> 0 | AJ26: =SUM(AF26:AI26) -> 13 | AK26: 0 | AL26: 0 | AM26: 0 | AN26: =52-SUM(AK26:AM26) -> 52 | AO26: =SUM(AK26:AN26) -> 52 | AP26: 0 | AQ26: 0 | AR26: 24 | AS26: =-12-SUM(AP26:AR26) -> -36 | AT26: =SUM(AP26:AS26) -> -12 | AU26: 0 | AV26: -9 | AW26: 0 | AX26: 0 | AY26: =SUM(AU26:AX26) -> -9 | AZ26: 0 | BA26: =11 -> 11 | BB26: 0 | BC26: 0 | BD26: =SUM(AZ26:BC26) -> 11 | BE26: 0 | BF26: 0 | BG26: 0 | BH26: 0 | BI26: =SUM(BE26:BH26) -> 0 | BJ26: 0 | BK26: 0 | BL26: 0 | BM26: 0 | BN26: =SUM(BJ26:BM26) -> 0 | BO26: 0 | BP26: 0 | BQ26: 0 | BR26: 0 | BS26: =SUM(BO26:BR26) -> 0 | BT26: 0 | BU26: 0 | BV26: 0 | BW26: 0 | BX26: =SUM(BT26:BW26) -> 0 | BY26: 0 | BZ26: 0 | CA26: 0 | CD26: =A26 -> Other Income/ (Expense) | CE26: =B26 -> 10.256 | CF26: =C26 -> 33.16 | CG26: =D26 -> 16.55 | CH26: =E26 -> 0 | CI26: =F26 -> 0 | CJ26: =K26 -> 0 | CK26: =P26 -> 17.305 | CL26: =U26 -> 0 | CM26: =Z26 -> 10.145 | CN26: =AE26 -> 0 | CO26: =AJ26 -> 13 | CP26: =AO26 -> 52 | CQ26: =AT26 -> -12 | CR26: =AY26 -> -9 | CS26: =BD26 -> 11 | CT26: =BI26 -> 0 | CU26: =BN26 -> 0 | CV26: =BS26 -> 0 | CW26: =BX26 -> 0 | CX26: =BY26 -> 0 | CY26: =BZ26 -> 0 | CZ26: =CA26 -> 0 | DB26: =SUM(BO26,BP26,BQ26,BR26) -> 0
B27: ______ | C27: ______ | D27: ______ | E27: ______ | F27: ______ | G27: ______ | H27: ______ | I27: ______ | J27: ______ | K27: ______ | L27: ______ | M27: ______ | N27: ______ | O27: ______ | P27: ______ | Q27: ______ | R27: ______ | S27: ______ | T27: ______ | U27: ______ | V27: ______ | W27: ______ | X27: ______ | Y27: ______ | Z27: ______ | AA27: ______ | AB27: ______ | AC27: ______ | AD27: ______ | AE27: ______ | AF27: ______ | AG27: ______ | AH27: ______ | AI27: ______ | AJ27: ______ | AK27: ______ | AL27: ______ | AM27: ______ | AN27: ______ | AO27: ______ | AP27: ______ | AQ27: ______ | AR27: ______ | AS27: ______ | AT27: ______ | AU27: ______ | AV27: ______ | AW27: ______ | AX27: ______ | AY27: ______ | AZ27: ______ | BA27: ______ | BB27: ______ | BC27: ______ | BD27: ______ | BE27: ______ | BF27: ______ | BG27: ______ | BH27: ______ | BI27: ______ | BJ27: ______ | BK27: ______ | BL27: ______ | BM27: ______ | BN27: ______ | BO27: ______ | BP27: ______ | BQ27: ______ | BR27: ______ | BS27: ______ | BT27: ______ | BU27: ______ | BV27: ______ | BW27: ______ | BX27: ______ | BY27: ______ | BZ27: ______ | CA27: ______ | CE27: ______ | CF27: ______ | CG27: ______ | CH27: ______ | CI27: ______ | CJ27: ______ | CK27: ______ | CL27: ______ | CM27: ______ | CN27: ______ | CO27: ______ | CP27: ______ | CQ27: ______ | CR27: ______ | CS27: ______ | CT27: ______ | CU27: ______ | CV27: ______ | CW27: ______ | CX27: ______ | CY27: ______ | CZ27: ______
A28: Total Expenses | B28: =B23+B21-B26 -> 3795.05 | C28: =C23+C21-C26 -> 3582.684 | D28: =D23+D21-D26 -> 3768.449 | E28: =E23+E21-E26 -> 3951.201 | F28: =F23+F21-F26 -> 4465.529 | G28: =G23+G21-G26 -> 961.715 | H28: =H23+H21-H26 -> 1126.717 | I28: =I23+I21-I26 -> 1321.936 | ... AN28: =AN23+AN21-AN26 -> 819 | AO28: =SUM(AK28:AN28) -> 2924 | AP28: =AP23+AP21-AP26 -> 747 | AQ28: =AQ23+AQ21-AQ26 -> 769 | AR28: =AR23+AR21-AR26 -> 735 | AS28: =AS23+AS21-AS26 -> 824 | AT28: =SUM(AP28:AS28) -> 3075 | AU28: =AU23+AU21-AU26 -> 742.5 | AV28: =AV23+AV21-AV26 -> 793.5 | AW28: =AW23+AW21-AW26 -> 754 | AX28: =AX23+AX21-AX26 -> 812 | AY28: =SUM(AU28:AX28) -> 3102 | AZ28: =AZ23+AZ21-AZ26 -> 745 | BA28: =BA23+BA21-BA26 -> 757 | BB28: =BB23+BB21-BB26 -> 758 | BC28: =BC23+BC21-BC26 -> 843 | BD28: =SUM(AZ28:BC28) -> 3103 | BE28: =BE23+BE21-BE26 -> 772 | BF28: =BF23+BF21-BF26 -> 808 | BG28: =BG23+BG21-BG26 -> 778 | BH28: =BH23+BH21-BH26 -> 788 | BI28: =SUM(BE28:BH28) -> 3146 | BJ28: =BJ23+BJ21-BJ26 -> 745 | BK28: =BK23+BK21-BK26 -> 774 | BL28: =BL23+BL21-BL26 -> 790 | BM28: =BM23+BM21-BM26 -> 816 | BN28: =SUM(BJ28:BM28) -> 3125 | BO28: =BO23+BO21-BO26 -> 811 | BP28: =BP23+BP21-BP26 -> 847.45366 | BQ28: =BQ23+BQ21-BQ26 -> 849.23738 | BR28: =BR23+BR21-BR26 -> 867.54111 | BS28: =SUM(BO28:BR28) -> 3375.2321 | BT28: =BT23+BT21-BT26 -> 831.31759 | BU28: =BU23+BU21-BU26 -> 870.33791 | BV28: =BV23+BV21-BV26 -> 873.27192 | BW28: =BW23+BW21-BW26 -> 889.69902 | BX28: =SUM(BT28:BW28) -> 3464.6264 | BY28: =BY23+BY21-BY26 -> 3602.0848 | BZ28: =BZ23+BZ21-BZ26 -> 3739.1975 | CA28: =CA23+CA21-CA26 -> 3870.3114 | CD28: =A28 -> Total Expenses | CE28: =B28 -> 3795.05 | CF28: =C28 -> 3582.684 | CG28: =D28 -> 3768.449 | CH28: =E28 -> 3951.201 | CI28: =F28 -> 4465.529 | CJ28: =K28 -> 4643.597 | CK28: =P28 -> 4904.479 | CL28: =U28 -> 4728.625 | CM28: =Z28 -> 4512.113 | CN28: =AE28 -> 4582.031 | CO28: =AJ28 -> 4151.1 | CP28: =AO28 -> 2924 | CQ28: =AT28 -> 3075 | CR28: =AY28 -> 3102 | CS28: =BD28 -> 3103 | CT28: =BI28 -> 3146 | CU28: =BN28 -> 3125 | CV28: =BS28 -> 3375.2321 | CW28: =BX28 -> 3464.6264 | CX28: =BY28 -> 3602.0848 | CY28: =BZ28 -> 3739.1975 | CZ28: =CA28 -> 3870.3114 | DB28: =SUM(BO28,BP28,BQ28,BR28) -> 3375.2321
A30: EBITDA | B30: =B14-B28 -> 850.485 | C30: =C14-C28 -> 1057.5 | D30: =D14-D28 -> 1121.871 | E30: =E14-E28 -> 1299.337 | F30: =F14-F28 -> 1538.113 | G30: =G14-G28 -> 178.964 | H30: =H14-H28 -> 400.826 | I30: =I14-I28 -> 670.634 | ... M30: =M14-M28 -> 495.691 | N30: =N14-N28+N26+N42 -> 761.137 | O30: =O14-O28 -> 340.158 | P30: =P14-P28 -> 1867.802 | Q30: =Q14-Q28 -> 192.787 | R30: =R14-R28 -> 431.936 | S30: =S14-S28 -> 719.905 | T30: =U30-S30-R30-Q30 -> 281.802 | U30: =U14-U28 -> 1626.43 | V30: =V14-V28 -> 167.957 | W30: =W14-W28 -> 351.749 | X30: =X14-X28 -> 593.062 | Y30: =Y14-Y28 -> 326.901 | Z30: =Z14-Z28 -> 1439.669 | AA30: =AA14-AA28 -> 226.2 | AB30: =AB14-AB28 -> 365.5 | ... AJ30: =AJ14-AJ28 -> 2094.9 | AK30: =AK39+AK34 -> 342 | AL30: =AL39+AL34 -> 381 | AM30: =AM39+AM34 -> 395 | AN30: =AN39+AN34 -> 408 | AO30: =SUM(AK30:AN30) -> 1526 | AP30: =AP39+AP34 -> 434 | AQ30: =AQ39+AQ34 -> 481 | AR30: =AR39+AR34 -> 417 | AS30: =AS39+AS34 -> 382 | AT30: =SUM(AP30:AS30) -> 1714 | AU30: =AU39+AU34 -> 453.5 | AV30: =AV39+AV34 -> 508.5 | AW30: =AW39+AW34 -> 509 | AX30: =AX39+AX34 -> 478 | AY30: =SUM(AU30:AX30) -> 1949 | AZ30: =AZ39+AZ34 -> 528 | BA30: =BA39+BA34 -> 585 | BB30: =BB39+BB34 -> 566 | BC30: =BC39+BC34 -> 531 | BD30: =SUM(AZ30:BC30) -> 2210 | BE30: =BE39+BE34 -> 569 | BF30: =BF39+BF34 -> 674 | BG30: =BG39+BG34 -> 661 | BH30: =BH39+BH34 -> 611 | BI30: =SUM(BE30:BH30) -> 2515 | BJ30: =BJ39+BJ34 -> 708 | BK30: =BK39+BK34 -> 735 | BL30: =BL39+BL34 -> 723 | BM30: =BM39+BM34 -> 773 | BN30: =SUM(BJ30:BM30) -> 2939 | BO30: =BO39+BO34 -> 756 | BP30: =BP39+BP34 -> 792.92857 | BQ30: =BQ39+BQ34 -> 774.09206 | BR30: =BR39+BR34 -> 803.59713 | BS30: =SUM(BO30:BR30) -> 3126.6178 | BT30: =BT39+BT34 -> 815.11416 | BU30: =BU39+BU34 -> 867.02705 | BV30: =BV39+BV34 -> 848.01583 | BW30: =BW39+BW34 -> 881.25417 | BX30: =SUM(BT30:BW30) -> 3411.4112 | BY30: =BY39+BY34 -> 3629.441 | BZ30: =BZ39+BZ34 -> 3869.1814 | CA30: =CA39+CA34 -> 4094.5434 | CB30: =(CA30/BN30)^(1/5)-1 -> 0.068565574 | CD30: =A30 -> EBITDA | CE30: =CE14-CE28 -> 850.485 | CF30: =CF14-CF28 -> 1057.5 | CG30: =CG14-CG28 -> 1121.871 | CH30: =CH14-CH28 -> 1299.337 | CI30: =CI14-CI28 -> 1538.113 | CJ30: =CJ14-CJ28 -> 1611.541 | CK30: =CK14-CK28 -> 1867.802 | CL30: =CL14-CL28 -> 1626.43 | ... CO30: =CO14-CO28 -> 2094.9 | CP30: =AO30 -> 1526 | CQ30: =AT30 -> 1714 | CR30: =AY30 -> 1949 | CS30: =BD30 -> 2210 | CT30: =BI30 -> 2515 | CU30: =BN30 -> 2939 | CV30: =BS30 -> 3126.6178 | CW30: =BX30 -> 3411.4112 | CX30: =BY30 -> 3629.441 | CY30: =BZ30 -> 3869.1814 | CZ30: =CA30 -> 4094.5434 | DB30: =SUM(BO30,BP30,BQ30,BR30) -> 3126.6178
A31: EBITDA Margin | B31: =B30/B14 -> 0.18307579 | C31: =C30/C14 -> 0.22790045 | D31: =D30/D14 -> 0.22940646 | E31: =E30/E14 -> 0.2474674 | F31: =F30/F14 -> 0.25619666 | G31: =G30/G14 -> 0.15689252 | H31: =H30/H14 -> 0.26239916 | I31: =I30/I14 -> 0.33656735 | ... CA31: =CA30/CA14 -> 0.51407634 | CD31: =A31 -> EBITDA Margin | CE31: =B31 -> 0.18307579 | CF31: =C31 -> 0.22790045 | CG31: =D31 -> 0.22940646 | CH31: =E31 -> 0.2474674 | CI31: =F31 -> 0.25619666 | CJ31: =K31 -> 0.25763476 | CK31: =P31 -> 0.27580102 | CL31: =U31 -> 0.25592697 | CM31: =Z31 -> 0.24188873 | CN31: =AE31 -> 0.25716843 | CO31: =AJ31 -> 0.33539866 | CP31: =AO31 -> 0.34292135 | CQ31: =AT31 -> 0.35790353 | CR31: =AY31 -> 0.38586419 | CS31: =BD31 -> 0.41596085 | CT31: =BI31 -> 0.4442678 | CU31: =BN31 -> 0.48466359 | CV31: =BS31 -> 0.48088126 | CW31: =BX31 -> 0.49613039 | CX31: =BY31 -> 0.50189146 | CY31: =BZ31 -> 0.50854216 | CZ31: =CA31 -> 0.51407634 | DB31: =DB30/$DB$14 -> 0.48088126
A32: Year-over-Year Growth | C32: =C30/B30-1 -> 0.24340817 | D32: =D30/C30-1 -> 0.060870922 | E32: =E30/D30-1 -> 0.15818753 | F32: =F30/E30-1 -> 0.18376757 | K32: =K30/F30-1 -> 0.047739015 | L32: =L30/G30-1 -> 0.42706354 | M32: =M30/H30-1 -> 0.23667377 | N32: =N30/I30-1 -> 0.1349514 | O32: =O30/J30-1 -> -0.058039361 | P32: =P30/K30-1 -> 0.15901612 | Q32: =Q30/L30-1 -> -0.24513593 | R32: =R30/M30-1 -> -0.12861843 | ... BX32: =BX30/BS30-1 -> 0.091086751 | BY32: =BY30/BX30-1 -> 0.063911912 | BZ32: =BZ30/BY30-1 -> 0.066054363 | CA32: =CA30/BZ30-1 -> 0.058245385 | CD32: =A32 -> Year-over-Year Growth | CF32: =C32 -> 0.24340817 | CG32: =D32 -> 0.060870922 | CH32: =E32 -> 0.15818753 | CI32: =F32 -> 0.18376757 | CJ32: =K32 -> 0.047739015 | CK32: =P32 -> 0.15901612 | CL32: =U32 -> -0.12922783 | CM32: =Z32 -> -0.1148288 | CN32: =AE32 -> 0.10185049 | CO32: =AJ32 -> 0.32062031 | CP32: =AO32 -> -0.27156428 | CQ32: =AT32 -> 0.1231979 | CR32: =AY32 -> 0.13710618 | CS32: =BD32 -> 0.13391483 | CT32: =BI32 -> 0.13800905 | CU32: =BN32 -> 0.16858847 | CV32: =BS32 -> 0.063837275 | CW32: =BX32 -> 0.091086751 | CX32: =BY32 -> 0.063911912 | CY32: =BZ32 -> 0.066054363 | CZ32: =CA32 -> 0.058245385
A34: Depreciation and Amortization | B34: =B35+B36 -> 180.357 | C34: =C35+C36 -> 123.088 | D34: =D35+D36 -> 115.797 | E34: =E35+E36 -> 124.647 | F34: =F35+F36 -> 150.985 | G34: =G35+G36 -> 39.49 | H34: =H35+H36 -> 40.423 | I34: =I35+I36 -> 39.005 | ... AI34: =AI35+AI36 -> 40.1 | AJ34: =SUM(AF34:AI34) -> 156 | AK34: =AK35+AK36 -> 31 | AL34: =AL35+AL36 -> 34 | AM34: =AM35+AM36 -> 39 | AN34: =AN35+AN36 -> 37 | AO34: =SUM(AK34:AN34) -> 141 | AP34: =AP35+AP36 -> 35 | AQ34: =AQ35+AQ36 -> 35 | AR34: =AR35+AR36 -> 33 | AS34: =AS35+AS36 -> 34 | AT34: =SUM(AP34:AS34) -> 137 | AU34: =AU35+AU36 -> 33 | AV34: =AV35+AV36 -> 34 | AW34: =AW35+AW36 -> 33 | AX34: =AX35+AX36 -> 34 | AY34: =SUM(AU34:AX34) -> 134 | AZ34: =AZ35+AZ36 -> 33 | BA34: =BA35+BA36 -> 33 | BB34: =BB35+BB36 -> 38 | BC34: =BC35+BC36 -> 53 | BD34: =SUM(AZ34:BC34) -> 157 | BE34: =BE35+BE36 -> 42 | BF34: =BF35+BF36 -> 45 | BG34: =BG35+BG36 -> 47 | BH34: =BH35+BH36 -> 47 | BI34: =SUM(BE34:BH34) -> 181 | BJ34: =BJ35+BJ36 -> 43 | BK34: =BK35+BK36 -> 45 | BL34: =BL35+BL36 -> 46 | BM34: =BM35+BM36 -> 46 | BN34: =SUM(BJ34:BM34) -> 180 | BO34: =BO35+BO36 -> 45 | BP34: =BP37*BP14 -> 47.277577 | BQ34: =BQ37*BQ14 -> 47.731036 | BR34: =BR37*BR14 -> 46.706683 | BS34: =SUM(BO34:BR34) -> 186.7153 | BT34: =BT37*BT14 -> 46.100089 | BU34: =BU37*BU14 -> 48.646219 | BV34: =BV37*BV14 -> 48.196057 | BW34: =BW37*BW14 -> 49.586689 | BX34: =SUM(BT34:BW34) -> 192.52905 | BY34: =BY37*BY14 -> 195.2512 | BZ34: =BZ37*BZ14 -> 197.81785 | CA34: =CA37*CA14 -> 199.12137 | CD34: =A34 -> Depreciation and Amortization | CE34: =CE35+CE36 -> 180.357 | CF34: =CF35+CF36 -> 123.088 | CG34: =CG35+CG36 -> 115.797 | CH34: =CH35+CH36 -> 124.647 | CI34: =CI35+CI36 -> 150.985 | CJ34: =CJ35+CJ36 -> 161.587 | CK34: =CK35+CK36 -> 160.989 | CL34: =CL35+CL36 -> 178.346 | ... CO34: =CO35+CO36 -> 156 | CP34: =AO34 -> 141 | CQ34: =AT34 -> 137 | CR34: =AY34 -> 134 | CS34: =BD34 -> 157 | CT34: =BI34 -> 181 | CU34: =BN34 -> 180 | CV34: =BS34 -> 186.7153 | CW34: =BX34 -> 192.52905 | CX34: =BY34 -> 195.2512 | CY34: =BZ34 -> 197.81785 | CZ34: =CA34 -> 199.12137 | DB34: =SUM(BO34,BP34,BQ34,BR34) -> 186.7153
A35: Depreciation | B35: 88.802 | C35: 86.818 | D35: 82.826 | E35: 92.177 | F35: 106.75 | G35: 27.564 | H35: 28.316 | I35: 26.868 | J35: =113.2-SUM(G35:I35) -> 30.452 | K35: =SUM(G35:J35) -> 113.2 | L35: 28.905 | M35: 28.798 | N35: 26.199 | O35: =112.586-SUM(L35:N35) -> 28.684 | P35: =SUM(L35:O35) -> 112.586 | Q35: 27.527 | R35: 30.411 | S35: 29.952 | T35: =119.849-SUM(Q35:S35) -> 31.959 | U35: =SUM(Q35:T35) -> 119.849 | V35: 29.412 | W35: 28.782 | X35: 26.031 | Y35: =112.764-SUM(V35:X35) -> 28.539 | Z35: =SUM(V35:Y35) -> 112.764 | AA35: 25.9 | AB35: 26.2 | AC35: 23.3 | AD35: =104.504-SUM(AA35:AC35) -> 29.104 | AE35: =SUM(AA35:AD35) -> 104.504 | AF35: 25 | AG35: 25 | AH35: 23.1 | AI35: =98-SUM(AF35:AH35) -> 24.9 | AJ35: =SUM(AF35:AI35) -> 98 | AK35: 22 | AL35: 23 | AM35: 24 | AN35: =93-SUM(AK35:AM35) -> 24 | AO35: =SUM(AK35:AN35) -> 93 | AP35: 23 | AQ35: 22 | AR35: 20 | AS35: =86-SUM(AP35:AR35) -> 21 | AT35: =SUM(AP35:AS35) -> 86 | AU35: 21 | AV35: 22 | AW35: 21 | AX35: =86-SUM(AU35:AW35) -> 22 | AY35: =SUM(AU35:AX35) -> 86 | AZ35: 22 | BA35: =43-AZ35 -> 21 | BB35: =64-BA35-AZ35 -> 21 | BC35: =90-SUM(AZ35:BB35) -> 26 | BD35: =SUM(AZ35:BC35) -> 90 | BE35: 18 | BF35: =40-BE35 -> 22 | BG35: =63-BF35-BE35 -> 23 | BH35: =85-SUM(BE35:BG35) -> 22 | BI35: =SUM(BE35:BH35) -> 85 | BJ35: 19 | BK35: =39-BJ35 -> 20 | BL35: =61-BK35-BJ35 -> 22 | BM35: =82-SUM(BJ35:BL35) -> 21 | BN35: =SUM(BJ35:BM35) -> 82 | BO35: 21 | BP35: =BP34-BP36 -> 12.777577 | BQ35: =BQ34-BQ36 -> 13.231036 | BR35: =BR34-BR36 -> 12.206683 | BS35: =SUM(BO35:BR35) -> 59.215296 | BT35: =BT34-BT36 -> 15.975089 | BU35: =BU34-BU36 -> 18.521219 | BV35: =BV34-BV36 -> 18.071057 | BW35: =BW34-BW36 -> 19.461689 | BX35: =SUM(BT35:BW35) -> 72.029054 | BY35: =BY34-BY36 -> 80.751197 | BZ35: =BZ34-BZ36 -> 95.317851 | CA35: =CA34-CA36 -> 98.621369 | CD35: =A35 -> Depreciation | CE35: =B35 -> 88.802 | CF35: =C35 -> 86.818 | CG35: =D35 -> 82.826 | CH35: =E35 -> 92.177 | CI35: =F35 -> 106.75 | CJ35: =K35 -> 113.2 | CK35: =P35 -> 112.586 | CL35: =U35 -> 119.849 | CM35: =Z35 -> 112.764 | CN35: =AE35 -> 104.504 | CO35: =AJ35 -> 98 | CP35: =AO35 -> 93 | CQ35: =AT35 -> 86 | CR35: =AY35 -> 86 | CS35: =BD35 -> 90 | CT35: =BI35 -> 85 | CU35: =BN35 -> 82 | CV35: =BS35 -> 59.215296 | CW35: =BX35 -> 72.029054 | CX35: =BY35 -> 80.751197 | CY35: =BZ35 -> 95.317851 | CZ35: =CA35 -> 98.621369 | DB35: =SUM(BO35,BP35,BQ35,BR35) -> 59.215296
A36: Amortization | B36: =34.919+56.636 -> 91.555 | C36: 36.27 | D36: 32.971 | E36: 32.47 | F36: 44.235 | G36: 11.926 | H36: 12.107 | I36: 12.137 | J36: =48.387-SUM(G36:I36) -> 12.217 | K36: =SUM(G36:J36) -> 48.387 | L36: 11.612 | M36: 11.468 | N36: 11.709 | O36: =48.403-SUM(L36:N36) -> 13.614 | P36: =SUM(L36:O36) -> 48.403 | Q36: 14.2 | R36: 13.144 | S36: 13.637 | T36: =58.497-SUM(Q36:S36) -> 17.516 | U36: =SUM(Q36:T36) -> 58.497 | V36: 14.204 | W36: 11.44 | X36: 11.066 | Y36: =52.72-SUM(V36:X36) -> 16.01 | Z36: =SUM(V36:Y36) -> 52.72 | AA36: 10 | AB36: 13 | AC36: 8.4 | AD36: =45.595-SUM(AA36:AC36) -> 14.195 | AE36: =SUM(AA36:AD36) -> 45.595 | AF36: 14 | AG36: 14 | AH36: 14.8 | AI36: =58-SUM(AF36:AH36) -> 15.2 | AJ36: =SUM(AF36:AI36) -> 58 | AK36: 9 | AL36: 11 | AM36: 15 | AN36: =48-SUM(AK36:AM36) -> 13 | AO36: =SUM(AK36:AN36) -> 48 | AP36: 12 | AQ36: 13 | AR36: 13 | AS36: =51-SUM(AP36:AR36) -> 13 | AT36: =SUM(AP36:AS36) -> 51 | AU36: 12 | AV36: 12 | AW36: 12 | AX36: =48-SUM(AU36:AW36) -> 12 | AY36: =+SUM(AU36:AX36) -> 48 | AZ36: 11 | BA36: =23-AZ36 -> 12 | BB36: =40-BA36-AZ36 -> 17 | BC36: =67-SUM(AZ36:BB36) -> 27 | BD36: =+SUM(AZ36:BC36) -> 67 | BE36: 24 | BF36: =47-BE36 -> 23 | BG36: =71-BF36-BE36 -> 24 | BH36: =96-SUM(BE36:BG36) -> 25 | BI36: =+SUM(BE36:BH36) -> 96 | BJ36: 24 | BK36: =49-BJ36 -> 25 | BL36: =73-BK36-BJ36 -> 24 | BM36: =98-SUM(BJ36:BL36) -> 25 | BN36: =+SUM(BJ36:BM36) -> 98 | BO36: 24 | BP36: =($BS$36-$BO$36)/3 -> 34.5 | BQ36: =($BS$36-$BO$36)/3 -> 34.5 | BR36: =+BS36-SUM(BO36:BQ36) -> 34.5 | BS36: 127.5 | BT36: =+$BX$36/4 -> 30.125 | BU36: =+$BX$36/4 -> 30.125 | BV36: =+$BX$36/4 -> 30.125 | BW36: =+BX36-SUM(BT36:BV36) -> 30.125 | BX36: =88+32.5 -> 120.5 | BY36: =82+32.5 -> 114.5 | BZ36: =70+32.5 -> 102.5 | CA36: =68+32.5 -> 100.5 | CD36: =A36 -> Amortization | CE36: =B36 -> 91.555 | CF36: =C36 -> 36.27 | CG36: =D36 -> 32.971 | CH36: =E36 -> 32.47 | CI36: =F36 -> 44.235 | CJ36: =K36 -> 48.387 | CK36: =P36 -> 48.403 | CL36: =U36 -> 58.497 | CM36: =Z36 -> 52.72 | CN36: =AE36 -> 45.595 | CO36: =AJ36 -> 58 | CP36: =AO36 -> 48 | CQ36: =AT36 -> 51 | CR36: =AY36 -> 48 | CS36: =BD36 -> 67 | CT36: =BI36 -> 96 | CU36: =BN36 -> 98 | CV36: =BS36 -> 127.5 | CW36: =BX36 -> 120.5 | CX36: =BY36 -> 114.5 | CY36: =BZ36 -> 102.5 | CZ36: =CA36 -> 100.5 | DB36: =SUM(BO36,BP36,BQ36,BR36) -> 127.5
A37: % of Total Revenue | B37: =B34/B14 -> 0.038823731 | C37: =C34/C14 -> 0.026526534 | D37: =D34/D14 -> 0.023678819 | E37: =E34/E14 -> 0.023739853 | F37: =F34/F14 -> 0.025148901 | G37: =G34/G14 -> 0.034619731 | H37: =H34/H14 -> 0.026462758 | I37: =I34/I14 -> 0.019575222 | ... BO37: =BO34/BO14 -> 0.028717294 | BP37: =+BK37-0.001 -> 0.028821074 | BQ37: =+BL37-0.001 -> 0.029403173 | BR37: =+BM37-0.001 -> 0.027949025 | BS37: =BS34/BS14 -> 0.028717257 | BT37: 0.028 | BU37: 0.028 | BV37: 0.028 | BW37: 0.028 | BX37: =BX34/BX14 -> 0.028 | BY37: =BX37-0.1% -> 0.027 | BZ37: =BY37-0.1% -> 0.026 | CA37: =BZ37-0.1% -> 0.025 | CD37: =A37 -> % of Total Revenue | CE37: =B37 -> 0.038823731 | CF37: =C37 -> 0.026526534 | CG37: =D37 -> 0.023678819 | CH37: =E37 -> 0.023739853 | CI37: =F37 -> 0.025148901 | CJ37: =K37 -> 0.025832683 | CK37: =P37 -> 0.023771754 | CL37: =U37 -> 0.028063644 | CM37: =Z37 -> 0.02780411 | CN37: =AE37 -> 0.024333811 | CO37: =AJ37 -> 0.024975985 | CP37: =AO37 -> 0.031685393 | CQ37: =AT37 -> 0.028607225 | CR37: =AY37 -> 0.0265294 | CS37: =BD37 -> 0.02955016 | CT37: =BI37 -> 0.03197315 | CU37: =BN37 -> 0.029683377 | CV37: =BS37 -> 0.028717257 | CW37: =BX37 -> 0.028 | CX37: =BY37 -> 0.027 | CY37: =BZ37 -> 0.026 | CZ37: =CA37 -> 0.025 | DB37: =DB36/$DB$14 -> 0.019609804
A39: Operating Profit | B39: =B14-B28-B34 -> 670.128 | C39: =C14-C28-C34 -> 934.412 | D39: =D14-D28-D34 -> 1006.074 | E39: =E14-E28-E34 -> 1174.69 | F39: =F14-F28-F34 -> 1387.128 | G39: =G14-G28-G34 -> 139.474 | H39: =H14-H28-H34 -> 360.403 | I39: =I14-I28-I34 -> 631.629 | ... AI39: =AI14-AI28-AI34 -> 242 | AJ39: =SUM(AF39:AI39) -> 1422.9 | AK39: =AK14-AK28-AK34 -> 311 | AL39: =AL14-AL28-AL34 -> 347 | AM39: =AM14-AM28-AM34 -> 356 | AN39: =AN14-AN28-AN34 -> 371 | AO39: =SUM(AK39:AN39) -> 1385 | AP39: =AP14-AP28-AP34 -> 399 | AQ39: =AQ14-AQ28-AQ34 -> 446 | AR39: =AR14-AR28-AR34 -> 384 | AS39: =AS14-AS28-AS34 -> 348 | AT39: =SUM(AP39:AS39) -> 1577 | AU39: =AU14-AU28-AU34 -> 420.5 | AV39: =AV14-AV28-AV34 -> 474.5 | AW39: =AW14-AW28-AW34 -> 476 | AX39: =AX14-AX28-AX34 -> 444 | AY39: =SUM(AU39:AX39) -> 1815 | AZ39: =AZ14-AZ28-AZ34 -> 495 | BA39: =BA14-BA28-BA34 -> 552 | BB39: =BB14-BB28-BB34 -> 528 | BC39: =BC14-BC28-BC34 -> 478 | BD39: =SUM(AZ39:BC39) -> 2053 | BE39: =BE14-BE28-BE34 -> 527 | BF39: =BF14-BF28-BF34 -> 629 | BG39: =BG14-BG28-BG34 -> 614 | BH39: =BH14-BH28-BH34 -> 564 | BI39: =SUM(BE39:BH39) -> 2334 | BJ39: =BJ14-BJ28-BJ34 -> 665 | BK39: =BK14-BK28-BK34 -> 690 | BL39: =BL14-BL28-BL34 -> 677 | BM39: =BM14-BM28-BM34 -> 727 | BN39: =SUM(BJ39:BM39) -> 2759 | BO39: =BO14-BO28-BO34 -> 711 | BP39: ='Op Metrics'!BP142 -> 745.65099 | BQ39: ='Op Metrics'!BQ142 -> 726.36102 | BR39: ='Op Metrics'!BR142 -> 756.89044 | BS39: =SUM(BO39:BR39) -> 2939.9025 | BT39: ='Op Metrics'!BT142 -> 769.01407 | BU39: ='Op Metrics'!BU142 -> 818.38083 | BV39: ='Op Metrics'!BV142 -> 799.81978 | BW39: ='Op Metrics'!BW142 -> 831.66748 | BX39: =SUM(BT39:BW39) -> 3218.8822 | BY39: ='Op Metrics'!BY142 -> 3434.1898 | BZ39: ='Op Metrics'!BZ142 -> 3671.3636 | CA39: ='Op Metrics'!CA142 -> 3895.422 | CB39: =(CA39/BN39)^(1/5)-1 -> 0.071422008 | CD39: =A39 -> Operating Profit | CE39: =CE14-CE28-CE34 -> 670.128 | CF39: =CF14-CF28-CF34 -> 934.412 | CG39: =CG14-CG28-CG34 -> 1006.074 | CH39: =CH14-CH28-CH34 -> 1174.69 | CI39: =CI14-CI28-CI34 -> 1387.128 | CJ39: =CJ14-CJ28-CJ34 -> 1449.954 | CK39: =CK14-CK28-CK34 -> 1706.813 | CL39: =CL14-CL28-CL34 -> 1448.084 | ... CO39: =CO14-CO28-CO34 -> 1938.9 | CP39: =AO39 -> 1385 | CQ39: =AT39 -> 1577 | CR39: =AY39 -> 1815 | CS39: =BD39 -> 2053 | CT39: =BI39 -> 2334 | CU39: =BN39 -> 2759 | CV39: =BS39 -> 2939.9025 | CW39: =BX39 -> 3218.8822 | CX39: =BY39 -> 3434.1898 | CY39: =BZ39 -> 3671.3636 | CZ39: =CA39 -> 3895.422 | DB39: =SUM(BO39,BP39,BQ39,BR39) -> 2939.9025
A40: Operating Margin | B40: =B39/B14 -> 0.14425206 | C40: =C39/C14 -> 0.20137391 | D40: =D39/D14 -> 0.20572764 | E40: =E39/E14 -> 0.22372755 | F40: =F39/F14 -> 0.23104775 | G40: =G39/G14 -> 0.12227279 | H40: =H39/H14 -> 0.2359364 | I40: =I39/I14 -> 0.31699213 | ... CA40: =CA39/CA14 -> 0.48907634 | CD40: =A40 -> Operating Margin | CE40: =B40 -> 0.14425206 | CF40: =C40 -> 0.20137391 | CG40: =D40 -> 0.20572764 | CH40: =E40 -> 0.22372755 | CI40: =F40 -> 0.23104775 | CJ40: =K40 -> 0.23180208 | CK40: =P40 -> 0.25202926 | CL40: =U40 -> 0.22786333 | CM40: =Z40 -> 0.21408462 | CN40: =AE40 -> 0.23283462 | CO40: =AJ40 -> 0.2278098 | CP40: =AO40 -> 0.31123596 | CQ40: =AT40 -> 0.3292963 | CR40: =AY40 -> 0.35933479 | CS40: =BD40 -> 0.38641069 | CT40: =BI40 -> 0.41229465 | CU40: =BN40 -> 0.45498021 | CV40: =BS40 -> 0.452164 | CW40: =BX40 -> 0.46813039 | CX40: =BY40 -> 0.47489146 | CY40: =BZ40 -> 0.48254216 | CZ40: =CA40 -> 0.48907634 | DB40: =DB39/$DB$14 -> 0.452164
A42: Interest Expense, Net | B42: -55.07 | C42: -22.517 | D42: -7.097 | E42: -5.785 | F42: -5.202 | G42: 2.509 | H42: -8.555 | I42: -7.515 | J42: =-13.631-SUM(G42:I42) -> -0.07 | K42: =SUM(G42:J42) -> -13.631 | L42: -1.204 | M42: -12.099 | N42: -15.423 | O42: =-40.581-SUM(L42:N42) -> -11.855 | P42: =SUM(L42:O42) -> -40.581 | Q42: -17.83 | R42: -20.354 | S42: -22.002 | T42: =-75.624-SUM(Q42:S42) -> -15.438 | U42: =SUM(Q42:T42) -> -75.624 | V42: -20.591 | W42: -18.499 | X42: -17.827 | Y42: =-76.867-SUM(V42:X42) -> -19.95 | Z42: =SUM(V42:Y42) -> -76.867 | AA42: -22.1 | AB42: -20.9 | AC42: -19.3 | AD42: =-81.643-SUM(AA42:AC42) -> -19.343 | AE42: =SUM(AA42:AD42) -> -81.643 | AF42: -19 | AG42: -20 | AH42: -18.1 | AI42: -19 | AJ42: =SUM(AF42:AI42) -> -76.1 | AK42: -21 | AL42: -21 | AM42: -21 | AN42: =-81-SUM(AK42:AM42) -> -18 | AO42: =SUM(AK42:AN42) -> -81 | AP42: -15 | AQ42: -16 | AR42: -14 | AS42: =-59-SUM(AP42:AR42) -> -14 | AT42: =SUM(AP42:AS42) -> -59 | AU42: -14 | AV42: -14 | AW42: -12 | AX42: -19 | AY42: =SUM(AU42:AX42) -> -59 | AZ42: -16 | BA42: -16 | BB42: -30 | BC42: -40 | BD42: =SUM(AZ42:BC42) -> -102 | BE42: -40 | BF42: -42 | BG42: -39 | BH42: =-60+21 -> -39 | BI42: =SUM(BE42:BH42) -> -160 | BJ42: -37 | BK42: -37 | BL42: -37 | BM42: -39 | BN42: =SUM(BJ42:BM42) -> -150 | BO42: -34 | BP42: =-BP293 -> -37.128513 | BQ42: =-BQ293 -> -37.128513 | BR42: =-BR293 -> -37.128513 | BS42: =SUM(BO42:BR42) -> -145.38554 | BT42: =-BT293 -> -37.03875 | BU42: =-BU293 -> -37.03875 | BV42: =-BV293 -> -37.03875 | BW42: =-BW293 -> -37.03875 | BX42: =SUM(BT42:BW42) -> -148.155 | BY42: =-BY293 -> -148.155 | BZ42: =-BZ293 -> -148.155 | CA42: =-CA293 -> -148.155 | CD42: =A42 -> Interest Expense, Net | CE42: =B42 -> -55.07 | CF42: =C42 -> -22.517 | CG42: =D42 -> -7.097 | CH42: =E42 -> -5.785 | CI42: =F42 -> -5.202 | CJ42: =K42 -> -13.631 | CK42: =P42 -> -40.581 | CL42: =U42 -> -75.624 | CM42: =Z42 -> -76.867 | CN42: =AE42 -> -81.643 | CO42: =AJ42 -> -76.1 | CP42: =AO42 -> -81 | CQ42: =AT42 -> -59 | CR42: =AY42 -> -59 | CS42: =BD42 -> -102 | CT42: =BI42 -> -160 | CU42: =BN42 -> -150 | CV42: =BS42 -> -145.38554 | CW42: =BX42 -> -148.155 | CX42: =BY42 -> -148.155 | CY42: =BZ42 -> -148.155 | CZ42: =CA42 -> -148.155 | DB42: =SUM(BO42,BP42,BQ42,BR42) -> -145.38554
A43: Other income/ (expense), net | BO43: =4 -> 4 | BP43: 0 | BQ43: 0 | BR43: 0 | BS43: =SUM(BO43:BR43) -> 4 | BT43: 0 | BU43: 0 | BV43: 0 | BW43: 0 | BX43: =SUM(BT43:BW43) -> 0 | BY43: 0 | BZ43: 0 | CA43: 0 | CD43: =A43 -> Other income/ (expense), net | CO43: =AJ43 -> 0 | CP43: =AO43 -> 0 | CQ43: =AT43 -> 0 | CR43: =AY43 -> 0 | CS43: =BD43 -> 0 | CT43: =BI43 -> 0 | CU43: =BN43 -> 0 | CV43: =BS43 -> 4 | CW43: =BX43 -> 0 | CX43: =BY43 -> 0 | CY43: =BZ43 -> 0 | CZ43: =CA43 -> 0
A45: Pretax Income | B45: =B39+B42 -> 615.058 | C45: =C39+C42 -> 911.895 | D45: =D39+D42 -> 998.977 | E45: =E39+E42 -> 1168.905 | F45: =F39+F42 -> 1381.926 | G45: =G39+G42 -> 141.983 | H45: =H39+H42 -> 351.848 | I45: =I39+I42 -> 624.114 | ... BN45: =BN39+BN42 -> 2609 | BO45: =BO39+BO42+BO43 -> 681 | BP45: =BP39+BP42+BP43 -> 708.52248 | BQ45: =BQ39+BQ42+BQ43 -> 689.23251 | BR45: =BR39+BR42+BR43 -> 719.76193 | BS45: =BS39+BS42+BS43 -> 2798.5169 | BT45: =BT39+BT42+BT43 -> 731.97532 | BU45: =BU39+BU42+BU43 -> 781.34208 | BV45: =BV39+BV42+BV43 -> 762.78103 | ... CA45: =CA39+CA42+CA43 -> 3747.267 | CD45: =A45 -> Pretax Income | CE45: =CE39+CE42 -> 615.058 | CF45: =CF39+CF42 -> 911.895 | CG45: =CG39+CG42 -> 998.977 | CH45: =CH39+CH42 -> 1168.905 | CI45: =CI39+CI42 -> 1381.926 | CJ45: =CJ39+CJ42 -> 1436.323 | CK45: =CK39+CK42 -> 1666.232 | CL45: =CL39+CL42 -> 1372.46 | ... CO45: =CO39+CO42 -> 1862.8 | CP45: =AO45 -> 1304 | CQ45: =AT45 -> 1518 | CR45: =AY45 -> 1756 | CS45: =BD45 -> 1951 | CT45: =BI45 -> 2174 | CU45: =BN45 -> 2609 | CV45: =BS45 -> 2798.5169 | CW45: =BX45 -> 3070.7272 | CX45: =BY45 -> 3286.0348 | CY45: =BZ45 -> 3523.2086 | CZ45: =CA45 -> 3747.267 | DB45: =SUM(BO45,BP45,BQ45,BR45) -> 2798.5169
A46: Income Tax Benefit (Expense)- Reported | B46: -238.027 | C46: -325.429 | D46: -442.466 | E46: -412.495 | F46: -515.656 | G46: -43.963 | H46: -130.887 | I46: -226.441 | J46: =-522.592-SUM(G46:I46) -> -121.301 | K46: =SUM(G46:J46) -> -522.592 | L46: -87.139 | M46: -166.248 | N46: -271.211 | O46: =-608.973-SUM(L46:N46) -> -84.375 | P46: =SUM(L46:O46) -> -608.973 | Q46: -48.667 | R46: -127.377 | S46: -234.099 | T46: =-479.695-SUM(Q46:S46) -> -69.552 | U46: =SUM(Q46:T46) -> -479.695 | V46: -37.765 | W46: -96.088 | X46: -195.882 | Y46: =-429.108-SUM(V46:X46) -> -99.373 | Z46: =SUM(V46:Y46) -> -429.108 | AA46: -61.2 | AB46: -111.2 | AC46: -221.7 | AD46: =-487.547-SUM(AA46:AC46) -> -93.447 | AE46: =SUM(AA46:AD46) -> -487.547 | AF46: -72 | AG46: -122 | AH46: -213.7 | AI46: -68 | AJ46: =SUM(AF46:AI46) -> -475.7 | AK46: -98 | AL46: -107 | AM46: -82 | AN46: -117 | AO46: =SUM(AK46:AN46) -> -404 | AP46: -89 | AQ46: -147 | AR46: -123 | AS46: -75 | AT46: =SUM(AP46:AS46) -> -434 | AU46: =-141+(253-245)/2-1 -> -138 | AV46: =-156+(253-245)/2+1 -> -151 | AW46: -139 | AX46: 183 | AY46: =SUM(AU46:AX46) -> -245 | AZ46: -156 | BA46: -185 | BB46: -99 | BC46: -108 | BD46: =SUM(AZ46:BC46) -> -548 | BE46: -149 | BF46: -197 | BG46: -386 | BH46: -228 | BI46: =SUM(BE46:BH46) -> -960 | BJ46: -181 | BK46: -183 | BL46: -169 | BM46: -290 | BN46: =SUM(BJ46:BM46) -> -823 | BO46: -147 | BP46: =-BP45*BP249 -> -152.33233 | BQ46: =-BQ45*BQ249 -> -148.18499 | BR46: =-BR45*BR249 -> -154.74882 | BS46: =SUM(BO46:BR46) -> -602.26614 | BT46: =-BT45*BT249 -> -157.37469 | BU46: =-BU45*BU249 -> -167.98855 | BV46: =-BV45*BV249 -> -163.99792 | BW46: =-BW45*BW249 -> -170.84518 | BX46: =SUM(BT46:BW46) -> -660.20634 | BY46: =-BY45*BY249 -> -706.49749 | BZ46: =-BZ45*BZ249 -> -757.48985 | CA46: =-CA45*CA249 -> -805.66241 | CD46: =A46 -> Income Tax Benefit (Expense)- Reported | CE46: =B46 -> -238.027 | CF46: =C46 -> -325.429 | CG46: =D46 -> -442.466 | CH46: =E46 -> -412.495 | CI46: =F46 -> -515.656 | CJ46: =K46 -> -522.592 | CK46: =P46 -> -608.973 | CL46: =U46 -> -479.695 | CM46: =Z46 -> -429.108 | CN46: =AE46 -> -487.547 | CO46: =AJ46 -> -475.7 | CP46: =AO46 -> -404 | CQ46: =AT46 -> -434 | CR46: =AY46 -> -245 | CS46: =BD46 -> -548 | CT46: =BI46 -> -960 | CU46: =BN46 -> -823 | CV46: =BS46 -> -602.26614 | CW46: =BX46 -> -660.20634 | CX46: =BY46 -> -706.49749 | CY46: =BZ46 -> -757.48985 | CZ46: =CA46 -> -805.66241 | DB46: =SUM(BO46,BP46,BQ46,BR46) -> -602.26614
A47: Income Tax Benefit (Expense)- Extraordinary income (expenses) | B47: 0 | C47: =-14.5*C245 -> -5.6405 | D47: =131.3*D245 -> 51.0757 | E47: 0 | F47: =(-23.2+1.236)*F245 -> -7.841148 | G47: =-23.8*G245 -> -9.3296 | H47: 0 | I47: =-15.4*I245 -> -6.0368 | J47: =-31.5*J242-SUM(G47:I47) -> 14.983785 | K47: =SUM(G47:J47) -> -0.38261527 | L47: =17.305*L245 -> 6.835475 | M47: 0 | N47: 0 | O47: =-43.7*O245-SUM(L47:N47) -> -24.096975 | P47: =SUM(L47:O47) -> -17.2615 | Q47: 0 | R47: =-23.7*R245 -> -9.2904 | S47: =-23.4*(S245) -> -9.1728 | T47: =(-73.4*(T245))-SUM(Q47:S47) -> -10.3096 | U47: =SUM(Q47:T47) -> -28.7728 | V47: 0 | W47: =(-15.2-13.849)*(W245) -> -11.300061 | X47: 0 | Y47: =-6.7-SUM(V47:X47) -> 4.600061 | Z47: =SUM(V47:Y47) -> -6.7 | AA47: 0 | AB47: 0 | AC47: 4 | AD47: =-5.5-SUM(AA47:AC47) -> -9.5 | AE47: =SUM(AA47:AD47) -> -5.5 | AF47: 0 | AG47: 0 | AH47: 0 | AI47: -15 | AJ47: =SUM(AF47:AI47) -> -15 | AK47: -11 | AL47: -15 | AM47: -30 | AN47: -9 | AO47: =SUM(AK47:AN47) -> -65 | AP47: -46 | AQ47: -3 | AR47: -6 | AS47: -26 | AT47: =SUM(AP47:AS47) -> -81 | AU47: 0 | AV47: 0 | AW47: -17 | AX47: -319 | AY47: =SUM(AU47:AX47) -> -336 | AZ47: 2 | BA47: 12 | BB47: -45 | BC47: -18 | BD47: =SUM(AZ47:BC47) -> -49 | BE47: -5 | BF47: 9 | BG47: =206 -> 206 | BH47: 53 | BI47: =SUM(BE47:BH47) -> 263 | BJ47: -9 | BK47: -5 | BL47: -7 | BM47: 96 | BN47: =SUM(BJ47:BM47) -> 75 | BO47: 0 | BP47: 0 | BQ47: 0 | BR47: 0 | BS47: =SUM(BO47:BR47) -> 0 | BT47: 0 | BU47: 0 | BV47: 0 | BW47: 0 | BX47: =SUM(BT47:BW47) -> 0 | BY47: 0 | BZ47: 0 | CA47: 0 | CD47: =A47 -> Income Tax Benefit (Expense)- Extraordinary income (expenses) | CE47: =B47 -> 0 | CF47: =C47 -> -5.6405 | CG47: =D47 -> 51.0757 | CH47: =E47 -> 0 | CI47: =F47 -> -7.841148 | CJ47: =K47 -> -0.38261527 | CK47: =P47 -> -17.2615 | CL47: =U47 -> -28.7728 | CM47: =Z47 -> -6.7 | CN47: =AE47 -> -5.5 | CO47: =AJ47 -> -15 | CP47: =AO47 -> -65 | CQ47: =AT47 -> -81 | CR47: =AY47 -> -336 | CS47: =BD47 -> -49 | CT47: =BI47 -> 263 | CU47: =BN47 -> 75 | CV47: =BS47 -> 0 | CW47: =BX47 -> 0 | CX47: =BY47 -> 0 | CY47: =BZ47 -> 0 | CZ47: =CA47 -> 0 | DB47: =SUM(BO47,BP47,BQ47,BR47) -> 0
A48: Income Tax Benefit (Expense) | B48: =B46+B47 -> -238.027 | C48: =C46+C47 -> -331.0695 | D48: =D46+D47 -> -391.3903 | E48: =E46+E47 -> -412.495 | F48: =F46+F47 -> -523.49715 | G48: =G46+G47 -> -53.2926 | H48: =H46+H47 -> -130.887 | I48: =I46+I47 -> -232.4778 | ... CA48: =CA46+CA47 -> -805.66241 | CD48: =A48 -> Income Tax Benefit (Expense) | CE48: =B48 -> -238.027 | CF48: =C48 -> -331.0695 | CG48: =D48 -> -391.3903 | CH48: =E48 -> -412.495 | CI48: =F48 -> -523.49715 | CJ48: =K48 -> -522.97462 | CK48: =P48 -> -626.2345 | CL48: =U48 -> -508.4678 | CM48: =Z48 -> -435.808 | CN48: =AE48 -> -493.047 | CO48: =AJ48 -> -490.7 | CP48: =AO48 -> -469 | CQ48: =AT48 -> -515 | CR48: =AY48 -> -581 | CS48: =BD48 -> -597 | CT48: =BI48 -> -697 | CU48: =BN48 -> -748 | CV48: =BS48 -> -602.26614 | CW48: =BX48 -> -660.20634 | CX48: =BY48 -> -706.49749 | CY48: =BZ48 -> -757.48985 | CZ48: =CA48 -> -805.66241 | DB48: =SUM(BO48,BP48,BQ48,BR48) -> -602.26614
A49: Tax rate | K49: =-K48/K45 -> 0.36410655 | L49: =-L48/L45 -> 0.37582615 | M49: =-M48/M45 -> 0.37500169 | N49: =-N48/N45 -> 0.37500017 | O49: =-O48/O45 -> 0.37926601 | P49: =-P48/P45 -> 0.37583872 | Q49: =-Q48/Q45 -> 0.3652856 | R49: =-R48/R45 -> 0.37135156 | ... CA49: =-CA48/CA45 -> 0.215 | CD49: =A49 -> Tax rate | CG49: =-CG48/CG45 -> 0.3917911 | CH49: =-CH48/CH45 -> 0.3528901 | CI49: =-CI48/CI45 -> 0.37881706 | CJ49: =-CJ48/CJ45 -> 0.36410655 | CK49: =-CK48/CK45 -> 0.37583872 | CL49: =-CL48/CL45 -> 0.37047914 | CM49: =-CM48/CM45 -> 0.36398684 | CN49: =-CN48/CN45 -> 0.36399106 | ... CZ49: =-CZ48/CZ45 -> 0.215
...

Sheet Op Metrics
A6: S&P Global, Inc.
A7: Operating Metrics ($M)
CB8: 17-22E
A9: Fiscal Year Ending December 31 | B9: =MHFI!B9 -> 2001 | C9: =MHFI!C9 -> 2002 | D9: =MHFI!D9 -> 2003 | E9: =MHFI!E9 -> 2004 | F9: =MHFI!F9 -> 2005 | G9: =MHFI!G9 -> 1Q06 | H9: =MHFI!H9 -> 2Q06 | I9: =MHFI!I9 -> 3Q06 | ... CA9: =MHFI!CA9 -> 2022E | CB9: CAGR | CF9: =+A9 -> Fiscal Year Ending December 31 | CG9: =+B9 -> 2001 | CH9: =+C9 -> 2002 | CI9: =+D9 -> 2003 | CJ9: =+E9 -> 2004 | CK9: =+F9 -> 2005 | CL9: =+K9 -> 2006 | CM9: =+P9 -> 2007 | CN9: =+U9 -> 2008 | CO9: =+Z9 -> 2009 | CP9: =+AE9 -> 2010 | CQ9: =+AJ9 -> 2011 | CR9: =+AO9 -> 2012 | CS9: =+AT9 -> 2013 | CT9: =+AY9 -> 2014 | CU9: =+BD9 -> 2015 | CV9: =+BI9 -> 2016 | CW9: =+BN9 -> 2017 | CX9: =+BS9 -> 2018E | CY9: =+BX9 -> 2019E | CZ9: =+BY9 -> 2020E | DA9: =+BZ9 -> 2021E | DB9: =+CA9 -> 2022E
A10: Revenue | CF10: =A10 -> Revenue
