Workbook
Name _1._Discounted_Cash_Flow_Valuation: "1. Discounted Cash Flow Valuation"
Name _2._Sum_of_the_Parts: "Sum of the Parts"
Name _3._Relative_Valuation: "Multiple Valuation"
Name AdditionalInstructions: IndexInformation!$B$42
Name Address: ImportantDisclosures!$A$2:$A$2
Name ANA: ModPubIndex!$A$7
Name Authors: ImportantDisclosures!$A$7
Name Authors: IndexInformation!$B$18
Name BRO: ModPubIndex!$A$1
Name CashFlowCapitalExpenditureCellular: 0
Name CashFlowCapitalExpenditureOther: 0
Name CashFlowCapitalExpenditurePaging: 0
Name CashFlowCapitalExpenditureTelephone: 0
Name CashFlowCapitalExpenditureWireless: 0
Name CashFlowDividendPaidPreferredStock: 0
Name CopyrightStamp: ImportantDisclosures!$A$27
Name Corinthian_Colleges: '[2]Print '!$B$2:$M$71
Name COU: ModPubIndex!$A$5
Name CQEnd: IndexInformation!$B$31
Name Currency: IndexInformation!$B$24
Name CurrentStockPrice: IndexInformation!$B$23
Name CurrQtrEPS: IndexInformation!$B$29
Name CurrYearEPS: IndexInformation!$B$11
Name CurrYearTotalRevenue: IndexInformation!$B$10
Name CurrYearTotalRevenueActual: IndexInformation!$B$32
Name CUSIP: IndexInformation!$B$20
Name CYEnd: IndexInformation!$B$30
Name Date: ImportantDisclosures!$A$8
Name Deleted: IndexInformation!$B$27
Name Description: IndexInformation!$B$7
Name Discipline: IndexInformation!$B$3
Name DISCIPLINE: ModPubIndex!$A$12
Name DisclosuresText: ImportantDisclosures!$A$22
Name Distribution: IndexInformation!$B$26
Name DistTable: ImportantDisclosures!#REF!
Name DistTablePreamble: ImportantDisclosures!#REF!
Name DOCDAT: ModPubIndex!$A$2
Name DOCTIME: ModPubIndex!$A$3
Name DocType: IndexInformation!$B$5
Name EMAIL_ALERT: ModPubIndex!$A$10
Name EmailAlert: IndexInformation!$B$28
Name EquityAdjustments: 0
Name EquityEmployeeStockOwnershipPlan: 0
Name EquityPaidInCapital: 0
Name EquityTreasuryStock: 0
Name FiveYearGrowthRate: IndexInformation!$B$16
Name FollowingYearEPS: IndexInformation!$B$15
Name FollowingYearTotalRevenue: IndexInformation!$B$14
Name FollowingYearTotalRevenueActual: IndexInformation!$B$34
Name HL: ModPubIndex!$A$8
Name IncomeEPSFullyDiluted: 0
Name IncomeEPSPrimary: 0
Name IncomeEPSRegular: 0
Name IND: ModPubIndex!$A$9
Name Industry: ImportantDisclosures!$A$12
Name IndustryId: IndexInformation!$B$40
Name IndustryRating: ImportantDisclosures!$A$13
Name KeepVersions: IndexInformation!$B$8
Name LanguageCode: IndexInformation!$B$38
Name LastCell: ImportantDisclosures!$A$22

Sheet ImportantDisclosures
A2: 1585 Broadway
A3: New York, NY 10036-8293
A4: United States
A5: Tel: +1 (1)212 761 4000
A7: Authors: Toni Kaplan, Priscilla Russo
A8: Date: 21 Feb 2018
A10: Ticker: VRSK.O
A11: Stock Rating: Equal-Weight
A12: Industry: Business & Education Services
A13: Industry View: In-Line
A14: Price as of 21 Feb 2018: 99.23
A15: Target Price: 107
... A120: Equal-weight and Not-Rated to hold and Underweight to sell recommendations, respectively.
B122: Coverage Universe | D122: Investment Banking Clients (IBC) | G122: Other Material Investment Services Clients (MISC)
A123: Stock Rating Category | B123: Count | C123: % of Total | D123: Count | E123: % of Total IBC | F123: % of Rating Category | G123: Count | H123: % of Total Other MISC
A124: Overweight/Buy | B124: 1173 | C124: 0.37 | D124: 318 | E124: 0.41 | F124: 0.27 | G124: 571 | H124: 0.39
A125: Equal-weight/Hold | B125: 1390 | C125: 0.44 | D125: 359 | E125: 0.47 | F125: 0.26 | G125: 653 | H125: 0.45
A126: Not-Rated/Hold | B126: 53 | C126: 0.02 | D126: 5 | E126: 0.01 | F126: 0.09 | G126: 8 | H126: 0.01
A127: Underweight/Sell | B127: 564 | C127: 0.18 | D127: 90 | E127: 0.12 | F127: 0.16 | G127: 219 | H127: 0.15
A128: Total | B128: 3180 | D128: 772 | G128: 1451
A130: Data include common stock and ADRs currently assigned ratings. Investment Banking Clients are companies
A131: from whom Morgan Stanley received investment banking compensation in the last 12 months. Due to rounding
A132: off of decimals, the percentages provided in the "% of total" column may not add up to exactly 100
A133: percent.
A135: Analyst Stock Ratings
A137: Overweight (O). The stock's total return is expected to exceed the average total return of the analyst's
A138: industry (or industry team's) coverage universe, on a risk-adjusted basis, over the next 12-18 months.
A140: Equal-weight (E). The stock's total return is expected to be in line with the average total return of
A141: the analyst's industry (or industry team's) coverage universe, on a risk-adjusted basis, over the next
A142: 12-18 months.
A144: Not-Rated (NR). Currently the analyst does not have adequate conviction about the stock's total return
A145: relative to the average total return of the analyst's industry (or industry team's) coverage universe,
... A391: © Copyright 2018 Morgan Stanley

Sheet VA
C1: 2005 | D1: 2006 | E1: 1Q07 | F1: 2Q07 | G1: 3Q07 | H1: 4Q07 | I1: 2007 | J1: 1Q08 | K1: 2Q08 | L1: 3Q08 | M1: 4Q08 | N1: 2008 | O1: 1Q09 | P1: 2Q09 | Q1: 3Q09 | R1: 4Q09 | S1: 2009 | T1: 1Q10 | U1: 2Q10 | V1: 3Q10 | W1: 4Q10 | X1: 2010 | Y1: 1Q11 | Z1: 2Q11 | AA1: 3Q11 | AB1: 4Q11 | AC1: 2011 | AD1: 1Q12 | AE1: 2Q12 | AF1: 3Q12 | AG1: 4Q12 | AH1: 2012 | AI1: 1Q13 | AJ1: 2Q13 | AK1: 3Q13 | AL1: 4Q13 | AM1: 2013 | AN1: 1Q14 | AO1: 2Q14 | AP1: 3Q14 | AQ1: 4Q14 | AR1: 2014 | AS1: 1Q15 | AT1: 2Q15 | AU1: 3Q15 | AV1: 4Q15 | AW1: 2015 | AX1: 1Q16 | AY1: 2Q16 | AZ1: 3Q16 | BA1: 4Q16 | BB1: 2016 | BC1: 1Q17 | BD1: 2Q17 | BE1: 3Q17 | BF1: 4Q17 | BG1: 2017 | BH1: 1Q18E | BI1: 2Q18E | BJ1: 3Q18E | BK1: 4Q18E | BL1: 2018E | BM1: 1Q19E | BN1: 2Q19E | BO1: 3Q19E | BP1: 4Q19E | BQ1: 2019E | BR1: 1Q20E | BS1: 2Q20E | BT1: 3Q20E | BU1: 4Q20E | BV1: 2020E | BW1: 1Q21E | BX1: 2Q21E | BY1: 3Q21E | BZ1: 4Q21E | CA1: 2021E | CJ1: =AC1 -> 2011 | CK1: =AH1 -> 2012 | CL1: =AM1 -> 2013 | CM1: =AR1 -> 2014 | CN1: =AW1 -> 2015 | CO1: =BB1 -> 2016 | CP1: =BG1 -> 2017 | CQ1: =BL1 -> 2018E | CR1: =BQ1 -> 2019E | CS1: =BV1 -> 2020E | CT1: =CA1 -> 2021E
A3: 2
A8: Verisk Analytics | CD8: Verisk Analytics
A9: Quarterly Income Statement | CD9: Annual Income Statement
A10: (Values in millions, except per-share amounts) | CB10: 4 YR CAGR | CD10: (Values in millions, except per-share amounts)
A11: Fiscal Year Ending Dec. 31 | C11: =C1 -> 2005 | D11: =D1 -> 2006 | E11: =E1 -> 1Q07 | F11: =F1 -> 2Q07 | G11: =G1 -> 3Q07 | H11: =H1 -> 4Q07 | I11: =I1 -> 2007 | J11: =J1 -> 1Q08 | ... AH11: =AH1 -> 2012 | AI11: =AI1&"R" -> 1Q13R | AJ11: =AJ1&"R" -> 2Q13R | AK11: =AK1&"R" -> 3Q13R | AL11: =AL1 -> 4Q13 | AM11: =AM1 -> 2013 | AN11: =AN1 -> 1Q14 | AO11: =AO1 -> 2Q14 | AP11: =AP1 -> 3Q14 | AQ11: =AQ1 -> 4Q14 | AR11: =AR1 -> 2014 | AS11: =AS1 -> 1Q15 | ... AW11: =AW1 -> 2015 | AX11: =AX$1 -> 1Q16 | AY11: =AY$1 -> 2Q16 | AZ11: =AZ$1 -> 3Q16 | BA11: =BA$1 -> 4Q16 | BB11: =BB$1 -> 2016 | BC11: =BC$1 -> 1Q17 | BD11: =BD$1 -> 2Q17 | BE11: =BE$1 -> 3Q17 | ... CA11: =CA$1 -> 2021E | CB11: '17 - '21 | CD11: =A11 -> Fiscal Year Ending Dec. 31 | CE11: =D11 -> 2006 | CF11: =I11 -> 2007 | CG11: =N11 -> 2008 | CH11: =S11 -> 2009 | CI11: =X11 -> 2010 | CJ11: =AC11 -> 2011 | CK11: =AH11 -> 2012 | CL11: =AM11 -> 2013 | CM11: =AR11 -> 2014 | CN11: =AW11 -> 2015 | CO11: =BB11 -> 2016 | CP11: =BG11 -> 2017 | CQ11: =BL11 -> 2018E | CR11: =BQ11 -> 2019E | CS11: =BV11 -> 2020E | CT11: =CA11 -> 2021E
A12: Total Revenue | B12: 12 | C12: =C245+C313 -> 645.66 | D12: =D245+D313 -> 730.133 | E12: =E245+E313 -> 198.834 | F12: =F245+F313 -> 201.154 | G12: =G245+G313 -> 199.723 | H12: =H245+H313 -> 202.484 | I12: =SUM(E12:H12) -> 802.195 | J12: =J245+J313 -> 215.618 | K12: =K245+K313 -> 222.072 | L12: =L245+L313 -> 224.391 | M12: =M245+M313 -> 231.469 | N12: =SUM(J12:M12) -> 893.55 | O12: =O245+O313 -> 245.751 | P12: =P245+P313 -> 257.916 | Q12: =Q245+Q313 -> 258.311 | R12: =R245+R313 -> 265.126 | S12: =SUM(O12:R12) -> 1027.104 | T12: =T245+T313 -> 276.154 | U12: =U245+U313 -> 281.677 | V12: =V245+V313 -> 287.354 | W12: =W245+W313 -> 293.158 | X12: =SUM(T12:W12) -> 1138.343 | Y12: =Y245+Y313 -> 312.869 | Z12: =Z245+Z313 -> 327.28 | AA12: =AA245+AA313 -> 340.098 | AB12: =AB245+AB313 -> 351.593 | AC12: =SUM(Y12:AB12) -> 1331.84 | AD12: =AD245+AD313 -> 346.501 | AE12: =AE245+AE313 -> 373.226 | AF12: =AF245+AF313 -> 398.863 | AG12: =AG245+AG313 -> 415.73 | AH12: =SUM(AD12:AG12) -> 1534.32 | AI12: =AI245+AI313 -> 376.697 | AJ12: =AJ245+AJ313 -> 390.366 | AK12: =AK245+AK313 -> 411.927 | AL12: =AL245+AL313 -> 416.723 | AM12: =SUM(AI12:AL12) -> 1595.713 | AN12: =AN245+AN313 -> 409.643 | AO12: =AO245+AO313 -> 423.554 | AP12: =AP245+AP313 -> 448.665 | AQ12: =AQ245+AQ313 -> 464.864 | AR12: =SUM(AN12:AQ12) -> 1746.726 | AS12: =AS245+AS313 -> 459.397 | AT12: =AT245+AT313 -> 497.65 | AU12: =AU245+AU313 -> 550.401 | AV12: =AV245+AV313 -> 560.6 | AW12: =SUM(AS12:AV12) -> 2068.048 | AX12: =AX245+AX313 -> 492.701 | AY12: =AY245+AY313 -> 498.296 | AZ12: =AZ245+AZ313 -> 498.081 | BA12: =BA245+BA313 -> 506.1 | BB12: =BB245+BB313 -> 1995.178 | BC12: =BC245+BC313 -> 502.6 | BD12: =BD245+BD313 -> 523.2 | BE12: =BE245+BE313 -> 549.1 | ... CA12: =CA245+CA313 -> 2784.2835 | CB12: =(CA12/BG12)^(1/4)-1 -> 0.067361217 | CD12: =A12 -> Total Revenue | CE12: =D12 -> 730.133 | CF12: =I12 -> 802.195 | CG12: =N12 -> 893.55 | CH12: =S12 -> 1027.104 | CI12: =X12 -> 1138.343 | CJ12: =AC12 -> 1331.84 | CK12: =AH12 -> 1534.32 | CL12: =AM12 -> 1595.713 | CM12: =AR12 -> 1746.726 | CN12: =AW12 -> 2068.048 | CO12: =BB12 -> 1995.178 | CP12: =BG12 -> 2145.2 | CQ12: =BL12 -> 2359.4133 | CR12: =BQ12 -> 2495.6575 | CS12: =BV12 -> 2635.8576 | CT12: =CA12 -> 2784.2835
A13: Annual Growth (2016 from continuing operations) | I13: =I12/D12-1 -> 0.098697087 | J13: =J12/E12-1 -> 0.084412123 | K13: =K12/F12-1 -> 0.10398998 | L13: =L12/G12-1 -> 0.12351106 | M13: =M12/H12-1 -> 0.14314711 | N13: =N12/I12-1 -> 0.11388129 | O13: =O12/J12-1 -> 0.13975178 | P13: =P12/K12-1 -> 0.16140711 | ... AW13: =AW12/AR12-1 -> 0.18395673 | AX13: 0.2820739 | AY13: 0.16261316 | AZ13: 0.058845663 | BA13: 0.060117302 | BB13: 0.13317317 | BC13: =BC12/AX12-1 -> 0.020091293 | BD13: =BD12/AY12-1 -> 0.049978326 | BE13: =BE12/AZ12-1 -> 0.10243113 | BF13: =BF12/BA12-1 -> 0.1268524 | BG13: =BG12/BB12-1 -> 0.075192289 | BH13: =BH12/BC12-1 -> 0.13042977 | BI13: =BI12/BD12-1 -> 0.11368884 | BJ13: =BJ12/BE12-1 -> 0.089470649 | ... CA13: =CA12/BV12-1 -> 0.056310316 | CD13: =A13 -> Annual Growth (2016 from continuing operations) | CF13: =I13 -> 0.098697087 | CG13: =N13 -> 0.11388129 | CH13: =S13 -> 0.1494645 | CI13: =X13 -> 0.10830354 | CJ13: =AC13 -> 0.16998128 | CK13: =AH13 -> 0.15203027 | CL13: =AM13 -> 0.040013165 | CM13: =AR13 -> 0.094636692 | CN13: =AW13 -> 0.18395673 | CO13: =BB13 -> 0.13317317 | CP13: =BG13 -> 0.075192289 | CQ13: =BL13 -> 0.099857045 | CR13: =BQ13 -> 0.057744931 | CS13: =BV13 -> 0.056177614 | CT13: =CA13 -> 0.056310316
A14: Total Revenue (pro forma for Mortgage) | X14: =+Revenue_end_mkt!H85 -> 1000.978 | Y14: =+Revenue_end_mkt!I85 -> 281.416 | Z14: =+Revenue_end_mkt!J85 -> 292.799 | AA14: =+Revenue_end_mkt!K85 -> 306.89251 | AB14: =+Revenue_end_mkt!L85 -> 321.35349 | AC14: =+Revenue_end_mkt!M85 -> 1202.461 | AD14: =+Revenue_end_mkt!N85 -> 313.469 | AE14: =+Revenue_end_mkt!O85 -> 339.089 | ... AM14: =+Revenue_end_mkt!W85 -> 1595.713 | CB14: =((1+BG14)*(1+#REF!)*(1+#REF!)*(1+BV14))^0.25-1 -> #REF! | CD14: =A14 -> Total Revenue (pro forma for Mortgage) | CF14: =I14 -> 0 | CG14: =N14 -> 0 | CH14: =S14 -> 0 | CI14: =X14 -> 1000.978 | CJ14: =AC14 -> 1202.461 | CK14: =AH14 -> 1407.806 | CL14: =AM14 -> 1595.713 | CM14: =AR14 -> 0 | CN14: =AW14 -> 0 | CO14: =BB14 -> 0 | CP14: =BG14 -> 0 | CQ14: =BL14 -> 0 | CR14: =BQ14 -> 0 | CS14: =BV14 -> 0 | CT14: =CA14 -> 0
A15: Revenue Growth (pro forma for mortgage, hc chg) | AC15: =+AC14/X14-1 -> 0.20128614 | AD15: =+AD14/Y14-1 -> 0.113899 | AE15: =+AE14/Z14-1 -> 0.1580948 | AF15: =+AF14/AA14-1 -> 0.19509924 | AG15: =+AG14/AB14-1 -> 0.20888992 | AH15: =+AH14/AC14-1 -> 0.17077061 | AI15: =+AI14/AD14-1 -> 0.20170416 | AJ15: =+AJ14/AE14-1 -> 0.15121989 | ... AM15: =+AM14/AH14-1 -> 0.13347507 | AN15: =+AN12/AI14-1 -> 0.087460213 | AO15: =+AO12/AJ14-1 -> 0.08501765 | AP15: =+AP12/AK14-1 -> 0.089185705 | AQ15: =+AQ12/AL14-1 -> 0.11552278 | AR15: =+AR12/AM14-1 -> 0.094636692 | AS15: =+AS12/AN12-1 -> 0.12145698 | AT15: =+AT12/AO12-1 -> 0.17493873 | AU15: =+AU12/AP12-1 -> 0.2267527 | AV15: =+AV12/AQ12-1 -> 0.2059441 | AW15: =AW12/(AR12+Revenue_end_mkt!AB53-Revenue_end_mkt!AB46)-1 -> 0.20896201 | AX15: =+AX12/AS12-1 -> 0.072495032 | AY15: =+AY12/AT12-1 -> 0.0012981011 | AZ15: =+AZ12/AU12-1 -> -0.095057967 | BA15: =+BA12/AV12-1 -> -0.097217267 | BB15: =BB12/(AW12+Revenue_end_mkt!AG53-Revenue_end_mkt!AG46)-1 -> -0.035236126 | BC15: =+BC12/AX12-1 -> 0.020091293 | BD15: =+BD12/AY12-1 -> 0.049978326 | BE15: =+BE12/AZ12-1 -> 0.10243113 | BF15: =+BF12/BA12-1 -> 0.1268524 | BG15: =BG12/(BB12+Revenue_end_mkt!AL53-Revenue_end_mkt!AL46)-1 -> 0.075192289 | BH15: =+BH12/BC12-1 -> 0.13042977 | BI15: =+BI12/BD12-1 -> 0.11368884 | BJ15: =+BJ12/BE12-1 -> 0.089470649 | BK15: =+BK12/BF12-1 -> 0.070224443 | BL15: =BL12/(BG12+Revenue_end_mkt!AQ53-Revenue_end_mkt!AQ46)-1 -> 0.099857045 | BM15: =+BM12/BH12-1 -> 0.056675382 | BN15: =+BN12/BI12-1 -> 0.057604603 | BO15: =+BO12/BJ12-1 -> 0.057874675 | BP15: =+BP12/BK12-1 -> 0.05874734 | BQ15: =BQ12/(BL12+Revenue_end_mkt!AV53-Revenue_end_mkt!AV46)-1 -> 0.057744931 | BR15: =+BR12/BM12-1 -> 0.056048728 | BS15: =+BS12/BN12-1 -> 0.056129551 | BT15: =+BT12/BO12-1 -> 0.056290787 | BU15: =+BU12/BP12-1 -> 0.056232353 | BV15: =BV12/(BQ12+Revenue_end_mkt!BA53-Revenue_end_mkt!BA46)-1 -> 0.056177614 | BW15: =+BW12/BR12-1 -> 0.056180432 | BX15: =+BX12/BS12-1 -> 0.056262956 | BY15: =+BY12/BT12-1 -> 0.056423292 | BZ15: =+BZ12/BU12-1 -> 0.056365477 | CA15: =CA12/(BV12+Revenue_end_mkt!BF53-Revenue_end_mkt!BF46)-1 -> 0.056310316 | CB15: =((1+BG15)*(1+#REF!)*(1+#REF!)*(1+BV15))^0.25-1 -> #REF! | CD15: =A15 -> Revenue Growth (pro forma for mortgage, hc chg) | CF15: =I15 -> 0 | CG15: =N15 -> 0 | CH15: =S15 -> 0 | CI15: =X15 -> 0 | CJ15: =AC15 -> 0.20128614 | CK15: =AH15 -> 0.17077061 | CL15: =AM15 -> 0.13347507 | CM15: =AR15 -> 0.094636692 | CN15: =AW15 -> 0.20896201 | CO15: =BB15 -> -0.035236126 | CP15: =BG15 -> 0.075192289 | CQ15: =BL15 -> 0.099857045 | CR15: =BQ15 -> 0.057744931 | CS15: =BV15 -> 0.056177614 | CT15: =CA15 -> 0.056310316
A16: Organic C/C Growth | AI16: =Revenue_end_mkt!S88 -> 0.068 | AJ16: =Revenue_end_mkt!T88 -> 0.078 | AK16: =Revenue_end_mkt!U88 -> 0.061 | AL16: =Revenue_end_mkt!V88 -> 0.073 | AM16: =Revenue_end_mkt!W88 -> 0.085 | AN16: =Revenue_end_mkt!X88 -> 0.087460213 | AO16: =Revenue_end_mkt!Y88 -> 0.08501765 | AP16: =Revenue_end_mkt!Z88 -> 0.089185705 | ... AW16: =Revenue_end_mkt!AG88 -> 0.074 | AX16: =Revenue_end_mkt!AH92 -> 0.05636045 | AY16: =Revenue_end_mkt!AI92 -> 0.061691434 | AZ16: =Revenue_end_mkt!AJ92 -> 0.062 | BA16: =Revenue_end_mkt!AK92 -> 0.062 | BB16: =Revenue_end_mkt!AL92 -> 0.058 | BC16: =Revenue_end_mkt!AM92 -> 0.025 | BD16: =Revenue_end_mkt!AN92 -> 0.041 | BE16: =Revenue_end_mkt!AO92 -> 0.07 | ... CA16: =Revenue_end_mkt!BK92 -> 0.056310316 | CD16: =A16 -> Organic C/C Growth | CF16: =I16 -> 0 | CG16: =N16 -> 0 | CH16: =S16 -> 0 | CI16: =X16 -> 0 | CJ16: =AC16 -> 0 | CK16: =AH16 -> 0 | CL16: =AM16 -> 0.085 | CM16: =AR16 -> 0.094 | CN16: =AW16 -> 0.074 | CO16: =BB16 -> 0.058 | CP16: =BG16 -> 0.052502882 | CQ16: =BL16 -> 0.058586612 | CR16: =BQ16 -> 0.057744931 | CS16: =BV16 -> 0.056177614 | CT16: =CA16 -> 0.056310316
A17: Cost Of Revenues | B17: 15 | C17: =C251+C317 -> 295.111 | D17: =D251+D317 -> 331.804 | E17: =E251+E317 -> 86.987 | F17: =F251+F317 -> 89.515 | G17: =G251+G317 -> 85.343 | H17: =H251+H317 -> 95.346 | I17: =SUM(E17:H17) -> 357.191 | J17: =J251+J317 -> 93.31 | K17: =K251+K317 -> 97.368 | L17: =L251+L317 -> 98.307 | M17: =M251+M317 -> 97.912 | N17: =SUM(J17:M17) -> 386.897 | O17: =O251+O317 -> 107.523 | P17: =P251+P317 -> 112.978 | Q17: 117.383 | R17: =R251+R317 -> 153.41 | S17: =SUM(O17:R17) -> 491.294 | T17: =T251+T317 -> 114.993 | U17: =U251+U317 -> 115 | V17: =V251+V317 -> 117.005 | W17: =W251+W317 -> 116.475 | X17: =SUM(T17:W17) -> 463.473 | Y17: =Y251+Y317 -> 124.556 | Z17: =Z251+Z317 -> 131.185 | AA17: =AA251+AA317 -> 137.619 | AB17: =AB251+AB317 -> 140.375 | AC17: =SUM(Y17:AB17) -> 533.735 | AD17: =AD251+AD317 -> 133.33 | AE17: =AE251+AE317 -> 147.074 | AF17: =AF251+AF317 -> 156.749 | AG17: =AG251+AG317 -> 170.021 | AH17: =SUM(AD17:AG17) -> 607.174 | AI17: =AI251+AI317 -> 143.632 | AJ17: =AJ251+AJ317 -> 152.428 | AK17: =AK251+AK317 -> 156.306 | AL17: =AL251+AL317 -> 170.156 | AM17: =SUM(AI17:AL17) -> 622.522 | AN17: =AN251+AN317 -> 169.673 | AO17: =AO251+AO317 -> 172.47 | AP17: =AP251+AP317 -> 180.873 | AQ17: =AQ251+AQ317 -> 193.582 | AR17: =SUM(AN17:AQ17) -> 716.598 | AS17: =AS251+AS317 -> 184.216 | AT17: =AT251+AT317 -> 195.196 | AU17: =AU251+AU317 -> 210.167 | AV17: =AV251+AV317 -> 213.7 | AW17: =SUM(AS17:AV17) -> 803.279 | AX17: =AX251+AX317 -> 173.277 | AY17: =AY251+AY317 -> 178.466 | AZ17: =AZ251+AZ317 -> 169.665 | BA17: =BA251+BA317 -> 193 | BB17: =SUM(AX17:BA17) -> 714.408 | BC17: =BC251+BC317 -> 182.9 | BD17: =BD251+BD317 -> 193.7 | BE17: =BE251+BE317 -> 198.5 | BF17: =BF251+BF317 -> 208.7 | BG17: =SUM(BC17:BF17) -> 783.8 | BH17: =BH251+BH317 -> 215.81868 | BI17: =BI251+BI317 -> 220.71229 | BJ17: =BJ251+BJ317 -> 216.90207 | BK17: =BK251+BK317 -> 223.75651 | BL17: =SUM(BH17:BK17) -> 877.18955 | BM17: =BM251+BM317 -> 227.24307 | BN17: =BN251+BN317 -> 232.58902 | BO17: =BO251+BO317 -> 228.56957 | BP17: =BP251+BP317 -> 236.02337 | BQ17: =SUM(BM17:BP17) -> 924.42503 | BR17: =BR251+BR317 -> 239.1054 | BS17: =BS251+BS317 -> 244.71876 | BT17: =BT251+BT317 -> 240.46133 | BU17: =BU251+BU317 -> 248.30346 | BV17: =SUM(BR17:BU17) -> 972.58895 | BW17: =BW251+BW317 -> 251.61519 | BX17: =BX251+BX317 -> 257.50969 | BY17: =BY251+BY317 -> 252.99867 | BZ17: =BZ251+BZ317 -> 261.25075 | CA17: =SUM(BW17:BZ17) -> 1023.3743 | CD17: =A17 -> Cost Of Revenues | CE17: =D17 -> 331.804 | CF17: =I17 -> 357.191 | CG17: =N17 -> 386.897 | CH17: =S17 -> 491.294 | CI17: =X17 -> 463.473 | CJ17: =AC17 -> 533.735 | CK17: =AH17 -> 607.174 | CL17: =AM17 -> 622.522 | CM17: =AR17 -> 716.598 | CN17: =AW17 -> 803.279 | CO17: =BB17 -> 714.408 | CP17: =BG17 -> 783.8 | CQ17: =BL17 -> 877.18955 | CR17: =BQ17 -> 924.42503 | CS17: =BV17 -> 972.58895 | CT17: =CA17 -> 1023.3743
A18: Gross Margin | B18: 16 | C18: =1-C17/C12 -> 0.54293126 | D18: =1-D17/D12 -> 0.54555677 | E18: =1-E17/E12 -> 0.56251446 | F18: =1-F17/F12 -> 0.55499269 | G18: =1-G17/G12 -> 0.57269318 | H18: =1-H17/H12 -> 0.52911835 | I18: =1-I17/I12 -> 0.55473295 | J18: =1-J17/J12 -> 0.56724392 | ... CA18: =1-CA17/CA12 -> 0.63244609 | CD18: =A18 -> Gross Margin | CE18: =D18 -> 0.54555677 | CF18: =I18 -> 0.55473295 | CG18: =N18 -> 0.56701136 | CH18: =S18 -> 0.52167064 | CI18: =X18 -> 0.59285295 | CJ18: =AC18 -> 0.59924991 | CK18: =AH18 -> 0.6042716 | CL18: =AM18 -> 0.60987847 | CM18: =AR18 -> 0.58974791 | CN18: =AW18 -> 0.61157623 | CO18: =BB18 -> 0.6419327 | CP18: =BG18 -> 0.63462614 | CQ18: =BL18 -> 0.62821709 | CR18: =BQ18 -> 0.62958658 | CS18: =BV18 -> 0.63101612 | CT18: =CA18 -> 0.63244609
A19: Selling General and Administrative | C19: =C257+C323 -> 88.723 | D19: =D257+D323 -> 100.124 | E19: =E257+E323 -> 27.925 | F19: =F257+F323 -> 27.675 | G19: =G257+G323 -> 26.989 | H19: =H257+H323 -> 24.987 | I19: =SUM(E19:H19) -> 107.576 | J19: =J257+J323 -> 28.674 | K19: =K257+K323 -> 30.354 | L19: =L257+L323 -> 32.265 | M19: =M257+M323 -> 39.946 | N19: =SUM(J19:M19) -> 131.239 | O19: =O257+O323 -> 33.32 | P19: =P257+P323 -> 38.905 | Q19: =38.5 -> 38.5 | R19: =R257+R323 -> 51.879 | S19: =SUM(O19:R19) -> 162.604 | T19: =T257+T323 -> 37.514 | U19: =U257+U323 -> 42.638 | V19: =V257+V323 -> 40.982 | W19: =W257+W323 -> 45.24 | X19: =SUM(T19:W19) -> 166.374 | Y19: =Y257+Y323 -> 49.256 | Z19: =Z257+Z323 -> 55.909 | AA19: =AA257+AA323 -> 51.475 | AB19: =AB257+AB323 -> 52.829 | AC19: =SUM(Y19:AB19) -> 209.469 | AD19: =AD257+AD323 -> 53.979 | AE19: =AE257+AE323 -> 62.473 | AF19: =AF257+AF323 -> 58.707 | AG19: =AG257+AG323 -> 56.2 | AH19: =SUM(AD19:AG19) -> 231.359 | AI19: =AI257+AI323 -> 56.322 | AJ19: =AJ257+AJ323 -> 58.198 | AK19: =AK257+AK323 -> 56.783 | AL19: =AL257+AL323 -> 57.679 | AM19: =SUM(AI19:AL19) -> 228.982 | AN19: =AN257+AN323 -> 57.134 | AO19: =AO257+AO323 -> 57.074 | AP19: =AP257+AP323 -> 56.164 | AQ19: =AQ257+AQ323 -> 56.934 | AR19: =SUM(AN19:AQ19) -> 227.306 | AS19: =AS257+AS323 -> 58.306 | AT19: =AT257+AT323 -> 91.292 | AU19: =AU257+AU323 -> 79.31 | AV19: =AV257+AV323 -> 83.8 | AW19: =SUM(AS19:AV19) -> 312.708 | AX19: =AX257+AX323 -> 71.037 | AY19: =AY257+AY323 -> 75.557 | AZ19: =AZ257+AZ323 -> 77.814 | BA19: =BA257+BA323 -> 77.2 | BB19: =SUM(AX19:BA19) -> 301.608 | BC19: =BC257+BC323 -> 75.9 | BD19: =BD257+BD323 -> 78.8 | BE19: =BE257+BE323 -> 80.9 | BF19: =BF257+BF323 -> 87.2 | BG19: =SUM(BC19:BF19) -> 322.8 | BH19: =BH257+BH323 -> 83.643193 | BI19: =BI257+BI323 -> 87.06328 | BJ19: =BJ257+BJ323 -> 88.653914 | BK19: =BK257+BK323 -> 93.607949 | BL19: =SUM(BH19:BK19) -> 352.96834 | BM19: =BM257+BM323 -> 87.661882 | BN19: =BN257+BN323 -> 91.343995 | BO19: =BO257+BO323 -> 93.040746 | BP19: =BP257+BP323 -> 98.340828 | BQ19: =SUM(BM19:BP19) -> 370.38745 | BR19: =BR257+BR323 -> 91.806375 | BS19: =BS257+BS323 -> 95.678304 | BT19: =BT257+BT323 -> 97.472846 | BU19: =BU257+BU323 -> 103.03517 | BV19: =SUM(BR19:BU19) -> 387.9927 | BW19: =BW257+BW323 -> 96.156162 | BX19: =BX257+BX323 -> 100.22818 | BY19: =BY257+BY323 -> 102.12614 | BZ19: =BZ257+BZ323 -> 107.96412 | CA19: =SUM(BW19:BZ19) -> 406.47459 | CD19: =A19 -> Selling General and Administrative | CE19: =D19 -> 100.124 | CF19: =I19 -> 107.576 | CG19: =N19 -> 131.239 | CH19: =S19 -> 162.604 | CI19: =X19 -> 166.374 | CJ19: =AC19 -> 209.469 | CK19: =AH19 -> 231.359 | CL19: =AM19 -> 228.982 | CM19: =AR19 -> 227.306 | CN19: =AW19 -> 312.708 | CO19: =BB19 -> 301.608 | CP19: =BG19 -> 322.8 | CQ19: =BL19 -> 352.96834 | CR19: =BQ19 -> 370.38745 | CS19: =BV19 -> 387.9927 | CT19: =CA19 -> 406.47459
A20: % of Total Revenue | C20: =C19/C12 -> 0.13741443 | D20: =D19/D12 -> 0.13713118 | E20: =E19/E12 -> 0.14044379 | F20: =F19/F12 -> 0.13758116 | G20: =G19/G12 -> 0.13513216 | H20: =H19/H12 -> 0.12340234 | I20: =I19/I12 -> 0.13410206 | J20: =J19/J12 -> 0.13298519 | ... CA20: =CA19/CA12 -> 0.14598893 | CD20: =A20 -> % of Total Revenue | CE20: =D20 -> 0.13713118 | CF20: =I20 -> 0.13410206 | CG20: =N20 -> 0.14687371 | CH20: =S20 -> 0.15831308 | CI20: =X20 -> 0.14615454 | CJ20: =AC20 -> 0.1572779 | CK20: =AH20 -> 0.15078927 | CL20: =AM20 -> 0.14349824 | CM20: =AR20 -> 0.1301326 | CN20: =AW20 -> 0.15120926 | CO20: =BB20 -> 0.15116847 | CP20: =BG20 -> 0.15047548 | CQ20: =BL20 -> 0.14960004 | CR20: =BQ20 -> 0.14841277 | CS20: =BV20 -> 0.1471979 | CT20: =CA20 -> 0.14598893
C21: ______ | D21: ______ | E21: ______ | F21: ______ | G21: ______ | H21: ______ | I21: ______ | J21: ______ | K21: ______ | L21: ______ | M21: ______ | N21: ______ | O21: ______ | P21: ______ | Q21: ______ | R21: ______ | S21: ______ | T21: ______ | U21: ______ | V21: ______ | W21: ______ | X21: ______ | Y21: ______ | Z21: ______ | AA21: ______ | AB21: ______ | AC21: ______ | AD21: ______ | AE21: ______ | AF21: ______ | AG21: ______ | AH21: ______ | AI21: ______ | AJ21: ______ | AK21: ______ | AL21: ______ | AM21: ______ | AN21: ______ | AO21: ______ | AP21: ______ | AQ21: ______ | AR21: ______ | AS21: ______ | AT21: ______ | AU21: ______ | AV21: ______ | AW21: ______ | AX21: ______ | AY21: ______ | AZ21: ______ | BA21: ______ | BB21: ______ | BC21: ______ | BD21: ______ | BE21: ______ | BF21: ______ | BG21: ______ | BH21: ______ | BI21: ______ | BJ21: ______ | BK21: ______ | BL21: ______ | BM21: ______ | BN21: ______ | BO21: ______ | BP21: ______ | BQ21: ______ | BR21: ______ | BS21: ______ | BT21: ______ | BU21: ______ | BV21: ______ | BW21: ______ | BX21: ______ | BY21: ______ | BZ21: ______ | CA21: ______
A22: Total Expenses | C22: =SUM(C17,C19) -> 383.834 | D22: =SUM(D17,D19) -> 431.928 | E22: =SUM(E17,E19) -> 114.912 | F22: =SUM(F17,F19) -> 117.19 | G22: =SUM(G17,G19) -> 112.332 | H22: =SUM(H17,H19) -> 120.333 | I22: =SUM(I17,I19) -> 464.767 | J22: =SUM(J17,J19) -> 121.984 | ... CA22: =SUM(CA17,CA19) -> 1429.8489 | CD22: =A22 -> Total Expenses | CE22: =D22 -> 431.928 | CF22: =I22 -> 464.767 | CG22: =N22 -> 518.136 | CH22: =S22 -> 653.898 | CI22: =X22 -> 629.847 | CJ22: =AC22 -> 743.204 | CK22: =AH22 -> 838.533 | CL22: =AM22 -> 851.504 | CM22: =AR22 -> 943.904 | CN22: =AW22 -> 1115.987 | CO22: =BB22 -> 1016.016 | CP22: =BG22 -> 1106.6 | CQ22: =BL22 -> 1230.1579 | CR22: =BQ22 -> 1294.8125 | CS22: =BV22 -> 1360.5816 | CT22: =CA22 -> 1429.8489
A24: Adjustments | D24: =D265+D331 -> 11.732 | I24: =I265+I331 -> 13.804 | J24: =J265+J331 -> 3.166 | K24: =K265+K331 -> 3.611 | L24: =L265+L331 -> 3.24 | M24: =M265+M331 -> 2.546 | N24: =N265+N331 -> 12.563 | O24: =O265+O331 -> 2.833 | P24: =P265+P331 -> 3.76 | Q24: =3.822+3.154 -> 6.976 | R24: =R265+R331 -> 60.725 | S24: =S265+S331 -> 74.27 | T24: 0 | U24: 0 | V24: 0 | W24: 0 | X24: =X265+X331 -> 0 | Y24: =Y265+Y331 -> 0 | Z24: =Z265+Z331 -> 3.364 | AA24: =AA265+AA331 -> 0 | AB24: =AB265+AB331 -> 0 | AC24: =AC265+AC331 -> 3.364 | AD24: =AD265+AD331 -> -0.435 | AE24: =AE265+AE331 -> -0.126 | ... AR24: =AR265+AR331 -> -0.158 | AS24: =-(AS265+AS331) -> 0.6 | AT24: =-26.617+0.221 -> -26.396 | AU24: =-(-AU265+AU331) -> -17.912 | AV24: =AV265+AV331 -> 0.1 | AW24: =SUM(AS24:AV24) -> -43.608 | AX24: =AX265+AX331 -> 0.212 | AY24: =AY265+AY331 -> 0.846 | AZ24: =AZ265+AZ331 -> 2.7 | BA24: =-(BA265-BA331) -> 21.9 | BB24: =SUM(AX24:BA24) -> 25.658 | BC24: =-(BC265-BC331) -> 1.9 | BD24: =-(BD265-BD331) -> 3.4 | BE24: =-(BE265-BE331) -> 2.6 | BF24: =-(BF265-BF331) -> 1.7 | BG24: =-(BG265-BG331) -> 9.6 | BH24: =-(BH265-BH331) -> 0 | BI24: =-(BI265-BI331) -> 0 | BJ24: =-(BJ265-BJ331) -> 0 | BK24: =-(BK265-BK331) -> 0 | BL24: =BL265+BL331 -> 0 | BM24: =-(BM265-BM331) -> 0 | BN24: =-(BN265-BN331) -> 0 | BO24: =-(BO265-BO331) -> 0 | BP24: =-(BP265-BP331) -> 0 | BQ24: =BQ265+BQ331 -> 0 | BR24: =-(BR265-BR331) -> 0 | BS24: =-(BS265-BS331) -> 0 | BT24: =-(BT265-BT331) -> 0 | BU24: =-(BU265-BU331) -> 0 | BV24: =BV265+BV331 -> 0 | BW24: =-(BW265-BW331) -> 0 | BX24: =-(BX265-BX331) -> 0 | BY24: =-(BY265-BY331) -> 0 | BZ24: =-(BZ265-BZ331) -> 0 | CA24: =CA265+CA331 -> 0 | CD24: =A24 -> Adjustments | CE24: =D24 -> 11.732 | CF24: =I24 -> 13.804 | CG24: =N24 -> 12.563 | CH24: =S24 -> 74.27 | CI24: =X24 -> 0 | CJ24: =AC24 -> 3.364 | CK24: =AH24 -> -0.128 | CL24: =AM24 -> 0.635 | CM24: =AR24 -> -0.158 | CN24: =AW24 -> -43.608 | CO24: =BB24 -> 25.658 | CP24: =BG24 -> 9.6 | CQ24: =BL24 -> 0 | CR24: =BQ24 -> 0 | CS24: =BV24 -> 0 | CT24: =CA24 -> 0
A25: % of Total Revenue | D25: =D24/D12 -> 0.016068305 | I25: =I24/I12 -> 0.017207786 | J25: =J24/J12 -> 0.014683375 | K25: =K24/K12 -> 0.016260492 | L25: =L24/L12 -> 0.014439082 | M25: =M24/M12 -> 0.010999313 | N25: =N24/N12 -> 0.01405965 | O25: =O24/O12 -> 0.011527929 | P25: =P24/P12 -> 0.01457839 | ... CA25: =CA24/CA12 -> 0 | CD25: =A25 -> % of Total Revenue | CE25: =D25 -> 0.016068305 | CF25: =I25 -> 0.017207786 | CG25: =N25 -> 0.01405965 | CH25: =S25 -> 0.072310107 | CI25: =X25 -> 0 | CJ25: =AC25 -> 0.0025258289 | CK25: =AH25 -> -8.3424579e-05 | CL25: =AM25 -> 0.00039794123 | CM25: =AR25 -> -9.0454943e-05 | CN25: =AW25 -> -0.021086551 | CO25: =BB25 -> 0.012860005 | CP25: =BG25 -> 0.0044751072 | CQ25: =BL25 -> 0 | CR25: =BQ25 -> 0 | CS25: =BV25 -> 0 | CT25: =CA25 -> 0
A27: Total Expenses ex. ESOP and IPO Expenses | C27: =C22-C24 -> 383.834 | D27: =D22-D24 -> 420.196 | E27: =E22-E24 -> 114.912 | F27: =F22-F24 -> 117.19 | G27: =G22-G24 -> 112.332 | H27: =H22-H24 -> 120.333 | I27: =I22-I24 -> 450.963 | J27: =J22-J24 -> 118.818 | ... AM27: =AM22-AM24 -> 850.869 | AR27: =AR22-AR24 -> 944.062 | AW27: =AW22-AW24 -> 1159.595 | BB27: =BB22-BB24 -> 990.358 | BG27: =BG22-BG24 -> 1097 | BL27: =BL22-BL24 -> 1230.1579 | BQ27: =BQ22-BQ24 -> 1294.8125 | BV27: =BV22-BV24 -> 1360.5816 | CA27: =CA22-CA24 -> 1429.8489 | CD27: =A27 -> Total Expenses ex. ESOP and IPO Expenses | CE27: =D27 -> 420.196 | CF27: =I27 -> 450.963 | CG27: =N27 -> 505.573 | CH27: =S27 -> 579.628 | CI27: =X27 -> 629.847 | CJ27: =AC27 -> 739.84 | CK27: =AH27 -> 838.661 | CL27: =AM27 -> 850.869 | CM27: =AR27 -> 944.062 | CN27: =AW27 -> 1159.595 | CO27: =BB27 -> 990.358 | CP27: =BG27 -> 1097 | CQ27: =BL27 -> 1230.1579 | CR27: =BQ27 -> 1294.8125 | CS27: =BV27 -> 1360.5816 | CT27: =CA27 -> 1429.8489
A29: EBITDA | C29: =C12-C22 -> 261.826 | D29: =D12-D22 -> 298.205 | E29: =E12-E22 -> 83.922 | F29: =F12-F22 -> 83.964 | G29: =G12-G22 -> 87.391 | H29: =H12-H22 -> 82.151 | I29: =I12-I22 -> 337.428 | J29: =J12-J22 -> 93.634 | ... AQ29: =AQ12-AQ22 -> 214.348 | AR29: =SUM(AN29:AQ29) -> 802.822 | AS29: =AS12-AS22 -> 216.875 | AT29: =AT12-AT22 -> 211.162 | AU29: =AU12-AU22 -> 260.924 | AV29: =AV12-AV22 -> 263.1 | AW29: =AW12-AW22 -> 952.061 | AX29: =AX12-AX22 -> 248.387 | AY29: =AY12-AY22 -> 244.273 | AZ29: =AZ12-AZ22 -> 250.602 | ... CA29: =CA12-CA22 -> 1354.4347 | CB29: =(CA29/BB29)^(1/5)-1 -> 0.067040005 | CD29: =A29 -> EBITDA | CE29: =D29 -> 298.205 | CF29: =I29 -> 337.428 | CG29: =N29 -> 375.414 | CH29: =S29 -> 373.206 | CI29: =X29 -> 508.496 | CJ29: =AC29 -> 588.636 | CK29: =AH29 -> 695.787 | CL29: =AM29 -> 744.209 | CM29: =AR29 -> 802.822 | CN29: =AW29 -> 952.061 | CO29: =BB29 -> 979.162 | CP29: =BG29 -> 1038.6 | CQ29: =BL29 -> 1129.2554 | CR29: =BQ29 -> 1200.845 | CS29: =BV29 -> 1275.2759 | CT29: =CA29 -> 1354.4347
A30: EBITDA Margin | C30: =C29/C12 -> 0.40551684 | D30: =D29/D12 -> 0.40842559 | E30: =E29/E12 -> 0.42207067 | F30: =F29/F12 -> 0.41741154 | G30: =G29/G12 -> 0.43756102 | H30: =H29/H12 -> 0.40571601 | I30: =I29/I12 -> 0.42063089 | J30: =J29/J12 -> 0.43425874 | ... CA30: =CA29/CA12 -> 0.48645716 | CD30: =A30 -> EBITDA Margin | CE30: =D30 -> 0.40842559 | CF30: =I30 -> 0.42063089 | CG30: =N30 -> 0.42013765 | CH30: =S30 -> 0.36335756 | CI30: =X30 -> 0.4466984 | CJ30: =AC30 -> 0.44197201 | CK30: =AH30 -> 0.45348232 | CL30: =AM30 -> 0.46638023 | CM30: =AR30 -> 0.4596153 | CN30: =AW30 -> 0.46036697 | CO30: =BB30 -> 0.49076423 | CP30: =BG30 -> 0.48415066 | CQ30: =BL30 -> 0.47861705 | CR30: =BQ30 -> 0.4811738 | CS30: =BV30 -> 0.48381822 | CT30: =CA30 -> 0.48645716
A31: Year-over-Year Growth | I31: =I29/D29-1 -> 0.13153032 | J31: =J29/E29-1 -> 0.11572651 | K31: =K29/F29-1 -> 0.12369587 | L31: =L29/G29-1 -> 0.073554485 | M31: =M29/H29-1 -> 0.13949921 | N31: =N29/I29-1 -> 0.11257513 | O31: =O29/J29-1 -> 0.12040498 | P31: =P29/K29-1 -> 0.12382618 | ... CA31: =CA29/BV29-1 -> 0.062071852 | CD31: =A31 -> Year-over-Year Growth | CF31: =I31 -> 0.13153032 | CG31: =N31 -> 0.11257513 | CH31: =S31 -> -0.0058815068 | CI31: =X31 -> 0.36250757 | CJ31: =AC31 -> 0.15760203 | CK31: =AH31 -> 0.1820327 | CL31: =AM31 -> 0.069593137 | CM31: =AR31 -> 0.07875879 | CN31: =AW31 -> 0.18589301 | CO31: =BB31 -> 0.028465613 | CP31: =BG31 -> 0.060702928 | CQ31: =BL31 -> 0.087286198 | CR31: =BQ31 -> 0.063395367 | CS31: =BV31 -> 0.061982119 | CT31: =CA31 -> 0.062071852
A33: Adj. EBITDA | C33: =C29+C24 -> 261.826 | D33: =D29+D24 -> 309.937 | E33: =E29+E24 -> 83.922 | F33: =F29+F24 -> 83.964 | G33: =G29+G24 -> 87.391 | H33: =H29+H24 -> 82.151 | I33: =I29+I24 -> 351.232 | J33: =J29+J24 -> 96.8 | ... O33: =O29+O24 -> 107.741 | P33: =P29+P24+P26 -> 109.793 | Q33: =Q29+Q24+Q26 -> 109.404 | R33: =R29+R24+R26 -> 120.562 | S33: =S29+S24+S26 -> 447.476 | T33: =T29+T24 -> 123.647 | U33: =U29+U24 -> 124.039 | V33: =V29+V24 -> 129.367 | W33: =W29+W24 -> 131.443 | X33: =X29+X24 -> 508.496 | Y33: =Y29+Y24 -> 139.057 | Z33: =Z29+Z24 -> 143.55 | AA33: =AA29+AA24 -> 151.004 | ... AC33: =AC29+AC24 -> 592 | AD33: =AD29-AD24 -> 159.627 | AE33: =AE29-AE24 -> 163.805 | AF33: =AF29-AF24 -> 182.905 | AG33: =AG29-AG24 -> 189.578 | AH33: =AH29-AH24 -> 695.915 | AI33: =AI29-AI24 -> 176.598 | AJ33: =AJ29-AJ24 -> 179.867 | AK33: =AK29-AK24 -> 199.066 | ... AQ33: =AQ29-AQ24 -> 214.582 | AR33: =SUM(AN33:AQ33) -> 802.98 | AS33: =AS29-AS24 -> 216.275 | AT33: =AT29-AT24 -> 237.558 | AU33: =AU29-AU24 -> 278.836 | AV33: =AV29-AV24 -> 263 | AW33: =AW29-AW24 -> 995.669 | AX33: =AX29+AX24 -> 248.599 | AY33: =AY29+AY24 -> 245.119 | AZ33: =AZ29+AZ24 -> 253.302 | BA33: =BA29+BA24 -> 257.8 | BB33: =BB29+BB24 -> 1004.82 | BC33: =BC29+BC24 -> 245.7 | BD33: =BD29+BD24 -> 254.1 | BE33: =BE29+BE24 -> 272.3 | ... CA33: =CA29+CA24 -> 1354.4347 | CB33: =(CA33/BG33)^(1/4)-1 -> 0.066174954 | CD33: =A33 -> Adj. EBITDA | CE33: =D33 -> 309.937 | CF33: =I33 -> 351.232 | CG33: =N33 -> 387.977 | CH33: =S33 -> 447.476 | CI33: =X33 -> 508.496 | CJ33: =AC33 -> 592 | CK33: =AH33 -> 695.915 | CL33: =AM33 -> 743.574 | CM33: =AR33 -> 802.98 | CN33: =AW33 -> 995.669 | CO33: =BB33 -> 1004.82 | CP33: =BG33 -> 1048.2 | CQ33: =BL33 -> 1129.2554 | CR33: =BQ33 -> 1200.845 | CS33: =BV33 -> 1275.2759 | CT33: =CA33 -> 1354.4347
A34: Adj. EBITDA Margin | C34: =C33/C12 -> 0.40551684 | D34: =D33/D12 -> 0.42449389 | E34: =E33/E12 -> 0.42207067 | F34: =F33/F12 -> 0.41741154 | G34: =G33/G12 -> 0.43756102 | H34: =H33/H12 -> 0.40571601 | I34: =I33/I12 -> 0.43783868 | J34: =J33/J12 -> 0.44894211 | ... CA34: =CA33/CA12 -> 0.48645716 | CD34: =A34 -> Adj. EBITDA Margin | CE34: =D34 -> 0.42449389 | CF34: =I34 -> 0.43783868 | CG34: =N34 -> 0.4341973 | CH34: =S34 -> 0.43566766 | CI34: =X34 -> 0.4466984 | CJ34: =AC34 -> 0.44449784 | CK34: =AH34 -> 0.45356575 | CL34: =AM34 -> 0.46598229 | CM34: =AR34 -> 0.45970576 | CN34: =AW34 -> 0.48145353 | CO34: =BB34 -> 0.50362424 | CP34: =BG34 -> 0.48862577 | CQ34: =BL34 -> 0.47861705 | CR34: =BQ34 -> 0.4811738 | CS34: =BV34 -> 0.48381822 | CT34: =CA34 -> 0.48645716
A35: Year-over-Year Growth | D35: =D33/C33-1 -> 0.1837518 | I35: =I33/D33-1 -> 0.13323675 | J35: =J33/E33-1 -> 0.15345201 | K35: =K33/F33-1 -> 0.1667024 | L35: =L33/G33-1 -> 0.11062924 | M35: =M33/H33-1 -> 0.17049093 | N35: =N33/I33-1 -> 0.10461746 | O35: =O33/J33-1 -> 0.11302686 | P35: =P33/K33-1 -> 0.12078276 | ... AW35: =AW33/AR33-1 -> 0.23996737 | AX35: 0.2411333 | AY35: 0.1249151 | AZ35: -0.0058791209 | BA35: 0.070153591 | BB35: 0.099485721 | BC35: =BC33/AX33-1 -> -0.01166135 | BD35: =BD33/AY33-1 -> 0.036639347 | BE35: =BE33/AZ33-1 -> 0.075001382 | BF35: =BF33/BA33-1 -> 0.07098526 | BG35: =BG33/BB33-1 -> 0.043171911 | BH35: =BH33/BC33-1 -> 0.093578053 | BI35: =BI33/BD33-1 -> 0.08188283 | BJ35: =BJ33/BE33-1 -> 0.07481583 | ... CA35: =CA33/BV33-1 -> 0.062071852 | CD35: =A35 -> Year-over-Year Growth | CE35: =D35 -> 0.1837518 | CF35: =I35 -> 0.13323675 | CG35: =N35 -> 0.10461746 | CH35: =S35 -> 0.15335703 | CI35: =X35 -> 0.13636486 | CJ35: =AC35 -> 0.16421761 | CK35: =AH35 -> 0.17553209 | CL35: =AM35 -> 0.068483938 | CM35: =AR35 -> 0.079892519 | CN35: =AW35 -> 0.23996737 | CO35: =BB35 -> 0.099485721 | CP35: =BG35 -> 0.043171911 | CQ35: =BL35 -> 0.077328224 | CR35: =BQ35 -> 0.063395367 | CS35: =BV35 -> 0.061982119 | CT35: =CA35 -> 0.062071852
A37: Depreciation and Amortization | C37: =C38+C39 -> 41.824 | D37: =D38+D39 -> 54.861 | E37: =E38+E39 -> 16.505 | F37: =F38+F39 -> 16.233 | G37: =G38+G39 -> 15.523 | H37: =H38+H39 -> 17.4 | I37: =I38+I39 -> 65.661 | J37: =J38+J39 -> 15.948 | ... AQ37: =AQ38+AQ39 -> 37.301 | AR37: =SUM(AN37:AQ37) -> 142.376 | AS37: =AS38+AS39 -> 38.583 | AT37: =AT38+AT39 -> 57.44 | AU37: =AU38+AU39 -> 52.044 | AV37: =AV38+AV39 -> 67.682 | AW37: =SUM(AS37:AV37) -> 215.749 | AX37: =AX38+AX39 -> 55.758 | AY37: =AY38+AY39 -> 53.194 | AZ37: =AZ38+AZ39 -> 52.18 | BA37: =BA38+BA39 -> 50.4 | BB37: =SUM(AX37:BA37) -> 211.532 | BC37: =BC38+BC39 -> 56.1 | BD37: =BD38+BD39 -> 55.7 | BE37: =BE38+BE39 -> 61.3 | BF37: =BF38+BF39 -> 64.3 | BG37: =SUM(BC37:BF37) -> 237.4 | BH37: =BH38+BH39 -> 70.91086 | BI37: =BI38+BI39 -> 70.04494 | BJ37: =BJ38+BJ39 -> 70.57008 | BK37: =BK38+BK39 -> 71.01484 | BL37: =SUM(BH37:BK37) -> 282.54072 | BM37: =BM38+BM39 -> 70.561862 | BN37: =BN38+BN39 -> 69.693847 | BO37: =BO38+BO39 -> 70.218594 | BP37: =BP38+BP39 -> 70.662655 | BQ37: =SUM(BM37:BP37) -> 281.13696 | BR37: =BR38+BR39 -> 69.855625 | BS37: =BS38+BS39 -> 68.98497 | BT37: =BT38+BT39 -> 69.509222 | BU37: =BU38+BU39 -> 69.952402 | BV37: =SUM(BR37:BU37) -> 278.30222 | BW37: =BW38+BW39 -> 67.613406 | BX37: =BX38+BX39 -> 66.749219 | BY37: =BY38+BY39 -> 67.274684 | BZ37: =BZ38+BZ39 -> 67.720022 | CA37: =SUM(BW37:BZ37) -> 269.35733 | CD37: =A37 -> Depreciation and Amortization | CE37: =D37 -> 54.861 | CF37: =I37 -> 65.661 | CG37: =N37 -> 64.872 | CH37: =S37 -> 71.199 | CI37: =X37 -> 67.582 | CJ37: =AC37 -> 78.619 | CK37: =AH37 -> 104.199 | CL37: =AM37 -> 129.93 | CM37: =AR37 -> 142.376 | CN37: =AW37 -> 215.749 | CO37: =BB37 -> 211.532 | CP37: =BG37 -> 237.4 | CQ37: =BL37 -> 282.54072 | CR37: =BQ37 -> 281.13696 | CS37: =BV37 -> 278.30222 | CT37: =CA37 -> 269.35733
A38: Depreciation | C38: =C277+C345 -> 22.024 | D38: =D277+D345 -> 28.007 | E38: =E277+E345 -> 7.582 | F38: =F277+F345 -> 7.916 | G38: =G277+G345 -> 7.799 | H38: =H277+H345 -> 8.448 | I38: =SUM(E38:H38) -> 31.745 | J38: =J277+J345 -> 7.907 | K38: =K277+K345 -> 8.517 | L38: =L277+L345 -> 9.054 | M38: =M277+M345 -> 9.839 | N38: =SUM(J38:M38) -> 35.317 | O38: =O277+O345 -> 9.195 | P38: =P277+P345 -> 9.718 | Q38: 9.621 | R38: =R277+R345 -> 10.044 | S38: =SUM(O38:R38) -> 38.578 | T38: =T277+T345 -> 9.929 | U38: =U277+U345 -> 9.944 | V38: =V277+V345 -> 10.035 | W38: =W277+W345 -> 10.82 | X38: =SUM(T38:W38) -> 40.728 | Y38: =Y277+Y345 -> 11.305 | Z38: =Z277+Z345 -> 10.855 | AA38: =AA277+AA345 -> 10.798 | AB38: =AB277+AB345 -> 10.869 | AC38: =SUM(Y38:AB38) -> 43.827 | AD38: =AD277+AD345 -> 11.644 | AE38: =AE277+AE345 -> 13.09 | AF38: =AF277+AF345 -> 12.714 | AG38: =AG277+AG345 -> 13.176 | AH38: =SUM(AD38:AG38) -> 50.624 | AI38: =AI277+AI345 -> 14.163 | AJ38: =AJ277+AJ345 -> 15.81 | AK38: =AK277+AK345 -> 16.745 | AL38: =AL277+AL345 -> 19.471 | AM38: =SUM(AI38:AL38) -> 66.189 | AN38: =AN277+AN345 -> 19.781 | AO38: =AO277+AO345 -> 20.723 | AP38: =AP277+AP345 -> 21.951 | AQ38: =AQ277+AQ345 -> 23.051 | AR38: =SUM(AN38:AQ38) -> 85.506 | AS38: =AS277+AS345 -> 24.442 | AT38: =AT277+AT345 -> 28.628 | AU38: =AU277+AU345 -> 33.501 | AV38: =AV277+AV345 -> 34.049 | AW38: =SUM(AS38:AV38) -> 120.62 | AX38: 31.887 | AY38: 29.388 | AZ38: 29.501 | BA38: 28.3 | BB38: =SUM(AX38:BA38) -> 119.076 | BC38: 33.8 | BD38: 31.8 | BE38: 33.8 | BF38: 36.2 | BG38: =SUM(BC38:BF38) -> 135.6 | BH38: =BH277+BH345 -> 38.63586 | BI38: =BI277+BI345 -> 37.76994 | BJ38: =BJ277+BJ345 -> 38.29508 | BK38: =BK277+BK345 -> 38.73984 | BL38: =SUM(BH38:BK38) -> 153.44072 | BM38: =BM277+BM345 -> 38.511862 | BN38: =BN277+BN345 -> 37.643847 | BO38: =BO277+BO345 -> 38.168594 | BP38: =BP277+BP345 -> 38.612655 | BQ38: =SUM(BM38:BP38) -> 152.93696 | BR38: =BR277+BR345 -> 38.355625 | BS38: =BS277+BS345 -> 37.48497 | BT38: =BT277+BT345 -> 38.009222 | BU38: =BU277+BU345 -> 38.452402 | BV38: =SUM(BR38:BU38) -> 152.30222 | BW38: =BW277+BW345 -> 38.738406 | BX38: =BX277+BX345 -> 37.874219 | BY38: =BY277+BY345 -> 38.399684 | BZ38: =BZ277+BZ345 -> 38.845022 | CA38: =SUM(BW38:BZ38) -> 153.85733 | CD38: =A38 -> Depreciation | CE38: =D38 -> 28.007 | CF38: =I38 -> 31.745 | CG38: =N38 -> 35.317 | CH38: =S38 -> 38.578 | CI38: =X38 -> 40.728 | CJ38: =AC38 -> 43.827 | CK38: =AH38 -> 50.624 | CL38: =AM38 -> 66.189 | CM38: =AR38 -> 85.506 | CN38: =AW38 -> 120.62 | CO38: =BB38 -> 119.076 | CP38: =BG38 -> 135.6 | CQ38: =BL38 -> 153.44072 | CR38: =BQ38 -> 152.93696 | CS38: =BV38 -> 152.30222 | CT38: =CA38 -> 153.85733
A39: Intangible Amortization | C39: =C279+C346 -> 19.8 | D39: =D279+D346 -> 26.854 | E39: =E279+E346 -> 8.923 | F39: =F279+F346 -> 8.317 | G39: =G279+G346 -> 7.724 | H39: =H279+H346 -> 8.952 | I39: =SUM(E39:H39) -> 33.916 | J39: =J279+J346 -> 8.041 | K39: =K279+K346 -> 6.896 | L39: =L279+L346 -> 7.041 | M39: =M279+M346 -> 7.577 | N39: =SUM(J39:M39) -> 29.555 | O39: =O279+O346 -> 8.51 | P39: =P279+P346 -> 8.464 | Q39: 8.012 | R39: =R279+R346 -> 7.635 | S39: =SUM(O39:R39) -> 32.621 | T39: =T279+T346 -> 7.304 | U39: =U279+U346 -> 7.02 | V39: =V279+V346 -> 5.614 | W39: =W279+W346 -> 6.916 | X39: =SUM(T39:W39) -> 26.854 | Y39: =Y279+Y346 -> 8.455 | Z39: =Z279+Z346 -> 8.877 | AA39: =AA279+AA346 -> 8.797 | AB39: =AB279+AB346 -> 8.663 | AC39: =SUM(Y39:AB39) -> 34.792 | AD39: =AD279+AD346 -> 8.587 | AE39: =AE279+AE346 -> 12.187 | AF39: =AF279+AF346 -> 15.442 | AG39: =AG279+AG346 -> 17.359 | AH39: =SUM(AD39:AG39) -> 53.575 | AI39: =AI279+AI346 -> 17.052 | AJ39: =AJ279+AJ346 -> 17.061 | AK39: =AK279+AK346 -> 15.258 | AL39: =AL279+AL346 -> 14.37 | AM39: =SUM(AI39:AL39) -> 63.741 | AN39: =AN279+AN346 -> 14.212 | AO39: =AO279+AO346 -> 14.221 | AP39: =AP279+AP346 -> 14.187 | AQ39: =AQ279+AQ346 -> 14.25 | AR39: =SUM(AN39:AQ39) -> 56.87 | AS39: =AS279+AS346 -> 14.141 | AT39: =AT279+AT346 -> 28.812 | AU39: =AU279+AU346 -> 18.543 | AV39: =AV279+AV346 -> 33.633 | AW39: =SUM(AS39:AV39) -> 95.129 | AX39: 23.871 | AY39: 23.806 | AZ39: 22.679 | BA39: 22.1 | BB39: =SUM(AX39:BA39) -> 92.456 | BC39: 22.3 | BD39: 23.9 | BE39: 27.5 | BF39: 28.1 | BG39: =SUM(BC39:BF39) -> 101.8 | BH39: =129.1/4 -> 32.275 | BI39: =BH39 -> 32.275 | BJ39: =BI39 -> 32.275 | BK39: =BJ39 -> 32.275 | BL39: =SUM(BH39:BK39) -> 129.1 | BM39: =128.2/4 -> 32.05 | BN39: =BM39 -> 32.05 | BO39: =BN39 -> 32.05 | BP39: =BO39 -> 32.05 | BQ39: =SUM(BM39:BP39) -> 128.2 | BR39: =126/4 -> 31.5 | BS39: =BR39 -> 31.5 | BT39: =BS39 -> 31.5 | BU39: =BT39 -> 31.5 | BV39: =SUM(BR39:BU39) -> 126 | BW39: =115.5/4 -> 28.875 | BX39: =BW39 -> 28.875 | BY39: =BX39 -> 28.875 | BZ39: =BY39 -> 28.875 | CA39: =SUM(BW39:BZ39) -> 115.5 | CD39: =A39 -> Intangible Amortization | CE39: =D39 -> 26.854 | CF39: =I39 -> 33.916 | CG39: =N39 -> 29.555 | CH39: =S39 -> 32.621 | CI39: =X39 -> 26.854 | CJ39: =AC39 -> 34.792 | CK39: =AH39 -> 53.575 | CL39: =AM39 -> 63.741 | CM39: =AR39 -> 56.87 | CN39: =AW39 -> 95.129 | CO39: =BB39 -> 92.456 | CP39: =BG39 -> 101.8 | CQ39: =BL39 -> 129.1 | CR39: =BQ39 -> 128.2 | CS39: =BV39 -> 126 | CT39: =CA39 -> 115.5
A40: % of Total Revenue | C40: =C37/C12 -> 0.064777127 | D40: =D37/D12 -> 0.075138365 | E40: =E37/E12 -> 0.083008942 | F40: =F37/F12 -> 0.080699365 | G40: =G37/G12 -> 0.077722646 | H40: =H37/H12 -> 0.085932716 | I40: =I37/I12 -> 0.081851669 | J40: =J37/J12 -> 0.07396414 | ... X40: =X37/X12 -> 0.059368749 | Z40: =Z37/Z12 -> 0.060290882 | AA40: =AA37/AA12 -> 0.057615746 | AB40: =AB37/AB12 -> 0.055552869 | AC40: =AC37/AC12 -> 0.059030364 | AD40: =AD37/AD12 -> 0.058386556 | AE40: =AE37/AE12 -> 0.067725721 | AF40: =AF37/AF12 -> 0.070590654 | AG40: =AF40 -> 0.070590654 | AH40: =AH37/AH12 -> 0.06791217 | AI40: =AI37/AI12 -> 0.082865008 | AJ40: =AJ37/AJ12 -> 0.084205592 | AK40: =AK37/AK12 -> 0.07769095 | AL40: =AL37/AL12 -> 0.081207421 | AM40: =AM37/AM12 -> 0.081424417 | AN40: =AN37/AN12 -> 0.082982011 | AO40: =AO37/AO12 -> 0.082501877 | AP40: =AP37/AP12 -> 0.080545619 | AQ40: =AP40 -> 0.080545619 | AR40: =AR37/AR12 -> 0.081510208 | AS40: =AS37/AS12 -> 0.083986182 | AT40: =AT37/AT12 -> 0.11542249 | AU40: 0.0302 | AV40: =AV37/AV12 -> 0.12073136 | AW40: =AW37/AW12 -> 0.10432495 | AX40: =AX37/AX12 -> 0.11316803 | AY40: =AY37/AY12 -> 0.10675181 | AZ40: =AZ37/AZ12 -> 0.10476208 | BA40: =BA37/BA12 -> 0.099585062 | BB40: =BB37/BB12 -> 0.10602162 | BC40: =BC37/BC12 -> 0.11161958 | ... CA40: =CA37/CA12 -> 0.096742062 | CD40: =A40 -> % of Total Revenue | CE40: =D40 -> 0.075138365 | CF40: =I40 -> 0.081851669 | CG40: =N40 -> 0.072600302 | CH40: =S40 -> 0.069320147 | CI40: =X40 -> 0.059368749 | CJ40: =AC40 -> 0.059030364 | CK40: =AH40 -> 0.06791217 | CL40: =AM40 -> 0.081424417 | CM40: =AR40 -> 0.081510208 | CN40: =AW40 -> 0.10432495 | CO40: =BB40 -> 0.10602162 | CP40: =BG40 -> 0.11066567 | CQ40: =BL40 -> 0.11975041 | CR40: =BQ40 -> 0.11265046 | CS40: =BV40 -> 0.10558318 | CT40: =CA40 -> 0.096742062
A42: Income from Operations | C42: =C12-C22-C37 -> 220.002 | D42: =D12-D22-D37 -> 243.344 | E42: =E12-E22-E37 -> 67.417 | F42: =F12-F22-F37 -> 67.731 | G42: =G12-G22-G37 -> 71.868 | H42: =H12-H22-H37 -> 64.751 | I42: =I12-I22-I37 -> 271.767 | J42: =J12-J22-J37 -> 77.686 | ... AQ42: =AQ12-AQ22-AQ37 -> 177.047 | AR42: =SUM(AN42:AQ42) -> 660.446 | AS42: =AS12-AS22-AS37 -> 178.292 | AT42: =AT12-AT22-AT37 -> 153.722 | AU42: =AU12-AU22-AU37 -> 208.88 | AV42: =AV12-AV22-AV37 -> 195.418 | AW42: =AW12-AW22-AW37 -> 736.312 | AX42: =AX12-AX22-AX37 -> 192.629 | AY42: =AY12-AY22-AY37 -> 191.079 | AZ42: =AZ12-AZ22-AZ37 -> 198.422 | ... CA42: =CA12-CA22-CA37 -> 1085.0773 | CD42: =A42 -> Income from Operations | CE42: =D42 -> 243.344 | CF42: =I42 -> 271.767 | CG42: =N42 -> 310.542 | CH42: =S42 -> 302.007 | CI42: =X42 -> 440.914 | CJ42: =AC42 -> 510.017 | CK42: =AH42 -> 591.588 | CL42: =AM42 -> 614.279 | CM42: =AR42 -> 660.446 | CN42: =AW42 -> 736.312 | CO42: =BB42 -> 767.63 | CP42: =BG42 -> 801.2 | CQ42: =BL42 -> 846.71472 | CR42: =BQ42 -> 919.70805 | CS42: =BV42 -> 996.97371 | CT42: =CA42 -> 1085.0773
A43: Operating Margin | C43: =C42/C12 -> 0.34073971 | D43: =D42/D12 -> 0.33328722 | E43: =E42/E12 -> 0.33906173 | F43: =F42/F12 -> 0.33671217 | G43: =G42/G12 -> 0.35983838 | H43: =H42/H12 -> 0.31978329 | I43: =I42/I12 -> 0.33877922 | J43: =J42/J12 -> 0.3602946 | ... CA43: =CA42/CA12 -> 0.3897151 | CD43: =A43 -> Operating Margin | CE43: =D43 -> 0.33328722 | CF43: =I43 -> 0.33877922 | CG43: =N43 -> 0.34753735 | CH43: =S43 -> 0.29403741 | CI43: =X43 -> 0.38732965 | CJ43: =AC43 -> 0.38294164 | CK43: =AH43 -> 0.38557015 | CL43: =AM43 -> 0.38495582 | CM43: =AR43 -> 0.37810509 | CN43: =AW43 -> 0.35604203 | CO43: =BB43 -> 0.38474261 | CP43: =BG43 -> 0.37348499 | CQ43: =BL43 -> 0.35886664 | CR43: =BQ43 -> 0.36852335 | CS43: =BV43 -> 0.37823504 | CT43: =CA43 -> 0.3897151
A45: Interest Income | C45: 2.919 | D45: 6.585 | E45: 2.1 | F45: =4.392-E45 -> 2.292 | G45: =5.953-SUM(E45:F45) -> 1.561 | H45: =8.442-SUM(E45:G45) -> 2.489 | I45: =SUM(E45:H45) -> 8.442 | J45: 0.816 | K45: =1.617-J45 -> 0.801 | L45: =2.005-SUM(J45:K45) -> 0.388 | M45: =2.233-SUM(J45:L45) -> 0.228 | N45: =SUM(J45:M45) -> 2.233 | O45: 0.043 | P45: =0.092-O45 -> 0.049 | Q45: 0.029 | R45: =0.195-SUM(O45:Q45) -> 0.074 | S45: =SUM(O45:R45) -> 0.195 | T45: 0.032 | U45: 0.092 | V45: 0.059 | W45: 0.122 | X45: =SUM(T45:W45) -> 0.305 | Y45: =0.01 -> 0.01 | Z45: -0.01 | AA45: 0.099 | AB45: 0.102 | AC45: 0.1983039 | AD45: 0.105 | AE45: 0.156 | AF45: 0.136 | AG45: =0.46-SUM(AD45:AF45) -> 0.063 | AH45: 0.68582109 | AI45: 0.044 | AJ45: 0.04 | AK45: 0.225 | AL45: 0.399 | AM45: =SUM(AI45:AL45) -> 0.708 | AN45: 0.02 | AO45: 0.074 | AP45: -0.285 | AQ45: 0.234 | AR45: =SUM(AN45:AQ45) -> 0.043 | AS45: -0.538 | AT45: -0.221 | AU45: 0 | AV45: -0.15 | AW45: =SUM(AS45:AV45) -> -0.909 | AX45: 0.044 | AY45: 0 | AZ45: 2.124 | BA45: 3.1 | BB45: =SUM(AX45:BA45) -> 5.268 | BC45: 1.9 | BD45: 3.4 | BE45: 2.6 | BF45: 1.3 | BG45: =SUM(BC45:BF45) -> 9.2 | BH45: =BH418 -> 1.3017817 | BI45: =BI418 -> 3.3550708 | BJ45: =BJ418 -> 3.3433209 | BK45: =BK418 -> 3.1192168 | BL45: =SUM(BH45:BK45) -> 11.11939 | BM45: =BM418 -> 2.460664 | BN45: =BN418 -> 4.385865 | BO45: =BO418 -> 4.1285554 | BP45: =BP418 -> 3.6436801 | BQ45: =SUM(BM45:BP45) -> 14.618764 | BR45: =BR418 -> 2.7015058 | BS45: =BS418 -> 4.667696 | BT45: =BT418 -> 4.3287483 | BU45: =BU418 -> 3.7486581 | BV45: =SUM(BR45:BU45) -> 15.446608 | BW45: =BW418 -> 2.688251 | BX45: =BX418 -> 4.9085526 | BY45: =BY418 -> 4.6945346 | BZ45: =BZ418 -> 4.2258027 | CA45: =SUM(BW45:BZ45) -> 16.517141 | CD45: =A45 -> Interest Income | CE45: =D45 -> 6.585 | CF45: =I45 -> 8.442 | CG45: =N45 -> 2.233 | CH45: =S45 -> 0.195 | CI45: =X45 -> 0.305 | CJ45: =AC45 -> 0.1983039 | CK45: =AH45 -> 0.68582109 | CL45: =AM45 -> 0.708 | CM45: =AR45 -> 0.043 | CN45: =AW45 -> -0.909 | CO45: =BB45 -> 5.268 | CP45: =BG45 -> 9.2 | CQ45: =BL45 -> 11.11939 | CR45: =BQ45 -> 14.618764 | CS45: =BV45 -> 15.446608 | CT45: =CA45 -> 16.517141
A46: Interest (Expense) | C46: -10.265 | D46: -16.668 | E46: -5.773 | F46: =-11.474-E46 -> -5.701 | G46: =-17.052-SUM(E46:F46) -> -5.578 | H46: =-22.928-SUM(E46:G46) -> -5.876 | I46: =SUM(E46:H46) -> -22.928 | J46: -6.326 | K46: =-14.173-J46 -> -7.847 | L46: =-22.566-SUM(J46:K46) -> -8.393 | M46: =-31.316-SUM(J46:L46) -> -8.75 | N46: =SUM(J46:M46) -> -31.316 | O46: -8.154 | P46: =-16.677-O46 -> -8.523 | Q46: =-9.449 -> -9.449 | R46: =-35.265-SUM(O46:Q46) -> -9.139 | S46: =SUM(O46:R46) -> -35.265 | T46: -8.466 | U46: -8.445 | V46: -8.484 | W46: =-9.269 -> -9.269 | X46: =SUM(T46:W46) -> -34.664 | Y46: -9.615 | Z46: -14.885 | AA46: -14.593 | AB46: -14.754 | AC46: =SUM(Y46:AB46) -> -53.847 | AD46: -16.385 | AE46: -17.377 | AF46: -18.133 | AG46: =-72.508-SUM(AD46:AF46) -> -20.613 | AH46: =SUM(AD46:AG46) -> -72.508 | AI46: -20.09 | AJ46: -19.704 | AK46: -18.692 | AL46: -17.65 | AM46: =SUM(AI46:AL46) -> -76.136 | AN46: -17.439 | AO46: =-17.459 -> -17.459 | AP46: -17.498 | AQ46: -17.588 | AR46: =SUM(AN46:AQ46) -> -69.984 | AS46: -18.262 | AT46: -37.662 | AU46: -33.003 | AV46: -32.389 | AW46: =SUM(AS46:AV46) -> -121.316 | AX46: -32.032 | AY46: -31.435 | AZ46: -28.15 | BA46: -28.4 | BB46: =SUM(AX46:BA46) -> -120.017 | BC46: -28.4 | BD46: -28.5 | BE46: -30.3 | BF46: -32.1 | BG46: -119.22476 | BH46: -33.156838 | BI46: -33.156838 | BJ46: -33.156838 | BK46: -33.156838 | BL46: -132.62735 | BM46: -33.156838 | BN46: -33.156838 | BO46: -33.156838 | BP46: -33.156838 | BQ46: -132.62735 | BR46: -33.156838 | BS46: -33.156838 | BT46: -33.156838 | BU46: -33.156838 | BV46: -132.62735 | BW46: -33.156838 | BX46: -33.156838 | BY46: -33.156838 | BZ46: -33.156838 | CA46: -132.62735 | CD46: =A46 -> Interest (Expense) | CE46: =D46 -> -16.668 | CF46: =I46 -> -22.928 | CG46: =N46 -> -31.316 | CH46: =S46 -> -35.265 | CI46: =X46 -> -34.664 | CJ46: =AC46 -> -53.847 | CK46: =AH46 -> -72.508 | CL46: =AM46 -> -76.136 | CM46: =AR46 -> -69.984 | CN46: =AW46 -> -121.316 | CO46: =BB46 -> -120.017 | CP46: =BG46 -> -119.22476 | CQ46: =BL46 -> -132.62735 | CR46: =BQ46 -> -132.62735 | CS46: =BV46 -> -132.62735 | CT46: =CA46 -> -132.62735
A47: Other Income (Expense) | C47: =0.027-0.014 -> 0.013 | D47: =-0.375-0.109 -> -0.484 | E47: =-0.018+0.012 -> -0.006 | F47: =0.592-0.021-E47 -> 0.577 | G47: =0.854-0.119-SUM(E47:F47) -> 0.164 | H47: =0.857+0.009-SUM(E47:G47) -> 0.131 | I47: =SUM(E47:H47) -> 0.866 | J47: -1.274 | K47: =-1.286-0.014-J47 -> -0.026 | L47: =-1.665-0.021-SUM(J47:K47) -> -0.386 | M47: =-2.511-0.049-SUM(J47:L47) -> -0.874 | N47: =SUM(J47:M47) -> -2.56 | O47: -0.398 | P47: =-0.365-O47 -> 0.033 | Q47: =0.024 -> 0.024 | R47: =-2.332-SUM(O47:Q47) -> -1.991 | S47: =SUM(O47:R47) -> -2.332 | T47: 0.032 | U47: 0.029 | V47: 0.009 | W47: =0.025 -> 0.025 | X47: =SUM(T47:W47) -> 0.095 | Y47: 0.362 | Z47: 0.125 | AA47: -0.086 | AB47: 0.285 | AC47: =SUM(Y47:AB47) -> 0.686 | AD47: 0.33 | AE47: -0.03 | AF47: -0.638 | AG47: =-0.332-SUM(AD47:AF47) -> 0.006 | AH47: =SUM(AD47:AG47) -> -0.332 | AI47: -0.193 | AJ47: 0.093 | AK47: 0 | AL47: 0.007 | AM47: =SUM(AI47:AL47) -> -0.093 | AN47: -0.011 | AO47: 0.126 | AP47: 0 | AQ47: 0 | AR47: =SUM(AN47:AQ47) -> 0.115 | AS47: 0 | AT47: 85.187 | AU47: 17.912 | AV47: 0 | AW47: =SUM(AS47:AV47) -> 103.099 | AX47: 0 | AY47: 0.846 | AZ47: 0 | BA47: 0 | BB47: =SUM(AX47:BA47) -> 0.846 | BC47: 0 | BD47: 0 | BE47: 0 | BF47: 0 | BG47: =SUM(BC47:BF47) -> 0 | BH47: 0 | BI47: 0 | BJ47: 0 | BK47: 0 | BL47: =SUM(BH47:BK47) -> 0 | BM47: 0 | BN47: 0 | BO47: 0 | BP47: 0 | BQ47: =SUM(BM47:BP47) -> 0 | BR47: 0 | BS47: 0 | BT47: 0 | BU47: 0 | BV47: =SUM(BR47:BU47) -> 0 | BW47: 0 | BX47: 0 | BY47: 0 | BZ47: 0 | CA47: =SUM(BW47:BZ47) -> 0 | CD47: =A47 -> Other Income (Expense) | CE47: =D47 -> -0.484 | CF47: =I47 -> 0.866 | CG47: =N47 -> -2.56 | CH47: =S47 -> -2.332 | CI47: =X47 -> 0.095 | CJ47: =AC47 -> 0.686 | CK47: =AH47 -> -0.332 | CL47: =AM47 -> -0.093 | CM47: =AR47 -> 0.115 | CN47: =AW47 -> 103.099 | CO47: =BB47 -> 0.846 | CP47: =BG47 -> 0 | CQ47: =BL47 -> 0 | CR47: =BQ47 -> 0 | CS47: =BV47 -> 0 | CT47: =CA47 -> 0
C48: ______ | D48: ______ | E48: ______ | F48: ______ | G48: ______ | H48: ______ | I48: ______ | J48: ______ | K48: ______ | L48: ______ | M48: ______ | N48: ______ | O48: ______ | P48: ______ | Q48: ______ | R48: ______ | S48: ______ | T48: ______ | U48: ______ | V48: ______ | W48: ______ | X48: ______ | Y48: ______ | Z48: ______ | AA48: ______ | AB48: ______ | AC48: ______ | AD48: ______ | AE48: ______ | AF48: ______ | AG48: ______ | AH48: ______ | AI48: ______ | AJ48: ______ | AK48: ______ | AL48: ______ | AM48: ______ | AN48: ______ | AO48: ______ | AP48: ______ | AQ48: ______ | AR48: ______ | AS48: ______ | AT48: ______ | AU48: ______ | AV48: ______ | AW48: ______ | AX48: ______ | AY48: ______ | AZ48: ______ | BA48: ______ | BB48: ______ | BC48: ______ | BD48: ______ | BE48: ______ | BF48: ______ | BG48: ______ | BH48: ______ | BI48: ______ | BJ48: ______ | BK48: ______ | BL48: ______ | BM48: ______ | BN48: ______ | BO48: ______ | BP48: ______ | BQ48: ______ | BR48: ______ | BS48: ______ | BT48: ______ | BU48: ______ | BV48: ______ | BW48: ______ | BX48: ______ | BY48: ______ | BZ48: ______ | CA48: ______
A49: Pretax Income | C49: =C42+C45+C46+C47 -> 212.669 | D49: =D42+D45+D46+D47 -> 232.777 | E49: =E42+E45+E46+E47 -> 63.738 | F49: =F42+F45+F46+F47 -> 64.899 | G49: =G42+G45+G46+G47 -> 68.015 | H49: =H42+H45+H46+H47 -> 61.495 | I49: =I42+I45+I46+I47 -> 258.147 | J49: =J42+J45+J46+J47 -> 70.902 | ... AQ49: =AQ42+AQ45+AQ46+AQ47 -> 159.693 | AR49: =SUM(AN49:AQ49) -> 590.62 | AS49: =AS42+AS45+AS46+AS47 -> 159.492 | AT49: =AT42+AT45+AT46+AT47 -> 201.026 | AU49: =AU42+AU45+AU46+AU47 -> 193.789 | AV49: =AV42+AV45+AV46+AV47 -> 162.879 | AW49: =SUM(AS49:AV49) -> 717.186 | AX49: =AX42+AX45+AX46+AX47 -> 160.641 | AY49: =AY42+AY45+AY46+AY47 -> 160.49 | AZ49: =AZ42+AZ45+AZ46+AZ47 -> 172.396 | BA49: =BA42+BA45+BA46+BA47 -> 160.2 | BB49: =SUM(AX49:BA49) -> 653.727 | BC49: =BC42+BC45+BC46+BC47 -> 161.2 | BD49: =BD42+BD45+BD46+BD47 -> 169.9 | BE49: =BE42+BE45+BE46+BE47 -> 180.7 | BF49: =BF42+BF45+BF46+BF47 -> 179.3 | BG49: =SUM(BC49:BF49) -> 691.1 | BH49: =BH42+BH45+BH46+BH47 -> 165.92621 | BI49: =BI42+BI45+BI46+BI47 -> 175.05972 | BJ49: =BJ42+BJ45+BJ46+BJ47 -> 192.28875 | BK49: =BK42+BK45+BK46+BK47 -> 191.93208 | BL49: =SUM(BH49:BK49) -> 725.20676 | BM49: =BM42+BM45+BM46+BM47 -> 184.19136 | BN49: =BN42+BN45+BN46+BN47 -> 193.84933 | BO49: =BO42+BO45+BO46+BO47 -> 211.99341 | BP49: =BP42+BP45+BP46+BP47 -> 211.66537 | BQ49: =SUM(BM49:BP49) -> 801.69946 | BR49: =BR42+BR45+BR46+BR47 -> 202.78071 | BS49: =BS42+BS45+BS46+BS47 -> 212.96566 | BT49: =BT42+BT45+BT46+BT47 -> 232.20278 | BU49: =BU42+BU45+BU46+BU47 -> 231.84382 | BV49: =SUM(BR49:BU49) -> 879.79297 | BW49: =BW42+BW45+BW46+BW47 -> 223.76869 | BX49: =BX42+BX45+BX46+BX47 -> 234.71948 | BY49: =BY42+BY45+BY46+BY47 -> 255.32998 | BZ49: =BZ42+BZ45+BZ46+BZ47 -> 255.14897 | CA49: =SUM(BW49:BZ49) -> 968.96713 | CD49: =A49 -> Pretax Income | CE49: =D49 -> 232.777 | CF49: =I49 -> 258.147 | CG49: =N49 -> 278.899 | CH49: =S49 -> 264.605 | CI49: =X49 -> 406.65 | CJ49: =AC49 -> 457.0543 | CK49: =AH49 -> 519.43382 | CL49: =AM49 -> 538.758 | CM49: =AR49 -> 590.62 | CN49: =AW49 -> 717.186 | CO49: =BB49 -> 653.727 | CP49: =BG49 -> 691.1 | CQ49: =BL49 -> 725.20676 | CR49: =BQ49 -> 801.69946 | CS49: =BV49 -> 879.79297 | CT49: =CA49 -> 968.96713
A50: Income Tax Benefit (Expense)- Reported | C50: -85.722 | D50: -91.992 | E50: -24.867 | F50: =-52.432-E50 -> -27.565 | G50: =-81.273-SUM(E50:F50) -> -28.841 | H50: =-103.184-SUM(E50:G50) -> -21.911 | I50: =SUM(E50:H50) -> -103.184 | J50: -29.876 | K50: =-61.818-J50 -> -31.942 | L50: =-90.311-SUM(J50:K50) -> -28.493 | M50: =-120.671-SUM(J50:L50) -> -30.36 | N50: =SUM(J50:M50) -> -120.671 | O50: -33.779 | P50: =-67.25-O50 -> -33.471 | Q50: -33.194 | R50: =-137.991-SUM(O50:Q50) -> -37.547 | S50: =SUM(O50:R50) -> -137.991 | T50: -42.637 | U50: -40.347 | V50: -42.422 | W50: -38.692 | X50: =SUM(T50:W50) -> -164.098 | Y50: -44.178 | Z50: -43.471 | AA50: -45.842 | AB50: -44.172 | AC50: =SUM(Y50:AB50) -> -177.663 | AD50: -48.41 | AE50: -47.82 | AF50: -53.705 | AG50: =-190.066-SUM(AD50:AF50) -> -40.131 | AH50: =SUM(AD50:AG50) -> -190.066 | AI50: -45.844 | AJ50: -45.68 | AK50: -53.474 | AL50: -51.428 | AM50: =SUM(AI50:AL50) -> -196.426 | AN50: -46.972 | AO50: -53.708 | AP50: =-AP49*AP380 -> -58.692 | AQ50: -60.383 | AR50: =SUM(AN50:AQ50) -> -219.755 | AS50: =-AS49*AS380 -> -60.806 | AT50: -37.706 | AU50: -61.975 | AV50: -49.372 | AW50: =SUM(AS50:AV50) -> -209.859 | AX50: -50.911 | AY50: -53.754 | AZ50: -44.819 | BA50: -52.7 | BB50: =SUM(AX50:BA50) -> -202.184 | BC50: -52.4 | BD50: -48.9 | BE50: -60 | BF50: 25.3 | BG50: =SUM(BC50:BF50) -> -136 | BH50: =-BH49*BH380 -> -36.503767 | BI50: =-BI49*BI380 -> -38.513138 | BJ50: =-BJ49*BJ380 -> -42.303526 | BK50: =-BK49*BK380 -> -42.225057 | BL50: =SUM(BH50:BK50) -> -159.54549 | BM50: =-BM49*BM380 -> -40.522099 | BN50: =-BN49*BN380 -> -42.646853 | BO50: =-BO49*BO380 -> -46.63855 | BP50: =-BP49*BP380 -> -46.566381 | BQ50: =SUM(BM50:BP50) -> -176.37388 | BR50: =-BR49*BR380 -> -44.611756 | BS50: =-BS49*BS380 -> -46.852446 | BT50: =-BT49*BT380 -> -51.084611 | BU50: =-BU49*BU380 -> -51.00564 | BV50: =SUM(BR50:BU50) -> -193.55445 | BW50: =-BW49*BW380 -> -49.229111 | BX50: =-BX49*BX380 -> -51.638285 | BY50: =-BY49*BY380 -> -56.172597 | BZ50: =-BZ49*BZ380 -> -56.132774 | CA50: =SUM(BW50:BZ50) -> -213.17277
A51: Income Tax Benefit (Expense)- Extraordinary income (expenses) | C51: 0 | D51: 0 | E51: 0 | F51: =0-E51 -> 0 | G51: 0 | H51: =0-SUM(E51:G51) -> 0 | I51: =SUM(E51:H51) -> 0 | J51: 0 | K51: =0-J51 -> 0 | L51: 0 | M51: =0-SUM(J51:L51) -> 0 | N51: =SUM(J51:M51) -> 0 | O51: 0 | P51: 0 | Q51: 0 | R51: 0 | S51: =SUM(O51:R51) -> 0 | T51: 0 | U51: 0 | V51: 0 | W51: 0 | X51: =SUM(T51:W51) -> 0 | Y51: 0 | Z51: 0 | AA51: 0 | AB51: 0 | AC51: =SUM(Y51:AB51) -> 0 | AD51: 0 | AE51: 0 | AF51: 0 | AG51: 0 | AH51: =SUM(AD51:AG51) -> 0 | AI51: 0 | AJ51: 0 | AK51: 0 | AL51: 0 | AM51: =SUM(AI51:AL51) -> 0 | AN51: 0 | AO51: 0 | AP51: 0 | AQ51: 0 | AR51: =SUM(AN51:AQ51) -> 0 | AS51: 0 | AT51: 0 | AU51: 0 | AV51: 0 | AW51: =SUM(AS51:AV51) -> 0 | AX51: 0 | AY51: 0 | AZ51: 0 | BA51: 0 | BB51: =SUM(AX51:BA51) -> 0 | BC51: 0 | BD51: 0 | BE51: 0 | BF51: 0 | BG51: =SUM(BC51:BF51) -> 0 | BH51: 0 | BI51: 0 | BJ51: 0 | BK51: 0 | BL51: =SUM(BH51:BK51) -> 0 | BM51: 0 | BN51: 0 | BO51: 0 | BP51: 0 | BQ51: =SUM(BM51:BP51) -> 0 | BR51: 0 | BS51: 0 | BT51: 0 | BU51: 0 | BV51: =SUM(BR51:BU51) -> 0 | BW51: 0 | BX51: 0 | BY51: 0 | BZ51: 0 | CA51: =SUM(BW51:BZ51) -> 0
