Workbook
Name AdditionalInstructions: IndexInformation!$B$42
Name Address: ImportantDisclosures!$A$2:$A$2
Name ANA: ModPubIndex!$A$7
Name Authors: ImportantDisclosures!$A$7
Name Authors: IndexInformation!$B$18
Name BRO: ModPubIndex!$A$1
Name CopyrightStamp: ImportantDisclosures!$A$27
Name COU: ModPubIndex!$A$5
Name CQEnd: IndexInformation!$B$31
Name Currency: IndexInformation!$B$24
Name CurrentStockPrice: IndexInformation!$B$23
Name CurrQtrEPS: IndexInformation!$B$29
Name CurrYearEPS: IndexInformation!$B$11
Name CurrYearTotalRevenue: IndexInformation!$B$10
Name CurrYearTotalRevenueActual: IndexInformation!$B$32
Name CUSIP: IndexInformation!$B$20
Name CYEnd: IndexInformation!$B$30
Name Date: ImportantDisclosures!$A$8
Name Deleted: IndexInformation!$B$27
Name Description: IndexInformation!$B$7
Name Discipline: IndexInformation!$B$3
Name DISCIPLINE: ModPubIndex!$A$12
Name DisclosuresText: ImportantDisclosures!$A$22
Name Distribution: IndexInformation!$B$26
Name DistTable: ImportantDisclosures!#REF!
Name DistTablePreamble: ImportantDisclosures!#REF!
Name DOCDAT: ModPubIndex!$A$2
Name DOCTIME: ModPubIndex!$A$3
Name DocType: IndexInformation!$B$5
Name EMAIL_ALERT: ModPubIndex!$A$10
Name EmailAlert: IndexInformation!$B$28
Name FiveYearGrowthRate: IndexInformation!$B$16
Name FollowingYearEPS: IndexInformation!$B$15
Name FollowingYearTotalRevenue: IndexInformation!$B$14
Name FollowingYearTotalRevenueActual: IndexInformation!$B$34
Name HL: ModPubIndex!$A$8
Name IND: ModPubIndex!$A$9
Name Industry: ImportantDisclosures!$A$12
Name IndustryId: IndexInformation!$B$40
Name IndustryRating: ImportantDisclosures!$A$13
Name KeepVersions: IndexInformation!$B$8
Name LanguageCode: IndexInformation!$B$38
Name LastCell: ImportantDisclosures!$A$22
Name MacroVersion: IndexInformation!$B$1
Name ModelPrice: ImportantDisclosures!$A$14
Name Multiplier: IndexInformation!$B$35
Name NextYearEPS: IndexInformation!$B$13
Name NextYearTotalRevenue: IndexInformation!$B$12
Name NextYearTotalRevenueActual: IndexInformation!$B$33
Name NUEestimates: Estimates!$B$3:$V$36
Name NUESummary: Summary!$B$5:$P$60
Name NUEvariance: Variance!$B$2:$K$30
Name ObjectType: IndexInformation!$B$37
Name PANA: ModPubIndex!$A$11
Name PathName: IndexInformation!$B$25
Name PRODUCT: ModPubIndex!$A$6
Name PSYM: ModPubIndex!$A$4
Name PublishDate: IndexInformation!$B$2
Name Rating: IndexInformation!$B$9
Name RatingsDefined: ImportantDisclosures!$A$21

Sheet ImportantDisclosures
A2: 1585 Broadway
A3: New York, NY 10036-8293
A4: United States
A5: Tel: +1 (1)212 761 4000
A7: Authors: Piyush Sood, Lynn Bernabei, Serena Rocha Calejon
A8: Date: 24 Apr 2018
A10: Ticker: NUE.N
A11: Stock Rating: Equal-Weight
A12: Industry: Steel
A13: Industry View: In-Line
A14: Price as of 24 Apr 2018: 62.88
A15: Target Price: 73
... A116: Equal-weight and Not-Rated to hold and Underweight to sell recommendations, respectively.
B118: Coverage Universe | D118: Investment Banking Clients (IBC) | G118: Other Material Investment Services Clients (MISC)
A119: Stock Rating Category | B119: Count | C119: % of Total | D119: Count | E119: % of Total IBC | F119: % of Rating Category | G119: Count | H119: % of Total Other MISC
A120: Overweight/Buy | B120: 1189 | C120: 0.38 | D120: 315 | E120: 0.41 | F120: 0.26 | G120: 555 | H120: 0.39
A121: Equal-weight/Hold | B121: 1355 | C121: 0.43 | D121: 364 | E121: 0.47 | F121: 0.27 | G121: 644 | H121: 0.45
A122: Not-Rated/Hold | B122: 53 | C122: 0.02 | D122: 4 | E122: 0.01 | F122: 0.08 | G122: 7 | H122: 0
A123: Underweight/Sell | B123: 545 | C123: 0.17 | D123: 84 | E123: 0.11 | F123: 0.15 | G123: 214 | H123: 0.15
A124: Total | B124: 3142 | D124: 767 | G124: 1420
A126: Data include common stock and ADRs currently assigned ratings. Investment Banking Clients are companies
A127: from whom Morgan Stanley received investment banking compensation in the last 12 months. Due to rounding
A128: off of decimals, the percentages provided in the "% of total" column may not add up to exactly 100
A129: percent.
A131: Analyst Stock Ratings
A133: Overweight (O). The stock's total return is expected to exceed the average total return of the analyst's
A134: industry (or industry team's) coverage universe, on a risk-adjusted basis, over the next 12-18 months.
A136: Equal-weight (E). The stock's total return is expected to be in line with the average total return of
A137: the analyst's industry (or industry team's) coverage universe, on a risk-adjusted basis, over the next
A138: 12-18 months.
A140: Not-Rated (NR). Currently the analyst does not have adequate conviction about the stock's total return
A141: relative to the average total return of the analyst's industry (or industry team's) coverage universe,
... A387: © Copyright 2018 Morgan Stanley

Sheet Summary
B2: Nucor Corporation
B3: Summary Information
B5: Key Assumptions | J5: Income Statement
B6: Year End December | C6: 2014 | D6: 2015 | E6: 2016 | F6: 2017 | G6: 2018E | H6: 2019E | J6: Year End December (US$M) | K6: =C6 -> 2014 | L6: =D6 -> 2015 | M6: =E6 -> 2016 | N6: =F6 -> 2017 | O6: =G6 -> 2018E | P6: =H6 -> 2019E
B7: Realizations, $/t | J7: Sales | K7: =Financials!$BV$15 -> 21105.141 | L7: =Financials!$CA$15 -> 16439.276 | M7: =Financials!$CF$15 -> 16208.122 | N7: =Financials!$CK$15 -> 20252.393 | O7: =Financials!$CP$15 -> 25483.944 | P7: =Financials!$CU$15 -> 26897.497
B8: Sheet | C8: =Operations!BV18 -> 735.75 | D8: =Operations!CA18 -> 570.75 | E8: =Operations!CF18 -> 572.5 | F8: =Operations!CK18 -> 689 | G8: =Operations!CP18 -> 845.78828 | H8: =Operations!CU18 -> 852.72645 | J8: Cash COGS | K8: =Financials!$BV$19 -> 18439.187 | L8: =Financials!$CA$19 -> 14152.668 | M8: =Financials!$CF$19 -> 13596.941 | N8: =Financials!$CK$19 -> 16917.664 | O8: =Financials!$CP$19 -> 21176.541 | P8: =Financials!$CU$19 -> 22695.771
B9: Tubular | C9: NA | D9: NA | E9: NA | F9: =Operations!CK158 -> 1000 | G9: =Operations!CP158 -> 0 | H9: =Operations!CU158 -> 0 | J9: D&A | K9: =Financials!$BV$21 -> 724.423 | L9: =Financials!$CA$21 -> 700.017 | M9: =Financials!$CF$21 -> 687.054 | N9: =Financials!$CK$21 -> 727.061 | O9: =Financials!$CP$21 -> 696 | P9: =Financials!$CU$21 -> 696
B10: Bars | C10: =Operations!BV19 -> 732.75 | D10: =Operations!CA19 -> 626 | E10: =Operations!CF19 -> 544.25 | F10: =Operations!CK19 -> 609 | G10: =Operations!CP19 -> 728.47678 | H10: =Operations!CU19 -> 736.47568 | J10: SG&A | K10: =Financials!$BV$28 -> 546.198 | L10: =Financials!$CA$28 -> 466.689 | M10: =Financials!$CF$28 -> 596.761 | N10: =Financials!$CK$28 -> 667.281 | O10: =Financials!$CP$28 -> 700.76365 | P10: =Financials!$CU$28 -> 699.33493
B11: Structural | C11: =Operations!BV20 -> 1025.25 | D11: =Operations!CA20 -> 959 | E11: =Operations!CF20 -> 854.25 | F11: =Operations!CK20 -> 759.25 | G11: =Operations!CP20 -> 876.66975 | H11: =Operations!CU20 -> 968.52453 | J11: EBITDA | K11: =Financials!$BV$97 -> 2119.756 | L11: =Financials!$CA$97 -> 1819.919 | M11: =Financials!$CF$97 -> 2014.42 | N11: =Financials!$CK$97 -> 2667.448 | O11: =Financials!$CP$97 -> 3606.6397 | P11: =Financials!$CU$97 -> 3502.3915
B12: Plate | C12: =Operations!BV21 -> 847.75 | D12: =Operations!CA21 -> 683 | E12: =Operations!CF21 -> 598.5 | F12: =Operations!CK21 -> 731.25 | G12: =Operations!CP21 -> 886.91192 | H12: =Operations!CU21 -> 916.72144 | J12: EBIT | K12: =Financials!$BV$31 -> 1395.333 | L12: =Financials!$CA$31 -> 1119.902 | M12: =Financials!$CF$31 -> 1327.366 | N12: =Financials!$CK$31 -> 1940.387 | O12: =Financials!$CP$31 -> 2910.6397 | P12: =Financials!$CU$31 -> 2806.3915
B13: Shipments, kt | J13: Pre-Tax Income | K13: =Financials!$BV$48 -> 1226.077 | L13: =Financials!$CA$48 -> 946.371 | M13: =Financials!$CF$48 -> 1158.122 | N13: =Financials!$CK$48 -> 1766.807 | O13: =Financials!$CP$48 -> 2747.0596 | P13: =Financials!$CU$48 -> 2650.1684
B14: Sheet | C14: =Operations!BV33 -> 8153 | D14: =Operations!CA33 -> 8080 | E14: =Operations!CF33 -> 9118 | F14: =Operations!CK33 -> 9311 | G14: =Operations!CP33 -> 9320.2 | H14: =Operations!CU33 -> 9506.604 | J14: Tax | K14: =Financials!$BV$51 -> 383.537 | L14: =Financials!$CA$51 -> 243.547 | M14: =Financials!$CF$51 -> 348.796 | N14: =Financials!$CK$51 -> 554.224 | O14: =Financials!$CP$51 -> 666.04343 | P14: =Financials!$CU$51 -> 636.04042
B15: Tubular | C15: NA | D15: NA | E15: NA | F15: =Operations!CK124 -> 917 | G15: =Operations!CP124 -> 1082.1 | H15: =Operations!CU124 -> 1103.742 | J15: Minority Interest | K15: =Financials!$BV$47 -> 0 | L15: =Financials!$CA$47 -> 0 | M15: =Financials!$CF$47 -> 0 | N15: =Financials!$CK$47 -> 0 | O15: =Financials!$CP$47 -> 0 | P15: =Financials!$CU$47 -> 0
B16: Bars | C16: =Operations!BV34+Operations!BV35 -> 5526 | D16: =Operations!CA34+Operations!CA35 -> 4790 | E16: =Operations!CF34+Operations!CF35 -> 5304 | F16: =Operations!CK34+Operations!CK35 -> 5838 | G16: =Operations!CP34+Operations!CP35 -> 6214.96 | H16: =Operations!CU34+Operations!CU35 -> 6307.2592 | J16: Adj. Net Income | K16: =Financials!$BV$57 -> 740.696 | L16: =Financials!$CA$57 -> 564.399 | M16: =Financials!$CF$57 -> 711.061 | N16: =Financials!$CK$57 -> 1150.7 | O16: =Financials!$CP$57 -> 1985.0832 | P16: =Financials!$CU$57 -> 1926.128
B17: Structural | C17: =Operations!BV36 -> 2560 | D17: =Operations!CA36 -> 2231 | E17: =Operations!CF36 -> 2319 | F17: =Operations!CK36 -> 1739 | G17: =Operations!CP36 -> 1754.66 | H17: =Operations!CU36 -> 1789.7532 | J17: Adj. EPS | K17: =Financials!$BV$60 -> 2.3137079 | L17: =Financials!$CA$60 -> 1.7599273 | M17: =Financials!$CF$60 -> 2.2233023 | N17: =Financials!$CK$60 -> 3.587244 | O17: =Financials!$CP$60 -> 6.2160938 | P17: =Financials!$CU$60 -> 6.0385929
B18: Plate | C18: =Operations!BV37 -> 2442 | D18: =Operations!CA37 -> 1905 | E18: =Operations!CF37 -> 2023 | F18: =Operations!CK37 -> 2249 | G18: =Operations!CP37 -> 2281.58 | H18: =Operations!CU37 -> 2327.2116 | J18: Reported EPS | K18: =Financials!$BV$92 -> 2.2301491 | L18: =Financials!$CA$92 -> 1.1152639 | M18: =Financials!$CF$92 -> 2.2956551 | N18: =Financials!$CK$92 -> 4.1534905 | O18: =Financials!$CP$92 -> 6.1478293 | P18: =Financials!$CU$92 -> 6.0385929
B19: Fabrication Productions | C19: =Operations!$BV$126 -> 6732 | D19: =Operations!$CA$126 -> 5674 | E19: =Operations!$CF$126 -> 5545 | F19: =Operations!$CK$126 -> 7355 | G19: =Operations!$CP$126 -> 7843.11 | H19: =Operations!$CU$126 -> 8034.7552
B20: Capacity Utilization | C20: =Operations!$BV$63 -> 0.77247807 | D20: =Operations!$CA$63 -> 0.66969802 | E20: =Operations!$CF$63 -> 0.79707865 | F20: =Operations!$CK$63 -> 0.88873708 | G20: =Operations!$CP$63 -> 0.8793329 | H20: =Operations!$CU$63 -> 0.89548182 | J20: Balance Sheet
J21: =+$J$6 -> Year End December (US$M) | K21: =+K6 -> 2014 | L21: =+L6 -> 2015 | M21: =+M6 -> 2016 | N21: =+N6 -> 2017 | O21: =+O6 -> 2018E | P21: =+P6 -> 2019E
B22: Segment EBIT | J22: Cash and Equivalents | K22: =Financials!$BV$113 -> 1024.144 | L22: =Financials!$CA$113 -> 1939.469 | M22: =Financials!$CF$113 -> 2045.961 | N22: =Financials!$CK$113 -> 949.104 | O22: =Financials!$CP$113 -> 1674.7993 | P22: =Financials!$CU$113 -> 3033.9736
B23: =+J6 -> Year End December (US$M) | C23: =+C6 -> 2014 | D23: =+D6 -> 2015 | E23: =+E6 -> 2016 | F23: =+F6 -> 2017 | G23: =+G6 -> 2018E | H23: =+H6 -> 2019E | J23: Receivables | K23: =Financials!BV115 -> 2068.298 | L23: =Financials!CA115 -> 1383.823 | M23: =Financials!CF115 -> 1631.676 | N23: =Financials!CK115 -> 2028.545 | O23: =Financials!CP115 -> 2621.148 | P23: =Financials!CU115 -> 2558.1728
B24: Steel | C24: =Financials!BV35 -> 1615.852 | D24: =Financials!CA35 -> 782.256 | E24: =Financials!CF35 -> 1688.568 | F24: =Financials!CK35 -> 1939.225 | G24: =Financials!CP35 -> 3058.31 | H24: =Financials!CU35 -> 2955.6011 | J24: Inventories | K24: =Financials!BV116 -> 2745.032 | L24: =Financials!CA116 -> 2145.444 | M24: =Financials!CF116 -> 2479.958 | N24: =Financials!CK116 -> 3461.686 | O24: =Financials!CP116 -> 4302.2041 | P24: =Financials!CU116 -> 4321.1195
B25: Steel Products | C25: =Financials!BV36 -> 166.323 | D25: =Financials!CA36 -> 276.048 | E25: =Financials!CF36 -> 249.97 | F25: =Financials!CK36 -> 351.802 | G25: =Financials!CP36 -> 372.13675 | H25: =Financials!CU36 -> 326.93932 | J25: Other Current Assets | K25: =K29-SUM(K26:K28,K22:K24) -> 604.414 | L25: =L29-SUM(L26:L28,L22:L24) -> 285.644 | M25: =M29-SUM(M26:M28,M22:M24) -> 348.798 | N25: =N29-SUM(N26:N28,N22:N24) -> 385.085 | O25: =O29-SUM(O26:O28,O22:O24) -> 238.701 | P25: =P29-SUM(P26:P28,P22:P24) -> 238.701
B26: Raw Materials | C26: =Financials!BV37 -> -29.053 | D26: =Financials!CA37 -> -199.805 | E26: =Financials!CF37 -> -95.121 | F26: =Financials!CK37 -> 129.296 | G26: =Financials!CP37 -> 213.2156 | H26: =Financials!CU37 -> 218.4173 | J26: Goodwill and Intangibles | K26: =Financials!BV122+Financials!BV123 -> 2930.757 | L26: =Financials!CA122+Financials!CA123 -> 2781.95 | M26: =Financials!CF122+Financials!CF123 -> 2919.563 | N26: =Financials!CK122+Financials!CK123 -> 3110.704 | O26: =Financials!CP122+Financials!CP123 -> 3087.686 | P26: =Financials!CU122+Financials!CU123 -> 3087.686
B27: Others | C27: =Financials!BV38+Financials!BV39 -> -357.789 | D27: =Financials!CA38+Financials!CA39 -> 261.403 | E27: =Financials!CF38+Financials!CF39 -> -516.051 | F27: =Financials!CK38+Financials!CK39 -> -479.936 | G27: =Financials!CP38+Financials!CP39 -> -733.02264 | H27: =Financials!CU38+Financials!CU39 -> -694.56626 | J27: Net PP&E | K27: =Financials!$BV$121 -> 5287.639 | L27: =Financials!$CA$121 -> 4891.153 | M27: =Financials!$CF$121 -> 5078.65 | N27: =Financials!$CK$121 -> 5093.147 | O27: =Financials!$CP$121 -> 5318.89 | P27: =Financials!$CU$121 -> 5487.89
J28: Other Long Term Assets | K28: =Financials!$BV$124 -> 955.643 | L28: =Financials!$CA$124 -> 822.916 | M28: =Financials!$CF$124 -> 718.912 | N28: =Financials!$CK$124 -> 812.987 | O28: =Financials!$CP$124 -> 1020.3063 | P28: =Financials!$CU$124 -> 995.7926
B29: Quarterly Data | J29: Total Assets | K29: =Financials!$BV$126 -> 15615.927 | L29: =Financials!$CA$126 -> 14250.399 | M29: =Financials!$CF$126 -> 15223.518 | N29: =Financials!$CK$126 -> 15841.258 | O29: =Financials!$CP$126 -> 18263.735 | P29: =Financials!$CU$126 -> 19723.335
B30: =+B6 -> Year End December | C30: =ROUNDUP(MONTH(C62)/3,0)&"Q"&YEAR(C62)-2000 -> 3Q17 | D30: =ROUNDUP(MONTH(D62)/3,0)&"Q"&YEAR(D62)-2000 -> 4Q17 | E30: =ROUNDUP(MONTH(E62)/3,0)&"Q"&YEAR(E62)-2000 -> 1Q18 | F30: =ROUNDUP(MONTH(F62)/3,0)&"Q"&YEAR(F62)-2000&"e" -> 2Q18e | G30: =ROUNDUP(MONTH(G62)/3,0)&"Q"&YEAR(G62)-2000&"e" -> 3Q18e | H30: =ROUNDUP(MONTH(H62)/3,0)&"Q"&YEAR(H62)-2000&"e" -> 4Q18e
B31: Quarterly Operating Data | J31: Short Term Debt | K31: =Financials!$BV$130 -> 223.811 | L31: =Financials!$CA$130 -> 51.315 | M31: =Financials!$CF$130 -> 617.959 | N31: =Financials!$CK$130 -> 552.833 | O31: =Financials!$CP$130 -> 0 | P31: =Financials!$CU$130 -> 0
B32: Sheet Realization | C32: =Operations!CI18 -> 695 | D32: =Operations!CJ18 -> 691 | E32: =Operations!CL18 -> 723 | F32: =Operations!CM18 -> 870.25 | G32: =Operations!CN18 -> 907.1875 | H32: =Operations!CO18 -> 882.71562 | J32: Long Term Debt | K32: =Financials!$BV$136 -> 4360.6 | L32: =Financials!$CA$136 -> 4360.6 | M32: =Financials!$CF$136 -> 3739.141 | N32: =Financials!$CK$136 -> 3242.242 | O32: =Financials!$CP$136 -> 4360.6 | P32: =Financials!$CU$136 -> 4360.6
B33: Steel Shipments | C33: =Operations!CI38 -> 4698 | D33: =Operations!CJ38 -> 4629 | E33: =Operations!CL38 -> 5016 | F33: =Operations!CM38 -> 5047.48 | G33: =Operations!CN38 -> 4789.21 | H33: =Operations!CO38 -> 4718.71 | J33: Payables | K33: =Financials!$BV$129 -> 993.872 | L33: =Financials!$CA$129 -> 566.527 | M33: =Financials!$CF$129 -> 838.109 | N33: =Financials!$CK$129 -> 1181.346 | O33: =Financials!$CP$129 -> 1468.1839 | P33: =Financials!$CU$129 -> 1474.639
B34: Capacity Utilization | C34: =Operations!CI63 -> 0.87942355 | D34: =Operations!CJ63 -> 0.86430288 | E34: =Operations!CL63 -> 0.91398552 | F34: =Operations!CM63 -> 0.90961478 | G34: =Operations!CN63 -> 0.85369031 | H34: =Operations!CO63 -> 0.84112348 | J34: Other Current Liabilities | K34: =Financials!$BV$134-SUM(K33,K31) -> 880.093 | L34: =Financials!$CA$134-L31-L33 -> 767.331 | M34: =Financials!$CF$134-M33-M31 -> 933.898 | N34: =Financials!$CK$134-N33-N31 -> 1090.585 | O34: =Financials!$CP$134-O33-O31 -> 1111.5172 | P34: =Financials!$CU$134-P33-P31 -> 1084.8121
B35: Quarterly Financial Data | J35: Other Long Term Liabilities | K35: =K38-SUM(K36:K37)-SUM(K31:K34) -> 1082.433 | L35: =L38-SUM(L36:L37)-SUM(L31:L34) -> 718.613 | M35: =M38-SUM(M36:M37)-SUM(M31:M34) -> 839.703 | N35: =N38-SUM(N36:N37)-SUM(N31:N34) -> 689.464 | O35: =O38-SUM(O36:O37)-SUM(O31:O34) -> 710.881 | P35: =P38-SUM(P36:P37)-SUM(P31:P34) -> 710.881
B36: Sales | C36: =Financials!CI15 -> 5170.117 | D36: =Financials!CJ15 -> 5092.328 | E36: =Financials!CL15 -> 5568.419 | F36: =Financials!CM15 -> 6597.9083 | G36: =Financials!CN15 -> 6737.6567 | H36: =Financials!CO15 -> 6579.9601 | J36: Minority Interest | K36: =Financials!$BV$147 -> 302.648 | L36: =Financials!$CA$147 -> 369.135 | M36: =Financials!$CF$147 -> 374.843 | N36: =Financials!$CK$147 -> 345.752 | O36: =Financials!$CP$147 -> 387.462 | P36: =Financials!$CU$147 -> 421.239
B37: EBITDA | C37: =Financials!CI97 -> 600.46 | D37: =Financials!CJ97 -> 548.171 | E37: =Financials!CL97 -> 748.826 | F37: =Financials!CM97 -> 962.59615 | G37: =Financials!CN97 -> 979.40743 | H37: =Financials!CO97 -> 915.8101 | J37: Shareholders' Equity | K37: =Financials!$BV$149-K36 -> 7772.47 | L37: =Financials!$CA$149-L36 -> 7416.878 | M37: =Financials!$CF$149-M36 -> 7879.865 | N37: =Financials!$CK$149-N36 -> 8739.036 | O37: =Financials!$CP$149-O36 -> 10225.091 | P37: =Financials!$CU$149-P36 -> 11671.164
B38: EBIT | C38: =Financials!CI31 -> 420.965 | D38: =Financials!CJ31 -> 364.326 | E38: =Financials!CL31 -> 574.826 | F38: =Financials!CM31 -> 788.59615 | G38: =Financials!CN31 -> 805.40743 | H38: =Financials!CO31 -> 741.8101 | J38: Liabilities & Equity | K38: =K29 -> 15615.927 | L38: =L29 -> 14250.399 | M38: =M29 -> 15223.518 | N38: =N29 -> 15841.258 | O38: =O29 -> 18263.735 | P38: =P29 -> 19723.335
B39: Adj. EPS | C39: =Financials!CI60 -> 0.79591474 | D39: =Financials!CJ60 -> 0.65222664 | E39: =Financials!CL60 -> 1.1731966 | F39: =Financials!CM60 -> 1.6981154 | G39: =Financials!CN60 -> 1.7468192 | H39: =Financials!CO60 -> 1.5997587
B40: Reported EPS | C40: =Financials!CI92 -> 0.83706662 | D40: =Financials!CJ92 -> 1.1997831 | E40: =Financials!CL92 -> 1.1051723 | F40: =Financials!CM92 -> 1.6981154 | G40: =Financials!CN92 -> 1.7468192 | H40: =Financials!CO92 -> 1.5997587 | J40: Cash flow Statement
J41: =+$J$6 -> Year End December (US$M) | K41: =+K21 -> 2014 | L41: =+L21 -> 2015 | M41: =+M21 -> 2016 | N41: =+N21 -> 2017 | O41: =+O21 -> 2018E | P41: =+P21 -> 2019E
B42: Important Ratios | J42: Net Income | K42: =Financials!$BV$192 -> 815.79 | L42: =Financials!$CA$192 -> 496.084 | M42: =Financials!$CF$192 -> 832.466 | N42: =Financials!$CK$192 -> 1394.221 | O42: =Financials!$CP$192 -> 2059.2162 | P42: =Financials!$CU$192 -> 2014.128
...

Sheet Operations
A2: Nucor Corporation
A3: Operating Drivers | AN3: 39508 | AO3: 39600 | AP3: 39692 | AQ3: 39783 | AS3: 39873 | AT3: 39965 | AU3: 40057 | AV3: 40148 | AW3: FY9 | AX3: 40238 | AY3: 40330 | AZ3: 40422 | BA3: 40513 | BB3: FY10 | BC3: 40603 | BD3: 40695 | BE3: 40787 | BF3: 40878 | BG3: FY11 | BH3: 40969 | BI3: 41061 | BJ3: 41153 | BK3: 41244 | BL3: FY12 | BM3: 41334 | BN3: 41426 | BO3: 41518 | BP3: 41609 | BQ3: FY13 | BR3: 41699 | BS3: 41791 | BT3: 41883 | BU3: 41974 | BV3: FY14 | BW3: 42064 | BX3: 42156 | BY3: 42248 | BZ3: 42339 | CA3: FY15 | CB3: 42430 | CC3: 42522 | CD3: 42614 | CE3: 42705 | CF3: FY16 | CG3: 42795 | CH3: 42887 | CI3: 42979 | CJ3: 43070 | CK3: FY17 | CL3: 43160 | CM3: 43252 | CN3: 43344 | CO3: 43435 | CP3: FY18 | CQ3: 43525 | CR3: 43617 | CS3: 43709 | CT3: 43800 | CU3: FY19 | CV3: 43891 | CW3: 43983 | CX3: 44075 | CY3: 44166 | CZ3: FY20
E4: 1997 | F4: 1998 | G4: 1999 | H4: 2000 | I4: 2001 | J4: 1Q | K4: 2Q | L4: 3Q | M4: 4Q | N4: 2002 | O4: 1Q | P4: 2Q | Q4: 3Q | R4: 4Q | S4: 2003 | T4: 1Q | U4: 2Q | V4: 3Q | W4: 4Q | X4: 2004 | Y4: 1Q | Z4: 2Q | AA4: 3Q | AB4: 4Q | AC4: 2005 | AD4: 1Q | AE4: 2Q | AF4: 3Q | AG4: 4Q | AH4: 2006 | AI4: 1Q | AJ4: 2Q | AK4: 3Q | AL4: 4Q | AM4: 2007 | AN4: 1Q | AO4: 2Q | AP4: 3Q | AQ4: 4Q | AR4: 2008 | AS4: 1Q | AT4: 2Q | AU4: 3Q | AV4: 4Q | AW4: 2009 | AX4: 1Q | AY4: 2Q | AZ4: 3Q | BA4: 4Q | BB4: 2010 | BC4: 1Q | BD4: 2Q | BE4: 3Q | BF4: 4Q | BG4: 2011 | BH4: 1Q | BI4: 2Q | BJ4: 3Q | BK4: 4Q | BL4: 2012 | BM4: 1Q | BN4: 2Q | BO4: 3Q | BP4: 4Q | BQ4: 2013 | BR4: 1Q | BS4: 2Q | BT4: 3Q | BU4: 4Q | BV4: 2014 | BW4: 1Q | BX4: 2Q | BY4: 3Q | BZ4: 4Q | CA4: 2015 | CB4: 1Q | CC4: 2Q | CD4: 3Q | CE4: 4Q | CF4: 2016 | CG4: 1Q | CH4: 2Q | CI4: 3Q | CJ4: 4Q | CK4: 2017 | CL4: 1Q | CM4: 2QE | CN4: 3QE | CO4: 4QE | CP4: 2018E | CQ4: 1QE | CR4: 2QE | CS4: 3QE | CT4: 4QE | CU4: 2019E | CV4: 1QE | CW4: 2QE | CX4: 3QE | CY4: 4QE | CZ4: 2020E
A5: Prices (US$ per Ton)
B6: Hot-Rolled Sheet | E6: 340 | F6: 303.33333 | G6: 291.66667 | H6: 301.25 | I6: 223.5 | N6: 322.08333 | S6: 290.5 | T6: 462.33333 | U6: 610 | V6: 703.33333 | W6: 658.33333 | X6: =AVERAGE(T6:W6) -> 608.5 | Y6: 631.66667 | Z6: 532.5 | AA6: 461.66667 | AB6: 550 | AC6: =AVERAGE(Y6:AB6) -> 543.95833 | AD6: 550 | AE6: 591.66667 | AF6: 621.66667 | AG6: 563.33333 | AH6: =AVERAGE(AD6:AG6) -> 581.66667 | AI6: 518.33333 | AJ6: 553.33333 | AK6: 516.66667 | AL6: 535 | AM6: =AVERAGE(AI6:AL6) -> 530.83333 | AN6: 691.66667 | AO6: 976.66667 | AP6: 1051.6667 | AQ6: 714 | AR6: =AVERAGE(AN6:AQ6) -> 858.5 | AS6: 508.66667 | AT6: 399 | AU6: 491.33333 | AV6: 528 | AW6: =AVERAGE(AS6:AV6) -> 481.75 | AX6: 592 | AY6: 682 | AZ6: 582.66667 | BA6: 557 | BB6: =AVERAGE(AX6:BA6) -> 603.41667 | BC6: 795.66667 | BD6: 813 | BE6: 687.66782 | BF6: 657.66667 | BG6: =AVERAGE(BC6:BF6) -> 738.50029 | BH6: 720.66667 | BI6: 660 | BJ6: 625.66667 | BK6: 619.99869 | BL6: =AVERAGE(BH6:BK6) -> 656.58301 | BM6: 616.66667 | BN6: 592.33333 | BO6: 643.66667 | BP6: 658.99708 | BQ6: =AVERAGE(BM6:BP6) -> 627.91594 | BR6: 654.66667 | BS6: 671 | BT6: 667.66667 | BU6: 634.33333 | BV6: =AVERAGE(BR6:BU6) -> 656.91667 | BW6: 536.33333 | BX6: 453.66667 | BY6: 459 | BZ6: 387 | CA6: =AVERAGE(BW6:BZ6) -> 459 | CB6: 398.33333 | CC6: 561.66667 | CD6: 592 | CE6: 521 | CF6: =AVERAGE(CB6:CE6) -> 518.25 | CG6: 622.66667 | CH6: 623.5942 | CI6: 621.41848 | CJ6: 618.09489 | CK6: =AVERAGE(CG6:CJ6) -> 621.44356 | CL6: 741.07743 | CM6: 885 | CN6: 830 | CO6: 785 | CP6: =AVERAGE(CL6:CO6) -> 810.26936 | CQ6: 800 | CR6: 770 | CS6: 760 | CT6: 715 | CU6: =AVERAGE(CQ6:CT6) -> 761.25 | CV6: 660 | CW6: 675 | CX6: 645 | CY6: 645 | CZ6: =AVERAGE(CV6:CY6) -> 656.25
B7: Hollow Sections ASTM A500 | AS7: 823.08333 | AT7: 649.26 | AU7: 698.53333 | AV7: 733.61333 | AW7: =AVERAGE(AS7:AV7) -> 726.1225 | AX7: 801.66667 | AY7: 872.42667 | AZ7: 836.59 | BA7: 817.80667 | BB7: =AVERAGE(AX7:BA7) -> 832.1225 | BC7: 1076.6667 | BD7: 1076.4267 | BE7: 961.71667 | BF7: 930.25667 | BG7: =AVERAGE(BC7:BF7) -> 1011.2667 | BH7: 993.95333 | BI7: 971.94667 | BJ7: 916.49667 | BK7: 903.70333 | BL7: =AVERAGE(BH7:BK7) -> 946.525 | BM7: 925.77 | BN7: 912.12 | BO7: 930.15333 | BP7: 952.18667 | BQ7: =AVERAGE(BM7:BP7) -> 930.0575 | BR7: 981.62 | BS7: 956.29333 | BT7: 935.44 | BU7: 895.50667 | BV7: =AVERAGE(BR7:BU7) -> 942.215 | BW7: 836.28333 | BX7: 719.63667 | BY7: 705.09 | BZ7: 623.33667 | CA7: =AVERAGE(BW7:BZ7) -> 721.08667 | CB7: 631.63667 | CC7: 772.28667 | CD7: 818.83333 | CE7: 803.60333 | CF7: =AVERAGE(CB7:CE7) -> 756.59 | CG7: 908.79333 | CH7: 925.30333 | CI7: 886.70667 | CJ7: 892.08333 | CK7: =AVERAGE(CG7:CJ7) -> 903.22167 | CL7: 920 | CM7: 1080 | CN7: =+CN8-CM8+CM7 -> 1075 | CO7: =+CO8-CN8+CN7 -> 1060 | CP7: =AVERAGE(CL7:CO7) -> 1033.75 | CQ7: =+CQ8-CO8+CO7 -> 1070 | CR7: =+CR8-CQ8+CQ7 -> 1075 | CS7: =+CS8-CR8+CR7 -> 1045 | CT7: =+CT8-CS8+CS7 -> 1000 | CU7: =AVERAGE(CQ7:CT7) -> 1047.5 | CV7: =+CV8-CT8+CT7 -> 940 | CW7: =+CW8-CV8+CV7 -> 935 | CX7: =+CX8-CW8+CW7 -> 925 | CY7: =+CY8-CX8+CX7 -> 910 | CZ7: =AVERAGE(CV7:CY7) -> 927.5
B8: Rebar | E8: 328.75 | F8: 342.08333 | G8: 283.75 | H8: 272.91667 | I8: 276.66667 | N8: 272.5 | S8: 279.16667 | T8: 424.33333 | U8: 520 | V8: 546.66667 | W8: 520 | X8: =AVERAGE(T8:W8) -> 502.75 | Y8: 483.33333 | Z8: 480 | AA8: 473.33333 | AB8: 506.66667 | AC8: =AVERAGE(Y8:AB8) -> 485.83333 | AD8: 500 | AE8: 516.66667 | AF8: 550 | AG8: 533.33333 | AH8: =AVERAGE(AD8:AG8) -> 525 | AI8: 535 | AJ8: 645.06667 | AK8: 601.46667 | AL8: 575.46667 | AM8: =AVERAGE(AI8:AL8) -> 589.25 | AN8: 652.66667 | AO8: 848.13333 | AP8: 1007.4667 | AQ8: 766.73333 | AR8: =AVERAGE(AN8:AQ8) -> 818.75 | AS8: 618.86667 | AT8: 495.06667 | AU8: 536.26667 | AV8: 494.46667 | AW8: =AVERAGE(AS8:AV8) -> 536.16667 | AX8: 522 | AY8: 616.86667 | AZ8: 599.93333 | BA8: 645.53333 | BB8: =AVERAGE(AX8:BA8) -> 596.08333 | BC8: 761.66667 | BD8: 754.8 | BE8: 750.26667 | BF8: 782.06667 | BG8: =AVERAGE(BC8:BF8) -> 762.2 | BH8: 767.13333 | BI8: 740.86667 | BJ8: 690.33333 | BK8: 661.73333 | BL8: =AVERAGE(BH8:BK8) -> 715.01667 | BM8: 678.73333 | BN8: 662.53333 | BO8: 645 | BP8: 651.8 | BQ8: =AVERAGE(BM8:BP8) -> 659.51667 | BR8: 687 | BS8: 687.13333 | BT8: 662.6 | BU8: 671.93333 | BV8: =AVERAGE(BR8:BU8) -> 677.16667 | BW8: 622.66667 | BX8: 587.66667 | BY8: 565.53333 | BZ8: 507.13333 | CA8: =AVERAGE(BW8:BZ8) -> 570.75 | CB8: 478.8 | CC8: 540.4 | CD8: 524.53333 | CE8: 503.93333 | CF8: =AVERAGE(CB8:CE8) -> 511.91667 | CG8: 545.06667 | CH8: 532.8 | CI8: 549 | CJ8: 564.4 | CK8: =AVERAGE(CG8:CJ8) -> 547.81667 | CL8: 637 | CM8: 730 | CN8: 725 | CO8: 710 | CP8: =AVERAGE(CL8:CO8) -> 700.5 | CQ8: 720 | CR8: 725 | CS8: 695 | CT8: 650 | CU8: =AVERAGE(CQ8:CT8) -> 697.5 | CV8: 590 | CW8: 585 | CX8: 575 | CY8: 560 | CZ8: =AVERAGE(CV8:CY8) -> 577.5
B9: SBQ | AN9: 766.6 | AO9: 963.33333 | AP9: 1240 | AQ9: 1055.0667 | AR9: =AVERAGE(AN9:AQ9) -> 1006.25 | AS9: 773.93333 | AT9: 691.73333 | AU9: 678.6 | AV9: 710 | AW9: =AVERAGE(AS9:AV9) -> 713.56667 | AX9: 824.73333 | AY9: 840.73333 | AZ9: 854.4 | BA9: 852.33333 | BB9: =AVERAGE(AX9:BA9) -> 843.05 | BC9: 963 | BD9: 1039.7333 | BE9: 1053.6667 | BF9: 1056.6667 | BG9: =AVERAGE(BC9:BF9) -> 1028.2667 | BH9: 1093.8667 | BI9: 1021.2 | BJ9: 900.86667 | BK9: 870.93333 | BL9: =AVERAGE(BH9:BK9) -> 971.71667 | BM9: 868.06667 | BN9: 863.93333 | BO9: 831.93333 | BP9: 824.06667 | BQ9: =AVERAGE(BM9:BP9) -> 847 | BR9: 877.86667 | BS9: 897.6 | BT9: 902.46667 | BU9: 926.06667 | BV9: =AVERAGE(BR9:BU9) -> 901 | BW9: 895.46667 | BX9: 776.33333 | BY9: 727.33333 | BZ9: 648 | CA9: =AVERAGE(BW9:BZ9) -> 761.78333 | CB9: 623.2 | CC9: 645.26667 | CD9: 639.4 | CE9: 601.26667 | CF9: =AVERAGE(CB9:CE9) -> 627.28333 | CG9: 691.2 | CH9: 754.66667 | CI9: 796.93333 | CJ9: 788.8 | CK9: =AVERAGE(CG9:CJ9) -> 757.9 | CL9: 824.13333 | CM9: 910 | CN9: 925 | CO9: 895 | CP9: =AVERAGE(CL9:CO9) -> 888.53333 | CQ9: 905 | CR9: 910 | CS9: 890 | CT9: 845 | CU9: =AVERAGE(CQ9:CT9) -> 887.5 | CV9: 805 | CW9: 810 | CX9: 800 | CY9: 785 | CZ9: =AVERAGE(CV9:CY9) -> 800
B10: Blended Bar | BC10: =(BC35*BC9+BC34*BC8)/(BC34+BC35) -> 818.91674 | BD10: =(BD35*BD9+BD34*BD8)/(BD34+BD35) -> 828.37574 | BE10: =(BE35*BE9+BE34*BE8)/(BE34+BE35) -> 826.24071 | BF10: =(BF35*BF9+BF34*BF8)/(BF34+BF35) -> 852.49904 | BG10: =(BG35*BG9+BG34*BG8)/(BG34+BG35) -> 831.84352 | BH10: =(BH35*BH9+BH34*BH8)/(BH34+BH35) -> 846.48471 | BI10: =(BI35*BI9+BI34*BI8)/(BI34+BI35) -> 805.66069 | BJ10: =(BJ35*BJ9+BJ34*BJ8)/(BJ34+BJ35) -> 738.84788 | ... CZ10: =(CZ35*CZ9+CZ34*CZ8)/(CZ34+CZ35) -> 626.9332
B11: Structural | E11: 384.58333 | F11: 379.58333 | G11: 333.75 | H11: 345.83333 | I11: 342.91667 | N11: 335.83333 | S11: 315.83333 | T11: 442.33333 | U11: 525.33333 | V11: 558 | W11: 578.66667 | X11: =AVERAGE(T11:W11) -> 526.08333 | Y11: 583 | Z11: 583 | AA11: 540 | AB11: 620 | AC11: =AVERAGE(Y11:AB11) -> 581.5 | AD11: 620 | AE11: 640.66667 | AF11: 670 | AG11: 670 | AH11: =AVERAGE(AD11:AG11) -> 650.16667 | AI11: 695 | AJ11: 770 | AK11: 770 | AL11: 787 | AM11: =AVERAGE(AI11:AL11) -> 755.5 | AN11: 855.33333 | AO11: 987 | AP11: 1133 | AQ11: 991.66667 | AR11: =AVERAGE(AN11:AQ11) -> 991.75 | AS11: 894 | AT11: 716.66667 | AU11: 741.66667 | AV11: 735 | AW11: =AVERAGE(AS11:AV11) -> 771.83333 | AX11: 735 | AY11: 769.66667 | AZ11: 734.66667 | BA11: 758.66667 | BB11: =AVERAGE(AX11:BA11) -> 749.5 | BC11: 875 | BD11: 895 | BE11: 831.332 | BF11: 820.33333 | BG11: =AVERAGE(BC11:BF11) -> 855.41633 | BH11: 837.66667 | BI11: 819 | BJ11: 769.66667 | BK11: 757.66499 | BL11: =AVERAGE(BH11:BK11) -> 795.99958 | BM11: 766.99497 | BN11: 769.66162 | BO11: 762.32833 | BP11: 758.66169 | BQ11: =AVERAGE(BM11:BP11) -> 764.41165 | BR11: 791.33333 | BS11: 794 | BT11: 799 | BU11: 796 | BV11: =AVERAGE(BR11:BU11) -> 795.08333 | BW11: 751.33333 | BX11: 702 | BY11: 685 | BZ11: 644 | CA11: =AVERAGE(BW11:BZ11) -> 695.58333 | CB11: 615.66667 | CC11: 642.06667 | CD11: 668.66667 | CE11: 650.33333 | CF11: =AVERAGE(CB11:CE11) -> 644.18333 | CG11: 703 | CH11: 712.2 | CI11: 700 | CJ11: 620 | CK11: =AVERAGE(CG11:CJ11) -> 683.8 | CL11: 690 | CM11: 835 | CN11: 830 | CO11: 815 | CP11: =AVERAGE(CL11:CO11) -> 792.5 | CQ11: 825 | CR11: 830 | CS11: 800 | CT11: 755 | CU11: =AVERAGE(CQ11:CT11) -> 802.5 | CV11: 695 | CW11: 705 | CX11: 695 | CY11: 680 | CZ11: =AVERAGE(CV11:CY11) -> 693.75
B12: Plate | E12: 417.91667 | F12: 430.37709 | G12: 330.86629 | H12: 340.5 | I12: 290.66667 | N12: 323.75 | S12: 331.66667 | T12: 490 | U12: 621 | V12: 716.33333 | W12: 786.33333 | X12: =AVERAGE(T12:W12) -> 653.41667 | Y12: 776.33333 | Z12: 742 | AA12: 690 | AB12: 765 | AC12: =AVERAGE(Y12:AB12) -> 743.33333 | AD12: 765 | AE12: 776.66667 | AF12: 796.66667 | AG12: 790 | AH12: =AVERAGE(AD12:AG12) -> 782.08333 | AI12: 760 | AJ12: 800 | AK12: 790 | AL12: 790 | AM12: =AVERAGE(AI12:AL12) -> 785 | AN12: 910 | AO12: 1235 | AP12: 1443.3333 | AQ12: 1130 | AR12: =AVERAGE(AN12:AQ12) -> 1179.5833 | AS12: 743.33333 | AT12: 566.66667 | AU12: 600 | AV12: 596.66667 | AW12: =AVERAGE(AS12:AV12) -> 626.66667 | AX12: 681.66667 | AY12: 823.33333 | AZ12: 755.66667 | BA12: 736.66667 | BB12: =AVERAGE(AX12:BA12) -> 749.33333 | BC12: 943.33333 | BD12: 1040 | BE12: 994.00088 | BF12: 904.66667 | BG12: =AVERAGE(BC12:BF12) -> 970.50022 | BH12: 914.66667 | BI12: 870.66667 | BJ12: 781 | BK12: 700.33333 | BL12: =AVERAGE(BH12:BK12) -> 816.66667 | BM12: 718 | BN12: 718 | BO12: 706.33333 | BP12: 721.33333 | BQ12: =AVERAGE(BM12:BP12) -> 715.91667 | BR12: 787 | BS12: 811.66667 | BT12: 846.66667 | BU12: 794 | BV12: =AVERAGE(BR12:BU12) -> 809.83333 | BW12: 664.33333 | BX12: 581.33333 | BY12: 540.66667 | BZ12: 458.66667 | CA12: =AVERAGE(BW12:BZ12) -> 561.25 | CB12: 473.33333 | CC12: 622 | CD12: 570.33333 | CE12: 509.66667 | CF12: =AVERAGE(CB12:CE12) -> 543.83333 | CG12: 682 | CH12: 717.78261 | CI12: 691.80105 | CJ12: 640.61304 | CK12: =AVERAGE(CG12:CJ12) -> 683.04918 | CL12: 819.59279 | CM12: 965 | CN12: 910 | CO12: 865 | CP12: =AVERAGE(CL12:CO12) -> 889.8982 | CQ12: 880 | CR12: 850 | CS12: 840 | CT12: 795 | CU12: =AVERAGE(CQ12:CT12) -> 841.25 | CV12: 740 | CW12: 755 | CX12: 725 | CY12: 725 | CZ12: =AVERAGE(CV12:CY12) -> 736.25
B13: Shredded Scrap (Long Ton) | T13: 244.5 | U13: 201.46667 | V13: 265.48333 | W13: 287.01667 | X13: =AVERAGE(T13:W13) -> 249.61667 | Y13: 246.37667 | Z13: 203.84667 | AA13: 220.79667 | AB13: 246.94 | AC13: =AVERAGE(Y13:AB13) -> 229.49 | AD13: 241.68333 | AE13: 267.78 | AF13: 254.14667 | AG13: 228.62 | AH13: =AVERAGE(AD13:AG13) -> 248.0575 | AI13: 299.89 | AJ13: 286.15333 | AK13: 278.87 | AL13: 295.4 | AM13: =AVERAGE(AI13:AL13) -> 290.07833 | AN13: 392.54 | AO13: 547.20667 | AP13: 513.71333 | AQ13: 193.66333 | AR13: =AVERAGE(AN13:AQ13) -> 411.78083 | AS13: 213.37333 | AT13: 191.80667 | AU13: 269.50667 | AV13: 265.71333 | AW13: =AVERAGE(AS13:AV13) -> 235.1 | AX13: 358.61667 | AY13: 368.89333 | AZ13: 339.70667 | BA13: 367.51667 | BB13: =AVERAGE(AX13:BA13) -> 358.68333 | BC13: 456.45667 | BD13: 447.39333 | BE13: 450 | BF13: 429.87 | BG13: =AVERAGE(BC13:BF13) -> 445.93 | BH13: 449.5 | BI13: 414.82667 | BJ13: 373.72 | BK13: 369.33 | BL13: =AVERAGE(BH13:BK13) -> 401.84417 | BM13: 390.07333 | BN13: 374.86667 | BO13: 366.60333 | BP13: 383.98333 | BQ13: =AVERAGE(BM13:BP13) -> 378.88167 | BR13: 412.41333 | BS13: 383.64333 | BT13: 374.24333 | BU13: 338.38333 | BV13: =AVERAGE(BR13:BU13) -> 377.17083 | BW13: 277.58667 | BX13: 249.18333 | BY13: 244.09 | BZ13: 171.85667 | CA13: =AVERAGE(BW13:BZ13) -> 235.67917 | CB13: 194.21667 | CC13: 260.70667 | CD13: 235.08 | CE13: 227.43667 | CF13: =AVERAGE(CB13:CE13) -> 229.36 | CG13: 301.52667 | CH13: 292.27333 | CI13: 289.08667 | CJ13: 272.81667 | CK13: =AVERAGE(CG13:CJ13) -> 288.92583 | CL13: 332.51333 | CM13: 375 | CN13: 360 | CO13: 345 | CP13: =AVERAGE(CL13:CO13) -> 353.12833 | CQ13: 355 | CR13: 360 | CS13: 350 | CT13: 335 | CU13: =AVERAGE(CQ13:CT13) -> 350 | CV13: 305 | CW13: 310 | CX13: 300 | CY13: 285 | CZ13: =AVERAGE(CV13:CY13) -> 300
B14: #1 Busheling Scrap (Long Ton) | T14: 260.22006 | U14: 251.76046 | V14: 365.16595 | W14: 411.30952 | X14: =AVERAGE(T14:W14) -> 322.114 | Y14: 303.50324 | Z14: 206.73882 | AA14: 223.92754 | AB14: 265.51587 | AC14: =AVERAGE(Y14:AB14) -> 249.92137 | AD14: 265.2193 | AE14: 315.45455 | AF14: 298.47101 | AG14: 231.23333 | AH14: =AVERAGE(AD14:AG14) -> 277.59455 | AI14: 301.20106 | AJ14: 310.33 | AK14: 312.79333 | AL14: 320.09333 | AM14: =AVERAGE(AI14:AL14) -> 311.10443 | AN14: 414.93667 | AO14: 682.81333 | AP14: 773.15667 | AQ14: 218.44667 | AR14: =AVERAGE(AN14:AQ14) -> 522.33833 | AS14: 226.29667 | AT14: 198.70333 | AU14: 315.73667 | AV14: 307.81667 | AW14: =AVERAGE(AS14:AV14) -> 262.13833 | AX14: 414.06333 | AY14: 467.11333 | AZ14: 417.85667 | BA14: 406.64 | BB14: =AVERAGE(AX14:BA14) -> 426.41833 | BC14: 485.19333 | BD14: 498.10667 | BE14: 511.63333 | BF14: 482.8 | BG14: =AVERAGE(BC14:BF14) -> 494.43333 | BH14: 487.22667 | BI14: 429.26333 | BJ14: 382.78 | BK14: 371.63 | BL14: =AVERAGE(BH14:BK14) -> 417.725 | BM14: 393.10333 | BN14: 392.21333 | BO14: 404.1 | BP14: 417.89333 | BQ14: =AVERAGE(BM14:BP14) -> 401.8275 | BR14: 414.45 | BS14: 397.29333 | BT14: 397 | BU14: 362.80667 | BV14: =AVERAGE(BR14:BU14) -> 392.8875 | BW14: 290.99333 | BX14: 248.18333 | BY14: 254.76333 | BZ14: 175.89333 | CA14: =AVERAGE(BW14:BZ14) -> 242.45833 | CB14: 183.29333 | CC14: 259.92333 | CD14: 261.29333 | CE14: 234.56333 | CF14: =AVERAGE(CB14:CE14) -> 234.76833 | CG14: 325.11 | CH14: 351.33333 | CI14: 359.13 | CJ14: 332.75667 | CK14: =AVERAGE(CG14:CJ14) -> 342.0825 | CL14: 366.45667 | CM14: 385 | CN14: 370 | CO14: 355 | CP14: =AVERAGE(CL14:CO14) -> 369.11417 | CQ14: 365 | CR14: 370 | CS14: 360 | CT14: 355 | CU14: =AVERAGE(CQ14:CT14) -> 362.5 | CV14: 325 | CW14: 330 | CX14: 320 | CY14: 305 | CZ14: =AVERAGE(CV14:CY14) -> 320
A16: Steel Segment
A17: Nucor Realizations
B18: Sheet | S18: =S83/S33*1000 -> 341.04271 | X18: =X83/X33*1000 -> 601.19695 | Y18: 675 | Z18: 609 | AA18: 523 | AB18: 583 | AC18: =AC83/AC33*1000 -> 598.54049 | AD18: 594 | AE18: 625 | AF18: 673 | AG18: 624 | AH18: =AH83/AH33*1000 -> 628.90453 | AI18: 596 | AJ18: 630 | AK18: 602 | AL18: 606 | AM18: =AVERAGE(AI18:AL18) -> 608.5 | AN18: 660 | AO18: 872 | AP18: 1090 | AQ18: 854 | AR18: =AVERAGE(AN18:AQ18) -> 869 | AS18: 610 | AT18: 499 | AU18: 510 | AV18: 597 | AW18: =AVERAGE(AS18:AV18) -> 554 | AX18: 634 | AY18: 726 | AZ18: 680 | BA18: 637 | BB18: =AVERAGE(AX18:BA18) -> 669.25 | BC18: 755 | BD18: 894 | BE18: 800 | BF18: 747 | BG18: 796 | BH18: 780 | BI18: 759 | BJ18: 707 | BK18: 690 | BL18: 735 | BM18: 699 | BN18: 676 | BO18: 693 | BP18: 724 | BQ18: =AVERAGE(BM18:BP18) -> 698 | BR18: 744 | BS18: 737 | BT18: 750 | BU18: 712 | BV18: =AVERAGE(BR18:BU18) -> 735.75 | BW18: 663 | BX18: 560 | BY18: 552 | BZ18: 508 | CA18: =AVERAGE(BW18:BZ18) -> 570.75 | CB18: 471 | CC18: 550 | CD18: 666 | CE18: 603 | CF18: =AVERAGE(CB18:CE18) -> 572.5 | CG18: 661 | CH18: 709 | CI18: 695 | CJ18: 691 | CK18: =AVERAGE(CG18:CJ18) -> 689 | CL18: 723 | CM18: ='Price Relationships'!$C$70 -> 870.25 | CN18: ='Price Relationships'!$C$71 -> 907.1875 | CO18: ='Price Relationships'!$C$72 -> 882.71562 | CP18: =AVERAGE(CL18:CO18) -> 845.78828 | CQ18: ='Price Relationships'!$C$73 -> 884.95047 | CR18: ='Price Relationships'!$C$74 -> 864.13266 | CS18: ='Price Relationships'!$C$75 -> 849.64643 | CT18: ='Price Relationships'!$C$76 -> 812.17625 | CU18: =AVERAGE(CQ18:CT18) -> 852.72645 | CV18: ='Price Relationships'!$C$77 -> 779.46169 | CW18: ='Price Relationships'!$C$78 -> 778.81159 | CX18: ='Price Relationships'!$C$79 -> 756.98406 | CY18: ='Price Relationships'!$C$80 -> 749.34442 | CZ18: =AVERAGE(CV18:CY18) -> 766.15044
B19: Bars | S19: =S84/S34*1000 -> 315.87794 | X19: =X84/X34*1000 -> 502.09115 | Y19: 514 | Z19: 499 | AA19: 496 | AB19: 542 | AC19: =AC84/AC34*1000 -> 511.74411 | AD19: 543 | AE19: 567 | AF19: 601 | AG19: 576 | AH19: =AH84/AH34*1000 -> 571.39229 | AI19: 585 | AJ19: 650 | AK19: 631 | AL19: 627 | AM19: =AVERAGE(AI19:AL19) -> 623.25 | AN19: 696 | AO19: 862 | AP19: 1011 | AQ19: 758 | AR19: =AVERAGE(AN19:AQ19) -> 831.75 | AS19: 633 | AT19: 538 | AU19: 557 | AV19: 535 | AW19: =AVERAGE(AS19:AV19) -> 565.75 | AX19: 618 | AY19: 709 | AZ19: 666 | BA19: 669 | BB19: =AVERAGE(AX19:BA19) -> 665.5 | BC19: 779 | BD19: 803 | BE19: 811 | BF19: 796 | BG19: 798 | BH19: 823 | BI19: 795 | BJ19: 745 | BK19: 723 | BL19: 772 | BM19: 732 | BN19: 731 | BO19: 708 | BP19: 709 | BQ19: =AVERAGE(BM19:BP19) -> 720 | BR19: 737 | BS19: 732 | BT19: 738 | BU19: 724 | BV19: =AVERAGE(BR19:BU19) -> 732.75 | BW19: 698 | BX19: 623 | BY19: 625 | BZ19: 558 | CA19: =AVERAGE(BW19:BZ19) -> 626 | CB19: 505 | CC19: 561 | CD19: 567 | CE19: 544 | CF19: =AVERAGE(CB19:CE19) -> 544.25 | CG19: 600 | CH19: 605 | CI19: 624 | CJ19: 607 | CK19: =AVERAGE(CG19:CJ19) -> 609 | CL19: 660 | CM19: ='Price Relationships'!$E$70 -> 744.02332 | CN19: ='Price Relationships'!$E$71 -> 761.16689 | CO19: ='Price Relationships'!$E$72 -> 748.71692 | CP19: =AVERAGE(CL19:CO19) -> 728.47678 | CQ19: ='Price Relationships'!$E$73 -> 751.06516 | CR19: ='Price Relationships'!$E$74 -> 758.72568 | CS19: ='Price Relationships'!$E$75 -> 738.44975 | CT19: ='Price Relationships'!$E$76 -> 697.66211 | CU19: =AVERAGE(CQ19:CT19) -> 736.47568 | CV19: ='Price Relationships'!$E$77 -> 637.39445 | CW19: ='Price Relationships'!$E$78 -> 626.54625 | CX19: ='Price Relationships'!$E$79 -> 616.49294 | CY19: ='Price Relationships'!$E$80 -> 601.7096 | CZ19: =AVERAGE(CV19:CY19) -> 620.53581
B20: Structural | S20: =S86/S36*1000 -> 361.81978 | X20: =X86/X36*1000 -> 543.79638 | Y20: 605 | Z20: 574 | AA20: 561 | AB20: 634 | AC20: =AC86/AC36*1000 -> 593.84299 | AD20: 649 | AE20: 667 | AF20: 703 | AG20: 727 | AH20: =AH86/AH36*1000 -> 687.16142 | AI20: 754 | AJ20: 825 | AK20: 839 | AL20: 867 | AM20: =AVERAGE(AI20:AL20) -> 821.25 | AN20: 930 | AO20: 1041 | AP20: 1153 | AQ20: 1109 | AR20: =AVERAGE(AN20:AQ20) -> 1058.25 | AS20: 967 | AT20: 763 | AU20: 738 | AV20: 726 | AW20: =AVERAGE(AS20:AV20) -> 798.5 | AX20: 740 | AY20: 770 | AZ20: 786 | BA20: 773 | BB20: =AVERAGE(AX20:BA20) -> 767.25 | BC20: 831 | BD20: 923 | BE20: 901 | BF20: 891 | BG20: 884 | BH20: 866 | BI20: 905 | BJ20: 958 | BK20: 956 | BL20: 925 | BM20: 949 | BN20: 959 | BO20: 923 | BP20: 969 | BQ20: =AVERAGE(BM20:BP20) -> 950 | BR20: 941 | BS20: 1039 | BT20: 1058 | BU20: 1063 | BV20: =AVERAGE(BR20:BU20) -> 1025.25 | BW20: 996 | BX20: 991 | BY20: 926 | BZ20: 923 | CA20: =AVERAGE(BW20:BZ20) -> 959 | CB20: 870 | CC20: 845 | CD20: 865 | CE20: 837 | CF20: =AVERAGE(CB20:CE20) -> 854.25 | CG20: 738 | CH20: 766 | CI20: 769 | CJ20: 764 | CK20: =AVERAGE(CG20:CJ20) -> 759.25 | CL20: 798 | CM20: ='Price Relationships'!$G$70 -> 864.1 | CN20: ='Price Relationships'!$G$71 -> 908.87 | CO20: ='Price Relationships'!$G$72 -> 935.709 | CP20: =AVERAGE(CL20:CO20) -> 876.66975 | CQ20: ='Price Relationships'!$G$73 -> 957.4963 | CR20: ='Price Relationships'!$G$74 -> 974.24741 | CS20: ='Price Relationships'!$G$75 -> 976.97319 | CT20: ='Price Relationships'!$G$76 -> 965.38123 | CU20: =AVERAGE(CQ20:CT20) -> 968.52453 | CV20: ='Price Relationships'!$G$77 -> 939.26686 | CW20: ='Price Relationships'!$G$78 -> 923.9868 | CX20: ='Price Relationships'!$G$79 -> 910.29076 | CY20: ='Price Relationships'!$G$80 -> 896.20353 | CZ20: =AVERAGE(CV20:CY20) -> 917.43699
B21: Plate | S21: =S87/S37*1000 -> 322.17417 | X21: =X87/X37*1000 -> 656.37361 | Y21: 763 | Z21: 708 | AA21: 625 | AB21: 684 | AC21: =AC87/AC37*1000 -> 696.65455 | AD21: 698 | AE21: 712 | AF21: 746 | AG21: 732 | AH21: =AH87/AH37*1000 -> 721.78973 | AI21: 685 | AJ21: 741 | AK21: 724 | AL21: 715 | AM21: =AVERAGE(AI21:AL21) -> 716.25 | AN21: 751 | AO21: 974 | AP21: 1289 | AQ21: 1096 | AR21: =AVERAGE(AN21:AQ21) -> 1027.5 | AS21: 714 | AT21: 542 | AU21: 555 | AV21: 595 | AW21: =AVERAGE(AS21:AV21) -> 601.5 | AX21: 637 | AY21: 761 | AZ21: 752 | BA21: 731 | BB21: =AVERAGE(AX21:BA21) -> 720.25 | BC21: 880 | BD21: 1029 | BE21: 1021 | BF21: 946 | BG21: 970 | BH21: 929 | BI21: 922 | BJ21: 837 | BK21: 778 | BL21: 872 | BM21: 769 | BN21: 765 | BO21: 753 | BP21: 767 | BQ21: =AVERAGE(BM21:BP21) -> 763.5 | BR21: 816 | BS21: 837 | BT21: 863 | BU21: 875 | BV21: =AVERAGE(BR21:BU21) -> 847.75 | BW21: 805 | BX21: 691 | BY21: 648 | BZ21: 588 | CA21: =AVERAGE(BW21:BZ21) -> 683 | CB21: 545 | CC21: 604 | CD21: 661 | CE21: 584 | CF21: =AVERAGE(CB21:CE21) -> 598.5 | CG21: 703 | CH21: 746 | CI21: 749 | CJ21: 727 | CK21: =AVERAGE(CG21:CJ21) -> 731.25 | CL21: 785 | CM21: ='Price Relationships'!$I$70 -> 911.08845 | CN21: ='Price Relationships'!$I$71 -> 947.47484 | CO21: ='Price Relationships'!$I$72 -> 904.0844 | CP21: =AVERAGE(CL21:CO21) -> 886.91192 | CQ21: ='Price Relationships'!$I$73 -> 934.03233 | CR21: ='Price Relationships'!$I$74 -> 924.40004 | CS21: ='Price Relationships'!$I$75 -> 920.92803 | CT21: ='Price Relationships'!$I$76 -> 887.52538 | CU21: =AVERAGE(CQ21:CT21) -> 916.72144 | CV21: ='Price Relationships'!$I$77 -> 839.76573 | CW21: ='Price Relationships'!$I$78 -> 840.40475 | CX21: ='Price Relationships'!$I$79 -> 812.60095 | CY21: ='Price Relationships'!$I$80 -> 805.56259 | CZ21: =AVERAGE(CV21:CY21) -> 824.58351
C22: Total Average Price | H22: =1000*H89/H38 -> 369.58611 | I22: =1000*I89/I38 -> 312.69449 | J22: =1000*J89/J38 -> 306.66184 | K22: =1000*K89/K38 -> 324.22745 | L22: =1000*L89/L38 -> 345.15783 | M22: =1000*M89/M38 -> 343.36313 | N22: =1000*N89/N38 -> 329.91631 | O22: =1000*O89/O38 -> 321.2573 | ... R22: =1000*R89/R38 -> 351.52998 | S22: =(S18*S33+S19*S34+S20*S36+S21*S37)/S38 -> 334.87837 | T22: =1000*T89/T38 -> 436.74757 | U22: =1000*U89/U38 -> 552.30566 | V22: =1000*V89/V38 -> 638.57591 | W22: =1000*W89/W38 -> 660.29759 | X22: =(X18*X33+X19*X34+X20*X36+X21*X37)/X38 -> 568.3606 | Y22: =1000*Y89/Y38 -> 629.26621 | Z22: =1000*Z89/Z38 -> 578.87854 | AA22: =1000*AA89/AA38 -> 530.30973 | AB22: =1000*AB89/AB38 -> 590.70095 | AC22: =(AC18*AC33+AC19*AC34+AC20*AC36+AC21*AC37)/AC38 -> 581.59458 | AD22: =1000*AD89/AD38 -> 598.06798 | AE22: =(AE18*AE33+AE19*AE34+AE20*AE36+AE21*AE37)/AE38 -> 621.72807 | AF22: =(AF18*AF33+AF19*AF34+AF20*AF36+AF21*AF37)/AF38 -> 664.02566 | AG22: =(AG18*AG33+AG19*AG34+AG20*AG36+AG21*AG37)/AG38 -> 640.51135 | AH22: =(AH18*AH33+AH19*AH34+AH20*AH36+AH21*AH37)/AH38 -> 630.77092 | AI22: =(AI18*AI33+AI19*AI34+AI20*AI36+AI21*AI37)/AI38 -> 625.92656 | AJ22: =(AJ18*AJ33+AJ19*AJ34+AJ20*AJ36+AJ21*AJ37)/AJ38 -> 681.86135 | AK22: =(AK18*AK33+AK19*AK34+AK20*AK36+AK21*AK37)/AK38 -> 663.89976 | AL22: =(AL18*AL33+AL19*AL34+AL20*AL36+AL21*AL37)/AL38 -> 666.64947 | ... BB22: =(BB18*BB33+BB19*BB34+BB20*BB36+BB21*BB37)/BB38 -> 688.73232 | BC22: =(BC18*BC33+BC19*(BC34+BC35)+BC20*BC36+BC21*BC37)/BC38 -> 788.94885 | BD22: =(BD18*BD33+BD19*(BD34+BD35)+BD20*BD36+BD21*BD37)/BD38 -> 890.83218 | BE22: =(BE18*BE33+BE19*(BE34+BE35)+BE20*BE36+BE21*BE37)/BE38 -> 847.09847 | BF22: =(BF18*BF33+BF19*(BF34+BF35)+BF20*BF36+BF21*BF37)/BF38 -> 806.20474 | BG22: =(BG18*BG33+BG19*(BG34+BG35)+BG20*BG36+BG21*BG37)/BG38 -> 832.40605 | BH22: =(BH18*BH33+BH19*(BH34+BH35)+BH20*BH36+BH21*BH37)/BH38 -> 824.25577 | BI22: =(BI18*BI33+BI19*(BI34+BI35)+BI20*BI36+BI21*BI37)/BI38 -> 811.37626 | BJ22: =(BJ18*BJ33+BJ19*(BJ34+BJ35)+BJ20*BJ36+BJ21*BJ37)/BJ38 -> 771.67007 | ... CC22: =(CC18*CC33+CC19*(CC34+CC35)+CC20*CC36+CC21*CC37)/CC38 -> 593.37584 | CD22: =(CD18*CD33+CD19*(CD34+CD35)+CD20*CD36+CD21*CD37+CD158*CD124)/CD38 -> 663.7084 | CE22: =(CE18*CE33+CE19*(CE34+CE35)+CE20*CE36+CE21*CE37+CE158*CE124)/CE38 -> 614.37636 | CF22: =(CF18*CF33+CF19*(CF34+CF35)+CF20*CF36+CF21*CF37+CF158*CF124)/CF38 -> 602.72537 | CG22: =(CG18*CG33+CG19*(CG34+CG35)+CG20*CG36+CG21*CG37)/CG38 -> 657.06337 | CH22: =(CH18*CH33+CH19*(CH34+CH35)+CH20*CH36+CH21*CH37)/CH38 -> 687.51919 | CI22: =(CI18*CI33+CI19*(CI34+CI35)+CI20*CI36+CI21*CI37)/CI38 -> 684.86356 | CJ22: =(CJ18*CJ33+CJ19*(CJ34+CJ35)+CJ20*CJ36+CJ21*CJ37)/CJ38 -> 673.67725 | CK22: =(CK18*CK33+CK19*(CK34+CK35)+CK20*CK36+CK21*CK37)/CK38 -> 675.94388 | CL22: =(CL18*CL33+CL19*(CL34+CL35)+CL20*CL36+CL21*CL37)/CL38 -> 716.43142 | CM22: =(CM18*CM33+CM19*(CM34+CM35)+CM20*CM36+CM21*CM37)/CM38 -> 837.22241 | CN22: =(CN18*CN33+CN19*(CN34+CN35)+CN20*CN36+CN21*CN37)/CN38 -> 865.81747 | ... CZ22: =(CZ18*CZ33+CZ19*(CZ34+CZ35)+CZ20*CZ36+CZ21*CZ37)/CZ38 -> 736.90109
C23: Y-O-Y Change | I23: =I22/H22-1 -> -0.15393331 | N23: =N22/I22-1 -> 0.055075538 | O23: =O22/J22-1 -> 0.047594631 | P23: =P22/K22-1 -> 0.030141598 | Q23: =Q22/L22-1 -> -0.036676345 | R23: =R22/M22-1 -> 0.023784876 | S23: =S22/N22-1 -> 0.015040376 | T23: =T22/O22-1 -> 0.35949461 | U23: =U22/P22-1 -> 0.65360884 | ... CZ23: =CZ22/CU22-1 -> -0.11622298
C24: Sequential Change | K24: =K22/J22-1 -> 0.057280061 | L24: =L22/K22-1 -> 0.064554631 | M24: =M22/L22-1 -> -0.0051996474 | P24: =P22/O22-1 -> 0.039665667 | Q24: =Q22/P22-1 -> -0.0044954391 | R24: =R22/Q22-1 -> 0.05723715 | T24: =T22/R22-1 -> 0.2424191 | U24: =U22/T22-1 -> 0.26458782 | V24: =V22/U22-1 -> 0.15620021 | W24: =W22/V22-1 -> 0.034015815 | Y24: =Y22/W22-1 -> -0.046996054 | Z24: =Z22/Y22-1 -> -0.080073692 | AA24: =AA22/Z22-1 -> -0.083901564 | AB24: =AB22/AA22-1 -> 0.11387916 | AD24: =AD22/AB22-1 -> 0.012471676 | AE24: =AE22/AD22-1 -> 0.039560871 | AF24: =AF22/AE22-1 -> 0.068032286 | AG24: =AG22/AF22-1 -> -0.03541174 | AI24: =AI22/AG22-1 -> -0.022770538 | AJ24: =AJ22/AI22-1 -> 0.089363177 | AK24: =AK22/AJ22-1 -> -0.026341994 | AL24: =AL22/AK22-1 -> 0.0041417495 | AN24: =AN22/AL22-1 -> 0.084529996 | AO24: =AO22/AN22-1 -> 0.25483361 | AP24: =AP22/AO22-1 -> 0.22165037 | AQ24: =AQ22/AP22-1 -> -0.18038221 | AS24: =AS22/AQ22-1 -> -0.24932107 | AT24: =AT22/AS22-1 -> -0.18394575 | AU24: =AU22/AT22-1 -> 0.0048550757 | AV24: =AV22/AU22-1 -> 0.064384229 | AX24: =AX22/AV22-1 -> 0.080280447 | AY24: =AY22/AX22-1 -> 0.14070151 | AZ24: =AZ22/AY22-1 -> -0.044041397 | BA24: =BA22/AZ22-1 -> -0.032360575 | BC24: =BC22/BA22-1 -> 0.16286419 | BD24: =BD22/BC22-1 -> 0.12913808 | BE24: =BE22/BD22-1 -> -0.049093094 | BF24: =BF22/BE22-1 -> -0.048275061 | BH24: =BH22/BF22-1 -> 0.022390131 | BI24: =BI22/BH22-1 -> -0.015625622 | BJ24: =BJ22/BI22-1 -> -0.048936848 | BK24: =BK22/BJ22-1 -> -0.028039585 | BM24: =BM22/BK22-1 -> 0.0080085788 | BN24: =BN22/BM22-1 -> -0.013896097 | BO24: =BO22/BN22-1 -> -0.005689124 | BP24: =BP22/BO22-1 -> 0.029120046 | BR24: =BR22/BP22-1 -> 0.025856296 | BS24: =BS22/BR22-1 -> 0.0085867518 | BT24: =BT22/BS22-1 -> 0.019396306 | BU24: =BU22/BT22-1 -> -0.036064509 | BW24: =BW22/BU22-1 -> -0.056142054 | BX24: =BX22/BW22-1 -> -0.11849553 | BY24: =BY22/BX22-1 -> -0.015852934 | BZ24: =BZ22/BY22-1 -> -0.074919505 | CB24: =CB22/BZ22-1 -> -0.084939619 | CC24: =CC22/CB22-1 -> 0.103731 | CD24: =CD22/CC22-1 -> 0.11852954 | CE24: =CE22/CD22-1 -> -0.074327875 | CG24: =CG22/CE22-1 -> 0.06948023 | CH24: =CH22/CG22-1 -> 0.046351415 | CI24: =CI22/CH22-1 -> -0.003862631 | CJ24: =CJ22/CI22-1 -> -0.016333628 | CL24: =CL22/CJ22-1 -> 0.063463873 | CM24: =CM22/CL22-1 -> 0.16860091 | CN24: =CN22/CM22-1 -> 0.034154682 | CO24: =CO22/CN22-1 -> -0.02297405 | CQ24: =CQ22/CO22-1 -> 0.0090286829 | CR24: =CR22/CQ22-1 -> -0.0037582822 | CS24: =CS22/CR22-1 -> -0.019616688 | CT24: =CT22/CS22-1 -> -0.044638418 | CV24: =CV22/CT22-1 -> -0.056499051 | CW24: =CW22/CV22-1 -> -0.00099868885 | CX24: =CX22/CW22-1 -> -0.029062298 | CY24: =CY22/CX22-1 -> -0.016784073
A26: Volume Growth
B27: Sheet | I27: =Operations!I33/Operations!H33-1 -> 0.13868941 | N27: =Operations!N33/Operations!I33-1 -> 0.14426488 | S27: =Operations!S33/Operations!N33-1 -> 0.19772649 | T27: =Operations!T33/Operations!O33-1 -> 0.21661891 | U27: =Operations!U33/Operations!P33-1 -> 0.24422051 | V27: =Operations!V33/Operations!Q33-1 -> 0.14042069 | W27: =Operations!W33/Operations!R33-1 -> 0.049347703 | X27: =Operations!X33/Operations!S33-1 -> 0.16163359 | Y27: =Operations!Y33/Operations!T33-1 -> -0.026848799 | Z27: =Operations!Z33/Operations!U33-1 -> -0.049070986 | ... AZ27: =Operations!AZ33/Operations!AU33-1 -> 0.058045977 | BA27: 0.1 | BB27: =Operations!BB33/Operations!AW33-1 -> 0.42632387 | BC27: =Operations!BC33/Operations!AX33-1 -> 0.044 | BD27: =Operations!BD33/Operations!AY33-1 -> -0.092445853 | BE27: =Operations!BE33/Operations!AZ33-1 -> 0.0065181966 | BF27: =Operations!BF33/Operations!BA33-1 -> 0.082941176 | BG27: =Operations!BG33/Operations!BB33-1 -> 0.0088781275 | BH27: =Operations!BH33/Operations!BC33-1 -> -0.019157088 | BI27: =Operations!BI33/Operations!BD33-1 -> 0.12048894 | ... CL27: =Operations!CL33/Operations!CG33-1 -> -0.052223582 | CM27: 0.02 | CN27: 0.02 | CO27: 0.02 | CP27: =Operations!CP33/Operations!CK33-1 -> 0.00098807862 | CQ27: 0.02 | CR27: 0.02 | CS27: 0.02 | CT27: 0.02 | CU27: =Operations!CU33/Operations!CP33-1 -> 0.02 | CV27: 0.08 | CW27: 0.08 | CX27: 0.08 | CY27: 0.08 | CZ27: =Operations!CZ33/Operations!CU33-1 -> 0.08
B28: Bars | I28: =Operations!I34/Operations!H34-1 -> 0.21638751 | N28: =Operations!N34/Operations!I34-1 -> 0.096762188 | S28: =Operations!S34/Operations!N34-1 -> 0.87648456 | T28: =Operations!T34/Operations!O34-1 -> 0.02050581 | U28: =Operations!U34/Operations!P34-1 -> 0.0045420136 | V28: =Operations!V34/Operations!Q34-1 -> -0.1015299 | W28: =Operations!W34/Operations!R34-1 -> -0.13455657 | X28: =Operations!X34/Operations!S34-1 -> -0.051717902 | Y28: =Operations!Y34/Operations!T34-1 -> -0.078365707 | Z28: =Operations!Z34/Operations!U34-1 -> 0.14770158 | ... AZ28: =Operations!AZ34/Operations!AU34-1 -> 0.063200815 | BA28: -0.05 | BB28: =Operations!BB34/Operations!AW34-1 -> 0.10746762 | BC28: =Operations!BC34/Operations!AX34-1 -> -0.25097182 | BD28: =Operations!BD34/Operations!AY34-1 -> -0.02032294 | BE28: =Operations!BE34/Operations!AZ34-1 -> -0.12104506 | BF28: =Operations!BF34/Operations!BA34-1 -> -0.15371783 | BG28: =Operations!BG34/Operations!BB34-1 -> -0.14033342 | BH28: =Operations!BH34/Operations!BC34-1 -> 0.23872851 | BI28: =Operations!BI34/Operations!BD34-1 -> 0.15799943 | ... CL28: =Operations!CL34/Operations!CG34-1 -> 0.33085106 | CM28: 0.02 | CN28: 0.02 | CO28: 0.02 | CP28: =Operations!CP34/Operations!CK34-1 -> 0.088947617 | CQ28: 0.02 | CR28: 0.02 | CS28: 0.02 | CT28: 0.02 | CU28: =Operations!CU34/Operations!CP34-1 -> 0.02 | CV28: 0.19 | CW28: 0.19 | CX28: 0.19 | CY28: 0.19 | CZ28: =Operations!CZ34/Operations!CU34-1 -> 0.19
B29: Structural | I29: =Operations!I36/Operations!H36-1 -> -0.11150614 | N29: =Operations!N36/Operations!I36-1 -> -0.021826119 | S29: =Operations!S36/Operations!N36-1 -> 0.033841577 | T29: =Operations!T36/Operations!O36-1 -> 0.2640264 | U29: =Operations!U36/Operations!P36-1 -> -0.0098452883 | V29: =Operations!V36/Operations!Q36-1 -> -0.044034091 | W29: =Operations!W36/Operations!R36-1 -> -0.18708827 | X29: =Operations!X36/Operations!S36-1 -> -0.0071942446 | Y29: =Operations!Y36/Operations!T36-1 -> -0.14490862 | Z29: =Operations!Z36/Operations!U36-1 -> -0.029829545 | ... AZ29: =Operations!AZ36/Operations!AU36-1 -> 0.12350598 | BA29: 0.15 | BB29: =Operations!BB36/Operations!AW36-1 -> 0.31549815 | BC29: =Operations!BC36/Operations!AX36-1 -> 0.36983471 | BD29: =Operations!BD36/Operations!AY36-1 -> 0.042435424 | BE29: =Operations!BE36/Operations!AZ36-1 -> -0.069148936 | BF29: =Operations!BF36/Operations!BA36-1 -> 0.06557377 | BG29: =Operations!BG36/Operations!BB36-1 -> 0.093034128 | BH29: =Operations!BH36/Operations!BC36-1 -> 0.0045248869 | BI29: =Operations!BI36/Operations!BD36-1 -> 0.053097345 | ... CL29: =Operations!CL36/Operations!CG36-1 -> -0.017786561 | CM29: 0.02 | CN29: 0.02 | CO29: 0.02 | CP29: =Operations!CP36/Operations!CK36-1 -> 0.0090051754 | CQ29: 0.02 | CR29: 0.02 | CS29: 0.02 | CT29: 0.02 | CU29: =Operations!CU36/Operations!CP36-1 -> 0.02 | CV29: 0.02 | CW29: 0.02 | CX29: 0.02 | CY29: 0.02 | CZ29: =Operations!CZ36/Operations!CU36-1 -> 0.02
B30: Plate | I30: =Operations!I37/Operations!H37-1 -> 25.1 | N30: =Operations!N37/Operations!I37-1 -> 0.67049808 | S30: =Operations!S37/Operations!N37-1 -> 0.1456422 | T30: =Operations!T37/Operations!O37-1 -> 0.52212389 | U30: =Operations!U37/Operations!P37-1 -> 0.39316239 | V30: =Operations!V37/Operations!Q37-1 -> 0.99616858 | W30: =Operations!W37/Operations!R37-1 -> 0.84892086 | X30: =Operations!X37/Operations!S37-1 -> 0.70670671 | Y30: =Operations!Y37/Operations!T37-1 -> 0.71802326 | Z30: =Operations!Z37/Operations!U37-1 -> 0.50613497 | ... AZ30: =Operations!AZ37/Operations!AU37-1 -> 0.13070539 | BA30: 0.1 | BB30: =Operations!BB37/Operations!AW37-1 -> 0.38619403 | BC30: =Operations!BC37/Operations!AX37-1 -> 0.066907776 | BD30: =Operations!BD37/Operations!AY37-1 -> -0.010186757 | BE30: =Operations!BE37/Operations!AZ37-1 -> 0.088073394 | BF30: =Operations!BF37/Operations!BA37-1 -> -0.055350554 | BG30: =Operations!BG37/Operations!BB37-1 -> 0.021982952 | BH30: =Operations!BH37/Operations!BC37-1 -> 0.042372881 | BI30: =Operations!BI37/Operations!BD37-1 -> 0.036020583 | ... CL30: =Operations!CL37/Operations!CG37-1 -> -0.031971581 | CM30: 0.03 | CN30: 0.03 | CO30: 0.03 | CP30: =Operations!CP37/Operations!CK37-1 -> 0.014486438 | CQ30: 0.02 | CR30: 0.02 | CS30: 0.02 | CT30: 0.02 | CU30: =Operations!CU37/Operations!CP37-1 -> 0.02 | CV30: 0.02 | CW30: 0.02 | CX30: 0.02 | CY30: 0.02 | CZ30: =Operations!CZ37/Operations!CU37-1 -> 0.02
A32: Shipments
B33: Sheet | H33: 4456 | I33: 5074 | J33: 1436 | K33: 1396 | L33: 1432 | M33: 1542 | N33: =SUM(J33:M33) -> 5806 | O33: 1745 | P33: 1687 | Q33: 1759 | R33: 1763 | S33: =SUM(O33:R33) -> 6954 | T33: 2123 | U33: 2099 | V33: 2006 | W33: 1850 | X33: =SUM(T33:W33) -> 8078 | Y33: 2066 | Z33: 1996 | AA33: 1954 | AB33: 2010 | AC33: =SUM(Y33:AB33) -> 8026 | AD33: 2241 | AE33: 2221 | AF33: 2177 | AG33: 1856 | AH33: =SUM(AD33:AG33) -> 8495 | AI33: 2020 | AJ33: 2068 | AK33: 2038 | AL33: 2140 | AM33: =SUM(AI33:AL33) -> 8266 | AN33: 2211 | AO33: 2280 | AP33: 1920 | AQ33: 1094 | AR33: =SUM(AN33:AQ33) -> 7505 | AS33: 957 | AT33: 966 | AU33: 1740 | AV33: 1549 | AW33: =SUM(AS33:AV33) -> 5212 | AX33: 2000 | AY33: 1893 | AZ33: 1841 | BA33: 1700 | BB33: =SUM(AX33:BA33) -> 7434 | BC33: 2088 | BD33: 1718 | BE33: 1853 | BF33: 1841 | BG33: =SUM(BC33:BF33) -> 7500 | BH33: 2048 | BI33: 1925 | BJ33: 1804 | BK33: 1845 | BL33: =SUM(BH33:BK33) -> 7622 | BM33: 1837 | BN33: 1796 | BO33: 1965 | BP33: 1893 | BQ33: =SUM(BM33:BP33) -> 7491 | BR33: 1877 | BS33: 1972 | BT33: 2040 | BU33: 2264 | BV33: =SUM(BR33:BU33) -> 8153 | BW33: 1956 | BX33: 2196 | BY33: 2109 | BZ33: 1819 | CA33: =SUM(BW33:BZ33) -> 8080 | CB33: 2392 | CC33: 2522 | CD33: 2121 | CE33: 2083 | CF33: =SUM(CB33:CE33) -> 9118 | CG33: 2451 | CH33: 2371 | CI33: 2282 | CJ33: 2207 | CK33: =SUM(CG33:CJ33) -> 9311 | CL33: 2323 | CM33: =(1+Operations!CM27)*Operations!CH33 -> 2418.42 | CN33: =(1+Operations!CN27)*Operations!CI33 -> 2327.64 | CO33: =(1+Operations!CO27)*Operations!CJ33 -> 2251.14 | CP33: =SUM(CL33:CO33) -> 9320.2 | CQ33: =(1+Operations!CQ27)*Operations!CL33 -> 2369.46 | CR33: =(1+Operations!CR27)*Operations!CM33 -> 2466.7884 | CS33: =(1+Operations!CS27)*Operations!CN33 -> 2374.1928 | CT33: =(1+Operations!CT27)*Operations!CO33 -> 2296.1628 | CU33: =SUM(CQ33:CT33) -> 9506.604 | CV33: =(1+Operations!CV27)*Operations!CQ33 -> 2559.0168 | CW33: =(1+Operations!CW27)*Operations!CR33 -> 2664.1315 | CX33: =(1+Operations!CX27)*Operations!CS33 -> 2564.1282 | CY33: =(1+Operations!CY27)*Operations!CT33 -> 2479.8558 | CZ33: =SUM(CV33:CY33) -> 10267.132
B34: Rebar/M Bar | H34: 2209 | I34: 2687 | J34: 699 | K34: 774 | L34: 710 | M34: 764 | N34: =SUM(J34:M34) -> 2947 | O34: 1463 | P34: 1321 | Q34: 1438 | R34: 1308 | S34: =SUM(O34:R34) -> 5530 | T34: 1493 | U34: 1327 | V34: 1292 | W34: 1132 | X34: =SUM(T34:W34) -> 5244 | Y34: 1376 | Z34: 1523 | AA34: 1674 | AB34: 1410 | AC34: =SUM(Y34:AB34) -> 5983 | AD34: 1638 | AE34: 1809 | AF34: 1613 | AG34: 1453 | AH34: =SUM(AD34:AG34) -> 6513 | AI34: 1819 | AJ34: 1404 | AK34: 1548 | AL34: 1516 | AM34: =SUM(AI34:AL34) -> 6287 | AN34: 1516 | AO34: 1632 | AP34: 1272 | AQ34: 846 | AR34: =SUM(AN34:AQ34) -> 5266 | AS34: 781 | AT34: 918 | AU34: 981 | AV34: 949 | AW34: =SUM(AS34:AV34) -> 3629 | AX34: 1029 | AY34: 898 | AZ34: 1043 | BA34: 1049 | BB34: =SUM(AX34:BA34) -> 4019 | BC34: =1077-BC35 -> 770.75 | BD34: =1186-BD35 -> 879.75 | BE34: =1223-BE35 -> 916.75 | BF34: =1194-BF35 -> 887.75 | BG34: =SUM(BC34:BF34) -> 3455 | BH34: =1261-BH35 -> 954.75 | BI34: =1325-BI35 -> 1018.75 | BJ34: =1329-BJ35 -> 1022.75 | BK34: =1163-BK35 -> 856.75 | BL34: =SUM(BH34:BK34) -> 3853 | BM34: =1273-BM35 -> 951.4375 | BN34: =1272-BN35 -> 950.4375 | BO34: =1345-BO35 -> 1023.4375 | BP34: =1294-BP35 -> 972.4375 | BQ34: =SUM(BM34:BP34) -> 3897.75 | BR34: =1351-BR35 -> 951 | BS34: =1430-BS35 -> 1030 | BT34: =1502-BT35 -> 1102 | BU34: =1243-BU35 -> 843 | BV34: =SUM(BR34:BU34) -> 3926 | BW34: =1173-BW35 -> 773 | BX34: =1324-BX35 -> 924 | BY34: =1219-BY35 -> 819 | BZ34: =1074-BZ35 -> 674 | CA34: =SUM(BW34:BZ34) -> 3190 | CB34: =1355-CB35 -> 955 | CC34: =1384-CC35 -> 984 | CD34: =1308-CD35 -> 908 | CE34: =1257-CE35 -> 857 | CF34: =SUM(CB34:CE34) -> 3704 | CG34: =1340-CG35 -> 940 | CH34: =1493-CH35 -> 1093 | CI34: =1489-CI35 -> 1089 | CJ34: =1516-CJ35 -> 1116 | CK34: =SUM(CG34:CJ34) -> 4238 | CL34: =1651-CL35 -> 1251 | CM34: =(1+Operations!CM28)*Operations!CH34 -> 1114.86 | CN34: =(1+Operations!CN28)*Operations!CI34 -> 1110.78 | CO34: =(1+Operations!CO28)*Operations!CJ34 -> 1138.32 | CP34: =SUM(CL34:CO34) -> 4614.96 | CQ34: =(1+Operations!CQ28)*Operations!CL34 -> 1276.02 | CR34: =(1+Operations!CR28)*Operations!CM34 -> 1137.1572 | CS34: =(1+Operations!CS28)*Operations!CN34 -> 1132.9956 | CT34: =(1+Operations!CT28)*Operations!CO34 -> 1161.0864 | CU34: =SUM(CQ34:CT34) -> 4707.2592 | CV34: =(1+Operations!CV28)*Operations!CQ34 -> 1518.4638 | CW34: =(1+Operations!CW28)*Operations!CR34 -> 1353.2171 | CX34: =(1+Operations!CX28)*Operations!CS34 -> 1348.2648 | CY34: =(1+Operations!CY28)*Operations!CT34 -> 1381.6928 | CZ34: =SUM(CV34:CY34) -> 5601.6384
B35: SBQ | BC35: =BD35 -> 306.25 | BD35: =BE35 -> 306.25 | BE35: =BF35 -> 306.25 | BF35: =BG35/4 -> 306.25 | BG35: 1225 | BH35: =BI35 -> 306.25 | BI35: =BJ35 -> 306.25 | BJ35: =BK35 -> 306.25 | BK35: =BL35/4 -> 306.25 | BL35: 1225 | BM35: =BN35 -> 321.5625 | BN35: =BO35 -> 321.5625 | BO35: =BP35 -> 321.5625 | BP35: =BQ35/4 -> 321.5625 | BQ35: 1286.25 | BR35: 400 | BS35: 400 | BT35: 400 | BU35: 400 | BV35: =SUM(BR35:BU35) -> 1600 | BW35: 400 | BX35: 400 | BY35: 400 | BZ35: 400 | CA35: =SUM(BW35:BZ35) -> 1600 | CB35: 400 | CC35: 400 | CD35: 400 | CE35: 400 | CF35: =SUM(CB35:CE35) -> 1600 | CG35: 400 | CH35: 400 | CI35: =CJ35 -> 400 | CJ35: =CK35/4 -> 400 | CK35: 1600 | CL35: 400 | CM35: =CN35 -> 400 | CN35: =CO35 -> 400 | CO35: =CP35/4 -> 400 | CP35: 1600 | CQ35: =CR35 -> 400 | CR35: =CS35 -> 400 | CS35: =CT35 -> 400 | CT35: =CU35/4 -> 400 | CU35: 1600 | CV35: =CW35 -> 400 | CW35: =CX35 -> 400 | CX35: =CY35 -> 400 | CY35: =CZ35/4 -> 400 | CZ35: 1600
