Workbook
Name AdditionalInstructions: IndexInformation!$B$42
Name Address: ImportantDisclosures!$A$2:$A$2
Name ANA: ModPubIndex!$A$7
Name Authors: ImportantDisclosures!$A$7
Name Authors: IndexInformation!$B$18
Name BRO: ModPubIndex!$A$1
Name BSMethod: 2
Name calc: 'Deals and Terms'!calc
Name calc: 'Financings and Debt info'!calc
Name calc: Revs!calc
Name calc: 'Deals and Terms'!calc
Name cmdOK2_click: [5]!cmdOK2_click
Name cmdOK2_click: [5]!cmdOK2_click
Name CopyrightStamp: ImportantDisclosures!$A$27
Name COU: ModPubIndex!$A$5
Name CQEnd: IndexInformation!$B$31
Name Currency: IndexInformation!$B$24
Name CurrentStockPrice: IndexInformation!$B$23
Name CurrQtrEPS: IndexInformation!$B$29
Name CurrYearEPS: IndexInformation!$B$11
Name CurrYearTotalRevenue: IndexInformation!$B$10
Name CurrYearTotalRevenueActual: IndexInformation!$B$32
Name CUSIP: IndexInformation!$B$20
Name CYEnd: IndexInformation!$B$30
Name DATA_NEW: [6]Input!$H$6:$BE$465
Name dataseries4: OFFSET([7]c1!$G$12,0,0,COUNTA([7]c1!$G$12:$G$31),1)
Name Date: ImportantDisclosures!$A$8
Name Deleted: IndexInformation!$B$27
Name Description: IndexInformation!$B$7
Name DEVELOPMENT: 5
Name Discipline: IndexInformation!$B$3
Name DISCIPLINE: ModPubIndex!$A$12
Name Disclosure: [8]Input!$H$6:$BE$465
Name DisclosuresText: ImportantDisclosures!$A$22
Name Distribution: IndexInformation!$B$26
Name DistTable: ImportantDisclosures!#REF!
Name DistTablePreamble: ImportantDisclosures!#REF!
Name DOCDAT: ModPubIndex!$A$2
Name DOCTIME: ModPubIndex!$A$3
Name DocType: IndexInformation!$B$5
Name Drugs: 'Deals and Terms'!Drugs
Name Drugs: 'Financings and Debt info'!Drugs
Name Drugs: Revs!Drugs
Name Drugs: 'Deals and Terms'!Drugs
Name EMAIL_ALERT: ModPubIndex!$A$10
Name EmailAlert: IndexInformation!$B$28
Name FiveYearGrowthRate: IndexInformation!$B$16
Name FollowingYearEPS: IndexInformation!$B$15
Name FollowingYearTotalRevenue: IndexInformation!$B$14
Name FollowingYearTotalRevenueActual: IndexInformation!$B$34
Name FR_CODE_COPY_LINK: " "
Name FR_CODE_DOWNLOAD_START: " "
Name FR_CODE_STOCK_LINK: " "
Name FR_COM_ABBR: "CHKP"
Name FR_COM_AGG: 0
Name FR_COU_ABBR: "usa"
Name FR_COU_NAME_LINK: " "
Name FR_DATABOX_DOWNLOAD: "N"
Name FR_DISP_HIDDEN: FALSE
Name FR_END_DATE: "'"

Sheet ImportantDisclosures
A2: 1585 Broadway
A3: New York, NY 10036-8293
A4: United States
A5: Tel: +1 (1)212 761 4000
A7: Authors: Matthew Harrison
A8: Date: 16 Apr 2018
A10: Ticker: VRTX.O
A11: Stock Rating: Overweight
A12: Industry: Biotechnology
A13: Industry View: In-Line
A14: Price as of 16 Apr 2018: 159.56
A15: Target Price: 200
... A120: Equal-weight and Not-Rated to hold and Underweight to sell recommendations, respectively.
B122: Coverage Universe | D122: Investment Banking Clients (IBC) | G122: Other Material Investment Services Clients (MISC)
A123: Stock Rating Category | B123: Count | C123: % of Total | D123: Count | E123: % of Total IBC | F123: % of Rating Category | G123: Count | H123: % of Total Other MISC
A124: Overweight/Buy | B124: 1189 | C124: 0.38 | D124: 315 | E124: 0.41 | F124: 0.26 | G124: 555 | H124: 0.39
A125: Equal-weight/Hold | B125: 1355 | C125: 0.43 | D125: 364 | E125: 0.47 | F125: 0.27 | G125: 644 | H125: 0.45
A126: Not-Rated/Hold | B126: 53 | C126: 0.02 | D126: 4 | E126: 0.01 | F126: 0.08 | G126: 7 | H126: 0
A127: Underweight/Sell | B127: 545 | C127: 0.17 | D127: 84 | E127: 0.11 | F127: 0.15 | G127: 214 | H127: 0.15
A128: Total | B128: 3142 | D128: 767 | G128: 1420
A130: Data include common stock and ADRs currently assigned ratings. Investment Banking Clients are companies
A131: from whom Morgan Stanley received investment banking compensation in the last 12 months. Due to rounding
A132: off of decimals, the percentages provided in the "% of total" column may not add up to exactly 100
A133: percent.
A135: Analyst Stock Ratings
A137: Overweight (O). The stock's total return is expected to exceed the average total return of the analyst's
A138: industry (or industry team's) coverage universe, on a risk-adjusted basis, over the next 12-18 months.
A140: Equal-weight (E). The stock's total return is expected to be in line with the average total return of
A141: the analyst's industry (or industry team's) coverage universe, on a risk-adjusted basis, over the next
A142: 12-18 months.
A144: Not-Rated (NR). Currently the analyst does not have adequate conviction about the stock's total return
A145: relative to the average total return of the analyst's industry (or industry team's) coverage universe,
... A388: © Copyright 2018 Morgan Stanley

Sheet DCF
B3: ($ in millions) | E3: 2015 | F3: =E3+1 -> 2016 | G3: =F4+1 -> 2017 | H3: =G3+1 -> 2018 | I3: =H3+1 -> 2019 | J3: =I3+1 -> 2020 | K3: =J3+1 -> 2021 | L3: =K3+1 -> 2022 | M3: =L3+1 -> 2023 | N3: =M3+1 -> 2024 | O3: =N3+1 -> 2025 | ... T3: =S3+1 -> 2030 | U3: Terminal
F4: =E3+1 -> 2016 | U4: =T3+1 -> 2031
B5: Non-GAAP EBIT | E5: =IS!V41 -> -265.899 | F5: =IS!AA41 -> 210.893 | G5: =IS!AF41 -> 501.326 | H5: =IS!AK41 -> 767.36771 | I5: =IS!AP41 -> 917.00412 | J5: =IS!AU41 -> 1840.756 | K5: =IS!AZ41 -> 3006.2752 | L5: =IS!BE41 -> 3790.1287 | M5: =IS!BJ41 -> 4222.4732 | N5: =IS!BO41 -> 4528.4506 | O5: =IS!BT41 -> 5385.8072 | P5: =IS!BY41 -> 7005.921 | Q5: =IS!CD41 -> 7362.9783 | R5: =IS!CI41 -> 7769.2531 | S5: =IS!CN41 -> 8095.4751 | T5: =IS!CS41 -> 8542.5074
B6: Growth | F6: =IF(E5<0,"NM",F5/E5-1) -> NM | G6: =IF(F5<0,"NM",G5/F5-1) -> 1.3771581 | H6: =IF(G5<0,"NM",H5/G5-1) -> 0.53067607 | I6: =IF(H5<0,"NM",I5/H5-1) -> 0.19499962 | J6: =IF(I5<0,"NM",J5/I5-1) -> 1.0073585 | K6: =IF(J5<0,"NM",K5/J5-1) -> 0.6331742 | L6: =IF(K5<0,"NM",L5/K5-1) -> 0.26073912 | M6: =IF(L5<0,"NM",M5/L5-1) -> 0.11407119 | ... T6: =IF(S5<0,"NM",T5/S5-1) -> 0.055220013
B8: Taxes | E8: =IS!V42 -> 0.65 | F8: =IS!AA42 -> -0.079 | G8: =IS!AF42 -> 6.766 | H8: =IS!AK42 -> 0 | I8: =IS!AP42 -> 0 | J8: =IS!AU42 -> 0 | K8: =IS!AZ42 -> 0 | L8: =IS!BE42 -> 643.73552 | M8: =IS!BJ42 -> 855.15675 | N8: =IS!BO42 -> 920.94188 | O8: =IS!BT42 -> 1105.2735 | P8: =IS!BY42 -> 1453.598 | Q8: =IS!CD42 -> 1530.3653 | R8: =IS!CI42 -> 1617.7144 | S8: =IS!CN42 -> 1687.8522 | T8: =IS!CS42 -> 1783.9641
B9: Tax rate | H9: =H8/H5 -> 0 | I9: =I8/I5 -> 0 | J9: =J8/J5 -> 0 | K9: =K8/K5 -> 0 | L9: =L8/L5 -> 0.16984529 | M9: =M8/M5 -> 0.20252508 | N9: =N8/N5 -> 0.20336799 | O9: =O8/O5 -> 0.20521966 | ... T9: =T8/T5 -> 0.20883378
B10: Non-GAAP EBIT, after tax | E10: =E5-E8 -> -266.549 | F10: =F5-F8 -> 210.972 | G10: =G5-G8 -> 494.56 | H10: =H5-H8 -> 767.36771 | I10: =I5-I8 -> 917.00412 | J10: =J5-J8 -> 1840.756 | K10: =K5-K8 -> 3006.2752 | L10: =L5-L8 -> 3146.3932 | ... T10: =T5-T8 -> 6758.5433
B11: Plus: D&A | E11: =CF!I7 -> 62.343 | F11: =CF!J7 -> 61.398 | G11: =CF!K7 -> 62.822322 | H11: =CF!L7 -> 65.128658 | I11: =CF!M7 -> 67.341659 | J11: =CF!N7 -> 70.06428 | K11: =CF!O7 -> 70.633066 | L11: =CF!P7 -> 68.592163 | ... T11: =CF!X7 -> 55.54057
B12: Plus/Less: Change in non-Cash WC | E12: =((BS!E10-BS!E5-BS!E6)-BS!E25)-((BS!D10-BS!D5-BS!D6)-BS!D25) -> 67.191 | F12: =((BS!F10-BS!F5-BS!F6)-BS!F25)-((BS!E10-BS!E5-BS!E6)-BS!E25) -> -253.896 | G12: =((BS!G10-BS!G5-BS!G6)-BS!G25)-((BS!F10-BS!F5-BS!F6)-BS!F25) -> 148.591 | H12: =((BS!H10-BS!H5-BS!H6)-BS!H25)-((BS!G10-BS!G5-BS!G6)-BS!G25) -> 197.61204 | I12: =((BS!I10-BS!I5-BS!I6)-BS!I25)-((BS!H10-BS!H5-BS!H6)-BS!H25) -> 19.447086 | J12: =((BS!J10-BS!J5-BS!J6)-BS!J25)-((BS!I10-BS!I5-BS!I6)-BS!I25) -> 213.00661 | K12: =((BS!K10-BS!K5-BS!K6)-BS!K25)-((BS!J10-BS!J5-BS!J6)-BS!J25) -> 269.7896 | L12: =((BS!L10-BS!L5-BS!L6)-BS!L25)-((BS!K10-BS!K5-BS!K6)-BS!K25) -> 175.10691 | ... O12: =((BS!O10-BS!O5-BS!O6)-BS!O25)-((BS!N10-BS!N5-BS!N6)-BS!N25) -> 176.92824 | P12: =O12*1.1 -> 194.62106 | Q12: =P12*1.1 -> 214.08317 | R12: =Q12*1.1 -> 235.49149 | S12: =R12*1.1 -> 259.04063 | T12: =S12*1.1 -> 284.9447
B13: Less: Capital expenditures | E13: =CF!I27 -> -45.302 | F13: =CF!J27 -> -56.563 | G13: =CF!K27 -> -99.421 | H13: =CF!L27 -> -93.060137 | I13: =CF!M27 -> -90.676213 | J13: =CF!N27 -> -108.68412 | K13: =CF!O27 -> -144.23648 | L13: =CF!P27 -> -166.55293 | ... T13: =CF!X27 -> -211.08949
B14: Free Cash Flow to Firm (FCFF) | E14: =SUM(E10:E13) -> -182.317 | F14: =SUM(F10:F13) -> -38.089 | G14: =SUM(G10:G13) -> 606.55232 | H14: =SUM(H10:H13) -> 937.04827 | I14: =SUM(I10:I13) -> 913.11665 | J14: =SUM(J10:J13) -> 2015.1428 | K14: =SUM(K10:K13) -> 3202.4614 | L14: =SUM(L10:L13) -> 3223.5393 | ... T14: =SUM(T10:T13) -> 6887.9391 | U14: =T14*(1+C25)/(C23-C25) -> 72867.145
B15: YoY Growth | G15: =G14/F14-1 -> -16.924606 | H15: =H14/G14-1 -> 0.54487625 | I15: =I14/H14-1 -> -0.025539369 | J15: =J14/I14-1 -> 1.2068842 | K15: =K14/J14-1 -> 0.58919826 | L15: =L14/K14-1 -> 0.006581806 | M15: =M14/L14-1 -> 0.037852565 | N15: =N14/M14-1 -> 0.060512627 | ... U15: =U14/T14-1 -> 9.5789474
B16: Present Value of FCFF | E16: =E14/(1+$C$23)^(E3-$C$26) -> -254.50807 | F16: =F14/(1+$C$23)^(F4-$C$26) -> -48.337177 | G16: =G14/(1+$C$23)^(G3-$C$26) -> 699.77319 | H16: =H14/(1+$C$23)^(H3-$C$26) -> 982.78452 | I16: =I14/(1+$C$23)^(I3-$C$26) -> 870.62257 | J16: =J14/(1+$C$23)^(J3-$C$26) -> 1746.6938 | K16: =K14/(1+$C$23)^(K3-$C$26) -> 2523.4935 | L16: =L14/(1+$C$23)^(L3-$C$26) -> 2309.1842 | M16: =M14/(1+$C$23)^(M3-$C$26) -> 2178.7207 | N16: =N14/(1+$C$23)^(N3-$C$26) -> 2100.5098 | ... T16: =T14/(1+$C$23)^(T3-$C$26) -> 2301.8309 | U16: =U14/(1+$C$23)^(U4-$C$26) -> 22137.225
B18: Sum of Discounted CF | C18: =SUM(I16:U16)+H16*0.5 -> 49207.209
B19: Net Cash | C19: =BS!H5+BS!H6-BS!H21-BS!H30 -> 2717.6959
B20: Equity Value | C20: =C18+C19 -> 51924.904
B21: Equity Value Per Share | C21: =C20/C27 -> 200.04697
B23: Discount Rate | C23: 0.1
B24: Intermediate Growth Rate
B25: Terminal Growth Rate | C25: 0.005
B26: Time of Valuation | C26: 2018.5
B27: Shares Outstanding | C27: =IS!AK52 -> 259.56357
B29: Bull / Base / Bear Scenarios
A30: 1 | B30: Selector ---> | C30: 2 | D30: 1 = Bull
A31: 2 | D31: 2 = Base
A32: 3 | D32: 3 = Bear

Sheet IS
DG1: RIC | DH1: VRTX.O
B2: VERTEX PHARMACEUTICALS INC. (NSDQ:VRTX) | C2: 1Q12 | D2: 2Q12 | E2: 3Q12 | F2: 4Q12 | G2: 2012 | H2: 1Q13A | I2: 2Q13A | J2: 3Q13A | K2: 4Q13A | L2: 2013A | M2: 1Q14A | N2: 2Q14A | O2: 3Q14A | P2: 4Q14A | Q2: 2014A | R2: 1Q15A | S2: 2Q15A | T2: 3Q15A | U2: 4Q15A | V2: 2015A | W2: 1Q16A | X2: 2Q16A | Y2: 3Q16A | Z2: 4Q16A | AA2: 2016A | AB2: 1Q17A | AC2: 2Q17A | AD2: 3Q17A | AE2: 4Q17A | AF2: 2017A | AG2: 1Q18E | AH2: 2Q18E | AI2: 3Q18E | AJ2: 4Q18E | AK2: 2018E | AL2: 1Q19E | AM2: 2Q19E | AN2: 3Q19E | AO2: 4Q19E | AP2: 2019E | AQ2: 1Q20E | AR2: 2Q20E | AS2: 3Q20E | AT2: 4Q20E | AU2: 2020E | AV2: 1Q21E | AW2: 2Q21E | AX2: 3Q21E | AY2: 4Q21E | AZ2: 2021E | BA2: 1Q22E | BB2: 2Q22E | BC2: 3Q22E | BD2: 4Q22E | BE2: 2022E | BF2: 1Q23E | BG2: 2Q23E | BH2: 3Q23E | BI2: 4Q23E | BJ2: 2023E | BK2: 1Q24E | BL2: 2Q24E | BM2: 3Q24E | BN2: 4Q24E | BO2: 2024E | BP2: 1Q25E | BQ2: 2Q25E | BR2: 3Q25E | BS2: 4Q25E | BT2: 2025E | BU2: 1Q26E | BV2: 2Q26E | BW2: 3Q26E | BX2: 4Q26E | BY2: 2026E | BZ2: 1Q27E | CA2: 2Q27E | CB2: 3Q27E | CC2: 4Q27E | CD2: 2027E | CE2: 1Q28E | CF2: 2Q28E | CG2: 3Q28E | CH2: 4Q28E | CI2: 2028E | CJ2: 1Q29E | CK2: 2Q29E | CL2: 3Q29E | CM2: 4Q29E | CN2: 2029E | CO2: 1Q30E | CP2: 2Q30E | CQ2: 3Q30E | CR2: 4Q30E | CS2: 2030E | DG2: Currency | DH2: =_xll.TR(DH$1,"TR.NetIncome.currency","Null=-") -> #NAME?
B3: Kalydeco | H3: =H84 -> 61.827 | I3: =I84 -> 98.973 | J3: =J84 -> 101.061 | K3: =K84 -> 109.424 | L3: =SUM(H3:K3) -> 371.285 | M3: =M84 -> 99.515 | N3: =N84 -> 113.055 | O3: =O84 -> 126.801 | P3: =P84 -> 124.379 | Q3: =SUM(M3:P3) -> 463.75 | R3: =R84 -> 130.174 | S3: =S84 -> 154.888 | T3: =T84 -> 165.9 | U3: =U84 -> 180.712 | V3: =SUM(R3:U3) -> 631.674 | W3: =W84 -> 170.5 | X3: =X84 -> 180 | Y3: =Y84 -> 176 | Z3: =Z84 -> 176.9 | AA3: =SUM(W3:Z3) -> 703.4 | AB3: =AB84 -> 186 | AC3: =AC84 -> 190 | AD3: =AD84 -> 213 | AE3: =AE84 -> 256 | AF3: =AE3+AD3+AC3+AB3 -> 845 | AG3: =AG84 -> 230 | AH3: =AH84 -> 235 | AI3: =AI84 -> 240 | AJ3: =AJ84 -> 244.21633 | AK3: =Revs!BO7 -> 949.21633 | AP3: =Revs!BT7 -> 980.27101 | AU3: =Revs!BY7 -> 1110.9818 | AZ3: =Revs!CD7 -> 1156.4902 | BE3: =Revs!CI7 -> 1148.5928 | BJ3: =Revs!CN7 -> 1140.8533 | BO3: =Revs!CS7 -> 1133.2686 | BT3: =Revs!CX7 -> 549.58741 | BY3: =Revs!DC7 -> 309.22509 | CD3: =Revs!DH7 -> 305.22555 | CI3: =Revs!DM7 -> 53.740211 | CN3: =Revs!DR7 -> 8.7714489 | CS3: =Revs!DW7 -> 0
B5: Deuterated Kalydeco | AK5: =Revs!BO14 -> 0 | AP5: =Revs!BT14 -> 0 | AU5: =Revs!BY14 -> 0 | AZ5: =Revs!CD14 -> 0 | BE5: =Revs!CI14 -> 0 | BJ5: =Revs!CN14 -> 0 | BO5: =Revs!CS14 -> 0 | BT5: =Revs!CX14 -> 611.54792 | BY5: =Revs!DC14 -> 787.69957 | CD5: =Revs!DH14 -> 784.24476 | CI5: =Revs!DM14 -> 1068.4306 | CN5: =Revs!DR14 -> 1069.6362 | CS5: =Revs!DW14 -> 1159.5553
B7: Orkambi | H7: =H86 -> 0 | I7: =I86 -> 0 | J7: =J86 -> 0 | K7: =K86 -> 0 | L7: =SUM(H7:K7) -> 0 | M7: =M86 -> 0 | N7: =N86 -> 0 | O7: =O86 -> 0 | P7: =P86 -> 0 | Q7: =SUM(M7:P7) -> 0 | R7: =R86 -> 0 | S7: =S86 -> 0 | T7: =T86 -> 130.8 | U7: =U86 -> 219.863 | V7: =SUM(R7:U7) -> 350.663 | W7: =W86 -> 223.91 | X7: =X86 -> 245.651 | Y7: =Y86 -> 233.689 | Z7: =Z86 -> 276.982 | AA7: =SUM(W7:Z7) -> 980.232 | AB7: =AB86 -> 294.622 | AC7: =AC86 -> 323.988 | AD7: =AD86 -> 336.642 | AE7: =AE86 -> 365.228 | AF7: =AE7+AD7+AC7+AB7 -> 1320.48 | AG7: =AG86 -> 360 | AH7: =AH86 -> 370 | AI7: =AI86 -> 380 | AJ7: =AJ86 -> 383.74949 | AK7: =Revs!BO29 -> 1493.7495 | AP7: =Revs!BT29 -> 1464.5138 | AU7: =Revs!BY29 -> 1274.3007 | AZ7: =Revs!CD29 -> 1205.8609 | BE7: =Revs!CI29 -> 1054.5016 | BJ7: =Revs!CN29 -> 899.68021 | BO7: =Revs!CS29 -> 620.57975 | BT7: =Revs!CX29 -> 388.74281 | BY7: =Revs!DC29 -> 212.1148 | CD7: =Revs!DH29 -> 110.87855 | CI7: =Revs!DM29 -> 52.19564 | CN7: =Revs!DR29 -> 17.92106 | CS7: =Revs!DW29 -> 1.4870667
B9: Symdeko | AG9: =AG87 -> 10 | AH9: =AH87 -> 40 | AI9: =AI87 -> 75 | AJ9: =AJ87 -> 94.718853 | AK9: =Revs!BO36 -> 219.71885 | AP9: =Revs!BT36 -> 485.0044 | AU9: =Revs!BY36 -> 571.63076 | AZ9: =Revs!CD36 -> 599.76369 | BE9: =Revs!CI36 -> 538.73244 | BJ9: =Revs!CN36 -> 465.68008 | BO9: =Revs!CS36 -> 291.16133 | BT9: =Revs!CX36 -> 149.56093 | BY9: =Revs!DC36 -> 78.350642 | CD9: =Revs!DH36 -> 40.13191 | CI9: =Revs!DM36 -> 15.948799 | CN9: =Revs!DR36 -> 6.1827656 | CS9: =Revs!DW36 -> 0.513038
B11: Triple Combo | AG11: =AG88 -> 0 | AH11: =AH88 -> 0 | AI11: =AI88 -> 0 | AJ11: =AJ88 -> 0 | AK11: =Revs!BO43 -> 0 | AP11: =Revs!BT43 -> 0 | AU11: =Revs!BY43 -> 1075.9316 | AZ11: =Revs!CD43 -> 2389.9398 | BE11: =Revs!CI43 -> 3438.3045 | BJ11: =Revs!CN43 -> 4043.2969 | BO11: =Revs!CS43 -> 4662.0948 | BT11: =Revs!CX43 -> 5668.0216 | BY11: =Revs!DC43 -> 7490.0759 | CD11: =Revs!DH43 -> 7760.3895 | CI11: =Revs!DM43 -> 7913.4381 | CN11: =Revs!DR43 -> 8012.4009 | CS11: =Revs!DW43 -> 8036.3479
B14: INCIVEK | H14: =H89 -> 205.554 | I14: =I89 -> 155.816 | J14: =J89 -> 85.592 | K14: =K89 -> 19.398 | L14: =SUM(H14:K14) -> 466.36 | M14: =M89+M59 -> 0 | N14: =N89+N59 -> 0 | O14: =O89+O59 -> 0 | P14: =P89+P59 -> 1.126 | Q14: =SUM(M14:P14) -> 1.126 | R14: =R89+R59 -> 0 | S14: =S89+S59 -> 0 | T14: =T89+T59 -> 0 | U14: =U89+U59 -> 0 | V14: =SUM(R14:U14) -> 0 | W14: =W89+W59 -> 0 | X14: =X89+X59 -> 0 | Y14: =Y89+Y59 -> 0 | Z14: =Z89+Z59 -> 0 | AA14: =Revs!BE23 -> 0 | AF14: =Revs!BJ23 -> 0 | AK14: =Revs!BO23 -> 0 | AP14: =Revs!BT23 -> 0 | AU14: =Revs!BY23 -> 0 | AZ14: =Revs!CD23 -> 0 | BE14: =Revs!CI23 -> 0 | BJ14: =Revs!CN23 -> 0 | BO14: =Revs!CS23 -> 0 | BT14: =Revs!CX23 -> 0 | BY14: =Revs!DC23 -> 0 | CD14: =Revs!DH23 -> 0 | CI14: =Revs!DM23 -> 0 | CN14: =Revs!DR23 -> 0 | CS14: =Revs!DW23 -> 0
B15: Net product sales | H15: =H3+H7+H14 -> 267.381 | I15: =I3+I7+I14 -> 254.789 | J15: =J3+J7+J14 -> 186.653 | K15: =K3+K7+K14 -> 128.822 | L15: =L3+L7+L14 -> 837.645 | M15: =M3+M7+M14 -> 99.515 | N15: =N3+N7+N14 -> 113.055 | O15: =O3+O7+O14 -> 126.801 | ... AA15: =AA3+AA7+AA14 -> 1683.632 | AB15: =AB83 -> 480.622 | AC15: =AC3+AC7+AC14 -> 513.988 | AD15: =AD3+AD7+AD14 -> 549.642 | AE15: =AE3+AE7+AE14 -> 621.228 | AF15: =AF3+AF7+AF14+AF9+AF11+AF5 -> 2165.48 | AG15: =AG83 -> 600 | AH15: =AH83 -> 645 | AI15: =AI83 -> 695 | AJ15: =AJ83 -> 722.68467 | AK15: =AK3+AK7+AK14+AK9+AK11+AK5 -> 2662.6847 | AP15: =AP3+AP7+AP14+AP9+AP11+AP5 -> 2929.7892 | AU15: =AU3+AU7+AU14+AU9+AU11+AU5 -> 4032.845 | AZ15: =AZ3+AZ7+AZ14+AZ9+AZ11+AZ5 -> 5352.0546 | BE15: =BE3+BE7+BE14+BE9+BE11+BE5 -> 6180.1313 | BJ15: =BJ3+BJ7+BJ14+BJ9+BJ11+BJ5 -> 6549.5105 | BO15: =BO3+BO7+BO14+BO9+BO11+BO5 -> 6707.1044 | BT15: =BT3+BT7+BT14+BT9+BT11+BT5 -> 7367.4607 | BY15: =BY3+BY7+BY14+BY9+BY11+BY5 -> 8877.466 | CD15: =CD3+CD7+CD14+CD9+CD11+CD5 -> 9000.8703 | CI15: =CI3+CI7+CI14+CI9+CI11+CI5 -> 9103.7533 | CN15: =CN3+CN7+CN14+CN9+CN11+CN5 -> 9114.9124 | CS15: =CS3+CS7+CS14+CS9+CS11+CS5 -> 9197.9033
AI16: Co. Guidance | AK16: $2,650-2,800M
B17: Collaboration and license agreement revenues | H17: =17.414+H58 -> 17.414 | I17: =6.841+I58 -> 6.841 | J17: =8.035+J58 -> 8.035 | K17: =185.448+K58 -> 3.052 | L17: =SUM(H17:K17) -> 35.342 | M17: =4.257+M60 -> 2.857 | N17: =3.087+N60 -> 1.587 | O17: =33.502+O60 -> 32.102 | P17: =10.829+P60 -> 8.029 | Q17: =SUM(M17:P17) -> 44.575 | R17: =0.842+R60 -> 0.174 | S17: =0.611+S60 -> 0 | T17: =T91+T60 -> 0.942 | U17: =U91+U60 -> 4.958 | V17: =SUM(R17:U17) -> 6.074 | W17: =W91+W60 -> 0 | X17: =X91+X60 -> 0.102 | Y17: =Y91+Y60 -> 0.216 | Z17: =Z91+Z60 -> 0.816 | AA17: =SUM(W17:Z17) -> 1.134 | AB17: =AB91+AB60 -> 0.083 | AC17: =AC91+AC60 -> 0.064 | AD17: =AD91+AD60 -> 0.001 | AE17: =AE91+AE60 -> 0.055 | AF17: =AE17+AD17+AC17+AB17 -> 0.203 | AG17: =AG91+AG60 -> 0 | AH17: =AH91+AH60 -> 0 | AI17: =AI91+AI60 -> 0 | AJ17: =AJ91+AJ60 -> 0 | AK17: =Revs!BO51 -> 0 | AP17: =Revs!BT51 -> 0 | AU17: =Revs!BY51 -> 0 | AZ17: =Revs!CD51 -> 0 | BE17: =Revs!CI51 -> 0 | BJ17: =Revs!CN51 -> 0 | BO17: =Revs!CS51 -> 0 | BT17: =Revs!CX51 -> 0 | BY17: =Revs!DC51 -> 0 | CD17: =Revs!DH51 -> 0 | CI17: =Revs!DM51 -> 0 | CN17: =Revs!DR51 -> 0 | CS17: =Revs!DW51 -> 0
B18: Royalty revenues | H18: 43.573 | I18: 49.12 | J18: 27.012 | K18: 36.887 | L18: =SUM(H18:K18) -> 156.592 | M18: =10.733+M61 -> 5.838 | N18: =13.015+N61 -> 7.334 | O18: =8.386+O61 -> 6.112 | P18: =8.785+P61 -> 7.054 | Q18: =SUM(M18:P18) -> 26.338 | R18: =6.792+R61 -> 5.292 | S18: =5.077+S61 -> 5.094 | T18: =T93+T61 -> 4.654 | U18: =U93+U61 -> 4.822 | V18: =SUM(R18:U18) -> 19.862 | W18: =W93+W61 -> 2.745 | X18: =X93+X61 -> 5.771 | Y18: =Y93+Y61 -> 3.632 | Z18: =Z93+Z61 -> 3.887 | AA18: =SUM(W18:Z18) -> 16.035 | AB18: =AB93 -> 1.551 | AC18: =AC93 -> 2.861 | AD18: =AD93 -> 2.231 | AE18: =AE93 -> 1.345 | AF18: =AE18+AD18+AC18+AB18 -> 7.988 | AG18: =AG93 -> 0 | AH18: =AH93 -> 0 | AI18: =AI93 -> 0 | AJ18: =AJ93 -> 0 | AK18: =Revs!BO50 -> 0 | AP18: =Revs!BT50 -> 0 | AU18: =Revs!BY50 -> 0 | AZ18: =Revs!CD50 -> 0 | BE18: =Revs!CI50 -> 0 | BJ18: =Revs!CN50 -> 0 | BO18: =Revs!CS50 -> 0 | BT18: =Revs!CX50 -> 0 | BY18: =Revs!DC50 -> 0 | CD18: =Revs!DH50 -> 0 | CI18: =Revs!DM50 -> 0 | CN18: =Revs!DR50 -> 0 | CS18: =Revs!DW50 -> 0
B19: Non-GAAP Revenues | H19: =H15+H17+H18 -> 328.368 | I19: =I15+I17+I18 -> 310.75 | J19: =J15+J17+J18 -> 221.7 | K19: =K15+K17+K18 -> 168.761 | L19: =L15+L17+L18 -> 1029.579 | M19: =M15+M17+M18+M57 -> 108.21 | N19: =N15+N17+N18+N57 -> 121.976 | O19: =O15+O17+O18 -> 165.015 | P19: =P15+P17+P18+P57 -> 140.588 | Q19: =Q15+Q17+Q18+Q57 -> 535.789 | R19: =R15+R17+R18+R62 -> 135.44 | S19: =S15+S17+S18+S62 -> 159.908 | T19: =T15+T17+T18+T62 -> 302.296 | U19: =U15+U17+U18+U62 -> 410.355 | V19: =V15+V17+V18+V62 -> 1007.999 | W19: =W15+W17+W18+W62 -> 397.155 | X19: =X15+X17+X18+X62 -> 431.524 | Y19: =Y15+Y17+Y18+Y62 -> 413.537 | ... AE19: =AE15+AE17+AE18+AE62 -> 622.628 | AF19: =AF15+AF17+AF18+AF57 -> 2173.671 | AG19: =AG15+AG17+AG18+AG62 -> 600 | AH19: =AH15+AH17+AH18+AH62 -> 645 | AI19: =AI15+AI17+AI18+AI62 -> 695 | AJ19: =AJ15+AJ17+AJ18+AJ62 -> 722.68467 | AK19: =AK15+AK17+AK18+AK57 -> 2662.6847 | AP19: =AP15+AP17+AP18+AP57 -> 2929.7892 | AU19: =AU15+AU17+AU18+AU57 -> 4032.845 | AZ19: =AZ15+AZ17+AZ18+AZ57 -> 5352.0546 | BE19: =BE15+BE17+BE18+BE57 -> 6180.1313 | BJ19: =BJ15+BJ17+BJ18+BJ57 -> 6549.5105 | BO19: =BO15+BO17+BO18+BO57 -> 6707.1044 | BT19: =BT15+BT17+BT18+BT57 -> 7367.4607 | BY19: =BY15+BY17+BY18+BY57 -> 8877.466 | CD19: =CD15+CD17+CD18+CD57 -> 9000.8703 | CI19: =CI15+CI17+CI18+CI57 -> 9103.7533 | CN19: =CN15+CN17+CN18+CN57 -> 9114.9124 | CS19: =CS15+CS17+CS18+CS57 -> 9197.9033
B20: Consensus Revenue | AG20: =_xll.TR($DH$1,"TR.RevenueMean","Period=#1 Curn=#2 Scale=6 Null=BLANK",,LEFT(AG$2,1)&"CQ20"&MID(AG$2,3,2),$DH$2) -> #NAME? | AH20: =_xll.TR($DH$1,"TR.RevenueMean","Period=#1 Curn=#2 Scale=6 Null=BLANK",,LEFT(AH$2,1)&"CQ20"&MID(AH$2,3,2),$DH$2) -> #NAME? | AI20: =_xll.TR($DH$1,"TR.RevenueMean","Period=#1 Curn=#2 Scale=6 Null=BLANK",,LEFT(AI$2,1)&"CQ20"&MID(AI$2,3,2),$DH$2) -> #NAME? | AJ20: =_xll.TR($DH$1,"TR.RevenueMean","Period=#1 Curn=#2 Scale=6 Null=BLANK",,LEFT(AJ$2,1)&"CQ20"&MID(AJ$2,3,2),$DH$2) -> #NAME? | AK20: =_xll.TR($DH$1,"AVAIL(TR.RevenueMean(Methodology=WeightedAnnual),TR.RevenueMean(Methodology=Interimsum))","Period=#1 Curn=#2 Scale=6 Null=BLANK",,"CY"&LEFT(AK$2,4),$DH$2) -> #NAME? | AP20: =_xll.TR($DH$1,"AVAIL(TR.RevenueMean(Methodology=WeightedAnnual),TR.RevenueMean(Methodology=Interimsum))","Period=#1 Curn=#2 Scale=6 Null=BLANK",,"CY"&LEFT(AP$2,4),$DH$2) -> #NAME? | AU20: =_xll.TR($DH$1,"AVAIL(TR.RevenueMean(Methodology=WeightedAnnual),TR.RevenueMean(Methodology=Interimsum))","Period=#1 Curn=#2 Scale=6 Null=BLANK",,"CY"&LEFT(AU$2,4),$DH$2) -> #NAME?
B22: Costs and expenses | V22: =SUM(R42:U42) -> 0.65
B23: Cost of product revenues/royalties | H23: =H98+H63 -> 42.743 | I23: =I98+I63 -> 32.848 | J23: =J98+J63 -> 22.063 | K23: =K98+K63 -> 22.264 | L23: 119.919 | M23: =M98+M63 -> 9.589 | N23: =N98+N63 -> 11.067 | O23: =O98+O63 -> 11.018 | P23: =P98+P63 -> 13.226 | Q23: 44.951 | R23: =R98+R63 -> 10.711 | S23: =S98+S63 -> 16.489 | T23: =T98+T63 -> 33.506 | U23: =U98+U63 -> 63.176 | V23: =V98+V63 -> 123.882 | W23: =W98+W63 -> 50.51 | X23: =X98+X63 -> 45.258 | Y23: =Y98+Y63 -> 54.093 | ... AE23: =AE98+AE63 -> 84.052 | AF23: =AE23+AD23+AC23+AB23 -> 275.119 | AG23: =AG98+AG63 -> 72.321663 | AH23: =AH98+AH63 -> 77.745788 | AI23: =AI98+AI63 -> 83.772594 | AJ23: =AK23-AG23-AH23-AI23 -> 87.109596 | AK23: =AK98+AK63 -> 320.94964 | AP23: =AP98+AP63 -> 354.09854 | AU23: =AU98+AU63 -> 466.44801 | AZ23: =AZ98+AZ63 -> 585.35894 | BE23: =BE98+BE63 -> 652.17576 | BJ23: =BJ98+BJ63 -> 665.53142 | BO23: =BO98+BO63 -> 650.93668 | BT23: =BT98+BT63 -> 628.91172 | BY23: =BY98+BY63 -> 726.81424 | CD23: =CD98+CD63 -> 740.2834 | CI23: =CI98+CI63 -> 721.35077 | CN23: =CN98+CN63 -> 723.58173 | CS23: =CS98+CS63 -> 723.42132
B24: Bull | R24: =R153 -> 177.174 | S24: =S153 -> 181.911 | T24: =T153 -> 201.588 | U24: =U153 -> 203.51 | V24: =SUM(R24:U24) -> 764.183 | W24: =W153 -> 222.046 | X24: =X153 -> 215 | Y24: =Y153 -> 217.51345 | Z24: =Z153 -> 219.58729 | AA24: =SUM(W24:Z24) -> 874.14674 | AE24: =AE153 -> 187.84338 | AF24: =AF153 -> 911.13157 | AK24: =AK153 -> 1066.0239 | AP24: =AP153 -> 1140.6456 | AU24: =AU153 -> 1197.6779 | AZ24: =AZ153 -> 1233.6082 | BE24: =BE153 -> 1233.6082 | BJ24: =BJ153 -> 1196.6 | BO24: =BO153 -> 1136.77 | BT24: =BT153 -> 1057.1961 | BY24: =BY153 -> 983.19236 | CD24: =CD153 -> 924.20082 | CI24: =CI153 -> 859.50676 | CN24: =CN153 -> 799.34129 | CS24: =CS153 -> 731.39728
B25: Base | R25: =R154 -> 177.174 | S25: =S154 -> 181.911 | T25: =T154 -> 201.588 | U25: =U154 -> 203.51 | V25: =SUM(R25:U25) -> 764.183 | W25: =W154 -> 222.046 | X25: =X154 -> 215 | Y25: =Y154 -> 210 | Z25: =Z154 -> 226.03308 | AA25: =SUM(W25:Z25) -> 873.07908 | AB25: =AB27 -> 226.581 | AC25: =AC27 -> 240.459 | AD25: =AD27 -> 243.212 | AE25: =AF25-AB25-AC25-AD25 -> 254.50038 | AF25: =AF154 -> 964.75238 | AK25: =AK154 -> 1109.4652 | AL25: =AL154 -> 0 | AM25: =AM154 -> 0 | AN25: =AN154 -> 0 | AO25: =AO154 -> 0 | AP25: =AP154 -> 1187.1278 | AQ25: =AQ154 -> 0 | AR25: =AR154 -> 0 | ... CS25: =CS154 -> 753.10439
B26: Bear | R26: =R155 -> 177.174 | S26: =S155 -> 181.911 | T26: =T155 -> 201.588 | U26: =U155 -> 203.51 | V26: =SUM(R26:U26) -> 764.183 | W26: =W155 -> 222.046 | X26: =X155 -> 215 | Y26: =Y155 -> 207.63564 | Z26: =Z155 -> 209.6153 | AA26: =SUM(W26:Z26) -> 854.29694 | AE26: =AE155 -> 128.18417 | AF26: =AF155 -> 708.39764 | AK26: =AK155 -> 602.13799 | AP26: =AP155 -> 451.6035 | AU26: =AU155 -> 338.70262 | AZ26: =AZ155 -> 254.02697 | BE26: =BE155 -> 190.52022 | BJ26: =BJ155 -> 142.89017 | BO26: =BO155 -> 107.16763 | BT26: =BT155 -> 80.37572 | BY26: =BY155 -> 60.28179 | CD26: =CD155 -> 45.211342 | CI26: =CI155 -> 33.908507 | CN26: =CN155 -> 25.43138 | CS26: =CS155 -> 19.073535
B27: Research & development | H27: =H101+H64 -> 194.774 | I27: =I101+I64 -> 191.189 | J27: =J101+J64 -> 200.2865 | K27: =K101+K64 -> 208.132 | L27: 787.639 | M27: =M101+M64 -> 181.535 | N27: =N101+N64 -> 179.512 | O27: =O101+O64 -> 157.383 | P27: =P101+P64 -> 175.677 | Q27: 694.192 | R27: =R101+R64 -> 177.174 | S27: =S101+S64 -> 181.911 | T27: =T101+T64 -> 201.588 | U27: =U101+U64 -> 203.51 | V27: =V101+V64 -> 764.183 | W27: =W101+W64 -> 222.046 | X27: =X101+X64 -> 217.673 | Y27: =Y101+Y64 -> 210.966 | Z27: =Z101+Z64 -> 207.085 | AA27: =SUM(W27:Z27) -> 857.77 | AB27: =AB101+AB64 -> 226.581 | AC27: =AC101+AC64 -> 240.459 | AD27: =AD101+AD64 -> 243.212 | AE27: =AE101+AE64 -> 249.234 | AF27: =AE27+AD27+AC27+AB27 -> 959.486 | AG27: =AK27/4 -> 277.36631 | AH27: =AK27/4 -> 277.36631 | AI27: =AK27/4 -> 277.36631 | AJ27: =AK27-SUM(AG27:AI27) -> 277.36631 | AK27: =CHOOSE($B$149,AK24,AK25,AK26) -> 1109.4652 | AP27: =CHOOSE($B$149,AP24,AP25,AP26) -> 1187.1278 | AU27: =CHOOSE($B$149,AU24,AU25,AU26) -> 1246.4842 | AZ27: =CHOOSE($B$149,AZ24,AZ25,AZ26) -> 1283.8787 | BE27: =CHOOSE($B$149,BE24,BE25,BE26) -> 1283.8787 | BJ27: =CHOOSE($B$149,BJ24,BJ25,BJ26) -> 1245.3624 | BO27: =CHOOSE($B$149,BO24,BO25,BO26) -> 1183.0942 | BT27: =CHOOSE($B$149,BT24,BT25,BT26) -> 1100.2776 | BY27: =CHOOSE($B$149,BY24,BY25,BY26) -> 1023.2582 | CD27: =CHOOSE($B$149,CD24,CD25,CD26) -> 951.63013 | CI27: =CHOOSE($B$149,CI24,CI25,CI26) -> 885.01602 | CN27: =CHOOSE($B$149,CN24,CN25,CN26) -> 823.0649 | CS27: =CHOOSE($B$149,CS24,CS25,CS26) -> 753.10439
B28: Bull | R28: =R161 -> 69.149 | S28: =S161 -> 72.016 | T28: =T161 -> 76.117 | U28: =U161 -> 77.63 | V28: =SUM(R28:U28) -> 294.912 | W28: =W161 -> 83.679 | X28: =X161 -> 84 | Y28: =Y161 -> 89.627768 | Z28: =Z161 -> 91.409325 | AA28: =SUM(W28:Z28) -> 348.71609 | AE28: =AE161 -> 97.598042 | AF28: =AF161 -> 376.77588 | AK28: =AK161 -> 418.22123 | AP28: =AP161 -> 439.13229 | AU28: =AU161 -> 461.08891 | AZ28: =AZ161 -> 484.14335 | BE28: =BE161 -> 508.35052 | BJ28: =BJ161 -> 533.76805 | BO28: =BO161 -> 544.44341 | BT28: =BT161 -> 555.33228 | BY28: =BY161 -> 555.33228 | CD28: =CD161 -> 555.33228 | CI28: =CI161 -> 555.33228 | CN28: =CN161 -> 555.33228 | CS28: =CS161 -> 555.33228
B29: Base | R29: =R162 -> 69.149 | S29: =S162 -> 72.016 | T29: =T162 -> 76.117 | U29: =U162 -> 77.63 | V29: =SUM(R29:U29) -> 294.912 | W29: =W162 -> 83.679 | X29: =X162 -> 84 | Y29: =Y162 -> 84 | Z29: =Z162 -> 84.52068 | AA29: =SUM(W29:Z29) -> 336.19968 | AB29: =AB31 -> 86.344 | AC29: =AC31 -> 92.906 | AD29: =AD31 -> 90.557 | AE29: =AF29-AB29-AC29-AD29 -> 94.969653 | AF29: =AF162 -> 364.77665 | AK29: =AK162 -> 404.90208 | AP29: =AP162 -> 425.14719 | AU29: =AU162 -> 446.40455 | AZ29: =AZ162 -> 468.72478 | BE29: =BE162 -> 492.16101 | BJ29: =BJ162 -> 516.76907 | BO29: =BO162 -> 527.10445 | BT29: =BT162 -> 537.64654 | BY29: =BY162 -> 537.64654 | CD29: =CD162 -> 537.64654 | CI29: =CI162 -> 537.64654 | CN29: =CN162 -> 537.64654 | CS29: =CS162 -> 537.64654
B30: Bear | R30: =R163 -> 69.149 | S30: =S163 -> 72.016 | T30: =T163 -> 76.117 | U30: =U163 -> 77.63 | V30: =SUM(R30:U30) -> 294.912 | W30: =W163 -> 83.679 | X30: =X163 -> 84 | Y30: =Y163 -> 63.253227 | Z30: =Z163 -> 64.51053 | AA30: =SUM(W30:Z30) -> 295.44276 | AE30: 90 | AF30: =AF163 -> 220.56468 | AK30: =AK163 -> 198.50822 | AP30: =AP163 -> 168.73198 | AU30: =AU163 -> 143.42219 | AZ30: =AZ163 -> 121.90886 | BE30: =BE163 -> 103.62253 | BJ30: =BJ163 -> 88.07915 | BO30: =BO163 -> 74.867278 | BT30: =BT163 -> 63.637186 | BY30: =BY163 -> 54.091608 | CD30: =CD163 -> 45.977867 | CI30: =CI163 -> 39.081187 | CN30: =CN163 -> 33.219009 | CS30: =CS163 -> 28.236157
B31: Selling, general & administrative | H31: =H102+H69 -> 79.759 | I31: =I102+I69 -> 89.517 | J31: =J102+J69 -> 74.385 | K31: =K102+K69 -> 65.448 | L31: 309.097 | M31: =M102+M69 -> 52.411 | N31: =N102+N69 -> 57.883 | O31: =O102+O69 -> 55.054 | P31: =P102+P69 -> 60.368 | Q31: 225.634 | R31: =R102+R69 -> 69.149 | S31: =S102+S69 -> 72.016 | T31: =T102+T69 -> 76.117 | U31: =U102+U69 -> 77.63 | V31: =SUM(R31:U31) -> 294.912 | W31: =W102+W69 -> 83.679 | X31: =X102+X69 -> 88.591 | Y31: =Y102+Y69 -> 83.992 | Z31: =Z102+Z69 -> 87.922 | AA31: =SUM(W31:Z31) -> 344.184 | AB31: =AB102+AB69 -> 86.344 | AC31: =AC102+AC69 -> 92.906 | AD31: =AD102+AD69 -> 90.557 | AE31: =AE102+AE69 -> 105.504 | AF31: =AE31+AD31+AC31+AB31 -> 375.311 | AG31: =AK31/4 -> 101.22552 | AH31: =AK31/4 -> 101.22552 | AI31: =AK31/4 -> 101.22552 | AJ31: =AK31-SUM(AG31:AI31) -> 101.22552 | AK31: =CHOOSE($B$149,AK28,AK29,AK30) -> 404.90208 | AP31: =CHOOSE($B$149,AP28,AP29,AP30) -> 425.14719 | AU31: =CHOOSE($B$149,AU28,AU29,AU30) -> 446.40455 | AZ31: =CHOOSE($B$149,AZ28,AZ29,AZ30) -> 468.72478 | BE31: =CHOOSE($B$149,BE28,BE29,BE30) -> 492.16101 | BJ31: =CHOOSE($B$149,BJ28,BJ29,BJ30) -> 516.76907 | BO31: =CHOOSE($B$149,BO28,BO29,BO30) -> 527.10445 | BT31: =CHOOSE($B$149,BT28,BT29,BT30) -> 537.64654 | BY31: =CHOOSE($B$149,BY28,BY29,BY30) -> 537.64654 | CD31: =CHOOSE($B$149,CD28,CD29,CD30) -> 537.64654 | CI31: =CHOOSE($B$149,CI28,CI29,CI30) -> 537.64654 | CN31: =CHOOSE($B$149,CN28,CN29,CN30) -> 537.64654 | CS31: =CHOOSE($B$149,CS28,CS29,CS30) -> 537.64654
B33: Total non-GAAP R&D and SG&A | L33: =L27+L31 -> 1096.736 | Q33: =Q27+Q31 -> 919.826 | V33: =V27+V31 -> 1059.095 | AA33: =AA27+AA31 -> 1201.954 | AF33: =AF27+AF31 -> 1334.797 | AK33: =AK27+AK31 -> 1514.3673 | AP33: =AP27+AP31 -> 1612.275 | AU33: =AU27+AU31 -> 1692.8887 | AZ33: =AZ27+AZ31 -> 1752.6035 | BE33: =BE27+BE31 -> 1776.0397 | BJ33: =BJ27+BJ31 -> 1762.1314 | BO33: =BO27+BO31 -> 1710.1987 | BT33: =BT27+BT31 -> 1637.9242 | BY33: =BY27+BY31 -> 1560.9047 | CD33: =CD27+CD31 -> 1489.2767 | CI33: =CI27+CI31 -> 1422.6626 | CN33: =CN27+CN31 -> 1360.7114 | CS33: =CS27+CS31 -> 1290.7509
AF34: Co. Guidance: $1.33-1.36B
B35: Restructuring expense, impairment charges | H35: =H104+H74 -> 0 | I35: =I104+I74 -> 0 | J35: =J104+J74 -> 0 | K35: =K104+K74 -> 0 | L35: =L104+L74 -> 0 | M35: =M104+M74 -> 0 | N35: =N104+N74 -> 0 | O35: =O104+O74 -> 0 | ... AE35: =AE104+AE74 -> 0 | AF35: =AE35+AD35+AC35+AB35 -> 0 | AG35: =AG104+AG74 -> 0 | AH35: =AH104+AH74 -> 0 | AI35: =AI104+AI74 -> 0 | AJ35: 0 | AK35: =AK104+AK74 -> 0 | AP35: =AP104+AP74 -> 0 | AU35: =AU104+AU74 -> 0 | AZ35: =AZ104+AZ74 -> 0 | BE35: =BE104+BE74 -> 0 | BJ35: =BJ104+BJ74 -> 0 | BO35: =BO104+BO74 -> 0 | BT35: =BT104+BT74 -> 0 | BY35: =BY104+BY74 -> 0 | CD35: =CD104+CD74 -> 0 | CI35: =CI104+CI74 -> 0 | CN35: =CN104+CN74 -> 0 | CS35: =CS104+CS74 -> 0
B37: Non-GAAP Operating Income (Loss) | H37: =H19-H23-H27-H31-H35 -> 11.092 | I37: =I19-I23-I27-I31-I35 -> -2.804 | J37: =J19-J23-J27-J31-J35 -> -75.0345 | K37: =K19-K23-K27-K31-K35 -> -127.083 | L37: =L19-L23-L27-L31-L35 -> -187.076 | M37: =M19-M23-M27-M31-M35 -> -135.325 | N37: =N19-N23-N27-N31-N35 -> -126.486 | O37: =O19-O23-O27-O31-O35 -> -58.44 | ... AK37: =AK19-AK23-AK27-AK31-AK35 -> 827.36771 | AP37: =AP19-AP23-AP27-AP31-AP35 -> 963.41564 | AU37: =AU19-AU23-AU27-AU31-AU35 -> 1873.5082 | AZ37: =AZ19-AZ23-AZ27-AZ31-AZ35 -> 3014.0922 | BE37: =BE19-BE23-BE27-BE31-BE35 -> 3751.9158 | BJ37: =BJ19-BJ23-BJ27-BJ31-BJ35 -> 4121.8477 | BO37: =BO19-BO23-BO27-BO31-BO35 -> 4345.9691 | BT37: =BT19-BT23-BT27-BT31-BT35 -> 5100.6248 | BY37: =BY19-BY23-BY27-BY31-BY35 -> 6589.747 | CD37: =CD19-CD23-CD27-CD31-CD35 -> 6771.3103 | CI37: =CI19-CI23-CI27-CI31-CI35 -> 6959.74 | CN37: =CN19-CN23-CN27-CN31-CN35 -> 7030.6192 | CS37: =CS19-CS23-CS27-CS31-CS35 -> 7183.7311
B39: Other income/(expense) | H39: =H110+H75 -> -4.644 | I39: =I110+I75 -> -2.853 | J39: =J110+J75 -> 4.656 | K39: =K110+K75 -> -0.011 | L39: =L110+L75 -> -3.027 | M39: =M110+M75 -> -15.266 | N39: =N110+N75 -> -14.539 | O39: =O110+O75 -> -24.374 | P39: =P110+P75 -> -24.982 | Q39: -79.148 | R39: =R110+R75 -> -26.42 | S39: =S110+S75 -> -19.697 | T39: =T110+T75 -> -22.46 | U39: =U110+U75 -> -22.344 | V39: =V110+V75 -> -90.921 | W39: =W110+W75 -> -16.076 | X39: =X110+X75 -> -21.41 | Y39: =Y110+Y75 -> -20.343 | ... AE39: =AE110+AE75 -> -13.299 | AF39: =AE39+AD39+AC39+AB39 -> -62.429 | AG39: =AG110+AG75 -> -15 | AH39: =AH110+AH75 -> -15 | AI39: =AI110+AI75 -> -15 | AJ39: =AK39-AG39-AH39-AI39 -> -15 | AK39: =AK199+AF172 -> -60 | AP39: =AP199+AK172 -> -46.411521 | AU39: =AU199+AP172 -> -32.752231 | AZ39: =AZ199+AU172 -> -7.8170204 | BE39: =BE199+AZ172 -> 38.212892 | BJ39: =BJ199+BE172 -> 100.62556 | BO39: =BO199+BJ172 -> 182.48153 | BT39: =BT199+BO172 -> 285.1824 | BY39: =BY199+BT172 -> 416.17398 | CD39: =CD199+BY172 -> 591.66805 | CI39: =CI199+CD172 -> 809.5131 | CN39: =CN199+CI172 -> 1064.8559 | CS39: =CS199+CN172 -> 1358.7763
B41: Pretax Income (Loss) | H41: =H37+H39 -> 6.448 | I41: =I37+I39 -> -5.657 | J41: =J37+J39 -> -70.3785 | K41: =K37+K39 -> -127.094 | L41: =L37+L39 -> -190.103 | M41: =M37+M39 -> -150.591 | N41: =N37+N39 -> -141.025 | O41: =O37+O39 -> -82.814 | ... AK41: =AK37+AK39 -> 767.36771 | AP41: =AP37+AP39 -> 917.00412 | AU41: =AU37+AU39 -> 1840.756 | AZ41: =AZ37+AZ39 -> 3006.2752 | BE41: =BE37+BE39 -> 3790.1287 | BJ41: =BJ37+BJ39 -> 4222.4732 | BO41: =BO37+BO39 -> 4528.4506 | BT41: =BT37+BT39 -> 5385.8072 | BY41: =BY37+BY39 -> 7005.921 | CD41: =CD37+CD39 -> 7362.9783 | CI41: =CI37+CI39 -> 7769.2531 | CN41: =CN37+CN39 -> 8095.4751 | CS41: =CS37+CS39 -> 8542.5074
B42: Income Taxes (expense) benefit | H42: =H113-H76 -> 0.699 | I42: =I113-I76 -> 0.558 | J42: =J113-J76 -> 2.555 | K42: =K113-K76 -> 4.056 | L42: =L113-L76 -> 13.651 | M42: =M113-M76 -> 0.803 | N42: =N113-N76 -> 0.693 | O42: =O113-O76 -> 3.419 | P42: =P113-P76 -> 5.919 | Q42: 3.082 | R42: =R113-R76 -> 0.362 | S42: =S113-S76 -> 0.478 | T42: =T113-T76 -> 0.553 | U42: =U113-U76 -> -0.743 | V42: =V113-V76 -> 0.65 | W42: =W113-W76 -> 2.422 | X42: =X113-X76 -> 0.62 | Y42: =Y113-Y76 -> 1.012 | Z42: =Z113-Z76 -> -4.133 | AA42: =SUM(W42:Z42) -> -0.079 | AB42: =AB113-AB76 -> 3.594 | AC42: =AC113-AC76 -> -3.795 | AD42: =AD113-AD76 -> -5.722 | AE42: =AE113-AE76 -> 12.689 | AF42: =AE42+AD42+AC42+AB42 -> 6.766 | AG42: =AG113-AG76 -> 0 | AH42: =AH113-AH76 -> 0 | AI42: =AI113-AI76 -> 0 | AJ42: =AJ113-AJ76 -> 0 | AK42: =AK182 -> 0 | AP42: =AP182 -> 0 | AU42: =AU182 -> 0 | AZ42: =AZ182 -> 0 | BE42: =BE182 -> 643.73552 | BJ42: =BJ182 -> 855.15675 | BO42: =BO182 -> 920.94188 | BT42: =BT182 -> 1105.2735 | BY42: =BY182 -> 1453.598 | CD42: =CD182 -> 1530.3653 | CI42: =CI182 -> 1617.7144 | CN42: =CN182 -> 1687.8522 | CS42: =CS182 -> 1783.9641
B43: Tax Rate | R43: =IF(R41<0,0,R42/R41) -> 0 | S43: =IF(S41<0,0,S42/S41) -> 0 | T43: =IF(T41<0,0,T42/T41) -> 0 | U43: =IF(U41<0,0,U42/U41) -> -0.017004234 | V43: 0 | W43: =IF(W41<0,0,W42/W41) -> 0.097488327 | X43: =IF(X41<0,0,X42/X41) -> 0.010581649 | Y43: =IF(Y41<0,0,Y42/Y41) -> 0.022925492 | Z43: =IF(Z41<0,0,Z42/Z41) -> -0.049607509 | AA43: =IF(AA41<0,0,AA42/AA41) -> -0.00037459754 | AB43: =IF(AB41<0,0,AB42/AB41) -> 0.034228571 | AC43: =IF(AC41<0,0,AC42/AC41) -> -0.039904524 | AD43: =IF(AD41<0,0,AD42/AD41) -> -0.043784673 | ... AJ43: =IF(AJ41<0,0,AJ42/AJ41) -> 0 | AK43: =AK42/AK41 -> 0 | AP43: =AP42/AP41 -> 0 | AU43: =AU42/AU41 -> 0 | AZ43: =AZ42/AZ41 -> 0 | BE43: =BE42/BE41 -> 0.16984529 | BJ43: =BJ42/BJ41 -> 0.20252508 | BO43: =BO42/BO41 -> 0.20336799 | BT43: =BT42/BT41 -> 0.20521966 | BY43: =BY42/BY41 -> 0.20748136 | CD43: =CD42/CD41 -> 0.20784597 | CI43: =CI42/CI41 -> 0.20822007 | CN43: =CN42/CN41 -> 0.20849328 | CS43: =CS42/CS41 -> 0.20883378
B45: Non-GAAP Net Income (Loss) from Continuing Operations | H45: =H41-H42 -> 5.749 | I45: =I41-I42 -> -6.215 | J45: =J41-J42-1.22 -> -74.1535 | K45: =K41-K42 -> -131.15 | L45: =L41-L42+0.452 -> -203.302 | M45: =M41-M42 -> -151.394 | N45: =N41-N42 -> -141.718 | O45: =O41-O42 -> -86.233 | P45: =P41-P42 -> -139.584 | Q45: =Q41-Q42 -> -511.218 | R45: =R41-R42 -> -148.376 | S45: =S41-S42 -> -130.683 | T45: =T41-T42 -> -31.928 | U45: =U41-U42 -> 44.438 | V45: =SUM(R45:U45) -> -266.549 | W45: =W41-W42 -> 22.422 | X45: =X41-X42 -> 57.972 | Y45: =Y41-Y42 -> 43.131 | Z45: =Z41-Z42 -> 87.447 | AA45: =AA41+AA42 -> 210.814 | AB45: =AB41-AB42 -> 101.406 | AC45: =AC41-AC42 -> 98.897 | AD45: =AD41-AD42 -> 136.407 | AE45: =AE41-AE42 -> 157.85 | AF45: =AF41-AF42 -> 494.56 | AG45: =AG41-AG42 -> 134.08651 | AH45: =AH41-AH42 -> 173.66238 | AI45: =AI41-AI42 -> 217.63558 | ... AK45: =AK41-AK42 -> 767.36771 | AP45: =AP41-AP42 -> 917.00412 | AU45: =AU41-AU42 -> 1840.756 | AZ45: =AZ41-AZ42 -> 3006.2752 | BE45: =BE41-BE42 -> 3146.3932 | BJ45: =BJ41-BJ42 -> 3367.3165 | BO45: =BO41-BO42 -> 3607.5087 | BT45: =BT41-BT42 -> 4280.5336 | BY45: =BY41-BY42 -> 5552.3229 | CD45: =CD41-CD42 -> 5832.613 | CI45: =CI41-CI42 -> 6151.5387 | CN45: =CN41-CN42 -> 6407.623 | CS45: =CS41-CS42 -> 6758.5433
B47: Non-GAAP EPS (basic) | H47: =H45/H135 -> 0.026687277 | I47: =I45/I135 -> -0.027988813 | J47: =J45/J135 -> -0.32170018 | K47: =K45/K135 -> -0.5671008 | L47: =L45/L135 -> -0.90394209 | M47: =M45/M135 -> -0.65007493 | N47: =N45/N135 -> -0.60612982 | O47: =O45/O135 -> -0.36518208 | ... S47: =S45/S135 -> -0.54280042 | T47: =T45/T51 -> -0.13195079 | U47: =U45/U51 -> 0.18041712 | V47: =V45/V51 -> -1.100844 | W47: =W45/W51 -> 0.090895087 | X47: =X45/X51 -> 0.23712175 | Y47: =Y45/Y51 -> 0.17390901 | Z47: =Z45/Z51 -> 0.35295471 | AA47: =AA45/AA51 -> 0.85442504 | ... AK47: =AK45/AK51 -> 2.9563768 | AP47: =AP45/AP51 -> 3.4978902 | AU47: =AU45/AU51 -> 6.9519996 | AZ47: =AZ45/AZ51 -> 11.241412 | BE47: =BE45/BE51 -> 11.648869 | BJ47: =BJ45/BJ51 -> 12.343358 | BO47: =BO45/BO51 -> 13.092887 | BT47: =BT45/BT51 -> 15.381708 | BY47: =BY45/BY51 -> 19.754225 | CD47: =CD45/CD51 -> 20.545989 | CI47: =CI45/CI51 -> 21.45489 | CN47: =CN45/CN51 -> 22.126774 | CS47: =CS45/CS51 -> 23.107495
B48: Non-GAAP EPS (diluted) | H48: =H45/H136 -> 0.026687277 | I48: =I45/I136 -> -0.027988813 | J48: =J45/J136 -> -0.32170018 | K48: =K45/K136 -> -0.5671008 | L48: =L45/L136 -> -0.90394209 | M48: =M45/M136 -> -0.65007493 | N48: =N45/N136 -> -0.60612982 | O48: =O45/O136 -> -0.36518208 | ... S48: =S45/S136 -> -0.54280042 | T48: =T45/T52 -> -0.13195079 | U48: =U45/U52 -> 0.18041712 | V48: =V45/V52 -> -1.100844 | W48: =W45/W52 -> 0.090895087 | X48: =X45/X52 -> 0.23712175 | Y48: =Y45/Y52 -> 0.17390901 | Z48: =Z45/Z52 -> 0.35295471 | AA48: =AA45/AA52 -> 0.83502375 | ... AK48: =AK45/AK52 -> 2.9563768 | AP48: =AP45/AP52 -> 3.4978902 | AU48: =AU45/AU52 -> 6.9519996 | AZ48: =AZ45/AZ52 -> 11.241412 | BE48: =BE45/BE52 -> 11.648869 | BJ48: =BJ45/BJ52 -> 12.343358 | BO48: =BO45/BO52 -> 13.092887 | BT48: =BT45/BT52 -> 15.381708 | BY48: =BY45/BY52 -> 19.754225 | CD48: =CD45/CD52 -> 20.545989 | CI48: =CI45/CI52 -> 21.45489 | CN48: =CN45/CN52 -> 22.126774 | CS48: =CS45/CS52 -> 23.107495
B49: Consensus EPS | AG49: =_xll.TR($DH$1,"TR.EPSMean","Period=#1 Curn=#2 Null=-",,LEFT(AG$2,1)&"CQ20"&MID(AG$2,3,2),$DH$2) -> #NAME? | AH49: =_xll.TR($DH$1,"TR.EPSMean","Period=#1 Curn=#2 Null=-",,LEFT(AH$2,1)&"CQ20"&MID(AH$2,3,2),$DH$2) -> #NAME? | AI49: =_xll.TR($DH$1,"TR.EPSMean","Period=#1 Curn=#2 Null=-",,LEFT(AI$2,1)&"CQ20"&MID(AI$2,3,2),$DH$2) -> #NAME? | AJ49: =_xll.TR($DH$1,"TR.EPSMean","Period=#1 Curn=#2 Null=-",,LEFT(AJ$2,1)&"CQ20"&MID(AJ$2,3,2),$DH$2) -> #NAME? | AK49: =_xll.TR($DH$1,"AVAIL(TR.EPSMean(Methodology=WeightedAnnual),TR.EPSMean(Methodology=Interimsum))","Period=#1 Curn=#2 Null=BLANK",,"CY"&LEFT(AK$2,4),$DH$2) -> #NAME? | AP49: =_xll.TR($DH$1,"AVAIL(TR.EPSMean(Methodology=WeightedAnnual),TR.EPSMean(Methodology=Interimsum))","Period=#1 Curn=#2 Null=BLANK",,"CY"&LEFT(AP$2,4),$DH$2) -> #NAME? | AU49: =_xll.TR($DH$1,"AVAIL(TR.EPSMean(Methodology=WeightedAnnual),TR.EPSMean(Methodology=Interimsum))","Period=#1 Curn=#2 Null=BLANK",,"CY"&LEFT(AU$2,4),$DH$2) -> #NAME?
B51: Basic Shares Outstanding | H51: 215.421 | I51: 222.053 | J51: 230.505 | K51: 231.264 | L51: 224.906 | M51: 232.887 | N51: 233.808 | O51: 236.137 | P51: 238.272 | Q51: 235.307 | R51: 239.493 | S51: 240.757 | T51: 241.969 | U51: 246.307 | V51: =AVERAGE(R51:U51) -> 242.1315 | W51: 246.68 | X51: 244.482 | Y51: 248.009 | Z51: 247.757 | AA51: =AVERAGE(W51:Z51) -> 246.732 | AB51: 248.7 | AC51: 251.635 | AD51: 255.792 | AE51: 256.804 | AF51: =AVERAGE(AB51:AE51) -> 253.23275 | AG51: =AK51 -> 259.56357 | AH51: =AK51 -> 259.56357 | AI51: =AK51 -> 259.56357 | AJ51: =AK51 -> 259.56357 | AK51: =AF51*1.025 -> 259.56357 | AP51: =AK51*1.01 -> 262.1592 | AU51: =AP51*1.01 -> 264.7808 | AZ51: =AU51*1.01 -> 267.4286 | BE51: =AZ51*1.01 -> 270.10289 | BJ51: =BE51*1.01 -> 272.80392 | BO51: =BJ51*1.01 -> 275.53196 | BT51: =BO51*1.01 -> 278.28728 | BY51: =BT51*1.01 -> 281.07015 | CD51: =BY51*1.01 -> 283.88085 | CI51: =CD51*1.01 -> 286.71966 | CN51: =CI51*1.01 -> 289.58686 | CS51: =CN51*1.01 -> 292.48273
B52: Diluted Shares Outstanding | H52: 215.421 | I52: 222.053 | J52: 230.505 | K52: 231.264 | L52: 224.906 | M52: =M51 -> 232.887 | N52: 233.808 | O52: 236.137 | P52: 238.272 | Q52: 235.307 | R52: =R51 -> 239.493 | S52: 240.757 | T52: =T51 -> 241.969 | U52: 246.307 | V52: =AVERAGE(R52:U52) -> 242.1315 | W52: =W51 -> 246.68 | X52: =X51 -> 244.482 | Y52: =Y51 -> 248.009 | Z52: =Z51 -> 247.757 | AA52: =U52*1.025 -> 252.46467 | AB52: =AB51 -> 248.7 | AC52: =AC51 -> 251.635 | AD52: =AD51 -> 255.792 | AE52: =AE51 -> 256.804 | AF52: =AVERAGE(AB52:AE52) -> 253.23275 | AG52: =AG51 -> 259.56357 | AH52: =AH51 -> 259.56357 | AI52: =AI51 -> 259.56357 | AJ52: =AJ51 -> 259.56357 | AK52: =AF52*1.025 -> 259.56357 | AP52: =AK52*1.01 -> 262.1592 | AU52: =AP52*1.01 -> 264.7808 | AZ52: =AU52*1.01 -> 267.4286 | BE52: =AZ52*1.01 -> 270.10289 | BJ52: =BE52*1.01 -> 272.80392 | BO52: =BJ52*1.01 -> 275.53196 | BT52: =BO52*1.01 -> 278.28728 | BY52: =BT52*1.01 -> 281.07015 | CD52: =BY52*1.01 -> 283.88085 | CI52: =CD52*1.01 -> 286.71966 | CN52: =CI52*1.01 -> 289.58686 | CS52: =CN52*1.01 -> 292.48273
L54: =+L57+L63+L64+L69+L74+L75+L76 -> -923.0845
B56: Non-GAAP Adjustments
...

Sheet MW-Cache
A1: $F$2
A2: VRTX.O,mscalc:sedolCodeCalc | B2: 2931034 | C2: VRTX.O,mscalc:targetPrice,,,,USD | D2: 200 | E2: VRTX.O,mscalc:closePriceCurrencyCalc | F2: USD

Sheet Revs
B4: Product revenue | C4: 1Q06A | D4: 2Q06A | E4: 3Q06A | F4: 4Q06A | G4: 2006 | H4: 1Q07A | I4: 2Q07A | J4: 3Q07A | K4: 4Q07A | L4: 2007 | M4: 1Q08A | N4: 2Q08A | O4: 3Q08A | P4: 4Q08A | Q4: 2008 | R4: 1Q09A | S4: 2Q09A | T4: 3Q09A | U4: 4Q09A | V4: 2009 | W4: 1Q10A | X4: 2Q10A | Y4: 3Q10A | Z4: 4Q10A | AA4: 2010 | AB4: 1Q11A | AC4: 2Q11A | AD4: 3Q11A | AE4: 4Q11A | AF4: 2011 | AG4: 1Q12A | AH4: 2Q12A | AI4: 3Q12A | AJ4: 4Q12A | AK4: 2012 | AL4: 1Q13A | AM4: 2Q13A | AN4: 3Q13A | AO4: 4Q13A | AP4: 2013 | AQ4: 1Q14A | AR4: 2Q14A | AS4: 3Q14A | AT4: 4Q14A | AU4: 2014A | AV4: 1Q15A | AW4: 2Q15A | AX4: 3Q15A | AY4: 4Q15A | AZ4: 2015A | BA4: 1Q16A | BB4: 2Q16A | BC4: 3Q16A | BD4: 4Q16A | BE4: 2016A | BF4: 1Q17A | BG4: 2Q17A | BH4: 3Q17A | BI4: 4Q17A | BJ4: 2017A | BK4: 1Q18E | BL4: 2Q18E | BM4: 3Q18E | BN4: 4Q18E | BO4: 2018E | BP4: 1Q19E | BQ4: 2Q19E | BR4: 3Q19E | BS4: 4Q19E | BT4: 2019E | BU4: 1Q20E | BV4: 2Q20E | BW4: 3Q20E | BX4: 4Q20E | BY4: 2020E | BZ4: 1Q21E | CA4: 2Q21E | CB4: 3Q21E | CC4: 4Q21E | CD4: 2021E | CE4: 1Q22E | CF4: 2Q22E | CG4: 3Q22E | CH4: 4Q22E | CI4: 2022E | CJ4: 1Q23E | CK4: 2Q23E | CL4: 3Q23E | CM4: 4Q23E | CN4: 2023E | CO4: 1Q24E | CP4: 2Q24E | CQ4: 3Q24E | CR4: 4Q24E | CS4: 2024E | CT4: 1Q25E | CU4: 2Q25E | CV4: 3Q25E | CW4: 4Q25E | CX4: 2025E | CY4: 1Q26E | CZ4: 2Q26E | DA4: 3Q26E | DB4: 4Q26E | DC4: 2026E | DD4: 1Q27E | DE4: 2Q27E | DF4: 3Q27E | DG4: 4Q27E | DH4: 2027E | DI4: 1Q28E | DJ4: 2Q28E | DK4: 3Q28E | DL4: 4Q28E | DM4: 2028E | DN4: 1Q29E | DO4: 2Q29E | DP4: 3Q29E | DQ4: 4Q29E | DR4: 2029E | DS4: 1Q30E | DT4: 2Q30E | DU4: 3Q30E | DV4: 4Q30E | DW4: 2030E
B5: Kalydeco Sales (US) | C5: 0 | D5: 0 | E5: 0 | F5: 0 | G5: =SUM(C5:F5) -> 0 | H5: 0 | I5: 0 | J5: 0 | K5: 0 | L5: =SUM(H5:K5) -> 0 | M5: 0 | N5: 0 | O5: 0 | P5: 0 | Q5: =SUM(M5:P5) -> 0 | R5: 0 | S5: 0 | T5: 0 | U5: 0 | V5: =SUM(R5:U5) -> 0 | W5: 0 | X5: 0 | Y5: 0 | Z5: 0 | AA5: =SUM(W5:Z5) -> 0 | AB5: 0 | AC5: 0 | AD5: 0 | AE5: 0 | AF5: =SUM(AB5:AE5) -> 0 | AG5: 18.448 | AH5: 45.534 | AI5: 49.161 | AJ5: 50 | AK5: =SUM(AG5:AJ5) -> 163.143 | AL5: 50 | AM5: 55 | AN5: 55 | AO5: 56 | AP5: =SUM(AL5:AO5) -> 216 | AQ5: 56 | AR5: 63 | AS5: 74 | AT5: 68 | AU5: =SUM(AQ5:AT5) -> 261 | AV5: 72 | AW5: 93 | AX5: =165.929-AX6 -> 95.029 | AY5: =180-AY6 -> 105 | AZ5: =AY5+AX5+AW5+AV5 -> 365.029 | BA5: 95 | BB5: 103 | BC5: 101 | BD5: 101 | BE5: =SUM(BA5:BD5) -> 400 | BF5: 102 | BG5: 112 | BH5: 133 | BI5: 164 | BJ5: =SUM(BF5:BI5) -> 511 | BK5: 150 | BL5: 155 | BM5: 160 | BN5: =BO5-SUM(BK5:BM5) -> 171.23235 | BO5: ='CF Market'!M327 -> 636.23235 | BT5: ='CF Market'!N327 -> 673.904 | BY5: ='CF Market'!O327 -> 719.66808 | CD5: ='CF Market'!P327 -> 761.61849 | CI5: ='CF Market'!Q327 -> 761.61849 | CN5: ='CF Market'!R327 -> 761.61849 | CS5: ='CF Market'!S327 -> 761.61849 | CX5: ='CF Market'!T327 -> 408.62116 | DC5: ='CF Market'!U327 -> 216.07716 | DH5: ='CF Market'!V327 -> 216.07716 | DM5: ='CF Market'!W327 -> 43.857245 | DR5: ='CF Market'!X327 -> 8.7714489 | DW5: ='CF Market'!Y327 -> 0
B6: Kalydeco Sales (ex-US) | C6: 0 | D6: 0 | E6: 0 | F6: 0 | G6: =SUM(C6:F6) -> 0 | H6: 0 | I6: 0 | J6: 0 | K6: 0 | L6: =SUM(H6:K6) -> 0 | M6: 0 | N6: 0 | O6: 0 | P6: 0 | Q6: =SUM(M6:P6) -> 0 | R6: 0 | S6: 0 | T6: 0 | U6: 0 | V6: =SUM(R6:U6) -> 0 | W6: 0 | X6: 0 | Y6: 0 | Z6: 0 | AA6: =SUM(W6:Z6) -> 0 | AB6: 0 | AC6: 0 | AD6: 0 | AE6: 0 | AF6: =SUM(AB6:AE6) -> 0 | AG6: 0 | AH6: 0 | AI6: 0 | AJ6: =58.5-AJ5 -> 8.5 | AK6: =SUM(AG6:AJ6) -> 8.5 | AL6: =61.8-AL5 -> 11.8 | AM6: =99-AM5 -> 44 | AN6: =101.1-AN5 -> 46.1 | AO6: =109.5-AO5 -> 53.5 | AP6: =SUM(AL6:AO6) -> 155.4 | AQ6: =99.5-AQ5 -> 43.5 | AR6: =122.319-AR5-AR19 -> 50.019 | AS6: =137.099-AS5-AS19 -> 52.799 | AT6: =124.942-AT5-AT19 -> 56.342 | AU6: =SUM(AQ6:AT6) -> 202.66 | AV6: =130.875-AV5-AV19 -> 58.2 | AW6: 62 | AX6: 70.9 | AY6: 75 | AZ6: =AY6+AX6+AW6+AV6 -> 266.1 | BA6: =BA7-BA5 -> 75.5 | BB6: =BB7-BB5 -> 77 | BC6: =BC7-BC5 -> 75 | BD6: =BD7-BD5 -> 75.9 | BE6: =SUM(BA6:BD6) -> 303.4 | BF6: =BF7-BF5 -> 84 | BG6: =BG7-BG5 -> 78 | BH6: =BH7-BH5 -> 80 | BI6: =BI7-BI5 -> 92 | BJ6: =SUM(BF6:BI6) -> 334 | BK6: 80 | BL6: 80 | BM6: 80 | BN6: =BO6-SUM(BK6:BM6) -> 72.983977 | BO6: ='CF Market'!M333+'CF Market'!M339 -> 312.98398 | BT6: ='CF Market'!N333+'CF Market'!N339 -> 306.36701 | BY6: ='CF Market'!O333+'CF Market'!O339 -> 391.31375 | CD6: ='CF Market'!P333+'CF Market'!P339 -> 394.87173 | CI6: ='CF Market'!Q333+'CF Market'!Q339 -> 386.9743 | CN6: ='CF Market'!R333+'CF Market'!R339 -> 379.23481 | CS6: ='CF Market'!S333+'CF Market'!S339 -> 371.65012 | CX6: ='CF Market'!T333+'CF Market'!T339 -> 140.96626 | DC6: ='CF Market'!U333+'CF Market'!U339 -> 93.147931 | DH6: ='CF Market'!V333+'CF Market'!V339 -> 89.148392 | DM6: ='CF Market'!W333+'CF Market'!W339 -> 9.8829666 | DR6: ='CF Market'!X333+'CF Market'!X339 -> 0 | DW6: ='CF Market'!Y333+'CF Market'!Y339 -> 0
B7: Kalydeco revenues, net | C7: =C5+C6 -> 0 | D7: =D5+D6 -> 0 | E7: =E5+E6 -> 0 | F7: =F5+F6 -> 0 | G7: =G5+G6 -> 0 | H7: =H5+H6 -> 0 | I7: =I5+I6 -> 0 | J7: =J5+J6 -> 0 | ... AS7: =AS5+AS6 -> 126.799 | AT7: =AT6+AT5 -> 124.342 | AU7: =AU5+AU6 -> 463.66 | AV7: =AV5+AV6 -> 130.2 | AW7: 154.9 | AX7: 166 | AY7: =AY5+AY6 -> 180 | AZ7: =AZ5+AZ6 -> 631.129 | BA7: =IS!W84 -> 170.5 | BB7: =IS!X84 -> 180 | BC7: =IS!Y84 -> 176 | BD7: =IS!Z84 -> 176.9 | BE7: =BE5+BE6 -> 703.4 | BF7: =IS!AB84 -> 186 | BG7: =IS!AC84 -> 190 | BH7: =IS!AD84 -> 213 | BI7: =IS!AE84 -> 256 | BJ7: =BJ5+BJ6 -> 845 | BK7: =BK5+BK6 -> 230 | BL7: =BL5+BL6 -> 235 | BM7: =BM5+BM6 -> 240 | BN7: =BN5+BN6 -> 244.21633 | BO7: =BO5+BO6 -> 949.21633 | BT7: =BT5+BT6 -> 980.27101 | BY7: =BY5+BY6 -> 1110.9818 | CD7: =CD5+CD6 -> 1156.4902 | CI7: =CI5+CI6 -> 1148.5928 | CN7: =CN5+CN6 -> 1140.8533 | CS7: =CS5+CS6 -> 1133.2686 | CX7: =CX5+CX6 -> 549.58741 | DC7: =DC5+DC6 -> 309.22509 | DH7: =DH5+DH6 -> 305.22555 | DM7: =DM5+DM6 -> 53.740211 | DR7: =DR5+DR6 -> 8.7714489 | DW7: =DW5+DW6 -> 0
BH8: Co. Guidance | BJ8: $810-830M
B9: QoQ Growth | C9: NM | D9: =IF(C7=0,"NM",D7/C7-1) -> NM | E9: =IF(D7=0,"NM",E7/D7-1) -> NM | F9: =IF(E7=0,"NM",F7/E7-1) -> NM | G9: NM | H9: =IF(F7=0,"NM",H7/F7-1) -> NM | I9: =IF(H7=0,"NM",I7/H7-1) -> NM | J9: =IF(I7=0,"NM",J7/I7-1) -> NM | K9: =IF(J7=0,"NM",K7/J7-1) -> NM | L9: NM | M9: =IF(K7=0,"NM",M7/K7-1) -> NM | N9: =IF(M7=0,"NM",N7/M7-1) -> NM | O9: =IF(N7=0,"NM",O7/N7-1) -> NM | P9: =IF(O7=0,"NM",P7/O7-1) -> NM | Q9: NM | R9: =IF(P7=0,"NM",R7/P7-1) -> NM | S9: =IF(R7=0,"NM",S7/R7-1) -> NM | T9: =IF(S7=0,"NM",T7/S7-1) -> NM | U9: =IF(T7=0,"NM",U7/T7-1) -> NM | V9: NM | W9: =IF(U7=0,"NM",W7/U7-1) -> NM | X9: =IF(W7=0,"NM",X7/W7-1) -> NM | Y9: =IF(X7=0,"NM",Y7/X7-1) -> NM | Z9: =IF(Y7=0,"NM",Z7/Y7-1) -> NM | AA9: NM | AB9: =IF(Z7=0,"NM",AB7/Z7-1) -> NM | AC9: =IF(AB7=0,"NM",AC7/AB7-1) -> NM | AD9: =IF(AC7=0,"NM",AD7/AC7-1) -> NM | AE9: =IF(AD7=0,"NM",AE7/AD7-1) -> NM | AF9: NM | AG9: =IF(AE7=0,"NM",AG7/AE7-1) -> NM | AH9: =IF(AG7=0,"NM",AH7/AG7-1) -> 1.468235 | AI9: =IF(AH7=0,"NM",AI7/AH7-1) -> 0.079654763 | AJ9: =IF(AI7=0,"NM",AJ7/AI7-1) -> 0.18996766 | AK9: NM | AL9: =IF(AJ7=0,"NM",AL7/AJ7-1) -> 0.056410256 | AM9: =IF(AL7=0,"NM",AM7/AL7-1) -> 0.60194175 | AN9: =IF(AM7=0,"NM",AN7/AM7-1) -> 0.021212121 | AO9: =IF(AN7=0,"NM",AO7/AN7-1) -> 0.083086053 | AP9: NM | AQ9: =IF(AO7=0,"NM",AQ7/AO7-1) -> -0.091324201 | AR9: =IF(AQ7=0,"NM",AR7/AQ7-1) -> 0.13586935 | AS9: =IF(AR7=0,"NM",AS7/AR7-1) -> 0.1219264 | AT9: =IF(AS7=0,"NM",AT7/AS7-1) -> -0.019377124 | AU9: NM | AV9: =IF(AT7=0,"NM",AV7/AT7-1) -> 0.047111998 | AW9: =IF(AV7=0,"NM",AW7/AV7-1) -> 0.18970814 | AX9: =IF(AW7=0,"NM",AX7/AW7-1) -> 0.071659135 | AY9: =IF(AX7=0,"NM",AY7/AX7-1) -> 0.084337349 | AZ9: NM | BA9: =IF(AY7=0,"NM",BA7/AY7-1) -> -0.052777778 | BB9: =IF(BA7=0,"NM",BB7/BA7-1) -> 0.055718475 | BC9: =IF(BB7=0,"NM",BC7/BB7-1) -> -0.022222222 | BD9: =IF(BC7=0,"NM",BD7/BC7-1) -> 0.0051136364 | BE9: NM | BF9: =IF(BD7=0,"NM",BF7/BD7-1) -> 0.051441492 | BG9: =IF(BF7=0,"NM",BG7/BF7-1) -> 0.021505376 | BH9: =IF(BG7=0,"NM",BH7/BG7-1) -> 0.12105263 | BI9: =IF(BH7=0,"NM",BI7/BH7-1) -> 0.20187793 | BJ9: NM | BK9: =IF(BI7=0,"NM",BK7/BI7-1) -> -0.1015625 | BL9: =IF(BK7=0,"NM",BL7/BK7-1) -> 0.02173913 | BM9: =IF(BL7=0,"NM",BM7/BL7-1) -> 0.021276596 | BN9: =IF(BM7=0,"NM",BN7/BM7-1) -> 0.017568033 | BO9: NM | BT9: NM | BY9: NM | CD9: NM | CI9: NM | CN9: NM | CS9: NM | CX9: NM | DC9: NM | DH9: NM | DM9: NM | DR9: NM | DW9: NM
B10: YoY Growth | C10: NM | D10: NM | E10: MN | F10: NM | G10: NM | H10: =IF(C7=0,"NM",H7/C7-1) -> NM | I10: =IF(D7=0,"NM",I7/D7-1) -> NM | J10: =IF(E7=0,"NM",J7/E7-1) -> NM | K10: =IF(F7=0,"NM",K7/F7-1) -> NM | L10: =IF(G7=0,"NM",L7/G7-1) -> NM | M10: =IF(H7=0,"NM",M7/H7-1) -> NM | N10: =IF(I7=0,"NM",N7/I7-1) -> NM | O10: =IF(J7=0,"NM",O7/J7-1) -> NM | ... BO10: =IF(BJ7=0,"NM",BO7/BJ7-1) -> 0.12333293 | BT10: =IF(BO7=0,"NM",BT7/BO7-1) -> 0.03271613 | BY10: =IF(BT7=0,"NM",BY7/BT7-1) -> 0.13334151 | CD10: =IF(BY7=0,"NM",CD7/BY7-1) -> 0.040962319 | CI10: =IF(CD7=0,"NM",CI7/CD7-1) -> -0.006828795 | CN10: =IF(CI7=0,"NM",CN7/CI7-1) -> -0.0067382331 | CS10: =IF(CN7=0,"NM",CS7/CN7-1) -> -0.006648266 | CX10: =IF(CS7=0,"NM",CX7/CS7-1) -> -0.51504223 | DC10: =IF(CX7=0,"NM",DC7/CX7-1) -> -0.43735049 | DH10: =IF(DC7=0,"NM",DH7/DC7-1) -> -0.01293407 | DM10: =IF(DH7=0,"NM",DM7/DH7-1) -> -0.82393279 | DR10: =IF(DM7=0,"NM",DR7/DM7-1) -> -0.83678053 | DW10: =IF(DR7=0,"NM",DW7/DR7-1) -> -1
B12: Deuterated Kalydeco Sales (US) | BJ12: ='CF Market'!L328 -> 0 | BO12: ='CF Market'!M328 -> 0 | BT12: ='CF Market'!N328 -> 0 | BY12: ='CF Market'!O328 -> 0 | CD12: ='CF Market'!P328 -> 0 | CI12: ='CF Market'!Q328 -> 0 | CN12: ='CF Market'!R328 -> 0 | CS12: ='CF Market'!S328 -> 0 | CX12: ='CF Market'!T328 -> 388.29707 | DC12: ='CF Market'!U328 -> 529.496 | DH12: ='CF Market'!V328 -> 529.496 | DM12: ='CF Market'!W328 -> 741.2944 | DR12: ='CF Market'!X328 -> 741.2944 | DW12: ='CF Market'!Y328 -> 837.78034
B13: Deuterated Kalydeco Sales (ex-US) | BJ13: ='CF Market'!L334+'CF Market'!L340 -> 0 | BO13: ='CF Market'!M334+'CF Market'!M340 -> 0 | BT13: ='CF Market'!N334+'CF Market'!N340 -> 0 | BY13: ='CF Market'!O334+'CF Market'!O340 -> 0 | CD13: ='CF Market'!P334+'CF Market'!P340 -> 0 | CI13: ='CF Market'!Q334+'CF Market'!Q340 -> 0 | CN13: ='CF Market'!R334+'CF Market'!R340 -> 0 | CS13: ='CF Market'!S334+'CF Market'!S340 -> 0 | CX13: ='CF Market'!T334+'CF Market'!T340 -> 223.25086 | DC13: ='CF Market'!U334+'CF Market'!U340 -> 258.20357 | DH13: ='CF Market'!V334+'CF Market'!V340 -> 254.74876 | DM13: ='CF Market'!W334+'CF Market'!W340 -> 327.13624 | DR13: ='CF Market'!X334+'CF Market'!X340 -> 328.34176 | DW13: ='CF Market'!Y334+'CF Market'!Y340 -> 321.77493
B14: Deuterated Kalydeco revenues, net | BJ14: =BJ12+BJ13 -> 0 | BO14: =BO12+BO13 -> 0 | BT14: =BT12+BT13 -> 0 | BY14: =BY12+BY13 -> 0 | CD14: =CD12+CD13 -> 0 | CI14: =CI12+CI13 -> 0 | CN14: =CN12+CN13 -> 0 | CS14: =CS12+CS13 -> 0 | CX14: =CX12+CX13 -> 611.54792 | DC14: =DC12+DC13 -> 787.69957 | DH14: =DH12+DH13 -> 784.24476 | DM14: =DM12+DM13 -> 1068.4306 | DR14: =DR12+DR13 -> 1069.6362 | DW14: =DW12+DW13 -> 1159.5553
B16: QoQ Growth | C16: NM | D16: =IF(C10=0,"NM",D10/C10-1) -> #VALUE! | E16: =IF(D10=0,"NM",E10/D10-1) -> #VALUE! | F16: =IF(E10=0,"NM",F10/E10-1) -> #VALUE! | G16: NM | H16: =IF(F10=0,"NM",H10/F10-1) -> #VALUE! | I16: =IF(H10=0,"NM",I10/H10-1) -> #VALUE! | J16: =IF(I10=0,"NM",J10/I10-1) -> #VALUE! | K16: =IF(J10=0,"NM",K10/J10-1) -> #VALUE! | L16: NM | M16: =IF(K10=0,"NM",M10/K10-1) -> #VALUE! | N16: =IF(M10=0,"NM",N10/M10-1) -> #VALUE! | O16: =IF(N10=0,"NM",O10/N10-1) -> #VALUE! | P16: =IF(O10=0,"NM",P10/O10-1) -> #VALUE! | Q16: NM | R16: =IF(P10=0,"NM",R10/P10-1) -> #VALUE! | S16: =IF(R10=0,"NM",S10/R10-1) -> #VALUE! | T16: =IF(S10=0,"NM",T10/S10-1) -> #VALUE! | U16: =IF(T10=0,"NM",U10/T10-1) -> #VALUE! | V16: NM | W16: =IF(U10=0,"NM",W10/U10-1) -> #VALUE! | X16: =IF(W10=0,"NM",X10/W10-1) -> #VALUE! | Y16: =IF(X10=0,"NM",Y10/X10-1) -> #VALUE! | Z16: =IF(Y10=0,"NM",Z10/Y10-1) -> #VALUE! | AA16: NM | AB16: =IF(Z10=0,"NM",AB10/Z10-1) -> #VALUE! | AC16: =IF(AB10=0,"NM",AC10/AB10-1) -> #VALUE! | AD16: =IF(AC10=0,"NM",AD10/AC10-1) -> #VALUE! | AE16: =IF(AD10=0,"NM",AE10/AD10-1) -> #VALUE! | BJ16: NM | BO16: NM | BT16: NM | BY16: NM | CD16: NM | CI16: NM | CN16: NM | CS16: NM | CX16: NM | DC16: NM | DH16: NM | DM16: NM | DR16: NM | DW16: NM
B17: YoY Growth | C17: NM | D17: NM | E17: MN | F17: NM | G17: NM | H17: =IF(C10=0,"NM",H10/C10-1) -> #VALUE! | I17: =IF(D10=0,"NM",I10/D10-1) -> #VALUE! | J17: =IF(E10=0,"NM",J10/E10-1) -> #VALUE! | K17: =IF(F10=0,"NM",K10/F10-1) -> #VALUE! | L17: =IF(G10=0,"NM",L10/G10-1) -> #VALUE! | M17: =IF(H10=0,"NM",M10/H10-1) -> #VALUE! | N17: =IF(I10=0,"NM",N10/I10-1) -> #VALUE! | O17: =IF(J10=0,"NM",O10/J10-1) -> #VALUE! | ... AE17: =IF(Z10=0,"NM",AE10/Z10-1) -> #VALUE! | BJ17: =IF(BE14=0,"NM",BJ14/BE14-1) -> NM | BO17: =IF(BJ14=0,"NM",BO14/BJ14-1) -> NM | BT17: =IF(BO14=0,"NM",BT14/BO14-1) -> NM | BY17: =IF(BT14=0,"NM",BY14/BT14-1) -> NM | CD17: =IF(BY14=0,"NM",CD14/BY14-1) -> NM | CI17: =IF(CD14=0,"NM",CI14/CD14-1) -> NM | CN17: =IF(CI14=0,"NM",CN14/CI14-1) -> NM | CS17: =IF(CN14=0,"NM",CS14/CN14-1) -> NM | CX17: =IF(CS14=0,"NM",CX14/CS14-1) -> NM | DC17: =IF(CX14=0,"NM",DC14/CX14-1) -> 0.28804226 | DH17: =IF(DC14=0,"NM",DH14/DC14-1) -> -0.004385945 | DM17: =IF(DH14=0,"NM",DM14/DH14-1) -> 0.36236886 | DR17: =IF(DM14=0,"NM",DR14/DM14-1) -> 0.0011283099 | DW17: =IF(DR14=0,"NM",DW14/DR14-1) -> 0.084065129
B19: Incivek sale (US) | C19: 0 | D19: 0 | E19: 0 | F19: 0 | G19: =SUM(C19:F19) -> 0 | H19: 0 | I19: 0 | J19: 0 | K19: 0 | L19: =SUM(H19:K19) -> 0 | M19: 0 | N19: 0 | O19: 0 | P19: 0 | Q19: =SUM(M19:P19) -> 0 | R19: 0 | S19: 0 | T19: 0 | U19: 0 | V19: =SUM(R19:U19) -> 0 | W19: 0 | X19: 0 | Y19: 0 | Z19: 0 | AA19: =SUM(W19:Z19) -> 0 | AB19: 0 | AC19: 74.535 | AD19: 419.595 | AE19: 456.759 | AF19: =SUM(AB19:AE19) -> 950.889 | AG19: 356.927 | AH19: 327.739 | AI19: 254.34 | AJ19: 222.809 | AK19: =SUM(AG19:AJ19) -> 1161.815 | AL19: =267.381-AL7 -> 205.581 | AM19: =254.789-AM7 -> 155.789 | AN19: 85.553 | AO19: 19.322 | AP19: =SUM(AL19:AO19) -> 466.245 | AQ19: =103.461-AQ7 -> 3.961 | AR19: 9.3 | AS19: 10.3 | AT19: 0.6 | AU19: =SUM(AQ19:AT19) -> 24.161 | AV19: =138.509-130.2-AV50-AV51 -> 0.675 | AW19: 5.488 | AX19: 0 | AY19: 0 | AZ19: =SUM(AV19:AY19) -> 6.163 | BA19: 0 | BB19: 0 | BC19: 0 | BD19: 0 | BE19: =SUM(BA19:BD19) -> 0 | BJ19: =SUM(BF19:BI19) -> 0 | BO19: =SUM(BK19:BN19) -> 0 | BT19: =SUM(BP19:BS19) -> 0 | BY19: =SUM(BU19:BX19) -> 0 | CD19: =SUM(BZ19:CC19) -> 0 | CI19: =SUM(CE19:CH19) -> 0 | CN19: =SUM(CJ19:CM19) -> 0 | CS19: =SUM(CO19:CR19) -> 0 | CX19: =SUM(CT19:CW19) -> 0 | DC19: =SUM(CY19:DB19) -> 0 | DH19: =SUM(DD19:DG19) -> 0 | DM19: =SUM(DI19:DL19) -> 0 | DR19: =SUM(DN19:DQ19) -> 0 | DW19: =SUM(DS19:DV19) -> 0
B20: Incivek sale (ex-US) | C20: 0 | D20: 0 | E20: 0 | F20: 0 | G20: =SUM(C20:F20) -> 0 | H20: 0 | I20: 0 | J20: 0 | K20: 0 | L20: =SUM(H20:K20) -> 0 | M20: 0 | N20: 0 | O20: 0 | P20: 0 | Q20: =SUM(M20:P20) -> 0 | R20: 0 | S20: 0 | T20: 0 | U20: 0 | V20: =SUM(R20:U20) -> 0 | W20: 0 | X20: 0 | Y20: 0 | Z20: 0 | AA20: =SUM(W20:Z20) -> 0 | AB20: 0 | AC20: 0 | AD20: 0 | AE20: 72 | AF20: =SUM(AB20:AE20) -> 72 | AG20: 132 | AH20: 102 | AI20: 71 | AJ20: 138 | AK20: =SUM(AG20:AJ20) -> 443 | AL20: 162 | AM20: 172 | AN20: 76 | AO20: 0 | AP20: =SUM(AL20:AO20) -> 410 | AQ20: 0 | AR20: 0 | AS20: 0 | AT20: 0 | AU20: =SUM(AQ20:AT20) -> 0 | AV20: 0 | AW20: 0 | AX20: 0 | AY20: 0 | AZ20: =SUM(AV20:AY20) -> 0 | BA20: 0 | BB20: 0 | BC20: 0 | BD20: 0 | BE20: =SUM(BA20:BD20) -> 0 | BJ20: =SUM(BF20:BI20) -> 0 | BO20: =SUM(BK20:BN20) -> 0 | BT20: =SUM(BP20:BS20) -> 0 | BY20: =SUM(BU20:BX20) -> 0 | CD20: =SUM(BZ20:CC20) -> 0 | CI20: =SUM(CE20:CH20) -> 0 | CN20: =SUM(CJ20:CM20) -> 0 | CS20: =SUM(CO20:CR20) -> 0 | CX20: =SUM(CT20:CW20) -> 0 | DC20: =SUM(CY20:DB20) -> 0 | DH20: =SUM(DD20:DG20) -> 0 | DM20: =SUM(DI20:DL20) -> 0 | DR20: =SUM(DN20:DQ20) -> 0 | DW20: =SUM(DS20:DV20) -> 0
B22: Incivek royalty (ex-US) | C22: 0 | D22: 0 | E22: 0 | F22: 0 | G22: =SUM(C22:F22) -> 0 | H22: 0 | I22: 0 | J22: 0 | K22: 0 | L22: =SUM(H22:K22) -> 0 | M22: 0 | N22: 0 | O22: 0 | P22: 0 | Q22: =SUM(M22:P22) -> 0 | R22: 0 | S22: 0 | T22: 0 | U22: 0 | V22: =SUM(R22:U22) -> 0 | W22: 0 | X22: 0 | Y22: 0 | Z22: 0 | AA22: =SUM(W22:Z22) -> 0 | AB22: 0 | AC22: 0 | AD22: 0 | AE22: =25.405-AE50 -> 20.315 | AF22: =SUM(AB22:AE22) -> 20.315 | AG22: 32.884 | AH22: 27.97 | AI22: 19.957 | AJ22: =36.8 -> 36.8 | AK22: =SUM(AG22:AJ22) -> 117.611 | AL22: 39 | AM22: 44.1 | AN22: 21 | AO22: 26.387 | AP22: =SUM(AL22:AO22) -> 130.487 | AQ22: 0 | AR22: 0 | AS22: 0 | AT22: 0 | AU22: =SUM(AQ22:AT22) -> 0 | AV22: 0 | AW22: 0 | AX22: 0 | AY22: 0 | AZ22: =SUM(AV22:AY22) -> 0 | BA22: 0 | BB22: 0 | BC22: 0 | BD22: 0 | BE22: =SUM(BA22:BD22) -> 0 | BJ22: =SUM(BF22:BI22) -> 0 | BO22: =SUM(BK22:BN22) -> 0 | BT22: =SUM(BP22:BS22) -> 0 | BY22: =SUM(BU22:BX22) -> 0 | CD22: =SUM(BZ22:CC22) -> 0 | CI22: =SUM(CE22:CH22) -> 0 | CN22: =SUM(CJ22:CM22) -> 0 | CS22: =SUM(CO22:CR22) -> 0 | CX22: =SUM(CT22:CW22) -> 0 | DC22: =SUM(CY22:DB22) -> 0 | DH22: =SUM(DD22:DG22) -> 0 | DM22: =SUM(DI22:DL22) -> 0 | DR22: =SUM(DN22:DQ22) -> 0 | DW22: =SUM(DS22:DV22) -> 0
