Workbook
Name _Agreement1: AGREEMENTS!$H$9:$S$83
Name _Agreement2: AGREEMENTS!$H$84:$S$146
Name _AIS: 'IS-ANNUAL'!$H$9:$CE$79
Name _ARev1: 'REV-ANNUAL'!$H$9:$CE$82
Name _ARev2: 'REV-ANNUAL'!$H$106:$CE$217
Name _ARev3: 'REV-ANNUAL'!$H$219:$CE$237
Name _ARev4: 'REV-ANNUAL'!$H$239:$CE$333
Name _ARev5: 'REV-ANNUAL'!$H$336:$CE$447
Name _ARev6: 'REV-ANNUAL'!$H$449:$CE$467
Name _BS: CFBS!$H$64:$CE$115
Name _CF: CFBS!$H$9:$CE$59
Name _DCF: DCF!$H$9:$CE$59
Name _FCF: DCF!$H$9:$CE$14
Name _FinMet: CFBS!$H$120:$CE$183
Name _Footnotes: FOOTNOTES!$H$10:$P$268
Name _MgmtProj: 'MGMT PROJECTIONS'!$H$10:$O$22
Name _Pipe1: PIPELINE!$H$9:$CE$45
Name _Pipe2: PIPELINE!$H$46:$CE$78
Name _TheoPipe: PIPELINE!$H$80:$CE$91
Name AdditionalInstructions: IndexInformation!$B$42
Name Address: ImportantDisclosures!$A$2:$A$2
Name ANA: ModPubIndex!$A$7
Name Authors: ImportantDisclosures!$A$7
Name Authors: IndexInformation!$B$18
Name BRO: ModPubIndex!$A$1
Name CompanyName: summary!$J$7
Name CompanyName: summary!$J$7
Name CompanyName: summary!$J$7
Name CompanyName: summary!$J$7
Name CompanyName: summary!$J$7
Name CompanyName: summary!$J$7
Name CompanyName: summary!$J$7
Name CompanyName: summary!$J$7
Name CompanyName: summary!$J$7
Name CompanyName: summary!$J$7
Name CompanyName: summary!$J$7
Name CompanyTicker: summary!$J$8
Name CompanyTicker: summary!$J$8
Name CopyrightStamp: ImportantDisclosures!$A$27
Name COU: ModPubIndex!$A$5
Name CQEnd: IndexInformation!$B$31
Name Currency: IndexInformation!$B$24
Name CurrentStockPrice: IndexInformation!$B$23
Name CurrPrice: [11]summary!$J$16
Name CurrQtrEPS: IndexInformation!$B$29
Name CurrYearEPS: IndexInformation!$B$11
Name CurrYearTotalRevenue: IndexInformation!$B$10
Name CurrYearTotalRevenueActual: IndexInformation!$B$32
Name CUSIP: IndexInformation!$B$20
Name CYEnd: IndexInformation!$B$30
Name dataseries4: OFFSET([12]c1!$G$12,0,0,COUNTA([12]c1!$G$12:$G$31),1)
Name Date: ImportantDisclosures!$A$8
Name Deleted: IndexInformation!$B$27
Name Description: IndexInformation!$B$7
Name Discipline: IndexInformation!$B$3
Name DISCIPLINE: ModPubIndex!$A$12
Name DisclosuresText: ImportantDisclosures!$A$22
Name Distribution: IndexInformation!$B$26
Name DistTable: ImportantDisclosures!#REF!
Name DistTablePreamble: ImportantDisclosures!#REF!

Sheet summary
FZ1: Section Header
L4: 38442 | M4: 38533 | N4: 38625 | O4: 38717 | P4: 38717 | Q4: 38807 | R4: 38898 | S4: 38990 | T4: 39082 | U4: 39082 | V4: 39172 | W4: 39263 | X4: 39355 | Y4: 39447 | Z4: 39447 | AA4: 39538 | AB4: 39629 | AC4: 39721 | AD4: 39813 | AE4: 39813 | AF4: 39903 | AG4: 39994 | AH4: 40086 | AI4: 40178 | AJ4: 40178 | AK4: 40268 | AL4: 40359 | AM4: 40451 | AN4: 40543 | AO4: 40543 | AP4: 40633 | AQ4: 40724 | AR4: 40816 | AS4: 40908 | AT4: 40908 | AU4: 40999 | AV4: 41090 | AW4: 41182 | AX4: 41274 | AY4: 41274 | AZ4: 41364 | BA4: 41455 | BB4: 41547 | BC4: 41639 | BD4: 41639 | BE4: 41729 | BF4: 41820 | BG4: 41912 | BH4: 42004 | BI4: 42004 | BJ4: 42094 | BK4: 42185 | BL4: 42277 | BM4: 42369 | BN4: 42369 | BO4: 42460 | BP4: 42551 | BQ4: 42643 | BR4: 42735 | BS4: 42735 | BT4: 42825 | BU4: 42916 | BV4: 43008 | BW4: 43100 | BX4: 43100 | BY4: 43190 | BZ4: 43281 | CA4: 43373 | CB4: 43465 | CC4: 43465 | CD4: 43555 | CE4: 43646 | CF4: 43738 | CG4: 43830 | CH4: 43830 | CI4: 43921 | CJ4: 44012 | CK4: 44104 | CL4: 44196 | CM4: 44196
H5: =CompanyName -> Eli Lilly & Co. | J5: =LatestRpQ -> 43190
H6: summary page | J6: =LatestFiledQ -> 43100
H7: Company name | J7: Eli Lilly & Co.
H8: Ticker | J8: LLY
H9: TRSL ticker | J9: LLY-N
H10: Latest reported quarter | J10: 43190
H11: Latest filed quarter | J11: 43100 | CP11: Bear | CQ11: Rev disapointment | CR11: Base | CS11: EPS upside | CT11: M&A | CU11: PE expan | CV11: Bull
H12: Rating | J12: Equal-weight | CQ12: 23 | CS12: 5 | CT12: 5 | CU12: 9
H13: Price Target | J13: 93 | CP13: =CQ13 -> 67 | CQ13: =CR13-CQ12 -> 67 | CR13: 90 | CS13: =CR13 -> 90 | CT13: =CS12+CS13 -> 95 | CU13: =CT12+CT13 -> 100 | CV13: =CU12+CU13 -> 109
H14: Date Last Updated | J14: 43214
H15: MW ticker | J15: LLY.N
H17: Price | J17: =_xll.ThomsonONEAddinShim.SpreadsheetFormulas.TF($J$9,"TF.PR.PriceClose()") -> $80.09 | K17: =_xll.ThomsonONEAddinShim.SpreadsheetFormulas.TF(FDS_ticker, "TF.PR.Pricedate()") -> 43214
H18: Shares Outstanding (Qtr) | J18: ='IS-ANNUAL'!BN50 -> 1065.668
H19: Market Cap | J19: =J18*J17 -> 85349.35
H21: Net Debt (Qtr) | J21: =CFBS!BI172 -> 3194.5
H23: Total Enterprise Value | J23: =J19+J21 -> 88543.85
H24: No. of Employees | J24: 38270
H25: Current Quarter EPS | J25: ='IS-ANNUAL'!BC49 -> 0.73857064
H26: Date | J26: =LatestRpQ -> 43190
H27: Last Year's Quarter EPS | J27: ='IS-ANNUAL'!AX49 -> 0.84857317
H29: Stockholder's Equity (Yr) | J29: =CFBS!AY113 -> 14773.9
H30: Book Value per share (Qtr) | J30: =CFBS!BB156 -> 15.583114
H31: LT Debt/Total Capital | J31: =CFBS!AY176 -> 0.27240805
H32: Date | J32: =CFBS!AY9 -> 2012A
H34: IBES Growth Rate | J34: =_xll.ThomsonONEAddinShim.SpreadsheetFormulas.TF(FDS_ticker, "TF.ES.EPS.LTGMean()") -> 0.12 | AE34: =78/4.51 -> 17.2949
H36: Beginning year | J36: 2016a | K36: 2017e | AE36: =AE34/9 -> 1.9216556
H37: Ending year | J37: 2020e | K37: 2020E
H38: CAGR number of yrs | J38: 4 | K38: 3
J40: =J36 & "–" & J37 & " CAGR" -> 2016a–2020e CAGR | K40: =K36 & "–" & K37 & " CAGR" -> 2017e–2020E CAGR
H41: ='IS-ANNUAL'!H11 -> Total revenues | J41: =(INDEX('IS-ANNUAL'!$11:$11,0,MATCH(summary!$J$37,'IS-ANNUAL'!$9:$9,0))/INDEX('IS-ANNUAL'!$11:$11,0,MATCH(summary!$J$36,'IS-ANNUAL'!$9:$9,0)))^(1/$J$38)-1 -> 0.047269598 | K41: =(INDEX('IS-ANNUAL'!$11:$11,0,MATCH(summary!$K$37,'IS-ANNUAL'!$9:$9,0))/INDEX('IS-ANNUAL'!$11:$11,0,MATCH(summary!$K$36,'IS-ANNUAL'!$9:$9,0)))^(1/$K$38)-1 -> #N/A
H42: ='IS-ANNUAL'!H24 -> COGS | J42: =(INDEX('IS-ANNUAL'!$24:$24,0,MATCH(summary!$J$37,'IS-ANNUAL'!$9:$9,0))/INDEX('IS-ANNUAL'!$24:$24,0,MATCH(summary!$J$36,'IS-ANNUAL'!$9:$9,0)))^(1/$J$38)-1 -> 0.04754276 | K42: =(INDEX('IS-ANNUAL'!$24:$24,0,MATCH(summary!$K$37,'IS-ANNUAL'!$9:$9,0))/INDEX('IS-ANNUAL'!$24:$24,0,MATCH(summary!$K$36,'IS-ANNUAL'!$9:$9,0)))^(1/$K$38)-1 -> #N/A
H43: ='IS-ANNUAL'!H25 -> Gross profit | J43: =(INDEX('IS-ANNUAL'!$25:$25,0,MATCH(summary!$J$37,'IS-ANNUAL'!$9:$9,0))/INDEX('IS-ANNUAL'!$25:$25,0,MATCH(summary!$J$36,'IS-ANNUAL'!$9:$9,0)))^(1/$J$38)-1 -> 0.047185756 | K43: =(INDEX('IS-ANNUAL'!$25:$25,0,MATCH(summary!$K$37,'IS-ANNUAL'!$9:$9,0))/INDEX('IS-ANNUAL'!$25:$25,0,MATCH(summary!$K$36,'IS-ANNUAL'!$9:$9,0)))^(1/$K$38)-1 -> #N/A
H44: ='IS-ANNUAL'!H28 -> R&D | J44: =(INDEX('IS-ANNUAL'!$28:$28,0,MATCH(summary!$J$37,'IS-ANNUAL'!$9:$9,0))/INDEX('IS-ANNUAL'!$28:$28,0,MATCH(summary!$J$36,'IS-ANNUAL'!$9:$9,0)))^(1/$J$38)-1 -> 0.0032337096 | K44: =(INDEX('IS-ANNUAL'!$28:$28,0,MATCH(summary!$K$37,'IS-ANNUAL'!$9:$9,0))/INDEX('IS-ANNUAL'!$28:$28,0,MATCH(summary!$K$36,'IS-ANNUAL'!$9:$9,0)))^(1/$K$38)-1 -> #N/A
H45: ='IS-ANNUAL'!H26 -> SG&A | J45: =(INDEX('IS-ANNUAL'!$26:$26,0,MATCH(summary!$J$37,'IS-ANNUAL'!$9:$9,0))/INDEX('IS-ANNUAL'!$26:$26,0,MATCH(summary!$J$36,'IS-ANNUAL'!$9:$9,0)))^(1/$J$38)-1 -> -0.0029484618 | K45: =(INDEX('IS-ANNUAL'!$26:$26,0,MATCH(summary!$K$37,'IS-ANNUAL'!$9:$9,0))/INDEX('IS-ANNUAL'!$26:$26,0,MATCH(summary!$K$36,'IS-ANNUAL'!$9:$9,0)))^(1/$K$38)-1 -> #N/A
H46: ='IS-ANNUAL'!H29 -> Operating income, EBITA | J46: =(INDEX('IS-ANNUAL'!$29:$29,0,MATCH(summary!$J$37,'IS-ANNUAL'!$9:$9,0))/INDEX('IS-ANNUAL'!$29:$29,0,MATCH(summary!$J$36,'IS-ANNUAL'!$9:$9,0)))^(1/$J$38)-1 -> 0.14608052 | K46: =(INDEX('IS-ANNUAL'!$29:$29,0,MATCH(summary!$K$37,'IS-ANNUAL'!$9:$9,0))/INDEX('IS-ANNUAL'!$29:$29,0,MATCH(summary!$K$36,'IS-ANNUAL'!$9:$9,0)))^(1/$K$38)-1 -> #N/A
H47: ='IS-ANNUAL'!H44 -> Pretax income | J47: =(INDEX('IS-ANNUAL'!$44:$44,0,MATCH(summary!$J$37,'IS-ANNUAL'!$9:$9,0))/INDEX('IS-ANNUAL'!$44:$44,0,MATCH(summary!$J$36,'IS-ANNUAL'!$9:$9,0)))^(1/$J$38)-1 -> 0.14489102 | K47: =(INDEX('IS-ANNUAL'!$44:$44,0,MATCH(summary!$K$37,'IS-ANNUAL'!$9:$9,0))/INDEX('IS-ANNUAL'!$44:$44,0,MATCH(summary!$K$36,'IS-ANNUAL'!$9:$9,0)))^(1/$K$38)-1 -> #N/A
H48: ='IS-ANNUAL'!H47 -> Net income | J48: =(INDEX('IS-ANNUAL'!$47:$47,0,MATCH(summary!$J$37,'IS-ANNUAL'!$9:$9,0))/INDEX('IS-ANNUAL'!$47:$47,0,MATCH(summary!$J$36,'IS-ANNUAL'!$9:$9,0)))^(1/$J$38)-1 -> 0.15766638 | K48: =(INDEX('IS-ANNUAL'!$47:$47,0,MATCH(summary!$K$37,'IS-ANNUAL'!$9:$9,0))/INDEX('IS-ANNUAL'!$47:$47,0,MATCH(summary!$K$36,'IS-ANNUAL'!$9:$9,0)))^(1/$K$38)-1 -> #N/A
H49: ='IS-ANNUAL'!H49 -> Adj. Dil. EPS | J49: =(INDEX('IS-ANNUAL'!$49:$49,0,MATCH(summary!$J$37,'IS-ANNUAL'!$9:$9,0))/INDEX('IS-ANNUAL'!$49:$49,0,MATCH(summary!$J$36,'IS-ANNUAL'!$9:$9,0)))^(1/$J$38)-1 -> 0.16275907 | K49: =(INDEX('IS-ANNUAL'!$49:$49,0,MATCH(summary!$K$37,'IS-ANNUAL'!$9:$9,0))/INDEX('IS-ANNUAL'!$49:$49,0,MATCH(summary!$K$36,'IS-ANNUAL'!$9:$9,0)))^(1/$K$38)-1 -> #N/A
...

Sheet ImportantDisclosures
A2: 1585 Broadway
A3: New York, NY 10036-8293
A4: United States
A5: Tel: +1 (1)212 761 4000
A7: Authors: David Risinger
A8: Date: 25 Apr 2018
A10: Ticker: LLY.N
A11: Stock Rating: Equal-Weight
A12: Industry: Major Pharmaceuticals
A13: Industry View: In-Line
A14: Price as of 25 Apr 2018: 80.09
A15: Target Price: 93
... A126: Equal-weight and Not-Rated to hold and Underweight to sell recommendations, respectively.
B128: Coverage Universe | D128: Investment Banking Clients (IBC) | G128: Other Material Investment Services Clients (MISC)
A129: Stock Rating Category | B129: Count | C129: % of Total | D129: Count | E129: % of Total IBC | F129: % of Rating Category | G129: Count | H129: % of Total Other MISC
A130: Overweight/Buy | B130: 1189 | C130: 0.38 | D130: 315 | E130: 0.41 | F130: 0.26 | G130: 555 | H130: 0.39
A131: Equal-weight/Hold | B131: 1355 | C131: 0.43 | D131: 364 | E131: 0.47 | F131: 0.27 | G131: 644 | H131: 0.45
A132: Not-Rated/Hold | B132: 53 | C132: 0.02 | D132: 4 | E132: 0.01 | F132: 0.08 | G132: 7 | H132: 0
A133: Underweight/Sell | B133: 545 | C133: 0.17 | D133: 84 | E133: 0.11 | F133: 0.15 | G133: 214 | H133: 0.15
A134: Total | B134: 3142 | D134: 767 | G134: 1420
A136: Data include common stock and ADRs currently assigned ratings. Investment Banking Clients are companies
A137: from whom Morgan Stanley received investment banking compensation in the last 12 months. Due to rounding
A138: off of decimals, the percentages provided in the "% of total" column may not add up to exactly 100
A139: percent.
A141: Analyst Stock Ratings
A143: Overweight (O). The stock's total return is expected to exceed the average total return of the analyst's
A144: industry (or industry team's) coverage universe, on a risk-adjusted basis, over the next 12-18 months.
A146: Equal-weight (E). The stock's total return is expected to be in line with the average total return of
A147: the analyst's industry (or industry team's) coverage universe, on a risk-adjusted basis, over the next
A148: 12-18 months.
A150: Not-Rated (NR). Currently the analyst does not have adequate conviction about the stock's total return
A151: relative to the average total return of the analyst's industry (or industry team's) coverage universe,
... A397: © Copyright 2018 Morgan Stanley

Sheet COVER SHEET
FZ1: Section Header
D2: =CompanyName -> Eli Lilly & Co.
D3: ="Ticker: " & CompanyTicker -> Ticker: LLY
D4: ="Rating: " & Rating -> Rating: Equal-weight
D5: ="Price Target: " & TEXT(PriceTarget, "$0") -> Price Target: $93
D6: ="Date: " & TEXT(DtLastUpdt, "m/d/yyyy") -> Date: 4/24/2018
D8: David R. Risinger, CFA
D9: Senior US Major Pharmaceuticals Analyst
D10: (212) 761-6494
D11: david.risinger@morganstanley.com
B13: Go to Annual Income Statement | D13: Go to Footnotes | F13: Go to Management Projections
B15: Go to Quarterly Income Statement | D15: Go to Agreements | F15: Go to Selected Franchises
B17: Go to Annual Revenues | D17: Go to Pipeline | F17: Go to DCF
B19: Go to Quarterly Revenues | D19: Go to Cash Flow/Balance Sheet

Sheet MW-Cache
A1: $FZ$2
A2: LLY.N,mstag:researchAndDevelopment,2015FY,,FYR | B2: 4,819.8927559 | C2: LLY.N,mstag:researchAndDevelopment,2012FY,,FYR | D2: 5,240.21 | E2: LLY.N,mstag:revenueNet,2018Q3,,FYR | F2: 5,896.886 | G2: LLY.N,mstag:revenueNet,2018Q1,,FYR | H2: 5,539.322 | I2: PFE.N,mstag:revenueNet,2012FY,,FYR,USD | J2: 62,880.57093596 | K2: LLY.N,mstag:sellingGeneralAndAdministrativeExpenses,2013FY,,FYR | L2: 7,708.264 | M2: NOVOb.CO,mscalc:marketCapitalizationCurrent | N2: 532,335.205932404 | O2: LLY.N,mscalc:epsForConsensusForThomsonFeed,2018Q3,,FYR | P2: 1.29745235543281 | Q2: LLY.N,mscalc:epsForConsensusForThomsonFeed,2016Q3,,FYR | R2: 0.877651100221911 | S2: NOVOb.CO,mstag:revenueNet,2013FY,,FYR | T2: 83,789.2855310202 | U2: LLY.N,mscalc:epsForConsensusForThomsonFeed,2016Q1,,FYR | V2: 0.829950850128166 | W2: NOVOb.CO,mstag:revenueNet,2014FY,,FYR | X2: 91,763.306526585 | Y2: LLY.N,mscalc:epsForConsensusForThomsonFeed,2017Q1,,FYR | Z2: 0.98427917667797 | AA2: LLY.N,mstag:revenueNet,2017FY,,FYR | AB2: 22,659.922 | AC2: LLY.N,mstag:revenueNet,2016FY,,FYR | AD2: 21,210.2 | AE2: NOVOb.CO,mscalc:priceToSales,2012FY,,FYR | AF2: 7.05828823393677 | AG2: LLY.N,mscalc:closePriceCurrencyCalc | AH2: USD | AI2: LLY.N,mstag:revenueNet,2017Q4,,FYR | AJ2: 6,160.8 | AK2: LLY.N,mscalc:targetPrice | AL2: 35 | AM2: LLY.N,mstag:revenueNet,2018Q2,,FYR | AN2: 5,919.644 | AO2: LLY.N,mscalc:epsForConsensusForThomsonFeed,2022FY,,FYR | AP2: 7.59880083712444 | AQ2: NOVOb.CO,mscalc:sharePriceCurrent | AR2: 944.5 | AS2: LLY.N,mscalc:targetPrice,,,,USD | AT2: 93 | AU2: LLY.N,mstag:revenueNet,2017Q3,,FYR | AV2: 5,658.1 | AW2: LLY.N,mscalc:epsForConsensusForThomsonFeed,2023FY,,FYR | AX2: 8.23734103140301 | AY2: LLY.N,mscalc:epsForConsensusForThomsonFeed,2016Q2,,FYR | AZ2: 0.857291363034781 | BA2: LLY.N,mstag:revenueNet,2015FY,,FYR | BB2: 19,958.7 | BC2: LLY.N,mscalc:epsForConsensusForThomsonFeed,2021FY,,FYR | BD2: 6.87922774344024 | BE2: LLY.N,mscalc:epsForConsensusForThomsonFeed,2017Q2,,FYR | BF2: 1.11379137459678 | BG2: LLY.N,mstag:revenueNet,2014FY,,FYR | BH2: 20,706.8357451 | BI2: LLY.N,mstag:researchAndDevelopment,2013FY,,FYR | BJ2: 5,397.4163 | BK2: LLY.N,mstag:sellingGeneralAndAdministrativeExpenses,2012FY,,FYR | BL2: 7,708.264 | BM2: LLY.N,mstag:researchAndDevelopment,2016FY,,FYR | BN2: 4,578.898118105 | BO2: LLY.N,mstag:revenueNet,2022FY,,FYR | BP2: 28,570.8276999715 | BQ2: PFE.N,mscalc:epsForConsensusForThomsonFeed,2012FY,,FYR,USD | BR2: 2.30043255392233 | BS2: LLY.N,mscalc:epsForConsensusForThomsonFeed,2015FY,,FYR | BT2: 3.40650183734521 | BU2: LLY.N,mscalc:epsForConsensusForThomsonFeed,2018Q4,,FYR | BV2: 1.18354579796166 | BW2: LLY.N,mscalc:epsForConsensusForThomsonFeed,2014FY,,FYR | BX2: 2.73980739540057 | BY2: LLY.N,mscalc:epsForConsensusForThomsonFeed,2018FY,,FYR | BZ2: 4.90238940806421 | CA2: LLY.N,mstag:sellingGeneralAndAdministrativeExpenses,2015FY,,FYR | CB2: 6,937.4376 | CC2: LLY.N,mstag:revenueNet,2020FY,,FYR | CD2: 25,383.6853101 | CE2: ,mscalc:sedolCodeCalc | CF2: NA | CG2: ,mscalc:targetPrice,,,,USD | CH2: NA | CI2: LLY.N,mscalc:sedolCodeCalc | CJ2: 2516152 | CK2: LLY.N,mstag:revenueNet,2017Q1,,FYR | CL2: 5,228.4 | CM2: NOVOb.CO,mstag:revenueNet,2015FY,,FYR | CN2: 100,088.46242012 | CO2: LLY.N,mscalc:epsForConsensusForThomsonFeed,2017Q3,,FYR | CP2: 1.04808124807651 | CQ2: LLY.N,mstag:revenueNet,2016Q1,,FYR | CR2: 4,865.1 | CS2: NOVOb.CO,mstag:revenueNet,2016FY,,FYR | CT2: 105,840.518468098 | CU2: LLY.N,mscalc:epsForConsensusForThomsonFeed,2018Q1,,FYR | CV2: 1.17060883235996 | CW2: LLY.N,mscalc:epsForConsensusForThomsonFeed,2020FY,,FYR | CX2: 6.13264701376174 | CY2: LLY.N,mscalc:marketCapitalizationCurrent | CZ2: 47,366.05438 | DA2: LLY.N,mstag:revenueNet,2012FY,,FYR | DB2: 22,829.187 | DC2: LLY.N,mscalc:priceToSales,2012FY,,FYR | DD2: 2.07480250523157 | DE2: LLY.N,mstag:sellingGeneralAndAdministrativeExpenses,2017FY,,FYR | DF2: 6,590.56572 | DG2: LLY.N,mstag:revenueNet,2023FY,,FYR | DH2: 29,907.3390228689 | DI2: LLY.N,mscalc:factsetIdCalc | DJ2: NA | DK2: ,mscalc:closePriceCurrencyCalc | DL2: NA | DM2: NOVOb.CO,mstag:revenueNet,2011FY,,FYR | DN2: 66,345.7 | DO2: LLY.N,mscalc:epsForConsensusForThomsonFeed,2017Q4,,FYR | DP2: 1.14175642025113 | DQ2: NOVOb.CO,mstag:revenueNet,2012FY,,FYR | DR2: 75,419.8735286691 | DS2: LLY.N,mstag:revenueNet,2017Q2,,FYR | DT2: 5,824.3 | DU2: LLY.N,mscalc:epsForConsensusForThomsonFeed,2017FY,,FYR | DV2: 4.22949843436989 | DW2: LLY.N,mstag:revenueNet,2016Q2,,FYR | DX2: 5,404.8 | DY2: LLY.N,mscalc:epsForConsensusForThomsonFeed,2018Q2,,FYR | DZ2: 1.25080870206138 | EA2: LLY.N,mstag:revenueNet,2018FY,,FYR | EB2: 23,524.735 | EC2: LLY.N,mstag:revenueNet,2016Q3,,FYR | ED2: 5,191.7 | EE2: LLY.N,mstag:sellingGeneralAndAdministrativeExpenses,2014FY,,FYR | EF2: 6,937.4376 | EG2: LLY.N,mstag:researchAndDevelopment,2017FY,,FYR | EH2: 4,349.95321219975 | EI2: LLY.N,mstag:revenueNet,2021FY,,FYR | EJ2: 27,006.288050128 | EK2: LLY.N,mstag:revenueNet,2013FY,,FYR | EL2: 24,132.15242 | EM2: LLY.N,mstag:revenueNet,2016Q4,,FYR | EN2: 5,760.5 | EO2: LLY.N,mscalc:epsForConsensusForThomsonFeed,2012FY,,FYR | EP2: 3.42075776568533 | EQ2: LLY.N,mscalc:epsForConsensusForThomsonFeed,2013FY,,FYR | ER2: 4.0229705476243 | ES2: LLY.N,mstag:researchAndDevelopment,2014FY,,FYR | ET2: 5,073.571322 | EU2: LLY.N,mscalc:epsForConsensusForThomsonFeed,2019FY,,FYR | EV2: 5.42559190656427 | EW2: LLY.N,mstag:sellingGeneralAndAdministrativeExpenses,2016FY,,FYR | EX2: 6937.4376 | EY2: LLY.N,mstag:revenueNet,2018Q4,,FYR | EZ2: 6,168.883 | FA2: LLY.N,mscalc:epsForConsensusForThomsonFeed,2016FY,,FYR | FB2: 3.50832728370803 | FC2: LLY.N,mscalc:epsForConsensusForThomsonFeed,2016Q4,,FYR | FD2: 0.954688562766958 | FE2: LLY.N,mstag:revenueNet,2019FY,,FYR | FF2: 24,130.36493 | FG2: NOVOb.CO,mscalc:currentDilutedSharesOutstandingCalc | FH2: 563.61589

Sheet IS-ANNUAL
EW1: Section Header
AS3: =LEFT(AS9,1)&"FQ"&LEFT($AT9,4) -> 4FQ2011 | AU3: =LEFT(AU9,1)&"FQ"&LEFT($AY9,4) -> 1FQ2012 | AV3: =LEFT(AV9,1)&"FQ"&LEFT($AY9,4) -> 2FQ2012 | AW3: =LEFT(AW9,1)&"FQ"&LEFT($AY9,4) -> 3FQ2012 | AX3: =LEFT(AX9,1)&"FQ"&LEFT($AY9,4) -> 4FQ2012 | AZ3: =LEFT(AZ9,1)&"FQ"&LEFT($BD9,4) -> 1FQ2013 | BA3: =LEFT(BA9,1)&"FQ"&LEFT($BD9,4) -> 2FQ2013 | BB3: =LEFT(BB9,1)&"FQ"&LEFT($BD9,4) -> 3FQ2013 | BC3: =LEFT(BC9,1)&"FQ"&LEFT($BD9,4) -> 4FQ2013 | BE3: =LEFT(BE9,1)&"FQ"&LEFT($BI9,4) -> 1FQ2014 | BF3: =LEFT(BF9,1)&"FQ"&LEFT($BI9,4) -> 2FQ2014 | BG3: =LEFT(BG9,1)&"FQ"&LEFT($BI9,4) -> 3FQ2014 | BH3: =LEFT(BH9,1)&"FQ"&LEFT($BI9,4) -> 4FQ2014 | BJ3: =LEFT(BJ9,1)&"FQ"&LEFT(BN9,4) -> 1FQ2015 | BK3: =LEFT(BK9,1)&"FQ"&LEFT(BN9,4) -> 2FQ2015 | BL3: =LEFT(BL9,1)&"FQ"&LEFT(BN9,4) -> 3FQ2015 | BM3: =LEFT(BM9,1)&"FQ"&LEFT(BN9,4) -> 4FQ2015 | BO3: =LEFT(BO9,1)&"FQ"&LEFT(BS9,4) -> 1FQ2016 | BP3: =LEFT(BP9,1)&"FQ"&LEFT(BS9,4) -> 2FQ2016 | BQ3: =LEFT(BQ9,1)&"FQ"&LEFT(BS9,4) -> 3FQ2016 | BR3: =LEFT(BR9,1)&"FQ"&LEFT(BS9,4) -> 4FQ2016 | BT3: =LEFT(BT9,1)&"FQ"&LEFT(BX9,4) -> 1FQ2017 | BU3: =LEFT(BU9,1)&"FQ"&LEFT(BX9,4) -> 2FQ2017 | BV3: =LEFT(BV9,1)&"FQ"&LEFT(BX9,4) -> 3FQ2017 | BW3: =LEFT(BW9,1)&"FQ"&LEFT(BX9,4) -> 4FQ2017 | BY3: =LEFT(BY9,1)&"FQ"&LEFT(CC9,4) -> 1FQ2018 | BZ3: =LEFT(BZ9,1)&"FQ"&LEFT(CC9,4) -> 2FQ2018 | CA3: =LEFT(CA9,1)&"FQ"&LEFT(CC9,4) -> 3FQ2018 | CB3: =LEFT(CB9,1)&"FQ"&LEFT(CC9,4) -> 4FQ2018
L4: 38442 | M4: 38533 | N4: 38625 | O4: 38717 | P4: 38717 | Q4: 38807 | R4: 38898 | S4: 38990 | T4: 39082 | U4: 39082 | V4: 39172 | W4: 39263 | X4: 39355 | Y4: 39447 | Z4: 39447 | AA4: 39538 | AB4: 39629 | AC4: 39721 | AD4: 39813 | AE4: 39813 | AF4: 39903 | AG4: 39994 | AH4: 40086 | AI4: 40178 | AJ4: 40178 | AK4: 40268 | AL4: 40359 | AM4: 40451 | AN4: 40543 | AO4: 40543 | AP4: 40633 | AQ4: 40724 | AR4: 40816 | AS4: 40908 | AT4: 40908 | AU4: 40999 | AV4: 41090 | AW4: 41182 | AX4: 41274 | AY4: 41274 | AZ4: 41364 | BA4: 41455 | BB4: 41547 | BC4: 41639 | BD4: 41639 | BE4: 41729 | BF4: 41820 | BG4: 41912 | BH4: 42004 | BI4: 42004 | BJ4: 42094 | BK4: 42185 | BL4: 42277 | BM4: 42369 | BN4: 42369 | BO4: 42460 | BP4: 42551 | BQ4: 42643 | BR4: 42735 | BS4: 42735 | BT4: 42825 | BU4: 42916 | BV4: 43008 | BW4: 43100 | BX4: 43100 | BY4: 43190 | BZ4: 43281 | CA4: 43373 | CB4: 43465 | CC4: 43465 | CD4: 43830 | CE4: 44196 | CF4: 44561 | CG4: 44926 | CH4: 45291
H5: =CompanyName -> Eli Lilly & Co. | J5: =LatestRpQ -> 43190
H6: Annual Income Statement | J6: =LatestFiledQ -> 43100
H9: ($M) | L9: ="1Q:" & RIGHT(YEAR(L$4),2) & IF(L$4<=LatestRpQ, "A", "E") -> 1Q:05A | M9: ="2Q:" & RIGHT(YEAR(M$4),2) & IF(M$4<=LatestRpQ, "A", "E") -> 2Q:05A | N9: ="3Q:" & RIGHT(YEAR(N$4),2) & IF(N$4<=LatestRpQ, "A", "E") -> 3Q:05A | O9: ="4Q:" & RIGHT(YEAR(O$4),2) & IF(O$4<=LatestRpQ, "A", "E") -> 4Q:05A | P9: =YEAR(P$4) & IF(P$4<=LatestRpQ, "A", "E") -> 2005A | Q9: ="1Q:" & RIGHT(YEAR(Q$4),2) & IF(Q$4<=LatestRpQ, "A", "E") -> 1Q:06A | R9: ="2Q:" & RIGHT(YEAR(R$4),2) & IF(R$4<=LatestRpQ, "A", "E") -> 2Q:06A | S9: ="3Q:" & RIGHT(YEAR(S$4),2) & IF(S$4<=LatestRpQ, "A", "E") -> 3Q:06A | T9: ="4Q:" & RIGHT(YEAR(T$4),2) & IF(T$4<=LatestRpQ, "A", "E") -> 4Q:06A | U9: =YEAR(U$4) & IF(U$4<=LatestRpQ, "A", "E") -> 2006A | V9: ="1Q:" & RIGHT(YEAR(V$4),2) & IF(V$4<=LatestRpQ, "A", "E") -> 1Q:07A | W9: ="2Q:" & RIGHT(YEAR(W$4),2) & IF(W$4<=LatestRpQ, "A", "E") -> 2Q:07A | X9: ="3Q:" & RIGHT(YEAR(X$4),2) & IF(X$4<=LatestRpQ, "A", "E") -> 3Q:07A | Y9: ="4Q:" & RIGHT(YEAR(Y$4),2) & IF(Y$4<=LatestRpQ, "A", "E") -> 4Q:07A | Z9: =YEAR(Z$4) & IF(Z$4<=LatestRpQ, "A", "E") -> 2007A | AA9: ="1Q:" & RIGHT(YEAR(AA$4),2) & IF(AA$4<=LatestRpQ, "A", "E") -> 1Q:08A | AB9: ="2Q:" & RIGHT(YEAR(AB$4),2) & IF(AB$4<=LatestRpQ, "A", "E") -> 2Q:08A | AC9: ="3Q:" & RIGHT(YEAR(AC$4),2) & IF(AC$4<=LatestRpQ, "A", "E") -> 3Q:08A | AD9: ="4Q:" & RIGHT(YEAR(AD$4),2) & IF(AD$4<=LatestRpQ, "A", "E") -> 4Q:08A | AE9: =YEAR(AE$4) & IF(AE$4<=LatestRpQ, "A", "E") -> 2008A | AF9: ="1Q:" & RIGHT(YEAR(AF$4),2) & IF(AF$4<=LatestRpQ, "A", "E") -> 1Q:09A | AG9: ="2Q:" & RIGHT(YEAR(AG$4),2) & IF(AG$4<=LatestRpQ, "A", "E") -> 2Q:09A | AH9: ="3Q:" & RIGHT(YEAR(AH$4),2) & IF(AH$4<=LatestRpQ, "A", "E") -> 3Q:09A | AI9: ="4Q:" & RIGHT(YEAR(AI$4),2) & IF(AI$4<=LatestRpQ, "A", "E") -> 4Q:09A | AJ9: =YEAR(AJ$4) & IF(AJ$4<=LatestRpQ, "A", "E") -> 2009A | AK9: ="1Q:" & RIGHT(YEAR(AK$4),2) & IF(AK$4<=LatestRpQ, "A", "E") -> 1Q:10A | AL9: ="2Q:" & RIGHT(YEAR(AL$4),2) & IF(AL$4<=LatestRpQ, "A", "E") -> 2Q:10A | AM9: ="3Q:" & RIGHT(YEAR(AM$4),2) & IF(AM$4<=LatestRpQ, "A", "E") -> 3Q:10A | AN9: ="4Q:" & RIGHT(YEAR(AN$4),2) & IF(AN$4<=LatestRpQ, "A", "E") -> 4Q:10A | AO9: =YEAR(AO$4) & IF(AO$4<=LatestRpQ, "A", "E") -> 2010A | AP9: ="1Q:" & RIGHT(YEAR(AP$4),2) & IF(AP$4<=LatestRpQ, "A", "E") -> 1Q:11A | AQ9: ="2Q:" & RIGHT(YEAR(AQ$4),2) & IF(AQ$4<=LatestRpQ, "A", "E") -> 2Q:11A | AR9: ="3Q:" & RIGHT(YEAR(AR$4),2) & IF(AR$4<=LatestRpQ, "A", "E") -> 3Q:11A | AS9: ="4Q:" & RIGHT(YEAR(AS$4),2) & IF(AS$4<=LatestRpQ, "A", "E") -> 4Q:11A | AT9: =YEAR(AT$4) & IF(AT$4<=LatestRpQ, "A", "E") -> 2011A | AU9: ="1Q:" & RIGHT(YEAR(AU$4),2) & IF(AU$4<=LatestRpQ, "A", "E") -> 1Q:12A | AV9: ="2Q:" & RIGHT(YEAR(AV$4),2) & IF(AV$4<=LatestRpQ, "A", "E") -> 2Q:12A | AW9: ="3Q:" & RIGHT(YEAR(AW$4),2) & IF(AW$4<=LatestRpQ, "A", "E") -> 3Q:12A | AX9: ="4Q:" & RIGHT(YEAR(AX$4),2) & IF(AX$4<=LatestRpQ, "A", "E") -> 4Q:12A | AY9: =YEAR(AY$4) & IF(AY$4<=LatestRpQ, "A", "E") -> 2012A | AZ9: ="1Q:" & RIGHT(YEAR(AZ$4),2) & IF(AZ$4<=LatestRpQ, "A", "E") -> 1Q:13A | BA9: ="2Q:" & RIGHT(YEAR(BA$4),2) & IF(BA$4<=LatestRpQ, "A", "E") -> 2Q:13A | BB9: ="3Q:" & RIGHT(YEAR(BB$4),2) & IF(BB$4<=LatestRpQ, "A", "E") -> 3Q:13A | BC9: ="4Q:" & RIGHT(YEAR(BC$4),2) & IF(BC$4<=LatestRpQ, "A", "E") -> 4Q:13A | BD9: =YEAR(BD$4) & IF(BD$4<=LatestRpQ, "A", "E") -> 2013A | BE9: ="1Q:" & RIGHT(YEAR(BE$4),2) & IF(BE$4<=LatestRpQ, "A", "E") -> 1Q:14A | BF9: ="2Q:" & RIGHT(YEAR(BF$4),2) & IF(BF$4<=LatestRpQ, "A", "E") -> 2Q:14A | BG9: ="3Q:" & RIGHT(YEAR(BG$4),2) & IF(BG$4<=LatestRpQ, "A", "E") -> 3Q:14A | BH9: ="4Q:" & RIGHT(YEAR(BH$4),2) & IF(BH$4<=LatestRpQ, "A", "E") -> 4Q:14A | BI9: =YEAR(BI$4) & IF(BI$4<=LatestRpQ, "A", "E") -> 2014A | BJ9: ="1Q:" & RIGHT(YEAR(BJ$4),2) & IF(BJ$4<=LatestRpQ, "A", "E") -> 1Q:15A | BK9: ="2Q:" & RIGHT(YEAR(BK$4),2) & IF(BK$4<=LatestRpQ, "A", "E") -> 2Q:15A | BL9: ="3Q:" & RIGHT(YEAR(BL$4),2) & IF(BL$4<=LatestRpQ, "A", "E") -> 3Q:15A | BM9: ="4Q:" & RIGHT(YEAR(BM$4),2) & IF(BM$4<=LatestRpQ, "A", "E") -> 4Q:15A | BN9: =YEAR(BN$4) & IF(BN$4<=LatestRpQ, "A", "E") -> 2015A | BO9: ="1Q:" & RIGHT(YEAR(BO$4),2) & IF(BO$4<=LatestRpQ, "A", "E") -> 1Q:16A | BP9: ="2Q:" & RIGHT(YEAR(BP$4),2) & IF(BP$4<=LatestRpQ, "A", "E") -> 2Q:16A | BQ9: ="3Q:" & RIGHT(YEAR(BQ$4),2) & IF(BQ$4<=LatestRpQ, "A", "E") -> 3Q:16A | BR9: ="4Q:" & RIGHT(YEAR(BR$4),2) & IF(BR$4<=LatestRpQ, "A", "E") -> 4Q:16A | BS9: =YEAR(BS$4) & IF(BS$4<=LatestRpQ, "A", "E") -> 2016A | BT9: ="1Q:" & RIGHT(YEAR(BT$4),2) & IF(BT$4<=LatestRpQ, "A", "E") -> 1Q:17A | BU9: ="2Q:" & RIGHT(YEAR(BU$4),2) & IF(BU$4<=LatestRpQ, "A", "E") -> 2Q:17A | BV9: ="3Q:" & RIGHT(YEAR(BV$4),2) & IF(BV$4<=LatestRpQ, "A", "E") -> 3Q:17A | BW9: ="4Q:" & RIGHT(YEAR(BW$4),2) & IF(BW$4<=LatestRpQ, "A", "E") -> 4Q:17A | BX9: =YEAR(BX$4) & IF(BX$4<=LatestRpQ, "A", "E") -> 2017A | BY9: ="1Q:" & RIGHT(YEAR(BY$4),2) & IF(BY$4<=LatestRpQ, "A", "E") -> 1Q:18A | BZ9: ="2Q:" & RIGHT(YEAR(BZ$4),2) & IF(BZ$4<=LatestRpQ, "A", "E") -> 2Q:18E | CA9: ="3Q:" & RIGHT(YEAR(CA$4),2) & IF(CA$4<=LatestRpQ, "A", "E") -> 3Q:18E | CB9: ="4Q:" & RIGHT(YEAR(CB$4),2) & IF(CB$4<=LatestRpQ, "A", "E") -> 4Q:18E | CC9: =YEAR(CC$4) & IF(CC$4<=LatestRpQ, "A", "E") -> 2018E | CD9: =YEAR(CD$4) & IF(CD$4<=LatestRpQ, "A", "E") -> 2019E | CE9: =YEAR(CE$4) & IF(CE$4<=LatestRpQ, "A", "E") -> 2020E | CF9: =YEAR(CF$4) & IF(CF$4<=LatestRpQ, "A", "E") -> 2021E | CG9: =YEAR(CG$4) & IF(CG$4<=LatestRpQ, "A", "E") -> 2022E | CH9: =YEAR(CH$4) & IF(CH$4<=LatestRpQ, "A", "E") -> 2023E
H11: Total revenues | L11: 3497.4 | M11: 3667.7 | N11: 3601.1 | O11: 3879.1 | P11: 14645.3 | Q11: ='REV-ANNUAL'!Q235 -> 3714.8 | R11: ='REV-ANNUAL'!R235 -> 3867.1 | S11: ='REV-ANNUAL'!S235 -> 3864.05 | T11: ='REV-ANNUAL'!T235 -> 4245.3 | U11: =Q11+R11+S11+T11 -> 15691.25 | V11: ='REV-ANNUAL'!V235 -> 4226.2 | W11: ='REV-ANNUAL'!W235 -> 4630.9 | X11: ='REV-ANNUAL'!X235 -> 4586.8 | Y11: ='REV-ANNUAL'!Y235 -> 5189.8 | Z11: =V11+W11+X11+Y11 -> 18633.7 | AA11: ='REV-ANNUAL'!AA235 -> 4911 | AB11: ='REV-ANNUAL'!AB235 -> 5251 | AC11: ='REV-ANNUAL'!AC235 -> 5308.7 | AD11: ='REV-ANNUAL'!AD235 -> 5261.7 | AE11: =AA11+AB11+AC11+AD11 -> 20732.4 | AF11: ='REV-ANNUAL'!AF235 -> 5046.5 | AG11: ='REV-ANNUAL'!AG235 -> 5292.61 | AH11: ='REV-ANNUAL'!AH235 -> 5562.2 | AI11: ='REV-ANNUAL'!AI235 -> 5934.7 | AJ11: =AF11+AG11+AH11+AI11 -> 21836.01 | AK11: ='REV-ANNUAL'!AK235 -> 5485.4 | AL11: ='REV-ANNUAL'!AL235 -> 5748.7 | AM11: ='REV-ANNUAL'!AM235 -> 5654.9 | AN11: ='REV-ANNUAL'!AN235 -> 6187.08 | AO11: ='REV-ANNUAL'!AO235 -> 23076.08 | AP11: ='REV-ANNUAL'!AP235 -> 5839.2 | AQ11: ='REV-ANNUAL'!AQ235 -> 6253 | AR11: ='REV-ANNUAL'!AR235 -> 6148 | ... CH11: ='REV-ANNUAL'!CH235 -> 28120.927 | EW11: Non-GAAP P&L
H12: Pharmaceuticals | L12: 3301.9 | M12: 3466.8 | N12: 3385.5 | O12: 3627.7 | P12: 13785.1 | Q12: ='REV-ANNUAL'!Q11 -> 3516.4 | R12: ='REV-ANNUAL'!R11 -> 3666.1 | S12: ='REV-ANNUAL'!S11 -> 3647.85 | T12: ='REV-ANNUAL'!T11 -> 3985.4 | U12: ='REV-ANNUAL'!U11 -> 14815.55 | V12: ='REV-ANNUAL'!V11 -> 4011.1 | W12: ='REV-ANNUAL'!W11 -> 4416.2 | X12: ='REV-ANNUAL'!X11 -> 4350.2 | ... AD12: ='REV-ANNUAL'!AD11 -> 4775.2 | AE12: =SUM(AA12:AD12) -> 18917 | AF12: ='REV-ANNUAL'!AF11 -> 4627.3 | AG12: ='REV-ANNUAL'!AG11 -> 4837.75 | AH12: ='REV-ANNUAL'!AH11 -> 5071.1 | AI12: ='REV-ANNUAL'!AI11 -> 5428.1 | AJ12: =SUM(AF12:AI12) -> 19964.25 | AK12: ='REV-ANNUAL'!AK11 -> 5042.9 | AL12: ='REV-ANNUAL'!AL11 -> 5265.2 | AM12: ='REV-ANNUAL'!AM11 -> 5133.7 | AN12: ='REV-ANNUAL'!AN11 -> 5609.48 | AO12: ='REV-ANNUAL'!AO11 -> 21051.28 | AP12: ='REV-ANNUAL'!AP11 -> 5320.2 | AQ12: ='REV-ANNUAL'!AQ11 -> 5697.2 | AR12: ='REV-ANNUAL'!AR11 -> 5520.7 | ... CH12: ='REV-ANNUAL'!CH11 -> 23755.99
H13: ='REV-ANNUAL'!H118 -> Cyramza | AO13: ='REV-ANNUAL'!AO118 -> 0 | AT13: ='REV-ANNUAL'!AT118 -> 0 | AY13: ='REV-ANNUAL'!AY118 -> 0 | BD13: ='REV-ANNUAL'!BD118 -> 0 | BE13: ='REV-ANNUAL'!BE19 -> 283.1 | BF13: ='REV-ANNUAL'!BF19 -> 243.8 | BG13: ='REV-ANNUAL'!BG19 -> 257.4 | BH13: ='REV-ANNUAL'!BH19 -> 253.1 | BI13: ='REV-ANNUAL'!BI118 -> 75.7 | BJ13: ='REV-ANNUAL'!BJ118 -> 67.5 | BK13: ='REV-ANNUAL'!BK118 -> 87.7 | BL13: ='REV-ANNUAL'!BL118 -> 111.2 | BM13: ='REV-ANNUAL'!BM118 -> 117.5 | BN13: ='REV-ANNUAL'!BN118 -> 383.9 | BO13: ='REV-ANNUAL'!BO118 -> 131 | BP13: ='REV-ANNUAL'!BP118 -> 147 | ... CH13: ='REV-ANNUAL'!CH118 -> 890.77652
H14: ='REV-ANNUAL'!H71 -> Jardiance/Glyxambi (100% GM, receive 50% GP from BI) | AO14: ='REV-ANNUAL'!AO71 -> 0 | AT14: ='REV-ANNUAL'!AT71 -> 0 | AY14: ='REV-ANNUAL'!AY71 -> 0 | BD14: ='REV-ANNUAL'!BD71 -> 0 | BE14: ='REV-ANNUAL'!BE71 -> 0 | BF14: ='REV-ANNUAL'!BF71 -> 0 | BG14: ='REV-ANNUAL'!BG71 -> 4.5 | BH14: ='REV-ANNUAL'!BH71 -> 5.6 | BI14: ='REV-ANNUAL'!BI71 -> 10.1 | BJ14: ='REV-ANNUAL'!BJ71 -> 19.3 | BK14: ='REV-ANNUAL'!BK71 -> 11.1 | ... CH14: ='REV-ANNUAL'!CH71 -> 1759.8203
H15: ='REV-ANNUAL'!H68 -> Tradjenta/Jenta (100% GM, receive 50% GP from BI) | AO15: ='REV-ANNUAL'!AO68 -> 0 | AP15: ='REV-ANNUAL'!AP68 -> 0 | AQ15: ='REV-ANNUAL'!AQ68 -> 5.6 | AR15: ='REV-ANNUAL'!AR68 -> 2.8 | AS15: ='REV-ANNUAL'!AS68 -> 6.7 | AT15: ='REV-ANNUAL'!AT68 -> 15.1 | AU15: ='REV-ANNUAL'!AU68 -> 12.8 | AV15: ='REV-ANNUAL'!AV68 -> 13.2 | ... CH15: ='REV-ANNUAL'!CH68 -> 753.49251
H16: ='REV-ANNUAL'!H25 -> Cymbalta | L16: ='REV-ANNUAL'!L25 -> 106.8 | M16: ='REV-ANNUAL'!M25 -> 161.4 | N16: ='REV-ANNUAL'!N25 -> 182.7 | O16: ='REV-ANNUAL'!O25 -> 228.8 | P16: ='REV-ANNUAL'!P25 -> 679.7 | Q16: ='REV-ANNUAL'!Q25 -> 233.2 | R16: ='REV-ANNUAL'!R25 -> 310.4 | S16: ='REV-ANNUAL'!S25 -> 348.6 | ... CH16: ='REV-ANNUAL'!CH25 -> 176.23155
H17: ='REV-ANNUAL'!H50 -> Humulin | L17: ='REV-ANNUAL'!L50 -> 256.9 | M17: ='REV-ANNUAL'!M50 -> 249.7 | N17: ='REV-ANNUAL'!N50 -> 250.9 | O17: ='REV-ANNUAL'!O50 -> 247.2 | P17: ='REV-ANNUAL'!P50 -> 1004.7 | Q17: ='REV-ANNUAL'!Q50 -> 218.5 | R17: ='REV-ANNUAL'!R50 -> 219.8 | S17: ='REV-ANNUAL'!S50 -> 230 | ... CH17: ='REV-ANNUAL'!CH50 -> 1137.3212
H18: ='REV-ANNUAL'!H53 -> Humalog | L18: ='REV-ANNUAL'!L53 -> 286.1 | M18: ='REV-ANNUAL'!M53 -> 296.2 | N18: ='REV-ANNUAL'!N53 -> 306.2 | O18: ='REV-ANNUAL'!O53 -> 309.1 | P18: ='REV-ANNUAL'!P53 -> 1197.6 | Q18: ='REV-ANNUAL'!Q53 -> 304.5 | R18: ='REV-ANNUAL'!R53 -> 320.5 | S18: ='REV-ANNUAL'!S53 -> 322.2 | ... CH18: ='REV-ANNUAL'!CH53 -> 1629.5046
H19: ='REV-ANNUAL'!H115 -> Alimta | L19: ='REV-ANNUAL'!L115 -> 93.9 | M19: ='REV-ANNUAL'!M115 -> 111.1 | N19: ='REV-ANNUAL'!N115 -> 122.3 | O19: ='REV-ANNUAL'!O115 -> 135.9 | P19: ='REV-ANNUAL'!P115 -> 463.2 | Q19: ='REV-ANNUAL'!Q115 -> 130.1 | R19: ='REV-ANNUAL'!R115 -> 153.1 | S19: ='REV-ANNUAL'!S115 -> 157.2 | ... CH19: ='REV-ANNUAL'!CH115 -> 250.76596
H20: ='REV-ANNUAL'!H143 -> Cialis | L20: ='REV-ANNUAL'!L143 -> 0 | M20: ='REV-ANNUAL'!M143 -> 0 | N20: ='REV-ANNUAL'!N143 -> 0 | O20: ='REV-ANNUAL'!O143 -> 0 | P20: ='REV-ANNUAL'!P143 -> 0 | Q20: ='REV-ANNUAL'!Q143 -> 0 | R20: ='REV-ANNUAL'!R143 -> 0 | S20: ='REV-ANNUAL'!S143 -> 0 | ... CH20: ='REV-ANNUAL'!CH143 -> 305.41451
H21: Animal health | L21: 195.5 | M21: 201 | N21: 215.8 | O21: 251.5 | P21: 863.8 | Q21: ='REV-ANNUAL'!Q206 -> 198.4 | R21: ='REV-ANNUAL'!R206 -> 201 | S21: ='REV-ANNUAL'!S206 -> 216.2 | T21: ='REV-ANNUAL'!T206 -> 259.9 | U21: ='REV-ANNUAL'!U206 -> 875.5 | V21: ='REV-ANNUAL'!V206 -> 215.1 | W21: ='REV-ANNUAL'!W206 -> 214.7 | X21: ='REV-ANNUAL'!X206 -> 236.6 | ... AD21: ='REV-ANNUAL'!AD206 -> 326.4 | AE21: =SUM(AA21:AD21) -> 1093.3 | AF21: ='REV-ANNUAL'!AF206 -> 264.1 | AG21: ='REV-ANNUAL'!AG206 -> 275.4 | AH21: ='REV-ANNUAL'!AH206 -> 314.6 | AI21: ='REV-ANNUAL'!AI206 -> 353.2 | AJ21: =SUM(AF21:AI21) -> 1207.3 | AK21: ='REV-ANNUAL'!AK206 -> 289.6 | AL21: ='REV-ANNUAL'!AL206 -> 324.1 | AM21: ='REV-ANNUAL'!AM206 -> 353.3 | AN21: ='REV-ANNUAL'!AN206 -> 424.3 | AO21: ='REV-ANNUAL'!AO206 -> 1391.3 | AP21: ='REV-ANNUAL'!AP206 -> 369.8 | AQ21: ='REV-ANNUAL'!AQ206 -> 389.5 | AR21: ='REV-ANNUAL'!AR206 -> 451.1 | ... CH21: ='REV-ANNUAL'!CH206 -> 4364.9374
H22: Pipeline | L22: 195.5 | M22: 201 | N22: 215.8 | O22: 251.5 | Q22: ='REV-ANNUAL'!Q207 -> 84 | R22: ='REV-ANNUAL'!R207 -> 92.7 | S22: ='REV-ANNUAL'!S207 -> 98 | T22: ='REV-ANNUAL'!T207 -> 131.2 | V22: ='REV-ANNUAL'!V207 -> 92.7 | W22: ='REV-ANNUAL'!W207 -> 96.1 | X22: ='REV-ANNUAL'!X207 -> 112.4 | Y22: ='REV-ANNUAL'!Y207 -> 179.7 | AF22: ='REV-ANNUAL'!AF201 -> 0 | AG22: ='REV-ANNUAL'!AG201 -> 0 | AH22: ='REV-ANNUAL'!AH201 -> 0 | AI22: ='REV-ANNUAL'!AI201 -> 0 | AJ22: ='REV-ANNUAL'!AJ201 -> 0 | AK22: ='REV-ANNUAL'!AK201 -> 0 | AL22: ='REV-ANNUAL'!AL201 -> 0 | AM22: ='REV-ANNUAL'!AM201 -> 0 | ... CH22: ='REV-ANNUAL'!CH201 -> 4099.8971
H24: COGS | L24: 859 | M24: 871.3 | N24: 845.7 | O24: 898.2 | P24: =SUM(L24:O24) -> 3474.2 | Q24: 806.5 | R24: 860.6 | S24: 860.4 | T24: 1019 | U24: =SUM(Q24:T24) -> 3546.5 | V24: 922.5 | W24: 998.9 | X24: 1054.6 | Y24: 1272.8 | Z24: =SUM(V24:Y24) -> 4248.8 | AA24: 1155.1 | AB24: 1183.3 | AC24: 1199.2 | AD24: 930.9 | AE24: =SUM(AA24:AD24) -> 4468.5 | AF24: 816.4 | AG24: 947.4 | AH24: 1051.9 | AI24: 1431.3 | AJ24: =SUM(AF24:AI24) -> 4247 | AK24: 1122.5 | AL24: 1023.9 | AM24: 987.6 | AN24: 1232.2 | AO24: =SUM(AK24:AN24) -> 4366.2 | AP24: 1180.1 | AQ24: 1228 | AR24: 1338.1 | AS24: 1321.7 | AT24: =SUM(AP24:AS24) -> 5067.9 | AU24: 1197.9 | AV24: 1146.7 | AW24: 1203.6 | AX24: 1248.3 | AY24: =SUM(AU24:AX24) -> 4796.5 | AZ24: 1158.3 | BA24: 1165.2 | BB24: 1198.1 | BC24: 1386.5 | BD24: =SUM(AZ24:BC24) -> 4908.1 | BE24: =1222.7-92.4 -> 1130.3 | BF24: =1189.7-95.8 -> 1093.9 | BG24: =1267-98.1 -> 1168.9 | BH24: =1253.1-98.8 -> 1154.3 | BI24: =SUM(BE24:BH24) -> 4547.4 | BJ24: 1012.3 | BK24: 1033.9 | BL24: 1099 | BM24: 1222.3 | BN24: =SUM(BJ24:BM24) -> 4367.5 | BO24: 1152.4 | BP24: 1298.4 | BQ24: 1225.1 | BR24: 1303.3 | BS24: =SUM(BO24:BR24) -> 4979.2 | BT24: 1143 | BU24: 1359.2 | BV24: 1406.1 | BW24: 1450.7 | BX24: =SUM(BT24:BW24) -> 5359 | BY24: =1420.2 -> 1420.2 | BZ24: =BZ11*BZ56 -> 1504.315 | CA24: =CA11*CA56 -> 1527.0779 | CB24: =CB11*CB56 -> 1561.3365 | CC24: =SUM(BY24:CB24) -> 6012.9294 | CD24: =CD11*CD56 -> 5975.8612 | CE24: =CE11*CE56 -> 5995.7927 | CF24: =CF11*CF56 -> 6081.14 | CG24: =CG11*CG56 -> 6123.9603 | CH24: =CH11*CH56 -> 6186.604
H25: Gross profit | L25: =L11-L24 -> 2638.4 | M25: =M11-M24 -> 2796.4 | N25: =N11-N24 -> 2755.4 | O25: =O11-O24 -> 2980.9 | P25: =P11-P24 -> 11171.1 | Q25: =Q11-Q24 -> 2908.3 | R25: =R11-R24 -> 3006.5 | S25: =S11-S24 -> 3003.65 | ... CH25: =CH11-CH24 -> 21934.323
H26: SG&A | L26: 1090.4 | M26: 1146.1 | N26: 1070.9 | O26: 1189.6 | P26: =SUM(L26:O26) -> 4497 | Q26: 1142.9 | R26: 1237.9 | S26: 1198.2 | T26: 1310.8 | U26: =SUM(Q26:T26) -> 4889.8 | V26: 1336.8 | W26: 1524.7 | X26: 1477.8 | Y26: 1755.8 | Z26: =SUM(V26:Y26) -> 6095.1 | AA26: 1575 | AB26: 1739.6 | AC26: 1673.2 | AD26: 1740.5 | AE26: =SUM(AA26:AD26) -> 6728.3 | AF26: 1529.2 | AG26: 1708.2 | AH26: 1701.8 | AI26: 1953.3 | AJ26: =SUM(AF26:AI26) -> 6892.5 | AK26: 1614.4 | AL26: 1755.4 | AM26: 1694.9 | AN26: 1988.7 | AO26: =SUM(AK26:AN26) -> 7053.4 | AP26: 1785.7 | AQ26: 2043 | AR26: 1917.8 | AS26: 2133.4 | AT26: =SUM(AP26:AS26) -> 7879.9 | AU26: 1847.5 | AV26: 1931.1 | AW26: 1757.4 | AX26: 1977.5 | AY26: =SUM(AU26:AX26) -> 7513.5 | AZ26: 1652 | BA26: 1867.6 | BB26: 1652.4 | BC26: 1953.6 | BD26: =SUM(AZ26:BC26) -> 7125.6 | BE26: =1484.9-35.7 -> 1449.2 | BF26: =1663.9-36 -> 1627.9 | BG26: =1672.1-119-36.3 -> 1516.8 | BH26: =1799.9-35.7 -> 1764.2 | BI26: =SUM(BE26:BH26) -> 6358.1 | BJ26: 1487.9 | BK26: =1635.4-35.8 -> 1599.6 | BL26: =1575.7-35.8 -> 1539.9 | BM26: 1796.3 | BN26: =SUM(BJ26:BM26) -> 6423.7 | BO26: =1473.9-1.7 -> 1472.2 | BP26: 1620.8 | BQ26: 1563.7 | BR26: 1788.4 | BS26: =SUM(BO26:BR26) -> 6445.1 | BT26: =1544.7-1.8 -> 1542.9 | BU26: 1705.8 | BV26: 1554.3 | BW26: 1779.3 | BX26: =SUM(BT26:BW26) -> 6582.3 | BY26: =1498.9 -> 1498.9 | BZ26: =BU26*(1+BZ70) -> 1637.568 | CA26: =BV26*(1+CA70) -> 1507.671 | CB26: =BW26*(1+CB70) -> 1725.921 | CC26: =SUM(BY26:CB26) -> 6370.06 | CD26: =CC26*(1+CD70) -> 6306.3594 | CE26: =CD26*(1+CE70) -> 6369.423 | CF26: =CE26*(1+CF70) -> 6496.8115 | CG26: =CF26*(1+CG70) -> 6626.7477 | CH26: =CG26*(1+CH70) -> 6759.2826
H27: IMCL collab agreemt reimbursemt | P27: 64.796 | Q27: 21.109 | R27: 13.43 | S27: 16.266 | T27: 17.698 | U27: =SUM(Q27:T27) -> 68.503 | V27: 19.385 | W27: 15.818 | X27: 18.495 | Y27: 16.934 | Z27: =SUM(V27:Y27) -> 70.632 | AA27: 18.082 | AB27: 19.544 | AC27: 23.112 | AD27: NA | BG27: 1243.2 | BW27: 1779.1 | BX27: =SUM(BT27:BW27) -> 1779.1 | BY27: 1779.1 | CC27: =SUM(BY27:CB27) -> 1779.1
H28: R&D | L28: 702.2 | M28: 762.4 | N28: 751 | O28: 809.9 | P28: =SUM(L28:O28) -> 3025.5 | Q28: 740.8 | R28: 774.8 | S28: 755.7 | T28: 858 | U28: =SUM(Q28:T28) -> 3129.3 | V28: 834.2 | W28: 854.4 | X28: 844.5 | Y28: 953.6 | Z28: =SUM(V28:Y28) -> 3486.7 | AA28: 913.1 | AB28: 994.3 | AC28: 996.4 | AD28: 1101.5 | AE28: =SUM(AA28:AD28) -> 4005.3 | AF28: 947.3 | AG28: 1040.4 | AH28: 1122.1 | AI28: 1216.7 | AJ28: =SUM(AF28:AI28) -> 4326.5 | AK28: 1039.1 | AL28: 1187.2 | AM28: 1219.8 | AN28: 1438.1 | AO28: =SUM(AK28:AN28) -> 4884.2 | AP28: 1124 | AQ28: 1260.6 | AR28: 1280.9 | AS28: 1355.3 | AT28: =SUM(AP28:AS28) -> 5020.8 | AU28: 1151.5 | AV28: 1320.7 | AW28: 1342.8 | AX28: =1463.091316 -> 1463.0913 | AY28: =SUM(AU28:AX28) -> 5278.0913 | AZ28: 1348.1 | BA28: 1330.4 | BB28: 1377.4 | BC28: 1475.4 | BD28: =SUM(AZ28:BC28) -> 5531.3 | BE28: =1109.3-0.7 -> 1108.6 | BF28: =1195.4-0.2 -> 1195.2 | BG28: =1243.2-0.2 -> 1243 | BH28: =1185.7-0.2 -> 1185.5 | BI28: =SUM(BE28:BH28) -> 4732.3 | BJ28: 1039.1 | BK28: 1169.5 | BL28: 1169.5 | BM28: 1444.2 | BN28: =SUM(BJ28:BM28) -> 4822.3 | BO28: =1221-0.2 -> 1220.8 | BP28: 1335.7 | BQ28: 1236.2 | BR28: 1450.5 | BS28: =SUM(BO28:BR28) -> 5243.2 | BT28: 1238.3 | BU28: 1250.8 | BV28: 1319.2 | BW28: 1473 | BX28: =SUM(BT28:BW28) -> 5281.3 | BY28: =1176.7 -> 1176.7 | BZ28: =BU28*(1+BZ71) -> 1288.324 | CA28: =BV28*(1+CA71) -> 1306.008 | CB28: =BW28*(1+CB71) -> 1487.73 | CC28: =SUM(BY28:CB28) -> 5258.762 | CD28: =CC28*(1+CD71) -> 5258.762 | CE28: =CD28*(1+CE71) -> 5311.3496 | CF28: =CE28*(1+CF71) -> 5417.5766 | CG28: =CF28*(1+CG71) -> 5525.9281 | CH28: =CG28*(1+CH71) -> 5636.4467
H29: Operating income, EBITA | L29: =L25-L26-L28 -> 845.8 | M29: =M25-M26-M28 -> 887.9 | N29: =N25-N26-N28 -> 933.5 | O29: =O25-O26-O28 -> 981.4 | P29: =P25-P26-P28 -> 3648.6 | Q29: =Q25-Q26-Q28 -> 1024.6 | R29: =R25-R26-R28 -> 993.8 | S29: =S25-S26-S28 -> 1049.75 | ... CH29: =CH25-CH26-CH28 -> 9538.5938
H30: Amortization (from 10-Q/K) | AO30: 385.7 | AT30: 469 | AU30: 147.7 | AV30: 133.1 | AW30: 140.8 | AX30: 141.4 | AY30: =SUM(AU30:AX30) -> 563 | AZ30: 146.1 | BA30: 145.2 | BB30: 132.2 | BC30: 131.5 | BD30: =SUM(AZ30:BC30) -> 555
H31: EBITA (est.) | AO31: =AO29+AO30 -> 7157.98 | AT31: =AT29+AT30 -> 6787 | AU31: =AU29+AU30 -> 1552.8 | AV31: =AV29+AV30 -> 1335.3 | AW31: =AW29+AW30 -> 1280.3 | AX31: =AX29+AX30 -> 1409.8087 | AY31: =AY29+AY30 -> 5578.2087 | AZ31: =AZ29+AZ30 -> 1589.4 | BA31: =BA29+BA30 -> 1711.7 | ... BD31: =BD29+BD30 -> 6102.8
H32: Depreciation (from 10-Q/K) | L32: =P32/4 -> 180.25 | M32: =(P32-L32)/3 -> 180.25 | N32: =(P32-L32-M32)/2 -> 180.25 | O32: =P32-N32-M32-L32 -> 180.25 | P32: 721 | Q32: =U32/4 -> 198.55 | R32: =(U32-Q32)/3 -> 198.55 | S32: =(U32-Q32-R32)/2 -> 198.55 | T32: =U32-S32-R32-Q32 -> 198.55 | U32: 794.2 | V32: =Z32/4 -> 218.775 | W32: =(Z32-V32)/3 -> 218.775 | X32: =(Z32-V32-W32)/2 -> 218.775 | Y32: =Z32-X32-W32-V32 -> 218.775 | Z32: 875.1 | AA32: =AE32/4 -> 232.3 | AB32: =(AE32-AA32)/3 -> 232.3 | AC32: =(AE32-AA32-AB32)/2 -> 232.3 | AD32: =AE32-AC32-AB32-AA32 -> 232.3 | AE32: 929.2 | AF32: =AJ32/4 -> 255.2 | AG32: =(AJ32-AF32)/3 -> 255.2 | AH32: =(AJ32-AF32-AG32)/2 -> 255.2 | AI32: =AJ32-AH32-AG32-AF32 -> 255.2 | AJ32: 1020.8 | AO32: 942.5 | AT32: 904.6 | AU32: 238.2 | AV32: 228.9 | AW32: 228.9 | AX32: 203.2 | AY32: =SUM(AU32:AX32) -> 899.2 | AZ32: 235.4 | BA32: 218.7 | BB32: 216.8 | BC32: 219.7 | BD32: =SUM(AZ32:BC32) -> 890.6 | BE32: 216.8 | BF32: 214.3 | BG32: 208.4 | BH32: 203.6 | BI32: =SUM(BE32:BH32) -> 843.1 | BJ32: 203.3 | BK32: 215.1 | BL32: 204.2 | BM32: 173.3 | BN32: =SUM(BJ32:BM32) -> 795.9 | BO32: 213 | BP32: 205.1 | BQ32: 215.1 | BR32: 175.5 | BS32: =SUM(BO32:BR32) -> 808.7 | BT32: 210.8 | BU32: 217.5 | BV32: 217.1 | BW32: 238.5 | BX32: =SUM(BT32:BW32) -> 883.9 | BY32: 215.75 | BZ32: 215.75 | CA32: 215.75 | CB32: 215.75 | CC32: =SUM(BY32:CB32) -> 863 | CD32: =CC32 -> 863 | CE32: =CD32 -> 863 | CF32: =CE32 -> 863 | CG32: =CF32 -> 863 | CH32: =CG32 -> 863
H33: EBITDA | L33: =L29+L32 -> 1026.05 | M33: =M29+M32 -> 1068.15 | N33: =N29+N32 -> 1113.75 | O33: =O29+O32 -> 1161.65 | P33: =P29+P32 -> 4369.6 | Q33: =Q29+Q32 -> 1223.15 | R33: =R29+R32 -> 1192.35 | S33: =S29+S32 -> 1248.3 | ... AJ33: =AJ29+AJ32 -> 7390.81 | AO33: =AO29+AO32+AO30 -> 8100.48 | AT33: =AT29+AT32+AT30 -> 7691.6 | AU33: =AU29+AU32+AU30 -> 1791 | AV33: =AV29+AV32+AV30 -> 1564.2 | AW33: =AW29+AW32+AW30 -> 1509.2 | AX33: =AX29+AX32+AX30 -> 1613.0087 | AY33: =AY29+AY32+AY30 -> 6477.4087 | AZ33: =AZ29+AZ32+AZ30 -> 1824.8 | BA33: =BA29+BA32+BA30 -> 1930.4 | ... BD33: =BD29+BD32+BD30 -> 6993.4 | BE33: =BE29+BE32 -> 1211.8 | BF33: =BF29+BF32 -> 1232.9 | BG33: =BG29+BG32 -> 1155.3 | BH33: =BH29+BH32 -> 1220.9 | BI33: =BI29+BI32 -> 4820.9 | BJ33: =BJ29+BJ32 -> 1308.7 | BK33: =BK29+BK32 -> 1390.8 | BL33: =BL29+BL32 -> 1355.5 | ... CH33: =CH29+CH32 -> 10401.594
H34: Other income (expense) | L34: =L37+L35+L36 -> 98.6 | M34: =M37+M35+M36 -> 45.757 | N34: =N37+N35+N36 -> 84.7 | O34: =O37+O35+O36 -> 84.6 | P34: =P37+P35+P36 -> 313.657 | Q34: =Q37+Q35+Q36 -> 31.7 | R34: =R37+R35+R36 -> 47 | S34: =S37+S35+S36 -> 56 | ... AN34: =AN37+AN35+AN36 -> -39.4 | AO34: =AO35+AO37+AO36 -> -5 | AP34: =AP37+AP35+AP36 -> -11.2 | AQ34: =AQ37+AQ35+AQ36 -> -57.6 | AR34: =AR37+AR35+AR36 -> -83.4 | AS34: =AS37+AS35+AS36 -> -26.8 | AT34: =AT37+AT35+AT36 -> -179 | AU34: =AU37+AU35+AU36 -> -46 | AV34: =AV37+AV35+AV36 -> -16.5 | AW34: =AW37+AW35+AW36 -> 0.7 | ... CH34: =CH37+CH35+CH36 -> 178.68569 | EW34: Non-GAAP Other Income/(Deductions)
H35: Interest expense | L35: -24.6 | M35: -12 | N35: -24.3 | O35: -44.3 | P35: =SUM(L35:O35) -> -105.2 | Q35: -65 | R35: -66 | S35: -62.7 | T35: -44.6 | U35: =SUM(Q35:T35) -> -238.3 | V35: -53 | W35: -59 | X35: -55.8 | Y35: -60.4 | Z35: =SUM(V35:Y35) -> -228.2 | AA35: -73.8 | AB35: -68.6 | AC35: -62 | AD35: -61.1 | AE35: =SUM(AA35:AD35) -> -265.5 | AF35: -87.6 | AG35: -64.3 | AH35: -59.2 | AI35: -50.2 | AJ35: =SUM(AF35:AI35) -> -261.3 | AK35: -47.6 | AL35: -47.5 | AM35: -47.2 | AN35: -43.2 | AO35: =SUM(AK35:AN35) -> -185.5 | AP35: -45.8 | AQ35: -45.1 | AR35: -45 | AS35: -50 | AT35: =SUM(AP35:AS35) -> -185.9 | AU35: -45.3 | AV35: -43 | AW35: -47 | AX35: -42.6 | AY35: =SUM(AU35:AX35) -> -177.9 | AZ35: -40.3 | BA35: -40.3 | BB35: -39.8 | BC35: -39.7 | BD35: =SUM(AZ35:BC35) -> -160.1 | BE35: -37.8 | BF35: -35.5 | BG35: -38.1 | BH35: -37.4 | BI35: =SUM(BE35:BH35) -> -148.8 | BJ35: -40.9 | BK35: -48 | BL35: -39.3 | BM35: -44.2 | BN35: =SUM(BJ35:BM35) -> -172.4 | BO35: -43.4 | BP35: -43.2 | BQ35: -47.2 | BR35: -51.4 | BS35: =SUM(BO35:BR35) -> -185.2 | BT35: -46.6 | BU35: -53.6 | BV35: -61.9 | BW35: -62.9 | BX35: =SUM(BT35:BW35) -> -225 | BY35: =-61.2 -> -61.2 | BZ35: =(CC35-BY35)/3 -> -54.570342 | CA35: =(CC35-BY35-BZ35)/2 -> -54.570342 | CB35: =CC35-BY35-BZ35-CA35 -> -54.570342 | CC35: =-DEBT!CC20 -> -224.91102 | CD35: =-DEBT!CD20 -> -149.94362 | CE35: =-DEBT!CE20 -> -133.35731 | CF35: =-DEBT!CF20 -> -133.35731 | CG35: =-DEBT!CG20 -> -130.08581 | CH35: =-DEBT!CH20 -> -126.81431
H36: Interest income | L36: 46 | M36: 46.3 | N36: 52 | O36: 67.9 | P36: =SUM(L36:O36) -> 212.2 | Q36: 59.7 | R36: 68 | S36: 67.5 | T36: 66.3 | U36: =SUM(Q36:T36) -> 261.5 | V36: 57 | W36: 50 | X36: 50 | Y36: 58 | Z36: =SUM(V36:Y36) -> 215 | AA36: 17.8 | AB36: 2.5 | AC36: 4.7 | AD36: 1.8 | AE36: =SUM(AA36:AD36) -> 26.8 | AF36: 27.4 | AG36: 18.8 | AH36: 15.2 | AI36: 13.8 | AJ36: =SUM(AF36:AI36) -> 75.2 | AK36: 10.6 | AL36: 11 | AM36: 16.3 | AN36: 14 | AO36: =SUM(AK36:AN36) -> 51.9 | AP36: 15.5 | AQ36: 17.8 | AR36: 22.2 | AS36: 24.4 | AT36: =SUM(AP36:AS36) -> 79.9 | AU36: 26.1 | AV36: 27.2 | AW36: 25.7 | AX36: 26.1 | AY36: =SUM(AU36:AX36) -> 105.1 | AZ36: 23.6 | BA36: 29.7 | BB36: 32.2 | BC36: 34.2 | BD36: =SUM(AZ36:BC36) -> 119.7 | BE36: 34.4 | BF36: 33.6 | BG36: 28.8 | BH36: 24.2 | BI36: =SUM(BE36:BH36) -> 121 | BJ36: 21.4 | BK36: 20.6 | BL36: 21.2 | BM36: 23.8 | BN36: =SUM(BJ36:BM36) -> 87 | BO36: 24.2 | BP36: 23.5 | BQ36: 29.1 | BR36: 31.9 | BS36: =SUM(BO36:BR36) -> 108.7 | BT36: 32.6 | BU36: 36.9 | BV36: 45.1 | BW36: 52.7 | BX36: =SUM(BT36:BW36) -> 167.3 | BY36: =45.5 -> 45.5 | BZ36: =180/4 -> 45 | CA36: =180/4 -> 45 | CB36: =180/4 -> 45 | CC36: =SUM(BY36:CB36) -> 180.5 | CD36: =CC36 -> 180.5 | CE36: =CD36 -> 180.5 | CF36: =CE36 -> 180.5 | CG36: =CF36 -> 180.5 | CH36: =CG36 -> 180.5
H37: Other income (expense), net | L37: =L38+L39+L40+L41+L42 -> 77.2 | M37: =M38+M39+M40+M41+M42 -> 11.457 | N37: =N38+N39+N40+N41+N42 -> 57 | O37: =O38+O39+O40+O41+O42 -> 61 | P37: =P38+P39+P40+P41+P42 -> 206.657 | Q37: =Q38+Q39+Q40+Q41+Q42 -> 37 | R37: =R38+R39+R40+R41+R42 -> 45 | S37: =S38+S39+S40+S41+S42 -> 51.2 | ... V37: =V38+V39+V40+V41+V42 -> 34 | W37: =W38+W39+W40+W41 -> 11 | X37: =X38+X39+X40+X41 -> 56 | Y37: =Y38+Y39+Y40+Y41 -> 34 | Z37: =Z38+Z39+Z40+Z41+Z42 -> 135 | AA37: =AA38+AA39+AA40+AA41 -> 10.7 | AB37: =AB38+AB39+AB40+AB41 -> 29.1 | AC37: =AC38+AC39+AC40+AC41 -> -19 | AD37: =AD38+AD39+AD40+AD41 -> -50 | AE37: =AE38+AE39+AE40+AE41 -> -29.2 | AF37: =AF38+AF39+AF40+AF41 -> -10.5 | AG37: =AG38+AG39+AG40+AG41 -> 21.4 | AH37: =AH38+AH39+AH40+AH41 -> -22.9 | ... AO37: =AO38+AO39+AO40+AO41 -> 128.6 | AP37: 19.1 | AQ37: =40.4-0.9-69.8 -> -30.3 | AR37: =9.8+11.6-82 -> -60.6 | AS37: =-4.7+10.8-7.3 -> -1.2 | AT37: =SUM(AP37:AS37) -> -73 | AU37: -26.8 | AV37: -0.7 | AW37: 22 | AX37: -35.5 | AY37: =SUM(AU37:AX37) -> -41 | AZ37: 50.5 | BA37: 22.5 | BB37: -23.7 | BC37: 14.6 | BD37: =SUM(AZ37:BC37) -> 63.9 | BE37: 59.4 | BF37: 55.7 | BG37: =-8+77+33.8 -> 102.8 | BH37: 58.4 | BI37: =SUM(BE37:BH37) -> 276.3 | BJ37: 112.2 | BK37: 56.8 | BL37: 104.6 | BM37: 65.1 | BN37: =SUM(BJ37:BM37) -> 338.7 | BO37: 74.1 | BP37: 40.9 | BQ37: 45.3 | BR37: 35.3 | BS37: =SUM(BO37:BR37) -> 195.6 | BT37: 29.1 | BU37: 12.8 | BV37: 2.9 | BW37: 65.3 | BX37: =SUM(BT37:BW37) -> 110.1 | BY37: 83.2 | BZ37: 50 | CA37: 50 | CB37: 50 | CC37: =SUM(BY37:CB37) -> 233.2 | CD37: 125 | CE37: 125 | CF37: 125 | CG37: 125 | CH37: 125
H38: Outlicense of mkt. prod. | L38: 14.5 | M38: 10 | N38: 12 | O38: 43 | P38: =SUM(L38:O38) -> 79.5 | Q38: 1 | R38: 1 | S38: 10.1 | T38: 12.6 | U38: =SUM(Q38:T38) -> 24.7 | V38: 2 | W38: 1 | X38: 26 | Y38: 5 | Z38: =SUM(V38:Y38) -> 34 | AA38: 4 | AB38: 5.4 | AC38: 11.7 | AD38: 33.8 | AE38: =SUM(AA38:AD38) -> 54.9 | AF38: 3.3 | AG38: 4.8 | AH38: 0 | AI38: 0 | AJ38: =SUM(AF38:AI38) -> 8.1 | AK38: 0 | AL38: 0 | AM38: 0 | AN38: 0 | AO38: =SUM(AK38:AN38) -> 0 | AP38: 0 | AQ38: 0 | AR38: 0 | AS38: 0 | AT38: =SUM(AP38:AS38) -> 0 | AU38: 0 | AV38: 0 | AW38: 0 | AX38: 0 | AY38: =SUM(AU38:AX38) -> 0 | AZ38: 0 | BD38: 0 | BE38: 0 | BF38: 0 | BG38: 0 | BH38: 0 | BI38: 0 | BN38: 0 | BS38: 0 | BT38: 0 | BU38: 0 | BV38: 0 | BW38: 0 | BX38: 0 | BY38: 0 | BZ38: 0 | CA38: 0 | CB38: 0 | CC38: 0 | CD38: 0 | CE38: 0 | CF38: 0 | CG38: 0 | CH38: 0
H39: Outlicense of dev. stage prod. | L39: 39 | M39: 13 | N39: 0 | O39: 12 | P39: =SUM(L39:O39) -> 64 | Q39: 8 | R39: 16 | S39: 3.1 | T39: 21.6 | U39: =SUM(Q39:T39) -> 48.7 | V39: 25 | W39: 29 | X39: 31 | Y39: 39 | Z39: =SUM(V39:Y39) -> 124 | AA39: 25 | AB39: 13 | AC39: 0 | AD39: 2 | AE39: =SUM(AA39:AD39) -> 40 | AF39: 1 | AG39: 0 | AH39: 0 | AI39: 0 | AJ39: =SUM(AF39:AI39) -> 1 | AK39: 11.2 | AL39: 1.6 | AM39: 3.5 | AN39: 1.2 | AO39: =SUM(AK39:AN39) -> 17.5 | AP39: 0 | AQ39: 0 | AR39: 0 | AS39: 0 | AT39: =SUM(AP39:AS39) -> 0 | AU39: 0 | AV39: 0 | AW39: 0 | AX39: 0 | AY39: =SUM(AU39:AX39) -> 0 | AZ39: 0 | BD39: 0 | BE39: 0 | BF39: 0 | BG39: 0 | BH39: 0 | BI39: 0 | BN39: 0 | BS39: 0 | BT39: 0 | BU39: 0 | BV39: 0 | BW39: 0 | BX39: 0 | BY39: 0 | BZ39: 0 | CA39: 0 | CB39: 0 | CC39: 0 | CD39: 0 | CE39: 0 | CF39: 0 | CG39: 0 | CH39: 0
H40: Partnered prod. in dev. | L40: 1.63 | M40: 2 | N40: 2 | O40: 3 | P40: =SUM(L40:O40) -> 8.63 | Q40: 1 | R40: 1 | S40: 1.1 | T40: 0.6 | U40: =SUM(Q40:T40) -> 3.7 | V40: 14 | W40: 0 | X40: 10 | Y40: 3 | Z40: =SUM(V40:Y40) -> 27 | AA40: 0 | AB40: 2.5 | AC40: 0 | AD40: 1.1 | AE40: =SUM(AA40:AD40) -> 3.6 | AF40: 0 | AG40: 0 | AH40: 0 | AI40: 0 | AJ40: =SUM(AF40:AI40) -> 0 | AK40: 0 | AL40: 0 | AM40: 0 | AN40: 0 | AO40: =SUM(AK40:AN40) -> 0 | AP40: 0 | AQ40: 0 | AR40: 0 | AS40: 0 | AT40: =SUM(AP40:AS40) -> 0 | AU40: 0 | AV40: 0 | AW40: 0 | AX40: 0 | AY40: =SUM(AU40:AX40) -> 0 | AZ40: 0 | BD40: 0 | BE40: 0 | BF40: 0 | BG40: 0 | BH40: 0 | BI40: 0 | BN40: 0 | BS40: 0 | BT40: 0 | BU40: 0 | BV40: 0 | BW40: 0 | BX40: 0 | BY40: 0 | BZ40: 0 | CA40: 0 | CB40: 0 | CC40: 0 | CD40: 0 | CE40: 0 | CF40: 0 | CG40: 0 | CH40: 0
H41: Miscellaneous income/(expense) | L41: 34.8 | M41: -13 | N41: 37 | O41: -15 | P41: =SUM(L41:O41) -> 43.8 | Q41: 7 | R41: 4 | S41: 13.1 | T41: 16 | U41: =SUM(Q41:T41) -> 40.1 | V41: -18 | W41: -19 | X41: -11 | Y41: -13 | Z41: =SUM(V41:Y41) -> -61 | AA41: -18.3 | AB41: 8.2 | AC41: -30.7 | AD41: -86.9 | AE41: =SUM(AA41:AD41) -> -127.7 | AF41: -14.8 | AG41: 16.6 | AH41: -22.9 | AI41: -31.4 | AJ41: =SUM(AF41:AI41) -> -52.5 | AK41: 100.3 | AL41: 16.5 | AM41: 5.7 | AN41: -11.4 | AO41: =SUM(AK41:AN41) -> 111.1 | AP41: 0 | AQ41: 0 | AR41: 0 | AS41: 0 | AT41: =SUM(AP41:AS41) -> 0 | AU41: 0 | AV41: 0 | AW41: 0 | AX41: 0 | AY41: =SUM(AU41:AX41) -> 0 | AZ41: 0 | BD41: =AY41 -> 0 | BE41: 0 | BF41: =BA41 -> 0 | BG41: =BB41 -> 0 | BH41: =BC41 -> 0 | BI41: =BD41 -> 0 | BN41: =BI41 -> 0 | BS41: =BN41 -> 0 | BT41: =BO41 -> 0 | BU41: =BP41 -> 0 | BV41: =BQ41 -> 0 | BW41: =BR41 -> 0 | BX41: =BS41 -> 0 | BY41: =BT41 -> 0 | BZ41: =BU41 -> 0 | ... CC41: =BX41 -> 0 | CD41: =CC41 -> 0 | CE41: =CD41 -> 0 | CF41: =CE41 -> 0 | CG41: =CF41 -> 0 | CH41: =CG41 -> 0
H42: Cialis JV | L42: -12.73 | M42: -0.543 | N42: 6 | O42: 18 | P42: =SUM(L42:O42) -> 10.727 | Q42: 20 | R42: 23 | S42: 23.8 | T42: 30.2 | U42: =SUM(Q42:T42) -> 97 | V42: 11 | W42: 0 | X42: 0 | Y42: 0 | Z42: =SUM(V42:Y42) -> 11 | AA42: 0 | AB42: 0 | AC42: 0 | AD42: 0 | AE42: =SUM(AA42:AD42) -> 0 | AF42: 0 | AJ42: =SUM(AF42:AI42) -> 0 | AO42: =SUM(AK42:AN42) -> 0
H43: IMCL lic fees and milestones | P43: 96.442 | Q43: 144.403 | R43: 33.456 | S43: 34.948 | T43: 19.462 | U43: =SUM(Q43:T43) -> 232.269 | V43: 29.294 | W43: 33.445 | X43: 19.226 | Y43: 20.945 | Z43: =SUM(V43:Y43) -> 102.91 | AA43: 24.132 | AB43: 27.818 | AC43: 25.771 | AD43: NA | AE43: =SUM(AA43:AD43) -> 77.721 | AF43: 0
H44: Pretax income | L44: 944.4 | M44: 933.657 | N44: 1018.2 | O44: 1066 | P44: =P29+P34 -> 3962.257 | Q44: =Q29+Q34 -> 1056.3 | R44: =R29+R34 -> 1040.8 | S44: =S29+S34 -> 1105.75 | T44: =T29+T34 -> 1160.2 | U44: =U29+U34 -> 4363.05 | V44: =V29+V34 -> 1170.7 | W44: =W29+W34 -> 1254.9 | ... AD44: =AD29+AD34 -> 1379.5 | AE44: =SUM(AA44:AD44) -> 5262.4 | AF44: =AF29+AF34 -> 1682.9 | AG44: =AG29+AG34 -> 1572.51 | AH44: =AH29+AH34 -> 1619.5 | AI44: =AI29+AI34 -> 1265.6 | AJ44: =SUM(AF44:AI44) -> 6140.51 | AK44: =AK29+AK34 -> 1783.9 | AL44: =AL29+AL34 -> 1763.8 | AM44: =AM29+AM34 -> 1730.9 | AN44: =AN29+AN34 -> 1488.68 | AO44: =SUM(AK44:AN44) -> 6767.28 | AP44: =AP29+AP34 -> 1738.2 | AQ44: =AQ29+AQ34 -> 1663.8 | AR44: =AR29+AR34 -> 1527.8 | AS44: =AS29+AS34 -> 1209.2 | AT44: =AT29+AT34 -> 6139 | AU44: =AU29+AU34 -> 1359.1 | AV44: =AV29+AV34 -> 1185.7 | AW44: =AW29+AW34 -> 1140.2 | ... CH44: =CH29+CH34 -> 9717.2795 | EW44: Pretax Income
H45: Taxes | L45: 207.768 | M45: 205.40454 | N45: 224.1 | O45: 195 | P45: =SUM(L45:O45) -> 832.27254 | Q45: 221.9 | R45: 218.5 | S45: 232.2 | T45: 230.6 | U45: =SUM(Q45:T45) -> 903.2 | V45: 257.6 | W45: 276.1 | X45: 263.3 | Y45: 253.1 | Z45: =SUM(V45:Y45) -> 1050.1 | AA45: 260.1 | AB45: 273.6 | AC45: 288.2 | AD45: 263.4 | AE45: =SUM(AA45:AD45) -> 1085.3 | AF45: 370.3 | AG45: 346 | AH45: 307.5 | AI45: 265.7 | AJ45: =SUM(AF45:AI45) -> 1289.5 | AK45: 486.4 | AL45: 396.9 | AM45: 389.4 | AN45: 253.7 | AO45: =SUM(AK45:AN45) -> 1526.4 | AP45: 363.3 | AQ45: 347.7 | AR45: 273.9 | AS45: 240.5 | AT45: =SUM(AP45:AS45) -> 1225.4 | AU45: 332.2 | AV45: 262.1 | AW45: 251.9 | AX45: 271.2 | AY45: =SUM(AU45:AX45) -> 1117.4 | AZ45: 229.7 | BA45: 323.5 | BB45: 310.3 | BC45: 205.5 | BD45: =SUM(AZ45:BC45) -> 1069 | BE45: =172.3+44.1 -> 216.4 | BF45: =206.9+45.2 -> 252.1 | BG45: =199.3+46.1 -> 245.4 | BH45: =130.2+46.2 -> 176.4 | BI45: =SUM(BE45:BH45) -> 890.3 | BJ45: 274.4 | BK45: 250.3 | BL45: 314.3 | BM45: 129.3 | BN45: =SUM(BJ45:BM45) -> 968.3 | BO45: 192.3 | BP45: 262.3 | BQ45: 262.9 | BR45: 220.7 | BS45: =SUM(BO45:BR45) -> 938.2 | BT45: 279.6 | BU45: 327.2 | BV45: 257.8 | BW45: 306.1 | BX45: =SUM(BT45:BW45) -> 1170.7 | BY45: =265.6 -> 265.6 | BZ45: =BZ44*BZ46 -> 284.80947 | CA45: =CA44*CA46 -> 307.9135 | CB45: =CB44*CB46 -> 264.38793 | CC45: =SUM(BY45:CB45) -> 1122.7109 | CD45: =CD44*CD46 -> 1210.708 | CE45: =CE44*CE46 -> 1321.5822 | CF45: =CF44*CF46 -> 1421.6984 | CG45: =CG44*CG46 -> 1504.2026 | CH45: =CH44*CH46 -> 1603.3511
...

Sheet REV-ANNUAL
EX1: Section Header
A3: REV-ANNUAL
L4: 38442 | M4: 38533 | N4: 38625 | O4: 38717 | P4: 38717 | Q4: 38807 | R4: 38898 | S4: 38990 | T4: 39082 | U4: 39082 | V4: 39172 | W4: 39263 | X4: 39355 | Y4: 39447 | Z4: 39447 | AA4: 39538 | AB4: 39629 | AC4: 39721 | AD4: 39813 | AE4: 39813 | AF4: 39903 | AG4: 39994 | AH4: 40086 | AI4: 40178 | AJ4: 40178 | AK4: 40268 | AL4: 40359 | AM4: 40451 | AN4: 40543 | AO4: 40543 | AP4: 40633 | AQ4: 40724 | AR4: 40816 | AS4: 40908 | AT4: 40908 | AU4: 40999 | AV4: 41090 | AW4: 41182 | AX4: 41274 | AY4: 41274 | AZ4: 41364 | BA4: 41455 | BB4: 41547 | BC4: 41639 | BD4: 41639 | BE4: 41729 | BF4: 41820 | BG4: 41912 | BH4: 42004 | BI4: 42004 | BJ4: 42094 | BK4: 42185 | BL4: 42277 | BM4: 42369 | BN4: 42369 | BO4: 42460 | BP4: 42551 | BQ4: 42643 | BR4: 42735 | BS4: 42735 | BT4: 42825 | BU4: 42916 | BV4: 43008 | BW4: 43100 | BX4: 43100 | BY4: 43190 | BZ4: 43281 | CA4: 43373 | CB4: 43465 | CC4: 43465 | CD4: 43830 | CE4: 44196 | CF4: 44561 | CG4: 44926 | CH4: 45291
H5: Eli Lilly & Co. | J5: =LatestRpQ -> 43190
H6: Annual Revenues | J6: =LatestFiledQ -> 43100
H9: ($M) | L9: ="1Q:" & RIGHT(YEAR(L$4),2) & IF(L$4<=LatestRpQ, "A", "E") -> 1Q:05A | M9: ="2Q:" & RIGHT(YEAR(M$4),2) & IF(M$4<=LatestRpQ, "A", "E") -> 2Q:05A | N9: ="3Q:" & RIGHT(YEAR(N$4),2) & IF(N$4<=LatestRpQ, "A", "E") -> 3Q:05A | O9: ="4Q:" & RIGHT(YEAR(O$4),2) & IF(O$4<=LatestRpQ, "A", "E") -> 4Q:05A | P9: =YEAR(P$4) & IF(P$4<=LatestRpQ, "A", "E") -> 2005A | Q9: ="1Q:" & RIGHT(YEAR(Q$4),2) & IF(Q$4<=LatestRpQ, "A", "E") -> 1Q:06A | R9: ="2Q:" & RIGHT(YEAR(R$4),2) & IF(R$4<=LatestRpQ, "A", "E") -> 2Q:06A | S9: ="3Q:" & RIGHT(YEAR(S$4),2) & IF(S$4<=LatestRpQ, "A", "E") -> 3Q:06A | T9: ="4Q:" & RIGHT(YEAR(T$4),2) & IF(T$4<=LatestRpQ, "A", "E") -> 4Q:06A | U9: =YEAR(U$4) & IF(U$4<=LatestRpQ, "A", "E") -> 2006A | V9: ="1Q:" & RIGHT(YEAR(V$4),2) & IF(V$4<=LatestRpQ, "A", "E") -> 1Q:07A | W9: ="2Q:" & RIGHT(YEAR(W$4),2) & IF(W$4<=LatestRpQ, "A", "E") -> 2Q:07A | X9: ="3Q:" & RIGHT(YEAR(X$4),2) & IF(X$4<=LatestRpQ, "A", "E") -> 3Q:07A | Y9: ="4Q:" & RIGHT(YEAR(Y$4),2) & IF(Y$4<=LatestRpQ, "A", "E") -> 4Q:07A | Z9: =YEAR(Z$4) & IF(Z$4<=LatestRpQ, "A", "E") -> 2007A | AA9: ="1Q:" & RIGHT(YEAR(AA$4),2) & IF(AA$4<=LatestRpQ, "A", "E") -> 1Q:08A | AB9: ="2Q:" & RIGHT(YEAR(AB$4),2) & IF(AB$4<=LatestRpQ, "A", "E") -> 2Q:08A | AC9: ="3Q:" & RIGHT(YEAR(AC$4),2) & IF(AC$4<=LatestRpQ, "A", "E") -> 3Q:08A | AD9: ="4Q:" & RIGHT(YEAR(AD$4),2) & IF(AD$4<=LatestRpQ, "A", "E") -> 4Q:08A | AE9: =YEAR(AE$4) & IF(AE$4<=LatestRpQ, "A", "E") -> 2008A | AF9: ="1Q:" & RIGHT(YEAR(AF$4),2) & IF(AF$4<=LatestRpQ, "A", "E") -> 1Q:09A | AG9: ="2Q:" & RIGHT(YEAR(AG$4),2) & IF(AG$4<=LatestRpQ, "A", "E") -> 2Q:09A | AH9: ="3Q:" & RIGHT(YEAR(AH$4),2) & IF(AH$4<=LatestRpQ, "A", "E") -> 3Q:09A | AI9: ="4Q:" & RIGHT(YEAR(AI$4),2) & IF(AI$4<=LatestRpQ, "A", "E") -> 4Q:09A | AJ9: =YEAR(AJ$4) & IF(AJ$4<=LatestRpQ, "A", "E") -> 2009A | AK9: ="1Q:" & RIGHT(YEAR(AK$4),2) & IF(AK$4<=LatestRpQ, "A", "E") -> 1Q:10A | AL9: ="2Q:" & RIGHT(YEAR(AL$4),2) & IF(AL$4<=LatestRpQ, "A", "E") -> 2Q:10A | AM9: ="3Q:" & RIGHT(YEAR(AM$4),2) & IF(AM$4<=LatestRpQ, "A", "E") -> 3Q:10A | AN9: ="4Q:" & RIGHT(YEAR(AN$4),2) & IF(AN$4<=LatestRpQ, "A", "E") -> 4Q:10A | AO9: =YEAR(AO$4) & IF(AO$4<=LatestRpQ, "A", "E") -> 2010A | AP9: ="1Q:" & RIGHT(YEAR(AP$4),2) & IF(AP$4<=LatestRpQ, "A", "E") -> 1Q:11A | AQ9: ="2Q:" & RIGHT(YEAR(AQ$4),2) & IF(AQ$4<=LatestRpQ, "A", "E") -> 2Q:11A | AR9: ="3Q:" & RIGHT(YEAR(AR$4),2) & IF(AR$4<=LatestRpQ, "A", "E") -> 3Q:11A | AS9: ="4Q:" & RIGHT(YEAR(AS$4),2) & IF(AS$4<=LatestRpQ, "A", "E") -> 4Q:11A | AT9: =YEAR(AT$4) & IF(AT$4<=LatestRpQ, "A", "E") -> 2011A | AU9: ="1Q:" & RIGHT(YEAR(AU$4),2) & IF(AU$4<=LatestRpQ, "A", "E") -> 1Q:12A | AV9: ="2Q:" & RIGHT(YEAR(AV$4),2) & IF(AV$4<=LatestRpQ, "A", "E") -> 2Q:12A | AW9: ="3Q:" & RIGHT(YEAR(AW$4),2) & IF(AW$4<=LatestRpQ, "A", "E") -> 3Q:12A | AX9: ="4Q:" & RIGHT(YEAR(AX$4),2) & IF(AX$4<=LatestRpQ, "A", "E") -> 4Q:12A | AY9: =YEAR(AY$4) & IF(AY$4<=LatestRpQ, "A", "E") -> 2012A | AZ9: ="1Q:" & RIGHT(YEAR(AZ$4),2) & IF(AZ$4<=LatestRpQ, "A", "E") -> 1Q:13A | BA9: ="2Q:" & RIGHT(YEAR(BA$4),2) & IF(BA$4<=LatestRpQ, "A", "E") -> 2Q:13A | BB9: ="3Q:" & RIGHT(YEAR(BB$4),2) & IF(BB$4<=LatestRpQ, "A", "E") -> 3Q:13A | BC9: ="4Q:" & RIGHT(YEAR(BC$4),2) & IF(BC$4<=LatestRpQ, "A", "E") -> 4Q:13A | BD9: =YEAR(BD$4) & IF(BD$4<=LatestRpQ, "A", "E") -> 2013A | BE9: ="1Q:" & RIGHT(YEAR(BE$4),2) & IF(BE$4<=LatestRpQ, "A", "E") -> 1Q:14A | BF9: ="2Q:" & RIGHT(YEAR(BF$4),2) & IF(BF$4<=LatestRpQ, "A", "E") -> 2Q:14A | BG9: ="3Q:" & RIGHT(YEAR(BG$4),2) & IF(BG$4<=LatestRpQ, "A", "E") -> 3Q:14A | BH9: ="4Q:" & RIGHT(YEAR(BH$4),2) & IF(BH$4<=LatestRpQ, "A", "E") -> 4Q:14A | BI9: =YEAR(BI$4) & IF(BI$4<=LatestRpQ, "A", "E") -> 2014A | BJ9: ="1Q:" & RIGHT(YEAR(BJ$4),2) & IF(BJ$4<=LatestRpQ, "A", "E") -> 1Q:15A | BK9: ="2Q:" & RIGHT(YEAR(BK$4),2) & IF(BK$4<=LatestRpQ, "A", "E") -> 2Q:15A | BL9: ="3Q:" & RIGHT(YEAR(BL$4),2) & IF(BL$4<=LatestRpQ, "A", "E") -> 3Q:15A | BM9: ="4Q:" & RIGHT(YEAR(BM$4),2) & IF(BM$4<=LatestRpQ, "A", "E") -> 4Q:15A | BN9: =YEAR(BN$4) & IF(BN$4<=LatestRpQ, "A", "E") -> 2015A | BO9: ="1Q:" & RIGHT(YEAR(BO$4),2) & IF(BO$4<=LatestRpQ, "A", "E") -> 1Q:16A | BP9: ="2Q:" & RIGHT(YEAR(BP$4),2) & IF(BP$4<=LatestRpQ, "A", "E") -> 2Q:16A | BQ9: ="3Q:" & RIGHT(YEAR(BQ$4),2) & IF(BQ$4<=LatestRpQ, "A", "E") -> 3Q:16A | BR9: ="4Q:" & RIGHT(YEAR(BR$4),2) & IF(BR$4<=LatestRpQ, "A", "E") -> 4Q:16A | BS9: =YEAR(BS$4) & IF(BS$4<=LatestRpQ, "A", "E") -> 2016A | BT9: ="1Q:" & RIGHT(YEAR(BT$4),2) & IF(BT$4<=LatestRpQ, "A", "E") -> 1Q:17A | BU9: ="2Q:" & RIGHT(YEAR(BU$4),2) & IF(BU$4<=LatestRpQ, "A", "E") -> 2Q:17A | BV9: ="3Q:" & RIGHT(YEAR(BV$4),2) & IF(BV$4<=LatestRpQ, "A", "E") -> 3Q:17A | BW9: ="4Q:" & RIGHT(YEAR(BW$4),2) & IF(BW$4<=LatestRpQ, "A", "E") -> 4Q:17A | BX9: =YEAR(BX$4) & IF(BX$4<=LatestRpQ, "A", "E") -> 2017A | BY9: ="1Q:" & RIGHT(YEAR(BY$4),2) & IF(BY$4<=LatestRpQ, "A", "E") -> 1Q:18A | BZ9: ="2Q:" & RIGHT(YEAR(BZ$4),2) & IF(BZ$4<=LatestRpQ, "A", "E") -> 2Q:18E | CA9: ="3Q:" & RIGHT(YEAR(CA$4),2) & IF(CA$4<=LatestRpQ, "A", "E") -> 3Q:18E | CB9: ="4Q:" & RIGHT(YEAR(CB$4),2) & IF(CB$4<=LatestRpQ, "A", "E") -> 4Q:18E | CC9: =YEAR(CC$4) & IF(CC$4<=LatestRpQ, "A", "E") -> 2018E | CD9: =YEAR(CD$4) & IF(CD$4<=LatestRpQ, "A", "E") -> 2019E | CE9: =YEAR(CE$4) & IF(CE$4<=LatestRpQ, "A", "E") -> 2020E | CF9: =YEAR(CF$4) & IF(CF$4<=LatestRpQ, "A", "E") -> 2021E | CG9: =YEAR(CG$4) & IF(CG$4<=LatestRpQ, "A", "E") -> 2022E | CH9: =YEAR(CH$4) & IF(CH$4<=LatestRpQ, "A", "E") -> 2023E
